File: flexion/3_axis/Specimen_RawData_2.csv
Specimen properties : Specimen label,"2"
Specimen properties : Support span,"72.00",mm
Specimen properties : Thickness,"3.77",mm
Specimen properties : Width,"12.95",mm
Maximum Load : Maximum Load,"469.4",N
Tangent Modulus of Elasticity : Tangent Modulus of Elasticity,"46072769395.23130",Pa
Test : Rate 1,"1.00000",mm/min
Specimen notes : Specimen note 1,""

Time,Displacement,Load,Flexure extension,Corrected extension,Flexure strain (Corrected extension),Flexure stress
(s),(mm),(N),(mm),(mm),(mm/mm),(MPa)
"0.00000","0.00000","40.07318","0.10581","-1.05437","0.00046","23.51392"
"0.60000","0.00811","42.56220","0.11358","-1.04659","0.00050","24.97442"
"1.20000","0.01831","45.58236","0.12338","-1.03680","0.00054","26.74657"
"1.80000","0.02848","48.40509","0.13317","-1.02701","0.00058","28.40288"
"2.40000","0.03817","51.35055","0.14246","-1.01771","0.00062","30.13120"
"3.00000","0.04817","54.06922","0.15210","-1.00808","0.00066","31.72644"
"3.60000","0.05841","57.05347","0.16194","-0.99824","0.00071","33.47752"
"4.20000","0.06865","59.97405","0.17183","-0.98835","0.00075","35.19125"
"4.80000","0.07819","62.76530","0.18104","-0.97913","0.00079","36.82908"
"5.40000","0.08817","65.81838","0.19066","-0.96951","0.00083","38.62055"
"6.00000","0.09827","68.89815","0.20041","-0.95977","0.00087","40.42768"
"6.60000","0.10847","72.23853","0.21021","-0.94997","0.00092","42.38773"
"7.20000","0.11815","75.29211","0.21954","-0.94064","0.00096","44.17949"
"7.80000","0.12823","78.57428","0.22923","-0.93095","0.00100","46.10539"
"8.40000","0.13847","81.93560","0.23908","-0.92110","0.00104","48.07773"
"9.00000","0.14861","85.22524","0.24884","-0.91134","0.00109","50.00801"
"9.60000","0.15808","88.41941","0.25795","-0.90222","0.00113","51.88226"
"10.20000","0.16818","91.72409","0.26773","-0.89244","0.00117","53.82137"
"10.80000","0.17839","94.98352","0.27763","-0.88255","0.00121","55.73391"
"11.40000","0.18842","98.46542","0.28731","-0.87286","0.00125","57.77700"
"12.00000","0.19812","101.74405","0.29669","-0.86348","0.00129","59.70082"
"12.60000","0.20827","104.91547","0.30653","-0.85365","0.00134","61.56173"
"13.20000","0.21852","108.35660","0.31644","-0.84373","0.00138","63.58090"
"13.80000","0.22842","111.76199","0.32601","-0.83417","0.00142","65.57909"
"14.40000","0.23810","114.99239","0.33538","-0.82480","0.00146","67.47461"
"15.00000","0.24825","118.37785","0.34519","-0.81498","0.00151","69.46111"
"15.60000","0.25848","121.84526","0.35509","-0.80509","0.00155","71.49570"
"16.20000","0.26830","125.12834","0.36459","-0.79559","0.00159","73.42213"
"16.80000","0.27812","128.34683","0.37409","-0.78609","0.00163","75.31066"
"17.40000","0.28831","131.75018","0.38395","-0.77622","0.00168","77.30766"
"18.00000","0.29864","135.09703","0.39395","-0.76622","0.00172","79.27150"
"18.60000","0.30829","138.41293","0.40328","-0.75690","0.00176","81.21719"
"19.20000","0.31814","141.77000","0.41281","-0.74737","0.00180","83.18703"
"19.80000","0.32828","144.98691","0.42264","-0.73754","0.00184","85.07463"
"20.40000","0.33843","148.49529","0.43244","-0.72774","0.00189","87.13326"
"21.00000","0.34820","151.65628","0.44190","-0.71827","0.00193","88.98805"
"21.60000","0.35822","154.90625","0.45161","-0.70857","0.00197","90.89505"
"22.20000","0.36839","158.33887","0.46145","-0.69873","0.00201","92.90923"
"22.80000","0.37865","161.75813","0.47143","-0.68875","0.00206","94.91556"
"23.40000","0.38817","164.83894","0.48068","-0.67950","0.00210","96.72330"
"24.00000","0.39815","168.20038","0.49037","-0.66981","0.00214","98.69571"
"24.60000","0.40831","171.47813","0.50025","-0.65993","0.00218","100.61901"
"25.20000","0.41859","175.00476","0.51023","-0.64994","0.00223","102.68835"
"25.80000","0.42818","178.03313","0.51957","-0.64061","0.00227","104.46531"
"26.40000","0.43821","181.31702","0.52931","-0.63086","0.00231","106.39222"
"27.00000","0.44845","184.67268","0.53927","-0.62090","0.00235","108.36124"
"27.60000","0.45859","187.96106","0.54913","-0.61105","0.00240","110.29077"
"28.20000","0.46808","190.95390","0.55836","-0.60181","0.00244","112.04690"
"28.80000","0.47819","194.35143","0.56819","-0.59198","0.00248","114.04047"
"29.40000","0.48842","197.68649","0.57814","-0.58204","0.00252","115.99741"
"30.00000","0.49840","200.93510","0.58784","-0.57233","0.00257","117.90361"
"30.60000","0.50812","204.00337","0.59732","-0.56286","0.00261","119.70399"
"31.20000","0.51824","207.26102","0.60717","-0.55300","0.00265","121.61549"
"31.80000","0.52850","210.50551","0.61717","-0.54300","0.00269","123.51928"
"32.40000","0.53848","213.79448","0.62689","-0.53329","0.00274","125.44917"
"33.00000","0.54808","216.84419","0.63625","-0.52393","0.00278","127.23866"
"33.60000","0.55820","219.99779","0.64612","-0.51406","0.00282","129.08911"
"34.20000","0.56845","223.23888","0.65610","-0.50407","0.00286","130.99089"
"34.80000","0.57834","226.34172","0.66575","-0.49442","0.00290","132.81157"
"35.40000","0.58816","229.47057","0.67531","-0.48486","0.00295","134.64749"
"36.00000","0.59838","232.77538","0.68527","-0.47491","0.00299","136.58667"
"36.60000","0.60857","235.89935","0.69522","-0.46496","0.00303","138.41974"
"37.20000","0.61829","238.95329","0.70469","-0.45548","0.00307","140.21172"
"37.80000","0.62812","241.85765","0.71428","-0.44589","0.00312","141.91592"
"38.40000","0.63828","245.04900","0.72420","-0.43598","0.00316","143.78853"
"39.00000","0.64847","248.39746","0.73413","-0.42605","0.00320","145.75331"
"39.60000","0.65828","251.32458","0.74372","-0.41646","0.00325","147.47087"
"40.20000","0.66815","254.23732","0.75337","-0.40681","0.00329","149.17999"
"40.80000","0.67838","257.39276","0.76335","-0.39682","0.00333","151.03152"
"41.40000","0.68862","260.59995","0.77334","-0.38684","0.00337","152.91342"
"42.00000","0.69817","263.43024","0.78268","-0.37750","0.00342","154.57417"
"42.60000","0.70812","266.33340","0.79240","-0.36777","0.00346","156.27766"
"43.20000","0.71834","269.50565","0.80238","-0.35779","0.00350","158.13907"
"43.80000","0.72853","272.68134","0.81232","-0.34785","0.00354","160.00247"
"44.40000","0.73814","275.40604","0.82173","-0.33845","0.00359","161.60126"
"45.00000","0.74822","278.32855","0.83158","-0.32860","0.00363","163.31612"
"45.60000","0.75842","281.37393","0.84154","-0.31863","0.00367","165.10307"
"46.20000","0.76860","284.46524","0.85149","-0.30869","0.00372","166.91698"
"46.80000","0.77812","287.13657","0.86080","-0.29937","0.00376","168.48444"
"47.40000","0.78819","290.05902","0.87065","-0.28952","0.00380","170.19926"
"48.00000","0.79831","293.05701","0.88057","-0.27961","0.00384","171.95840"
"48.60000","0.80841","295.95032","0.89048","-0.26970","0.00389","173.65613"
"49.20000","0.81820","298.65335","0.90008","-0.26009","0.00393","175.24219"
"49.80000","0.82830","301.62833","0.90998","-0.25020","0.00397","176.98784"
"50.40000","0.83855","304.64124","0.92003","-0.24015","0.00401","178.75574"
"51.00000","0.84852","307.47760","0.92982","-0.23036","0.00406","180.42004"
"51.60000","0.85804","310.00076","0.93916","-0.22101","0.00410","181.90057"
"52.20000","0.86822","313.00195","0.94914","-0.21103","0.00414","183.66159"
"52.80000","0.87844","315.95538","0.95917","-0.20101","0.00419","185.39459"
"53.40000","0.88835","318.66040","0.96890","-0.19128","0.00423","186.98183"
"54.00000","0.89814","321.32181","0.97851","-0.18167","0.00427","188.54347"
"54.60000","0.90836","324.16556","0.98853","-0.17164","0.00431","190.21211"
"55.20000","0.91856","327.02679","0.99855","-0.16163","0.00436","191.89101"
"55.80000","0.92831","329.71817","1.00812","-0.15206","0.00440","193.47025"
"56.40000","0.93808","332.30350","1.01771","-0.14247","0.00444","194.98724"
"57.00000","0.94824","335.07129","1.02769","-0.13249","0.00448","196.61131"
"57.60000","0.95853","337.88638","1.03779","-0.12239","0.00453","198.26314"
"58.20000","0.96823","340.42154","1.04732","-0.11286","0.00457","199.75070"
"58.80000","0.97812","343.11139","1.05703","-0.10314","0.00461","201.32904"
"59.40000","0.98837","345.84250","1.06711","-0.09307","0.00466","202.93158"
"60.00000","0.99870","348.58270","1.07726","-0.08292","0.00470","204.53947"
"60.60000","1.00816","350.90659","1.08658","-0.07360","0.00474","205.90306"
"61.20000","1.01815","353.55786","1.09639","-0.06379","0.00478","207.45877"
"61.80000","1.02831","356.25067","1.10638","-0.05380","0.00483","209.03883"
"62.40000","1.03845","358.79550","1.11635","-0.04382","0.00487","210.53207"
"63.00000","1.04816","361.20914","1.12592","-0.03426","0.00491","211.94833"
"63.60000","1.05824","363.79761","1.13583","-0.02435","0.00496","213.46719"
"64.20000","1.06843","366.39328","1.14585","-0.01433","0.00500","214.99026"
"64.80000","1.07868","369.07825","1.15592","-0.00425","0.00504","216.56573"
"65.40000","1.08814","371.39182","1.16524","0.00507","0.00508","217.92328"
"66.00000","1.09814","373.88153","1.17508","0.01490","0.00513","219.38417"
"66.60000","1.10835","376.40164","1.18512","0.02495","0.00517","220.86292"
"67.20000","1.11848","379.09256","1.19509","0.03491","0.00521","222.44188"
"67.80000","1.12817","381.23788","1.20463","0.04446","0.00526","223.70070"
"68.40000","1.13824","383.72574","1.21455","0.05437","0.00530","225.16051"
"69.00000","1.14854","386.24344","1.22468","0.06451","0.00534","226.63783"
"69.60000","1.15850","388.69400","1.23449","0.07431","0.00539","228.07576"
"70.20000","1.16810","390.81107","1.24397","0.08379","0.00543","229.31799"
"70.80000","1.17821","393.35455","1.25394","0.09376","0.00547","230.81046"
"71.40000","1.18843","395.63663","1.26402","0.10385","0.00552","232.14952"
"72.00000","1.19835","398.01187","1.27381","0.11363","0.00556","233.54324"
"72.60000","1.20811","400.19299","1.28344","0.12327","0.00560","234.82307"
"73.20000","1.21828","402.64163","1.29347","0.13330","0.00564","236.25987"
"73.80000","1.22860","404.98981","1.30366","0.14348","0.00569","237.63773"
"74.40000","1.23839","407.19229","1.31332","0.15315","0.00573","238.93008"
"75.00000","1.24812","409.28995","1.32293","0.16276","0.00577","240.16093"
"75.60000","1.25825","411.55270","1.33294","0.17276","0.00582","241.48866"
"76.20000","1.26848","413.78369","1.34303","0.18286","0.00586","242.79774"
"76.80000","1.27821","416.03189","1.35264","0.19246","0.00590","244.11694"
"77.40000","1.28817","418.19238","1.36248","0.20230","0.00595","245.38466"
"78.00000","1.29840","420.34882","1.37258","0.21240","0.00599","246.64999"
"78.60000","1.30862","422.50430","1.38268","0.22251","0.00603","247.91478"
"79.20000","1.31821","424.44128","1.39216","0.23198","0.00607","249.05136"
"79.80000","1.32815","426.53134","1.40198","0.24180","0.00612","250.27774"
"80.40000","1.33827","428.66989","1.41197","0.25180","0.00616","251.53259"
"81.00000","1.34844","430.81683","1.42203","0.26185","0.00620","252.79236"
"81.60000","1.35821","432.74109","1.43168","0.27151","0.00625","253.92146"
"82.20000","1.36821","434.80508","1.44156","0.28139","0.00629","255.13257"
"82.80000","1.37845","436.96469","1.45169","0.29151","0.00633","256.39978"
"83.40000","1.38862","439.00491","1.46173","0.30156","0.00638","257.59692"
"84.00000","1.39811","440.63824","1.47113","0.31096","0.00642","258.55533"
"84.60000","1.40816","442.70413","1.48107","0.32089","0.00646","259.76752"
"85.20000","1.41837","444.67328","1.49116","0.33099","0.00651","260.92297"
"85.80000","1.42850","446.67377","1.50118","0.34100","0.00655","262.09680"
"86.40000","1.43814","448.43372","1.51072","0.35055","0.00659","263.12952"
"87.00000","1.44824","450.17441","1.52073","0.36055","0.00664","264.15091"
"87.60000","1.45847","451.83209","1.53086","0.37068","0.00668","265.12360"
"88.20000","1.46853","453.14856","1.54084","0.38067","0.00672","265.89606"
"88.80000","1.47810","453.60388","1.55039","0.39021","0.00677","266.16324"
"89.40000","1.48827","454.78818","1.56049","0.40031","0.00681","266.85815"
"90.00000","1.49839","456.14807","1.57054","0.41036","0.00685","267.65610"
"90.60000","1.50832","457.00961","1.58041","0.42024","0.00690","268.16162"
"91.20000","1.51812","456.97986","1.59021","0.43004","0.00694","268.14417"
"91.80000","1.52833","455.26443","1.60052","0.44034","0.00698","267.13760"
"92.40000","1.53857","449.67929","1.61108","0.45090","0.00703","263.86038"
"93.00000","1.54843","443.42453","1.62130","0.46113","0.00707","260.19025"
"93.60000","1.55808","425.42383","1.63198","0.47180","0.00712","249.62788"
"94.20000","1.56827","416.78488","1.64266","0.48248","0.00717","244.55878"
"94.80000","1.57847","414.95035","1.65296","0.49278","0.00721","243.48232"
"95.40000","1.58829","414.68073","1.66279","0.50262","0.00726","243.32411"
"96.00000","1.59813","415.02835","1.67262","0.51244","0.00730","243.52809"
"96.60000","1.60839","415.88116","1.68282","0.52265","0.00734","244.02849"
"97.20000","1.61863","416.98911","1.69301","0.53283","0.00739","244.67860"
"97.80000","1.62822","417.87918","1.70254","0.54237","0.00743","245.20088"
"98.40000","1.63810","419.09158","1.71236","0.55218","0.00747","245.91229"
"99.00000","1.64830","420.09744","1.72250","0.56232","0.00752","246.50250"
"99.60000","1.65856","421.51324","1.73268","0.57250","0.00756","247.33325"
"100.20000","1.66822","422.56088","1.74228","0.58211","0.00760","247.94798"
"100.80000","1.67816","423.75549","1.75215","0.59197","0.00765","248.64896"
"101.40000","1.68839","424.99606","1.76231","0.60213","0.00769","249.37689"
"102.00000","1.69866","426.38391","1.77250","0.61232","0.00773","250.19124"
"102.60000","1.70810","427.56549","1.78187","0.62169","0.00778","250.88457"
"103.20000","1.71818","428.88760","1.79187","0.63170","0.00782","251.66034"
"103.80000","1.72839","430.27454","1.80201","0.64184","0.00786","252.47417"
"104.40000","1.73846","431.69974","1.81200","0.65182","0.00791","253.31042"
"105.00000","1.74816","432.77457","1.82164","0.66146","0.00795","253.94112"
"105.60000","1.75828","434.05319","1.83168","0.67150","0.00799","254.69138"
"106.20000","1.76848","435.29160","1.84181","0.68164","0.00804","255.41805"
"106.80000","1.77853","436.49274","1.85179","0.69161","0.00808","256.12283"
"107.40000","1.78813","437.48840","1.86134","0.70116","0.00812","256.70706"
"108.00000","1.79820","438.58420","1.87134","0.71117","0.00817","257.35007"
"108.60000","1.80835","439.57370","1.88144","0.72126","0.00821","257.93066"
"109.20000","1.81839","440.79776","1.89141","0.73123","0.00825","258.64893"
"109.80000","1.82817","441.63004","1.90114","0.74096","0.00830","259.13727"
"110.40000","1.83828","442.63162","1.91119","0.75102","0.00834","259.72498"
"111.00000","1.84860","443.70731","1.92145","0.76127","0.00838","260.35617"
"111.60000","1.85841","444.76901","1.93120","0.77103","0.00843","260.97916"
"112.20000","1.86804","445.36093","1.94080","0.78062","0.00847","261.32648"
"112.80000","1.87822","446.59335","1.95091","0.79074","0.00851","262.04962"
"113.40000","1.88853","447.40619","1.96117","0.80100","0.00856","262.52658"
"114.00000","1.89827","448.36542","1.97086","0.81068","0.00860","263.08942"
"114.60000","1.90815","449.01120","1.98070","0.82053","0.00864","263.46835"
"115.20000","1.91836","450.01392","1.99086","0.83068","0.00869","264.05673"
"115.80000","1.92860","450.93774","2.00104","0.84087","0.00873","264.59882"
"116.40000","1.93826","451.71930","2.01066","0.85048","0.00877","265.05740"
"117.00000","1.94814","452.32150","2.02050","0.86032","0.00882","265.41077"
"117.60000","1.95828","453.12857","2.03060","0.87042","0.00886","265.88434"
"118.20000","1.96851","453.96927","2.04078","0.88060","0.00890","266.37762"
"118.80000","1.97821","454.50992","2.05045","0.89027","0.00895","266.69485"
"119.40000","1.98819","455.23010","2.06039","0.90021","0.00899","267.11746"
"120.00000","1.99844","455.93033","2.07060","0.91042","0.00903","267.52832"
"120.60000","2.00867","456.73077","2.08078","0.92060","0.00908","267.99802"
"121.20000","2.01813","457.13153","2.09021","0.93004","0.00912","268.23315"
"121.80000","2.02817","457.68149","2.10022","0.94005","0.00916","268.55585"
"122.40000","2.03836","458.20306","2.11038","0.95021","0.00921","268.86191"
"123.00000","2.04839","458.69736","2.12039","0.96021","0.00925","269.15195"
"123.60000","2.05818","459.00330","2.13016","0.96998","0.00929","269.33145"
"124.20000","2.06828","459.42963","2.14023","0.98006","0.00934","269.58163"
"124.80000","2.07848","459.95651","2.15041","0.99023","0.00938","269.89078"
"125.40000","2.08855","460.29813","2.16046","1.00028","0.00943","270.09125"
"126.00000","2.09813","460.42996","2.17003","1.00985","0.00947","270.16861"
"126.60000","2.10815","460.58936","2.18004","1.01986","0.00951","270.26212"
"127.20000","2.11838","460.91000","2.19025","1.03007","0.00956","270.45029"
"127.80000","2.12842","461.08994","2.20029","1.04011","0.00960","270.55585"
"128.40000","2.13809","461.06824","2.20995","1.04977","0.00964","270.54312"
"129.00000","2.14830","461.23611","2.22016","1.05998","0.00969","270.64163"
"129.60000","2.15862","461.44916","2.23046","1.07028","0.00973","270.76663"
"130.20000","2.16843","461.22116","2.24029","1.08011","0.00978","270.63284"
"130.80000","2.17808","460.89258","2.24995","1.08977","0.00982","270.44003"
"131.40000","2.18827","460.79736","2.26015","1.09997","0.00986","270.38419"
"132.00000","2.19846","460.79889","2.27034","1.11016","0.00991","270.38507"
"132.60000","2.20825","460.58926","2.28014","1.11997","0.00995","270.26208"
"133.20000","2.21817","460.35141","2.29007","1.12990","0.00999","270.12250"
"133.80000","2.22835","460.02258","2.30028","1.14010","0.01004","269.92957"
"134.40000","2.23864","459.88672","2.31057","1.15039","0.01008","269.84982"
"135.00000","2.24832","459.48447","2.32028","1.16010","0.01012","269.61380"
"135.60000","2.25811","459.02948","2.33009","1.16991","0.01017","269.34683"
"136.20000","2.26824","458.81857","2.34023","1.18006","0.01021","269.22308"
"136.80000","2.27851","458.58417","2.35052","1.19034","0.01026","269.08554"
"137.40000","2.28820","458.34808","2.36022","1.20004","0.01030","268.94699"
"138.00000","2.29819","458.23093","2.37022","1.21004","0.01034","268.87827"
"138.60000","2.30841","458.12555","2.38044","1.22027","0.01039","268.81644"
"139.20000","2.31866","458.16318","2.39069","1.23052","0.01043","268.83850"
"139.80000","2.32815","457.98285","2.40019","1.24001","0.01047","268.73270"
"140.40000","2.33816","458.11191","2.41019","1.25002","0.01052","268.80841"
"141.00000","2.34830","458.20395","2.42033","1.26015","0.01056","268.86243"
"141.60000","2.35846","458.52136","2.43047","1.27029","0.01061","269.04868"
"142.20000","2.36814","458.54910","2.44015","1.27997","0.01065","269.06494"
"142.80000","2.37823","458.49750","2.45024","1.29006","0.01069","269.03467"
"143.40000","2.38845","458.74561","2.46044","1.30027","0.01074","269.18027"
"144.00000","2.39857","459.00476","2.47055","1.31038","0.01078","269.33234"
"144.60000","2.40810","458.95047","2.48009","1.31991","0.01082","269.30048"
"145.20000","2.41819","459.02914","2.49017","1.33000","0.01087","269.34662"
"145.80000","2.42843","459.30576","2.50039","1.34022","0.01091","269.50894"
"146.40000","2.43838","459.55838","2.51033","1.35016","0.01095","269.65717"
"147.00000","2.44811","459.52475","2.52006","1.35988","0.01100","269.63745"
"147.60000","2.45828","459.72705","2.53022","1.37005","0.01104","269.75613"
"148.20000","2.46857","459.95209","2.54050","1.38032","0.01109","269.88818"
"148.80000","2.47845","460.11011","2.55036","1.39019","0.01113","269.98093"
"149.40000","2.48813","459.98343","2.56005","1.39988","0.01117","269.90659"
"150.00000","2.49825","460.26721","2.57016","1.40998","0.01121","270.07309"
"150.60000","2.50838","460.18256","2.58029","1.42011","0.01126","270.02344"
"151.20000","2.51827","460.36154","2.59018","1.43000","0.01130","270.12845"
"151.80000","2.52816","460.51251","2.60005","1.43987","0.01135","270.21704"
"152.40000","2.53834","460.81949","2.61021","1.45004","0.01139","270.39716"
"153.00000","2.54862","461.18008","2.62048","1.46030","0.01143","270.60876"
"153.60000","2.55832","461.06027","2.63018","1.47001","0.01148","270.53845"
"154.20000","2.56809","461.14069","2.63995","1.47978","0.01152","270.58563"
"154.80000","2.57826","461.32031","2.65011","1.48993","0.01156","270.69104"
"155.40000","2.58856","461.52789","2.66039","1.50022","0.01161","270.81284"
"156.00000","2.59826","461.70731","2.67009","1.50991","0.01165","270.91812"
"156.60000","2.60816","461.74475","2.67998","1.51981","0.01169","270.94009"
"157.20000","2.61839","461.92804","2.69020","1.53003","0.01174","271.04764"
"157.80000","2.62861","462.22958","2.70040","1.54023","0.01178","271.22458"
"158.40000","2.63815","462.02786","2.70995","1.54978","0.01182","271.10620"
"159.00000","2.64817","462.23938","2.71997","1.55979","0.01187","271.23032"
"159.60000","2.65836","462.35117","2.73015","1.56997","0.01191","271.29590"
"160.20000","2.66850","462.44870","2.74029","1.58011","0.01196","271.35315"
"160.80000","2.67813","462.25278","2.74992","1.58974","0.01200","271.23819"
"161.40000","2.68820","462.35992","2.75999","1.59981","0.01204","271.30106"
"162.00000","2.69844","462.50131","2.77022","1.61004","0.01209","271.38400"
"162.60000","2.70863","462.31525","2.78042","1.62024","0.01213","271.27484"
"163.20000","2.71809","462.07727","2.78989","1.62972","0.01217","271.13519"
"163.80000","2.72817","461.94141","2.79999","1.63981","0.01222","271.05548"
"164.40000","2.73839","461.77618","2.81021","1.65004","0.01226","270.95853"
"165.00000","2.74842","461.50983","2.82026","1.66008","0.01231","270.80225"
"165.60000","2.75813","461.06866","2.82999","1.66981","0.01235","270.54337"
"166.20000","2.76832","460.62460","2.84021","1.68003","0.01239","270.28281"
"166.80000","2.77851","460.17090","2.85042","1.69024","0.01244","270.01657"
"167.40000","2.78847","459.68829","2.86041","1.70024","0.01248","269.73340"
"168.00000","2.79809","458.82297","2.87008","1.70991","0.01252","269.22565"
"168.60000","2.80823","458.06473","2.88027","1.72009","0.01257","268.78073"
"169.20000","2.81843","457.45065","2.89050","1.73032","0.01261","268.42041"
"169.80000","2.82840","456.77438","2.90051","1.74033","0.01266","268.02359"
"170.40000","2.83814","456.06778","2.91029","1.75012","0.01270","267.60898"
"171.00000","2.84832","455.67416","2.92049","1.76032","0.01274","267.37802"
"171.60000","2.85859","455.35587","2.93078","1.77060","0.01279","267.19125"
"172.20000","2.86833","455.03519","2.94054","1.78036","0.01283","267.00308"
"172.80000","2.87809","454.75272","2.95031","1.79014","0.01287","266.83734"
"173.40000","2.88828","454.74689","2.96050","1.80032","0.01292","266.83392"
"174.00000","2.89854","454.80872","2.97076","1.81058","0.01296","266.87018"
"174.60000","2.90822","454.76047","2.98045","1.82027","0.01300","266.84189"
"175.20000","2.91815","454.82571","2.99037","1.83020","0.01305","266.88016"
"175.80000","2.92835","455.00272","3.00056","1.84038","0.01309","266.98404"
"176.40000","2.93863","455.37491","3.01082","1.85064","0.01314","267.20242"
"177.00000","2.94819","455.37222","3.02038","1.86020","0.01318","267.20084"
"177.60000","2.95817","455.47015","3.03035","1.87017","0.01322","267.25830"
"178.20000","2.96828","455.86188","3.04044","1.88026","0.01327","267.48816"
"178.80000","2.97846","456.11282","3.05061","1.89043","0.01331","267.63541"
"179.40000","2.98820","456.43692","3.06033","1.90015","0.01335","267.82559"
"180.00000","2.99824","456.62619","3.07036","1.91018","0.01340","267.93665"
"180.60000","3.00848","457.07004","3.08057","1.92040","0.01344","268.19708"
"181.20000","3.01861","457.49588","3.09068","1.93050","0.01349","268.44696"
"181.80000","3.02808","457.34830","3.10016","1.93998","0.01353","268.36035"
"182.40000","3.03819","457.77423","3.11024","1.95007","0.01357","268.61029"
"183.00000","3.04839","458.02664","3.12042","1.96025","0.01362","268.75839"
"183.60000","3.05843","458.20657","3.13045","1.97028","0.01366","268.86398"
"184.20000","3.06815","458.42490","3.14017","1.97999","0.01370","268.99207"
"184.80000","3.07827","458.57727","3.15027","1.99010","0.01375","269.08148"
"185.40000","3.08851","458.95270","3.16049","2.00032","0.01379","269.30179"
"186.00000","3.09846","459.02460","3.17044","2.01026","0.01383","269.34396"
"186.60000","3.10806","459.18124","3.18003","2.01985","0.01388","269.43588"
"187.20000","3.11820","459.37946","3.19016","2.02999","0.01392","269.55219"
"187.80000","3.12848","459.76691","3.20042","2.04024","0.01396","269.77954"
"188.40000","3.13835","459.96033","3.21027","2.05010","0.01401","269.89304"
"189.00000","3.14809","459.97253","3.22002","2.05984","0.01405","269.90018"
"189.60000","3.15832","460.44052","3.23022","2.07004","0.01409","270.17480"
"190.20000","3.16862","460.63065","3.24051","2.08033","0.01414","270.28635"
"190.80000","3.17833","460.68890","3.25021","2.09003","0.01418","270.32053"
"191.40000","3.18813","460.84784","3.26000","2.09983","0.01422","270.41379"
"192.00000","3.19826","461.16354","3.27012","2.10994","0.01427","270.59903"
"192.60000","3.20841","461.29041","3.28026","2.12008","0.01431","270.67349"
"193.20000","3.21820","461.44644","3.29004","2.12986","0.01436","270.76505"
"193.80000","3.22820","461.68027","3.30003","2.13985","0.01440","270.90225"
"194.40000","3.23837","461.89487","3.31019","2.15001","0.01444","271.02817"
"195.00000","3.24867","462.12762","3.32048","2.16030","0.01449","271.16473"
"195.60000","3.25823","462.18921","3.33002","2.16985","0.01453","271.20087"
"196.20000","3.26810","462.38959","3.33988","2.17971","0.01457","271.31845"
"196.80000","3.27829","462.55942","3.35007","2.18990","0.01462","271.41812"
"197.40000","3.28850","462.91910","3.36026","2.20008","0.01466","271.62915"
"198.00000","3.29819","462.78165","3.36995","2.20978","0.01470","271.54849"
"198.60000","3.30821","463.03775","3.37996","2.21978","0.01475","271.69879"
"199.20000","3.31849","463.28683","3.39023","2.23005","0.01479","271.84494"
"199.80000","3.32859","463.36264","3.40033","2.24015","0.01484","271.88940"
"200.40000","3.33811","463.23715","3.40985","2.24967","0.01488","271.81580"
"201.00000","3.34817","463.34531","3.41990","2.25972","0.01492","271.87924"
"201.60000","3.35837","463.49475","3.43009","2.26992","0.01497","271.96695"
"202.20000","3.36846","463.59906","3.44017","2.28000","0.01501","272.02814"
"202.80000","3.37810","463.35269","3.44983","2.28966","0.01505","271.88358"
"203.40000","3.38821","463.54611","3.45993","2.29976","0.01510","271.99707"
"204.00000","3.39852","463.69547","3.47023","2.31005","0.01514","272.08472"
"204.60000","3.40858","463.76324","3.48029","2.32011","0.01519","272.12448"
"205.20000","3.41808","463.62305","3.48980","2.32962","0.01523","272.04221"
"205.80000","3.42823","463.74835","3.49994","2.33977","0.01527","272.11575"
"206.40000","3.43842","463.80328","3.51013","2.34995","0.01532","272.14798"
"207.00000","3.44830","463.87115","3.52000","2.35983","0.01536","272.18781"
"207.60000","3.45814","463.82944","3.52985","2.36967","0.01540","272.16333"
"208.20000","3.46833","463.99667","3.54003","2.37985","0.01545","272.26144"
"208.80000","3.47856","464.11121","3.55025","2.39008","0.01549","272.32864"
"209.40000","3.48838","463.90250","3.56008","2.39990","0.01553","272.20618"
"210.00000","3.49812","463.66998","3.56984","2.40966","0.01558","272.06976"
"210.60000","3.50823","463.64731","3.57994","2.41977","0.01562","272.05646"
"211.20000","3.51843","463.52652","3.59015","2.42998","0.01567","271.98557"
"211.80000","3.52827","463.55560","3.59999","2.43982","0.01571","272.00266"
"212.40000","3.53816","463.44223","3.60989","2.44972","0.01575","271.93613"
"213.00000","3.54838","463.35049","3.62012","2.45994","0.01580","271.88229"
"213.60000","3.55865","463.60590","3.63037","2.47019","0.01584","272.03217"
"214.20000","3.56820","463.44836","3.63993","2.47975","0.01588","271.93973"
"214.80000","3.57813","463.35150","3.64986","2.48969","0.01593","271.88287"
"215.40000","3.58831","463.52310","3.66004","2.49986","0.01597","271.98358"
"216.00000","3.59854","463.70193","3.67025","2.51007","0.01601","272.08850"
"216.60000","3.60817","463.67096","3.67988","2.51971","0.01606","272.07034"
"217.20000","3.61817","463.85336","3.68988","2.52970","0.01610","272.17737"
"217.80000","3.62838","464.23395","3.70007","2.53989","0.01614","272.40067"
"218.40000","3.63867","464.32010","3.71034","2.55017","0.01619","272.45123"
"219.00000","3.64813","464.26901","3.71981","2.55963","0.01623","272.42126"
"219.60000","3.65822","464.43060","3.72989","2.56971","0.01628","272.51608"
"220.20000","3.66835","464.62180","3.74002","2.57984","0.01632","272.62827"
"220.80000","3.67842","464.85425","3.75007","2.58989","0.01636","272.76465"
"221.40000","3.68812","464.85406","3.75977","2.59959","0.01641","272.76456"
"222.00000","3.69826","465.02649","3.76990","2.60972","0.01645","272.86572"
"222.60000","3.70848","465.16772","3.78011","2.61993","0.01649","272.94861"
"223.20000","3.71858","465.54663","3.79019","2.63001","0.01654","273.17093"
"223.80000","3.72807","465.50409","3.79968","2.63950","0.01658","273.14597"
"224.40000","3.73824","465.64462","3.80984","2.64966","0.01662","273.22842"
"225.00000","3.74840","465.98538","3.81998","2.65981","0.01667","273.42838"
"225.60000","3.75835","466.06708","3.82993","2.66975","0.01671","273.47632"
"226.20000","3.76812","466.20178","3.83969","2.67952","0.01675","273.55536"
"226.80000","3.77832","466.33124","3.84988","2.68970","0.01680","273.63132"
"227.40000","3.78857","466.68130","3.86011","2.69993","0.01684","273.83673"
"228.00000","3.79834","466.67075","3.86989","2.70971","0.01689","273.83054"
"228.60000","3.80805","466.64066","3.87960","2.71942","0.01693","273.81287"
"229.20000","3.81824","466.87027","3.88977","2.72959","0.01697","273.94760"
"229.80000","3.82854","467.10797","3.90006","2.73988","0.01702","274.08710"
"230.40000","3.83829","467.22974","3.90980","2.74963","0.01706","274.15854"
"231.00000","3.84813","467.21912","3.91965","2.75947","0.01710","274.15231"
"231.60000","3.85835","467.33817","3.92986","2.76968","0.01715","274.22217"
"232.20000","3.86865","467.57410","3.94014","2.77997","0.01719","274.36060"
"232.80000","3.87819","467.53992","3.94968","2.78950","0.01723","274.34055"
"233.40000","3.88815","467.65021","3.95964","2.79947","0.01728","274.40524"
"234.00000","3.89835","467.81259","3.96983","2.80965","0.01732","274.50055"
"234.60000","3.90849","468.01633","3.97996","2.81978","0.01737","274.62009"
"235.20000","3.91819","468.06165","3.98965","2.82948","0.01741","274.64667"
"235.80000","3.92821","468.18008","3.99967","2.83949","0.01745","274.71619"
"236.40000","3.93842","468.45419","4.00986","2.84968","0.01750","274.87701"
"237.00000","3.94864","468.53293","4.02007","2.85990","0.01754","274.92322"
"237.60000","3.95818","468.44147","4.02962","2.86945","0.01758","274.86954"
"238.20000","3.96816","468.53464","4.03960","2.87942","0.01763","274.92422"
"238.80000","3.97833","468.71481","4.04975","2.88958","0.01767","275.02994"
"239.40000","3.98848","468.88412","4.05990","2.89972","0.01772","275.12927"
"240.00000","3.99817","468.74591","4.06959","2.90942","0.01776","275.04819"
"240.60000","4.00821","468.86935","4.07963","2.91946","0.01780","275.12061"
"241.20000","4.01852","469.08060","4.08993","2.92975","0.01785","275.24457"
"241.80000","4.02857","469.09174","4.09997","2.93980","0.01789","275.25110"
"242.40000","4.03806","468.92654","4.10947","2.94930","0.01793","275.15417"
"243.00000","4.04817","469.02731","4.11958","2.95941","0.01798","275.21332"
"243.60000","4.05844","469.12247","4.12985","2.96967","0.01802","275.26913"
"244.20000","4.06840","469.20236","4.13980","2.97963","0.01806","275.31601"
"244.80000","4.07814","469.03970","4.14955","2.98938","0.01811","275.22058"
"245.40000","4.08829","469.05246","4.15970","2.99952","0.01815","275.22806"
"246.00000","4.09854","469.16782","4.16994","3.00977","0.01820","275.29575"
"246.60000","4.10841","469.38974","4.17980","3.01962","0.01824","275.42596"
"247.20000","4.11811","469.23239","4.18950","3.02933","0.01828","275.33365"
"247.80000","4.12825","469.29279","4.19964","3.03947","0.01832","275.36908"
"248.40000","4.13850","469.34244","4.20989","3.04972","0.01837","275.39822"
"249.00000","4.14829","469.17633","4.21969","3.05951","0.01841","275.30075"
"249.60000","4.15816","469.19073","4.22956","3.06939","0.01846","275.30920"
"250.20000","4.16838","469.04092","4.23979","3.07962","0.01850","275.22128"
"250.80000","4.17861","469.12491","4.25001","3.08984","0.01854","275.27057"
"251.40000","4.18822","468.99225","4.25963","3.09945","0.01859","275.19272"
"252.00000","4.19812","468.84451","4.26954","3.10937","0.01863","275.10605"
"252.60000","4.20830","468.85391","4.27972","3.11955","0.01867","275.11154"
"253.20000","4.21841","468.87253","4.28983","3.12965","0.01872","275.12247"
"253.80000","4.22823","468.50903","4.29966","3.13949","0.01876","274.90918"
"254.40000","4.23822","468.35236","4.30967","3.14950","0.01880","274.81726"
"255.00000","4.24841","468.08167","4.31987","3.15969","0.01885","274.65842"
"255.60000","4.25864","467.88184","4.33011","3.16994","0.01889","274.54117"
"256.20000","4.26817","467.46848","4.33967","3.17949","0.01894","274.29861"
"256.80000","4.27811","466.95297","4.34964","3.18946","0.01898","273.99612"
"257.40000","4.28832","466.44919","4.35988","3.19970","0.01902","273.70053"
"258.00000","4.29853","465.90845","4.37012","3.20994","0.01907","273.38324"
"258.60000","4.30813","464.99634","4.37977","3.21959","0.01911","272.84802"
"259.20000","4.31824","464.45044","4.38991","3.22973","0.01916","272.52771"
"259.80000","4.32852","463.82617","4.40023","3.24005","0.01920","272.16141"
"260.40000","4.33858","463.20404","4.41032","3.25015","0.01924","271.79636"
"261.00000","4.34809","462.39304","4.41987","3.25970","0.01929","271.32047"
"261.60000","4.35823","461.90970","4.43004","3.26986","0.01933","271.03687"
"262.20000","4.36838","461.57260","4.44022","3.28004","0.01937","270.83908"
"262.80000","4.37837","461.24817","4.45022","3.29005","0.01942","270.64871"
"263.40000","4.38815","460.88571","4.46003","3.29985","0.01946","270.43600"
"264.00000","4.39830","460.58591","4.47019","3.31001","0.01951","270.26010"
"264.60000","4.40857","459.97879","4.48050","3.32032","0.01955","269.90387"
"265.20000","4.41847","459.76984","4.49041","3.33023","0.01959","269.78125"
"265.80000","4.42808","459.38171","4.50004","3.33987","0.01964","269.55350"
"266.40000","4.43821","459.12149","4.51019","3.35001","0.01968","269.40082"
"267.00000","4.44849","459.08984","4.52046","3.36029","0.01972","269.38226"
"267.60000","4.45826","458.93927","4.53025","3.37007","0.01977","269.29388"
"268.20000","4.46816","458.66211","4.54016","3.37999","0.01981","269.13126"
"268.80000","4.47837","458.72604","4.55036","3.39019","0.01986","269.16879"
"269.40000","4.48864","458.62640","4.56064","3.40046","0.01990","269.11032"
"270.00000","4.49825","458.42590","4.57026","3.41009","0.01994","268.99268"
"270.60000","4.50813","458.29327","4.58015","3.41998","0.01999","268.91486"
"271.20000","4.51825","458.13727","4.59027","3.43010","0.02003","268.82330"
"271.80000","4.52850","458.08411","4.60053","3.44035","0.02007","268.79211"
"272.40000","4.53821","457.96716","4.61025","3.45007","0.02012","268.72348"
"273.00000","4.54816","457.94354","4.62020","3.46003","0.02016","268.70963"
"273.60000","4.55840","457.98062","4.63044","3.47026","0.02020","268.73138"
"274.20000","4.56869","458.24042","4.64071","3.48054","0.02025","268.88382"
"274.80000","4.57815","457.91214","4.65019","3.49002","0.02029","268.69119"
"275.40000","4.58815","458.01392","4.66019","3.50001","0.02033","268.75092"
"276.00000","4.59837","458.15836","4.67039","3.51022","0.02038","268.83566"
"276.60000","4.60850","458.29526","4.68052","3.52034","0.02042","268.91602"
"277.20000","4.61814","458.17099","4.69017","3.52999","0.02047","268.84308"
"277.80000","4.62824","458.37601","4.70026","3.54008","0.02051","268.96338"
"278.40000","4.63847","458.53217","4.71048","3.55030","0.02055","269.05502"
"279.00000","4.64859","458.73605","4.72059","3.56041","0.02060","269.17465"
"279.60000","4.65814","458.65155","4.73014","3.56996","0.02064","269.12506"
"280.20000","4.66819","458.76294","4.74018","3.58001","0.02068","269.19043"
"280.80000","4.67832","458.93848","4.75030","3.59012","0.02073","269.29343"
"281.40000","4.68837","459.16028","4.76035","3.60017","0.02077","269.42358"
"282.00000","4.69815","459.26730","4.77011","3.60994","0.02081","269.48639"
"282.60000","4.70830","459.20935","4.78027","3.62009","0.02086","269.45236"
"283.20000","4.71856","459.46591","4.79051","3.63034","0.02090","269.60291"
"283.80000","4.72847","459.64880","4.80041","3.64024","0.02095","269.71024"
"284.40000","4.73806","459.47287","4.81002","3.64984","0.02099","269.60699"
"285.00000","4.74821","459.73007","4.82015","3.65997","0.02103","269.75790"
"285.60000","4.75849","459.97388","4.83042","3.67024","0.02108","269.90097"
"286.20000","4.76833","459.96524","4.84026","3.68008","0.02112","269.89590"
"286.80000","4.77812","459.84937","4.85006","3.68988","0.02116","269.82791"
"287.40000","4.78832","459.89499","4.86025","3.70008","0.02121","269.85468"
"288.00000","4.79858","460.14328","4.87050","3.71032","0.02125","270.00037"
"288.60000","4.80824","459.87192","4.88017","3.71999","0.02129","269.84116"
"289.20000","4.81810","459.77844","4.89004","3.72986","0.02134","269.78632"
"289.80000","4.82831","459.89352","4.90024","3.74006","0.02138","269.85382"
"290.40000","4.83852","459.93240","4.91045","3.75027","0.02143","269.87665"
"291.00000","4.84819","459.56342","4.92014","3.75997","0.02147","269.66013"
"291.60000","4.85814","459.24075","4.93011","3.76993","0.02151","269.47079"
"292.20000","4.86836","459.05057","4.94034","3.78017","0.02156","269.35919"
"292.80000","4.87869","459.04541","4.95067","3.79050","0.02160","269.35617"
"293.40000","4.88817","458.52917","4.96018","3.80000","0.02164","269.05325"
"294.00000","4.89816","458.03235","4.97019","3.81002","0.02169","268.76175"
"294.60000","4.90833","457.67798","4.98039","3.82021","0.02173","268.55380"
"295.20000","4.91847","457.26834","4.99055","3.83037","0.02178","268.31345"
"295.80000","4.92815","456.81796","5.00025","3.84008","0.02182","268.04916"
"296.40000","4.93826","456.48157","5.01039","3.85021","0.02186","267.85178"
"297.00000","4.94843","456.16348","5.02057","3.86039","0.02191","267.66513"
"297.60000","4.95861","456.02298","5.03076","3.87058","0.02195","267.58270"
"298.20000","4.96812","455.50070","5.04030","3.88013","0.02199","267.27625"
"298.80000","4.97818","455.20886","5.05037","3.89020","0.02204","267.10498"
"299.40000","4.98836","455.05276","5.06057","3.90039","0.02208","267.01340"
"300.00000","4.99849","455.02380","5.07070","3.91052","0.02213","266.99640"
"300.60000","5.00815","454.68890","5.08038","3.92020","0.02217","266.79990"
"301.20000","5.01827","454.71402","5.09049","3.93032","0.02221","266.81464"
"301.80000","5.02852","454.68771","5.10074","3.94057","0.02226","266.79919"
"302.40000","5.03846","454.71600","5.11068","3.95051","0.02230","266.81580"
"303.00000","5.04806","454.37851","5.12031","3.96013","0.02234","266.61777"
"303.60000","5.05824","454.43616","5.13048","3.97030","0.02239","266.65158"
"304.20000","5.06847","454.41696","5.14072","3.98054","0.02243","266.64032"
"304.80000","5.07830","454.31439","5.15054","3.99037","0.02247","266.58014"
"305.40000","5.08813","454.09659","5.16039","4.00021","0.02252","266.45233"
"306.00000","5.09830","453.07925","5.17062","4.01045","0.02256","265.85538"
"306.60000","5.10858","452.92917","5.18091","4.02073","0.02261","265.76733"
"307.20000","5.11832","452.45477","5.19067","4.03050","0.02265","265.48895"
"307.80000","5.12810","452.28693","5.20046","4.04028","0.02269","265.39047"
"308.40000","5.13825","452.09369","5.21063","4.05045","0.02274","265.27707"
"309.00000","5.14849","452.11069","5.22087","4.06069","0.02278","265.28705"
"309.60000","5.15826","452.10822","5.23064","4.07046","0.02282","265.28561"
"310.20000","5.16819","451.89514","5.24057","4.08040","0.02287","265.16058"
"310.80000","5.17843","452.06161","5.25080","4.09063","0.02291","265.25827"
"311.40000","5.18863","452.21658","5.26099","4.10082","0.02296","265.34918"
"312.00000","5.19817","452.10574","5.27054","4.11037","0.02300","265.28415"
"312.60000","5.20813","452.21503","5.28050","4.12032","0.02304","265.34827"
"313.20000","5.21831","452.35065","5.29067","4.13050","0.02309","265.42786"
"313.80000","5.22848","452.52032","5.30083","4.14065","0.02313","265.52744"
"314.40000","5.23822","452.38602","5.31057","4.15040","0.02317","265.44861"
"315.00000","5.24820","452.46338","5.32056","4.16038","0.02322","265.49402"
"315.60000","5.25845","452.80344","5.33078","4.17060","0.02326","265.69354"
"316.20000","5.26858","452.85541","5.34091","4.18074","0.02330","265.72403"
"316.80000","5.27809","452.84372","5.35042","4.19025","0.02335","265.71719"
"317.40000","5.28816","452.77304","5.36049","4.20031","0.02339","265.67572"
"318.00000","5.29840","452.98203","5.37073","4.21055","0.02343","265.79834"
"318.60000","5.30845","453.07834","5.38077","4.22059","0.02348","265.85486"
"319.20000","5.31810","453.11154","5.39042","4.23024","0.02352","265.87433"
"319.80000","5.32828","453.20142","5.40059","4.24041","0.02357","265.92706"
"320.40000","5.33853","453.47375","5.41082","4.25064","0.02361","266.08688"
"321.00000","5.34847","453.60596","5.42076","4.26058","0.02365","266.16446"
"321.60000","5.35811","453.67676","5.43039","4.27021","0.02370","266.20599"
"322.20000","5.36823","453.74203","5.44051","4.28033","0.02374","266.24429"
"322.80000","5.37836","453.99493","5.45062","4.29045","0.02378","266.39270"
"323.40000","5.38828","454.04242","5.46055","4.30037","0.02383","266.42056"
"324.00000","5.39818","454.18848","5.47044","4.31026","0.02387","266.50626"
"324.60000","5.40834","454.23508","5.48060","4.32042","0.02391","266.53360"
"325.20000","5.41864","454.58157","5.49087","4.33069","0.02396","266.73691"
"325.80000","5.42837","454.59488","5.50060","4.34043","0.02400","266.74472"
"326.40000","5.43804","454.37793","5.51029","4.35011","0.02404","266.61743"
"327.00000","5.44826","454.68463","5.52049","4.36031","0.02409","266.79739"
"327.60000","5.45850","454.80463","5.53072","4.37055","0.02413","266.86780"
"328.20000","5.46825","454.78287","5.54047","4.38030","0.02418","266.85501"
"328.80000","5.47816","454.79251","5.55038","4.39021","0.02422","266.86069"
"329.40000","5.48842","454.90103","5.56063","4.40046","0.02426","266.92435"
"330.00000","5.49861","455.14935","5.57081","4.41063","0.02431","267.07007"
"330.60000","5.50819","455.04742","5.58040","4.42022","0.02435","267.01025"
"331.20000","5.51812","455.02802","5.59033","4.43015","0.02439","266.99887"
"331.80000","5.52830","455.12527","5.60050","4.44032","0.02444","267.05594"
"332.40000","5.53853","455.11633","5.61074","4.45056","0.02448","267.05069"
"333.00000","5.54816","455.16965","5.62036","4.46019","0.02452","267.08197"
"333.60000","5.55816","455.06558","5.63036","4.47019","0.02457","267.02090"
"334.20000","5.56842","455.13864","5.64063","4.48045","0.02461","267.06378"
"334.80000","5.57866","455.22415","5.65086","4.49068","0.02466","267.11395"
"335.40000","5.58810","454.97519","5.66031","4.50013","0.02470","266.96786"
"336.00000","5.59820","455.05133","5.67040","4.51023","0.02474","267.01254"
"336.60000","5.60836","454.77118","5.68058","4.52040","0.02479","266.84818"
"337.20000","5.61839","454.88327","5.69060","4.53043","0.02483","266.91394"
"337.80000","5.62815","454.63629","5.70038","4.54020","0.02487","266.76901"
"338.40000","5.63830","454.45636","5.71054","4.55037","0.02492","266.66345"
"339.00000","5.64850","454.45740","5.72074","4.56056","0.02496","266.66406"
"339.60000","5.65854","454.29230","5.73079","4.57062","0.02501","266.56717"
"340.20000","5.66810","454.01370","5.74036","4.58019","0.02505","266.40369"
"340.80000","5.67818","453.82529","5.75046","4.59028","0.02509","266.29315"
"341.40000","5.68841","453.67117","5.76069","4.60051","0.02514","266.20270"
"342.00000","5.69838","453.59302","5.77067","4.61050","0.02518","266.15686"
"342.60000","5.70815","453.17831","5.78046","4.62028","0.02522","265.91351"
"343.20000","5.71831","453.08121","5.79063","4.63045","0.02527","265.85654"
"343.80000","5.72862","453.00983","5.80094","4.64076","0.02531","265.81464"
"344.40000","5.73835","452.59207","5.81069","4.65052","0.02535","265.56952"
"345.00000","5.74811","452.33780","5.82047","4.66029","0.02540","265.42032"
"345.60000","5.75825","452.25681","5.83061","4.67043","0.02544","265.37280"
"346.20000","5.76851","452.26324","5.84087","4.68070","0.02549","265.37659"
"346.80000","5.77826","452.14874","5.85063","4.69045","0.02553","265.30939"
"347.40000","5.78813","451.83469","5.86052","4.70034","0.02557","265.12512"
"348.00000","5.79832","451.80917","5.87071","4.71053","0.02562","265.11014"
"348.60000","5.80867","451.93597","5.88106","4.72088","0.02566","265.18454"
"349.20000","5.81824","451.71613","5.89064","4.73046","0.02570","265.05554"
"349.80000","5.82816","451.65704","5.90056","4.74039","0.02575","265.02087"
"350.40000","5.83830","451.52875","5.91070","4.75053","0.02579","264.94559"
"351.00000","5.84847","451.52707","5.92088","4.76070","0.02584","264.94461"
"351.60000","5.85815","451.13199","5.93058","4.77040","0.02588","264.71277"
"352.20000","5.86822","450.95697","5.94066","4.78049","0.02592","264.61008"
"352.80000","5.87844","450.64975","5.95090","4.79072","0.02597","264.42981"
"353.40000","5.88862","450.53665","5.96109","4.80091","0.02601","264.36346"
"354.00000","5.89811","450.09857","5.97060","4.81042","0.02605","264.10641"
"354.60000","5.90821","450.04724","5.98070","4.82052","0.02610","264.07629"
"355.20000","5.91832","449.76642","5.99082","4.83065","0.02614","263.91150"
"355.80000","5.92840","449.54828","6.00092","4.84075","0.02618","263.78351"
"356.40000","5.93814","449.21408","6.01068","4.85050","0.02623","263.58740"
"357.00000","5.94826","449.02124","6.02081","4.86063","0.02627","263.47424"
"357.60000","5.95851","449.02573","6.03105","4.87088","0.02632","263.47687"
"358.20000","5.96850","448.87750","6.04106","4.88088","0.02636","263.38989"
"358.80000","5.97804","448.48904","6.05062","4.89045","0.02640","263.16196"
"359.40000","5.98820","448.37701","6.06078","4.90061","0.02645","263.09622"
"360.00000","5.99848","448.21426","6.07107","4.91090","0.02649","263.00073"
"360.60000","6.00842","448.05719","6.08102","4.92085","0.02653","262.90857"
"361.20000","6.01812","447.83264","6.09074","4.93056","0.02658","262.77679"
"361.80000","6.02829","447.52277","6.10092","4.94074","0.02662","262.59497"
"362.40000","6.03858","447.55954","6.11121","4.95103","0.02667","262.61655"
"363.00000","6.04837","447.15442","6.12102","4.96085","0.02671","262.37885"
"363.60000","6.05811","446.80103","6.13079","4.97061","0.02675","262.17148"
"364.20000","6.06830","446.60876","6.14099","4.98081","0.02680","262.05865"
"364.80000","6.07847","446.26926","6.15117","4.99100","0.02684","261.85947"
"365.40000","6.08826","445.83386","6.16099","5.00082","0.02688","261.60397"
"366.00000","6.09815","445.44702","6.17091","5.01073","0.02693","261.37698"
"366.60000","6.10836","445.10852","6.18113","5.02095","0.02697","261.17838"
"367.20000","6.11862","444.78574","6.19141","5.03124","0.02702","260.98895"
"367.80000","6.12831","443.34344","6.20118","5.04101","0.02706","260.14267"
"368.40000","6.13813","442.40475","6.21106","5.05088","0.02710","259.59186"
"369.00000","6.14828","441.58478","6.22125","5.06108","0.02715","259.11072"
"369.60000","6.15848","441.00537","6.23149","5.07131","0.02719","258.77075"
"370.20000","6.16820","440.33267","6.24124","5.08107","0.02723","258.37601"
"370.80000","6.17817","439.76569","6.25125","5.09107","0.02728","258.04333"
"371.40000","6.18845","439.38168","6.26154","5.10137","0.02732","257.81799"
"372.00000","6.19862","439.00284","6.27174","5.11157","0.02737","257.59570"
"372.60000","6.20812","438.44284","6.28127","5.12110","0.02741","257.26712"
"373.20000","6.21815","438.06467","6.29132","5.13115","0.02745","257.04520"
"373.80000","6.22835","437.75775","6.30154","5.14137","0.02750","256.86511"
"374.40000","6.23850","437.56528","6.31170","5.15152","0.02754","256.75217"
"375.00000","6.24813","437.19885","6.32136","5.16118","0.02758","256.53717"
"375.60000","6.25823","436.89133","6.33147","5.17129","0.02763","256.35672"
"376.20000","6.26847","436.08719","6.34176","5.18158","0.02767","255.88487"
"376.80000","6.27858","435.65833","6.35189","5.19171","0.02772","255.63322"
"377.40000","6.28808","434.80234","6.36144","5.20126","0.02776","255.13095"
"378.00000","6.29821","434.04745","6.37161","5.21144","0.02780","254.68802"
"378.60000","6.30845","433.05801","6.38191","5.22173","0.02785","254.10744"
"379.20000","6.31839","430.38208","6.39200","5.23182","0.02789","252.53726"
"379.80000","6.32814","428.17810","6.40187","5.24170","0.02793","251.24402"
"380.40000","6.33833","426.76767","6.41214","5.25197","0.02798","250.41641"
"381.00000","6.34856","425.66144","6.42244","5.26226","0.02802","249.76730"
"381.60000","6.35838","424.32272","6.43234","5.27216","0.02807","248.98178"
"381.92500","6.36370","389.82077","6.43963","5.27945","0.02810","228.73692"
"382.15400","6.36739","338.35172","6.44662","5.28644","0.02813","198.53618"
"382.75400","6.37760","333.53925","6.45715","5.29697","0.02818","195.71236"
"383.35400","6.38762","332.12689","6.46726","5.30709","0.02822","194.88362"
"383.95400","6.39740","331.69730","6.47707","5.31689","0.02826","194.63155"
"384.55400","6.40750","331.33298","6.48720","5.32702","0.02831","194.41777"
"385.15400","6.41773","331.69397","6.49741","5.33723","0.02835","194.62959"
"385.75400","6.42780","331.89471","6.50746","5.34728","0.02839","194.74738"
"385.80600","6.42874","331.96475","6.50840","5.34822","0.02840","194.78848"