File: flexion/3_axis/Specimen_RawData_1.csv
Specimen properties : Specimen label,"1"
Specimen properties : Support span,"72.00",mm
Specimen properties : Thickness,"3.83",mm
Specimen properties : Width,"13.06",mm
Maximum Load : Maximum Load,"519.6",N
Tangent Modulus of Elasticity : Tangent Modulus of Elasticity,"36649648264.07330",Pa
Test : Rate 1,"1.00000",mm/min
Specimen notes : Specimen note 1,""

Time,Displacement,Load,Flexure extension,Corrected extension,Flexure strain (Corrected extension),Flexure stress
(s),(mm),(N),(mm),(mm),(mm/mm),(MPa)
"0.00000","0.00000","45.15676","0.15840","-1.05505","0.00070","25.45691"
"0.40000","0.00478","46.51018","0.16299","-1.05045","0.00072","26.21990"
"0.80000","0.01131","48.62675","0.16924","-1.04421","0.00075","27.41311"
"1.20000","0.01798","50.66651","0.17564","-1.03780","0.00078","28.56301"
"1.60000","0.02495","52.59763","0.18235","-1.03110","0.00081","29.65167"
"2.00000","0.03170","54.51914","0.18885","-1.02460","0.00084","30.73492"
"2.40000","0.03835","56.44392","0.19524","-1.01821","0.00087","31.82000"
"2.80000","0.04478","58.16729","0.20145","-1.01200","0.00089","32.79155"
"3.20000","0.05137","59.85618","0.20783","-1.00562","0.00092","33.74365"
"3.60000","0.05799","61.84485","0.21422","-0.99923","0.00095","34.86475"
"4.00000","0.06485","63.71194","0.22087","-0.99258","0.00098","35.91732"
"4.40000","0.07188","65.72136","0.22766","-0.98579","0.00101","37.05011"
"4.80000","0.07828","67.34076","0.23387","-0.97958","0.00104","37.96304"
"5.20000","0.08494","69.26366","0.24031","-0.97314","0.00107","39.04707"
"5.60000","0.09137","71.08018","0.24652","-0.96693","0.00109","40.07113"
"6.00000","0.09801","73.02911","0.25293","-0.96052","0.00112","41.16983"
"6.40000","0.10478","74.80547","0.25949","-0.95396","0.00115","42.17124"
"6.80000","0.11166","76.72261","0.26615","-0.94729","0.00118","43.25202"
"7.20000","0.11842","78.73919","0.27268","-0.94077","0.00121","44.38886"
"7.60000","0.12484","80.36523","0.27891","-0.93454","0.00124","45.30553"
"8.00000","0.13149","82.16478","0.28534","-0.92811","0.00126","46.32002"
"8.40000","0.13799","84.01105","0.29162","-0.92182","0.00129","47.36084"
"8.80000","0.14479","86.00896","0.29820","-0.91525","0.00132","48.48716"
"9.20000","0.15177","87.97892","0.30496","-0.90849","0.00135","49.59771"
"9.60000","0.15830","89.81226","0.31131","-0.90214","0.00138","50.63125"
"10.00000","0.16494","91.64472","0.31777","-0.89568","0.00141","51.66429"
"10.40000","0.17140","93.45814","0.32406","-0.88939","0.00144","52.68660"
"10.80000","0.17804","95.15798","0.33052","-0.88293","0.00147","53.64488"
"11.20000","0.18473","97.15260","0.33702","-0.87643","0.00149","54.76934"
"11.60000","0.19170","99.12718","0.34379","-0.86965","0.00152","55.88250"
"12.00000","0.19851","100.95810","0.35043","-0.86302","0.00155","56.91467"
"12.40000","0.20486","102.73694","0.35660","-0.85684","0.00158","57.91748"
"12.80000","0.21148","104.51584","0.36305","-0.85040","0.00161","58.92033"
"13.20000","0.21800","106.49352","0.36938","-0.84407","0.00164","60.03524"
"13.60000","0.22467","108.25140","0.37588","-0.83757","0.00167","61.02623"
"14.00000","0.23164","110.30572","0.38264","-0.83080","0.00170","62.18435"
"14.40000","0.23840","112.13760","0.38923","-0.82422","0.00173","63.21706"
"14.80000","0.24506","114.05473","0.39570","-0.81775","0.00175","64.29784"
"15.20000","0.25146","115.84937","0.40192","-0.81153","0.00178","65.30955"
"15.60000","0.25802","117.62517","0.40831","-0.80514","0.00181","66.31065"
"16.00000","0.26463","119.53159","0.41473","-0.79871","0.00184","67.38538"
"16.40000","0.27148","121.30682","0.42141","-0.79204","0.00187","68.38616"
"16.80000","0.27856","123.47530","0.42828","-0.78517","0.00190","69.60863"
"17.20000","0.28493","125.07541","0.43449","-0.77896","0.00193","70.51069"
"17.60000","0.29153","126.88241","0.44091","-0.77254","0.00195","71.52937"
"18.00000","0.29809","128.82968","0.44728","-0.76616","0.00198","72.62714"
"18.40000","0.30469","130.68248","0.45370","-0.75975","0.00201","73.67165"
"18.80000","0.31148","132.50629","0.46032","-0.75313","0.00204","74.69981"
"19.20000","0.31833","134.30708","0.46699","-0.74646","0.00207","75.71500"
"19.60000","0.32511","136.31985","0.47358","-0.73987","0.00210","76.84969"
"20.00000","0.33145","137.91794","0.47977","-0.73368","0.00213","77.75060"
"20.40000","0.33814","139.86324","0.48626","-0.72719","0.00216","78.84726"
"20.80000","0.34462","141.55933","0.49258","-0.72087","0.00218","79.80342"
"21.20000","0.35146","143.46762","0.49923","-0.71422","0.00221","80.87921"
"21.60000","0.35850","145.53960","0.50607","-0.70738","0.00224","82.04728"
"22.00000","0.36503","147.19812","0.51244","-0.70101","0.00227","82.98227"
"22.40000","0.37165","149.01964","0.51889","-0.69456","0.00230","84.00914"
"22.80000","0.37810","150.94983","0.52514","-0.68831","0.00233","85.09727"
"23.20000","0.38471","152.57008","0.53159","-0.68185","0.00236","86.01069"
"23.60000","0.39136","154.42772","0.53807","-0.67538","0.00239","87.05792"
"24.00000","0.39825","156.31230","0.54477","-0.66868","0.00241","88.12035"
"24.40000","0.40517","158.29504","0.55151","-0.66194","0.00244","89.23811"
"24.80000","0.41154","159.90581","0.55774","-0.65570","0.00247","90.14616"
"25.20000","0.41818","161.81778","0.56422","-0.64923","0.00250","91.22403"
"25.60000","0.42469","163.57913","0.57058","-0.64287","0.00253","92.21699"
"26.00000","0.43141","165.43501","0.57714","-0.63631","0.00256","93.26323"
"26.40000","0.43831","167.29956","0.58388","-0.62957","0.00259","94.31436"
"26.80000","0.44504","169.09433","0.59046","-0.62299","0.00262","95.32616"
"27.20000","0.45167","170.90199","0.59694","-0.61651","0.00265","96.34521"
"27.60000","0.45811","172.54454","0.60323","-0.61021","0.00267","97.27119"
"28.00000","0.46469","174.42853","0.60965","-0.60379","0.00270","98.33328"
"28.40000","0.47129","176.19244","0.61610","-0.59735","0.00273","99.32768"
"28.80000","0.47823","178.15242","0.62288","-0.59057","0.00276","100.43261"
"29.20000","0.48522","180.08580","0.62971","-0.58374","0.00279","101.52254"
"29.60000","0.49163","181.66762","0.63598","-0.57746","0.00282","102.41429"
"30.00000","0.49819","183.40224","0.64239","-0.57106","0.00285","103.39217"
"30.40000","0.50471","185.18358","0.64876","-0.56469","0.00288","104.39639"
"30.80000","0.51131","186.94627","0.65521","-0.55823","0.00290","105.39011"
"31.20000","0.51814","188.84032","0.66188","-0.55157","0.00293","106.45786"
"31.60000","0.52501","190.77689","0.66859","-0.54486","0.00296","107.54960"
"32.00000","0.53176","192.46538","0.67519","-0.53826","0.00299","108.50147"
"32.40000","0.53820","194.16547","0.68148","-0.53196","0.00302","109.45989"
"32.80000","0.54478","195.87004","0.68792","-0.52552","0.00305","110.42084"
"33.20000","0.55131","197.53166","0.69431","-0.51914","0.00308","111.35757"
"33.60000","0.55810","199.46051","0.70094","-0.51251","0.00311","112.44495"
"34.00000","0.56514","201.32495","0.70782","-0.50562","0.00314","113.49602"
"34.40000","0.57159","203.03159","0.71414","-0.49931","0.00317","114.45813"
"34.80000","0.57826","204.78439","0.72067","-0.49278","0.00319","115.44627"
"35.20000","0.58475","206.55528","0.72701","-0.48644","0.00322","116.44460"
"35.60000","0.59139","208.26820","0.73352","-0.47993","0.00325","117.41025"
"36.00000","0.59808","209.95352","0.74007","-0.47338","0.00328","118.36034"
"36.40000","0.60492","211.71938","0.74677","-0.46668","0.00331","119.35583"
"36.80000","0.61186","213.56209","0.75356","-0.45989","0.00334","120.39465"
"37.20000","0.61819","215.23836","0.75976","-0.45369","0.00337","121.33964"
"37.60000","0.62484","216.93788","0.76627","-0.44718","0.00340","122.29774"
"38.00000","0.63127","218.62648","0.77256","-0.44089","0.00342","123.24968"
"38.40000","0.63805","220.38655","0.77921","-0.43424","0.00345","124.24191"
"38.80000","0.64504","222.19484","0.78605","-0.42740","0.00348","125.26132"
"39.20000","0.65172","224.02563","0.79258","-0.42087","0.00351","126.29343"
"39.60000","0.65837","225.67029","0.79910","-0.41435","0.00354","127.22059"
"40.00000","0.66475","227.16769","0.80536","-0.40808","0.00357","128.06474"
"40.40000","0.67138","228.97006","0.81185","-0.40160","0.00360","129.08083"
"40.80000","0.67794","230.67213","0.81828","-0.39517","0.00363","130.04036"
"41.20000","0.68489","232.50172","0.82507","-0.38838","0.00366","131.07178"
"41.60000","0.69181","234.27266","0.83186","-0.38159","0.00369","132.07014"
"42.00000","0.69830","235.81825","0.83822","-0.37523","0.00372","132.94147"
"42.40000","0.70487","237.51807","0.84465","-0.36879","0.00374","133.89972"
"42.80000","0.71134","239.11237","0.85100","-0.36245","0.00377","134.79851"
"43.20000","0.71801","240.88057","0.85753","-0.35592","0.00380","135.79532"
"43.60000","0.72481","242.57260","0.86419","-0.34926","0.00383","136.74919"
"44.00000","0.73171","244.38023","0.87095","-0.34250","0.00386","137.76823"
"44.40000","0.73840","245.88295","0.87752","-0.33592","0.00389","138.61539"
"44.80000","0.74484","247.58984","0.88384","-0.32961","0.00392","139.57764"
"45.20000","0.75138","249.11887","0.89026","-0.32319","0.00395","140.43962"
"45.60000","0.75796","250.78784","0.89670","-0.31674","0.00397","141.38049"
"46.00000","0.76474","252.53450","0.90336","-0.31009","0.00400","142.36517"
"46.40000","0.77187","254.35675","0.91034","-0.30311","0.00404","143.39246"
"46.80000","0.77837","255.87924","0.91673","-0.29672","0.00406","144.25075"
"47.20000","0.78491","257.54483","0.92314","-0.29031","0.00409","145.18971"
"47.60000","0.79142","259.00681","0.92953","-0.28392","0.00412","146.01390"
"48.00000","0.79803","260.65997","0.93602","-0.27743","0.00415","146.94586"
"48.40000","0.80470","262.21341","0.94257","-0.27088","0.00418","147.82161"
"48.80000","0.81157","263.89725","0.94931","-0.26413","0.00421","148.77086"
"49.20000","0.81848","265.67685","0.95609","-0.25736","0.00424","149.77411"
"49.60000","0.82486","267.16168","0.96235","-0.25110","0.00427","150.61118"
"50.00000","0.83153","268.79657","0.96889","-0.24456","0.00429","151.53284"
"50.40000","0.83800","270.29449","0.97525","-0.23820","0.00432","152.37729"
"50.80000","0.84468","271.87747","0.98181","-0.23164","0.00435","153.26968"
"51.20000","0.85171","273.54721","0.98871","-0.22474","0.00438","154.21098"
"51.60000","0.85829","275.17285","0.99516","-0.21829","0.00441","155.12744"
"52.00000","0.86498","276.78934","1.00173","-0.21172","0.00444","156.03873"
"52.40000","0.87141","278.30807","1.00805","-0.20540","0.00447","156.89490"
"52.80000","0.87808","279.86429","1.01459","-0.19886","0.00450","157.77222"
"53.20000","0.88466","281.45450","1.02105","-0.19240","0.00453","158.66869"
"53.60000","0.89157","283.12686","1.02784","-0.18561","0.00456","159.61147"
"54.00000","0.89851","284.80280","1.03465","-0.17880","0.00459","160.55627"
"54.40000","0.90490","286.11618","1.04094","-0.17251","0.00461","161.29669"
"54.80000","0.91153","287.77219","1.04744","-0.16601","0.00464","162.23026"
"55.20000","0.91798","289.20068","1.05378","-0.15966","0.00467","163.03557"
"55.60000","0.92471","290.73212","1.06039","-0.15306","0.00470","163.89890"
"56.00000","0.93152","292.38315","1.06710","-0.14635","0.00473","164.82967"
"56.40000","0.93840","293.96490","1.07387","-0.13957","0.00476","165.72137"
"56.80000","0.94506","295.46732","1.08043","-0.13302","0.00479","166.56834"
"57.20000","0.95148","296.98123","1.08674","-0.12670","0.00482","167.42181"
"57.60000","0.95810","298.40475","1.09327","-0.12018","0.00485","168.22432"
"58.00000","0.96461","299.95007","1.09968","-0.11377","0.00487","169.09547"
"58.40000","0.97146","301.35431","1.10643","-0.10702","0.00490","169.88712"
"58.80000","0.97846","303.05179","1.11332","-0.10013","0.00494","170.84406"
"59.20000","0.98503","304.49789","1.11979","-0.09366","0.00496","171.65930"
"59.60000","0.99155","306.00012","1.12621","-0.08724","0.00499","172.50616"
"60.00000","0.99809","307.39264","1.13266","-0.08079","0.00502","173.29120"
"60.40000","1.00467","308.87332","1.13914","-0.07431","0.00505","174.12592"
"60.80000","1.01141","310.40485","1.14578","-0.06767","0.00508","174.98932"
"61.20000","1.01827","311.89758","1.15254","-0.06091","0.00511","175.83084"
"61.60000","1.02513","313.41034","1.15929","-0.05415","0.00514","176.68364"
"62.00000","1.03152","314.81287","1.16559","-0.04785","0.00517","177.47432"
"62.40000","1.03816","316.22137","1.17214","-0.04131","0.00520","178.26836"
"62.80000","1.04466","317.66577","1.17854","-0.03491","0.00522","179.08263"
"63.20000","1.05136","319.09683","1.18514","-0.02830","0.00525","179.88937"
"63.60000","1.05839","320.65161","1.19208","-0.02137","0.00528","180.76588"
"64.00000","1.06501","322.02240","1.19861","-0.01484","0.00531","181.53865"
"64.40000","1.07166","323.55612","1.20515","-0.00830","0.00534","182.40329"
"64.80000","1.07809","324.98029","1.21148","-0.00197","0.00537","183.20615"
"65.20000","1.08473","326.21298","1.21804","0.00459","0.00540","183.90108"
"65.60000","1.09130","327.67664","1.22452","0.01107","0.00543","184.72620"
"66.00000","1.09818","329.17261","1.23129","0.01784","0.00546","185.56955"
"66.40000","1.10517","330.73645","1.23818","0.02473","0.00549","186.45116"
"66.80000","1.11154","332.03217","1.24446","0.03102","0.00552","187.18161"
"67.20000","1.11822","333.38239","1.25105","0.03761","0.00555","187.94279"
"67.60000","1.12468","334.78192","1.25742","0.04397","0.00557","188.73178"
"68.00000","1.13134","336.24420","1.26398","0.05053","0.00560","189.55614"
"68.40000","1.13822","337.74170","1.27076","0.05731","0.00563","190.40033"
"68.80000","1.14502","339.11536","1.27747","0.06402","0.00566","191.17473"
"69.20000","1.15175","340.55161","1.28410","0.07065","0.00569","191.98441"
"69.60000","1.15809","341.74231","1.29036","0.07691","0.00572","192.65567"
"70.00000","1.16475","343.06937","1.29694","0.08350","0.00575","193.40378"
"70.40000","1.17125","344.49252","1.30335","0.08990","0.00578","194.20609"
"70.80000","1.17813","345.91992","1.31013","0.09668","0.00581","195.01077"
"71.20000","1.18512","347.36264","1.31704","0.10359","0.00584","195.82410"
"71.60000","1.19171","348.76236","1.32353","0.11008","0.00587","196.61319"
"72.00000","1.19824","349.90869","1.32999","0.11654","0.00590","197.25943"
"72.40000","1.20470","351.30093","1.33636","0.12291","0.00592","198.04430"
"72.80000","1.21133","352.57993","1.34291","0.12946","0.00595","198.76532"
"73.20000","1.21807","353.89511","1.34957","0.13612","0.00598","199.50674"
"73.60000","1.22500","355.41699","1.35640","0.14295","0.00601","200.36470"
"74.00000","1.23180","356.65524","1.36312","0.14967","0.00604","201.06276"
"74.40000","1.23822","357.90442","1.36946","0.15601","0.00607","201.76698"
"74.80000","1.24481","359.26376","1.37596","0.16251","0.00610","202.53329"
"75.20000","1.25134","360.54401","1.38241","0.16896","0.00613","203.25504"
"75.60000","1.25802","361.84164","1.38901","0.17556","0.00616","203.98657"
"76.00000","1.26502","363.02664","1.39592","0.18248","0.00619","204.65460"
"76.40000","1.27169","364.53375","1.40250","0.18905","0.00622","205.50424"
"76.80000","1.27833","365.73837","1.40906","0.19561","0.00625","206.18333"
"77.20000","1.28478","367.07285","1.41543","0.20198","0.00627","206.93564"
"77.60000","1.29136","368.12650","1.42194","0.20850","0.00630","207.52963"
"78.00000","1.29803","369.56268","1.42852","0.21507","0.00633","208.33926"
"78.40000","1.30486","370.78488","1.43528","0.22183","0.00636","209.02827"
"78.80000","1.31184","372.21033","1.44216","0.22871","0.00639","209.83186"
"79.20000","1.31818","373.21896","1.44843","0.23498","0.00642","210.40048"
"79.60000","1.32488","374.50476","1.45505","0.24160","0.00645","211.12535"
"80.00000","1.33135","375.73642","1.46144","0.24799","0.00648","211.81969"
"80.40000","1.33801","376.96033","1.46803","0.25458","0.00651","212.50966"
"80.80000","1.34491","378.26001","1.47484","0.26139","0.00654","213.24236"
"81.20000","1.35168","379.55737","1.48153","0.26808","0.00657","213.97372"
"81.60000","1.35841","380.74130","1.48819","0.27474","0.00660","214.64116"
"82.00000","1.36481","381.96426","1.49450","0.28105","0.00662","215.33061"
"82.40000","1.37139","383.19305","1.50101","0.28756","0.00665","216.02333"
"82.80000","1.37793","384.27902","1.50748","0.29403","0.00668","216.63554"
"83.20000","1.38482","385.60416","1.51428","0.30084","0.00671","217.38258"
"83.60000","1.39184","386.97791","1.52121","0.30776","0.00674","218.15703"
"84.00000","1.39832","388.10345","1.52762","0.31417","0.00677","218.79155"
"84.40000","1.40496","389.16910","1.53419","0.32074","0.00680","219.39230"
"84.80000","1.41137","390.42950","1.54053","0.32709","0.00683","220.10284"
"85.20000","1.41800","391.54660","1.54710","0.33365","0.00686","220.73260"
"85.60000","1.42473","392.90219","1.55374","0.34030","0.00689","221.49681"
"86.00000","1.43167","394.14563","1.56062","0.34717","0.00692","222.19780"
"86.40000","1.43843","395.35187","1.56731","0.35387","0.00695","222.87781"
"86.80000","1.44485","396.32117","1.57368","0.36023","0.00698","223.42424"
"87.20000","1.45146","397.53748","1.58021","0.36676","0.00700","224.10994"
"87.60000","1.45800","398.72202","1.58668","0.37323","0.00703","224.77771"
"88.00000","1.46472","399.79761","1.59335","0.37990","0.00706","225.38406"
"88.40000","1.47174","401.23950","1.60029","0.38684","0.00709","226.19693"
"88.80000","1.47839","402.34332","1.60687","0.39342","0.00712","226.81921"
"89.20000","1.48497","403.36606","1.61339","0.39994","0.00715","227.39577"
"89.60000","1.49143","404.56363","1.61979","0.40634","0.00718","228.07089"
"90.00000","1.49801","405.67862","1.62630","0.41285","0.00721","228.69946"
"90.40000","1.50465","406.71582","1.63288","0.41943","0.00724","229.28418"
"90.80000","1.51157","408.02737","1.63972","0.42628","0.00727","230.02356"
"91.20000","1.51855","409.22876","1.64663","0.43319","0.00730","230.70084"
"91.60000","1.52491","410.16568","1.65294","0.43950","0.00733","231.22902"
"92.00000","1.53155","411.37436","1.65951","0.44607","0.00736","231.91042"
"92.40000","1.53802","412.43658","1.66593","0.45248","0.00738","232.50923"
"92.80000","1.54469","413.43878","1.67254","0.45909","0.00741","233.07422"
"93.20000","1.55155","414.67963","1.67933","0.46588","0.00744","233.77374"
"93.60000","1.55832","415.70630","1.68604","0.47259","0.00747","234.35252"
"94.00000","1.56503","416.83102","1.69269","0.47924","0.00750","234.98659"
"94.40000","1.57146","417.95029","1.69905","0.48560","0.00753","235.61755"
"94.80000","1.57813","419.04660","1.70566","0.49221","0.00756","236.23560"
"95.20000","1.58465","420.06714","1.71212","0.49867","0.00759","236.81093"
"95.60000","1.59150","421.04755","1.71891","0.50546","0.00762","237.36363"
"96.00000","1.59850","422.34775","1.72584","0.51239","0.00765","238.09660"
"96.40000","1.60493","423.45462","1.73221","0.51876","0.00768","238.72061"
"96.80000","1.61158","424.44983","1.73880","0.52535","0.00771","239.28165"
"97.20000","1.61803","425.45242","1.74520","0.53175","0.00774","239.84686"
"97.60000","1.62470","426.46307","1.75180","0.53836","0.00777","240.41661"
"98.00000","1.63146","427.67087","1.75850","0.54505","0.00780","241.09749"
"98.40000","1.63841","428.81946","1.76538","0.55193","0.00783","241.74501"
"98.80000","1.64514","429.78403","1.77206","0.55861","0.00786","242.28877"
"99.20000","1.65150","430.83084","1.77835","0.56491","0.00788","242.87892"
"99.60000","1.65812","431.76105","1.78492","0.57147","0.00791","243.40332"
"100.00000","1.66464","432.85257","1.79138","0.57794","0.00794","244.01866"
"100.40000","1.67139","433.99329","1.79807","0.58462","0.00797","244.66173"
"100.80000","1.67841","435.07199","1.80502","0.59157","0.00800","245.26984"
"101.20000","1.68505","436.16382","1.81160","0.59815","0.00803","245.88536"
"101.60000","1.69166","437.09869","1.81816","0.60472","0.00806","246.41238"
"102.00000","1.69810","438.12268","1.82455","0.61110","0.00809","246.98965"
"102.40000","1.70466","439.06961","1.83105","0.61760","0.00812","247.52348"
"102.80000","1.71132","440.10110","1.83765","0.62420","0.00815","248.10498"
"103.20000","1.71822","441.07916","1.84450","0.63105","0.00818","248.65636"
"103.60000","1.72522","442.09457","1.85143","0.63799","0.00821","249.22879"
"104.00000","1.73156","443.19736","1.85771","0.64426","0.00823","249.85048"
"104.40000","1.73816","444.03687","1.86426","0.65082","0.00826","250.32375"
"104.80000","1.74470","445.02130","1.87075","0.65730","0.00829","250.87872"
"105.20000","1.75136","445.96121","1.87735","0.66391","0.00832","251.40858"
"105.60000","1.75827","447.02054","1.88420","0.67075","0.00835","252.00578"
"106.00000","1.76501","448.08337","1.89089","0.67744","0.00838","252.60495"
"106.40000","1.77175","448.92780","1.89757","0.68412","0.00841","253.08099"
"106.80000","1.77810","449.80081","1.90387","0.69043","0.00844","253.57315"
"107.20000","1.78476","450.67892","1.91048","0.69704","0.00847","254.06818"
"107.60000","1.79128","451.68582","1.91695","0.70350","0.00850","254.63582"
"108.00000","1.79817","452.72229","1.92378","0.71034","0.00853","255.22012"
"108.40000","1.80519","453.69830","1.93074","0.71730","0.00856","255.77034"
"108.80000","1.81166","454.56616","1.93717","0.72372","0.00859","256.25958"
"109.20000","1.81829","455.61584","1.94373","0.73029","0.00862","256.85135"
"109.60000","1.82473","456.39008","1.95014","0.73669","0.00864","257.28781"
"110.00000","1.83137","457.33276","1.95672","0.74327","0.00867","257.81924"
"110.40000","1.83809","458.30151","1.96339","0.74994","0.00870","258.36539"
"110.80000","1.84496","459.27567","1.97020","0.75675","0.00873","258.91455"
"111.20000","1.85180","460.33914","1.97698","0.76353","0.00876","259.51410"
"111.60000","1.85818","461.07010","1.98332","0.76987","0.00879","259.92615"
"112.00000","1.86480","461.97028","1.98988","0.77643","0.00882","260.43362"
"112.40000","1.87133","462.87280","1.99636","0.78292","0.00885","260.94241"
"112.80000","1.87809","463.77332","2.00307","0.78962","0.00888","261.45007"
"113.20000","1.88509","464.81332","2.01001","0.79656","0.00891","262.03638"
"113.60000","1.89167","465.78479","2.01654","0.80309","0.00894","262.58405"
"114.00000","1.89830","466.57898","2.02312","0.80967","0.00897","263.03177"
"114.40000","1.90476","467.26846","2.02954","0.81609","0.00900","263.42047"
"114.80000","1.91133","468.23355","2.03606","0.82261","0.00903","263.96451"
"115.20000","1.91800","469.06088","2.04268","0.82923","0.00905","264.43094"
"115.60000","1.92497","470.13214","2.04958","0.83614","0.00909","265.03485"
"116.00000","1.93189","470.92532","2.05647","0.84302","0.00912","265.48199"
"116.40000","1.93827","471.68484","2.06280","0.84935","0.00914","265.91019"
"116.80000","1.94482","472.59717","2.06930","0.85585","0.00917","266.42450"
"117.20000","1.95134","473.43192","2.07577","0.86233","0.00920","266.89508"
"117.60000","1.95798","474.24692","2.08236","0.86892","0.00923","267.35452"
"118.00000","1.96491","475.22672","2.08924","0.87579","0.00926","267.90689"
"118.40000","1.97171","476.15137","2.09599","0.88254","0.00929","268.42816"
"118.80000","1.97836","476.94986","2.10259","0.88914","0.00932","268.87830"
"119.20000","1.98485","477.60831","2.10904","0.89560","0.00935","269.24951"
"119.60000","1.99142","478.37634","2.11557","0.90212","0.00938","269.68246"
"120.00000","1.99799","479.18661","2.12209","0.90864","0.00941","270.13925"
"120.40000","2.00481","480.03271","2.12886","0.91541","0.00944","270.61624"
"120.80000","2.01184","481.11136","2.13583","0.92239","0.00947","271.22433"
"121.20000","2.01822","481.79425","2.14217","0.92872","0.00950","271.60931"
"121.60000","2.02491","482.47971","2.14882","0.93538","0.00953","271.99573"
"122.00000","2.03138","483.27893","2.15525","0.94180","0.00955","272.44629"
"122.40000","2.03805","484.04779","2.16188","0.94843","0.00958","272.87973"
"122.80000","2.04486","484.92230","2.16863","0.95518","0.00961","273.37274"
"123.20000","2.05165","485.67828","2.17539","0.96194","0.00964","273.79892"
"123.60000","2.05848","486.52579","2.18216","0.96871","0.00967","274.27667"
"124.00000","2.06485","487.24091","2.18849","0.97504","0.00970","274.67984"
"124.40000","2.07147","487.96378","2.19507","0.98162","0.00973","275.08734"
"124.80000","2.07792","488.68591","2.20148","0.98803","0.00976","275.49445"
"125.20000","2.08477","489.50873","2.20828","0.99483","0.00979","275.95831"
"125.60000","2.09178","490.23022","2.21525","1.00180","0.00982","276.36505"
"126.00000","2.09834","490.90533","2.22178","1.00834","0.00985","276.74564"
"126.40000","2.10498","491.66956","2.22838","1.01493","0.00988","277.17645"
"126.80000","2.11142","492.21780","2.23479","1.02135","0.00991","277.48553"
"127.20000","2.11803","492.82922","2.24138","1.02793","0.00994","277.83023"
"127.60000","2.12466","493.54773","2.24797","1.03452","0.00996","278.23526"
"128.00000","2.13162","494.37238","2.25489","1.04144","0.01000","278.70016"
"128.40000","2.13848","495.20572","2.26171","1.04826","0.01003","279.16995"
"128.80000","2.14490","495.54346","2.26811","1.05466","0.01005","279.36035"
"129.20000","2.15149","496.15848","2.27467","1.06123","0.01008","279.70706"
"129.60000","2.15797","496.70981","2.28112","1.06768","0.01011","280.01788"
"130.00000","2.16469","497.38589","2.28781","1.07436","0.01014","280.39902"
"130.40000","2.17160","497.85342","2.29470","1.08125","0.01017","280.66260"
"130.80000","2.17841","498.34918","2.30148","1.08803","0.01020","280.94208"
"131.20000","2.18501","498.53452","2.30807","1.09462","0.01023","281.04654"
"131.60000","2.19148","498.83807","2.31453","1.10108","0.01026","281.21768"
"132.00000","2.19802","498.28625","2.32109","1.10764","0.01029","280.90659"
"132.40000","2.20462","497.95074","2.32771","1.11426","0.01032","280.71747"
"132.80000","2.21147","498.11298","2.33455","1.12111","0.01035","280.80890"
"133.20000","2.21858","498.33017","2.34165","1.12821","0.01038","280.93137"
"133.60000","2.22500","498.40912","2.34806","1.13461","0.01041","280.97586"
"134.00000","2.23154","498.24249","2.35462","1.14117","0.01044","280.88193"
"134.40000","2.23804","498.18948","2.36112","1.14767","0.01047","280.85205"
"134.80000","2.24469","498.25806","2.36776","1.15432","0.01050","280.89069"
"135.20000","2.25148","498.53888","2.37454","1.16109","0.01053","281.04901"
"135.60000","2.25829","498.66693","2.38135","1.16790","0.01056","281.12119"
"136.00000","2.26511","498.99408","2.38814","1.17470","0.01059","281.30563"
"136.40000","2.27151","499.24939","2.39453","1.18108","0.01061","281.44955"
"136.80000","2.27814","499.59143","2.40115","1.18770","0.01064","281.64240"
"137.20000","2.28465","500.00159","2.40764","1.19419","0.01067","281.87360"
"137.60000","2.29137","500.38467","2.41434","1.20089","0.01070","282.08957"
"138.00000","2.29849","500.84454","2.42143","1.20799","0.01073","282.34882"
"138.40000","2.30494","500.83374","2.42788","1.21443","0.01076","282.34274"
"138.80000","2.31161","501.03616","2.43454","1.22110","0.01079","282.45685"
"139.20000","2.31805","501.42319","2.44096","1.22751","0.01082","282.67502"
"139.60000","2.32471","501.86041","2.44761","1.23416","0.01085","282.92151"
"140.00000","2.33137","502.31180","2.45424","1.24079","0.01088","283.17596"
"140.40000","2.33831","502.77798","2.46116","1.24771","0.01091","283.43878"
"140.80000","2.34518","503.42191","2.46799","1.25455","0.01094","283.80179"
"141.20000","2.35154","503.96124","2.47432","1.26088","0.01097","284.10583"
"141.60000","2.35817","504.45212","2.48093","1.26748","0.01100","284.38257"
"142.00000","2.36462","504.93115","2.48735","1.27391","0.01103","284.65262"
"142.40000","2.37139","505.53876","2.49410","1.28065","0.01106","284.99515"
"142.80000","2.37828","506.06894","2.50096","1.28751","0.01109","285.29404"
"143.20000","2.38512","506.25992","2.50780","1.29435","0.01112","285.40170"
"143.60000","2.39169","506.62955","2.51434","1.30089","0.01115","285.61008"
"144.00000","2.39812","506.98318","2.52075","1.30730","0.01117","285.80945"
"144.40000","2.40473","507.42697","2.52735","1.31390","0.01120","286.05963"
"144.80000","2.41127","507.73468","2.53387","1.32042","0.01123","286.23309"
"145.20000","2.41816","508.33356","2.54073","1.32728","0.01126","286.57071"
"145.60000","2.42517","508.70987","2.54772","1.33427","0.01129","286.78287"
"146.00000","2.43165","509.31131","2.55417","1.34072","0.01132","287.12192"
"146.40000","2.43818","509.65695","2.56069","1.34724","0.01135","287.31677"
"146.80000","2.44473","510.08221","2.56721","1.35377","0.01138","287.55652"
"147.20000","2.45131","510.38434","2.57378","1.36033","0.01141","287.72684"
"147.60000","2.45817","510.81940","2.58061","1.36717","0.01144","287.97211"
"148.00000","2.46501","511.30597","2.58743","1.37398","0.01147","288.24640"
"148.40000","2.47174","511.64017","2.59414","1.38070","0.01150","288.43481"
"148.80000","2.47816","511.93912","2.60055","1.38710","0.01153","288.60333"
"149.20000","2.48479","512.35400","2.60716","1.39371","0.01156","288.83722"
"149.60000","2.49130","512.63776","2.61365","1.40020","0.01159","288.99719"
"150.00000","2.49803","513.22754","2.62036","1.40691","0.01162","289.32968"
"150.40000","2.50514","513.66077","2.62744","1.41399","0.01165","289.57391"
"150.80000","2.51167","513.82153","2.63397","1.42052","0.01168","289.66455"
"151.20000","2.51828","514.19519","2.64056","1.42711","0.01171","289.87518"
"151.60000","2.52473","514.43579","2.64699","1.43355","0.01173","290.01083"
"152.00000","2.53137","514.75769","2.65362","1.44017","0.01176","290.19229"
"152.40000","2.53802","514.81061","2.66027","1.44682","0.01179","290.22214"
"152.80000","2.54488","515.00940","2.66711","1.45367","0.01182","290.33420"
"153.20000","2.55179","515.31598","2.67401","1.46056","0.01185","290.50702"
"153.60000","2.55818","515.52405","2.68039","1.46694","0.01188","290.62433"
"154.00000","2.56486","515.70160","2.68706","1.47361","0.01191","290.72443"
"154.40000","2.57133","515.82281","2.69352","1.48007","0.01194","290.79276"
"154.80000","2.57803","516.27747","2.70020","1.48675","0.01197","291.04907"
"155.20000","2.58497","516.52881","2.70713","1.49368","0.01200","291.19077"
"155.60000","2.59169","516.89435","2.71383","1.50038","0.01203","291.39682"
"156.00000","2.59836","516.98090","2.72050","1.50705","0.01206","291.44562"
"156.40000","2.60473","517.19452","2.72686","1.51341","0.01209","291.56604"
"156.80000","2.61138","517.38544","2.73350","1.52005","0.01212","291.67368"
"157.20000","2.61795","517.61761","2.74005","1.52660","0.01215","291.80457"
"157.60000","2.62487","517.97162","2.74695","1.53351","0.01218","292.00412"
"158.00000","2.63181","518.17780","2.75388","1.54043","0.01221","292.12036"
"158.40000","2.63832","518.39337","2.76038","1.54694","0.01224","292.24188"
"158.80000","2.64487","518.41449","2.76694","1.55349","0.01227","292.25378"
"159.20000","2.65134","518.49091","2.77340","1.55995","0.01229","292.29688"
"159.60000","2.65799","518.71802","2.78004","1.56659","0.01232","292.42490"
"160.00000","2.66483","518.94067","2.78687","1.57342","0.01235","292.55042"
"160.40000","2.67172","519.14874","2.79375","1.58030","0.01238","292.66772"
"160.80000","2.67840","519.22223","2.80042","1.58698","0.01241","292.70917"
"161.20000","2.68485","519.25464","2.80687","1.59342","0.01244","292.72742"
"161.60000","2.69145","519.16949","2.81347","1.60002","0.01247","292.67941"
"162.00000","2.69798","519.20941","2.82000","1.60656","0.01250","292.70193"
"162.40000","2.70472","519.39154","2.82674","1.61329","0.01253","292.80460"
"162.80000","2.71179","519.58673","2.83379","1.62034","0.01256","292.91464"
"163.20000","2.71832","519.54187","2.84033","1.62688","0.01259","292.88934"
"163.60000","2.72494","519.44257","2.84695","1.63350","0.01262","292.83337"
"164.00000","2.73142","519.35907","2.85344","1.63999","0.01265","292.78629"
"164.40000","2.73802","519.08710","2.86005","1.64660","0.01268","292.63297"
"164.80000","2.74476","518.83746","2.86680","1.65335","0.01271","292.49225"
"165.20000","2.75159","518.40173","2.87365","1.66020","0.01274","292.24661"
"165.60000","2.75848","517.65259","2.88058","1.66713","0.01277","291.82428"
"166.00000","2.76481","516.31378","2.88698","1.67353","0.01280","291.06952"
"166.40000","2.77152","514.97925","2.89376","1.68031","0.01283","290.31720"
"166.80000","2.77797","513.56781","2.90027","1.68682","0.01286","289.52151"
"167.20000","2.78469","512.49133","2.90705","1.69360","0.01289","288.91464"
"167.60000","2.79171","511.82336","2.91410","1.70065","0.01292","288.53809"
"168.00000","2.79837","511.12991","2.92080","1.70735","0.01295","288.14716"
"168.40000","2.80502","510.71179","2.92747","1.71402","0.01298","287.91144"
"168.80000","2.81144","510.19681","2.93391","1.72047","0.01301","287.62112"
"169.20000","2.81802","509.70184","2.94052","1.72708","0.01303","287.34207"
"169.60000","2.82463","509.31177","2.94715","1.73370","0.01306","287.12219"
"170.00000","2.83153","508.95154","2.95407","1.74062","0.01310","286.91910"
"170.40000","2.83851","508.86795","2.96105","1.74760","0.01313","286.87198"
"170.80000","2.84494","508.55573","2.96750","1.75405","0.01315","286.69595"
"171.20000","2.85157","508.17331","2.97415","1.76070","0.01318","286.48038"
"171.60000","2.85800","507.78845","2.98060","1.76715","0.01321","286.26343"
"172.00000","2.86465","507.52087","2.98726","1.77381","0.01324","286.11258"
"172.40000","2.87149","507.41833","2.99411","1.78066","0.01327","286.05478"
"172.80000","2.87842","507.43561","3.00103","1.78759","0.01330","286.06451"
"173.20000","2.88506","507.05164","3.00770","1.79425","0.01333","285.84805"
"173.60000","2.89148","506.79367","3.01412","1.80067","0.01336","285.70261"
"174.00000","2.89807","506.21335","3.02075","1.80730","0.01339","285.37546"
"174.40000","2.90465","505.78043","3.02735","1.81390","0.01342","285.13141"
"174.80000","2.91142","505.35849","3.03414","1.82069","0.01345","284.89352"
"175.20000","2.91851","505.16492","3.04124","1.82779","0.01348","284.78442"
"175.60000","2.92502","504.86792","3.04777","1.83432","0.01351","284.61697"
"176.00000","2.93160","504.58737","3.05435","1.84090","0.01354","284.45883"
"176.40000","2.93809","504.40182","3.06085","1.84741","0.01357","284.35422"
"176.80000","2.94465","504.27994","3.06742","1.85398","0.01360","284.28549"
"177.20000","2.95135","504.08047","3.07413","1.86068","0.01363","284.17307"
"177.60000","2.95830","504.09940","3.08108","1.86763","0.01366","284.18372"
"178.00000","2.96519","503.97095","3.08798","1.87453","0.01369","284.11133"
"178.40000","2.97154","503.68155","3.09434","1.88089","0.01372","283.94818"
"178.80000","2.97818","503.59564","3.10099","1.88754","0.01375","283.89975"
"179.20000","2.98467","503.14987","3.10750","1.89405","0.01378","283.64844"
"179.60000","2.99135","502.97571","3.11419","1.90074","0.01380","283.55026"
"180.00000","2.99833","502.79163","3.12118","1.90773","0.01384","283.44647"
"180.40000","3.00496","502.42545","3.12782","1.91437","0.01387","283.24005"
"180.80000","3.01165","502.14194","3.13453","1.92108","0.01389","283.08023"
"181.20000","3.01812","501.87494","3.14101","1.92756","0.01392","282.92969"
"181.60000","3.02476","501.30371","3.14768","1.93423","0.01395","282.60767"
"182.00000","3.03133","500.94611","3.15427","1.94082","0.01398","282.40607"
"182.40000","3.03821","500.70081","3.16116","1.94771","0.01401","282.26779"
"182.80000","3.04521","500.48535","3.16817","1.95472","0.01404","282.14633"
"183.20000","3.05159","500.22992","3.17456","1.96112","0.01407","282.00232"
"183.60000","3.05818","499.80200","3.18118","1.96773","0.01410","281.76108"
"184.00000","3.06467","499.44092","3.18769","1.97424","0.01413","281.55753"
"184.40000","3.07138","499.13852","3.19441","1.98096","0.01416","281.38705"
"184.80000","3.07821","498.83496","3.20125","1.98780","0.01419","281.21591"
"185.20000","3.08510","498.49710","3.20816","1.99471","0.01422","281.02545"
"185.60000","3.09176","498.11899","3.21484","2.00140","0.01425","280.81229"
"186.00000","3.09813","497.52835","3.22124","2.00779","0.01428","280.47934"
"186.40000","3.10475","496.86487","3.22789","2.01444","0.01431","280.10529"
"186.80000","3.11129","496.21454","3.23447","2.02102","0.01434","279.73868"
"187.20000","3.11810","495.39166","3.24132","2.02787","0.01437","279.27478"
"187.60000","3.12514","494.79404","3.24839","2.03494","0.01440","278.93787"
"188.00000","3.13167","493.87772","3.25497","2.04152","0.01443","278.42130"
"188.40000","3.13827","493.08301","3.26160","2.04815","0.01446","277.97330"
"188.80000","3.14474","492.14651","3.26812","2.05467","0.01449","277.44534"
"189.20000","3.15133","490.92062","3.27477","2.06132","0.01452","276.75424"
"189.60000","3.15804","490.03088","3.28153","2.06808","0.01455","276.25266"
"190.00000","3.16496","489.01666","3.28850","2.07505","0.01458","275.68091"
"190.40000","3.17183","487.79025","3.29544","2.08199","0.01461","274.98953"
"190.80000","3.17818","486.59778","3.30186","2.08841","0.01464","274.31726"
"191.20000","3.18478","484.92462","3.30856","2.09511","0.01467","273.37402"
"191.60000","3.19133","483.29150","3.31520","2.10176","0.01470","272.45337"
"192.00000","3.19805","481.81104","3.32200","2.10855","0.01473","271.61877"
"192.40000","3.20505","480.31583","3.32909","2.11564","0.01476","270.77585"
"192.80000","3.21169","478.59494","3.33582","2.12238","0.01479","269.80569"
"193.20000","3.21836","476.87097","3.34259","2.12915","0.01482","268.83383"
"193.60000","3.22473","474.64169","3.34909","2.13564","0.01485","267.57709"
"194.00000","3.23140","472.46460","3.35588","2.14243","0.01488","266.34976"
"194.40000","3.23797","469.71762","3.36262","2.14917","0.01491","264.80115"
"194.80000","3.24490","466.90115","3.36970","2.15625","0.01494","263.21338"
"195.20000","3.25184","463.60834","3.37683","2.16338","0.01497","261.35709"
"195.60000","3.25828","459.37784","3.38351","2.17006","0.01500","258.97217"
"196.00000","3.26492","454.07797","3.39045","2.17700","0.01503","255.98438"
"196.40000","3.27138","443.30588","3.39753","2.18408","0.01506","249.91167"
"196.67800","3.27620","410.83023","3.40420","2.19075","0.01509","231.60367"
"196.83300","3.27867","369.96780","3.40914","2.19569","0.01511","208.56766"
"197.23300","3.28566","355.49533","3.41705","2.20360","0.01515","200.40886"
"197.63300","3.29219","350.97119","3.42388","2.21043","0.01518","197.85840"
"198.03300","3.29884","347.71246","3.43073","2.21728","0.01521","196.02132"
"198.43300","3.30530","345.64108","3.43732","2.22387","0.01524","194.85358"
"198.83300","3.31190","343.71472","3.44405","2.23060","0.01527","193.76761"
"199.23300","3.31859","342.50983","3.45081","2.23737","0.01530","193.08835"
"199.63300","3.32557","341.78751","3.45784","2.24439","0.01533","192.68114"
"200.03300","3.33242","341.14664","3.46473","2.25129","0.01536","192.31985"
"200.21600","3.33496","340.83282","3.46729","2.25384","0.01537","192.14294"