File: flexion/3_axis/Specimen_RawData_5.csv
Specimen properties : Specimen label,"5"
Specimen properties : Support span,"72.00",mm
Specimen properties : Thickness,"3.88",mm
Specimen properties : Width,"12.91",mm
Maximum Load : Maximum Load,"421.6",N
Tangent Modulus of Elasticity : Tangent Modulus of Elasticity,"40974140142.71020",Pa
Test : Rate 1,"1.00000",mm/min
Specimen notes : Specimen note 1,""

Time,Displacement,Load,Flexure extension,Corrected extension,Flexure strain (Corrected extension),Flexure stress
(s),(mm),(N),(mm),(mm),(mm/mm),(MPa)
"0.00000","0.00000","48.41339","0.14863","-1.05549","0.00067","26.90293"
"0.40000","0.00465","49.98383","0.15307","-1.05104","0.00069","27.77561"
"0.80000","0.01162","52.46053","0.15971","-1.04441","0.00072","29.15189"
"1.20000","0.01833","54.72318","0.16611","-1.03801","0.00075","30.40923"
"1.60000","0.02479","56.92659","0.17228","-1.03184","0.00077","31.63364"
"2.00000","0.03140","59.09360","0.17862","-1.02550","0.00080","32.83783"
"2.40000","0.03805","61.23669","0.18502","-1.01910","0.00083","34.02873"
"2.80000","0.04487","63.66915","0.19156","-1.01256","0.00086","35.38043"
"3.20000","0.05194","65.83170","0.19838","-1.00574","0.00089","36.58214"
"3.60000","0.05823","67.94437","0.20442","-0.99970","0.00092","37.75613"
"4.00000","0.06488","70.10121","0.21081","-0.99330","0.00095","38.95467"
"4.40000","0.07131","72.28667","0.21699","-0.98713","0.00097","40.16911"
"4.80000","0.07805","74.36553","0.22349","-0.98063","0.00100","41.32432"
"5.20000","0.08491","76.57075","0.23009","-0.97403","0.00103","42.54974"
"5.60000","0.09176","78.79467","0.23668","-0.96743","0.00106","43.78556"
"6.00000","0.09845","80.84930","0.24312","-0.96099","0.00109","44.92730"
"6.40000","0.10479","82.90408","0.24923","-0.95489","0.00112","46.06913"
"6.80000","0.11143","84.96670","0.25562","-0.94849","0.00115","47.21531"
"7.20000","0.11794","86.92863","0.26191","-0.94221","0.00118","48.30553"
"7.60000","0.12481","89.15165","0.26855","-0.93557","0.00121","49.54085"
"8.00000","0.13181","91.28046","0.27535","-0.92877","0.00124","50.72381"
"8.40000","0.13839","93.35517","0.28172","-0.92240","0.00127","51.87671"
"8.80000","0.14492","95.30365","0.28806","-0.91605","0.00129","52.95947"
"9.20000","0.15138","97.35475","0.29432","-0.90980","0.00132","54.09925"
"9.60000","0.15803","99.37499","0.30078","-0.90334","0.00135","55.22188"
"10.00000","0.16471","101.63775","0.30723","-0.89689","0.00138","56.47927"
"10.40000","0.17167","103.72742","0.31398","-0.89013","0.00141","57.64048"
"10.80000","0.17849","105.83228","0.32060","-0.88352","0.00144","58.81013"
"11.20000","0.18490","107.90075","0.32681","-0.87731","0.00147","59.95957"
"11.60000","0.19143","109.95731","0.33314","-0.87098","0.00150","61.10239"
"12.00000","0.19801","111.94226","0.33953","-0.86459","0.00152","62.20541"
"12.40000","0.20472","114.02509","0.34603","-0.85809","0.00155","63.36282"
"12.80000","0.21178","116.31644","0.35287","-0.85125","0.00158","64.63610"
"13.20000","0.21840","118.35792","0.35929","-0.84483","0.00161","65.77053"
"13.60000","0.22497","120.40643","0.36566","-0.83846","0.00164","66.90887"
"14.00000","0.23144","122.35375","0.37194","-0.83218","0.00167","67.99099"
"14.40000","0.23807","124.47706","0.37836","-0.82576","0.00170","69.17089"
"14.80000","0.24467","126.45684","0.38476","-0.81936","0.00173","70.27104"
"15.20000","0.25151","128.61870","0.39140","-0.81272","0.00176","71.47237"
"15.60000","0.25854","130.79001","0.39821","-0.80590","0.00179","72.67895"
"16.00000","0.26494","132.73671","0.40443","-0.79969","0.00182","73.76071"
"16.40000","0.27158","134.74179","0.41087","-0.79325","0.00185","74.87492"
"16.80000","0.27804","136.86113","0.41713","-0.78699","0.00187","76.05262"
"17.20000","0.28469","138.83318","0.42358","-0.78054","0.00190","77.14847"
"17.60000","0.29156","141.02271","0.43024","-0.77388","0.00193","78.36517"
"18.00000","0.29831","142.96950","0.43680","-0.76731","0.00196","79.44699"
"18.40000","0.30505","145.16298","0.44333","-0.76079","0.00199","80.66589"
"18.80000","0.31146","146.96835","0.44956","-0.75455","0.00202","81.66912"
"19.20000","0.31814","149.09351","0.45604","-0.74808","0.00205","82.85005"
"19.60000","0.32466","151.05864","0.46236","-0.74176","0.00208","83.94206"
"20.00000","0.33150","153.18469","0.46899","-0.73513","0.00211","85.12349"
"20.40000","0.33851","155.23384","0.47581","-0.72831","0.00214","86.26218"
"20.80000","0.34498","157.26889","0.48208","-0.72204","0.00216","87.39304"
"21.20000","0.35161","159.37740","0.48853","-0.71559","0.00219","88.56473"
"21.60000","0.35802","161.18532","0.49478","-0.70934","0.00222","89.56937"
"22.00000","0.36469","163.21739","0.50128","-0.70284","0.00225","90.69858"
"22.40000","0.37142","165.26274","0.50783","-0.69629","0.00228","91.83517"
"22.80000","0.37839","167.50842","0.51461","-0.68951","0.00231","93.08307"
"23.20000","0.38514","169.50629","0.52119","-0.68293","0.00234","94.19327"
"23.60000","0.39155","171.35820","0.52744","-0.67668","0.00237","95.22236"
"24.00000","0.39816","173.39368","0.53389","-0.67023","0.00240","96.35346"
"24.40000","0.40465","175.31981","0.54021","-0.66391","0.00243","97.42380"
"24.80000","0.41140","177.24805","0.54679","-0.65732","0.00246","98.49530"
"25.20000","0.41840","179.50359","0.55360","-0.65051","0.00249","99.74869"
"25.60000","0.42508","181.42111","0.56012","-0.64400","0.00252","100.81424"
"26.00000","0.43161","183.31332","0.56649","-0.63763","0.00254","101.86573"
"26.40000","0.43814","185.20456","0.57286","-0.63126","0.00257","102.91667"
"26.80000","0.44472","187.17120","0.57927","-0.62485","0.00260","104.00952"
"27.20000","0.45136","189.18704","0.58574","-0.61838","0.00263","105.12971"
"27.60000","0.45819","191.09232","0.59241","-0.61171","0.00266","106.18845"
"28.00000","0.46518","193.26929","0.59921","-0.60491","0.00269","107.39818"
"28.40000","0.47158","195.11414","0.60546","-0.59866","0.00272","108.42334"
"28.80000","0.47822","197.16344","0.61192","-0.59220","0.00275","109.56212"
"29.20000","0.48470","199.01328","0.61824","-0.58588","0.00278","110.59007"
"29.60000","0.49136","200.98288","0.62473","-0.57938","0.00281","111.68456"
"30.00000","0.49828","203.03079","0.63150","-0.57262","0.00284","112.82256"
"30.40000","0.50503","204.87622","0.63809","-0.56603","0.00287","113.84805"
"30.80000","0.51172","206.84604","0.64462","-0.55949","0.00289","114.94267"
"31.20000","0.51812","208.66342","0.65088","-0.55324","0.00292","115.95257"
"31.60000","0.52480","210.55943","0.65741","-0.54671","0.00295","117.00616"
"32.00000","0.53130","212.41975","0.66376","-0.54035","0.00298","118.03993"
"32.40000","0.53814","214.48816","0.67044","-0.53368","0.00301","119.18933"
"32.80000","0.54517","216.49434","0.67731","-0.52681","0.00304","120.30415"
"33.20000","0.55162","218.27679","0.68361","-0.52051","0.00307","121.29464"
"33.60000","0.55828","220.23404","0.69012","-0.51400","0.00310","122.38227"
"34.00000","0.56473","222.04491","0.69642","-0.50770","0.00313","123.38855"
"34.40000","0.57134","223.75833","0.70290","-0.50122","0.00316","124.34069"
"34.80000","0.57810","225.78885","0.70949","-0.49463","0.00319","125.46903"
"35.20000","0.58500","227.80911","0.71623","-0.48789","0.00322","126.59167"
"35.60000","0.59181","229.66629","0.72289","-0.48122","0.00325","127.62370"
"36.00000","0.59815","231.52602","0.72909","-0.47503","0.00327","128.65714"
"36.40000","0.60482","233.27086","0.73561","-0.46851","0.00330","129.62672"
"36.80000","0.61132","235.14403","0.74196","-0.46216","0.00333","130.66763"
"37.20000","0.61808","237.01079","0.74857","-0.45555","0.00336","131.70497"
"37.60000","0.62503","238.99065","0.75537","-0.44875","0.00339","132.80516"
"38.00000","0.63177","240.87143","0.76195","-0.44217","0.00342","133.85030"
"38.40000","0.63830","242.70276","0.76834","-0.43578","0.00345","134.86795"
"38.80000","0.64476","244.38095","0.77467","-0.42945","0.00348","135.80051"
"39.20000","0.65137","246.31929","0.78113","-0.42299","0.00351","136.87762"
"39.60000","0.65803","248.12180","0.78766","-0.41646","0.00354","137.87927"
"40.00000","0.66493","250.05676","0.79440","-0.40972","0.00357","138.95451"
"40.40000","0.67189","252.04292","0.80121","-0.40291","0.00360","140.05821"
"40.80000","0.67828","253.58232","0.80748","-0.39664","0.00363","140.91364"
"41.20000","0.68488","255.47014","0.81393","-0.39019","0.00366","141.96268"
"41.60000","0.69138","257.22650","0.82031","-0.38381","0.00368","142.93867"
"42.00000","0.69802","259.01700","0.82680","-0.37732","0.00371","143.93364"
"42.40000","0.70490","260.80844","0.83355","-0.37057","0.00374","144.92914"
"42.80000","0.71172","262.62891","0.84023","-0.36389","0.00377","145.94075"
"43.20000","0.71841","264.51572","0.84677","-0.35734","0.00380","146.98924"
"43.60000","0.72481","266.14621","0.85304","-0.35107","0.00383","147.89529"
"44.00000","0.73145","267.93149","0.85955","-0.34457","0.00386","148.88736"
"44.40000","0.73802","269.72598","0.86599","-0.33813","0.00389","149.88454"
"44.80000","0.74481","271.38724","0.87264","-0.33148","0.00392","150.80768"
"45.20000","0.75186","273.52350","0.87953","-0.32459","0.00395","151.99478"
"45.60000","0.75824","275.13809","0.88579","-0.31833","0.00398","152.89200"
"46.00000","0.76493","276.96701","0.89234","-0.31178","0.00401","153.90833"
"46.40000","0.77139","278.67068","0.89867","-0.30545","0.00404","154.85504"
"46.80000","0.77804","280.39633","0.90519","-0.29893","0.00406","155.81396"
"47.20000","0.78482","281.89438","0.91185","-0.29227","0.00409","156.64642"
"47.60000","0.79169","283.85095","0.91857","-0.28555","0.00413","157.73367"
"48.00000","0.79847","285.63943","0.92522","-0.27890","0.00415","158.72751"
"48.40000","0.80485","287.29080","0.93146","-0.27265","0.00418","159.64517"
"48.80000","0.81145","288.88321","0.93794","-0.26617","0.00421","160.53006"
"49.20000","0.81797","290.61801","0.94434","-0.25978","0.00424","161.49406"
"49.60000","0.82478","292.42773","0.95103","-0.25309","0.00427","162.49973"
"50.00000","0.83178","294.20114","0.95790","-0.24622","0.00430","163.48518"
"50.40000","0.83844","295.88000","0.96445","-0.23967","0.00433","164.41812"
"50.80000","0.84504","297.58917","0.97094","-0.23318","0.00436","165.36789"
"51.20000","0.85140","299.11008","0.97720","-0.22692","0.00439","166.21304"
"51.60000","0.85802","300.75272","0.98371","-0.22041","0.00442","167.12584"
"52.00000","0.86469","302.44357","0.99026","-0.21386","0.00445","168.06544"
"52.40000","0.87161","304.35913","0.99705","-0.20707","0.00448","169.12990"
"52.80000","0.87849","306.10721","1.00382","-0.20030","0.00451","170.10129"
"53.20000","0.88491","307.64526","1.01013","-0.19399","0.00454","170.95598"
"53.60000","0.89154","309.30304","1.01665","-0.18747","0.00457","171.87718"
"54.00000","0.89804","310.92618","1.02305","-0.18107","0.00459","172.77916"
"54.40000","0.90468","312.53674","1.02957","-0.17454","0.00462","173.67413"
"54.80000","0.91162","314.25601","1.03640","-0.16772","0.00465","174.62952"
"55.20000","0.91841","315.98383","1.04307","-0.16104","0.00468","175.58965"
"55.60000","0.92505","317.55377","1.04961","-0.15451","0.00471","176.46205"
"56.00000","0.93148","319.19867","1.05593","-0.14819","0.00474","177.37611"
"56.40000","0.93807","320.73672","1.06242","-0.14170","0.00477","178.23079"
"56.80000","0.94465","322.34979","1.06889","-0.13523","0.00480","179.12717"
"57.20000","0.95151","323.88052","1.07565","-0.12847","0.00483","179.97778"
"57.60000","0.95856","325.72568","1.08258","-0.12154","0.00486","181.00311"
"58.00000","0.96497","327.18671","1.08889","-0.11523","0.00489","181.81500"
"58.40000","0.97161","328.83600","1.09542","-0.10870","0.00492","182.73149"
"58.80000","0.97807","330.40878","1.10177","-0.10235","0.00495","183.60548"
"59.20000","0.98471","331.97845","1.10831","-0.09581","0.00498","184.47774"
"59.60000","0.99142","333.62323","1.11491","-0.08921","0.00501","185.39172"
"60.00000","0.99833","335.24976","1.12170","-0.08242","0.00504","186.29556"
"60.40000","1.00510","336.92191","1.12836","-0.07575","0.00507","187.22476"
"60.80000","1.01153","338.29208","1.13470","-0.06942","0.00510","187.98616"
"61.20000","1.01818","339.91348","1.14125","-0.06287","0.00513","188.88716"
"61.60000","1.02469","341.38232","1.14766","-0.05646","0.00515","189.70338"
"62.00000","1.03145","342.93170","1.15432","-0.04980","0.00518","190.56436"
"62.40000","1.03845","344.68457","1.16121","-0.04291","0.00521","191.53842"
"62.80000","1.04500","346.11334","1.16766","-0.03646","0.00524","192.33238"
"63.20000","1.05164","347.52368","1.17421","-0.02991","0.00527","193.11609"
"63.60000","1.05809","349.07690","1.18057","-0.02355","0.00530","193.97920"
"64.00000","1.06472","350.63242","1.18710","-0.01702","0.00533","194.84358"
"64.40000","1.07141","352.06140","1.19369","-0.01043","0.00536","195.63766"
"64.80000","1.07834","353.66559","1.20052","-0.00360","0.00539","196.52910"
"65.20000","1.08519","355.21881","1.20727","0.00315","0.00542","197.39221"
"65.60000","1.09155","356.55869","1.21354","0.00943","0.00545","198.13676"
"66.00000","1.09818","358.11887","1.22008","0.01596","0.00548","199.00375"
"66.40000","1.10469","359.45688","1.22650","0.02238","0.00551","199.74727"
"66.80000","1.11136","360.92316","1.23307","0.02895","0.00554","200.56207"
"67.20000","1.11832","362.44391","1.23994","0.03582","0.00557","201.40714"
"67.60000","1.12510","364.04532","1.24661","0.04249","0.00560","202.29703"
"68.00000","1.13176","365.29047","1.25320","0.04908","0.00563","202.98895"
"68.40000","1.13814","366.67908","1.25949","0.05537","0.00566","203.76059"
"68.80000","1.14473","368.19641","1.26597","0.06186","0.00569","204.60376"
"69.20000","1.15132","369.56433","1.27248","0.06836","0.00571","205.36391"
"69.60000","1.15817","371.07108","1.27923","0.07511","0.00574","206.20119"
"70.00000","1.16523","372.64319","1.28619","0.08207","0.00578","207.07480"
"70.40000","1.17162","373.83936","1.29251","0.08839","0.00580","207.73950"
"70.80000","1.17822","375.06552","1.29902","0.09491","0.00583","208.42087"
"71.20000","1.18477","376.41022","1.30549","0.10137","0.00586","209.16811"
"71.60000","1.19138","377.78378","1.31201","0.10790","0.00589","209.93138"
"72.00000","1.19815","379.23096","1.31869","0.11457","0.00592","210.73557"
"72.40000","1.20500","380.61139","1.32545","0.12133","0.00595","211.50266"
"72.80000","1.21181","382.00192","1.33217","0.12805","0.00598","212.27538"
"73.20000","1.21814","382.82239","1.33845","0.13433","0.00601","212.73129"
"73.60000","1.22483","384.03619","1.34506","0.14094","0.00604","213.40579"
"74.00000","1.23131","385.37134","1.35146","0.14734","0.00607","214.14772"
"74.40000","1.23814","386.74176","1.35820","0.15408","0.00610","214.90926"
"74.80000","1.24518","388.20627","1.36514","0.16102","0.00613","215.72307"
"75.20000","1.25173","389.41550","1.37162","0.16750","0.00616","216.39503"
"75.60000","1.25833","390.74658","1.37814","0.17402","0.00619","217.13470"
"76.00000","1.26478","392.09155","1.38452","0.18040","0.00622","217.88210"
"76.40000","1.27139","393.24030","1.39106","0.18695","0.00625","218.52045"
"76.80000","1.27802","394.57632","1.39761","0.19349","0.00628","219.26286"
"77.20000","1.28492","396.00064","1.40444","0.20032","0.00631","220.05434"
"77.60000","1.29189","397.35092","1.41132","0.20721","0.00634","220.80469"
"78.00000","1.29824","398.67535","1.41760","0.21349","0.00637","221.54066"
"78.40000","1.30487","399.81961","1.42417","0.22005","0.00640","222.17651"
"78.80000","1.31136","401.00287","1.43059","0.22647","0.00642","222.83405"
"79.20000","1.31807","402.33331","1.43722","0.23310","0.00645","223.57336"
"79.60000","1.32497","403.55121","1.44405","0.23994","0.00648","224.25014"
"80.00000","1.33172","404.74414","1.45074","0.24662","0.00651","224.91304"
"80.40000","1.33837","405.71875","1.45733","0.25321","0.00654","225.45462"
"80.80000","1.34479","406.65897","1.46369","0.25957","0.00657","225.97708"
"81.20000","1.35140","407.75494","1.47024","0.26612","0.00660","226.58612"
"81.60000","1.35797","408.69373","1.47676","0.27264","0.00663","227.10779"
"82.00000","1.36487","409.92993","1.48359","0.27947","0.00666","227.79474"
"82.40000","1.37190","410.97778","1.49056","0.28644","0.00669","228.37701"
"82.80000","1.37834","411.93558","1.49695","0.29283","0.00672","228.90926"
"83.20000","1.38490","412.67966","1.50347","0.29935","0.00675","229.32274"
"83.60000","1.39138","413.41879","1.50990","0.30578","0.00678","229.73347"
"84.00000","1.39800","414.45532","1.51646","0.31234","0.00681","230.30946"
"84.40000","1.40478","415.23495","1.52319","0.31907","0.00684","230.74269"
"84.80000","1.41170","415.77042","1.53008","0.32596","0.00687","231.04025"
"85.20000","1.41845","416.48853","1.53679","0.33267","0.00690","231.43930"
"85.60000","1.42490","416.98770","1.54321","0.33910","0.00693","231.71667"
"86.00000","1.43147","417.59583","1.54975","0.34563","0.00696","232.05461"
"86.40000","1.43800","418.36224","1.55624","0.35212","0.00699","232.48050"
"86.80000","1.44476","418.90060","1.56296","0.35885","0.00702","232.77966"
"87.20000","1.45182","419.81247","1.56997","0.36586","0.00705","233.28638"
"87.60000","1.45829","420.23291","1.57642","0.37231","0.00708","233.52002"
"88.00000","1.46497","420.41916","1.58309","0.37897","0.00711","233.62352"
"88.40000","1.47143","420.68240","1.58953","0.38542","0.00714","233.76979"
"88.80000","1.47808","420.14340","1.59622","0.39210","0.00717","233.47028"
"89.20000","1.48475","419.75208","1.60291","0.39879","0.00720","233.25282"
"89.60000","1.49159","419.60828","1.60976","0.40564","0.00723","233.17291"
"90.00000","1.49857","419.55331","1.61674","0.41262","0.00726","233.14236"
"90.40000","1.50487","419.53729","1.62304","0.41892","0.00729","233.13347"
"90.80000","1.51152","419.84000","1.62968","0.42556","0.00732","233.30168"
"91.20000","1.51797","419.98730","1.63611","0.43199","0.00735","233.38353"
"91.60000","1.52474","420.56967","1.64285","0.43873","0.00738","233.70715"
"92.00000","1.53165","421.09863","1.64973","0.44561","0.00741","234.00110"
"92.40000","1.53839","421.39926","1.65646","0.45234","0.00744","234.16815"
"92.80000","1.54507","421.55829","1.66313","0.45901","0.00747","234.25652"
"93.20000","1.55145","420.21591","1.66958","0.46547","0.00750","233.51057"
"93.60000","1.55807","417.25314","1.67637","0.47225","0.00753","231.86418"
"94.00000","1.56463","416.05295","1.68300","0.47888","0.00756","231.19725"
"94.40000","1.57154","414.84073","1.68998","0.48586","0.00759","230.52362"
"94.80000","1.57849","411.70358","1.69711","0.49299","0.00762","228.78033"
"95.20000","1.58499","408.90482","1.70377","0.49965","0.00765","227.22508"
"95.60000","1.59156","406.82037","1.71046","0.50634","0.00768","226.06679"
"96.00000","1.59804","405.44086","1.71701","0.51289","0.00771","225.30020"
"96.40000","1.60471","403.92355","1.72377","0.51966","0.00774","224.45705"
"96.80000","1.61148","403.31445","1.73057","0.52645","0.00777","224.11858"
"97.20000","1.61836","402.77844","1.73749","0.53337","0.00780","223.82071"
"97.60000","1.62508","401.99911","1.74426","0.54014","0.00783","223.38765"
"98.00000","1.63154","401.26523","1.75076","0.54664","0.00786","222.97983"
"98.40000","1.63808","401.04547","1.75730","0.55319","0.00789","222.85771"
"98.80000","1.64464","398.37552","1.76402","0.55990","0.00792","221.37404"
"99.20000","1.65142","397.71191","1.77084","0.56672","0.00795","221.00528"
"99.60000","1.65854","397.64517","1.77796","0.57384","0.00798","220.96820"
"100.00000","1.66505","397.59125","1.78447","0.58035","0.00801","220.93823"
"100.40000","1.67159","397.70068","1.79100","0.58689","0.00804","220.99904"
"100.80000","1.67810","397.87180","1.79751","0.59339","0.00807","221.09413"
"101.20000","1.68471","398.02884","1.80411","0.59999","0.00810","221.18140"
"101.60000","1.69139","398.41006","1.81077","0.60665","0.00813","221.39323"
"102.00000","1.69825","398.67029","1.81761","0.61349","0.00816","221.53784"
"102.40000","1.70517","399.23331","1.82449","0.62038","0.00819","221.85071"
"102.80000","1.71157","399.44550","1.83088","0.62676","0.00822","221.96863"
"103.20000","1.71821","399.75974","1.83751","0.63339","0.00825","222.14323"
"103.60000","1.72468","400.12103","1.84396","0.63984","0.00828","222.34401"
"104.00000","1.73136","400.54834","1.85062","0.64650","0.00831","222.58147"
"104.40000","1.73839","401.01675","1.85762","0.65350","0.00834","222.84175"
"104.80000","1.74496","401.30756","1.86417","0.66005","0.00837","223.00336"
"105.20000","1.75167","401.73563","1.87086","0.66674","0.00840","223.24123"
"105.60000","1.75810","401.95462","1.87728","0.67316","0.00843","223.36292"
"106.00000","1.76478","402.37646","1.88393","0.67981","0.00846","223.59734"
"106.40000","1.77133","402.82370","1.89045","0.68633","0.00849","223.84586"
"106.80000","1.77823","403.08102","1.89734","0.69322","0.00852","223.98886"
"107.20000","1.78521","403.51804","1.90430","0.70018","0.00855","224.23170"
"107.60000","1.79160","403.66635","1.91067","0.70655","0.00858","224.31412"
"108.00000","1.79823","404.03552","1.91729","0.71317","0.00861","224.51926"
"108.40000","1.80466","404.04517","1.92372","0.71960","0.00864","224.52461"
"108.80000","1.81138","404.41412","1.93041","0.72629","0.00867","224.72964"
"109.20000","1.81818","404.66931","1.93720","0.73308","0.00870","224.87146"
"109.60000","1.82512","404.98398","1.94412","0.74000","0.00873","225.04631"
"110.00000","1.83177","405.33942","1.95075","0.74663","0.00876","225.24382"
"110.40000","1.83817","405.57370","1.95713","0.75302","0.00879","225.37401"
"110.80000","1.84480","405.74878","1.96376","0.75964","0.00882","225.47130"
"111.20000","1.85129","405.95532","1.97023","0.76611","0.00885","225.58607"
"111.60000","1.85811","406.35449","1.97703","0.77291","0.00888","225.80789"
"112.00000","1.86515","406.81842","1.98405","0.77993","0.00891","226.06569"
"112.40000","1.87174","407.12134","1.99061","0.78650","0.00894","226.23402"
"112.80000","1.87824","407.31900","1.99710","0.79299","0.00897","226.34386"
"113.20000","1.88478","407.69046","2.00363","0.79951","0.00900","226.55028"
"113.60000","1.89135","408.00943","2.01018","0.80606","0.00903","226.72752"
"114.00000","1.89808","408.43747","2.01688","0.81276","0.00906","226.96539"
"114.40000","1.90494","408.71561","2.02373","0.81961","0.00909","227.11995"
"114.80000","1.91184","409.10510","2.03060","0.82648","0.00912","227.33638"
"115.20000","1.91822","409.20749","2.03698","0.83286","0.00915","227.39328"
"115.60000","1.92485","409.49374","2.04359","0.83947","0.00918","227.55235"
"116.00000","1.93133","409.69342","2.05007","0.84595","0.00921","227.66331"
"116.40000","1.93803","409.95801","2.05674","0.85262","0.00924","227.81033"
"116.80000","1.94507","410.41574","2.06376","0.85964","0.00927","228.06470"
"117.20000","1.95172","410.71112","2.07039","0.86627","0.00930","228.22884"
"117.60000","1.95834","410.96368","2.07700","0.87289","0.00933","228.36919"
"118.00000","1.96477","411.07642","2.08343","0.87931","0.00936","228.43182"
"118.40000","1.97142","411.37881","2.09006","0.88594","0.00939","228.59987"
"118.80000","1.97797","411.69324","2.09659","0.89247","0.00942","228.77460"
"119.20000","1.98485","412.04425","2.10344","0.89933","0.00945","228.96965"
"119.60000","1.99186","412.43091","2.11043","0.90632","0.00948","229.18451"
"120.00000","1.99824","412.62656","2.11681","0.91269","0.00951","229.29323"
"120.40000","2.00492","412.97296","2.12346","0.91935","0.00954","229.48572"
"120.80000","2.01138","412.99066","2.12992","0.92580","0.00956","229.49556"
"121.20000","2.01801","413.18219","2.13655","0.93243","0.00959","229.60199"
"121.60000","2.02486","413.45468","2.14337","0.93926","0.00963","229.75342"
"122.00000","2.03170","413.66849","2.15021","0.94609","0.00966","229.87222"
"122.40000","2.03843","413.70233","2.15694","0.95282","0.00969","229.89102"
"122.80000","2.04479","413.70798","2.16330","0.95918","0.00971","229.89417"
"123.20000","2.05145","413.60654","2.16996","0.96584","0.00974","229.83780"
"123.60000","2.05795","413.42435","2.17647","0.97235","0.00977","229.73656"
"124.00000","2.06478","413.27072","2.18331","0.97919","0.00980","229.65118"
"124.40000","2.07177","413.32556","2.19030","0.98618","0.00984","229.68166"
"124.80000","2.07841","413.08063","2.19695","0.99283","0.00987","229.54555"
"125.20000","2.08494","412.80444","2.20349","0.99938","0.00990","229.39207"
"125.60000","2.09139","412.53604","2.20996","1.00584","0.00992","229.24294"
"126.00000","2.09802","412.44083","2.21660","1.01248","0.00995","229.19002"
"126.40000","2.10474","412.05817","2.22334","1.01922","0.00998","228.97739"
"126.80000","2.11165","412.06223","2.23025","1.02613","0.01002","228.97963"
"127.20000","2.11849","411.91724","2.23710","1.03298","0.01005","228.89906"
"127.60000","2.12492","411.70410","2.24354","1.03942","0.01008","228.78062"
"128.00000","2.13151","411.49530","2.25014","1.04602","0.01010","228.66460"
"128.40000","2.13802","411.29333","2.25666","1.05254","0.01013","228.55237"
"128.80000","2.14470","411.11450","2.26335","1.05924","0.01016","228.45299"
"129.20000","2.15167","411.18320","2.27032","1.06620","0.01020","228.49117"
"129.60000","2.15838","411.11600","2.27704","1.07292","0.01023","228.45383"
"130.00000","2.16503","411.03043","2.28369","1.07957","0.01026","228.40627"
"130.40000","2.17146","410.85962","2.29013","1.08601","0.01028","228.31136"
"130.80000","2.17808","410.74707","2.29675","1.09263","0.01031","228.24881"
"131.20000","2.18473","410.80774","2.30340","1.09928","0.01034","228.28253"
"131.60000","2.19150","410.82278","2.31017","1.10605","0.01037","228.29089"
"132.00000","2.19851","411.01990","2.31717","1.11305","0.01041","228.40042"
"132.40000","2.20486","410.83844","2.32353","1.11941","0.01043","228.29959"
"132.80000","2.21157","410.79001","2.33024","1.12613","0.01046","228.27267"
"133.20000","2.21804","410.78720","2.33671","1.13259","0.01049","228.27112"
"133.60000","2.22470","410.74097","2.34338","1.13926","0.01052","228.24542"
"134.00000","2.23158","410.82706","2.35025","1.14613","0.01055","228.29326"
"134.40000","2.23838","410.65573","2.35705","1.15294","0.01058","228.19806"
"134.80000","2.24509","410.73257","2.36377","1.15965","0.01062","228.24075"
"135.20000","2.25148","410.50394","2.37017","1.16605","0.01064","228.11371"
"135.60000","2.25808","410.29590","2.37678","1.17266","0.01067","227.99811"
"136.00000","2.26462","410.20227","2.38333","1.17921","0.01070","227.94608"
"136.40000","2.27150","410.04825","2.39021","1.18609","0.01073","227.86049"
"136.80000","2.27851","410.07785","2.39722","1.19310","0.01077","227.87694"
"137.20000","2.28502","409.68716","2.40375","1.19963","0.01079","227.65984"
"137.60000","2.29165","409.51245","2.41039","1.20627","0.01082","227.56274"
"138.00000","2.29805","409.20175","2.41682","1.21270","0.01085","227.39009"
"138.40000","2.30467","408.93979","2.42345","1.21933","0.01088","227.24452"
"138.80000","2.31141","408.89490","2.43019","1.22607","0.01091","227.21957"
"139.20000","2.31837","408.80093","2.43715","1.23304","0.01094","227.16736"
"139.60000","2.32513","408.62552","2.44393","1.23981","0.01098","227.06989"
"140.00000","2.33153","408.36288","2.45034","1.24622","0.01100","226.92393"
"140.40000","2.33815","408.22107","2.45697","1.25285","0.01103","226.84514"
"140.80000","2.34467","407.91159","2.46351","1.25939","0.01106","226.67316"
"141.20000","2.35138","407.95743","2.47022","1.26610","0.01109","226.69864"
"141.60000","2.35841","407.93973","2.47724","1.27312","0.01112","226.68880"
"142.00000","2.36508","407.94440","2.48391","1.27979","0.01115","226.69139"
"142.40000","2.37166","407.74039","2.49050","1.28638","0.01118","226.57802"
"142.80000","2.37812","407.54919","2.49698","1.29286","0.01121","226.47179"
"143.20000","2.38470","407.66965","2.50355","1.29943","0.01124","226.53871"
"143.60000","2.39132","407.61832","2.51017","1.30605","0.01127","226.51019"
"144.00000","2.39823","407.71066","2.51708","1.31296","0.01130","226.56151"
"144.40000","2.40525","407.77274","2.52409","1.31997","0.01134","226.59599"
"144.80000","2.41160","407.76605","2.53045","1.32633","0.01136","226.59229"
"145.20000","2.41825","407.56091","2.53710","1.33298","0.01139","226.47829"
"145.60000","2.42471","407.60516","2.54356","1.33945","0.01142","226.50288"
"146.00000","2.43137","407.60764","2.55022","1.34610","0.01145","226.50426"
"146.40000","2.43820","407.66205","2.55705","1.35293","0.01148","226.53448"
"146.80000","2.44501","407.74905","2.56385","1.35973","0.01151","226.58284"
"147.20000","2.45173","407.64633","2.57058","1.36646","0.01154","226.52576"
"147.60000","2.45817","407.66089","2.57701","1.37290","0.01157","226.53384"
"148.00000","2.46480","407.53168","2.58366","1.37954","0.01160","226.46205"
"148.40000","2.47134","407.49557","2.59019","1.38608","0.01163","226.44199"
"148.80000","2.47817","407.51132","2.59703","1.39291","0.01166","226.45073"
"149.20000","2.48518","407.53287","2.60404","1.39992","0.01169","226.46271"
"149.60000","2.49163","407.49973","2.61049","1.40637","0.01172","226.44429"
"150.00000","2.49825","407.34018","2.61712","1.41300","0.01175","226.35564"
"150.40000","2.50474","407.09521","2.62362","1.41950","0.01178","226.21951"
"150.80000","2.51137","406.90332","2.63026","1.42614","0.01181","226.11287"
"151.20000","2.51812","406.76794","2.63702","1.43290","0.01184","226.03764"
"151.60000","2.52509","406.82721","2.64398","1.43986","0.01187","226.07057"
"152.00000","2.53186","406.73032","2.65076","1.44664","0.01190","226.01674"
"152.40000","2.53819","406.49786","2.65710","1.45299","0.01193","225.88756"
"152.80000","2.54482","406.51035","2.66373","1.45961","0.01196","225.89450"
"153.20000","2.55133","406.42667","2.67025","1.46613","0.01199","225.84801"
"153.60000","2.55804","406.41129","2.67696","1.47284","0.01202","225.83945"
"154.00000","2.56507","406.58234","2.68398","1.47987","0.01205","225.93451"
"154.40000","2.57174","406.54340","2.69065","1.48654","0.01208","225.91287"
"154.80000","2.57837","406.62363","2.69727","1.49316","0.01211","225.95744"
"155.20000","2.58479","406.59830","2.70370","1.49959","0.01214","225.94337"
"155.60000","2.59137","406.72437","2.71027","1.50616","0.01217","226.01343"
"156.00000","2.59799","406.65521","2.71690","1.51278","0.01220","225.97501"
"156.40000","2.60491","406.88733","2.72380","1.51968","0.01223","226.10399"
"156.80000","2.61190","407.11261","2.73078","1.52666","0.01226","226.22917"
"157.20000","2.61825","407.23108","2.73712","1.53300","0.01229","226.29501"
"157.60000","2.62486","407.22214","2.74373","1.53961","0.01232","226.29004"
"158.00000","2.63140","407.32526","2.75027","1.54615","0.01235","226.34734"
"158.40000","2.63805","407.35699","2.75692","1.55280","0.01238","226.36497"
"158.80000","2.64491","407.52496","2.76376","1.55965","0.01241","226.45831"
"159.20000","2.65168","407.64966","2.77053","1.56641","0.01244","226.52760"
"159.60000","2.65843","407.78690","2.77727","1.57316","0.01247","226.60387"
"160.00000","2.66479","407.75534","2.78363","1.57951","0.01250","226.58633"
"160.40000","2.67146","407.86932","2.79029","1.58617","0.01253","226.64967"
"160.80000","2.67798","407.90021","2.79681","1.59269","0.01256","226.66684"
"161.20000","2.68484","408.01404","2.80367","1.59955","0.01259","226.73009"
"161.60000","2.69185","408.17029","2.81067","1.60655","0.01262","226.81691"
"162.00000","2.69835","408.12482","2.81717","1.61305","0.01265","226.79164"
"162.40000","2.70497","408.26605","2.82378","1.61966","0.01268","226.87013"
"162.80000","2.71143","408.12073","2.83025","1.62613","0.01271","226.78938"
"163.20000","2.71805","408.18268","2.83687","1.63276","0.01274","226.82381"
"163.60000","2.72477","408.36353","2.84358","1.63946","0.01277","226.92430"
"164.00000","2.73162","408.40817","2.85043","1.64631","0.01280","226.94911"
"164.40000","2.73851","408.44598","2.85732","1.65320","0.01283","226.97012"
"164.80000","2.74487","408.47375","2.86367","1.65955","0.01286","226.98555"
"165.20000","2.75150","408.44897","2.87030","1.66618","0.01289","226.97179"
"165.60000","2.75801","408.55841","2.87681","1.67269","0.01292","227.03259"
"166.00000","2.76478","408.49756","2.88358","1.67946","0.01295","226.99878"
"166.40000","2.77174","408.65460","2.89053","1.68642","0.01298","227.08604"
"166.80000","2.77836","408.70868","2.89715","1.69303","0.01301","227.11609"
"167.20000","2.78499","408.69113","2.90378","1.69966","0.01304","227.10634"
"167.60000","2.79144","408.65298","2.91023","1.70611","0.01307","227.08514"
"168.00000","2.79802","408.72791","2.91681","1.71269","0.01310","227.12679"
"168.40000","2.80467","408.66266","2.92346","1.71934","0.01313","227.09053"
"168.80000","2.81163","408.79779","2.93042","1.72630","0.01316","227.16562"
"169.20000","2.81857","409.03391","2.93734","1.73323","0.01319","227.29683"
"169.60000","2.82495","408.93698","2.94373","1.73961","0.01322","227.24297"
"170.00000","2.83152","409.04028","2.95029","1.74617","0.01325","227.30037"
"170.40000","2.83802","408.95245","2.95680","1.75268","0.01328","227.25156"
"170.80000","2.84467","408.99612","2.96344","1.75932","0.01331","227.27583"
"171.20000","2.85157","408.96744","2.97034","1.76622","0.01334","227.25989"
"171.60000","2.85841","409.27673","2.97716","1.77304","0.01337","227.43176"
"172.00000","2.86504","409.23581","2.98380","1.77968","0.01340","227.40901"
"172.40000","2.87154","409.08148","2.99031","1.78619","0.01343","227.32326"
"172.80000","2.87811","408.95917","2.99689","1.79277","0.01346","227.25529"
"173.20000","2.88466","408.96484","3.00344","1.79932","0.01349","227.25844"
"173.60000","2.89146","408.91953","3.01024","1.80612","0.01352","227.23326"
"174.00000","2.89855","409.12088","3.01731","1.81320","0.01355","227.34515"
"174.40000","2.90492","408.94025","3.02369","1.81958","0.01358","227.24478"
"174.80000","2.91160","409.02942","3.03037","1.82625","0.01361","227.29433"
"175.20000","2.91806","408.88022","3.03684","1.83272","0.01364","227.21143"
"175.60000","2.92474","408.90323","3.04352","1.83940","0.01367","227.22421"
"176.00000","2.93152","408.99817","3.05029","1.84617","0.01370","227.27696"
"176.40000","2.93833","408.96564","3.05710","1.85298","0.01373","227.25888"
"176.80000","2.94516","409.00027","3.06394","1.85982","0.01376","227.27814"
"177.20000","2.95150","408.82407","3.07029","1.86617","0.01379","227.18022"
"177.60000","2.95817","408.76392","3.07696","1.87284","0.01382","227.14679"
"178.00000","2.96461","408.68808","3.08340","1.87928","0.01385","227.10464"
"178.40000","2.97142","408.68073","3.09021","1.88609","0.01388","227.10056"
"178.80000","2.97846","408.89090","3.09723","1.89312","0.01391","227.21736"
"179.20000","2.98507","408.76007","3.10385","1.89973","0.01394","227.14465"
"179.60000","2.99169","408.63333","3.11049","1.90637","0.01397","227.07422"
"180.00000","2.99808","408.54556","3.11688","1.91276","0.01400","227.02545"
"180.40000","3.00471","408.54364","3.12351","1.91939","0.01403","227.02438"
"180.80000","3.01133","408.35474","3.13014","1.92602","0.01406","226.91942"
"181.20000","3.01828","408.36682","3.13709","1.93297","0.01409","226.92613"
"181.60000","3.02516","408.32092","3.14397","1.93985","0.01412","226.90062"
"182.00000","3.03160","408.02838","3.15042","1.94630","0.01415","226.73807"
"182.40000","3.03820","407.89215","3.15704","1.95292","0.01418","226.66235"
"182.80000","3.04466","407.74741","3.16351","1.95939","0.01421","226.58192"
"183.20000","3.05136","407.62256","3.17021","1.96610","0.01424","226.51254"
"183.60000","3.05825","407.59418","3.17711","1.97299","0.01427","226.49678"
"184.00000","3.06509","407.54214","3.18395","1.97983","0.01430","226.46786"
"184.40000","3.07170","407.26074","3.19057","1.98645","0.01433","226.31149"
"184.80000","3.07817","406.95261","3.19706","1.99294","0.01436","226.14026"
"185.20000","3.08471","406.77264","3.20360","1.99949","0.01439","226.04025"
"185.60000","3.09131","406.51117","3.21022","2.00610","0.01442","225.89496"
"186.00000","3.09814","406.27615","3.21707","2.01295","0.01445","225.76436"
"186.40000","3.10525","406.30829","3.22418","2.02006","0.01448","225.78221"
"186.80000","3.11168","405.89386","3.23063","2.02651","0.01451","225.55193"
"187.20000","3.11822","405.53790","3.23719","2.03307","0.01454","225.35413"
"187.60000","3.12475","405.33078","3.24373","2.03961","0.01457","225.23903"
"188.00000","3.13137","405.03381","3.25037","2.04625","0.01460","225.07401"
"188.40000","3.13811","404.73141","3.25712","2.05300","0.01463","224.90596"
"188.80000","3.14495","404.48514","3.26398","2.05986","0.01466","224.76910"
"189.20000","3.15182","404.28635","3.27086","2.06674","0.01469","224.65865"
"189.60000","3.15819","403.59460","3.27727","2.07316","0.01472","224.27425"
"190.00000","3.16484","403.11954","3.28395","2.07983","0.01475","224.01025"
"190.40000","3.17135","402.09763","3.29051","2.08640","0.01478","223.44238"
"190.80000","3.17805","399.91504","3.29734","2.09322","0.01481","222.22954"
"191.20000","3.18514","398.01929","3.30454","2.10042","0.01484","221.17609"
"191.60000","3.19161","396.67996","3.31108","2.10696","0.01487","220.43184"
"192.00000","3.19830","396.13269","3.31781","2.11369","0.01490","220.12772"
"192.40000","3.20474","395.61694","3.32428","2.12016","0.01493","219.84113"
"192.80000","3.21142","395.22559","3.33098","2.12686","0.01496","219.62366"
"193.20000","3.21805","395.10379","3.33761","2.13349","0.01499","219.55597"
"193.60000","3.22495","394.63904","3.34454","2.14042","0.01502","219.29771"
"194.00000","3.23186","394.48273","3.35146","2.14734","0.01505","219.21085"
"194.40000","3.23823","394.18005","3.35784","2.15372","0.01508","219.04266"
"194.80000","3.24486","394.05441","3.36448","2.16036","0.01511","218.97284"
"195.20000","3.25130","393.53873","3.37095","2.16683","0.01514","218.68628"
"195.60000","3.25807","393.48499","3.37773","2.17361","0.01517","218.65642"
"196.00000","3.26495","393.37790","3.38461","2.18049","0.01520","218.59691"
"196.40000","3.27178","393.24817","3.39145","2.18733","0.01523","218.52481"
"196.80000","3.27837","393.15131","3.39805","2.19393","0.01526","218.47099"
"197.20000","3.28480","393.03653","3.40449","2.20037","0.01529","218.40721"
"197.60000","3.29144","392.89334","3.41113","2.20701","0.01532","218.32764"
"198.00000","3.29797","392.70697","3.41767","2.21355","0.01535","218.22408"
"198.40000","3.30485","392.86264","3.42454","2.22042","0.01538","218.31058"
"198.80000","3.31184","392.67493","3.43154","2.22742","0.01541","218.20627"
"199.20000","3.31834","392.40836","3.43806","2.23394","0.01544","218.05814"
"199.60000","3.32486","392.12912","3.44460","2.24048","0.01547","217.90297"
"200.00000","3.33142","392.00311","3.45116","2.24704","0.01550","217.83295"
"200.40000","3.33801","391.90656","3.45776","2.25364","0.01553","217.77930"
"200.80000","3.34484","391.97760","3.46458","2.26046","0.01556","217.81877"
"201.20000","3.35166","391.99261","3.47141","2.26729","0.01559","217.82712"
"201.60000","3.35844","392.08951","3.47818","2.27406","0.01562","217.88095"
"202.00000","3.36486","391.82590","3.48461","2.28049","0.01565","217.73447"
"202.40000","3.37148","391.85657","3.49123","2.28711","0.01568","217.75151"
"202.80000","3.37798","391.74487","3.49773","2.29362","0.01571","217.68945"
"203.20000","3.38472","391.97983","3.50446","2.30035","0.01574","217.82001"
"203.60000","3.39182","391.77908","3.51158","2.30746","0.01577","217.70845"
"204.00000","3.39836","391.84415","3.51811","2.31399","0.01580","217.74461"
"204.40000","3.40497","391.61832","3.52474","2.32062","0.01583","217.61913"
"204.80000","3.41141","391.45392","3.53119","2.32707","0.01586","217.52777"
"205.20000","3.41806","391.34109","3.53784","2.33372","0.01589","217.46507"
"205.60000","3.42469","391.29709","3.54447","2.34035","0.01592","217.44061"
"206.00000","3.43156","391.32669","3.55134","2.34722","0.01595","217.45706"
"206.40000","3.43850","391.29727","3.55828","2.35416","0.01598","217.44072"
"206.80000","3.44486","390.98788","3.56466","2.36055","0.01601","217.26880"
"207.20000","3.45155","390.95935","3.57135","2.36723","0.01604","217.25294"
"207.60000","3.45801","390.81998","3.57782","2.37370","0.01607","217.17549"
"208.00000","3.46470","390.70966","3.58451","2.38039","0.01610","217.11418"
"208.40000","3.47163","390.69370","3.59144","2.38733","0.01613","217.10532"
"208.80000","3.47839","390.71027","3.59820","2.39408","0.01616","217.11452"
"209.20000","3.48506","390.65973","3.60488","2.40076","0.01619","217.08644"
"209.60000","3.49142","390.38525","3.61125","2.40714","0.01622","216.93391"
"210.00000","3.49807","390.04263","3.61792","2.41380","0.01625","216.74353"
"210.40000","3.50461","389.89246","3.62447","2.42036","0.01628","216.66008"
"210.80000","3.51153","389.86380","3.63139","2.42728","0.01631","216.64415"
"211.20000","3.51850","389.79739","3.63837","2.43425","0.01634","216.60725"
"211.60000","3.52502","389.52151","3.64490","2.44079","0.01637","216.45395"
"212.00000","3.53158","389.55890","3.65146","2.44734","0.01640","216.47472"
"212.40000","3.53802","389.35648","3.65791","2.45379","0.01643","216.36223"
"212.80000","3.54467","389.21750","3.66457","2.46045","0.01646","216.28500"
"213.20000","3.55150","389.10339","3.67140","2.46729","0.01649","216.22160"
"213.60000","3.55839","388.88962","3.67831","2.47419","0.01652","216.10280"
"214.00000","3.56511","388.72617","3.68504","2.48092","0.01655","216.01198"
"214.40000","3.57156","388.26276","3.69152","2.48740","0.01658","215.75446"
"214.80000","3.57813","388.00241","3.69811","2.49399","0.01661","215.60979"
"215.20000","3.58466","387.65521","3.70466","2.50054","0.01664","215.41685"
"215.60000","3.59138","387.46625","3.71139","2.50727","0.01667","215.31184"
"216.00000","3.59846","387.27066","3.71848","2.51436","0.01670","215.20317"
"216.40000","3.60503","386.00940","3.72513","2.52101","0.01673","214.50229"
"216.80000","3.61165","384.45767","3.73185","2.52773","0.01676","213.64001"
"217.20000","3.61811","383.26114","3.73839","2.53427","0.01679","212.97510"
"217.60000","3.62471","382.07529","3.74507","2.54095","0.01682","212.31613"
"218.00000","3.63141","380.86688","3.75185","2.54773","0.01685","211.64464"
"218.40000","3.63823","379.85486","3.75873","2.55461","0.01688","211.08226"
"218.80000","3.64516","379.36423","3.76569","2.56158","0.01691","210.80962"
"219.20000","3.65152","378.81961","3.77209","2.56797","0.01694","210.50699"
"219.60000","3.65821","378.51300","3.77880","2.57468","0.01697","210.33661"
"220.00000","3.66467","377.98386","3.78529","2.58117","0.01700","210.04256"
"220.40000","3.67138","377.55942","3.79203","2.58791","0.01703","209.80670"
"220.80000","3.67836","376.88251","3.79905","2.59493","0.01706","209.43056"
"221.20000","3.68505","366.61530","3.80639","2.60228","0.01709","203.72514"
"221.60000","3.69171","358.80826","3.81356","2.60944","0.01713","199.38684"
"222.00000","3.69812","357.25638","3.82007","2.61595","0.01715","198.52448"
"222.40000","3.70472","356.46732","3.82672","2.62260","0.01718","198.08600"
"222.80000","3.71130","355.68839","3.83335","2.62923","0.01721","197.65315"
"223.20000","3.71818","355.18112","3.84027","2.63615","0.01725","197.37126"
"223.60000","3.72518","355.19797","3.84726","2.64314","0.01728","197.38063"
"224.00000","3.73164","354.94406","3.85374","2.64962","0.01731","197.23953"
"224.40000","3.73827","354.90652","3.86037","2.65626","0.01734","197.21867"
"224.80000","3.74469","354.92157","3.86679","2.66267","0.01736","197.22704"
"225.20000","3.75135","355.13641","3.87344","2.66932","0.01739","197.34642"
"225.60000","3.75814","355.46933","3.88020","2.67608","0.01742","197.53142"
"226.00000","3.76508","355.92059","3.88711","2.68299","0.01746","197.78218"
"226.40000","3.77175","356.39453","3.89376","2.68964","0.01749","198.04555"
"226.80000","3.77816","356.49811","3.90016","2.69604","0.01751","198.10310"
"227.20000","3.78479","356.81985","3.90677","2.70265","0.01754","198.28189"
"227.60000","3.79135","357.12973","3.91330","2.70919","0.01757","198.45409"
"228.00000","3.79808","357.63400","3.92000","2.71588","0.01760","198.73431"
"228.40000","3.80517","358.21631","3.92706","2.72294","0.01764","199.05789"
"228.69600","3.80972","358.24133","3.93160","2.72749","0.01766","199.07181"