File: flexion/3_axis/Specimen_RawData_3.csv
Specimen properties : Specimen label,"3"
Specimen properties : Support span,"72.00",mm
Specimen properties : Thickness,"3.87",mm
Specimen properties : Width,"12.87",mm
Maximum Load : Maximum Load,"471.5",N
Tangent Modulus of Elasticity : Tangent Modulus of Elasticity,"42144202293.70180",Pa
Test : Rate 1,"1.00000",mm/min
Specimen notes : Specimen note 1,""

Time,Displacement,Load,Flexure extension,Corrected extension,Flexure strain (Corrected extension),Flexure stress
(s),(mm),(N),(mm),(mm),(mm/mm),(MPa)
"0.00000","0.00000","48.63700","0.14381","-1.05552","0.00064","27.25148"
"0.50000","0.00659","50.94440","0.15009","-1.04923","0.00067","28.54432"
"1.00000","0.01468","53.58307","0.15782","-1.04150","0.00071","30.02278"
"1.50000","0.02328","56.47352","0.16604","-1.03329","0.00074","31.64231"
"2.00000","0.03133","58.99819","0.17378","-1.02555","0.00078","33.05689"
"2.50000","0.04018","61.83620","0.18229","-1.01703","0.00082","34.64704"
"3.00000","0.04803","64.19599","0.18987","-1.00946","0.00085","35.96923"
"3.50000","0.05668","66.91133","0.19820","-1.00113","0.00089","37.49065"
"4.00000","0.06485","69.41595","0.20608","-0.99325","0.00092","38.89399"
"4.50000","0.07336","72.13605","0.21427","-0.98506","0.00096","40.41808"
"5.00000","0.08149","74.63474","0.22210","-0.97723","0.00099","41.81810"
"5.50000","0.08982","77.30934","0.23012","-0.96921","0.00103","43.31669"
"6.00000","0.09833","79.93581","0.23833","-0.96100","0.00107","44.78831"
"6.50000","0.10636","82.55741","0.24605","-0.95328","0.00110","46.25720"
"7.00000","0.11499","85.37122","0.25435","-0.94498","0.00114","47.83379"
"7.50000","0.12305","87.95609","0.26212","-0.93721","0.00117","49.28210"
"8.00000","0.13184","90.80999","0.27064","-0.92869","0.00121","50.88115"
"8.50000","0.13966","93.38946","0.27820","-0.92113","0.00125","52.32644"
"9.00000","0.14836","96.21913","0.28662","-0.91271","0.00128","53.91191"
"9.50000","0.15649","99.03016","0.29448","-0.90485","0.00132","55.48694"
"10.00000","0.16489","101.78206","0.30261","-0.89672","0.00136","57.02884"
"10.50000","0.17317","104.43703","0.31063","-0.88870","0.00139","58.51643"
"11.00000","0.18145","107.35693","0.31862","-0.88071","0.00143","60.15245"
"11.50000","0.19007","110.05822","0.32698","-0.87235","0.00146","61.66600"
"12.00000","0.19800","112.62641","0.33466","-0.86467","0.00150","63.10497"
"12.50000","0.20670","115.63016","0.34307","-0.85626","0.00154","64.78797"
"13.00000","0.21466","118.29044","0.35077","-0.84856","0.00157","66.27853"
"13.50000","0.22358","121.27999","0.35939","-0.83994","0.00161","67.95360"
"14.00000","0.23142","123.77708","0.36699","-0.83234","0.00164","69.35272"
"14.50000","0.23994","126.55583","0.37523","-0.82409","0.00168","70.90967"
"15.00000","0.24819","129.34673","0.38321","-0.81612","0.00172","72.47341"
"15.50000","0.25652","132.11292","0.39128","-0.80805","0.00175","74.02332"
"16.00000","0.26485","134.86772","0.39934","-0.79999","0.00179","75.56685"
"16.50000","0.27303","137.52490","0.40726","-0.79207","0.00182","77.05567"
"17.00000","0.28173","140.56512","0.41566","-0.78367","0.00186","78.75912"
"17.50000","0.28965","143.03325","0.42334","-0.77598","0.00190","80.14202"
"18.00000","0.29829","146.04616","0.43170","-0.76763","0.00193","81.83016"
"18.50000","0.30643","148.58864","0.43958","-0.75975","0.00197","83.25472"
"19.00000","0.31524","151.52853","0.44810","-0.75122","0.00201","84.90195"
"19.50000","0.32311","154.10207","0.45572","-0.74360","0.00204","86.34392"
"20.00000","0.33161","156.98474","0.46395","-0.73538","0.00208","87.95909"
"20.50000","0.33992","159.58279","0.47203","-0.72730","0.00211","89.41479"
"21.00000","0.34811","162.36809","0.47998","-0.71934","0.00215","90.97540"
"21.50000","0.35655","165.01411","0.48819","-0.71113","0.00219","92.45798"
"22.00000","0.36473","167.70860","0.49615","-0.70318","0.00222","93.96770"
"22.50000","0.37344","170.58604","0.50461","-0.69472","0.00226","95.57995"
"23.00000","0.38128","173.02129","0.51225","-0.68708","0.00229","96.94442"
"23.50000","0.39005","175.87576","0.52077","-0.67856","0.00233","98.54379"
"24.00000","0.39807","178.42743","0.52857","-0.67076","0.00237","99.97350"
"24.50000","0.40677","181.21631","0.53704","-0.66229","0.00241","101.53612"
"25.00000","0.41476","183.71512","0.54482","-0.65451","0.00244","102.93621"
"25.50000","0.42326","186.42317","0.55308","-0.64625","0.00248","104.45354"
"26.00000","0.43159","189.05812","0.56120","-0.63813","0.00251","105.92992"
"26.50000","0.43973","191.58220","0.56912","-0.63021","0.00255","107.34416"
"27.00000","0.44828","194.33423","0.57744","-0.62189","0.00259","108.88613"
"27.50000","0.45633","196.92776","0.58527","-0.61406","0.00262","110.33930"
"28.00000","0.46517","199.72186","0.59387","-0.60546","0.00266","111.90485"
"28.50000","0.47303","202.11488","0.60153","-0.59780","0.00269","113.24566"
"29.00000","0.48171","204.81758","0.61000","-0.58933","0.00273","114.75999"
"29.50000","0.48979","207.27438","0.61787","-0.58146","0.00277","116.13655"
"30.00000","0.49846","210.15697","0.62632","-0.57301","0.00281","117.75167"
"30.50000","0.50645","212.53903","0.63412","-0.56521","0.00284","119.08635"
"31.00000","0.51479","215.10793","0.64225","-0.55708","0.00288","120.52571"
"31.50000","0.52328","217.66634","0.65053","-0.54880","0.00291","121.95920"
"32.00000","0.53133","220.21407","0.65838","-0.54095","0.00295","123.38670"
"32.50000","0.53987","222.86368","0.66671","-0.53262","0.00299","124.87128"
"33.00000","0.54804","225.33583","0.67468","-0.52465","0.00302","126.25644"
"33.50000","0.55687","228.09044","0.68329","-0.51604","0.00306","127.79986"
"34.00000","0.56471","230.36867","0.69095","-0.50838","0.00309","129.07635"
"34.50000","0.57339","233.04468","0.69941","-0.49992","0.00313","130.57573"
"35.00000","0.58151","235.51328","0.70734","-0.49199","0.00317","131.95889"
"35.50000","0.59007","238.09746","0.71568","-0.48364","0.00321","133.40681"
"36.00000","0.59815","240.49788","0.72358","-0.47575","0.00324","134.75179"
"36.50000","0.60649","242.96991","0.73172","-0.46761","0.00328","136.13687"
"37.00000","0.61499","245.46648","0.74002","-0.45930","0.00331","137.53571"
"37.50000","0.62296","247.86513","0.74781","-0.45152","0.00335","138.87968"
"38.00000","0.63162","250.43939","0.75627","-0.44305","0.00339","140.32205"
"38.50000","0.63968","252.83752","0.76415","-0.43518","0.00342","141.66573"
"39.00000","0.64850","255.32779","0.77278","-0.42655","0.00346","143.06104"
"39.50000","0.65635","257.55582","0.78045","-0.41888","0.00350","144.30940"
"40.00000","0.66507","260.19208","0.78897","-0.41036","0.00353","145.78651"
"40.50000","0.67315","262.55307","0.79688","-0.40245","0.00357","147.10939"
"41.00000","0.68164","265.06549","0.80517","-0.39415","0.00361","148.51711"
"41.50000","0.68985","267.50259","0.81320","-0.38613","0.00364","149.88261"
"42.00000","0.69807","269.72290","0.82125","-0.37808","0.00368","151.12666"
"42.50000","0.70667","272.23410","0.82965","-0.36968","0.00372","152.53371"
"43.00000","0.71467","274.54443","0.83747","-0.36186","0.00375","153.82819"
"43.50000","0.72339","277.07968","0.84600","-0.35333","0.00379","155.24870"
"44.00000","0.73140","279.37485","0.85383","-0.34549","0.00382","156.53468"
"44.50000","0.74025","281.91983","0.86249","-0.33684","0.00386","157.96065"
"45.00000","0.74806","283.99634","0.87014","-0.32918","0.00390","159.12411"
"45.50000","0.75660","286.38461","0.87850","-0.32083","0.00393","160.46228"
"46.00000","0.76488","288.75494","0.88659","-0.31274","0.00397","161.79039"
"46.50000","0.77319","291.08072","0.89474","-0.30459","0.00401","163.09352"
"47.00000","0.78147","293.30887","0.90287","-0.29646","0.00404","164.34196"
"47.50000","0.78970","295.66354","0.91094","-0.28839","0.00408","165.66130"
"48.00000","0.79840","298.14438","0.91947","-0.27986","0.00412","167.05132"
"48.50000","0.80633","300.12051","0.92727","-0.27206","0.00415","168.15855"
"49.00000","0.81500","302.53973","0.93577","-0.26356","0.00419","169.51405"
"49.50000","0.82309","304.78525","0.94372","-0.25561","0.00423","170.77222"
"50.00000","0.83189","307.21130","0.95235","-0.24698","0.00427","172.13155"
"50.50000","0.83974","309.28497","0.96006","-0.23927","0.00430","173.29343"
"51.00000","0.84829","311.48520","0.96846","-0.23086","0.00434","174.52623"
"51.50000","0.85654","313.77597","0.97657","-0.22276","0.00437","175.80975"
"52.00000","0.86481","316.08719","0.98468","-0.21465","0.00441","177.10474"
"52.50000","0.87318","318.29132","0.99291","-0.20642","0.00445","178.33972"
"53.00000","0.88136","320.39307","1.00094","-0.19839","0.00448","179.51733"
"53.50000","0.89007","322.70947","1.00949","-0.18984","0.00452","180.81523"
"54.00000","0.89795","324.73538","1.01724","-0.18208","0.00456","181.95035"
"54.50000","0.90674","327.13751","1.02587","-0.17346","0.00460","183.29626"
"55.00000","0.91473","329.14291","1.03372","-0.16561","0.00463","184.41991"
"55.50000","0.92347","331.53525","1.04231","-0.15702","0.00467","185.76033"
"56.00000","0.93143","333.48392","1.05014","-0.14919","0.00470","186.85219"
"56.50000","0.93990","335.67050","1.05846","-0.14087","0.00474","188.07733"
"57.00000","0.94825","337.88391","1.06666","-0.13267","0.00478","189.31752"
"57.50000","0.95645","339.93170","1.07472","-0.12461","0.00481","190.46490"
"58.00000","0.96494","342.11441","1.08307","-0.11625","0.00485","191.68788"
"58.50000","0.97304","344.05978","1.09105","-0.10828","0.00489","192.77788"
"59.00000","0.98181","346.34103","1.09967","-0.09966","0.00493","194.05608"
"59.50000","0.98967","348.33307","1.10740","-0.09193","0.00496","195.17221"
"60.00000","0.99834","350.55069","1.11593","-0.08340","0.00500","196.41475"
"60.50000","1.00646","352.42917","1.12393","-0.07540","0.00503","197.46727"
"61.00000","1.01511","354.72055","1.13244","-0.06689","0.00507","198.75114"
"61.50000","1.02309","356.62424","1.14029","-0.05904","0.00511","199.81778"
"62.00000","1.03148","358.76166","1.14854","-0.05079","0.00514","201.01538"
"62.50000","1.03997","360.71631","1.15691","-0.04242","0.00518","202.11058"
"63.00000","1.04808","362.68130","1.16489","-0.03444","0.00522","203.21158"
"63.50000","1.05655","364.84601","1.17322","-0.02610","0.00526","204.42447"
"64.00000","1.06471","366.83875","1.18126","-0.01807","0.00529","205.54100"
"64.50000","1.07352","368.89328","1.18993","-0.00940","0.00533","206.69217"
"65.00000","1.08132","370.71878","1.19762","-0.00171","0.00536","207.71500"
"65.50000","1.09004","372.89801","1.20619","0.00686","0.00540","208.93604"
"66.00000","1.09812","374.64655","1.21416","0.01483","0.00544","209.91574"
"66.50000","1.10671","376.80893","1.22262","0.02329","0.00548","211.12733"
"67.00000","1.11477","378.69421","1.23055","0.03122","0.00551","212.18367"
"67.50000","1.12315","380.56506","1.23882","0.03949","0.00555","213.23190"
"68.00000","1.13163","382.57657","1.24716","0.04783","0.00559","214.35896"
"68.50000","1.13968","384.38797","1.25509","0.05577","0.00562","215.37390"
"69.00000","1.14829","386.40619","1.26358","0.06425","0.00566","216.50471"
"69.50000","1.15635","388.26068","1.27151","0.07219","0.00570","217.54379"
"70.00000","1.16516","390.17764","1.28022","0.08089","0.00573","218.61787"
"70.50000","1.17303","391.94211","1.28798","0.08866","0.00577","219.60651"
"71.00000","1.18168","393.97253","1.29652","0.09719","0.00581","220.74416"
"71.50000","1.18982","395.72641","1.30456","0.10523","0.00584","221.72687"
"72.00000","1.19838","397.66272","1.31301","0.11368","0.00588","222.81178"
"72.50000","1.20654","399.43518","1.32107","0.12174","0.00592","223.80490"
"73.00000","1.21480","401.29364","1.32922","0.12990","0.00595","224.84621"
"73.50000","1.22333","403.10864","1.33765","0.13832","0.00599","225.86316"
"74.00000","1.23133","404.84372","1.34555","0.14623","0.00603","226.83533"
"74.50000","1.23992","406.76944","1.35403","0.15470","0.00606","227.91431"
"75.00000","1.24805","408.48093","1.36206","0.16273","0.00610","228.87326"
"75.50000","1.25685","410.44275","1.37075","0.17142","0.00614","229.97247"
"76.00000","1.26472","412.12692","1.37852","0.17920","0.00617","230.91612"
"76.50000","1.27332","413.88135","1.38702","0.18769","0.00621","231.89914"
"77.00000","1.28156","415.47064","1.39517","0.19584","0.00625","232.78963"
"77.50000","1.28995","417.32047","1.40346","0.20413","0.00629","233.82608"
"78.00000","1.29813","418.97009","1.41154","0.21221","0.00632","234.75038"
"78.50000","1.30641","420.62534","1.41973","0.22040","0.00636","235.67781"
"79.00000","1.31502","422.43457","1.42824","0.22891","0.00640","236.69154"
"79.50000","1.32295","423.89822","1.43608","0.23675","0.00643","237.51163"
"80.00000","1.33165","425.78345","1.44468","0.24535","0.00647","238.56793"
"80.50000","1.33972","427.35254","1.45265","0.25332","0.00651","239.44710"
"81.00000","1.34854","429.25327","1.46136","0.26204","0.00655","240.51207"
"81.50000","1.35638","430.62869","1.46913","0.26980","0.00658","241.28273"
"82.00000","1.36504","432.28177","1.47769","0.27836","0.00662","242.20895"
"82.50000","1.37320","433.93317","1.48576","0.28644","0.00665","243.13425"
"83.00000","1.38154","435.50156","1.49401","0.29468","0.00669","244.01302"
"83.50000","1.38986","437.11215","1.50224","0.30291","0.00673","244.91544"
"84.00000","1.39806","438.53458","1.51035","0.31103","0.00677","245.71243"
"84.50000","1.40672","440.32648","1.51892","0.31959","0.00680","246.71643"
"85.00000","1.41464","441.75870","1.52675","0.32743","0.00684","247.51891"
"85.50000","1.42340","443.43103","1.53542","0.33609","0.00688","248.45593"
"86.00000","1.43141","444.72342","1.54335","0.34403","0.00691","249.18005"
"86.50000","1.44024","446.53580","1.55208","0.35275","0.00695","250.19554"
"87.00000","1.44814","447.76700","1.55991","0.36059","0.00699","250.88539"
"87.50000","1.45659","449.31076","1.56828","0.36895","0.00702","251.75037"
"88.00000","1.46490","450.66971","1.57651","0.37718","0.00706","252.51178"
"88.50000","1.47312","451.93747","1.58466","0.38533","0.00710","253.22211"
"89.00000","1.48152","453.47354","1.59296","0.39363","0.00714","254.08278"
"89.50000","1.48970","454.61600","1.60108","0.40175","0.00717","254.72290"
"90.00000","1.49842","456.14099","1.60971","0.41039","0.00721","255.57736"
"90.50000","1.50634","457.26489","1.61757","0.41824","0.00725","256.20709"
"91.00000","1.51507","458.26797","1.62624","0.42691","0.00728","256.76910"
"91.50000","1.52313","456.89511","1.63438","0.43506","0.00732","255.99989"
"92.00000","1.53184","452.87238","1.64332","0.44399","0.00736","253.74594"
"92.50000","1.53975","438.75580","1.65204","0.45271","0.00740","245.83638"
"93.00000","1.54821","431.96823","1.66088","0.46156","0.00744","242.03328"
"93.50000","1.55658","427.39926","1.66951","0.47019","0.00748","239.47327"
"94.00000","1.56472","425.23001","1.67778","0.47845","0.00752","238.25783"
"94.50000","1.57322","423.95709","1.68635","0.48702","0.00755","237.54462"
"95.00000","1.58138","423.68192","1.69453","0.49520","0.00759","237.39043"
"95.50000","1.59016","424.03998","1.70329","0.50396","0.00763","237.59105"
"96.00000","1.59797","424.51025","1.71106","0.51174","0.00766","237.85455"
"96.50000","1.60679","425.39523","1.71983","0.52050","0.00770","238.35040"
"97.00000","1.61477","426.32590","1.72776","0.52844","0.00774","238.87186"
"97.50000","1.62344","427.33081","1.73638","0.53705","0.00778","239.43492"
"98.00000","1.63143","428.18872","1.74432","0.54499","0.00781","239.91560"
"98.50000","1.63981","429.35602","1.75264","0.55331","0.00785","240.56966"
"99.00000","1.64825","430.42847","1.76101","0.56168","0.00789","241.17055"
"99.50000","1.65635","431.38025","1.76906","0.56973","0.00792","241.70383"
"100.00000","1.66498","432.49069","1.77763","0.57830","0.00796","242.32602"
"100.50000","1.67302","433.38766","1.78561","0.58628","0.00800","242.82860"
"101.00000","1.68185","434.45911","1.79439","0.59506","0.00804","243.42892"
"101.50000","1.68971","435.06763","1.80220","0.60288","0.00807","243.76988"
"102.00000","1.69839","436.08908","1.81083","0.61150","0.00811","244.34221"
"102.50000","1.70648","436.63507","1.81889","0.61956","0.00815","244.64813"
"103.00000","1.71506","436.71228","1.82746","0.62813","0.00819","244.69139"
"103.50000","1.72311","436.18777","1.83554","0.63622","0.00822","244.39751"
"104.00000","1.73142","436.25827","1.84385","0.64452","0.00826","244.43701"
"104.50000","1.73998","436.51611","1.85239","0.65306","0.00830","244.58148"
"105.00000","1.74805","436.88589","1.86044","0.66111","0.00833","244.78867"
"105.50000","1.75667","437.40994","1.86903","0.66971","0.00837","245.08229"
"106.00000","1.76473","437.67676","1.87707","0.67775","0.00841","245.23178"
"106.50000","1.77349","438.18164","1.88581","0.68648","0.00845","245.51468"
"107.00000","1.78132","438.32477","1.89363","0.69430","0.00848","245.59486"
"107.50000","1.78998","438.83530","1.90226","0.70293","0.00852","245.88092"
"108.00000","1.79815","439.39719","1.91040","0.71107","0.00856","246.19576"
"108.50000","1.80665","439.66193","1.91888","0.71955","0.00859","246.34409"
"109.00000","1.81481","440.03607","1.92702","0.72769","0.00863","246.55373"
"109.50000","1.82313","440.37271","1.93532","0.73599","0.00867","246.74234"
"110.00000","1.83172","440.74609","1.94389","0.74457","0.00871","246.95155"
"110.50000","1.83962","440.72681","1.95179","0.75246","0.00874","246.94073"
"111.00000","1.84839","441.10162","1.96054","0.76121","0.00878","247.15076"
"111.50000","1.85634","441.05499","1.96850","0.76917","0.00882","247.12462"
"112.00000","1.86516","441.36975","1.97730","0.77797","0.00886","247.30098"
"112.50000","1.87303","441.46744","1.98516","0.78583","0.00889","247.35571"
"113.00000","1.88167","441.82889","1.99378","0.79445","0.00893","247.55824"
"113.50000","1.88983","442.07632","2.00193","0.80260","0.00897","247.69688"
"114.00000","1.89823","442.43863","2.01031","0.81098","0.00900","247.89989"
"114.50000","1.90655","442.76248","2.01861","0.81928","0.00904","248.08133"
"115.00000","1.91469","443.07803","2.02673","0.82740","0.00908","248.25815"
"115.50000","1.92335","443.52292","2.03537","0.83604","0.00912","248.50742"
"116.00000","1.93131","443.72952","2.04331","0.84398","0.00915","248.62317"
"116.50000","1.94003","444.19501","2.05201","0.85268","0.00919","248.88399"
"117.00000","1.94806","444.38290","2.06002","0.86069","0.00923","248.98926"
"117.50000","1.95688","444.92831","2.06881","0.86948","0.00927","249.29486"
"118.00000","1.96473","445.14911","2.07665","0.87732","0.00930","249.41858"
"118.50000","1.97323","445.51248","2.08513","0.88580","0.00934","249.62218"
"119.00000","1.98158","445.84976","2.09346","0.89413","0.00938","249.81116"
"119.50000","1.98988","446.21512","2.10175","0.90242","0.00941","250.01585"
"120.00000","1.99821","446.54794","2.11005","0.91072","0.00945","250.20235"
"120.50000","2.00638","446.81351","2.11820","0.91887","0.00949","250.35114"
"121.00000","2.01505","447.12292","2.12686","0.92753","0.00953","250.52451"
"121.50000","2.02293","447.38501","2.13472","0.93539","0.00956","250.67136"
"122.00000","2.03168","447.78470","2.14345","0.94412","0.00960","250.89531"
"122.50000","2.03972","448.07877","2.15148","0.95215","0.00964","251.06007"
"123.00000","2.04850","448.51828","2.16023","0.96090","0.00968","251.30634"
"123.50000","2.05643","448.69055","2.16815","0.96882","0.00971","251.40285"
"124.00000","2.06499","449.04922","2.17668","0.97736","0.00975","251.60382"
"124.50000","2.07328","449.32343","2.18497","0.98564","0.00979","251.75746"
"125.00000","2.08140","449.55222","2.19307","0.99374","0.00982","251.88565"
"125.50000","2.08991","449.93576","2.20156","1.00223","0.00986","252.10056"
"126.00000","2.09799","450.27426","2.20962","1.01029","0.00990","252.29021"
"126.50000","2.10675","450.70221","2.21836","1.01903","0.00994","252.53000"
"127.00000","2.11463","450.99481","2.22622","1.02689","0.00997","252.69394"
"127.50000","2.12342","451.53485","2.23497","1.03565","0.01001","252.99652"
"128.00000","2.13140","451.75980","2.24294","1.04361","0.01005","253.12256"
"128.50000","2.14016","452.50421","2.25166","1.05234","0.01009","253.53966"
"129.00000","2.14814","452.73920","2.25963","1.06030","0.01012","253.67133"
"129.50000","2.15650","453.17981","2.26797","1.06864","0.01016","253.91820"
"130.00000","2.16491","453.74728","2.27635","1.07702","0.01020","254.23616"
"130.50000","2.17302","454.17679","2.28443","1.08510","0.01023","254.47681"
"131.00000","2.18157","454.80975","2.29294","1.09361","0.01027","254.83147"
"131.50000","2.18971","455.09445","2.30106","1.10174","0.01031","254.99098"
"132.00000","2.19851","455.73557","2.30982","1.11050","0.01035","255.35020"
"132.50000","2.20637","456.02820","2.31767","1.11834","0.01038","255.51416"
"133.00000","2.21503","456.60419","2.32630","1.12698","0.01042","255.83690"
"133.50000","2.22317","457.05899","2.33441","1.13508","0.01046","256.09171"
"134.00000","2.23177","457.52399","2.34299","1.14366","0.01049","256.35226"
"134.50000","2.23980","457.83487","2.35100","1.15167","0.01053","256.52646"
"135.00000","2.24813","458.25156","2.35930","1.15997","0.01057","256.75992"
"135.50000","2.25662","458.68707","2.36777","1.16844","0.01061","257.00394"
"136.00000","2.26464","458.94510","2.37578","1.17645","0.01064","257.14850"
"136.50000","2.27326","459.51587","2.38436","1.18503","0.01068","257.46832"
"137.00000","2.28134","459.75540","2.39243","1.19310","0.01072","257.60254"
"137.50000","2.29019","460.28345","2.40125","1.20192","0.01076","257.89841"
"138.00000","2.29805","460.43439","2.40910","1.20977","0.01079","257.98297"
"138.50000","2.30678","460.88757","2.41780","1.21847","0.01083","258.23688"
"139.00000","2.31481","461.07928","2.42583","1.22650","0.01087","258.34430"
"139.50000","2.32332","461.36807","2.43432","1.23499","0.01090","258.50610"
"140.00000","2.33148","461.68851","2.44246","1.24313","0.01094","258.68564"
"140.50000","2.33977","462.01459","2.45073","1.25140","0.01098","258.86835"
"141.00000","2.34830","462.23724","2.45925","1.25992","0.01102","258.99310"
"141.50000","2.35628","462.29889","2.46723","1.26790","0.01105","259.02765"
"142.00000","2.36503","462.64044","2.47595","1.27662","0.01109","259.21902"
"142.50000","2.37301","462.66174","2.48394","1.28461","0.01113","259.23096"
"143.00000","2.38189","463.04333","2.49279","1.29346","0.01117","259.44476"
"143.50000","2.38974","462.71286","2.50066","1.30133","0.01120","259.25961"
"144.00000","2.39832","462.77783","2.50924","1.30991","0.01124","259.29602"
"144.50000","2.40649","462.62741","2.51741","1.31809","0.01128","259.21173"
"145.00000","2.41491","462.48654","2.52584","1.32651","0.01131","259.13278"
"145.50000","2.42317","462.19839","2.53412","1.33479","0.01135","258.97134"
"146.00000","2.43142","461.95938","2.54239","1.34306","0.01139","258.83743"
"146.50000","2.44006","461.65604","2.55104","1.35171","0.01143","258.66745"
"147.00000","2.44802","461.18967","2.55903","1.35970","0.01146","258.40616"
"147.50000","2.45669","460.99313","2.56770","1.36838","0.01150","258.29602"
"148.00000","2.46475","460.56821","2.57580","1.37647","0.01154","258.05795"
"148.50000","2.47354","460.60089","2.58458","1.38525","0.01158","258.07626"
"149.00000","2.48140","460.21017","2.59246","1.39313","0.01161","257.85733"
"149.50000","2.48991","460.11005","2.60098","1.40165","0.01165","257.80124"
"150.00000","2.49820","460.14590","2.60927","1.40994","0.01169","257.82132"
"150.50000","2.50651","459.92374","2.61759","1.41826","0.01172","257.69684"
"151.00000","2.51485","459.87045","2.62594","1.42661","0.01176","257.66699"
"151.50000","2.52305","459.90540","2.63413","1.43480","0.01180","257.68658"
"152.00000","2.53174","460.07382","2.64281","1.44348","0.01184","257.78094"
"152.50000","2.53968","459.95331","2.65075","1.45143","0.01187","257.71341"
"153.00000","2.54842","460.15607","2.65949","1.46016","0.01191","257.82703"
"153.50000","2.55639","459.96677","2.66747","1.46814","0.01195","257.72095"
"154.00000","2.56518","460.13043","2.67624","1.47692","0.01199","257.81265"
"154.50000","2.57307","460.05930","2.68415","1.48482","0.01202","257.77280"
"155.00000","2.58160","460.07809","2.69267","1.49335","0.01206","257.78333"
"155.50000","2.58989","460.25888","2.70095","1.50162","0.01210","257.88464"
"156.00000","2.59810","460.37939","2.70915","1.50983","0.01213","257.95215"
"156.50000","2.60658","460.46469","2.71763","1.51830","0.01217","257.99994"
"157.00000","2.61469","460.37744","2.72574","1.52642","0.01221","257.95105"
"157.50000","2.62342","460.52261","2.73446","1.53513","0.01225","258.03241"
"158.00000","2.63132","460.41440","2.74237","1.54305","0.01228","257.97177"
"158.50000","2.64005","460.43237","2.75110","1.55177","0.01232","257.98184"
"159.00000","2.64807","460.24951","2.75913","1.55980","0.01236","257.87939"
"159.50000","2.65682","460.29327","2.76788","1.56856","0.01240","257.90390"
"160.00000","2.66477","460.08505","2.77584","1.57651","0.01243","257.78723"
"160.50000","2.67318","460.05737","2.78425","1.58493","0.01247","257.77173"
"161.00000","2.68162","460.12238","2.79269","1.59336","0.01251","257.80814"
"161.50000","2.68979","460.05859","2.80086","1.60153","0.01255","257.77240"
"162.00000","2.69825","460.22836","2.80932","1.60999","0.01258","257.86752"
"162.50000","2.70640","460.10855","2.81747","1.61814","0.01262","257.80038"
"163.00000","2.71509","460.44678","2.82614","1.62681","0.01266","257.98990"
"163.50000","2.72298","460.32883","2.83403","1.63471","0.01269","257.92383"
"164.00000","2.73164","460.58051","2.84268","1.64335","0.01273","258.06485"
"164.50000","2.73980","460.60883","2.85084","1.65151","0.01277","258.08072"
"165.00000","2.74846","460.97961","2.85947","1.66015","0.01281","258.28845"
"165.50000","2.75645","461.00174","2.86747","1.66814","0.01284","258.30084"
"166.00000","2.76485","461.27875","2.87585","1.67652","0.01288","258.45605"
"166.50000","2.77331","461.57605","2.88430","1.68497","0.01292","258.62265"
"167.00000","2.78140","461.67389","2.89238","1.69305","0.01296","258.67746"
"167.50000","2.78994","462.05850","2.90090","1.70157","0.01299","258.89297"
"168.00000","2.79804","462.22595","2.90899","1.70966","0.01303","258.98679"
"168.50000","2.80679","462.57642","2.91772","1.71839","0.01307","259.18317"
"169.00000","2.81469","462.66293","2.92561","1.72628","0.01310","259.23163"
"169.50000","2.82344","463.15155","2.93434","1.73501","0.01314","259.50540"
"170.00000","2.83149","463.33438","2.94238","1.74305","0.01318","259.60785"
"170.50000","2.84003","463.68887","2.95089","1.75156","0.01322","259.80646"
"171.00000","2.84814","463.87994","2.95900","1.75967","0.01325","259.91351"
"171.50000","2.85646","464.07483","2.96730","1.76798","0.01329","260.02271"
"172.00000","2.86494","464.46204","2.97576","1.77643","0.01333","260.23969"
"172.50000","2.87298","464.52457","2.98380","1.78447","0.01336","260.27472"
"173.00000","2.88164","465.02454","2.99242","1.79310","0.01340","260.55484"
"173.50000","2.88967","465.07147","3.00046","1.80113","0.01344","260.58115"
"174.00000","2.89851","465.57669","3.00927","1.80994","0.01348","260.86423"
"174.50000","2.90638","465.63895","3.01714","1.81781","0.01351","260.89911"
"175.00000","2.91498","466.02628","3.02571","1.82638","0.01355","261.11612"
"175.50000","2.92320","466.19452","3.03392","1.83459","0.01359","261.21039"
"176.00000","2.93163","466.51340","3.04234","1.84301","0.01363","261.38907"
"176.50000","2.93982","466.80429","3.05051","1.85118","0.01366","261.55203"
"177.00000","2.94812","467.14078","3.05879","1.85946","0.01370","261.74057"
"177.50000","2.95667","467.35098","3.06732","1.86800","0.01374","261.85837"
"178.00000","2.96465","467.53214","3.07529","1.87597","0.01377","261.95987"
"178.50000","2.97326","467.86029","3.08389","1.88456","0.01381","262.14374"
"179.00000","2.98141","468.13568","3.09202","1.89269","0.01385","262.29803"
"179.50000","2.99023","468.53159","3.10082","1.90150","0.01389","262.51987"
"180.00000","2.99806","468.65811","3.10864","1.90932","0.01392","262.59076"
"180.50000","3.00672","469.03281","3.11728","1.91795","0.01396","262.80069"
"181.00000","3.01488","469.20456","3.12543","1.92610","0.01400","262.89691"
"181.50000","3.02324","469.35742","3.13378","1.93445","0.01404","262.98257"
"182.00000","3.03148","469.58899","3.14201","1.94268","0.01407","263.11234"
"182.50000","3.03977","469.64679","3.15029","1.95097","0.01411","263.14471"
"183.00000","3.04837","470.04794","3.15888","1.95955","0.01415","263.36948"
"183.50000","3.05631","470.08438","3.16681","1.96748","0.01418","263.38989"
"184.00000","3.06507","470.39389","3.17555","1.97622","0.01422","263.56332"
"184.50000","3.07307","470.30261","3.18356","1.98423","0.01426","263.51218"
"185.00000","3.08189","470.71432","3.19236","1.99303","0.01430","263.74286"
"185.50000","3.08975","470.65707","3.20022","2.00089","0.01433","263.71078"
"186.00000","3.09830","470.91055","3.20876","2.00943","0.01437","263.85278"
"186.50000","3.10650","470.89429","3.21695","2.01763","0.01441","263.84369"
"187.00000","3.11478","471.04507","3.22523","2.02590","0.01445","263.92816"
"187.50000","3.12320","471.14771","3.23364","2.03431","0.01448","263.98569"
"188.00000","3.13135","471.24854","3.24178","2.04245","0.01452","264.04218"
"188.50000","3.14006","471.31223","3.25049","2.05116","0.01456","264.07785"
"189.00000","3.14801","471.20685","3.25845","2.05912","0.01460","264.01880"
"189.50000","3.15670","471.41333","3.26713","2.06780","0.01463","264.13449"
"190.00000","3.16477","471.27438","3.27520","2.07587","0.01467","264.05664"
"190.50000","3.17355","471.38217","3.28398","2.08465","0.01471","264.11703"
"191.00000","3.18144","471.16476","3.29188","2.09255","0.01474","263.99524"
"191.50000","3.18994","471.10635","3.30038","2.10105","0.01478","263.96249"
"192.00000","3.19825","471.07037","3.30869","2.10937","0.01482","263.94235"
"192.50000","3.20642","470.83121","3.31688","2.11755","0.01486","263.80835"
"193.00000","3.21487","470.72470","3.32534","2.12601","0.01489","263.74866"
"193.50000","3.22307","470.55991","3.33355","2.13422","0.01493","263.65634"
"194.00000","3.23180","470.30231","3.34229","2.14296","0.01497","263.51199"
"194.50000","3.23968","469.75674","3.35020","2.15087","0.01501","263.20633"
"195.00000","3.24839","469.47711","3.35893","2.15960","0.01505","263.04962"
"195.50000","3.25642","469.04184","3.36699","2.16766","0.01508","262.80576"
"196.00000","3.26512","468.69907","3.37570","2.17637","0.01512","262.61371"
"196.50000","3.27306","468.27542","3.38366","2.18434","0.01516","262.37631"
"197.00000","3.28156","467.84439","3.39218","2.19286","0.01519","262.13483"
"197.50000","3.28993","467.41940","3.40058","2.20125","0.01523","261.89670"
"198.00000","3.29805","467.03558","3.40872","2.20940","0.01527","261.68164"
"198.50000","3.30663","466.76981","3.41732","2.21800","0.01531","261.53271"
"199.00000","3.31470","466.30310","3.42541","2.22609","0.01534","261.27124"
"199.50000","3.32355","466.04602","3.43428","2.23495","0.01538","261.12720"
"200.00000","3.33136","465.65439","3.44211","2.24278","0.01542","260.90775"
"200.50000","3.34010","465.25812","3.45088","2.25155","0.01546","260.68573"
"201.00000","3.34807","464.90118","3.45887","2.25954","0.01549","260.48572"
"201.50000","3.35675","464.72330","3.46756","2.26823","0.01553","260.38605"
"202.00000","3.36480","464.10519","3.47564","2.27631","0.01557","260.03973"
"202.50000","3.37310","463.80054","3.48396","2.28463","0.01561","259.86902"
"203.00000","3.38159","463.53983","3.49246","2.29314","0.01564","259.72296"
"203.50000","3.38969","463.19473","3.50058","2.30125","0.01568","259.52960"
"204.00000","3.39828","462.97699","3.50918","2.30986","0.01572","259.40759"
"204.50000","3.40635","462.63553","3.51728","2.31795","0.01575","259.21628"
"205.00000","3.41519","462.55789","3.52612","2.32679","0.01579","259.17276"
"205.50000","3.42303","462.03598","3.53399","2.33466","0.01583","258.88034"
"206.00000","3.43168","461.91626","3.54264","2.34332","0.01587","258.81326"
"206.50000","3.43985","461.54996","3.55084","2.35151","0.01590","258.60803"
"207.00000","3.44836","461.48273","3.55935","2.36002","0.01594","258.57034"
"207.50000","3.45651","460.99982","3.56753","2.36820","0.01598","258.29977"
"208.00000","3.46481","460.78036","3.57584","2.37652","0.01602","258.17682"
"208.50000","3.47334","460.59085","3.58438","2.38505","0.01606","258.07065"
"209.00000","3.48134","460.08890","3.59241","2.39308","0.01609","257.78940"
"209.50000","3.48999","459.89609","3.60108","2.40175","0.01613","257.68137"
"210.00000","3.49805","459.50046","3.60915","2.40982","0.01617","257.45969"
"210.50000","3.50685","459.35068","3.61796","2.41864","0.01621","257.37576"
"211.00000","3.51466","458.84351","3.62580","2.42647","0.01624","257.09158"
"211.50000","3.52334","458.57007","3.63450","2.43517","0.01628","256.93839"
"212.00000","3.53150","458.24609","3.64267","2.44335","0.01632","256.75687"
"212.50000","3.53991","457.92944","3.65110","2.45177","0.01635","256.57944"
"213.00000","3.54818","457.51740","3.65940","2.46007","0.01639","256.34857"
"213.50000","3.55643","457.19110","3.66766","2.46833","0.01643","256.16574"
"214.00000","3.56506","456.95618","3.67631","2.47699","0.01647","256.03412"
"214.50000","3.57299","456.35529","3.68427","2.48494","0.01650","255.69743"
"215.00000","3.58172","456.15811","3.69302","2.49369","0.01654","255.58696"
"215.50000","3.58967","455.70755","3.70099","2.50166","0.01658","255.33450"
"216.00000","3.59859","455.42093","3.70993","2.51060","0.01662","255.17390"
"216.50000","3.60640","454.87219","3.71777","2.51844","0.01665","254.86646"
"217.00000","3.61493","454.61478","3.72631","2.52698","0.01669","254.72221"
"217.50000","3.62318","454.07120","3.73460","2.53527","0.01673","254.41765"
"218.00000","3.63153","453.63251","3.74297","2.54364","0.01677","254.17184"
"218.50000","3.63986","453.16348","3.75132","2.55200","0.01680","253.90906"
"219.00000","3.64802","452.71939","3.75951","2.56019","0.01684","253.66023"
"219.50000","3.65671","452.16623","3.76824","2.56891","0.01688","253.35030"
"220.00000","3.66465","451.47958","3.77621","2.57688","0.01691","252.96556"
"220.50000","3.67330","450.94275","3.78489","2.58556","0.01695","252.66476"
"221.00000","3.68143","450.25708","3.79306","2.59373","0.01699","252.28058"
"221.50000","3.69024","449.59598","3.80191","2.60258","0.01703","251.91017"
"222.00000","3.69811","448.47617","3.80984","2.61052","0.01706","251.28273"
"222.50000","3.70661","446.30618","3.81846","2.61913","0.01710","250.06688"
"223.00000","3.71491","444.54410","3.82687","2.62754","0.01714","249.07959"
"223.50000","3.72313","442.77008","3.83519","2.63586","0.01718","248.08560"
"224.00000","3.73155","441.11786","3.84370","2.64437","0.01722","247.15985"
"224.50000","3.73970","439.09891","3.85197","2.65264","0.01725","246.02863"
"225.00000","3.74842","437.21060","3.86080","2.66147","0.01729","244.97060"
"225.50000","3.75626","435.35855","3.86874","2.66941","0.01733","243.93289"
"226.00000","3.76505","434.01312","3.87760","2.67827","0.01737","243.17905"
"226.50000","3.77308","432.34592","3.88573","2.68640","0.01740","242.24490"
"227.00000","3.78179","431.10349","3.89451","2.69518","0.01744","241.54877"
"227.50000","3.78976","429.35837","3.90258","2.70325","0.01748","240.57097"
"228.00000","3.79825","427.99692","3.91114","2.71182","0.01752","239.80814"
"228.50000","3.80661","426.69052","3.91958","2.72026","0.01756","239.07616"
"229.00000","3.81475","425.07019","3.92781","2.72848","0.01759","238.16829"
"229.50000","3.82330","423.17618","3.93647","2.73714","0.01763","237.10707"
"230.00000","3.83133","421.35794","3.94461","2.74528","0.01767","236.08830"
"230.50000","3.84015","420.01471","3.95351","2.75418","0.01771","235.33568"
"231.00000","3.84803","417.99216","3.96150","2.76217","0.01774","234.20244"
"231.50000","3.85674","416.48801","3.97029","2.77096","0.01778","233.35966"
"232.00000","3.86479","414.02094","3.97849","2.77916","0.01782","231.97736"
"232.50000","3.87346","412.56888","3.98724","2.78791","0.01786","231.16376"
"233.00000","3.88145","411.32291","3.99529","2.79597","0.01790","230.46564"
"233.50000","3.88979","410.71329","4.00368","2.80435","0.01793","230.12407"
"234.00000","3.89829","410.34888","4.01219","2.81287","0.01797","229.91988"
"234.50000","3.90634","409.58380","4.02029","2.82096","0.01801","229.49121"
"235.00000","3.91487","409.39563","4.02883","2.82950","0.01805","229.38577"
"235.50000","3.92302","408.46686","4.03703","2.83771","0.01808","228.86539"
"236.00000","3.93186","408.26727","4.04588","2.84655","0.01812","228.75356"
"236.50000","3.93972","407.83530","4.05377","2.85444","0.01816","228.51152"
"237.00000","3.94839","407.78815","4.06244","2.86311","0.01820","228.48509"
"237.50000","3.95651","407.67422","4.07057","2.87124","0.01823","228.42126"
"238.00000","3.96505","407.52737","4.07911","2.87978","0.01827","228.33899"
"238.50000","3.97314","407.30206","4.08722","2.88789","0.01831","228.21274"
"239.00000","3.98151","407.25494","4.09559","2.89626","0.01834","228.18634"
"239.50000","3.99000","407.06689","4.10409","2.90476","0.01838","228.08098"
"240.00000","3.99798","406.73291","4.11209","2.91276","0.01842","227.89384"
"240.50000","4.00662","406.61255","4.12074","2.92141","0.01846","227.82640"
"241.00000","4.01468","406.55554","4.12880","2.92947","0.01849","227.79446"
"241.50000","4.02351","406.80859","4.13762","2.93829","0.01853","227.93625"
"242.00000","4.03136","405.88925","4.14552","2.94619","0.01857","227.42114"
"242.50000","4.04008","405.82480","4.15424","2.95491","0.01861","227.38503"
"243.00000","4.04815","405.67917","4.16233","2.96300","0.01864","227.30344"
"243.50000","4.05664","405.27518","4.17083","2.97151","0.01868","227.07707"
"244.00000","4.06486","404.76489","4.17908","2.97975","0.01872","226.79115"
"244.50000","4.07308","404.65976","4.18731","2.98799","0.01876","226.73225"
"245.00000","4.08167","404.65683","4.19590","2.99657","0.01879","226.73061"
"245.50000","4.08967","404.36359","4.20392","3.00459","0.01883","226.56630"
"246.00000","4.09837","404.42325","4.21261","3.01329","0.01887","226.59973"
"246.50000","4.10639","404.10760","4.22065","3.02132","0.01890","226.42288"
"247.00000","4.11525","404.20773","4.22950","3.03018","0.01894","226.47897"
"247.50000","4.12307","403.99521","4.23734","3.03801","0.01898","226.35989"
"248.00000","4.13160","404.06833","4.24586","3.04654","0.01902","226.40086"
"248.50000","4.13985","403.95712","4.25412","3.05480","0.01905","226.33856"
"249.00000","4.14819","403.95401","4.26245","3.06313","0.01909","226.33682"
"249.50000","4.15647","403.89841","4.27075","3.07142","0.01913","226.30566"
"250.00000","4.16470","403.88800","4.27898","3.07965","0.01917","226.29984"
"250.50000","4.17340","403.98636","4.28767","3.08834","0.01921","226.35493"
"251.00000","4.18134","403.94641","4.29561","3.09628","0.01924","226.33257"
"251.50000","4.19000","403.86124","4.30427","3.10495","0.01928","226.28484"
"252.00000","4.19809","403.65384","4.31237","3.11304","0.01932","226.16862"
"252.50000","4.20691","403.54840","4.32120","3.12187","0.01936","226.10956"
"253.00000","4.21474","403.20453","4.32905","3.12972","0.01939","225.91689"
"253.50000","4.22328","403.08646","4.33760","3.13827","0.01943","225.85072"
"254.00000","4.23155","402.86594","4.34588","3.14656","0.01947","225.72717"
"254.50000","4.23978","402.35504","4.35414","3.15482","0.01950","225.44090"
"255.00000","4.24818","402.06509","4.36256","3.16323","0.01954","225.27846"
"255.50000","4.25637","401.46552","4.37078","3.17145","0.01958","224.94250"
"256.00000","4.26507","401.08682","4.37950","3.18018","0.01962","224.73032"
"256.50000","4.27295","400.48984","4.38742","3.18809","0.01965","224.39583"
"257.00000","4.28174","400.27518","4.39622","3.19689","0.01969","224.27556"
"257.50000","4.28972","399.30051","4.40426","3.20493","0.01973","223.72945"
"258.00000","4.29851","398.63312","4.41308","3.21375","0.01977","223.35550"
"258.50000","4.30644","397.22260","4.42109","3.22176","0.01980","222.56519"
"259.00000","4.31490","396.06750","4.42962","3.23029","0.01984","221.91798"
"259.50000","4.32323","394.71741","4.43803","3.23870","0.01988","221.16151"
"260.00000","4.33143","393.22009","4.44632","3.24699","0.01992","220.32257"
"260.50000","4.33995","391.81589","4.45491","3.25558","0.01995","219.53578"
"261.00000","4.34805","390.08466","4.46311","3.26379","0.01999","218.56577"
"261.50000","4.35681","388.67526","4.47196","3.27263","0.02003","217.77608"
"262.00000","4.36466","386.88873","4.47991","3.28059","0.02007","216.77509"
"262.50000","4.37332","384.90967","4.48870","3.28937","0.02011","215.66621"
"263.00000","4.38146","382.45468","4.49700","3.29767","0.02014","214.29066"
"263.50000","4.39012","379.54776","4.50585","3.30652","0.02018","212.66191"
"264.00000","4.39809","375.86249","4.51406","3.31473","0.02022","210.59705"
"264.50000","4.40647","369.78207","4.52282","3.32350","0.02026","207.19017"
"265.00000","4.41496","363.74960","4.53171","3.33238","0.02030","203.81015"
"265.50000","4.42307","356.69305","4.54026","3.34093","0.02034","199.85634"
"266.00000","4.43156","352.74396","4.54900","3.34968","0.02038","197.64365"
"266.50000","4.43972","349.48438","4.55737","3.35805","0.02041","195.81729"
"267.00000","4.44851","345.81158","4.56640","3.36707","0.02045","193.75941"
"267.50000","4.45633","340.55865","4.57456","3.37523","0.02049","190.81618"
"268.00000","4.46504","337.04861","4.58351","3.38418","0.02053","188.84949"
"268.50000","4.47313","332.96863","4.59187","3.39254","0.02057","186.56346"
"269.00000","4.48174","329.60730","4.60071","3.40138","0.02061","184.68010"
"269.50000","4.48978","327.12341","4.60891","3.40958","0.02064","183.28838"
"270.00000","4.49817","325.74670","4.61739","3.41806","0.02068","182.51700"
"270.50000","4.50662","324.73184","4.62591","3.42658","0.02072","181.94836"
"271.00000","4.51467","324.04333","4.63401","3.43468","0.02076","181.56259"
"271.50000","4.52329","323.45895","4.64267","3.44334","0.02080","181.23517"
"272.00000","4.53135","322.42078","4.65079","3.45146","0.02083","180.65347"
"272.50000","4.54015","322.18826","4.65961","3.46028","0.02087","180.52319"
"273.00000","4.54803","321.56635","4.66753","3.46820","0.02091","180.17473"
"273.50000","4.55668","321.14050","4.67621","3.47688","0.02095","179.93613"
"274.00000","4.56482","318.55435","4.68452","3.48519","0.02098","178.48709"
"274.50000","4.57338","316.41367","4.69323","3.49390","0.02102","177.28766"
"275.00000","4.58153","315.44519","4.70144","3.50212","0.02106","176.74503"
"275.50000","4.58979","315.08832","4.70972","3.51040","0.02110","176.54506"
"276.00000","4.59833","314.62100","4.71829","3.51896","0.02113","176.28323"
"276.50000","4.60633","314.55408","4.72630","3.52697","0.02117","176.24573"
"277.00000","4.61493","314.44843","4.73491","3.53558","0.02121","176.18652"
"277.50000","4.62305","314.39102","4.74304","3.54371","0.02124","176.15437"
"278.00000","4.63187","314.76099","4.75182","3.55250","0.02128","176.36166"
"278.50000","4.63971","314.67624","4.75968","3.56035","0.02132","176.31418"
"279.00000","4.64832","314.97351","4.76826","3.56893","0.02136","176.48074"
"279.50000","4.65656","315.17035","4.77649","3.57716","0.02139","176.59103"
"280.00000","4.66497","315.35275","4.78489","3.58556","0.02143","176.69322"
"280.50000","4.67313","315.75867","4.79302","3.59369","0.02147","176.92067"
"281.00000","4.68142","316.01852","4.80129","3.60196","0.02151","177.06627"
"281.50000","4.69000","316.35822","4.80985","3.61053","0.02154","177.25659"
"281.64600","4.69211","316.26065","4.81196","3.61264","0.02155","177.20192"