File: flexion/3_axis/Specimen_RawData_4.csv
Specimen properties : Specimen label,"4"
Specimen properties : Support span,"72.00",mm
Specimen properties : Thickness,"3.79",mm
Specimen properties : Width,"12.84",mm
Maximum Load : Maximum Load,"473.2",N
Tangent Modulus of Elasticity : Tangent Modulus of Elasticity,"44628727982.32170",Pa
Test : Rate 1,"1.00000",mm/min
Specimen notes : Specimen note 1,""

Time,Displacement,Load,Flexure extension,Corrected extension,Flexure strain (Corrected extension),Flexure stress
(s),(mm),(N),(mm),(mm),(mm/mm),(MPa)
"0.00000","0.00000","49.11806","0.14823","-1.05558","0.00065","28.76216"
"0.50000","0.00641","51.36780","0.15433","-1.04947","0.00068","30.07955"
"1.00000","0.01478","54.25965","0.16232","-1.04149","0.00071","31.77294"
"1.50000","0.02325","57.06440","0.17041","-1.03339","0.00075","33.41532"
"2.00000","0.03138","59.73376","0.17821","-1.02559","0.00078","34.97842"
"2.50000","0.03986","62.43237","0.18638","-1.01742","0.00082","36.55865"
"3.00000","0.04802","65.00241","0.19424","-1.00957","0.00085","38.06359"
"3.50000","0.05687","67.82599","0.20276","-1.00104","0.00089","39.71700"
"4.00000","0.06470","70.37719","0.21030","-0.99351","0.00092","41.21091"
"4.50000","0.07340","73.16864","0.21867","-0.98514","0.00096","42.84551"
"5.00000","0.08150","75.75193","0.22646","-0.97735","0.00099","44.35821"
"5.50000","0.09012","78.51128","0.23476","-0.96904","0.00103","45.97401"
"6.00000","0.09814","80.98094","0.24249","-0.96132","0.00106","47.42017"
"6.50000","0.10652","83.78893","0.25054","-0.95326","0.00110","49.06446"
"7.00000","0.11498","86.47873","0.25869","-0.94512","0.00113","50.63953"
"7.50000","0.12302","88.97997","0.26646","-0.93734","0.00117","52.10418"
"8.00000","0.13162","91.80275","0.27479","-0.92901","0.00121","53.75712"
"8.50000","0.13969","94.40394","0.28260","-0.92120","0.00124","55.28030"
"9.00000","0.14849","97.29185","0.29112","-0.91268","0.00128","56.97139"
"9.50000","0.15634","99.86389","0.29873","-0.90508","0.00131","58.47750"
"10.00000","0.16510","102.77737","0.30720","-0.89660","0.00135","60.18356"
"10.50000","0.17315","105.25553","0.31501","-0.88880","0.00138","61.63469"
"11.00000","0.18170","108.24522","0.32327","-0.88054","0.00142","63.38538"
"11.50000","0.18984","110.65103","0.33117","-0.87264","0.00145","64.79415"
"12.00000","0.19811","113.44979","0.33917","-0.86464","0.00149","66.43302"
"12.50000","0.20665","116.14431","0.34745","-0.85636","0.00152","68.01086"
"13.00000","0.21469","118.75844","0.35523","-0.84858","0.00156","69.54162"
"13.50000","0.22337","121.52913","0.36364","-0.84017","0.00160","71.16405"
"14.00000","0.23139","124.19564","0.37139","-0.83241","0.00163","72.72549"
"14.50000","0.24024","127.07915","0.37996","-0.82384","0.00167","74.41400"
"15.00000","0.24807","129.53557","0.38755","-0.81626","0.00170","75.85240"
"15.50000","0.25664","132.35559","0.39585","-0.80795","0.00174","77.50373"
"16.00000","0.26487","134.97070","0.40382","-0.79998","0.00177","79.03506"
"16.50000","0.27327","137.74142","0.41196","-0.79185","0.00181","80.65752"
"17.00000","0.28147","140.35947","0.41990","-0.78390","0.00184","82.19057"
"17.50000","0.28973","142.94864","0.42791","-0.77590","0.00188","83.70673"
"18.00000","0.29840","145.89049","0.43629","-0.76751","0.00191","85.42939"
"18.50000","0.30635","148.32251","0.44401","-0.75980","0.00195","86.85352"
"19.00000","0.31499","151.12744","0.45238","-0.75143","0.00198","88.49600"
"19.50000","0.32309","153.70169","0.46022","-0.74358","0.00202","90.00341"
"20.00000","0.33192","156.61339","0.46877","-0.73504","0.00206","91.70842"
"20.50000","0.33973","158.90567","0.47638","-0.72743","0.00209","93.05071"
"21.00000","0.34832","161.76364","0.48472","-0.71908","0.00213","94.72427"
"21.50000","0.35654","164.34698","0.49272","-0.71108","0.00216","96.23700"
"22.00000","0.36487","167.05098","0.50082","-0.70298","0.00220","97.82038"
"22.50000","0.37317","169.62250","0.50890","-0.69491","0.00223","99.32619"
"23.00000","0.38140","172.28014","0.51691","-0.68690","0.00227","100.88243"
"23.50000","0.39005","174.97603","0.52533","-0.67848","0.00230","102.46107"
"24.00000","0.39797","177.57924","0.53302","-0.67078","0.00234","103.98544"
"24.50000","0.40674","180.28235","0.54157","-0.66224","0.00238","105.56830"
"25.00000","0.41471","182.70532","0.54933","-0.65447","0.00241","106.98713"
"25.50000","0.42351","185.59160","0.55788","-0.64592","0.00245","108.67725"
"26.00000","0.43144","187.99147","0.56561","-0.63820","0.00248","110.08255"
"26.50000","0.43994","190.66815","0.57388","-0.62993","0.00252","111.64993"
"27.00000","0.44823","193.26428","0.58196","-0.62185","0.00255","113.17016"
"27.50000","0.45650","195.88507","0.59000","-0.61381","0.00259","114.70482"
"28.00000","0.46494","198.44705","0.59822","-0.60559","0.00262","116.20504"
"28.50000","0.47306","201.06035","0.60612","-0.59769","0.00266","117.73531"
"29.00000","0.48179","203.66823","0.61464","-0.58916","0.00270","119.26242"
"29.50000","0.48966","206.13162","0.62232","-0.58149","0.00273","120.70491"
"30.00000","0.49833","208.77679","0.63078","-0.57303","0.00277","122.25385"
"30.50000","0.50644","211.25494","0.63869","-0.56512","0.00280","123.70499"
"31.00000","0.51517","213.96121","0.64719","-0.55661","0.00284","125.28970"
"31.50000","0.52310","216.31068","0.65494","-0.54887","0.00287","126.66549"
"32.00000","0.53153","218.90605","0.66316","-0.54064","0.00291","128.18526"
"32.50000","0.53997","221.44810","0.67140","-0.53241","0.00295","129.67381"
"33.00000","0.54811","223.88319","0.67934","-0.52446","0.00298","131.09973"
"33.50000","0.55654","226.42795","0.68757","-0.51623","0.00302","132.58987"
"34.00000","0.56473","228.93266","0.69556","-0.50825","0.00305","134.05656"
"34.50000","0.57350","231.62744","0.70411","-0.49969","0.00309","135.63455"
"35.00000","0.58134","233.88968","0.71177","-0.49204","0.00312","136.95926"
"35.50000","0.59005","236.60112","0.72026","-0.48354","0.00316","138.54700"
"36.00000","0.59812","239.00494","0.72814","-0.47566","0.00319","139.95461"
"36.50000","0.60678","241.60107","0.73660","-0.46721","0.00323","141.47484"
"37.00000","0.61478","243.93355","0.74441","-0.45939","0.00327","142.84067"
"37.50000","0.62321","246.43639","0.75265","-0.45115","0.00330","144.30626"
"38.00000","0.63161","248.83757","0.76086","-0.44294","0.00334","145.71233"
"38.50000","0.63970","251.26361","0.76877","-0.43504","0.00337","147.13295"
"39.00000","0.64828","253.79810","0.77716","-0.42665","0.00341","148.61707"
"39.50000","0.65636","256.12683","0.78506","-0.41875","0.00344","149.98071"
"40.00000","0.66514","258.65921","0.79364","-0.41016","0.00348","151.46359"
"40.50000","0.67304","260.97189","0.80136","-0.40245","0.00352","152.81784"
"41.00000","0.68173","263.51157","0.80986","-0.39394","0.00355","154.30501"
"41.50000","0.68982","265.79703","0.81777","-0.38603","0.00359","155.64331"
"42.00000","0.69846","268.33313","0.82622","-0.37759","0.00362","157.12837"
"42.50000","0.70654","270.65179","0.83412","-0.36969","0.00366","158.48611"
"43.00000","0.71483","273.05042","0.84223","-0.36158","0.00369","159.89069"
"43.50000","0.72332","275.36771","0.85054","-0.35327","0.00373","161.24762"
"44.00000","0.73134","277.59195","0.85839","-0.34542","0.00377","162.55008"
"44.50000","0.73991","280.07819","0.86677","-0.33704","0.00380","164.00595"
"45.00000","0.74807","282.30411","0.87475","-0.32905","0.00384","165.30939"
"45.50000","0.75685","284.97141","0.88334","-0.32047","0.00387","166.87128"
"46.00000","0.76473","287.06897","0.89105","-0.31276","0.00391","168.09956"
"46.50000","0.77334","289.44434","0.89948","-0.30433","0.00395","169.49051"
"47.00000","0.78155","291.69626","0.90753","-0.29628","0.00398","170.80917"
"47.50000","0.79003","294.10849","0.91585","-0.28796","0.00402","172.22171"
"48.00000","0.79814","296.32742","0.92381","-0.28000","0.00405","173.52106"
"48.50000","0.80647","298.62698","0.93198","-0.27182","0.00409","174.86761"
"49.00000","0.81501","300.92615","0.94037","-0.26344","0.00413","176.21393"
"49.50000","0.82298","303.17865","0.94819","-0.25561","0.00416","177.53294"
"50.00000","0.83166","305.51697","0.95672","-0.24709","0.00420","178.90219"
"50.50000","0.83972","307.59634","0.96463","-0.23917","0.00423","180.11981"
"51.00000","0.84857","310.08267","0.97332","-0.23049","0.00427","181.57574"
"51.50000","0.85636","312.15442","0.98097","-0.22283","0.00430","182.78889"
"52.00000","0.86504","314.52362","0.98950","-0.21431","0.00434","184.17624"
"52.50000","0.87319","316.70883","0.99749","-0.20632","0.00438","185.45583"
"53.00000","0.88160","318.99222","1.00576","-0.19805","0.00441","186.79292"
"53.50000","0.88985","321.05984","1.01386","-0.18995","0.00445","188.00366"
"54.00000","0.89809","323.33963","1.02195","-0.18185","0.00448","189.33864"
"54.50000","0.90669","325.59756","1.03040","-0.17341","0.00452","190.66083"
"55.00000","0.91466","327.59229","1.03823","-0.16557","0.00455","191.82887"
"55.50000","0.92340","329.92480","1.04682","-0.15699","0.00459","193.19473"
"56.00000","0.93140","331.98032","1.05468","-0.14912","0.00463","194.39839"
"56.50000","0.94028","334.42181","1.06340","-0.14041","0.00466","195.82806"
"57.00000","0.94813","336.33527","1.07113","-0.13268","0.00470","196.94852"
"57.50000","0.95663","338.55566","1.07948","-0.12433","0.00474","198.24873"
"58.00000","0.96490","340.68991","1.08760","-0.11621","0.00477","199.49849"
"58.50000","0.97319","342.70917","1.09576","-0.10805","0.00481","200.68091"
"59.00000","0.98151","344.72604","1.10395","-0.09985","0.00484","201.86192"
"59.50000","0.98973","346.90414","1.11203","-0.09178","0.00488","203.13736"
"60.00000","0.99841","349.16959","1.12056","-0.08325","0.00492","204.46394"
"60.50000","1.00635","351.03922","1.12838","-0.07542","0.00495","205.55875"
"61.00000","1.01508","353.35486","1.13697","-0.06684","0.00499","206.91472"
"61.50000","1.02312","355.30609","1.14489","-0.05892","0.00502","208.05731"
"62.00000","1.03187","357.54047","1.15348","-0.05032","0.00506","209.36569"
"62.50000","1.03974","359.39203","1.16124","-0.04257","0.00509","210.44992"
"63.00000","1.04824","361.57120","1.16960","-0.03421","0.00513","211.72598"
"63.50000","1.05656","363.53363","1.17780","-0.02601","0.00517","212.87512"
"64.00000","1.06478","365.57858","1.18588","-0.01793","0.00520","214.07259"
"64.50000","1.07322","367.65121","1.19419","-0.00961","0.00524","215.28627"
"65.00000","1.08139","369.55392","1.20224","-0.00157","0.00527","216.40044"
"65.50000","1.09015","371.80231","1.21085","0.00704","0.00531","217.71703"
"66.00000","1.09796","373.56262","1.21855","0.01475","0.00535","218.74782"
"66.50000","1.10679","375.64682","1.22725","0.02344","0.00538","219.96828"
"67.00000","1.11476","377.52551","1.23510","0.03129","0.00542","221.06837"
"67.50000","1.12349","379.62399","1.24369","0.03988","0.00546","222.29720"
"68.00000","1.13143","381.33374","1.25153","0.04772","0.00549","223.29837"
"68.50000","1.13988","383.42874","1.25983","0.05603","0.00553","224.52515"
"69.00000","1.14826","385.34723","1.26809","0.06429","0.00556","225.64856"
"69.50000","1.15639","387.23611","1.27610","0.07229","0.00560","226.75464"
"70.00000","1.16497","389.16037","1.28456","0.08075","0.00563","227.88142"
"70.50000","1.17301","390.84656","1.29250","0.08870","0.00567","228.86880"
"71.00000","1.18182","393.08630","1.30119","0.09738","0.00571","230.18034"
"71.50000","1.18971","394.67569","1.30899","0.10518","0.00574","231.11104"
"72.00000","1.19840","396.73755","1.31756","0.11376","0.00578","232.31841"
"72.50000","1.20648","398.56149","1.32554","0.12173","0.00581","233.38646"
"73.00000","1.21511","400.45901","1.33406","0.13025","0.00585","234.49760"
"73.50000","1.22312","402.05801","1.34197","0.13817","0.00589","235.43393"
"74.00000","1.23147","403.99936","1.35022","0.14641","0.00592","236.57072"
"74.50000","1.23999","405.87067","1.35863","0.15482","0.00596","237.66650"
"75.00000","1.24808","407.58475","1.36662","0.16282","0.00599","238.67023"
"75.50000","1.25667","409.39877","1.37511","0.17130","0.00603","239.73247"
"76.00000","1.26472","411.04947","1.38306","0.17926","0.00607","240.69907"
"76.50000","1.27349","412.98727","1.39173","0.18792","0.00610","241.83380"
"77.00000","1.28132","414.50513","1.39947","0.19566","0.00614","242.72261"
"77.50000","1.29000","416.42984","1.40804","0.20423","0.00618","243.84967"
"78.00000","1.29814","418.11258","1.41608","0.21227","0.00621","244.83504"
"78.50000","1.30667","419.87183","1.42451","0.22070","0.00625","245.86520"
"79.00000","1.31479","421.51120","1.43254","0.22873","0.00628","246.82516"
"79.50000","1.32316","423.25516","1.44081","0.23701","0.00632","247.84637"
"80.00000","1.33169","424.97882","1.44924","0.24544","0.00636","248.85571"
"80.50000","1.33965","426.53683","1.45711","0.25330","0.00639","249.76804"
"81.00000","1.34836","428.43387","1.46571","0.26190","0.00643","250.87889"
"81.50000","1.35636","429.85965","1.47363","0.26982","0.00646","251.71379"
"82.00000","1.36518","431.69287","1.48235","0.27854","0.00650","252.78728"
"82.50000","1.37304","433.04791","1.49013","0.28632","0.00654","253.58075"
"83.00000","1.38172","434.86557","1.49871","0.29490","0.00657","254.64511"
"83.50000","1.38984","436.33710","1.50675","0.30294","0.00661","255.50681"
"84.00000","1.39828","437.92654","1.51509","0.31129","0.00665","256.43753"
"84.50000","1.40653","439.52328","1.52325","0.31945","0.00668","257.37253"
"85.00000","1.41474","440.97424","1.53138","0.32757","0.00672","258.22217"
"85.50000","1.42334","442.42734","1.53989","0.33609","0.00675","259.07306"
"86.00000","1.43132","443.63998","1.54781","0.34400","0.00679","259.78317"
"86.50000","1.44000","444.98141","1.55641","0.35261","0.00683","260.56866"
"87.00000","1.44806","445.89572","1.56442","0.36061","0.00686","261.10406"
"87.50000","1.45690","446.67014","1.57322","0.36941","0.00690","261.55753"
"88.00000","1.46474","447.48746","1.58101","0.37720","0.00694","262.03613"
"88.50000","1.47329","448.63699","1.58949","0.38568","0.00697","262.70929"
"89.00000","1.48157","449.71295","1.59771","0.39391","0.00701","263.33932"
"89.50000","1.48993","450.86313","1.60601","0.40220","0.00704","264.01285"
"90.00000","1.49821","451.91272","1.61423","0.41042","0.00708","264.62744"
"90.50000","1.50639","452.95554","1.62235","0.41854","0.00712","265.23810"
"91.00000","1.51504","454.21408","1.63092","0.42712","0.00715","265.97507"
"91.50000","1.52295","455.13596","1.63878","0.43497","0.00719","266.51489"
"92.00000","1.53166","456.30252","1.64743","0.44362","0.00723","267.19800"
"92.50000","1.53972","457.24823","1.65543","0.45163","0.00726","267.75177"
"93.00000","1.54856","458.47781","1.66421","0.46040","0.00730","268.47177"
"93.50000","1.55642","459.30609","1.67202","0.46821","0.00733","268.95679"
"94.00000","1.56502","460.06348","1.68057","0.47677","0.00737","269.40030"
"94.50000","1.57326","460.68082","1.68877","0.48497","0.00741","269.76181"
"95.00000","1.58148","461.41348","1.69695","0.49314","0.00744","270.19083"
"95.50000","1.58991","462.15869","1.70534","0.50153","0.00748","270.62720"
"96.00000","1.59804","457.16727","1.71375","0.50994","0.00752","267.70438"
"96.50000","1.60676","451.77188","1.72278","0.51897","0.00756","264.54498"
"97.00000","1.61464","446.63968","1.73096","0.52715","0.00759","261.53970"
"97.50000","1.62342","438.27341","1.74021","0.53641","0.00763","256.64066"
"98.00000","1.63140","427.00195","1.74883","0.54503","0.00767","250.04041"
"98.50000","1.64020","424.11435","1.75780","0.55399","0.00771","248.34950"
"99.00000","1.64814","422.84756","1.76581","0.56200","0.00775","247.60771"
"99.50000","1.65656","422.54370","1.77425","0.57044","0.00778","247.42978"
"100.00000","1.66489","422.58707","1.78258","0.57877","0.00782","247.45517"
"100.50000","1.67307","422.90097","1.79074","0.58693","0.00786","247.63898"
"101.00000","1.68159","423.43988","1.79922","0.59542","0.00789","247.95454"
"101.50000","1.68972","423.97562","1.80733","0.60352","0.00793","248.26826"
"102.00000","1.69851","424.88794","1.81606","0.61226","0.00797","248.80249"
"102.50000","1.70637","425.30383","1.82390","0.62010","0.00800","249.04604"
"103.00000","1.71506","426.17419","1.83254","0.62873","0.00804","249.55569"
"103.50000","1.72315","427.12646","1.84058","0.63678","0.00807","250.11331"
"104.00000","1.73184","428.09201","1.84921","0.64541","0.00811","250.67871"
"104.50000","1.73980","428.92935","1.85712","0.65331","0.00815","251.16904"
"105.00000","1.74816","429.90912","1.86543","0.66162","0.00818","251.74275"
"105.50000","1.75661","431.00339","1.87382","0.67001","0.00822","252.38353"
"106.00000","1.76468","431.78638","1.88184","0.67803","0.00825","252.84203"
"106.50000","1.77325","432.97018","1.89035","0.68654","0.00829","253.53523"
"107.00000","1.78136","433.81335","1.89840","0.69460","0.00833","254.02896"
"107.50000","1.79020","434.68149","1.90719","0.70339","0.00837","254.53732"
"108.00000","1.79804","434.93393","1.91502","0.71122","0.00840","254.68515"
"108.50000","1.80679","435.68555","1.92373","0.71993","0.00844","255.12527"
"109.00000","1.81481","436.10870","1.93172","0.72792","0.00847","255.37306"
"109.50000","1.82339","437.03708","1.94025","0.73645","0.00851","255.91669"
"110.00000","1.83148","437.69461","1.94831","0.74450","0.00855","256.30173"
"110.50000","1.83980","438.52203","1.95658","0.75277","0.00858","256.78622"
"111.00000","1.84831","439.48465","1.96503","0.76122","0.00862","257.34991"
"111.50000","1.85632","440.12585","1.97301","0.76920","0.00865","257.72540"
"112.00000","1.86502","441.01611","1.98166","0.77785","0.00869","258.24670"
"112.50000","1.87302","441.59064","1.98962","0.78582","0.00873","258.58313"
"113.00000","1.88188","442.63312","1.99842","0.79462","0.00877","259.19357"
"113.50000","1.88974","443.24683","2.00625","0.80244","0.00880","259.55295"
"114.00000","1.89837","444.07431","2.01483","0.81103","0.00884","260.03751"
"114.50000","1.90648","444.82233","2.02290","0.81909","0.00887","260.47552"
"115.00000","1.91498","445.66006","2.03136","0.82755","0.00891","260.96606"
"115.50000","1.92318","446.37961","2.03951","0.83570","0.00895","261.38742"
"116.00000","1.93144","447.09830","2.04773","0.84392","0.00898","261.80826"
"116.50000","1.94005","447.86777","2.05629","0.85249","0.00902","262.25885"
"117.00000","1.94805","448.46121","2.06427","0.86046","0.00906","262.60635"
"117.50000","1.95669","449.26874","2.07285","0.86904","0.00909","263.07919"
"118.00000","1.96476","449.80002","2.08090","0.87709","0.00913","263.39032"
"118.50000","1.97353","450.52451","2.08962","0.88582","0.00917","263.81454"
"119.00000","1.98139","451.02960","2.09746","0.89365","0.00920","264.11032"
"119.50000","1.98995","451.57455","2.10599","0.90218","0.00924","264.42941"
"120.00000","1.99820","452.03088","2.11421","0.91041","0.00927","264.69666"
"120.50000","2.00659","452.69937","2.12256","0.91875","0.00931","265.08810"
"121.00000","2.01486","453.07800","2.13081","0.92700","0.00935","265.30981"
"121.50000","2.02308","453.53394","2.13901","0.93520","0.00938","265.57678"
"122.00000","2.03174","454.16833","2.14762","0.94382","0.00942","265.94827"
"122.50000","2.03970","454.53888","2.15557","0.95176","0.00946","266.16525"
"123.00000","2.04841","455.07736","2.16424","0.96044","0.00949","266.48056"
"123.50000","2.05640","455.56799","2.17221","0.96840","0.00953","266.76788"
"124.00000","2.06518","456.11978","2.18096","0.97715","0.00957","267.09097"
"124.50000","2.07308","456.36417","2.18884","0.98504","0.00960","267.23410"
"125.00000","2.08165","456.93555","2.19738","0.99357","0.00964","267.56866"
"125.50000","2.08989","457.19553","2.20560","1.00180","0.00968","267.72092"
"126.00000","2.09814","457.61908","2.21383","1.01003","0.00971","267.96893"
"126.50000","2.10657","457.90771","2.22224","1.01843","0.00975","268.13794"
"127.00000","2.11468","458.18863","2.23034","1.02653","0.00978","268.30246"
"127.50000","2.12338","458.57016","2.23901","1.03521","0.00982","268.52585"
"128.00000","2.13133","458.73318","2.24695","1.04314","0.00986","268.62131"
"128.50000","2.14004","459.28778","2.25564","1.05183","0.00989","268.94608"
"129.00000","2.14807","459.41095","2.26366","1.05985","0.00993","269.01819"
"129.50000","2.15685","459.81049","2.27241","1.06861","0.00997","269.25217"
"130.00000","2.16477","459.98114","2.28032","1.07652","0.01000","269.35208"
"130.50000","2.17323","460.26273","2.28877","1.08496","0.01004","269.51697"
"131.00000","2.18162","460.44766","2.29715","1.09335","0.01008","269.62527"
"131.50000","2.18983","460.63126","2.30535","1.10155","0.01011","269.73279"
"132.00000","2.19824","460.92831","2.31374","1.10994","0.01015","269.90674"
"132.50000","2.20643","461.12561","2.32192","1.11812","0.01019","270.02225"
"133.00000","2.21510","461.48572","2.33056","1.12676","0.01022","270.23312"
"133.50000","2.22300","461.48511","2.33847","1.13467","0.01026","270.23276"
"134.00000","2.23166","461.92157","2.34710","1.14329","0.01030","270.48834"
"134.50000","2.23978","461.98807","2.35522","1.15142","0.01033","270.52728"
"135.00000","2.24850","462.46234","2.36391","1.16010","0.01037","270.80502"
"135.50000","2.25645","462.46463","2.37186","1.16806","0.01040","270.80637"
"136.00000","2.26491","462.76016","2.38031","1.17650","0.01044","270.97940"
"136.50000","2.27330","462.89969","2.38869","1.18488","0.01048","271.06110"
"137.00000","2.28144","463.16855","2.39681","1.19301","0.01051","271.21854"
"137.50000","2.28992","463.35403","2.40528","1.20147","0.01055","271.32715"
"138.00000","2.29805","463.51389","2.41341","1.20960","0.01059","271.42078"
"138.50000","2.30680","463.89050","2.42213","1.21832","0.01062","271.64130"
"139.00000","2.31469","463.87253","2.43003","1.22622","0.01066","271.63077"
"139.50000","2.32347","464.24872","2.43878","1.23497","0.01070","271.85107"
"140.00000","2.33147","464.35968","2.44677","1.24297","0.01073","271.91605"
"140.50000","2.34008","464.53290","2.45538","1.25157","0.01077","272.01749"
"141.00000","2.34815","464.65787","2.46344","1.25963","0.01081","272.09064"
"141.50000","2.35651","464.85342","2.47178","1.26798","0.01084","272.20517"
"142.00000","2.36493","464.96765","2.48020","1.27640","0.01088","272.27206"
"142.50000","2.37300","465.15149","2.48826","1.28446","0.01091","272.37970"
"143.00000","2.38161","465.44312","2.49685","1.29305","0.01095","272.55048"
"143.50000","2.38968","465.37579","2.50493","1.30112","0.01099","272.51105"
"144.00000","2.39852","465.58051","2.51376","1.30995","0.01103","272.63092"
"144.50000","2.40639","465.64737","2.52162","1.31781","0.01106","272.67007"
"145.00000","2.41503","465.75153","2.53026","1.32645","0.01110","272.73108"
"145.50000","2.42319","465.85275","2.53841","1.33460","0.01113","272.79034"
"146.00000","2.43172","466.07214","2.54693","1.34312","0.01117","272.91882"
"146.50000","2.43984","466.08127","2.55505","1.35124","0.01121","272.92416"
"147.00000","2.44817","466.10892","2.56337","1.35957","0.01124","272.94034"
"147.50000","2.45666","466.26566","2.57186","1.36805","0.01128","273.03214"
"148.00000","2.46465","466.08508","2.57985","1.37605","0.01132","272.92639"
"148.50000","2.47326","466.24649","2.58846","1.38465","0.01135","273.02090"
"149.00000","2.48140","466.36853","2.59659","1.39278","0.01139","273.09238"
"149.50000","2.49022","466.40881","2.60541","1.40160","0.01143","273.11597"
"150.00000","2.49805","466.38980","2.61324","1.40943","0.01146","273.10483"
"150.50000","2.50675","466.57062","2.62193","1.41812","0.01150","273.21069"
"151.00000","2.51485","466.55774","2.63003","1.42622","0.01154","273.20316"
"151.50000","2.52331","466.82452","2.63848","1.43467","0.01157","273.35938"
"152.00000","2.53147","466.75839","2.64664","1.44284","0.01161","273.32065"
"152.50000","2.53980","466.94482","2.65495","1.45115","0.01165","273.42984"
"153.00000","2.54837","467.08685","2.66352","1.45971","0.01168","273.51300"
"153.50000","2.55633","467.11084","2.67148","1.46768","0.01172","273.52704"
"154.00000","2.56508","467.40146","2.68022","1.47641","0.01176","273.69724"
"154.50000","2.57307","467.38269","2.68821","1.48440","0.01179","273.68622"
"155.00000","2.58193","467.69339","2.69705","1.49324","0.01183","273.86816"
"155.50000","2.58976","467.69995","2.70487","1.50106","0.01187","273.87201"
"156.00000","2.59834","467.88022","2.71344","1.50963","0.01190","273.97757"
"156.50000","2.60650","467.81366","2.72161","1.51780","0.01194","273.93860"
"157.00000","2.61483","467.88342","2.72994","1.52613","0.01198","273.97943"
"157.50000","2.62319","467.94336","2.73829","1.53448","0.01201","274.01456"
"158.00000","2.63138","467.96506","2.74648","1.54267","0.01205","274.02725"
"158.50000","2.64003","468.24268","2.75512","1.55131","0.01209","274.18982"
"159.00000","2.64800","468.28571","2.76308","1.55928","0.01212","274.21500"
"159.50000","2.65669","468.39481","2.77177","1.56796","0.01216","274.27890"
"160.00000","2.66476","468.48700","2.77983","1.57602","0.01219","274.33289"
"160.50000","2.67357","468.71390","2.78863","1.58482","0.01223","274.46576"
"161.00000","2.68144","468.75845","2.79649","1.59269","0.01227","274.49185"
"161.50000","2.68997","468.95303","2.80502","1.60121","0.01230","274.60577"
"162.00000","2.69825","468.97220","2.81329","1.60949","0.01234","274.61700"
"162.50000","2.70647","469.05893","2.82151","1.61770","0.01238","274.66779"
"163.00000","2.71488","469.15216","2.82991","1.62610","0.01241","274.72238"
"163.50000","2.72308","469.24957","2.83811","1.63430","0.01245","274.77942"
"164.00000","2.73177","469.39197","2.84679","1.64299","0.01249","274.86279"
"164.50000","2.73967","469.37875","2.85469","1.65088","0.01252","274.85507"
"165.00000","2.74841","469.56631","2.86342","1.65961","0.01256","274.96490"
"165.50000","2.75643","469.53992","2.87144","1.66764","0.01260","274.94943"
"166.00000","2.76518","469.79874","2.88017","1.67637","0.01263","275.10101"
"166.50000","2.77307","469.76028","2.88807","1.68426","0.01267","275.07849"
"167.00000","2.78159","469.95740","2.89657","1.69277","0.01271","275.19391"
"167.50000","2.78993","469.97089","2.90491","1.70111","0.01274","275.20181"
"168.00000","2.79808","469.97360","2.91307","1.70926","0.01278","275.20340"
"168.50000","2.80661","470.19669","2.92158","1.71778","0.01282","275.33401"
"169.00000","2.81472","470.32285","2.92968","1.72588","0.01285","275.40790"
"169.50000","2.82353","470.61462","2.93847","1.73467","0.01289","275.57877"
"170.00000","2.83136","470.49100","2.94632","1.74251","0.01292","275.50638"
"170.50000","2.84012","470.87170","2.95506","1.75125","0.01296","275.72931"
"171.00000","2.84808","470.70184","2.96303","1.75922","0.01300","275.62982"
"171.50000","2.85680","471.07205","2.97173","1.76792","0.01304","275.84662"
"172.00000","2.86481","470.93936","2.97974","1.77594","0.01307","275.76892"
"172.50000","2.87315","470.99832","2.98808","1.78427","0.01311","275.80344"
"173.00000","2.88159","471.13644","2.99651","1.79270","0.01314","275.88434"
"173.50000","2.88972","471.26611","3.00464","1.80083","0.01318","275.96027"
"174.00000","2.89828","471.38794","3.01319","1.80938","0.01322","276.03159"
"174.50000","2.90637","471.58408","3.02126","1.81746","0.01325","276.14645"
"175.00000","2.91516","471.70004","3.03005","1.82625","0.01329","276.21436"
"175.50000","2.92302","471.62305","3.03791","1.83411","0.01333","276.16925"
"176.00000","2.93167","471.82339","3.04655","1.84274","0.01336","276.28659"
"176.50000","2.93984","471.96350","3.05471","1.85090","0.01340","276.36862"
"177.00000","2.94843","472.22452","3.06329","1.85948","0.01344","276.52145"
"177.50000","2.95650","472.06641","3.07136","1.86756","0.01347","276.42889"
"178.00000","2.96484","472.33347","3.07969","1.87588","0.01351","276.58527"
"178.50000","2.97332","472.35675","3.08817","1.88436","0.01355","276.59891"
"179.00000","2.98138","472.44324","3.09623","1.89242","0.01358","276.64954"
"179.50000","2.99000","472.71973","3.10483","1.90102","0.01362","276.81146"
"180.00000","2.99807","472.73993","3.11290","1.90909","0.01365","276.82327"
"180.50000","3.00688","473.02899","3.12169","1.91788","0.01369","276.99255"
"181.00000","3.01467","472.95746","3.12948","1.92568","0.01373","276.95065"
"181.50000","3.02339","473.02740","3.13820","1.93439","0.01377","276.99161"
"182.00000","3.03150","472.72876","3.14633","1.94252","0.01380","276.81674"
"182.50000","3.03997","472.75980","3.15479","1.95099","0.01384","276.83490"
"183.00000","3.04815","472.65106","3.16299","1.95918","0.01387","276.77124"
"183.50000","3.05644","472.86591","3.17127","1.96746","0.01391","276.89703"
"184.00000","3.06503","472.98428","3.17984","1.97604","0.01395","276.96637"
"184.50000","3.07300","472.77487","3.18783","1.98402","0.01398","276.84375"
"185.00000","3.08171","472.96420","3.19653","1.99272","0.01402","276.95462"
"185.50000","3.08968","473.00049","3.20449","2.00068","0.01406","276.97586"
"186.00000","3.09857","473.23181","3.21337","2.00956","0.01410","277.11130"
"186.50000","3.10641","472.95364","3.22123","2.01742","0.01413","276.94843"
"187.00000","3.11497","472.97916","3.22978","2.02598","0.01417","276.96338"
"187.50000","3.12318","472.86484","3.23800","2.03420","0.01420","276.89642"
"188.00000","3.13160","472.91760","3.24642","2.04261","0.01424","276.92731"
"188.50000","3.13985","472.61383","3.25469","2.05088","0.01428","276.74945"
"189.00000","3.14806","472.37125","3.26291","2.05910","0.01431","276.60739"
"189.50000","3.15672","472.20496","3.27158","2.06778","0.01435","276.51001"
"190.00000","3.16466","471.83853","3.27954","2.07574","0.01439","276.29544"
"190.50000","3.17330","471.86902","3.28818","2.08437","0.01442","276.31329"
"191.00000","3.18142","471.39679","3.29632","2.09251","0.01446","276.03677"
"191.50000","3.19025","471.52652","3.30515","2.10134","0.01450","276.11273"
"192.00000","3.19811","471.08707","3.31303","2.10922","0.01453","275.85541"
"192.50000","3.20667","471.02664","3.32159","2.11779","0.01457","275.82004"
"193.00000","3.21492","470.98230","3.32985","2.12604","0.01461","275.79407"
"193.50000","3.22320","470.90381","3.33813","2.13432","0.01464","275.74811"
"194.00000","3.23155","471.06030","3.34647","2.14266","0.01468","275.83975"
"194.50000","3.23973","471.17273","3.35465","2.15084","0.01472","275.90558"
"195.00000","3.24843","471.35287","3.36333","2.15953","0.01475","276.01105"
"195.50000","3.25628","471.32285","3.37119","2.16738","0.01479","275.99347"
"196.00000","3.26506","471.60968","3.37995","2.17614","0.01483","276.16144"
"196.50000","3.27307","471.65604","3.38796","2.18415","0.01486","276.18857"
"197.00000","3.28182","471.92731","3.39669","2.19288","0.01490","276.34744"
"197.50000","3.28976","471.69482","3.40465","2.20084","0.01493","276.21130"
"198.00000","3.29830","471.92676","3.41318","2.20937","0.01497","276.34711"
"198.50000","3.30659","471.89746","3.42147","2.21766","0.01501","276.32996"
"199.00000","3.31478","471.93854","3.42966","2.22585","0.01504","276.35400"
"199.50000","3.32328","472.03629","3.43814","2.23434","0.01508","276.41125"
"200.00000","3.33134","471.84186","3.44622","2.24242","0.01512","276.29739"
"200.50000","3.34015","472.10101","3.45501","2.25120","0.01516","276.44916"
"201.00000","3.34803","471.87082","3.46291","2.25910","0.01519","276.31436"
"201.50000","3.35674","472.03629","3.47161","2.26780","0.01523","276.41125"
"202.00000","3.36478","471.85617","3.47966","2.27586","0.01526","276.30579"
"202.50000","3.37350","471.97437","3.48838","2.28457","0.01530","276.37500"
"203.00000","3.38146","471.85590","3.49634","2.29253","0.01534","276.30560"
"203.50000","3.38983","472.03604","3.50470","2.30089","0.01537","276.41110"
"204.00000","3.39828","471.96066","3.51315","2.30934","0.01541","276.36697"
"204.50000","3.40637","471.88849","3.52125","2.31744","0.01545","276.32471"
"205.00000","3.41487","472.16772","3.52973","2.32593","0.01548","276.48822"
"205.50000","3.42303","471.90149","3.53791","2.33410","0.01552","276.33231"
"206.00000","3.43185","472.18030","3.54671","2.34291","0.01556","276.49557"
"206.50000","3.43972","471.81216","3.55460","2.35079","0.01559","276.28000"
"207.00000","3.44838","471.89716","3.56326","2.35945","0.01563","276.32977"
"207.50000","3.45651","471.82819","3.57139","2.36758","0.01567","276.28940"
"208.00000","3.46512","471.82468","3.58000","2.37620","0.01570","276.28732"
"208.50000","3.47315","471.67245","3.58804","2.38423","0.01574","276.19818"
"209.00000","3.48153","471.80896","3.59641","2.39260","0.01578","276.27814"
"209.50000","3.48998","471.76764","3.60487","2.40106","0.01581","276.25394"
"210.00000","3.49800","471.58105","3.61290","2.40909","0.01585","276.14468"
"210.50000","3.50661","471.69122","3.62150","2.41769","0.01589","276.20920"
"211.00000","3.51469","471.51102","3.62959","2.42578","0.01592","276.10367"
"211.50000","3.52351","471.80750","3.63839","2.43459","0.01596","276.27728"
"212.00000","3.53135","471.56067","3.64625","2.44244","0.01599","276.13275"
"212.50000","3.54011","471.74762","3.65499","2.45118","0.01603","276.24222"
"213.00000","3.54815","471.55273","3.66305","2.45924","0.01607","276.12808"
"213.50000","3.55672","471.64081","3.67161","2.46780","0.01611","276.17966"
"214.00000","3.56485","471.46698","3.67975","2.47595","0.01614","276.07788"
"214.50000","3.57312","471.46512","3.68802","2.48422","0.01618","276.07678"
"215.00000","3.58166","471.32587","3.69657","2.49276","0.01622","275.99524"
"215.50000","3.58968","471.09750","3.70460","2.50080","0.01625","275.86151"
"216.00000","3.59837","471.00967","3.71329","2.50949","0.01629","275.81009"
"216.50000","3.60640","470.76099","3.72134","2.51753","0.01632","275.66446"
"217.00000","3.61526","470.75354","3.73020","2.52639","0.01636","275.66010"
"217.50000","3.62307","470.52155","3.73802","2.53422","0.01640","275.52426"
"218.00000","3.63163","470.34564","3.74659","2.54278","0.01643","275.42126"
"218.50000","3.63986","470.19986","3.75483","2.55102","0.01647","275.33588"
"219.00000","3.64828","470.17947","3.76325","2.55944","0.01651","275.32394"
"219.50000","3.65649","470.03305","3.77147","2.56766","0.01654","275.23822"
"220.00000","3.66474","469.94565","3.77973","2.57592","0.01658","275.18701"
"220.50000","3.67340","469.79892","3.78839","2.58459","0.01662","275.10110"
"221.00000","3.68136","469.36130","3.79638","2.59257","0.01665","274.84485"
"221.50000","3.69000","460.72827","3.80552","2.60171","0.01669","269.78958"
"222.00000","3.69810","459.15353","3.81370","2.60989","0.01673","268.86746"
"222.50000","3.70693","458.49704","3.82257","2.61876","0.01677","268.48303"
"223.00000","3.71473","457.83511","3.83041","2.62660","0.01680","268.09543"
"223.50000","3.72332","457.71646","3.83900","2.63519","0.01684","268.02597"
"224.00000","3.73153","457.29932","3.84724","2.64344","0.01688","267.78168"
"224.50000","3.73985","457.37637","3.85555","2.65174","0.01691","267.82681"
"225.00000","3.74818","457.15552","3.86390","2.66009","0.01695","267.69748"
"225.50000","3.75640","457.02676","3.87212","2.66831","0.01699","267.62210"
"226.00000","3.76505","457.11743","3.88077","2.67697","0.01702","267.67517"
"226.50000","3.77296","456.76260","3.88870","2.68490","0.01706","267.46741"
"227.00000","3.78174","456.92044","3.89747","2.69367","0.01710","267.55981"
"227.50000","3.78973","456.76804","3.90547","2.70166","0.01713","267.47058"
"228.00000","3.79852","456.94223","3.91425","2.71044","0.01717","267.57260"
"228.50000","3.80643","456.78723","3.92217","2.71836","0.01720","267.48181"
"229.00000","3.81495","456.94769","3.93068","2.72687","0.01724","267.57578"
"229.50000","3.82323","457.07928","3.93895","2.73515","0.01728","267.65283"
"230.00000","3.83152","457.24991","3.94724","2.74343","0.01731","267.75275"
"230.50000","3.83994","457.40387","3.95565","2.75184","0.01735","267.84293"
"231.00000","3.84807","457.31207","3.96378","2.75997","0.01739","267.78915"
"231.50000","3.85680","457.57419","3.97249","2.76868","0.01743","267.94266"
"232.00000","3.86466","457.46347","3.98035","2.77655","0.01746","267.87781"
"232.50000","3.87333","457.75684","3.98902","2.78521","0.01750","268.04959"
"233.00000","3.88146","457.70883","3.99715","2.79334","0.01753","268.02148"
"233.50000","3.89017","458.08685","4.00583","2.80203","0.01757","268.24286"
"234.00000","3.89810","458.05011","4.01376","2.80996","0.01761","268.22134"
"234.50000","3.90651","458.19623","4.02217","2.81837","0.01764","268.30688"
"235.00000","3.91497","458.38849","4.03061","2.82681","0.01768","268.41946"
"235.50000","3.92312","458.42953","4.03876","2.83496","0.01772","268.44351"
"236.00000","3.93155","458.38245","4.04719","2.84339","0.01775","268.41592"
"236.50000","3.93973","458.31372","4.05538","2.85158","0.01779","268.37570"
"237.00000","3.94849","458.69913","4.06412","2.86031","0.01783","268.60138"
"237.50000","3.95632","458.56461","4.07196","2.86815","0.01786","268.52261"
"238.00000","3.96506","458.73657","4.08068","2.87687","0.01790","268.62329"
"238.50000","3.97312","458.65768","4.08876","2.88495","0.01794","268.57712"
"239.00000","3.98179","458.95322","4.09740","2.89359","0.01797","268.75015"
"239.50000","3.98976","458.80618","4.10539","2.90158","0.01801","268.66406"
"240.00000","3.99822","458.85983","4.11384","2.91003","0.01805","268.69550"
"240.50000","4.00662","458.91818","4.12224","2.91843","0.01808","268.72964"
"241.00000","4.01471","458.81973","4.13034","2.92653","0.01812","268.67200"
"241.50000","4.02329","458.98035","4.13890","2.93509","0.01816","268.76605"
"242.00000","4.03136","458.86966","4.14698","2.94318","0.01819","268.70123"
"242.50000","4.04014","458.97961","4.15575","2.95195","0.01823","268.76562"
"243.00000","4.04804","458.96103","4.16365","2.95984","0.01826","268.75473"
"243.50000","4.05675","458.25314","4.17240","2.96860","0.01830","268.34021"
"244.00000","4.06483","457.93210","4.18050","2.97669","0.01834","268.15222"
"244.50000","4.07344","458.09186","4.18911","2.98530","0.01838","268.24579"
"245.00000","4.08153","457.86108","4.19720","2.99340","0.01841","268.11066"
"245.50000","4.08982","457.85587","4.20550","3.00169","0.01845","268.10757"
"246.00000","4.09833","457.83078","4.21401","3.01020","0.01849","268.09290"
"246.50000","4.10636","457.65460","4.22205","3.01824","0.01852","267.98975"
"247.00000","4.11492","456.47748","4.23067","3.02687","0.01856","267.30045"
"247.50000","4.12305","455.73575","4.23884","3.03504","0.01859","266.86612"
"248.00000","4.13185","455.54880","4.24766","3.04385","0.01863","266.75662"
"248.50000","4.13972","455.12296","4.25555","3.05174","0.01867","266.50726"
"249.00000","4.14836","455.12970","4.26419","3.06038","0.01871","266.51123"
"249.50000","4.15655","454.76941","4.27240","3.06859","0.01874","266.30023"
"250.00000","4.16502","454.77481","4.28087","3.07706","0.01878","266.30341"
"250.50000","4.17313","454.56024","4.28900","3.08519","0.01881","266.17776"
"251.00000","4.18145","454.52740","4.29732","3.09351","0.01885","266.15854"
"251.50000","4.19002","454.64252","4.30588","3.10207","0.01889","266.22595"
"252.00000","4.19797","454.40747","4.31385","3.11004","0.01892","266.08832"
"252.50000","4.20665","454.71591","4.32251","3.11870","0.01896","266.26892"
"253.00000","4.21472","454.46478","4.33059","3.12679","0.01900","266.12186"
"253.50000","4.22355","454.81534","4.33940","3.13559","0.01904","266.32715"
"254.00000","4.23137","454.55881","4.34724","3.14343","0.01907","266.17691"
"254.50000","4.24007","454.54892","4.35593","3.15213","0.01911","266.17114"
"255.00000","4.24819","454.48459","4.36406","3.16025","0.01914","266.13345"
"255.50000","4.25659","454.40778","4.37246","3.16865","0.01918","266.08847"
"256.00000","4.26484","454.01501","4.38074","3.17693","0.01922","265.85849"
"256.50000","4.27309","453.85501","4.38899","3.18518","0.01925","265.76480"
"257.00000","4.28170","453.91013","4.39760","3.19379","0.01929","265.79706"
"257.50000","4.28966","453.46472","4.40559","3.20178","0.01933","265.53625"
"258.00000","4.29840","453.64517","4.41432","3.21051","0.01936","265.64194"
"258.50000","4.30640","453.33389","4.42234","3.21853","0.01940","265.45966"
"259.00000","4.31527","453.38409","4.43120","3.22739","0.01944","265.48904"
"259.50000","4.32314","452.88745","4.43910","3.23529","0.01947","265.19821"
"260.00000","4.33164","452.66376","4.44762","3.24381","0.01951","265.06723"
"260.50000","4.33990","452.42020","4.45589","3.25208","0.01955","264.92462"
"261.00000","4.34817","452.20441","4.46417","3.26036","0.01958","264.79825"
"261.50000","4.35651","451.93033","4.47253","3.26872","0.01962","264.63776"
"262.00000","4.36472","451.59970","4.48075","3.27694","0.01966","264.44415"
"262.50000","4.37341","451.36777","4.48945","3.28565","0.01969","264.30835"
"263.00000","4.38135","450.64450","4.49744","3.29363","0.01973","263.88483"
"263.50000","4.39007","450.27020","4.50618","3.30237","0.01977","263.66565"
"264.00000","4.39812","449.81818","4.51426","3.31045","0.01980","263.40094"
"264.50000","4.40685","449.32761","4.52302","3.31921","0.01984","263.11368"
"265.00000","4.41474","448.70901","4.53094","3.32713","0.01988","262.75143"
"265.50000","4.42325","448.29468","4.53947","3.33566","0.01991","262.50882"
"266.00000","4.43155","447.79297","4.54780","3.34399","0.01995","262.21503"
"266.50000","4.43977","447.58282","4.55603","3.35223","0.01999","262.09198"
"267.00000","4.44821","447.22409","4.56449","3.36068","0.02002","261.88193"
"267.50000","4.45641","446.80624","4.57272","3.36891","0.02006","261.63724"
"268.00000","4.46516","446.71246","4.58147","3.37767","0.02010","261.58234"
"268.50000","4.47297","446.10654","4.58932","3.38551","0.02013","261.22751"
"269.00000","4.48180","445.84824","4.59816","3.39436","0.02017","261.07626"
"269.50000","4.48976","445.01385","4.60617","3.40236","0.02021","260.58768"
"270.00000","4.49849","444.43713","4.61493","3.41113","0.02024","260.24994"
"270.50000","4.50644","441.67828","4.62304","3.41924","0.02028","258.63446"
"271.00000","4.51488","440.81262","4.63153","3.42772","0.02032","258.12753"
"271.50000","4.52325","440.16101","4.63994","3.43613","0.02035","257.74597"
"272.00000","4.53139","439.57318","4.64811","3.44430","0.02039","257.40176"
"272.50000","4.53996","436.91245","4.65683","3.45302","0.02043","255.84370"
"273.00000","4.54801","435.40652","4.66497","3.46116","0.02046","254.96188"
"273.50000","4.55682","435.00644","4.67379","3.46999","0.02050","254.72760"
"274.00000","4.56469","434.64294","4.68169","3.47789","0.02054","254.51476"
"274.50000","4.57338","434.55203","4.69039","3.48658","0.02057","254.46152"
"275.00000","4.58147","434.32355","4.69848","3.49468","0.02061","254.32773"
"275.50000","4.59011","434.50235","4.70711","3.50331","0.02065","254.43242"
"276.00000","4.59812","434.32437","4.71514","3.51133","0.02068","254.32820"
"276.50000","4.60646","434.19177","4.72349","3.51968","0.02072","254.25056"
"277.00000","4.61499","434.21118","4.73202","3.52821","0.02076","254.26192"
"277.50000","4.62309","434.06201","4.74012","3.53631","0.02079","254.17458"
"278.00000","4.63166","434.22623","4.74869","3.54488","0.02083","254.27074"
"278.50000","4.63973","434.29813","4.75674","3.55294","0.02087","254.31284"
"279.00000","4.64850","434.51962","4.76550","3.56169","0.02090","254.44254"
"279.50000","4.65632","434.41589","4.77333","3.56953","0.02094","254.38179"
"280.00000","4.66500","434.68814","4.78200","3.57819","0.02098","254.54121"
"280.50000","4.67313","434.75470","4.79012","3.58632","0.02101","254.58018"
"281.00000","4.68168","434.81229","4.79867","3.59486","0.02105","254.61391"
"281.50000","4.68980","434.85657","4.80678","3.60298","0.02109","254.63985"
"282.00000","4.69818","434.87637","4.81516","3.61135","0.02112","254.65144"
"282.50000","4.70670","434.98889","4.82368","3.61987","0.02116","254.71733"
"283.00000","4.71464","435.02957","4.83161","3.62781","0.02119","254.74115"
"283.50000","4.72337","435.19171","4.84034","3.63653","0.02123","254.83609"
"284.00000","4.73135","435.06943","4.84833","3.64452","0.02127","254.76448"
"284.50000","4.74017","435.44211","4.85712","3.65332","0.02131","254.98271"
"285.00000","4.74802","435.37720","4.86498","3.66117","0.02134","254.94470"
"285.50000","4.75670","435.54828","4.87365","3.66984","0.02138","255.04489"
"286.00000","4.76484","435.59653","4.88178","3.67797","0.02141","255.07314"
"286.50000","4.77331","435.75266","4.89024","3.68644","0.02145","255.16457"
"287.00000","4.78155","435.70999","4.89849","3.69468","0.02149","255.13959"
"287.50000","4.78972","435.82910","4.90666","3.70285","0.02152","255.20934"
"288.00000","4.79833","435.96042","4.91526","3.71145","0.02156","255.28622"
"288.50000","4.80632","435.93472","4.92325","3.71944","0.02160","255.27118"
"289.00000","4.81502","436.13123","4.93194","3.72813","0.02163","255.38625"
"289.50000","4.82307","436.06097","4.93999","3.73618","0.02167","255.34511"
"290.00000","4.83191","436.34833","4.94881","3.74500","0.02171","255.51338"
"290.50000","4.83974","436.24020","4.95665","3.75284","0.02174","255.45006"
"291.00000","4.84829","436.43884","4.96518","3.76137","0.02178","255.56638"
"291.50000","4.85657","436.38339","4.97347","3.76967","0.02182","255.53391"
"292.00000","4.86493","436.30191","4.98184","3.77803","0.02185","255.48619"
"292.50000","4.87322","436.37265","4.99012","3.78631","0.02189","255.52762"
"293.00000","4.88140","436.27182","4.99831","3.79450","0.02193","255.46858"
"293.50000","4.89003","436.55112","5.00692","3.80311","0.02196","255.63213"
"294.00000","4.89794","436.22641","5.01485","3.81104","0.02200","255.44199"
"294.50000","4.90667","436.48523","5.02356","3.81975","0.02204","255.59354"
"295.00000","4.91472","436.37064","5.03162","3.82781","0.02207","255.52644"
"295.50000","4.92353","436.55093","5.04042","3.83662","0.02211","255.63202"
"296.00000","4.93141","436.39810","5.04831","3.84450","0.02214","255.54253"
"296.50000","4.94002","436.59061","5.05691","3.85310","0.02218","255.65524"
"297.00000","4.94827","436.51099","5.06516","3.86136","0.02222","255.60863"
"297.50000","4.95647","436.52216","5.07336","3.86956","0.02225","255.61516"
"298.00000","4.96489","436.38260","5.08179","3.87798","0.02229","255.53345"
"298.50000","4.97302","436.41660","5.08992","3.88611","0.02233","255.55334"
"299.00000","4.98174","436.66690","5.09863","3.89482","0.02237","255.69992"
"299.50000","4.98964","436.43591","5.10653","3.90273","0.02240","255.56467"
"300.00000","4.99844","436.55899","5.11533","3.91152","0.02244","255.63673"
"300.50000","5.00640","436.31387","5.12331","3.91950","0.02247","255.49319"
"301.00000","5.01520","436.48135","5.13209","3.92829","0.02251","255.59128"
"301.50000","5.02314","436.33887","5.14005","3.93624","0.02255","255.50784"
"302.00000","5.03155","436.39606","5.14845","3.94464","0.02258","255.54132"
"302.50000","5.03990","436.27075","5.15680","3.95300","0.02262","255.46796"
"303.00000","5.04809","436.28308","5.16499","3.96119","0.02266","255.47517"
"303.50000","5.05657","436.33618","5.17347","3.96966","0.02269","255.50626"
"304.00000","5.06472","436.11945","5.18163","3.97782","0.02273","255.37935"
"304.50000","5.07348","436.05194","5.19040","3.98660","0.02277","255.33981"
"305.00000","5.08138","435.53210","5.19833","3.99452","0.02280","255.03542"
"305.50000","5.09007","435.36801","5.20702","4.00322","0.02284","254.93933"
"306.00000","5.09815","435.21375","5.21512","4.01131","0.02288","254.84900"
"306.50000","5.10683","434.95282","5.22381","4.02000","0.02291","254.69621"
"307.00000","5.11479","434.75293","5.23179","4.02798","0.02295","254.57916"
"307.50000","5.12318","434.57922","5.24018","4.03638","0.02299","254.47743"
"308.00000","5.13162","434.29065","5.24864","4.04483","0.02302","254.30846"
"308.50000","5.13969","434.06552","5.25672","4.05291","0.02306","254.17662"
"309.00000","5.14826","433.98984","5.26529","4.06149","0.02310","254.13231"
"309.50000","5.15635","433.63016","5.27340","4.06960","0.02313","253.92169"
"310.00000","5.16519","433.57938","5.28225","4.07844","0.02317","253.89195"
"310.50000","5.17304","433.23810","5.29012","4.08631","0.02321","253.69211"
"311.00000","5.18182","433.19626","5.29890","4.09510","0.02324","253.66762"
"311.50000","5.18980","432.79211","5.30691","4.10310","0.02328","253.43095"
"312.00000","5.19838","432.60095","5.31549","4.11169","0.02332","253.31902"
"312.50000","5.20647","432.12943","5.32361","4.11980","0.02335","253.04291"
"313.00000","5.21481","431.80237","5.33197","4.12816","0.02339","252.85139"
"313.50000","5.22331","431.15494","5.34051","4.13670","0.02343","252.47227"
"314.00000","5.23132","430.47028","5.34856","4.14475","0.02346","252.07135"
"314.50000","5.24000","429.93912","5.35727","4.15346","0.02350","251.76031"
"315.00000","5.24801","426.19580","5.36549","4.16168","0.02354","249.56834"
"315.50000","5.25688","424.28061","5.37447","4.17066","0.02358","248.44685"
"316.00000","5.26474","422.28488","5.38245","4.17864","0.02361","247.27821"
"316.50000","5.27337","421.12054","5.39114","4.18733","0.02365","246.59641"
"317.00000","5.28148","420.09860","5.39931","4.19550","0.02368","245.99799"
"317.50000","5.28997","419.39017","5.40784","4.20403","0.02372","245.58315"
"318.00000","5.29818","418.77682","5.41608","4.21228","0.02376","245.22400"
"318.50000","5.30645","418.18591","5.42439","4.22058","0.02379","244.87798"
"319.00000","5.31506","417.52527","5.43303","4.22922","0.02383","244.49112"
"319.50000","5.32304","416.74042","5.44106","4.23726","0.02387","244.03152"
"320.00000","5.33168","416.25305","5.44973","4.24592","0.02391","243.74614"
"320.50000","5.33977","415.53415","5.45786","4.25405","0.02394","243.32518"
"321.00000","5.34852","413.69992","5.46671","4.26291","0.02398","242.25110"
"321.50000","5.35639","402.42133","5.47523","4.27142","0.02402","235.64667"
"322.00000","5.36495","396.33429","5.48413","4.28033","0.02406","232.08228"
"322.50000","5.37320","392.90344","5.49258","4.28877","0.02409","230.07327"
"323.00000","5.38158","391.15170","5.50106","4.29725","0.02413","229.04750"
"323.50000","5.38985","390.08505","5.50939","4.30558","0.02417","228.42290"
"324.00000","5.39809","389.37625","5.51767","4.31386","0.02420","228.00784"
"324.37600","5.40451","367.04810","5.52552","4.32171","0.02424","214.93311"
"324.79100","5.41157","351.69507","5.53356","4.32976","0.02427","205.94279"
"325.29100","5.41962","351.24240","5.54164","4.33784","0.02431","205.67772"
"325.79100","5.42833","351.31363","5.55034","4.34654","0.02435","205.71944"
"326.29100","5.43628","351.37933","5.55830","4.35449","0.02438","205.75790"
"326.79100","5.44476","352.01065","5.56673","4.36293","0.02442","206.12759"
"327.29100","5.45311","352.63306","5.57505","4.37124","0.02446","206.49205"
"327.79100","5.46125","353.11688","5.58315","4.37935","0.02449","206.77538"
"328.02600","5.46526","353.42398","5.58714","4.38333","0.02451","206.95520"