File: flexion/5_axis/New folder/Specimen_RawData_13.csv
Specimen properties : Specimen label,"G2"
Specimen properties : Support span,"72.00",mm
Specimen properties : Thickness,"4.30",mm
Specimen properties : Width,"13.79",mm
Maximum Load : Maximum Load,"910.6",N
Tangent Modulus of Elasticity : Tangent Modulus of Elasticity,"42705467014.90370",Pa
Test : Rate 1,"1.00000",mm/min
Specimen notes : Specimen note 1,""

Time,Displacement,Load,Flexure extension,Corrected extension,Flexure strain (Corrected extension),Flexure stress
(s),(mm),(N),(mm),(mm),(mm/mm),(MPa)
"0.00000","-0.00007","49.29149","0.07912","-1.05568","0.00039","20.87827"
"0.50000","0.00634","52.17069","0.08515","-1.04965","0.00042","22.09781"
"1.00000","0.01427","55.70049","0.09261","-1.04219","0.00046","23.59292"
"1.50000","0.02303","59.40409","0.10090","-1.03390","0.00050","25.16164"
"2.00000","0.03096","62.79240","0.10843","-1.02636","0.00054","26.59682"
"2.50000","0.03989","66.50274","0.11692","-1.01787","0.00058","28.16840"
"3.00000","0.04769","69.65017","0.12435","-1.01044","0.00062","29.50154"
"3.50000","0.05628","73.32875","0.13252","-1.00228","0.00066","31.05967"
"4.00000","0.06448","76.76928","0.14031","-0.99449","0.00070","32.51697"
"4.50000","0.07292","80.25726","0.14835","-0.98645","0.00074","33.99436"
"5.00000","0.08115","83.84424","0.15615","-0.97864","0.00078","35.51369"
"5.50000","0.08934","87.36493","0.16393","-0.97086","0.00082","37.00494"
"6.00000","0.09800","91.06341","0.17223","-0.96257","0.00086","38.57150"
"6.50000","0.10594","94.67541","0.17983","-0.95497","0.00089","40.10142"
"7.00000","0.11460","98.29184","0.18813","-0.94667","0.00094","41.63322"
"7.50000","0.12271","101.87486","0.19589","-0.93891","0.00097","43.15088"
"8.00000","0.13159","105.86238","0.20438","-0.93042","0.00102","44.83986"
"8.50000","0.13938","109.29646","0.21183","-0.92297","0.00105","46.29442"
"9.00000","0.14795","113.07363","0.22003","-0.91476","0.00110","47.89431"
"9.50000","0.15622","116.85309","0.22793","-0.90686","0.00113","49.49517"
"10.00000","0.16450","120.55341","0.23585","-0.89894","0.00117","51.06250"
"10.50000","0.17284","124.29055","0.24383","-0.89097","0.00121","52.64544"
"11.00000","0.18104","128.04753","0.25166","-0.88314","0.00125","54.23677"
"11.50000","0.18973","132.01263","0.25997","-0.87483","0.00129","55.91626"
"12.00000","0.19758","135.52493","0.26747","-0.86732","0.00133","57.40395"
"12.50000","0.20636","139.73219","0.27585","-0.85895","0.00137","59.18601"
"13.00000","0.21435","143.26007","0.28349","-0.85131","0.00141","60.68031"
"13.50000","0.22311","147.35236","0.29186","-0.84294","0.00145","62.41367"
"14.00000","0.23104","150.89745","0.29944","-0.83536","0.00149","63.91525"
"14.50000","0.23960","155.00407","0.30759","-0.82720","0.00153","65.65469"
"15.00000","0.24788","158.79648","0.31552","-0.81928","0.00157","67.26102"
"15.50000","0.25610","162.56921","0.32343","-0.81137","0.00161","68.85903"
"16.00000","0.26457","166.38672","0.33156","-0.80323","0.00165","70.47600"
"16.50000","0.27265","170.22012","0.33932","-0.79548","0.00169","72.09971"
"17.00000","0.28143","174.29820","0.34776","-0.78704","0.00173","73.82705"
"17.50000","0.28932","177.95360","0.35534","-0.77946","0.00177","75.37536"
"18.00000","0.29805","182.04088","0.36371","-0.77108","0.00181","77.10659"
"18.50000","0.30609","185.77975","0.37144","-0.76336","0.00185","78.69026"
"19.00000","0.31483","189.85336","0.37983","-0.75497","0.00189","80.41571"
"19.50000","0.32276","193.61237","0.38744","-0.74736","0.00193","82.00790"
"20.00000","0.33112","197.51324","0.39547","-0.73932","0.00197","83.66019"
"20.50000","0.33957","201.62370","0.40358","-0.73122","0.00201","85.40125"
"21.00000","0.34768","205.47319","0.41138","-0.72342","0.00205","87.03176"
"21.50000","0.35616","209.53328","0.41954","-0.71526","0.00209","88.75148"
"22.00000","0.36433","213.30325","0.42740","-0.70739","0.00213","90.34832"
"22.50000","0.37314","217.52249","0.43587","-0.69893","0.00217","92.13545"
"23.00000","0.38100","221.42157","0.44342","-0.69138","0.00221","93.78697"
"23.50000","0.38968","225.58675","0.45177","-0.68303","0.00225","95.55121"
"24.00000","0.39781","229.37112","0.45960","-0.67520","0.00229","97.15414"
"24.50000","0.40644","233.56233","0.46789","-0.66690","0.00233","98.92941"
"25.00000","0.41443","237.35336","0.47558","-0.65922","0.00237","100.53516"
"25.50000","0.42282","241.56491","0.48363","-0.65116","0.00241","102.31904"
"26.00000","0.43128","245.57774","0.49177","-0.64303","0.00245","104.01875"
"26.50000","0.43930","249.32819","0.49951","-0.63528","0.00249","105.60731"
"27.00000","0.44790","253.56514","0.50778","-0.62702","0.00253","107.40195"
"27.50000","0.45597","257.37906","0.51556","-0.61923","0.00257","109.01740"
"28.00000","0.46478","261.78656","0.52403","-0.61076","0.00261","110.88427"
"28.50000","0.47265","265.51239","0.53161","-0.60318","0.00265","112.46241"
"29.00000","0.48139","269.85590","0.54002","-0.59478","0.00269","114.30218"
"29.50000","0.48945","273.70227","0.54779","-0.58701","0.00273","115.93138"
"30.00000","0.49801","277.84409","0.55603","-0.57877","0.00277","117.68571"
"30.50000","0.50615","281.77554","0.56387","-0.57093","0.00281","119.35095"
"31.00000","0.51441","285.83539","0.57181","-0.56298","0.00285","121.07057"
"31.50000","0.52294","289.94812","0.58003","-0.55477","0.00289","122.81259"
"32.00000","0.53099","293.79822","0.58782","-0.54698","0.00293","124.44337"
"32.50000","0.53966","297.95599","0.59621","-0.53859","0.00297","126.20447"
"33.00000","0.54769","301.89517","0.60398","-0.53082","0.00301","127.87297"
"33.50000","0.55655","306.27051","0.61254","-0.52226","0.00305","129.72623"
"34.00000","0.56437","310.03867","0.62011","-0.51469","0.00309","131.32230"
"34.50000","0.57293","314.27747","0.62839","-0.50641","0.00313","133.11771"
"35.00000","0.58117","318.26648","0.63636","-0.49844","0.00317","134.80733"
"35.50000","0.58959","322.52670","0.64450","-0.49030","0.00321","136.61182"
"36.00000","0.59777","326.38736","0.65242","-0.48238","0.00325","138.24707"
"36.50000","0.60602","330.56342","0.66039","-0.47441","0.00329","140.01591"
"37.00000","0.61467","334.58682","0.66877","-0.46602","0.00333","141.72009"
"37.50000","0.62264","338.53110","0.67647","-0.45832","0.00337","143.39076"
"38.00000","0.63128","342.76337","0.68484","-0.44996","0.00341","145.18341"
"38.50000","0.63938","346.72766","0.69268","-0.44211","0.00345","146.86256"
"39.00000","0.64821","351.02148","0.70123","-0.43356","0.00349","148.68127"
"39.50000","0.65604","354.83356","0.70882","-0.42598","0.00353","150.29594"
"40.00000","0.66463","359.08231","0.71714","-0.41766","0.00357","152.09558"
"40.50000","0.67284","362.90356","0.72510","-0.40969","0.00361","153.71414"
"41.00000","0.68116","367.03183","0.73316","-0.40164","0.00365","155.46274"
"41.50000","0.68948","371.00302","0.74123","-0.39357","0.00369","157.14481"
"42.00000","0.69770","374.89670","0.74919","-0.38561","0.00373","158.79405"
"42.50000","0.70636","379.24203","0.75757","-0.37722","0.00377","160.63458"
"43.00000","0.71428","383.02493","0.76526","-0.36954","0.00381","162.23691"
"43.50000","0.72302","387.25879","0.77372","-0.36107","0.00385","164.03023"
"44.00000","0.73101","390.87442","0.78150","-0.35330","0.00389","165.56169"
"44.50000","0.73982","395.35007","0.79005","-0.34474","0.00393","167.45743"
"45.00000","0.74773","398.97076","0.79775","-0.33705","0.00397","168.99104"
"45.50000","0.75624","403.06073","0.80603","-0.32877","0.00401","170.72342"
"46.00000","0.76451","406.98926","0.81407","-0.32072","0.00405","172.38741"
"46.50000","0.77281","410.93179","0.82215","-0.31265","0.00409","174.05734"
"47.00000","0.78122","414.85434","0.83033","-0.30446","0.00413","175.71880"
"47.50000","0.78937","418.71365","0.83827","-0.29653","0.00417","177.35349"
"48.00000","0.79807","422.78748","0.84674","-0.28806","0.00421","179.07903"
"48.50000","0.80596","426.46298","0.85442","-0.28038","0.00425","180.63585"
"49.00000","0.81461","430.64343","0.86283","-0.27197","0.00429","182.40656"
"49.50000","0.82275","434.44061","0.87075","-0.26405","0.00433","184.01491"
"50.00000","0.83147","438.57303","0.87924","-0.25556","0.00438","185.76527"
"50.50000","0.83940","442.18735","0.88696","-0.24783","0.00441","187.29617"
"51.00000","0.84784","446.11584","0.89518","-0.23962","0.00446","188.96016"
"51.50000","0.85624","450.13242","0.90335","-0.23145","0.00450","190.66145"
"52.00000","0.86441","453.78665","0.91131","-0.22349","0.00454","192.20926"
"52.50000","0.87285","457.92932","0.91951","-0.21529","0.00458","193.96396"
"53.00000","0.88103","461.57501","0.92749","-0.20731","0.00462","195.50816"
"53.50000","0.88979","465.83591","0.93600","-0.19880","0.00466","197.31294"
"54.00000","0.89763","469.20331","0.94365","-0.19114","0.00470","198.73926"
"54.50000","0.90633","473.42136","0.95211","-0.18269","0.00474","200.52588"
"55.00000","0.91441","477.18063","0.95997","-0.17482","0.00478","202.11819"
"55.50000","0.92309","481.21252","0.96842","-0.16638","0.00482","203.82597"
"56.00000","0.93107","484.79022","0.97621","-0.15859","0.00486","205.34137"
"56.50000","0.93952","488.89871","0.98442","-0.15038","0.00490","207.08159"
"57.00000","0.94790","492.49719","0.99262","-0.14218","0.00494","208.60579"
"57.50000","0.95601","496.34885","1.00052","-0.13427","0.00498","210.23723"
"58.00000","0.96458","500.23032","1.00890","-0.12590","0.00502","211.88129"
"58.50000","0.97265","503.90829","1.01679","-0.11801","0.00506","213.43916"
"59.00000","0.98144","507.93179","1.02538","-0.10942","0.00510","215.14339"
"59.50000","0.98932","511.53711","1.03308","-0.10172","0.00514","216.67047"
"60.00000","0.99804","515.63324","1.04159","-0.09321","0.00518","218.40547"
"60.50000","1.00611","519.20209","1.04948","-0.08532","0.00522","219.91711"
"61.00000","1.01477","523.11914","1.05794","-0.07685","0.00527","221.57625"
"61.50000","1.02283","526.79840","1.06582","-0.06898","0.00530","223.13466"
"62.00000","1.03113","530.55566","1.07393","-0.06086","0.00534","224.72612"
"62.50000","1.03960","534.36621","1.08221","-0.05258","0.00539","226.34015"
"63.00000","1.04763","538.02350","1.09006","-0.04474","0.00543","227.88925"
"63.50000","1.05620","541.82281","1.09844","-0.03635","0.00547","229.49852"
"64.00000","1.06436","545.58527","1.10642","-0.02838","0.00551","231.09216"
"64.50000","1.07313","549.46997","1.11500","-0.01980","0.00555","232.73761"
"65.00000","1.08101","552.92352","1.12271","-0.01209","0.00559","234.20042"
"65.50000","1.08965","556.88025","1.13116","-0.00364","0.00563","235.87636"
"66.00000","1.09783","560.47614","1.13917","0.00438","0.00567","237.39946"
"66.50000","1.10635","564.27362","1.14750","0.01271","0.00571","239.00795"
"67.00000","1.11445","567.85046","1.15543","0.02063","0.00575","240.52298"
"67.50000","1.12276","571.40057","1.16357","0.02877","0.00579","242.02669"
"68.00000","1.13130","575.27710","1.17193","0.03713","0.00583","243.66867"
"68.50000","1.13929","578.80890","1.17974","0.04494","0.00587","245.16463"
"69.00000","1.14794","582.67328","1.18820","0.05340","0.00591","246.80145"
"69.50000","1.15603","586.19727","1.19612","0.06132","0.00595","248.29410"
"70.00000","1.16485","590.17786","1.20475","0.06995","0.00600","249.98013"
"70.50000","1.17266","593.40472","1.21242","0.07762","0.00603","251.34694"
"71.00000","1.18137","597.36084","1.22095","0.08615","0.00608","253.02261"
"71.50000","1.18948","600.94238","1.22889","0.09410","0.00612","254.53964"
"72.00000","1.19792","604.58893","1.23717","0.10237","0.00616","256.08420"
"72.50000","1.20615","608.28180","1.24523","0.11044","0.00620","257.64838"
"73.00000","1.21437","611.64899","1.25330","0.11851","0.00624","259.07462"
"73.50000","1.22298","615.41571","1.26175","0.12695","0.00628","260.67007"
"74.00000","1.23094","618.69537","1.26956","0.13477","0.00632","262.05923"
"74.50000","1.23969","622.64215","1.27814","0.14334","0.00636","263.73096"
"75.00000","1.24767","625.98651","1.28596","0.15117","0.00640","265.14752"
"75.50000","1.25655","629.94012","1.29467","0.15987","0.00644","266.82214"
"76.00000","1.26443","633.17664","1.30240","0.16760","0.00648","268.19302"
"76.50000","1.27296","636.94299","1.31076","0.17596","0.00652","269.78833"
"77.00000","1.28120","640.37170","1.31884","0.18405","0.00656","271.24063"
"77.50000","1.28951","643.90479","1.32700","0.19220","0.00660","272.73712"
"78.00000","1.29780","647.39270","1.33514","0.20034","0.00664","274.21448"
"78.50000","1.30600","650.76691","1.34318","0.20838","0.00668","275.64368"
"79.00000","1.31469","654.60217","1.35170","0.21691","0.00673","277.26819"
"79.50000","1.32267","657.85675","1.35953","0.22474","0.00677","278.64673"
"80.00000","1.33140","661.58203","1.36810","0.23330","0.00681","280.22464"
"80.50000","1.33943","664.92737","1.37598","0.24118","0.00685","281.64160"
"81.00000","1.34818","668.58002","1.38457","0.24977","0.00689","283.18875"
"81.50000","1.35604","671.66620","1.39229","0.25749","0.00693","284.49594"
"82.00000","1.36453","675.26599","1.40062","0.26583","0.00697","286.02072"
"82.50000","1.37284","678.86133","1.40877","0.27398","0.00701","287.54358"
"83.00000","1.38107","682.12683","1.41686","0.28206","0.00705","288.92673"
"83.50000","1.38950","685.61200","1.42513","0.29033","0.00709","290.40292"
"84.00000","1.39769","689.06250","1.43317","0.29838","0.00713","291.86447"
"84.50000","1.40642","692.52643","1.44175","0.30695","0.00718","293.33167"
"85.00000","1.41426","695.79620","1.44944","0.31464","0.00721","294.71664"
"85.50000","1.42310","699.41815","1.45811","0.32331","0.00726","296.25076"
"86.00000","1.43106","702.57098","1.46593","0.33113","0.00730","297.58621"
"86.50000","1.43979","706.33942","1.47450","0.33970","0.00734","299.18240"
"87.00000","1.44773","709.31305","1.48231","0.34751","0.00738","300.44193"
"87.50000","1.45619","712.76056","1.49061","0.35581","0.00742","301.90219"
"88.00000","1.46455","716.14630","1.49882","0.36402","0.00746","303.33627"
"88.50000","1.47269","719.37030","1.50682","0.37202","0.00750","304.70184"
"89.00000","1.48126","722.83746","1.51523","0.38043","0.00754","306.17044"
"89.50000","1.48930","725.97504","1.52313","0.38834","0.00758","307.49942"
"90.00000","1.49815","729.60736","1.53182","0.39702","0.00762","309.03793"
"90.50000","1.50600","732.54059","1.53953","0.40473","0.00766","310.28036"
"91.00000","1.51472","736.11383","1.54809","0.41330","0.00770","311.79388"
"91.50000","1.52278","739.23846","1.55601","0.42122","0.00774","313.11737"
"92.00000","1.53139","742.82043","1.56447","0.42967","0.00779","314.63458"
"92.50000","1.53940","745.71686","1.57236","0.43756","0.00783","315.86139"
"93.00000","1.54773","748.96838","1.58056","0.44576","0.00787","317.23865"
"93.50000","1.55627","752.42889","1.58895","0.45415","0.00791","318.70441"
"94.00000","1.56439","755.47723","1.59694","0.46214","0.00795","319.99557"
"94.50000","1.57294","758.84155","1.60535","0.47056","0.00799","321.42059"
"95.00000","1.58102","761.82404","1.61330","0.47850","0.00803","322.68387"
"95.50000","1.58980","765.32959","1.62194","0.48714","0.00807","324.16873"
"96.00000","1.59762","768.20636","1.62964","0.49485","0.00811","325.38724"
"96.50000","1.60631","771.62476","1.63819","0.50339","0.00815","326.83514"
"97.00000","1.61442","774.57184","1.64617","0.51137","0.00819","328.08344"
"97.50000","1.62301","777.97070","1.65462","0.51982","0.00823","329.52307"
"98.00000","1.63112","780.83801","1.66261","0.52781","0.00827","330.73758"
"98.50000","1.63948","783.94458","1.67084","0.53605","0.00832","332.05341"
"99.00000","1.64801","787.06647","1.67924","0.54444","0.00836","333.37576"
"99.50000","1.65595","789.96375","1.68706","0.55226","0.00840","334.60294"
"100.00000","1.66465","793.05542","1.69564","0.56084","0.00844","335.91248"
"100.50000","1.67264","795.95984","1.70349","0.56870","0.00848","337.14270"
"101.00000","1.68147","799.25952","1.71218","0.57739","0.00852","338.54034"
"101.50000","1.68933","801.87738","1.71993","0.58513","0.00856","339.64917"
"102.00000","1.69802","804.99359","1.72848","0.59368","0.00860","340.96909"
"102.50000","1.70611","807.38458","1.73647","0.60167","0.00864","341.98184"
"103.00000","1.71459","809.84229","1.74484","0.61004","0.00868","343.02286"
"103.50000","1.72283","811.46106","1.75301","0.61822","0.00872","343.70850"
"104.00000","1.73104","812.41345","1.76118","0.62639","0.00877","344.11191"
"104.50000","1.73965","812.50745","1.76978","0.63499","0.00881","344.15173"
"105.00000","1.74762","813.69458","1.77771","0.64291","0.00885","344.65454"
"105.50000","1.75631","812.73431","1.78644","0.65165","0.00889","344.24780"
"106.00000","1.76437","809.43799","1.79464","0.65984","0.00893","342.85159"
"106.50000","1.77319","795.54797","1.80406","0.66927","0.00898","336.96823"
"107.00000","1.78105","789.20117","1.81219","0.67739","0.00902","334.27994"
"107.50000","1.78957","787.48438","1.82078","0.68599","0.00906","333.55276"
"108.00000","1.79786","787.39569","1.82908","0.69429","0.00910","333.51520"
"108.50000","1.80625","784.73029","1.83758","0.70279","0.00915","332.38623"
"109.00000","1.81451","782.13550","1.84595","0.71115","0.00919","331.28714"
"109.50000","1.82270","782.42773","1.85413","0.71933","0.00923","331.41095"
"110.00000","1.83133","783.26996","1.86272","0.72793","0.00927","331.76767"
"110.50000","1.83924","783.42798","1.87062","0.73582","0.00931","331.83459"
"111.00000","1.84798","784.48523","1.87931","0.74452","0.00935","332.28241"
"111.50000","1.85600","785.75751","1.88729","0.75249","0.00939","332.82132"
"112.00000","1.86485","787.63776","1.89606","0.76126","0.00944","333.61774"
"112.50000","1.87273","789.06689","1.90387","0.76908","0.00948","334.22305"
"113.00000","1.88131","791.13739","1.91237","0.77758","0.00952","335.10007"
"113.50000","1.88956","793.09351","1.92054","0.78575","0.00956","335.92862"
"114.00000","1.89779","795.12762","1.92868","0.79388","0.00960","336.79019"
"114.50000","1.90619","797.30695","1.93699","0.80219","0.00964","337.71329"
"115.00000","1.91432","799.20135","1.94503","0.81024","0.00968","338.51569"
"115.50000","1.92304","801.68854","1.95365","0.81885","0.00972","339.56918"
"116.00000","1.93093","803.54315","1.96146","0.82666","0.00976","340.35474"
"116.50000","1.93973","806.00043","1.97015","0.83536","0.00981","341.39557"
"117.00000","1.94769","807.74463","1.97804","0.84324","0.00984","342.13434"
"117.50000","1.95651","809.58325","1.98677","0.85198","0.00989","342.91312"
"118.00000","1.96444","811.16309","1.99464","0.85984","0.00993","343.58231"
"118.50000","1.97284","813.08771","2.00295","0.86816","0.00997","344.39749"
"119.00000","1.98119","814.69611","2.01124","0.87644","0.01001","345.07877"
"119.50000","1.98938","816.52252","2.01935","0.88455","0.01005","345.85239"
"120.00000","1.99788","818.42828","2.02776","0.89296","0.01009","346.65961"
"120.50000","2.00602","820.04004","2.03583","0.90103","0.01013","347.34229"
"121.00000","2.01477","822.07385","2.04450","0.90970","0.01018","348.20374"
"121.50000","2.02267","823.48547","2.05233","0.91753","0.01021","348.80167"
"122.00000","2.03136","825.53320","2.06094","0.92614","0.01026","349.66901"
"122.50000","2.03945","827.12238","2.06896","0.93416","0.01030","350.34213"
"123.00000","2.04816","828.50067","2.07760","0.94281","0.01034","350.92593"
"123.50000","2.05608","827.33490","2.08557","0.95078","0.01038","350.43216"
"124.00000","2.06445","827.76379","2.09393","0.95913","0.01042","350.61380"
"124.50000","2.07288","828.93018","2.10231","0.96751","0.01046","351.10785"
"125.00000","2.08099","830.19275","2.11036","0.97557","0.01050","351.64264"
"125.50000","2.08957","831.87799","2.11887","0.98407","0.01055","352.35645"
"126.00000","2.09765","833.22815","2.12688","0.99209","0.01059","352.92834"
"126.50000","2.10647","835.00806","2.13563","1.00083","0.01063","353.68225"
"127.00000","2.11433","836.27655","2.14344","1.00864","0.01067","354.21954"
"127.50000","2.12313","838.14215","2.15215","1.01736","0.01071","355.00974"
"128.00000","2.13112","839.52435","2.16008","1.02529","0.01075","355.59521"
"128.50000","2.13971","841.34259","2.16860","1.03380","0.01079","356.36536"
"129.00000","2.14777","842.82281","2.17659","1.04180","0.01083","356.99234"
"129.50000","2.15611","844.38867","2.18487","1.05007","0.01087","357.65558"
"130.00000","2.16460","846.14362","2.19329","1.05849","0.01092","358.39890"
"130.50000","2.17263","847.41571","2.20126","1.06646","0.01096","358.93771"
"131.00000","2.18133","849.14874","2.20988","1.07509","0.01100","359.67178"
"131.50000","2.18929","850.36243","2.21780","1.08300","0.01104","360.18585"
"132.00000","2.19816","852.16675","2.22659","1.09180","0.01108","360.95010"
"132.50000","2.20601","853.34143","2.23440","1.09960","0.01112","361.44766"
"133.00000","2.21466","854.93408","2.24298","1.10818","0.01116","362.12225"
"133.50000","2.22277","856.14557","2.25104","1.11624","0.01120","362.63541"
"134.00000","2.23128","857.54852","2.25949","1.12469","0.01125","363.22964"
"134.50000","2.23947","858.78223","2.26762","1.13282","0.01129","363.75223"
"135.00000","2.24773","859.92908","2.27584","1.14104","0.01133","364.23798"
"135.50000","2.25634","861.46991","2.28438","1.14958","0.01137","364.89062"
"136.00000","2.26435","862.41162","2.29235","1.15755","0.01141","365.28952"
"136.50000","2.27298","863.83276","2.30093","1.16613","0.01145","365.89145"
"137.00000","2.28107","864.75110","2.30897","1.17418","0.01149","366.28043"
"137.50000","2.28983","866.15887","2.31768","1.18288","0.01153","366.87671"
"138.00000","2.29768","866.97888","2.32549","1.19070","0.01157","367.22406"
"138.50000","2.30627","868.29803","2.33402","1.19922","0.01162","367.78281"
"139.00000","2.31449","869.34448","2.34220","1.20740","0.01166","368.22604"
"139.50000","2.32291","870.33966","2.35058","1.21578","0.01170","368.64755"
"140.00000","2.33115","871.15674","2.35878","1.22399","0.01174","368.99365"
"140.50000","2.33936","871.92871","2.36697","1.23217","0.01178","369.32065"
"141.00000","2.34803","873.04962","2.37559","1.24079","0.01182","369.79541"
"141.50000","2.35599","873.66931","2.38352","1.24873","0.01186","370.05789"
"142.00000","2.36470","874.76624","2.39218","1.25739","0.01191","370.52252"
"142.50000","2.37269","875.28595","2.40015","1.26536","0.01195","370.74265"
"143.00000","2.38146","876.50446","2.40887","1.27408","0.01199","371.25876"
"143.50000","2.38938","877.06091","2.41677","1.28197","0.01203","371.49448"
"144.00000","2.39797","877.94604","2.42532","1.29052","0.01207","371.86938"
"144.50000","2.40618","878.73230","2.43350","1.29870","0.01211","372.20242"
"145.00000","2.41446","879.65717","2.44174","1.30695","0.01215","372.59415"
"145.50000","2.42286","880.34271","2.45011","1.31532","0.01219","372.88452"
"146.00000","2.43100","881.09357","2.45822","1.32342","0.01223","373.20258"
"146.50000","2.43968","882.18359","2.46686","1.33206","0.01228","373.66428"
"147.00000","2.44762","882.84790","2.47477","1.33997","0.01232","373.94565"
"147.50000","2.45635","883.73004","2.48346","1.34867","0.01236","374.31931"
"148.00000","2.46435","884.32281","2.49144","1.35664","0.01240","374.57037"
"148.50000","2.47314","885.31805","2.50019","1.36539","0.01244","374.99191"
"149.00000","2.48108","885.84937","2.50810","1.37330","0.01248","375.21698"
"149.50000","2.48953","886.55835","2.51652","1.38172","0.01252","375.51727"
"150.00000","2.49790","887.47900","2.52486","1.39006","0.01257","375.90723"
"150.50000","2.50614","888.17102","2.53307","1.39827","0.01261","376.20035"
"151.00000","2.51454","888.94061","2.54144","1.40664","0.01265","376.52634"
"151.50000","2.52273","889.63184","2.54960","1.41480","0.01269","376.81909"
"152.00000","2.53140","890.50586","2.55823","1.42343","0.01273","377.18930"
"152.50000","2.53929","890.91595","2.56610","1.43131","0.01277","377.36301"
"153.00000","2.54794","891.64246","2.57472","1.43992","0.01281","377.67075"
"153.50000","2.55607","891.95782","2.58284","1.44804","0.01285","377.80432"
"154.00000","2.56481","892.78149","2.59154","1.45675","0.01290","378.15320"
"154.50000","2.57274","892.87933","2.59947","1.46467","0.01294","378.19464"
"155.00000","2.58120","893.30023","2.60791","1.47311","0.01298","378.37292"
"155.50000","2.58959","893.73401","2.61628","1.48149","0.01302","378.55664"
"156.00000","2.59774","894.06799","2.62442","1.48962","0.01306","378.69812"
"156.50000","2.60621","894.61279","2.63286","1.49806","0.01310","378.92886"
"157.00000","2.61436","895.02661","2.64100","1.50620","0.01314","379.10416"
"157.50000","2.62309","895.78888","2.64970","1.51490","0.01319","379.42703"
"158.00000","2.63100","896.04083","2.65759","1.52280","0.01323","379.53375"
"158.50000","2.63975","896.85162","2.66632","1.53152","0.01327","379.87717"
"159.00000","2.64776","897.20703","2.67431","1.53951","0.01331","380.02771"
"159.50000","2.65641","897.91333","2.68293","1.54813","0.01335","380.32687"
"160.00000","2.66444","898.26947","2.69094","1.55615","0.01339","380.47772"
"160.50000","2.67279","898.86438","2.69927","1.56447","0.01343","380.72971"
"161.00000","2.68122","899.41931","2.70767","1.57287","0.01348","380.96475"
"161.50000","2.68931","899.96613","2.71574","1.58094","0.01352","381.19638"
"162.00000","2.69791","900.80408","2.72431","1.58951","0.01356","381.55130"
"162.50000","2.70597","901.23920","2.73235","1.59755","0.01360","381.73560"
"163.00000","2.71480","902.12189","2.74114","1.60634","0.01364","382.10950"
"163.50000","2.72269","902.54358","2.74901","1.61421","0.01368","382.28809"
"164.00000","2.73131","903.22925","2.75760","1.62281","0.01372","382.57852"
"164.50000","2.73948","903.73822","2.76576","1.63096","0.01376","382.79410"
"165.00000","2.74804","904.64783","2.77428","1.63948","0.01381","383.17938"
"165.50000","2.75613","905.17767","2.78235","1.64755","0.01385","383.40381"
"166.00000","2.76447","905.73254","2.79066","1.65587","0.01389","383.63885"
"166.50000","2.77295","906.31024","2.79912","1.66432","0.01393","383.88354"
"167.00000","2.78098","906.73694","2.80712","1.67233","0.01397","384.06427"
"167.50000","2.78957","907.38348","2.81569","1.68090","0.01401","384.33813"
"168.00000","2.79770","907.82959","2.82381","1.68901","0.01405","384.52707"
"168.50000","2.80652","908.58228","2.83259","1.69779","0.01410","384.84589"
"169.00000","2.81434","908.61359","2.84041","1.70561","0.01414","384.85916"
"169.50000","2.82303","909.22852","2.84908","1.71428","0.01418","385.11963"
"170.00000","2.83115","909.42896","2.85719","1.72239","0.01422","385.20453"
"170.50000","2.83961","909.91833","2.86563","1.73083","0.01426","385.41180"
"171.00000","2.84776","910.16608","2.87376","1.73897","0.01430","385.51675"
"171.50000","2.85608","910.40192","2.88207","1.74728","0.01434","385.61664"
"172.00000","2.86464","910.53888","2.89062","1.75583","0.01439","385.67465"
"172.50000","2.87263","910.14404","2.89863","1.76383","0.01443","385.50742"
"173.00000","2.88136","910.07745","2.90737","1.77257","0.01447","385.47922"
"173.50000","2.88935","909.29865","2.91539","1.78060","0.01451","385.14932"
"174.00000","2.89824","908.73224","2.92431","1.78951","0.01455","384.90942"
"174.50000","2.90604","907.41943","2.93216","1.79737","0.01459","384.35336"
"175.00000","2.91465","905.77954","2.94084","1.80604","0.01464","383.65875"
"175.50000","2.92280","901.51813","2.94917","1.81437","0.01468","381.85376"
"176.00000","2.93119","896.22131","2.95778","1.82298","0.01472","379.61020"
"176.50000","2.93950","891.78290","2.96627","1.83148","0.01476","377.73022"
"177.00000","2.94768","888.45270","2.97460","1.83980","0.01480","376.31967"
"177.50000","2.95634","885.79395","2.98336","1.84857","0.01485","375.19351"
"178.00000","2.96431","883.58026","2.99142","1.85663","0.01489","374.25586"
"178.50000","2.97299","882.16541","3.00017","1.86537","0.01493","373.65656"
"179.00000","2.98104","879.98669","3.00831","1.87351","0.01497","372.73373"
"179.50000","2.98984","878.96912","3.01715","1.88236","0.01502","372.30273"
"180.00000","2.99771","877.61200","3.02507","1.89028","0.01506","371.72791"
"180.50000","3.00627","876.83954","3.03366","1.89887","0.01510","371.40070"
"181.00000","3.01455","875.84735","3.04199","1.90719","0.01514","370.98044"
"181.50000","3.02280","875.13623","3.05027","1.91547","0.01518","370.67923"
"182.00000","3.03117","874.29388","3.05868","1.92388","0.01522","370.32245"
"182.50000","3.03939","873.43182","3.06693","1.93214","0.01526","369.95731"
"183.00000","3.04806","872.60297","3.07563","1.94084","0.01531","369.60623"
"183.50000","3.05598","871.61383","3.08360","1.94881","0.01535","369.18726"
"184.00000","3.06474","871.15027","3.09238","1.95758","0.01539","368.99091"
"184.50000","3.07274","870.42926","3.10041","1.96561","0.01543","368.68552"
"185.00000","3.08150","870.10870","3.10918","1.97438","0.01547","368.54974"
"185.50000","3.08935","869.08972","3.11707","1.98228","0.01551","368.11813"
"186.00000","3.09790","868.68469","3.12564","1.99085","0.01556","367.94656"
"186.50000","3.10621","868.13940","3.13397","1.99918","0.01560","367.71561"
"187.00000","3.11440","867.62598","3.14219","2.00739","0.01564","367.49814"
"187.50000","3.12292","867.23871","3.15072","2.01592","0.01568","367.33411"
"188.00000","3.13099","866.53094","3.15882","2.02403","0.01572","367.03433"
"188.50000","3.13981","866.14148","3.16766","2.03286","0.01576","366.86935"
"189.00000","3.14764","865.25122","3.17552","2.04072","0.01580","366.49228"
"189.50000","3.15641","864.93890","3.18431","2.04951","0.01585","366.35999"
"190.00000","3.16437","864.03357","3.19231","2.05751","0.01589","365.97650"
"190.50000","3.17314","863.77972","3.20109","2.06629","0.01593","365.86899"
"191.00000","3.18109","862.93140","3.20907","2.07427","0.01597","365.50967"
"191.50000","3.18945","862.32330","3.21746","2.08266","0.01601","365.25211"
"192.00000","3.19789","861.92328","3.22592","2.09112","0.01605","365.08267"
"192.50000","3.20603","861.29669","3.23408","2.09928","0.01610","364.81726"
"193.00000","3.21456","860.90704","3.24263","2.10783","0.01614","364.65222"
"193.50000","3.22266","860.27606","3.25075","2.11595","0.01618","364.38495"
"194.00000","3.23146","860.19867","3.25956","2.12476","0.01622","364.35217"
"194.50000","3.23932","859.54175","3.26744","2.13265","0.01626","364.07391"
"195.00000","3.24800","859.00433","3.27615","2.14135","0.01630","363.84628"
"195.50000","3.25614","858.46234","3.28431","2.14951","0.01635","363.61673"
"196.00000","3.26477","858.11707","3.29295","2.15815","0.01639","363.47046"
"196.50000","3.27279","857.46356","3.30100","2.16620","0.01643","363.19366"
"197.00000","3.28116","857.00128","3.30939","2.17459","0.01647","362.99786"
"197.50000","3.28962","856.37402","3.31787","2.18308","0.01651","362.73218"
"198.00000","3.29768","855.84790","3.32595","2.19116","0.01655","362.50934"
"198.50000","3.30628","855.51703","3.33457","2.19977","0.01660","362.36917"
"199.00000","3.31435","854.62524","3.34268","2.20788","0.01664","361.99146"
"199.50000","3.32316","854.41852","3.35150","2.21670","0.01668","361.90390"
"200.00000","3.33096","853.61804","3.35933","2.22453","0.01672","361.56482"
"200.50000","3.33968","853.23749","3.36806","2.23327","0.01676","361.40366"
"201.00000","3.34778","852.43665","3.37620","2.24140","0.01680","361.06442"
"201.50000","3.35627","851.97333","3.38471","2.24992","0.01685","360.86819"
"202.00000","3.36446","851.19122","3.39294","2.25814","0.01689","360.53693"
"202.50000","3.37277","850.44916","3.40128","2.26648","0.01693","360.22260"
"203.00000","3.38135","849.90002","3.40987","2.27508","0.01697","359.98999"
"203.50000","3.38931","848.59167","3.41789","2.28309","0.01701","359.43582"
"204.00000","3.39801","847.49622","3.42664","2.29184","0.01705","358.97183"
"204.50000","3.40595","846.04126","3.43464","2.29984","0.01709","358.35556"
"205.00000","3.41490","845.39539","3.44362","2.30882","0.01714","358.08197"
"205.50000","3.42269","843.76672","3.45148","2.31668","0.01718","357.39212"
"206.00000","3.43130","842.87433","3.46012","2.32532","0.01722","357.01416"
"206.50000","3.43948","841.64032","3.46836","2.33356","0.01726","356.49146"
"207.00000","3.44790","840.52020","3.47682","2.34203","0.01730","356.01703"
"207.50000","3.45615","839.24298","3.48513","2.35033","0.01734","355.47601"
"208.00000","3.46434","838.08191","3.49337","2.35858","0.01739","354.98422"
"208.50000","3.47300","837.10962","3.50207","2.36727","0.01743","354.57239"
"209.00000","3.48096","835.62189","3.51009","2.37530","0.01747","353.94226"
"209.50000","3.48959","834.56458","3.51877","2.38397","0.01751","353.49442"
"210.00000","3.49770","833.22125","3.52694","2.39215","0.01755","352.92542"
"210.50000","3.50657","832.32288","3.53585","2.40105","0.01760","352.54489"
"211.00000","3.51440","830.83252","3.54374","2.40894","0.01764","351.91364"
"211.50000","3.52296","829.70795","3.55235","2.41755","0.01768","351.43729"
"212.00000","3.53121","828.41895","3.56066","2.42587","0.01772","350.89133"
"212.50000","3.53951","827.19177","3.56901","2.43421","0.01776","350.37152"
"213.00000","3.54784","825.93915","3.57740","2.44260","0.01780","349.84094"
"213.50000","3.55604","824.41260","3.58566","2.45087","0.01785","349.19437"
"214.00000","3.56472","823.50708","3.59438","2.45958","0.01789","348.81082"
"214.50000","3.57259","821.77539","3.60232","2.46752","0.01793","348.07733"
"215.00000","3.58133","820.18555","3.61114","2.47634","0.01797","347.40393"
"215.50000","3.58936","818.47180","3.61924","2.48444","0.01801","346.67804"
"216.00000","3.59812","817.39771","3.62805","2.49325","0.01806","346.22308"
"216.50000","3.60605","815.83246","3.63604","2.50125","0.01810","345.56009"
"217.00000","3.61461","814.58807","3.64466","2.50987","0.01814","345.03302"
"217.50000","3.62289","813.34979","3.65299","2.51819","0.01818","344.50851"
"218.00000","3.63110","812.10779","3.66126","2.52646","0.01822","343.98245"
"218.50000","3.63957","810.77899","3.66978","2.53499","0.01826","343.41962"
"219.00000","3.64764","809.35089","3.67791","2.54312","0.01830","342.81470"
"219.50000","3.65644","808.17004","3.68676","2.55197","0.01835","342.31454"
"220.00000","3.66431","806.08508","3.69472","2.55993","0.01839","341.43143"
"220.50000","3.67305","804.44629","3.70354","2.56874","0.01843","340.73727"
"221.00000","3.68108","802.09076","3.71167","2.57688","0.01847","339.73956"
"221.50000","3.68982","800.23145","3.72049","2.58569","0.01852","338.95200"
"222.00000","3.69776","797.81006","3.72854","2.59374","0.01856","337.92639"
"222.50000","3.70614","796.05450","3.73699","2.60220","0.01860","337.18280"
"223.00000","3.71456","794.38409","3.74548","2.61068","0.01864","336.47525"
"223.50000","3.72269","792.63605","3.75369","2.61889","0.01868","335.73483"
"224.00000","3.73117","791.19366","3.76223","2.62744","0.01872","335.12390"
"224.50000","3.73932","789.64795","3.77045","2.63565","0.01876","334.46918"
"225.00000","3.74815","788.70190","3.77931","2.64452","0.01881","334.06848"
"225.50000","3.75598","787.08093","3.78721","2.65242","0.01885","333.38187"
"226.00000","3.76469","786.00793","3.79597","2.66117","0.01889","332.92740"
"226.50000","3.77281","784.41614","3.80415","2.66935","0.01893","332.25314"
"227.00000","3.78147","783.35468","3.81285","2.67806","0.01898","331.80356"
"227.50000","3.78945","782.02942","3.82089","2.68609","0.01902","331.24222"
"228.00000","3.79780","780.92853","3.82929","2.69449","0.01906","330.77591"
"228.50000","3.80627","780.03650","3.83780","2.70300","0.01910","330.39807"
"229.00000","3.81430","779.24548","3.84586","2.71106","0.01914","330.06305"
"229.50000","3.82291","778.63306","3.85449","2.71969","0.01918","329.80362"
"230.00000","3.83098","777.83997","3.86259","2.72780","0.01922","329.46771"
"230.50000","3.83980","777.88208","3.87141","2.73661","0.01927","329.48553"
"231.00000","3.84764","777.15790","3.87928","2.74449","0.01931","329.17880"
"231.50000","3.85640","777.27313","3.88804","2.75325","0.01935","329.22760"
"232.00000","3.86445","776.67853","3.89611","2.76131","0.01939","328.97577"
"232.50000","3.87300","776.61224","3.90467","2.76988","0.01943","328.94769"
"233.00000","3.88115","776.26776","3.91284","2.77804","0.01947","328.80176"
"233.50000","3.88939","775.83252","3.92109","2.78630","0.01951","328.61740"
"234.00000","3.89794","775.43939","3.92965","2.79486","0.01956","328.45090"
"234.50000","3.90598","775.00549","3.93772","2.80292","0.01960","328.26712"
"235.00000","3.91467","774.64343","3.94642","2.81163","0.01964","328.11377"
"235.50000","3.92270","773.87299","3.95448","2.81968","0.01968","327.78741"
"236.00000","3.93154","773.67987","3.96333","2.82854","0.01972","327.70563"
"236.50000","3.93935","772.59180","3.97119","2.83639","0.01976","327.24475"
"237.00000","3.94794","772.01013","3.97980","2.84500","0.01981","326.99838"
"237.50000","3.95617","771.22827","3.98806","2.85326","0.01985","326.66721"
"238.00000","3.96459","770.65759","3.99651","2.86171","0.01989","326.42548"
"238.50000","3.97278","769.66101","4.00473","2.86994","0.01993","326.00336"
"239.00000","3.98102","768.83344","4.01301","2.87822","0.01997","325.65283"
"239.50000","3.98968","768.03363","4.02170","2.88691","0.02002","325.31406"
"240.00000","3.99764","766.64777","4.02972","2.89492","0.02006","324.72705"
"240.50000","4.00628","765.57507","4.03841","2.90361","0.02010","324.27271"
"241.00000","4.01439","764.45410","4.04656","2.91177","0.02014","323.79788"
"241.50000","4.02321","763.67480","4.05542","2.92062","0.02018","323.46780"
"242.00000","4.03103","762.13928","4.06330","2.92850","0.02022","322.81741"
"242.50000","4.03962","761.11896","4.07193","2.93714","0.02027","322.38522"
"243.00000","4.04782","759.87170","4.08019","2.94539","0.02031","321.85693"
"243.50000","4.05618","758.51984","4.08861","2.95381","0.02035","321.28433"
"244.00000","4.06448","757.22498","4.09696","2.96216","0.02039","320.73587"
"244.50000","4.07268","755.31897","4.10524","2.97044","0.02043","319.92856"
"245.00000","4.08134","753.88080","4.11396","2.97916","0.02047","319.31937"
"245.50000","4.08928","752.12299","4.12196","2.98717","0.02051","318.57483"
"246.00000","4.09803","750.95557","4.13076","2.99597","0.02056","318.08035"
"246.50000","4.10602","749.37561","4.13882","3.00402","0.02060","317.41113"
"247.00000","4.11481","748.19244","4.14766","3.01286","0.02064","316.90997"
"247.50000","4.12273","746.56226","4.15565","3.02086","0.02068","316.21948"
"248.00000","4.13124","743.95032","4.16427","3.02947","0.02072","315.11316"
"248.50000","4.13952","740.67352","4.17269","3.03789","0.02077","313.72522"
"249.00000","4.14783","738.74902","4.18109","3.04629","0.02081","312.91006"
"249.50000","4.15622","737.20331","4.18955","3.05475","0.02085","312.25534"
"250.00000","4.16434","735.51154","4.19774","3.06294","0.02089","311.53876"
"250.50000","4.17307","734.56036","4.20651","3.07171","0.02094","311.13586"
"251.00000","4.18096","733.42487","4.21446","3.07966","0.02097","310.65491"
"251.50000","4.18963","732.73499","4.22315","3.08836","0.02102","310.36270"
"252.00000","4.19775","731.97278","4.23131","3.09652","0.02106","310.03986"
"252.50000","4.20647","731.67236","4.24004","3.10525","0.02110","309.91260"
"253.00000","4.21440","730.98358","4.24800","3.11320","0.02114","309.62088"
"253.50000","4.22283","730.89111","4.25644","3.12164","0.02118","309.58170"
"254.00000","4.23124","730.87115","4.26485","3.13005","0.02123","309.57324"
"254.50000","4.23944","730.70300","4.27306","3.13826","0.02127","309.50201"
"255.00000","4.24785","730.85156","4.28146","3.14666","0.02131","309.56494"
"255.50000","4.25602","730.82953","4.28963","3.15483","0.02135","309.55560"
"256.00000","4.26479","731.03021","4.29839","3.16359","0.02139","309.64062"
"256.50000","4.27262","730.92755","4.30623","3.17143","0.02143","309.59714"
"257.00000","4.28134","731.34985","4.31493","3.18013","0.02147","309.77600"
"257.50000","4.28940","731.43988","4.32299","3.18819","0.02151","309.81415"
"258.00000","4.29807","731.86371","4.33164","3.19684","0.02156","309.99365"
"258.50000","4.30606","731.81921","4.33962","3.20483","0.02160","309.97482"
"259.00000","4.31452","732.25439","4.34807","3.21327","0.02164","310.15915"
"259.50000","4.32290","732.47205","4.35644","3.22165","0.02168","310.25134"
"260.00000","4.33103","732.53839","4.36457","3.22977","0.02172","310.27942"
"260.50000","4.33956","732.50507","4.37310","3.23830","0.02176","310.26532"
"261.00000","4.34764","732.22461","4.38119","3.24640","0.02180","310.14651"
"261.50000","4.35645","731.96472","4.39001","3.25521","0.02185","310.03644"
"262.00000","4.36432","731.36481","4.39790","3.26311","0.02189","309.78235"
"262.50000","4.37304","731.32001","4.40663","3.27183","0.02193","309.76337"
"263.00000","4.38109","730.87366","4.41470","3.27990","0.02197","309.57431"
"263.50000","4.38977","731.01379","4.42338","3.28858","0.02201","309.63367"
"264.00000","4.39783","730.64783","4.43145","3.29665","0.02205","309.47864"
"264.50000","4.40613","730.61908","4.43975","3.30495","0.02210","309.46646"
"265.00000","4.41460","730.46509","4.44823","3.31344","0.02214","309.40125"
"265.50000","4.42265","730.18341","4.45629","3.32150","0.02218","309.28195"
"266.00000","4.43119","730.16071","4.46484","3.33004","0.02222","309.27231"
"266.50000","4.43935","728.24194","4.47308","3.33828","0.02226","308.45959"
"267.00000","4.44814","727.88245","4.48188","3.34708","0.02231","308.30731"
"267.20300","4.45111","727.32892","4.48488","3.35008","0.02232","308.07288"