File: flexion/5_axis/New folder/Specimen_RawData_16.csv
Specimen properties : Specimen label,"F1"
Specimen properties : Support span,"72.00",mm
Specimen properties : Thickness,"5.49",mm
Specimen properties : Width,"14.23",mm
Maximum Load : Maximum Load,"1089",N
Tangent Modulus of Elasticity : Tangent Modulus of Elasticity,"21362384154.25600",Pa
Test : Rate 1,"1.00000",mm/min
Specimen notes : Specimen note 1,""

Time,Displacement,Load,Flexure extension,Corrected extension,Flexure strain (Corrected extension),Flexure stress
(s),(mm),(N),(mm),(mm),(mm/mm),(MPa)
"0.00000","0.00000","45.31023","0.03248","-1.05507","0.00021","11.40960"
"0.40000","0.00480","47.45911","0.03699","-1.05055","0.00024","11.95071"
"0.80000","0.01139","50.49797","0.04317","-1.04438","0.00027","12.71593"
"1.20000","0.01820","53.47539","0.04958","-1.03796","0.00032","13.46568"
"1.60000","0.02518","56.59899","0.05614","-1.03140","0.00036","14.25223"
"2.00000","0.03172","59.45908","0.06233","-1.02521","0.00040","14.97243"
"2.40000","0.03836","62.46545","0.06862","-1.01893","0.00044","15.72947"
"2.80000","0.04481","65.17509","0.07475","-1.01280","0.00047","16.41178"
"3.20000","0.05143","68.19120","0.08101","-1.00653","0.00051","17.17127"
"3.60000","0.05816","71.28698","0.08738","-1.00016","0.00056","17.95082"
"4.00000","0.06512","74.28569","0.09400","-0.99355","0.00060","18.70593"
"4.40000","0.07191","77.38533","0.10042","-0.98713","0.00064","19.48645"
"4.80000","0.07825","80.12098","0.10644","-0.98110","0.00068","20.17532"
"5.20000","0.08487","83.15343","0.11271","-0.97484","0.00072","20.93892"
"5.60000","0.09142","86.04896","0.11892","-0.96863","0.00076","21.66805"
"6.00000","0.09810","89.12188","0.12527","-0.96228","0.00080","22.44184"
"6.40000","0.10507","92.31310","0.13193","-0.95561","0.00084","23.24543"
"6.80000","0.11181","95.39519","0.13837","-0.94918","0.00088","24.02153"
"7.20000","0.11849","98.30618","0.14477","-0.94278","0.00092","24.75455"
"7.60000","0.12484","101.28808","0.15083","-0.93672","0.00096","25.50542"
"8.00000","0.13141","104.25735","0.15710","-0.93044","0.00100","26.25311"
"8.40000","0.13804","107.35101","0.16343","-0.92412","0.00104","27.03213"
"8.80000","0.14491","110.50693","0.16999","-0.91755","0.00108","27.82683"
"9.20000","0.15196","113.73513","0.17672","-0.91082","0.00112","28.63972"
"9.60000","0.15832","116.70296","0.18280","-0.90475","0.00116","29.38705"
"10.00000","0.16493","119.82970","0.18910","-0.89844","0.00120","30.17440"
"10.40000","0.17148","122.80501","0.19536","-0.89219","0.00124","30.92361"
"10.80000","0.17810","125.72437","0.20169","-0.88585","0.00128","31.65874"
"11.20000","0.18490","128.94899","0.20818","-0.87937","0.00132","32.47073"
"11.60000","0.19171","132.13213","0.21469","-0.87286","0.00136","33.27228"
"12.00000","0.19851","135.28471","0.22117","-0.86637","0.00141","34.06614"
"12.40000","0.20487","138.17308","0.22726","-0.86029","0.00144","34.79346"
"12.80000","0.21155","141.04774","0.23365","-0.85389","0.00148","35.51733"
"13.20000","0.21804","143.99609","0.23985","-0.84769","0.00152","36.25976"
"13.60000","0.22489","147.07759","0.24641","-0.84114","0.00157","37.03571"
"14.00000","0.23191","150.54221","0.25309","-0.83445","0.00161","37.90814"
"14.40000","0.23844","153.30444","0.25935","-0.82820","0.00165","38.60370"
"14.80000","0.24503","156.20374","0.26566","-0.82188","0.00169","39.33377"
"15.20000","0.25150","159.01491","0.27188","-0.81567","0.00173","40.04166"
"15.60000","0.25811","162.05272","0.27822","-0.80932","0.00177","40.80661"
"16.00000","0.26476","165.19907","0.28461","-0.80294","0.00181","41.59889"
"16.40000","0.27166","168.36908","0.29124","-0.79631","0.00185","42.39714"
"16.80000","0.27859","171.61401","0.29789","-0.78965","0.00189","43.21424"
"17.20000","0.28495","174.53107","0.30400","-0.78354","0.00193","43.94879"
"17.60000","0.29160","177.66138","0.31038","-0.77716","0.00197","44.73703"
"18.00000","0.29809","180.70297","0.31662","-0.77092","0.00201","45.50294"
"18.40000","0.30481","183.69460","0.32308","-0.76446","0.00205","46.25626"
"18.80000","0.31171","187.07655","0.32970","-0.75784","0.00209","47.10788"
"19.20000","0.31844","190.27406","0.33615","-0.75139","0.00214","47.91304"
"19.60000","0.32507","193.38419","0.34252","-0.74503","0.00218","48.69621"
"20.00000","0.33151","196.40837","0.34871","-0.73884","0.00222","49.45773"
"20.40000","0.33811","199.49928","0.35504","-0.73250","0.00226","50.23605"
"20.80000","0.34471","202.73584","0.36137","-0.72617","0.00230","51.05105"
"21.20000","0.35164","206.02299","0.36804","-0.71951","0.00234","51.87880"
"21.60000","0.35864","209.32359","0.37478","-0.71277","0.00238","52.70992"
"22.00000","0.36505","212.51498","0.38093","-0.70661","0.00242","53.51355"
"22.40000","0.37160","215.57127","0.38724","-0.70031","0.00246","54.28315"
"22.80000","0.37811","218.62134","0.39350","-0.69405","0.00250","55.05119"
"23.20000","0.38473","221.77315","0.39988","-0.68767","0.00254","55.84485"
"23.60000","0.39157","225.13780","0.40644","-0.68110","0.00258","56.69211"
"24.00000","0.39842","228.48076","0.41302","-0.67452","0.00262","57.53390"
"24.40000","0.40515","231.72682","0.41950","-0.66805","0.00267","58.35129"
"24.80000","0.41160","234.68817","0.42570","-0.66184","0.00270","59.09699"
"25.20000","0.41820","237.96365","0.43205","-0.65549","0.00275","59.92179"
"25.60000","0.42472","241.10764","0.43831","-0.64923","0.00279","60.71348"
"26.00000","0.43151","244.34680","0.44485","-0.64269","0.00283","61.52914"
"26.40000","0.43855","247.77592","0.45163","-0.63592","0.00287","62.39263"
"26.80000","0.44499","250.98282","0.45782","-0.62973","0.00291","63.20016"
"27.20000","0.45167","254.21127","0.46425","-0.62329","0.00295","64.01311"
"27.60000","0.45816","257.25854","0.47050","-0.61704","0.00299","64.78046"
"28.00000","0.46481","260.51440","0.47691","-0.61064","0.00303","65.60031"
"28.40000","0.47152","263.82861","0.48336","-0.60418","0.00307","66.43487"
"28.80000","0.47834","267.27490","0.48992","-0.59762","0.00311","67.30268"
"29.20000","0.48525","270.59946","0.49657","-0.59097","0.00316","68.13984"
"29.60000","0.49159","273.74780","0.50267","-0.58487","0.00319","68.93262"
"30.00000","0.49823","277.01926","0.50906","-0.57848","0.00323","69.75641"
"30.40000","0.50468","280.26883","0.51526","-0.57228","0.00327","70.57469"
"30.80000","0.51148","283.74643","0.52179","-0.56575","0.00332","71.45039"
"31.20000","0.51847","287.20984","0.52852","-0.55903","0.00336","72.32251"
"31.60000","0.52515","290.49966","0.53495","-0.55260","0.00340","73.15092"
"32.00000","0.53175","293.90787","0.54132","-0.54623","0.00344","74.00915"
"32.40000","0.53818","296.95847","0.54754","-0.54000","0.00348","74.77732"
"32.80000","0.54478","300.37228","0.55391","-0.53363","0.00352","75.63696"
"33.20000","0.55135","303.73294","0.56026","-0.52728","0.00356","76.48320"
"33.60000","0.55831","307.20349","0.56699","-0.52055","0.00360","77.35712"
"34.00000","0.56524","310.75400","0.57368","-0.51386","0.00365","78.25118"
"34.40000","0.57168","314.03787","0.57990","-0.50764","0.00368","79.07809"
"34.80000","0.57828","317.25720","0.58629","-0.50126","0.00373","79.88876"
"35.20000","0.58475","320.55087","0.59253","-0.49501","0.00377","80.71814"
"35.60000","0.59141","323.99332","0.59896","-0.48858","0.00381","81.58498"
"36.00000","0.59825","327.64050","0.60556","-0.48199","0.00385","82.50338"
"36.40000","0.60514","331.09763","0.61222","-0.47532","0.00389","83.37392"
"36.80000","0.61180","334.55136","0.61865","-0.46889","0.00393","84.24361"
"37.20000","0.61825","337.74301","0.62489","-0.46266","0.00397","85.04730"
"37.60000","0.62480","341.06934","0.63121","-0.45633","0.00401","85.88491"
"38.00000","0.63137","344.43317","0.63756","-0.44998","0.00405","86.73196"
"38.40000","0.63816","347.90845","0.64414","-0.44341","0.00409","87.60707"
"38.80000","0.64530","351.63754","0.65104","-0.43650","0.00414","88.54610"
"39.20000","0.65177","355.00156","0.65729","-0.43026","0.00418","89.39319"
"39.60000","0.65832","358.32767","0.66363","-0.42392","0.00422","90.23074"
"40.00000","0.66482","361.60895","0.66992","-0.41763","0.00426","91.05700"
"40.40000","0.67143","365.03476","0.67631","-0.41124","0.00430","91.91965"
"40.80000","0.67812","368.50037","0.68278","-0.40477","0.00434","92.79234"
"41.20000","0.68500","372.16132","0.68942","-0.39813","0.00438","93.71420"
"41.60000","0.69189","375.67590","0.69608","-0.39146","0.00442","94.59921"
"42.00000","0.69828","378.97186","0.70226","-0.38528","0.00446","95.42917"
"42.40000","0.70493","382.45261","0.70869","-0.37886","0.00450","96.30566"
"42.80000","0.71139","385.91147","0.71493","-0.37262","0.00454","97.17664"
"43.20000","0.71809","389.38501","0.72141","-0.36614","0.00458","98.05131"
"43.60000","0.72517","393.18329","0.72827","-0.35928","0.00463","99.00776"
"44.00000","0.73170","396.54007","0.73461","-0.35294","0.00467","99.85303"
"44.40000","0.73838","399.98932","0.74109","-0.34646","0.00471","100.72159"
"44.80000","0.74483","403.42148","0.74735","-0.34020","0.00475","101.58585"
"45.20000","0.75149","406.76395","0.75381","-0.33373","0.00479","102.42751"
"45.60000","0.75806","410.22665","0.76019","-0.32735","0.00483","103.29946"
"46.00000","0.76497","413.87543","0.76689","-0.32066","0.00487","104.21826"
"46.40000","0.77193","417.43478","0.77365","-0.31389","0.00492","105.11454"
"46.80000","0.77831","420.87781","0.77983","-0.30772","0.00496","105.98154"
"47.20000","0.78496","424.22046","0.78629","-0.30125","0.00500","106.82325"
"47.60000","0.79138","427.61737","0.79252","-0.29503","0.00504","107.67863"
"48.00000","0.79811","431.14563","0.79905","-0.28850","0.00508","108.56708"
"48.40000","0.80495","434.78683","0.80568","-0.28187","0.00512","109.48398"
"48.80000","0.81185","438.50217","0.81237","-0.27518","0.00516","110.41953"
"49.20000","0.81847","441.93109","0.81879","-0.26875","0.00520","111.28297"
"49.60000","0.82488","445.21960","0.82501","-0.26253","0.00524","112.11106"
"50.00000","0.83150","448.71112","0.83144","-0.25611","0.00528","112.99026"
"50.40000","0.83801","452.14691","0.83775","-0.24979","0.00532","113.85543"
"50.80000","0.84484","455.60855","0.84439","-0.24316","0.00537","114.72710"
"51.20000","0.85188","459.48108","0.85120","-0.23634","0.00541","115.70225"
"51.60000","0.85844","462.80334","0.85757","-0.22997","0.00545","116.53883"
"52.00000","0.86496","466.32025","0.86389","-0.22365","0.00549","117.42443"
"52.40000","0.87150","469.73984","0.87023","-0.21731","0.00553","118.28551"
"52.80000","0.87806","473.13104","0.87660","-0.21095","0.00557","119.13946"
"53.20000","0.88483","476.70486","0.88317","-0.20438","0.00561","120.03938"
"53.60000","0.89171","480.33978","0.88984","-0.19770","0.00565","120.95470"
"54.00000","0.89853","484.02017","0.89646","-0.19109","0.00570","121.88145"
"54.40000","0.90492","487.22244","0.90266","-0.18489","0.00574","122.68782"
"54.80000","0.91158","490.81348","0.90913","-0.17842","0.00578","123.59209"
"55.20000","0.91806","494.15176","0.91544","-0.17211","0.00582","124.43270"
"55.60000","0.92477","497.54828","0.92198","-0.16556","0.00586","125.28798"
"56.00000","0.93180","501.47366","0.92881","-0.15874","0.00590","126.27644"
"56.40000","0.93844","504.88025","0.93527","-0.15227","0.00594","127.13425"
"56.80000","0.94506","508.34665","0.94173","-0.14582","0.00598","128.00713"
"57.20000","0.95149","511.61926","0.94799","-0.13956","0.00602","128.83121"
"57.60000","0.95811","515.20526","0.95443","-0.13311","0.00606","129.73419"
"58.00000","0.96474","518.53021","0.96089","-0.12665","0.00611","130.57146"
"58.40000","0.97159","522.13519","0.96756","-0.11998","0.00615","131.47923"
"58.80000","0.97859","525.87164","0.97438","-0.11317","0.00619","132.42010"
"59.20000","0.98495","529.10651","0.98058","-0.10697","0.00623","133.23468"
"59.60000","0.99163","532.67645","0.98708","-0.10047","0.00627","134.13362"
"60.00000","0.99808","535.98743","0.99336","-0.09418","0.00631","134.96736"
"60.40000","1.00473","539.47980","0.99984","-0.08771","0.00635","135.84679"
"60.80000","1.01161","543.05780","1.00654","-0.08100","0.00640","136.74776"
"61.20000","1.01841","546.78040","1.01316","-0.07439","0.00644","137.68515"
"61.60000","1.02516","550.16968","1.01975","-0.06780","0.00648","138.53860"
"62.00000","1.03151","553.54828","1.02593","-0.06162","0.00652","139.38937"
"62.40000","1.03817","556.95978","1.03242","-0.05512","0.00656","140.24843"
"62.80000","1.04467","560.33063","1.03876","-0.04878","0.00660","141.09724"
"63.20000","1.05155","563.95575","1.04547","-0.04207","0.00664","142.01009"
"63.60000","1.05854","567.54297","1.05228","-0.03526","0.00669","142.91339"
"64.00000","1.06509","570.97833","1.05867","-0.02887","0.00673","143.77846"
"64.40000","1.07165","574.45569","1.06506","-0.02248","0.00677","144.65408"
"64.80000","1.07810","577.74902","1.07135","-0.01619","0.00681","145.48338"
"65.20000","1.08472","581.16730","1.07781","-0.00974","0.00685","146.34415"
"65.60000","1.09148","584.60370","1.08440","-0.00314","0.00689","147.20946"
"66.00000","1.09844","588.33704","1.09117","0.00363","0.00693","148.14955"
"66.40000","1.10521","591.92255","1.09778","0.01024","0.00698","149.05243"
"66.80000","1.11162","595.16394","1.10404","0.01650","0.00702","149.86865"
"67.20000","1.11821","598.57404","1.11048","0.02293","0.00706","150.72734"
"67.60000","1.12473","601.94916","1.11685","0.02930","0.00710","151.57724"
"68.00000","1.13142","605.31409","1.12339","0.03584","0.00714","152.42456"
"68.40000","1.13845","609.11823","1.13025","0.04270","0.00718","153.38248"
"68.80000","1.14511","612.53687","1.13676","0.04921","0.00722","154.24333"
"69.20000","1.15171","615.98993","1.14320","0.05565","0.00726","155.11285"
"69.60000","1.15819","619.33484","1.14953","0.06198","0.00730","155.95514"
"70.00000","1.16480","622.68518","1.15599","0.06844","0.00735","156.79878"
"70.40000","1.17143","626.13623","1.16247","0.07492","0.00739","157.66780"
"70.80000","1.17825","629.61658","1.16913","0.08158","0.00743","158.54419"
"71.20000","1.18523","633.33344","1.17594","0.08840","0.00747","159.48013"
"71.60000","1.19159","636.50751","1.18216","0.09462","0.00751","160.27940"
"72.00000","1.19828","639.99976","1.18869","0.10114","0.00755","161.15878"
"72.40000","1.20474","643.25244","1.19501","0.10746","0.00759","161.97784"
"72.80000","1.21141","646.70416","1.20153","0.11398","0.00763","162.84703"
"73.20000","1.21836","650.27740","1.20831","0.12077","0.00768","163.74681"
"73.60000","1.22512","653.78674","1.21491","0.12737","0.00772","164.63049"
"74.00000","1.23180","657.22552","1.22144","0.13390","0.00776","165.49641"
"74.40000","1.23821","660.50659","1.22771","0.14016","0.00780","166.32263"
"74.80000","1.24479","663.71326","1.23414","0.14660","0.00784","167.13010"
"75.20000","1.25135","667.08862","1.24055","0.15301","0.00788","167.98006"
"75.60000","1.25821","670.73663","1.24725","0.15971","0.00793","168.89865"
"76.00000","1.26523","674.31183","1.25411","0.16657","0.00797","169.79893"
"76.40000","1.27172","677.53119","1.26046","0.17292","0.00801","170.60960"
"76.80000","1.27838","680.94409","1.26697","0.17942","0.00805","171.46901"
"77.20000","1.28476","684.11560","1.27321","0.18566","0.00809","172.26762"
"77.60000","1.29139","687.47198","1.27968","0.19214","0.00813","173.11279"
"78.00000","1.29816","690.93536","1.28630","0.19876","0.00817","173.98491"
"78.40000","1.30512","694.37585","1.29311","0.20556","0.00822","174.85127"
"78.80000","1.31185","697.88849","1.29968","0.21214","0.00826","175.73578"
"79.20000","1.31826","701.16602","1.30594","0.21840","0.00830","176.56110"
"79.60000","1.32488","704.48871","1.31242","0.22487","0.00834","177.39780"
"80.00000","1.33138","707.68860","1.31878","0.23123","0.00838","178.20355"
"80.40000","1.33811","711.01312","1.32536","0.23781","0.00842","179.04071"
"80.80000","1.34515","714.70386","1.33223","0.24469","0.00847","179.97008"
"81.20000","1.35181","717.96539","1.33875","0.25120","0.00851","180.79137"
"81.60000","1.35838","721.09406","1.34517","0.25763","0.00855","181.57919"
"82.00000","1.36484","724.11176","1.35150","0.26395","0.00859","182.33908"
"82.40000","1.37141","727.45306","1.35792","0.27037","0.00863","183.18047"
"82.80000","1.37807","730.73645","1.36443","0.27689","0.00867","184.00725"
"83.20000","1.38498","734.10480","1.37119","0.28365","0.00871","184.85544"
"83.60000","1.39194","737.58704","1.37800","0.29046","0.00876","185.73230"
"84.00000","1.39830","740.60846","1.38422","0.29668","0.00880","186.49313"
"84.40000","1.40497","743.92682","1.39075","0.30320","0.00884","187.32874"
"84.80000","1.41142","746.97266","1.39707","0.30953","0.00888","188.09570"
"85.20000","1.41806","750.25165","1.40357","0.31603","0.00892","188.92139"
"85.60000","1.42496","753.67566","1.41034","0.32279","0.00896","189.78360"
"86.00000","1.43174","756.90283","1.41698","0.32943","0.00900","190.59622"
"86.40000","1.43845","760.20325","1.42356","0.33601","0.00905","191.42731"
"86.80000","1.44487","763.20331","1.42985","0.34231","0.00909","192.18275"
"87.20000","1.45154","766.55493","1.43637","0.34883","0.00913","193.02673"
"87.60000","1.45807","769.65430","1.44278","0.35523","0.00917","193.80719"
"88.00000","1.46491","772.86365","1.44948","0.36194","0.00921","194.61533"
"88.40000","1.47192","776.32703","1.45635","0.36880","0.00925","195.48744"
"88.80000","1.47836","779.31415","1.46266","0.37512","0.00929","196.23964"
"89.20000","1.48496","782.38660","1.46914","0.38160","0.00934","197.01332"
"89.60000","1.49146","785.50677","1.47550","0.38796","0.00938","197.79901"
"90.00000","1.49811","788.47260","1.48203","0.39449","0.00942","198.54584"
"90.40000","1.50488","791.48737","1.48867","0.40113","0.00946","199.30498"
"90.80000","1.51181","794.70447","1.49547","0.40793","0.00950","200.11508"
"91.20000","1.51854","797.70050","1.50207","0.41453","0.00954","200.86952"
"91.60000","1.52490","800.35425","1.50831","0.42077","0.00958","201.53777"
"92.00000","1.53152","803.19763","1.51481","0.42726","0.00963","202.25375"
"92.40000","1.53805","806.05542","1.52122","0.43367","0.00967","202.97337"
"92.80000","1.54479","809.01990","1.52782","0.44028","0.00971","203.71986"
"93.20000","1.55182","812.08478","1.53473","0.44718","0.00975","204.49164"
"93.60000","1.55845","814.90100","1.54124","0.45369","0.00979","205.20079"
"94.00000","1.56507","817.58496","1.54774","0.46019","0.00983","205.87663"
"94.40000","1.57150","820.12506","1.55405","0.46651","0.00987","206.51627"
"94.80000","1.57806","822.92206","1.56050","0.47295","0.00992","207.22058"
"95.20000","1.58473","825.69373","1.56705","0.47950","0.00996","207.91852"
"95.60000","1.59165","828.41052","1.57385","0.48630","0.01000","208.60263"
"96.00000","1.59863","831.40515","1.58070","0.49315","0.01004","209.35670"
"96.40000","1.60495","833.79828","1.58692","0.49937","0.01008","209.95932"
"96.80000","1.61156","835.75446","1.59344","0.50589","0.01012","210.45190"
"97.20000","1.61810","837.06732","1.59993","0.51238","0.01017","210.78250"
"97.60000","1.62476","835.82190","1.60664","0.51909","0.01021","210.46889"
"98.00000","1.63169","833.92169","1.61365","0.52611","0.01025","209.99040"
"98.40000","1.63843","833.67798","1.62040","0.53286","0.01030","209.92903"
"98.80000","1.64513","834.52405","1.62707","0.53952","0.01034","210.14207"
"99.20000","1.65150","836.07233","1.63337","0.54582","0.01038","210.53195"
"99.60000","1.65817","837.92676","1.63995","0.55241","0.01042","210.99892"
"100.00000","1.66471","839.63068","1.64642","0.55888","0.01046","211.42798"
"100.40000","1.67159","841.70691","1.65321","0.56566","0.01050","211.95081"
"100.80000","1.67862","844.10199","1.66014","0.57259","0.01055","212.55391"
"101.20000","1.68506","846.23535","1.66649","0.57894","0.01059","213.09111"
"101.60000","1.69166","848.60577","1.67299","0.58545","0.01063","213.68800"
"102.00000","1.69812","850.62952","1.67936","0.59182","0.01067","214.19762"
"102.40000","1.70477","852.03705","1.68596","0.59841","0.01071","214.55205"
"102.80000","1.71150","853.54651","1.69263","0.60508","0.01076","214.93214"
"103.20000","1.71838","855.31854","1.69943","0.61189","0.01080","215.37836"
"103.60000","1.72522","857.70264","1.70617","0.61863","0.01084","215.97870"
"104.00000","1.73158","859.90790","1.71243","0.62489","0.01088","216.53401"
"104.40000","1.73820","862.35645","1.71896","0.63141","0.01092","217.15057"
"104.80000","1.74474","864.99414","1.72538","0.63784","0.01096","217.81477"
"105.20000","1.75151","867.58307","1.73205","0.64450","0.01101","218.46669"
"105.60000","1.75848","870.50098","1.73889","0.65134","0.01105","219.20146"
"106.00000","1.76509","873.01318","1.74539","0.65785","0.01109","219.83406"
"106.40000","1.77170","875.82709","1.75189","0.66434","0.01113","220.54263"
"106.80000","1.77815","878.09070","1.75824","0.67070","0.01117","221.11263"
"107.20000","1.78473","880.84296","1.76471","0.67716","0.01121","221.80568"
"107.60000","1.79142","883.50085","1.77129","0.68374","0.01126","222.47496"
"108.00000","1.79837","886.38867","1.77812","0.69058","0.01130","223.20215"
"108.40000","1.80532","889.13159","1.78495","0.69741","0.01134","223.89285"
"108.80000","1.81168","891.57446","1.79121","0.70367","0.01138","224.50798"
"109.20000","1.81823","894.17358","1.79765","0.71010","0.01142","225.16248"
"109.60000","1.82474","896.74432","1.80405","0.71650","0.01146","225.80981"
"110.00000","1.83140","899.23871","1.81061","0.72306","0.01150","226.43793"
"110.40000","1.83833","900.45959","1.81749","0.72995","0.01155","226.74536"
"110.80000","1.84512","902.49951","1.82419","0.73664","0.01159","227.25903"
"111.20000","1.85176","904.67810","1.83075","0.74320","0.01163","227.80762"
"111.60000","1.85826","906.57489","1.83716","0.74962","0.01167","228.28525"
"112.00000","1.86483","908.92035","1.84363","0.75609","0.01171","228.87587"
"112.40000","1.87139","910.90149","1.85011","0.76256","0.01176","229.37474"
"112.80000","1.87819","913.48206","1.85681","0.76926","0.01180","230.02455"
"113.20000","1.88527","916.08521","1.86377","0.77623","0.01184","230.68005"
"113.60000","1.89163","918.36377","1.87004","0.78249","0.01188","231.25381"
"114.00000","1.89831","920.81378","1.87661","0.78907","0.01192","231.87076"
"114.40000","1.90478","923.21802","1.88299","0.79544","0.01196","232.47617"
"114.80000","1.91147","925.57428","1.88957","0.80203","0.01201","233.06950"
"115.20000","1.91824","928.21515","1.89624","0.80869","0.01205","233.73450"
"115.60000","1.92506","930.90179","1.90295","0.81540","0.01209","234.41103"
"116.00000","1.93187","933.46674","1.90964","0.82210","0.01213","235.05692"
"116.40000","1.93824","934.95490","1.91596","0.82841","0.01217","235.43164"
"116.80000","1.94487","935.57288","1.92256","0.83502","0.01222","235.58725"
"117.20000","1.95133","927.54260","1.92936","0.84181","0.01226","233.56516"
"117.60000","1.95815","926.50891","1.93622","0.84868","0.01230","233.30486"
"118.00000","1.96520","922.41846","1.94344","0.85590","0.01235","232.27484"
"118.40000","1.97178","920.16357","1.95011","0.86257","0.01239","231.70703"
"118.80000","1.97839","920.48163","1.95671","0.86917","0.01243","231.78712"
"119.20000","1.98481","921.03088","1.96311","0.87556","0.01247","231.92543"
"119.60000","1.99143","921.99127","1.96969","0.88214","0.01252","232.16727"
"120.00000","1.99807","923.20947","1.97628","0.88874","0.01256","232.47401"
"120.40000","2.00502","924.98138","1.98316","0.89561","0.01260","232.92021"
"120.80000","2.01187","926.74884","1.98993","0.90238","0.01264","233.36526"
"121.20000","2.01831","928.35175","1.99630","0.90876","0.01268","233.76891"
"121.60000","2.02491","930.27472","2.00282","0.91527","0.01273","234.25313"
"122.00000","2.03139","932.00476","2.00922","0.92168","0.01277","234.68877"
"122.40000","2.03810","933.93073","2.01586","0.92831","0.01281","235.17375"
"122.80000","2.04502","936.13928","2.02268","0.93514","0.01285","235.72989"
"123.20000","2.05183","938.33374","2.02941","0.94186","0.01290","236.28247"
"123.60000","2.05841","940.15540","2.03591","0.94837","0.01294","236.74118"
"124.00000","2.06490","942.16064","2.04231","0.95476","0.01298","237.24612"
"124.40000","2.07141","944.21588","2.04874","0.96120","0.01302","237.76366"
"124.80000","2.07804","946.26599","2.05528","0.96773","0.01306","238.27989"
"125.20000","2.08490","948.43311","2.06204","0.97450","0.01310","238.82561"
"125.60000","2.09198","950.77667","2.06902","0.98147","0.01315","239.41574"
"126.00000","2.09839","952.70618","2.07534","0.98780","0.01319","239.90161"
"126.40000","2.10495","954.46332","2.08182","0.99427","0.01323","240.34407"
"126.80000","2.11145","956.23193","2.08824","1.00070","0.01327","240.78943"
"127.20000","2.11809","958.20178","2.09479","1.00725","0.01331","241.28546"
"127.60000","2.12490","960.33972","2.10150","1.01396","0.01335","241.82381"
"128.00000","2.13171","962.24078","2.10822","1.02068","0.01340","242.30252"
"128.40000","2.13849","964.20984","2.11492","1.02738","0.01344","242.79836"
"128.80000","2.14491","965.70990","2.12127","1.03373","0.01348","243.17609"
"129.20000","2.15156","967.48907","2.12784","1.04030","0.01352","243.62410"
"129.60000","2.15806","968.91998","2.13428","1.04674","0.01356","243.98442"
"130.00000","2.16479","970.62195","2.14094","1.05339","0.01360","244.41299"
"130.40000","2.17194","972.34149","2.14801","1.06046","0.01365","244.84599"
"130.80000","2.17834","973.45819","2.15436","1.06681","0.01369","245.12718"
"131.20000","2.18501","974.72974","2.16097","1.07342","0.01373","245.44737"
"131.60000","2.19146","975.67731","2.16737","1.07983","0.01377","245.68599"
"132.00000","2.19811","976.48541","2.17400","1.08645","0.01381","245.88947"
"132.40000","2.20479","977.01587","2.18065","1.09311","0.01386","246.02304"
"132.80000","2.21173","977.94513","2.18754","1.10000","0.01390","246.25705"
"133.20000","2.21859","979.12000","2.19435","1.10681","0.01394","246.55289"
"133.60000","2.22493","979.95184","2.20065","1.11311","0.01398","246.76236"
"134.00000","2.23157","981.13251","2.20725","1.11970","0.01403","247.05966"
"134.40000","2.23801","982.25214","2.21364","1.12609","0.01407","247.34160"
"134.80000","2.24479","983.66364","2.22036","1.13281","0.01411","247.69702"
"135.20000","2.25173","985.22614","2.22722","1.13967","0.01415","248.09048"
"135.60000","2.25851","986.49915","2.23394","1.14640","0.01419","248.41104"
"136.00000","2.26509","987.84955","2.24047","1.15292","0.01424","248.75108"
"136.40000","2.27151","989.00299","2.24683","1.15929","0.01428","249.04153"
"136.80000","2.27813","990.39246","2.25339","1.16584","0.01432","249.39142"
"137.20000","2.28468","991.52222","2.25989","1.17235","0.01436","249.67590"
"137.60000","2.29160","993.00732","2.26674","1.17919","0.01440","250.04987"
"138.00000","2.29859","994.56152","2.27366","1.18612","0.01445","250.44122"
"138.40000","2.30507","995.71307","2.28010","1.19255","0.01449","250.73120"
"138.80000","2.31159","996.93872","2.28656","1.19902","0.01453","251.03984"
"139.20000","2.31812","998.15356","2.29305","1.20550","0.01457","251.34575"
"139.60000","2.32472","999.20166","2.29960","1.21205","0.01461","251.60966"
"140.00000","2.33158","1000.42511","2.30640","1.21886","0.01466","251.91774"
"140.40000","2.33843","1001.14795","2.31323","1.22568","0.01470","252.09976"
"140.80000","2.34515","1001.55298","2.31993","1.23238","0.01474","252.20175"
"141.20000","2.35158","1001.73663","2.32635","1.23881","0.01478","252.24800"
"141.60000","2.35821","1002.34998","2.33295","1.24541","0.01482","252.40245"
"142.00000","2.36470","1002.88287","2.33943","1.25188","0.01487","252.53664"
"142.40000","2.37145","1003.47540","2.34615","1.25860","0.01491","252.68584"
"142.80000","2.37857","1004.52777","2.35323","1.26568","0.01495","252.95084"
"143.20000","2.38509","1004.98389","2.35973","1.27218","0.01499","253.06569"
"143.60000","2.39171","1005.47418","2.36632","1.27878","0.01504","253.18915"
"144.00000","2.39813","1005.68469","2.37274","1.28520","0.01508","253.24216"
"144.40000","2.40474","1005.58673","2.37936","1.29181","0.01512","253.21750"
"144.80000","2.41146","1005.08063","2.38609","1.29854","0.01516","253.09006"
"145.20000","2.41831","1004.35034","2.39297","1.30543","0.01521","252.90616"
"145.60000","2.42522","1002.78528","2.39995","1.31240","0.01525","252.51205"
"146.00000","2.43160","999.44312","2.40647","1.31892","0.01529","251.67047"
"146.40000","2.43828","994.30029","2.41337","1.32582","0.01533","250.37544"
"146.80000","2.44474","988.96326","2.42006","1.33251","0.01538","249.03152"
"147.20000","2.45141","981.87701","2.42706","1.33951","0.01542","247.24713"
"147.60000","2.45838","970.63977","2.43452","1.34698","0.01547","244.41748"
"148.00000","2.46510","967.49561","2.44138","1.35384","0.01551","243.62575"
"148.40000","2.47178","966.60095","2.44811","1.36056","0.01556","243.40045"
"148.80000","2.47814","966.70996","2.45446","1.36691","0.01560","243.42790"
"149.20000","2.48479","967.44562","2.46107","1.37353","0.01564","243.61316"
"149.60000","2.49137","968.37317","2.46762","1.38007","0.01568","243.84673"
"150.00000","2.49829","970.01788","2.47446","1.38691","0.01572","244.26088"
"150.40000","2.50523","971.85431","2.48131","1.39377","0.01577","244.72331"
"150.80000","2.51170","973.30145","2.48773","1.40018","0.01581","245.08772"
"151.20000","2.51829","975.15594","2.49423","1.40669","0.01585","245.55470"
"151.60000","2.52475","976.80438","2.50061","1.41307","0.01589","245.96979"
"152.00000","2.53139","978.75262","2.50717","1.41962","0.01593","246.46037"
"152.40000","2.53823","980.85944","2.51391","1.42637","0.01597","246.99089"
"152.80000","2.54514","983.11554","2.52073","1.43318","0.01602","247.55901"
"153.20000","2.55182","985.09033","2.52732","1.43977","0.01606","248.05629"
"153.60000","2.55826","987.03204","2.53367","1.44612","0.01610","248.54523"
"154.00000","2.56482","989.14093","2.54014","1.45259","0.01614","249.07626"
"154.40000","2.57140","991.12640","2.54663","1.45908","0.01618","249.57623"
"154.80000","2.57815","993.38257","2.55328","1.46573","0.01622","250.14436"
"155.20000","2.58520","995.63257","2.56022","1.47268","0.01627","250.71094"
"155.60000","2.59172","997.66785","2.56667","1.47912","0.01631","251.22343"
"156.00000","2.59833","999.66052","2.57319","1.48565","0.01635","251.72522"
"156.40000","2.60484","1001.65308","2.57961","1.49207","0.01639","252.22696"
"156.80000","2.61142","1003.76727","2.58611","1.49857","0.01643","252.75934"
"157.20000","2.61815","1005.77307","2.59276","1.50521","0.01647","253.26442"
"157.60000","2.62498","1007.90234","2.59950","1.51195","0.01652","253.80060"
"158.00000","2.63188","1010.05908","2.60630","1.51876","0.01656","254.34367"
"158.40000","2.63822","1011.96191","2.61257","1.52502","0.01660","254.82283"
"158.80000","2.64492","1014.07373","2.61918","1.53163","0.01664","255.35461"
"159.20000","2.65139","1015.82819","2.62557","1.53803","0.01668","255.79640"
"159.60000","2.65809","1017.87427","2.63219","1.54465","0.01673","256.31161"
"160.00000","2.66513","1020.10791","2.63914","1.55159","0.01677","256.87408"
"160.40000","2.67175","1021.93591","2.64567","1.55813","0.01681","257.33438"
"160.80000","2.67842","1023.72339","2.65227","1.56472","0.01685","257.78448"
"161.20000","2.68483","1025.37183","2.65862","1.57107","0.01689","258.19958"
"161.60000","2.69142","1027.20618","2.66512","1.57758","0.01693","258.66150"
"162.00000","2.69802","1028.97729","2.67166","1.58411","0.01698","259.10748"
"162.40000","2.70496","1030.80371","2.67852","1.59097","0.01702","259.56741"
"162.80000","2.71193","1032.74329","2.68541","1.59786","0.01706","260.05582"
"163.20000","2.71833","1034.30530","2.69173","1.60419","0.01710","260.44913"
"163.60000","2.72499","1035.99854","2.69833","1.61078","0.01715","260.87552"
"164.00000","2.73139","1037.37427","2.70467","1.61713","0.01719","261.22192"
"164.40000","2.73806","1038.87134","2.71128","1.62373","0.01723","261.59891"
"164.80000","2.74491","1040.73877","2.71805","1.63050","0.01727","262.06915"
"165.20000","2.75183","1042.30054","2.72490","1.63736","0.01731","262.46243"
"165.60000","2.75846","1043.76660","2.73147","1.64392","0.01736","262.83160"
"166.00000","2.76488","1044.98523","2.73784","1.65029","0.01740","263.13846"
"166.40000","2.77151","1046.45813","2.74440","1.65686","0.01744","263.50934"
"166.80000","2.77803","1047.72546","2.75088","1.66333","0.01748","263.82849"
"167.20000","2.78484","1049.14856","2.75762","1.67008","0.01752","264.18683"
"167.60000","2.79193","1050.93713","2.76463","1.67708","0.01757","264.63721"
"168.00000","2.79845","1052.11951","2.77110","1.68356","0.01761","264.93494"
"168.40000","2.80499","1053.33716","2.77759","1.69004","0.01765","265.24158"
"168.80000","2.81148","1054.54797","2.78402","1.69648","0.01769","265.54645"
"169.20000","2.81805","1055.83459","2.79054","1.70300","0.01773","265.87045"
"169.60000","2.82476","1057.13574","2.79720","1.70965","0.01777","266.19809"
"170.00000","2.83173","1058.57019","2.80410","1.71655","0.01782","266.55930"
"170.40000","2.83859","1060.07507","2.81090","1.72336","0.01786","266.93823"
"170.80000","2.84494","1061.18481","2.81720","1.72965","0.01790","267.21768"
"171.20000","2.85159","1062.46533","2.82380","1.73625","0.01794","267.54013"
"171.60000","2.85808","1063.66028","2.83023","1.74269","0.01798","267.84103"
"172.00000","2.86475","1064.97449","2.83684","1.74930","0.01803","268.17197"
"172.40000","2.87174","1066.32654","2.84378","1.75624","0.01807","268.51242"
"172.80000","2.87840","1067.74927","2.85038","1.76284","0.01811","268.87070"
"173.20000","2.88508","1068.98804","2.85700","1.76946","0.01815","269.18262"
"173.60000","2.89151","1069.98633","2.86339","1.77585","0.01819","269.43399"
"174.00000","2.89817","1071.30347","2.86999","1.78245","0.01824","269.76569"
"174.40000","2.90475","1072.49011","2.87652","1.78898","0.01828","270.06448"
"174.80000","2.91165","1073.91479","2.88336","1.79581","0.01832","270.42322"
"175.20000","2.91862","1075.45544","2.89027","1.80272","0.01837","270.81119"
"175.60000","2.92499","1076.48474","2.89659","1.80905","0.01841","271.07037"
"176.00000","2.93159","1077.66528","2.90314","1.81560","0.01845","271.36765"
"176.40000","2.93808","1078.87622","2.90958","1.82203","0.01849","271.67258"
"176.80000","2.94476","1080.19092","2.91620","1.82866","0.01853","272.00363"
"177.20000","2.95162","1081.42249","2.92301","1.83547","0.01857","272.31375"
"177.60000","2.95852","1082.75781","2.92985","1.84231","0.01862","272.64999"
"178.00000","2.96518","1083.80396","2.93647","1.84892","0.01866","272.91342"
"178.40000","2.97154","1084.88721","2.94278","1.85523","0.01870","273.18619"
"178.80000","2.97815","1085.81396","2.94935","1.86181","0.01874","273.41956"
"179.20000","2.98472","1086.74695","2.95588","1.86834","0.01878","273.65451"
"179.60000","2.99151","1087.62683","2.96263","1.87508","0.01883","273.87607"
"180.00000","2.99855","1088.52185","2.96963","1.88209","0.01887","274.10144"
"180.40000","3.00508","1088.66516","2.97616","1.88861","0.01891","274.13754"
"180.80000","3.01169","1088.64465","2.98277","1.89523","0.01895","274.13235"
"181.20000","3.01813","1087.34998","2.98927","1.90172","0.01899","273.80637"
"181.60000","3.02471","1084.63806","2.99596","1.90842","0.01904","273.12347"
"182.00000","3.03145","1082.07190","3.00282","1.91527","0.01908","272.47726"
"182.40000","3.03836","1080.26160","3.00980","1.92225","0.01912","272.02142"
"182.80000","3.04525","1079.04712","3.01675","1.92920","0.01917","271.71561"
"183.20000","3.05159","1077.93030","3.02313","1.93559","0.01921","271.43439"
"183.60000","3.05820","1077.39514","3.02976","1.94222","0.01925","271.29962"
"184.00000","3.06475","1076.63562","3.03635","1.94880","0.01929","271.10837"
"184.40000","3.07146","1076.29333","3.04307","1.95552","0.01934","271.02219"
"184.80000","3.07846","1076.32568","3.05007","1.96252","0.01938","271.03033"
"185.20000","3.08510","1076.42932","3.05671","1.96916","0.01942","271.05643"
"185.60000","3.09175","1076.51709","3.06335","1.97581","0.01947","271.07852"
"186.00000","3.09815","1076.37610","3.06976","1.98221","0.01951","271.04303"
"186.40000","3.10480","1076.52258","3.07640","1.98886","0.01955","271.07990"
"186.80000","3.11139","1076.17053","3.08300","1.99546","0.01959","270.99124"
"187.20000","3.11830","1076.12585","3.08992","2.00238","0.01963","270.98001"
"187.60000","3.12527","1076.08997","3.09689","2.00935","0.01968","270.97098"
"188.00000","3.13169","1075.74292","3.10333","2.01578","0.01972","270.88358"
"188.40000","3.13831","1075.51428","3.10996","2.02241","0.01976","270.82599"
"188.80000","3.14477","1075.15662","3.11643","2.02889","0.01980","270.73593"
"189.20000","3.15144","1074.43750","3.12313","2.03559","0.01984","270.55484"
"189.60000","3.15830","1070.85559","3.13015","2.04260","0.01989","269.65289"
"190.00000","3.16508","1067.98462","3.13704","2.04950","0.01993","268.92996"
"190.40000","3.17182","1065.80627","3.14388","2.05633","0.01998","268.38141"
"190.80000","3.17821","1063.66687","3.15037","2.06282","0.02002","267.84268"
"191.20000","3.18484","1062.07910","3.15706","2.06952","0.02006","267.44287"
"191.60000","3.19141","1060.69165","3.16369","2.07615","0.02010","267.09351"
"192.00000","3.19826","1059.61902","3.17059","2.08304","0.02015","266.82339"
"192.40000","3.20521","1058.86584","3.17757","2.09003","0.02019","266.63376"
"192.80000","3.21170","1058.06860","3.18410","2.09655","0.02023","266.43298"
"193.20000","3.21833","1057.35217","3.19075","2.10321","0.02027","266.25259"
"193.60000","3.22479","1056.40417","3.19725","2.10971","0.02032","266.01389"
"194.00000","3.23137","1055.81982","3.20386","2.11632","0.02036","265.86673"
"194.40000","3.23815","1055.38098","3.21066","2.12312","0.02040","265.75623"
"194.80000","3.24513","1055.03650","3.21766","2.13011","0.02045","265.66946"
"195.20000","3.25194","1054.49805","3.22449","2.13695","0.02049","265.53387"
"195.60000","3.25828","1053.71643","3.23086","2.14332","0.02053","265.33707"
"196.00000","3.26485","1053.11707","3.23746","2.14992","0.02057","265.18613"
"196.40000","3.27139","1052.40894","3.24403","2.15649","0.02061","265.00781"
"196.80000","3.27810","1052.07947","3.25075","2.16321","0.02066","264.92487"
"197.20000","3.28515","1051.74646","3.25782","2.17027","0.02070","264.84100"
"197.60000","3.29178","1051.38684","3.26446","2.17692","0.02074","264.75046"
"198.00000","3.29838","1051.04395","3.27108","2.18353","0.02078","264.66409"
"198.40000","3.30489","1050.74182","3.27760","2.19006","0.02083","264.58804"
"198.80000","3.31145","1050.42273","3.28418","2.19663","0.02087","264.50769"
"199.20000","3.31808","1050.25122","3.29081","2.20326","0.02091","264.46448"
"199.60000","3.32493","1050.12085","3.29767","2.21012","0.02095","264.43167"
"200.00000","3.33195","1050.18713","3.30469","2.21714","0.02100","264.44836"
"200.40000","3.33825","1049.67236","3.31101","2.22347","0.02104","264.31873"
"200.80000","3.34494","1049.42468","3.31771","2.23016","0.02108","264.25635"
"201.20000","3.35143","1048.98657","3.32422","2.23667","0.02112","264.14603"
"201.60000","3.35813","1048.74121","3.33093","2.24338","0.02117","264.08426"
"202.00000","3.36502","1048.42200","3.33783","2.25029","0.02121","264.00388"
"202.40000","3.37178","1048.12634","3.34460","2.25706","0.02125","263.92941"
"202.80000","3.37849","1047.69446","3.35133","2.26379","0.02129","263.82068"
"203.20000","3.38488","1047.08826","3.35775","2.27021","0.02134","263.66803"
"203.60000","3.39149","1046.66199","3.36438","2.27684","0.02138","263.56067"
"204.00000","3.39799","1046.14465","3.37090","2.28335","0.02142","263.43042"
"204.40000","3.40488","1045.94983","3.37779","2.29025","0.02146","263.38135"
"204.80000","3.41196","1045.71619","3.38489","2.29734","0.02151","263.32251"
"205.20000","3.41840","1045.19617","3.39135","2.30381","0.02155","263.19159"
"205.60000","3.42502","1044.44836","3.39800","2.31045","0.02159","263.00327"
"206.00000","3.43145","1044.03735","3.40445","2.31691","0.02163","262.89978"
"206.40000","3.43808","1043.68494","3.41110","2.32355","0.02167","262.81104"
"206.80000","3.44479","1043.31262","3.41782","2.33027","0.02172","262.71729"
"207.20000","3.45175","1043.27905","3.42478","2.33724","0.02176","262.70883"
"207.60000","3.45852","1043.08923","3.43156","2.34401","0.02180","262.66104"
"208.00000","3.46494","1042.70190","3.43800","2.35045","0.02185","262.56351"
"208.40000","3.47154","1042.32166","3.44461","2.35707","0.02189","262.46774"
"208.80000","3.47802","1042.15076","3.45110","2.36356","0.02193","262.42471"
"209.20000","3.48481","1041.98853","3.45790","2.37035","0.02197","262.38385"
"209.60000","3.49180","1042.00818","3.46489","2.37734","0.02202","262.38879"
"210.00000","3.49850","1041.83301","3.47159","2.38405","0.02206","262.34470"
"210.40000","3.50503","1041.58411","3.47813","2.39059","0.02210","262.28201"
"210.80000","3.51152","1041.17212","3.48464","2.39710","0.02214","262.17828"
"211.20000","3.51806","1040.64856","3.49120","2.40366","0.02218","262.04645"
"211.60000","3.52471","1040.35120","3.49787","2.41032","0.02223","261.97156"
"212.00000","3.53162","1040.05420","3.50479","2.41724","0.02227","261.89676"
"212.40000","3.53864","1039.48914","3.51183","2.42429","0.02231","261.75449"
"212.80000","3.54502","1038.69141","3.51825","2.43070","0.02236","261.55362"
"213.20000","3.55160","1037.52026","3.52487","2.43733","0.02240","261.25870"
"213.60000","3.55810","1035.79468","3.53145","2.44390","0.02244","260.82419"
"214.00000","3.56476","1033.64368","3.53819","2.45065","0.02248","260.28253"
"214.40000","3.57163","1031.72485","3.54515","2.45761","0.02253","259.79935"
"214.80000","3.57839","1030.31299","3.55196","2.46442","0.02257","259.44382"
"215.20000","3.58512","1029.20361","3.55874","2.47119","0.02261","259.16449"
"215.60000","3.59154","1027.90527","3.56521","2.47767","0.02265","258.83755"
"216.00000","3.59820","1027.21667","3.57191","2.48436","0.02270","258.66415"
"216.40000","3.60474","1026.39978","3.57848","2.49093","0.02274","258.45844"
"216.80000","3.61151","1025.75708","3.58527","2.49773","0.02278","258.29660"
"217.20000","3.61864","1025.47229","3.59242","2.50487","0.02283","258.22488"
"217.60000","3.62499","1024.72144","3.59880","2.51125","0.02287","258.03583"
"218.00000","3.63164","1024.15759","3.60547","2.51793","0.02291","257.89383"
"218.40000","3.63809","1023.39471","3.61196","2.52441","0.02295","257.70172"
"218.80000","3.64477","1022.51440","3.61867","2.53113","0.02299","257.48007"
"219.20000","3.65151","1021.66943","3.62545","2.53791","0.02304","257.26730"
"219.60000","3.65844","1020.70215","3.63242","2.54487","0.02308","257.02371"
"220.00000","3.66522","1019.56671","3.63925","2.55170","0.02312","256.73779"
"220.40000","3.67158","1017.08752","3.64571","2.55816","0.02317","256.11353"
"220.80000","3.67820","1016.01007","3.65237","2.56483","0.02321","255.84221"
"221.20000","3.68467","1015.21014","3.65888","2.57134","0.02325","255.64078"
"221.60000","3.69151","1014.84552","3.66573","2.57819","0.02329","255.54895"
"222.00000","3.69846","1014.40173","3.67271","2.58516","0.02334","255.43721"
"222.40000","3.70515","1013.94281","3.67941","2.59187","0.02338","255.32164"
"222.80000","3.71171","1013.26129","3.68600","2.59845","0.02342","255.15002"
"223.20000","3.71814","1012.64362","3.69246","2.60492","0.02346","254.99449"
"223.60000","3.72476","1012.34473","3.69909","2.61154","0.02350","254.91924"
"224.00000","3.73139","1011.91180","3.70573","2.61819","0.02355","254.81021"
"224.40000","3.73834","1012.00922","3.71268","2.62513","0.02359","254.83475"
"224.80000","3.74522","1011.43616","3.71959","2.63204","0.02363","254.69044"
"225.20000","3.75169","1010.75787","3.72609","2.63854","0.02368","254.51964"
"225.60000","3.75822","1010.23633","3.73264","2.64509","0.02372","254.38831"
"226.00000","3.76476","1009.96075","3.73919","2.65164","0.02376","254.31892"
"226.40000","3.77140","1009.89612","3.74583","2.65829","0.02380","254.30264"
"226.80000","3.77838","1009.10748","3.75285","2.66530","0.02385","254.10406"
"227.20000","3.78513","1001.07800","3.75993","2.67238","0.02389","252.08215"
"227.60000","3.79175","999.63702","3.76662","2.67907","0.02393","251.71930"
"227.84200","3.79568","972.72144","3.77173","2.68418","0.02397","244.94167"
"227.86300","3.79613","929.10071","3.77409","2.68654","0.02398","233.95749"
"227.90400","3.79688","887.33618","3.77659","2.68905","0.02400","223.44073"
"227.94300","3.79743","846.57928","3.77884","2.69129","0.02401","213.17772"
"227.95700","3.79762","802.01819","3.78096","2.69341","0.02402","201.95676"
"227.97200","3.79783","756.09601","3.78311","2.69556","0.02404","190.39307"
"228.00500","3.79835","712.90826","3.78551","2.69796","0.02405","179.51793"
"228.17600","3.80127","672.73120","3.79022","2.70268","0.02408","169.40091"
"228.57600","3.80801","647.46204","3.79809","2.71054","0.02413","163.03787"
"228.97600","3.81475","641.39410","3.80509","2.71755","0.02418","161.50990"
"229.37600","3.82112","635.61609","3.81173","2.72419","0.02422","160.05493"
"229.77600","3.82778","626.85620","3.81878","2.73124","0.02427","157.84909"
"230.17600","3.83429","620.58490","3.82557","2.73803","0.02431","156.26991"
"230.57600","3.84119","618.82227","3.83255","2.74501","0.02435","155.82607"
"230.97600","3.84819","617.35895","3.83962","2.75208","0.02440","155.45758"
"231.37600","3.85466","615.51923","3.84617","2.75863","0.02444","154.99432"
"231.77600","3.86128","613.50366","3.85288","2.76533","0.02448","154.48679"
"231.92400","3.86351","612.86908","3.85514","2.76760","0.02450","154.32700"