File: flexion/5_axis/New folder/Specimen_RawData_11.csv
Specimen properties : Specimen label,"F4"
Specimen properties : Support span,"72.00",mm
Specimen properties : Thickness,"5.42",mm
Specimen properties : Width,"13.48",mm
Maximum Load : Maximum Load,"758.8",N
Tangent Modulus of Elasticity : Tangent Modulus of Elasticity,"22977500106.65960",Pa
Test : Rate 1,"1.00000",mm/min
Specimen notes : Specimen note 1,""

Time,Displacement,Load,Flexure extension,Corrected extension,Flexure strain (Corrected extension),Flexure stress
(s),(mm),(N),(mm),(mm),(mm/mm),(MPa)
"0.00000","-0.00006","49.44160","0.08134","-1.05568","0.00051","13.48428"
"0.50000","0.00638","52.47725","0.08738","-1.04965","0.00055","14.31220"
"1.00000","0.01452","56.62250","0.09496","-1.04207","0.00060","15.44274"
"1.50000","0.02337","60.77934","0.10330","-1.03372","0.00065","16.57644"
"2.00000","0.03119","64.65982","0.11067","-1.02635","0.00069","17.63477"
"2.50000","0.03975","68.61008","0.11877","-1.01825","0.00075","18.71213"
"3.00000","0.04800","72.86488","0.12652","-1.01050","0.00079","19.87255"
"3.50000","0.05629","76.91499","0.13434","-1.00269","0.00084","20.97714"
"4.00000","0.06462","80.98394","0.14219","-0.99484","0.00089","22.08687"
"4.50000","0.07286","84.90633","0.14997","-0.98705","0.00094","23.15663"
"5.00000","0.08150","88.96795","0.15817","-0.97885","0.00099","24.26436"
"5.50000","0.08944","92.62199","0.16575","-0.97127","0.00104","25.26093"
"6.00000","0.09817","96.77477","0.17408","-0.96295","0.00109","26.39353"
"6.50000","0.10618","100.48208","0.18172","-0.95531","0.00114","27.40463"
"7.00000","0.11494","104.26551","0.19011","-0.94692","0.00119","28.43649"
"7.50000","0.12281","107.86499","0.19763","-0.93940","0.00124","29.41818"
"8.00000","0.13140","111.78275","0.20583","-0.93119","0.00129","30.48668"
"8.50000","0.13967","115.45689","0.21375","-0.92327","0.00134","31.48873"
"9.00000","0.14789","119.30371","0.22159","-0.91544","0.00139","32.53788"
"9.50000","0.15635","123.06665","0.22969","-0.90734","0.00144","33.56415"
"10.00000","0.16449","126.76193","0.23747","-0.89956","0.00149","34.57197"
"10.50000","0.17327","130.98796","0.24583","-0.89119","0.00154","35.72454"
"11.00000","0.18113","134.51888","0.25335","-0.88368","0.00159","36.68753"
"11.50000","0.18989","138.90572","0.26168","-0.87534","0.00164","37.88396"
"12.00000","0.19783","142.63014","0.26926","-0.86777","0.00169","38.89973"
"12.50000","0.20662","147.00160","0.27762","-0.85940","0.00174","40.09196"
"13.00000","0.21455","150.87570","0.28518","-0.85184","0.00179","41.14856"
"13.50000","0.22297","155.03888","0.29319","-0.84384","0.00184","42.28399"
"14.00000","0.23135","159.22964","0.30119","-0.83584","0.00189","43.42694"
"14.50000","0.23952","163.36061","0.30901","-0.82802","0.00194","44.55358"
"15.00000","0.24801","167.63100","0.31713","-0.81989","0.00199","45.71825"
"15.50000","0.25613","171.58728","0.32492","-0.81211","0.00204","46.79725"
"16.00000","0.26492","176.06186","0.33332","-0.80370","0.00209","48.01761"
"16.50000","0.27278","180.04012","0.34085","-0.79618","0.00214","49.10261"
"17.00000","0.28144","184.47002","0.34913","-0.78789","0.00219","50.31078"
"17.50000","0.28959","188.52840","0.35693","-0.78009","0.00224","51.41763"
"18.00000","0.29825","193.07286","0.36521","-0.77181","0.00229","52.65705"
"18.50000","0.30626","197.07426","0.37288","-0.76415","0.00234","53.74836"
"19.00000","0.31464","201.28819","0.38090","-0.75612","0.00239","54.89763"
"19.50000","0.32308","205.55202","0.38900","-0.74803","0.00244","56.06051"
"20.00000","0.33114","209.68153","0.39673","-0.74030","0.00249","57.18676"
"20.50000","0.33973","214.06093","0.40497","-0.73205","0.00254","58.38116"
"21.00000","0.34783","218.17110","0.41274","-0.72429","0.00259","59.50213"
"21.50000","0.35662","222.68591","0.42117","-0.71586","0.00264","60.73346"
"22.00000","0.36442","226.63858","0.42866","-0.70837","0.00269","61.81148"
"22.50000","0.37318","231.14558","0.43705","-0.69997","0.00274","63.04068"
"23.00000","0.38124","235.20071","0.44478","-0.69224","0.00279","64.14664"
"23.50000","0.38977","239.57570","0.45297","-0.68406","0.00284","65.33984"
"24.00000","0.39791","243.60915","0.46079","-0.67624","0.00289","66.43989"
"24.50000","0.40627","247.89510","0.46882","-0.66821","0.00294","67.60880"
"25.00000","0.41479","252.26894","0.47700","-0.66003","0.00299","68.80168"
"25.50000","0.42280","256.19302","0.48471","-0.65232","0.00304","69.87190"
"26.00000","0.43147","260.61124","0.49305","-0.64398","0.00309","71.07689"
"26.50000","0.43944","264.63614","0.50071","-0.63632","0.00314","72.17461"
"27.00000","0.44835","269.26724","0.50926","-0.62776","0.00319","73.43765"
"27.50000","0.45618","273.02548","0.51680","-0.62023","0.00324","74.46265"
"28.00000","0.46478","277.41418","0.52506","-0.61197","0.00329","75.65958"
"28.50000","0.47296","281.47528","0.53293","-0.60410","0.00334","76.76717"
"29.00000","0.48140","285.69733","0.54104","-0.59598","0.00339","77.91866"
"29.50000","0.48961","289.78937","0.54894","-0.58809","0.00344","79.03468"
"30.00000","0.49785","293.92355","0.55690","-0.58013","0.00349","80.16221"
"30.50000","0.50646","298.39630","0.56521","-0.57182","0.00355","81.38206"
"31.00000","0.51441","302.18140","0.57291","-0.56411","0.00359","82.41438"
"31.50000","0.52305","306.50684","0.58126","-0.55577","0.00365","83.59406"
"32.00000","0.53117","310.55844","0.58911","-0.54792","0.00370","84.69907"
"32.50000","0.54006","315.13199","0.59769","-0.53934","0.00375","85.94642"
"33.00000","0.54786","318.75299","0.60525","-0.53178","0.00380","86.93398"
"33.50000","0.55645","323.00555","0.61355","-0.52347","0.00385","88.09379"
"34.00000","0.56468","327.11633","0.62151","-0.51552","0.00390","89.21493"
"34.50000","0.57299","330.98920","0.62956","-0.50747","0.00395","90.27118"
"35.00000","0.58130","335.15753","0.63759","-0.49943","0.00400","91.40801"
"35.50000","0.58954","339.10812","0.64557","-0.49146","0.00405","92.48547"
"36.00000","0.59818","343.47156","0.65392","-0.48310","0.00410","93.67551"
"36.50000","0.60605","347.03073","0.66157","-0.47546","0.00415","94.64621"
"37.00000","0.61479","351.37006","0.67002","-0.46701","0.00420","95.82968"
"37.50000","0.62282","355.16144","0.67781","-0.45922","0.00425","96.86371"
"38.00000","0.63160","359.52222","0.68631","-0.45071","0.00431","98.05303"
"38.50000","0.63951","363.09070","0.69400","-0.44303","0.00435","99.02627"
"39.00000","0.64808","367.34320","0.70229","-0.43473","0.00441","100.18606"
"39.50000","0.65636","371.17856","0.71032","-0.42670","0.00446","101.23208"
"40.00000","0.66459","375.09598","0.71830","-0.41873","0.00451","102.30048"
"40.50000","0.67303","379.06729","0.72648","-0.41054","0.00456","103.38358"
"41.00000","0.68114","382.82861","0.73435","-0.40267","0.00461","104.40942"
"41.50000","0.68987","387.04959","0.74282","-0.39421","0.00466","105.56061"
"42.00000","0.69778","390.73563","0.75050","-0.38652","0.00471","106.56591"
"42.50000","0.70655","394.85736","0.75904","-0.37799","0.00476","107.69003"
"43.00000","0.71455","398.31870","0.76684","-0.37018","0.00481","108.63405"
"43.50000","0.72333","402.55161","0.77538","-0.36165","0.00486","109.78850"
"44.00000","0.73122","406.00711","0.78307","-0.35395","0.00491","110.73093"
"44.50000","0.73961","409.97504","0.79124","-0.34579","0.00496","111.81310"
"45.00000","0.74802","413.94498","0.79942","-0.33760","0.00501","112.89583"
"45.50000","0.75618","417.68280","0.80736","-0.32966","0.00506","113.91525"
"46.00000","0.76462","421.42700","0.81559","-0.32143","0.00512","114.93642"
"46.50000","0.77279","425.31918","0.82353","-0.31349","0.00517","115.99793"
"47.00000","0.78158","429.44000","0.83209","-0.30494","0.00522","117.12181"
"47.50000","0.78944","432.89996","0.83976","-0.29727","0.00527","118.06545"
"48.00000","0.79814","436.87979","0.84823","-0.28880","0.00532","119.15088"
"48.50000","0.80626","440.66800","0.85613","-0.28089","0.00537","120.18404"
"49.00000","0.81495","444.62991","0.86460","-0.27243","0.00542","121.26458"
"49.50000","0.82290","448.14606","0.87235","-0.26468","0.00547","122.22354"
"50.00000","0.83130","451.89365","0.88054","-0.25649","0.00552","123.24563"
"50.50000","0.83974","455.76096","0.88875","-0.24827","0.00558","124.30036"
"51.00000","0.84780","459.24854","0.89662","-0.24041","0.00562","125.25153"
"51.50000","0.85638","463.12659","0.90498","-0.23205","0.00568","126.30920"
"52.00000","0.86446","466.63885","0.91286","-0.22417","0.00573","127.26711"
"52.50000","0.87327","470.72565","0.92143","-0.21560","0.00578","128.38170"
"53.00000","0.88110","474.01218","0.92908","-0.20795","0.00583","129.27805"
"53.50000","0.88989","477.97964","0.93764","-0.19939","0.00588","130.36009"
"54.00000","0.89791","481.43594","0.94547","-0.19156","0.00593","131.30273"
"54.50000","0.90650","485.18997","0.95383","-0.18319","0.00598","132.32658"
"55.00000","0.91459","488.50775","0.96174","-0.17529","0.00603","133.23145"
"55.50000","0.92288","491.99060","0.96985","-0.16718","0.00608","134.18134"
"56.00000","0.93140","495.86227","0.97817","-0.15886","0.00614","135.23726"
"56.50000","0.93946","499.18872","0.98607","-0.15096","0.00619","136.14449"
"57.00000","0.94812","502.91620","0.99453","-0.14249","0.00624","137.16109"
"57.50000","0.95617","506.30328","1.00241","-0.13461","0.00629","138.08485"
"58.00000","0.96500","510.20114","1.01106","-0.12597","0.00634","139.14792"
"58.50000","0.97283","513.30554","1.01873","-0.11830","0.00639","139.99458"
"59.00000","0.98143","516.97443","1.02714","-0.10989","0.00644","140.99521"
"59.50000","0.98964","520.22247","1.03519","-0.10184","0.00649","141.88104"
"60.00000","0.99808","523.70349","1.04346","-0.09357","0.00655","142.83043"
"60.50000","1.00624","526.96973","1.05145","-0.08558","0.00660","143.72124"
"61.00000","1.01450","530.31415","1.05954","-0.07748","0.00665","144.63336"
"61.50000","1.02314","533.87347","1.06801","-0.06902","0.00670","145.60411"
"62.00000","1.03112","536.88849","1.07584","-0.06119","0.00675","146.42639"
"62.50000","1.03976","540.58917","1.08429","-0.05274","0.00680","147.43568"
"63.00000","1.04784","543.49646","1.09223","-0.04479","0.00685","148.22859"
"63.50000","1.05666","547.36121","1.10086","-0.03616","0.00691","149.28264"
"64.00000","1.06448","550.22955","1.10855","-0.02848","0.00695","150.06493"
"64.50000","1.07309","553.81445","1.11698","-0.02004","0.00701","151.04263"
"65.00000","1.08131","556.86102","1.12505","-0.01198","0.00706","151.87354"
"65.50000","1.08969","560.06281","1.13327","-0.00375","0.00711","152.74677"
"66.00000","1.09794","563.32422","1.14137","0.00434","0.00716","153.63625"
"66.50000","1.10616","566.46210","1.14943","0.01241","0.00721","154.49205"
"67.00000","1.11481","569.81097","1.15793","0.02090","0.00726","155.40540"
"67.50000","1.12274","572.73383","1.16572","0.02869","0.00731","156.20255"
"68.00000","1.13149","576.13306","1.17430","0.03727","0.00737","157.12962"
"68.50000","1.13948","578.90753","1.18215","0.04512","0.00742","157.88631"
"69.00000","1.14828","582.30988","1.19079","0.05377","0.00747","158.81424"
"69.50000","1.15621","584.97687","1.19859","0.06156","0.00752","159.54161"
"70.00000","1.16472","588.15833","1.20695","0.06993","0.00757","160.40930"
"70.50000","1.17299","591.15125","1.21507","0.07805","0.00762","161.22556"
"71.00000","1.18132","594.11768","1.22327","0.08625","0.00767","162.03459"
"71.50000","1.18968","597.08844","1.23150","0.09448","0.00773","162.84482"
"72.00000","1.19783","599.86066","1.23952","0.10250","0.00778","163.60089"
"72.50000","1.20653","603.08380","1.24808","0.11105","0.00783","164.47993"
"73.00000","1.21444","605.61713","1.25588","0.11885","0.00788","165.17085"
"73.50000","1.22308","608.72034","1.26438","0.12735","0.00793","166.01720"
"74.00000","1.23121","611.47278","1.27238","0.13535","0.00798","166.76788"
"74.50000","1.23994","614.43945","1.28098","0.14395","0.00804","167.57698"
"75.00000","1.24787","616.98694","1.28879","0.15177","0.00808","168.27176"
"75.50000","1.25632","619.84583","1.29712","0.16009","0.00814","169.05147"
"76.00000","1.26470","622.56909","1.30538","0.16835","0.00819","169.79419"
"76.50000","1.27293","625.13580","1.31349","0.17646","0.00824","170.49422"
"77.00000","1.28132","627.80701","1.32176","0.18473","0.00829","171.22273"
"77.50000","1.28950","630.35876","1.32983","0.19280","0.00834","171.91869"
"78.00000","1.29824","633.43842","1.33843","0.20140","0.00840","172.75861"
"78.50000","1.30609","635.44043","1.34619","0.20916","0.00844","173.30461"
"79.00000","1.31480","638.47729","1.35477","0.21774","0.00850","174.13286"
"79.50000","1.32287","640.80127","1.36273","0.22570","0.00855","174.76668"
"80.00000","1.33159","643.64661","1.37132","0.23429","0.00860","175.54269"
"80.50000","1.33954","645.97620","1.37917","0.24214","0.00865","176.17805"
"81.00000","1.34802","648.66327","1.38752","0.25050","0.00870","176.91090"
"81.50000","1.35636","651.08496","1.39576","0.25874","0.00876","177.57137"
"82.00000","1.36450","653.28986","1.40380","0.26677","0.00881","178.17271"
"82.50000","1.37302","655.83563","1.41221","0.27518","0.00886","178.86703"
"83.00000","1.38111","658.21936","1.42019","0.28316","0.00891","179.51715"
"83.50000","1.38991","660.87872","1.42888","0.29185","0.00896","180.24243"
"84.00000","1.39778","662.73480","1.43666","0.29964","0.00901","180.74864"
"84.50000","1.40653","665.46619","1.44528","0.30826","0.00907","181.49358"
"85.00000","1.41456","667.61890","1.45322","0.31619","0.00912","182.08069"
"85.50000","1.42327","670.17639","1.46181","0.32479","0.00917","182.77820"
"86.00000","1.43129","672.24805","1.46975","0.33272","0.00922","183.34322"
"86.50000","1.43961","674.56097","1.47796","0.34094","0.00927","183.97401"
"87.00000","1.44807","676.79688","1.48632","0.34930","0.00932","184.58382"
"87.50000","1.45613","678.84979","1.49429","0.35726","0.00937","185.14371"
"88.00000","1.46465","681.17023","1.50271","0.36568","0.00943","185.77657"
"88.50000","1.47281","683.30060","1.51077","0.37374","0.00948","186.35759"
"89.00000","1.48159","685.71747","1.51945","0.38242","0.00953","187.01674"
"89.50000","1.48948","687.57922","1.52725","0.39023","0.00958","187.52451"
"90.00000","1.49815","689.87030","1.53582","0.39879","0.00963","188.14935"
"90.50000","1.50630","691.71497","1.54389","0.40686","0.00969","188.65245"
"91.00000","1.51486","693.91882","1.55235","0.41532","0.00974","189.25351"
"91.50000","1.52291","695.75256","1.56032","0.42329","0.00979","189.75363"
"92.00000","1.53124","697.67310","1.56856","0.43154","0.00984","190.27742"
"92.50000","1.53976","699.83008","1.57699","0.43996","0.00989","190.86569"
"93.00000","1.54776","701.50244","1.58491","0.44788","0.00994","191.32181"
"93.50000","1.55641","703.66327","1.59346","0.45644","0.01000","191.91113"
"94.00000","1.56449","705.38605","1.60146","0.46444","0.01005","192.38098"
"94.50000","1.57331","707.65784","1.61019","0.47316","0.01010","193.00058"
"95.00000","1.58112","709.05707","1.61793","0.48091","0.01015","193.38219"
"95.50000","1.58985","711.16211","1.62657","0.48955","0.01020","193.95630"
"96.00000","1.59794","712.73242","1.63459","0.49756","0.01025","194.38457"
"96.50000","1.60640","714.46021","1.64298","0.50595","0.01031","194.85579"
"97.00000","1.61461","716.09027","1.65111","0.51408","0.01036","195.30037"
"97.50000","1.62285","717.51813","1.65929","0.52226","0.01041","195.68979"
"98.00000","1.63144","719.21472","1.66780","0.53077","0.01046","196.15250"
"98.50000","1.63942","720.46301","1.67572","0.53869","0.01051","196.49295"
"99.00000","1.64818","722.37018","1.68440","0.54737","0.01057","197.01309"
"99.50000","1.65614","723.66101","1.69231","0.55528","0.01062","197.36514"
"100.00000","1.66505","725.65393","1.70112","0.56410","0.01067","197.90868"
"100.50000","1.67289","726.72961","1.70892","0.57189","0.01072","198.20204"
"101.00000","1.68145","728.30731","1.71740","0.58038","0.01077","198.63234"
"101.50000","1.68966","729.72815","1.72555","0.58853","0.01082","199.01984"
"102.00000","1.69799","731.22296","1.73382","0.59679","0.01088","199.42752"
"102.50000","1.70627","732.59229","1.74203","0.60501","0.01093","199.80098"
"103.00000","1.71447","733.89935","1.75017","0.61314","0.01098","200.15746"
"103.50000","1.72314","735.49481","1.75877","0.62175","0.01103","200.59259"
"104.00000","1.73111","736.63501","1.76669","0.62967","0.01108","200.90356"
"104.50000","1.73985","738.33728","1.77536","0.63833","0.01114","201.36783"
"105.00000","1.74790","739.22186","1.78336","0.64634","0.01119","201.60909"
"105.50000","1.75665","740.75781","1.79204","0.65502","0.01124","202.02798"
"106.00000","1.76450","741.73315","1.79985","0.66283","0.01129","202.29399"
"106.50000","1.77303","743.02771","1.80832","0.67130","0.01134","202.64705"
"107.00000","1.78131","744.14539","1.81656","0.67953","0.01140","202.95187"
"107.50000","1.78957","745.25171","1.82478","0.68775","0.01145","203.25360"
"108.00000","1.79798","746.47565","1.83313","0.69611","0.01150","203.58742"
"108.50000","1.80618","747.40790","1.84129","0.70426","0.01155","203.84167"
"109.00000","1.81490","748.85815","1.84995","0.71293","0.01161","204.23720"
"109.50000","1.82273","749.64508","1.85775","0.72072","0.01165","204.45181"
"110.00000","1.83157","751.12762","1.86653","0.72951","0.01171","204.85616"
"110.50000","1.83952","751.87744","1.87444","0.73742","0.01176","205.06065"
"111.00000","1.84827","753.37152","1.88314","0.74611","0.01181","205.46814"
"111.50000","1.85619","753.79535","1.89104","0.75401","0.01186","205.58372"
"112.00000","1.86466","754.88397","1.89946","0.76244","0.01192","205.88063"
"112.50000","1.87301","755.70087","1.90778","0.77075","0.01197","206.10342"
"113.00000","1.88120","756.35266","1.91594","0.77891","0.01202","206.28119"
"113.50000","1.88972","757.06451","1.92443","0.78741","0.01207","206.47533"
"114.00000","1.89777","757.26831","1.93248","0.79545","0.01212","206.53091"
"114.50000","1.90658","758.00067","1.94125","0.80423","0.01218","206.73065"
"115.00000","1.91445","757.94763","1.94913","0.81210","0.01223","206.71619"
"115.50000","1.92320","758.67188","1.95784","0.82081","0.01228","206.91371"
"116.00000","1.93125","758.59979","1.96589","0.82887","0.01233","206.89404"
"116.50000","1.93991","758.82135","1.97455","0.83752","0.01239","206.95448"
"117.00000","1.94789","758.29926","1.98255","0.84553","0.01244","206.81209"
"117.50000","1.95623","757.87653","1.99091","0.85389","0.01249","206.69679"
"118.00000","1.96473","757.25995","1.99943","0.86241","0.01254","206.52863"
"118.50000","1.97288","756.08685","2.00763","0.87060","0.01259","206.20869"
"119.00000","1.98141","755.28601","2.01619","0.87917","0.01265","205.99028"
"119.50000","1.98948","754.11859","2.02431","0.88729","0.01270","205.67189"
"120.00000","1.99824","753.39996","2.03311","0.89608","0.01275","205.47589"
"120.50000","2.00607","751.99213","2.04100","0.90397","0.01280","205.09193"
"121.00000","2.01480","751.49670","2.04974","0.91272","0.01286","204.95682"
"121.50000","2.02289","750.62903","2.05787","0.92085","0.01291","204.72017"
"122.00000","2.03149","750.73682","2.06647","0.92944","0.01296","204.74957"
"122.50000","2.03957","750.26343","2.07457","0.93754","0.01301","204.62047"
"123.00000","2.04798","750.12903","2.08298","0.94595","0.01307","204.58380"
"123.50000","2.05647","750.32886","2.09146","0.95444","0.01312","204.63831"
"124.00000","2.06444","750.29834","2.09944","0.96241","0.01317","204.62999"
"124.50000","2.07311","750.57733","2.10809","0.97106","0.01322","204.70607"
"125.00000","2.08110","750.60712","2.11608","0.97906","0.01327","204.71420"
"125.50000","2.08993","751.05963","2.12489","0.98787","0.01333","204.83762"
"126.00000","2.09779","750.75806","2.13276","0.99574","0.01338","204.75536"
"126.50000","2.10651","751.26892","2.14147","1.00444","0.01343","204.89468"
"127.00000","2.11459","751.46851","2.14953","1.01251","0.01348","204.94913"
"127.50000","2.12310","752.06647","2.15802","1.02099","0.01354","205.11221"
"128.00000","2.13128","752.55139","2.16618","1.02915","0.01359","205.24446"
"128.50000","2.13952","753.02911","2.17440","1.03737","0.01364","205.37476"
"129.00000","2.14810","753.75659","2.18295","1.04592","0.01369","205.57315"
"129.50000","2.15610","754.14899","2.19093","1.05391","0.01374","205.68018"
"130.00000","2.16477","754.96307","2.19957","1.06254","0.01380","205.90221"
"130.50000","2.17283","755.31000","2.20761","1.07059","0.01385","205.99683"
"131.00000","2.18166","756.01660","2.21641","1.07939","0.01390","206.18953"
"131.50000","2.18950","756.15833","2.22425","1.08723","0.01395","206.22818"
"132.00000","2.19808","756.60889","2.23281","1.09579","0.01401","206.35107"
"132.50000","2.20633","754.23328","2.24116","1.10414","0.01406","205.70317"
"133.00000","2.21475","754.11371","2.24959","1.11256","0.01411","205.67055"
"133.50000","2.22296","754.00140","2.25780","1.12077","0.01416","205.63992"
"134.00000","2.23116","754.02118","2.26600","1.12898","0.01421","205.64532"
"134.50000","2.23979","754.50891","2.27461","1.13758","0.01427","205.77834"
"135.00000","2.24771","754.33569","2.28254","1.14551","0.01432","205.73109"
"135.50000","2.25643","754.73285","2.29124","1.15421","0.01437","205.83942"
"136.00000","2.26446","754.86761","2.29927","1.16224","0.01442","205.87617"
"136.50000","2.27332","755.59741","2.30809","1.17107","0.01448","206.07521"
"137.00000","2.28118","755.31702","2.31597","1.17894","0.01453","205.99873"
"137.50000","2.28982","755.84070","2.32458","1.18755","0.01458","206.14156"
"138.00000","2.29802","755.84821","2.33279","1.19576","0.01463","206.14360"
"138.50000","2.30629","755.68402","2.34106","1.20403","0.01469","206.09883"
"139.00000","2.31466","755.15045","2.34945","1.21242","0.01474","205.95331"
"139.50000","2.32281","754.49542","2.35763","1.22060","0.01479","205.77466"
"140.00000","2.33151","754.89117","2.36631","1.22928","0.01484","205.88260"
"140.50000","2.33941","754.60706","2.37422","1.23720","0.01489","205.80510"
"141.00000","2.34821","755.16840","2.38300","1.24598","0.01495","205.95821"
"141.50000","2.35615","755.14789","2.39094","1.25391","0.01500","205.95261"
"142.00000","2.36499","755.76019","2.39976","1.26273","0.01505","206.11960"
"142.50000","2.37289","755.75439","2.40766","1.27064","0.01510","206.11803"
"143.00000","2.38135","755.61902","2.41612","1.27909","0.01516","206.08110"
"143.50000","2.38964","755.55164","2.42442","1.28739","0.01521","206.06273"
"144.00000","2.39784","755.66302","2.43261","1.29559","0.01526","206.09309"
"144.50000","2.40632","755.72687","2.44108","1.30406","0.01531","206.11052"
"145.00000","2.41447","755.74408","2.44924","1.31221","0.01536","206.11520"
"145.50000","2.42324","756.17462","2.45799","1.32097","0.01542","206.23264"
"146.00000","2.43114","756.04596","2.46589","1.32886","0.01547","206.19754"
"146.50000","2.43983","756.41681","2.47456","1.33754","0.01552","206.29868"
"147.00000","2.44792","756.15558","2.48267","1.34565","0.01557","206.22743"
"147.50000","2.45666","756.45807","2.49140","1.35437","0.01563","206.30994"
"148.00000","2.46457","755.92456","2.49933","1.36230","0.01568","206.16443"
"148.50000","2.47295","755.95734","2.50771","1.37069","0.01573","206.17337"
"149.00000","2.48136","755.92340","2.51612","1.37910","0.01578","206.16411"
"149.50000","2.48949","756.04840","2.52424","1.38722","0.01583","206.19821"
"150.00000","2.49803","756.43298","2.53277","1.39575","0.01589","206.30309"
"150.50000","2.50612","756.48285","2.54085","1.40383","0.01594","206.31670"
"151.00000","2.51494","757.01263","2.54966","1.41263","0.01599","206.46118"
"151.50000","2.52279","756.80261","2.55751","1.42049","0.01604","206.40390"
"152.00000","2.53156","757.21948","2.56626","1.42924","0.01610","206.51759"
"152.50000","2.53957","757.02179","2.57429","1.43726","0.01615","206.46368"
"153.00000","2.54820","757.45538","2.58290","1.44587","0.01620","206.58194"
"153.50000","2.55623","757.34009","2.59093","1.45391","0.01625","206.55049"
"154.00000","2.56460","757.37006","2.59930","1.46228","0.01631","206.55865"
"154.50000","2.57306","757.52869","2.60775","1.47072","0.01636","206.60193"
"155.00000","2.58112","757.33301","2.61582","1.47879","0.01641","206.54855"
"155.50000","2.58978","757.54987","2.62447","1.48745","0.01646","206.60770"
"156.00000","2.59778","757.25555","2.63248","1.49546","0.01651","206.52744"
"156.50000","2.60664","757.64850","2.64133","1.50430","0.01657","206.63460"
"157.00000","2.61449","757.21429","2.64919","1.51217","0.01662","206.51617"
"157.50000","2.62316","757.45062","2.65786","1.52083","0.01667","206.58063"
"158.00000","2.63124","757.06891","2.66595","1.52892","0.01672","206.47653"
"158.50000","2.63979","757.16113","2.67449","1.53747","0.01678","206.50168"
"159.00000","2.64794","756.70245","2.68267","1.54565","0.01683","206.37659"
"159.50000","2.65622","756.27930","2.69097","1.55394","0.01688","206.26118"
"160.00000","2.66480","755.73309","2.69957","1.56254","0.01693","206.11221"
"160.50000","2.67281","754.55432","2.70763","1.57061","0.01699","205.79073"
"161.00000","2.68144","753.18781","2.71631","1.57928","0.01704","205.41803"
"161.50000","2.68953","750.47784","2.72452","1.58749","0.01709","204.67894"
"162.00000","2.69830","747.47125","2.73341","1.59639","0.01715","203.85895"
"162.50000","2.70615","743.27521","2.74144","1.60441","0.01720","202.71455"
"163.00000","2.71472","738.91034","2.75020","1.61317","0.01725","201.52411"
"163.50000","2.72295","731.02966","2.75879","1.62176","0.01731","199.37480"
"164.00000","2.73141","716.53198","2.76789","1.63087","0.01736","195.42084"
"164.50000","2.73960","701.28589","2.77676","1.63974","0.01742","191.26274"
"165.00000","2.74785","684.29694","2.78576","1.64874","0.01748","186.62932"
"165.50000","2.75648","678.37268","2.79466","1.65764","0.01753","185.01360"
"166.00000","2.76445","675.16388","2.80278","1.66575","0.01758","184.13844"
"166.50000","2.77315","673.39911","2.81155","1.67453","0.01764","183.65714"
"167.00000","2.78117","672.02478","2.81963","1.68261","0.01769","183.28232"
"167.50000","2.78995","671.89722","2.82842","1.69139","0.01774","183.24753"
"168.00000","2.79785","671.28625","2.83635","1.69932","0.01779","183.08090"
"168.50000","2.80647","671.64966","2.84495","1.70792","0.01785","183.18001"
"169.00000","2.81464","671.80933","2.85312","1.71609","0.01790","183.22356"
"169.50000","2.82297","672.14075","2.86143","1.72440","0.01795","183.31395"
"170.00000","2.83132","672.70270","2.86975","1.73273","0.01800","183.46721"
"170.50000","2.83947","672.85590","2.87790","1.74088","0.01805","183.50899"
"171.00000","2.84813","673.72339","2.88652","1.74949","0.01811","183.74557"
"171.50000","2.85609","673.92078","2.89447","1.75744","0.01816","183.79942"
"172.00000","2.86481","674.84998","2.90315","1.76612","0.01821","184.05284"
"172.50000","2.87283","675.27930","2.91115","1.77412","0.01826","184.16992"
"173.00000","2.88164","676.41400","2.91991","1.78288","0.01832","184.47940"
"173.50000","2.88956","676.78735","2.92781","1.79078","0.01837","184.58122"
"174.00000","2.89802","677.62830","2.93624","1.79921","0.01842","184.81058"
"174.50000","2.90638","678.35101","2.94456","1.80754","0.01847","185.00768"
"175.00000","2.91464","678.91113","2.95280","1.81577","0.01852","185.16045"
"175.50000","2.92300","679.53357","2.96113","1.82410","0.01858","185.33020"
"176.00000","2.93119","680.15112","2.96930","1.83227","0.01863","185.49863"
"176.50000","2.93986","681.06805","2.97793","1.84090","0.01868","185.74870"
"177.00000","2.94777","681.47070","2.98581","1.84878","0.01873","185.85852"
"177.50000","2.95642","682.29462","2.99443","1.85740","0.01878","186.08322"
"178.00000","2.96454","682.89648","3.00252","1.86549","0.01884","186.24738"
"178.50000","2.97329","683.82751","3.01123","1.87421","0.01889","186.50130"
"179.00000","2.98119","684.27856","3.01911","1.88209","0.01894","186.62431"
"179.50000","2.98969","684.90930","3.02758","1.89055","0.01899","186.79633"
"180.00000","2.99806","685.60889","3.03592","1.89889","0.01904","186.98714"
"180.50000","3.00622","686.10980","3.04406","1.90704","0.01910","187.12375"
"181.00000","3.01467","686.66229","3.05248","1.91546","0.01915","187.27443"
"181.50000","3.02283","687.28052","3.06062","1.92359","0.01920","187.44304"
"182.00000","3.03156","688.09467","3.06931","1.93228","0.01925","187.66508"
"182.50000","3.03946","688.50830","3.07719","1.94016","0.01930","187.77789"
"183.00000","3.04823","689.29919","3.08593","1.94890","0.01936","187.99359"
"183.50000","3.05623","689.51184","3.09391","1.95689","0.01941","188.05159"
"184.00000","3.06491","690.53308","3.10255","1.96552","0.01946","188.33011"
"184.50000","3.07290","690.67273","3.11054","1.97351","0.01951","188.36819"
"185.00000","3.08128","691.44757","3.11888","1.98185","0.01957","188.57953"
"185.50000","3.08968","691.92151","3.12726","1.99024","0.01962","188.70879"
"186.00000","3.09780","692.32025","3.13536","1.99834","0.01967","188.81754"
"186.50000","3.10636","692.70886","3.14391","2.00688","0.01972","188.92352"
"187.00000","3.11444","692.79315","3.15198","2.01495","0.01977","188.94650"
"187.50000","3.12326","692.80249","3.16080","2.02377","0.01983","188.94905"
"188.00000","3.13116","692.54095","3.16871","2.03168","0.01988","188.87773"
"188.50000","3.13980","692.60803","3.17735","2.04032","0.01993","188.89601"
"189.00000","3.14794","692.55835","3.18549","2.04846","0.01998","188.88246"
"189.50000","3.15654","693.08270","3.19407","2.05704","0.02004","189.02548"
"190.00000","3.16460","693.19946","3.20212","2.06510","0.02009","189.05733"
"190.50000","3.17295","693.44366","3.21046","2.07344","0.02014","189.12392"
"191.00000","3.18142","692.10754","3.21899","2.08197","0.02019","188.75952"
"191.50000","3.18944","692.02924","3.22702","2.08999","0.02024","188.73816"
"192.00000","3.19802","692.31952","3.23558","2.09856","0.02030","188.81734"
"192.50000","3.20616","692.34790","3.24372","2.10670","0.02035","188.82507"
"193.00000","3.21497","692.98676","3.25250","2.11548","0.02040","188.99931"
"193.50000","3.22280","692.97314","3.26033","2.12330","0.02045","188.99559"
"194.00000","3.23153","693.59302","3.26903","2.13200","0.02051","189.16466"
"194.50000","3.23962","693.77960","3.27711","2.14009","0.02056","189.21555"
"195.00000","3.24812","694.38123","3.28559","2.14856","0.02061","189.37962"
"195.50000","3.25622","694.49817","3.29369","2.15666","0.02066","189.41151"
"196.00000","3.26458","694.91888","3.30202","2.16500","0.02071","189.52626"
"196.50000","3.27311","695.40839","3.31053","2.17351","0.02077","189.65976"
"197.00000","3.28110","695.55511","3.31851","2.18149","0.02082","189.69978"
"197.50000","3.28983","696.17450","3.32722","2.19020","0.02087","189.86871"
"198.00000","3.29782","696.19800","3.33521","2.19818","0.02092","189.87512"
"198.50000","3.30672","696.94617","3.34407","2.20705","0.02098","190.07916"
"199.00000","3.31452","696.99585","3.35187","2.21484","0.02103","190.09271"
"199.50000","3.32314","697.59235","3.36046","2.22344","0.02108","190.25540"
"200.00000","3.33126","697.91425","3.36857","2.23155","0.02113","190.34319"
"200.50000","3.33967","698.29913","3.37697","2.23994","0.02118","190.44817"
"201.00000","3.34796","698.18970","3.38526","2.24823","0.02124","190.41832"
"201.50000","3.35614","698.04828","3.39345","2.25642","0.02129","190.37975"
"202.00000","3.36479","698.11694","3.40209","2.26507","0.02134","190.39847"
"202.50000","3.37277","697.66461","3.41009","2.27306","0.02139","190.27510"
"203.00000","3.38145","697.82611","3.41877","2.28174","0.02145","190.31915"
"203.50000","3.38951","697.79779","3.42682","2.28980","0.02150","190.31143"
"204.00000","3.39833","698.49725","3.43562","2.29859","0.02155","190.50220"
"204.50000","3.40620","698.28888","3.44349","2.30646","0.02160","190.44536"
"205.00000","3.41474","698.61487","3.45202","2.31500","0.02166","190.53427"
"205.50000","3.42300","698.62146","3.46028","2.32325","0.02171","190.53607"
"206.00000","3.43131","698.99487","3.46857","2.33155","0.02176","190.63791"
"206.50000","3.43965","699.15570","3.47690","2.33988","0.02181","190.68178"
"207.00000","3.44788","699.52563","3.48512","2.34810","0.02186","190.78267"
"207.50000","3.45652","699.79272","3.49374","2.35672","0.02192","190.85551"
"208.00000","3.46443","699.83875","3.50165","2.36463","0.02197","190.86806"
"208.50000","3.47318","700.43927","3.51038","2.37336","0.02202","191.03185"
"209.00000","3.48121","700.40576","3.51841","2.38138","0.02207","191.02271"
"209.50000","3.48997","700.94452","3.52715","2.39012","0.02213","191.16965"
"210.00000","3.49782","700.69519","3.53501","2.39798","0.02218","191.10164"
"210.50000","3.50638","700.97247","3.54355","2.40653","0.02223","191.17726"
"211.00000","3.51467","701.06207","3.55185","2.41482","0.02228","191.20171"
"211.50000","3.52288","701.18549","3.56004","2.42302","0.02233","191.23537"
"212.00000","3.53136","701.27582","3.56853","2.43150","0.02239","191.25999"
"212.50000","3.53949","701.45593","3.57664","2.43961","0.02244","191.30911"
"213.00000","3.54828","701.71771","3.58542","2.44840","0.02249","191.38051"
"213.50000","3.55612","701.61761","3.59327","2.45624","0.02254","191.35321"
"214.00000","3.56488","701.79218","3.60202","2.46499","0.02260","191.40082"
"214.50000","3.57284","701.41943","3.60999","2.47297","0.02265","191.29916"
"215.00000","3.58164","701.77441","3.61878","2.48175","0.02270","191.39598"
"215.50000","3.58956","701.52869","3.62671","2.48968","0.02275","191.32896"
"216.00000","3.59793","701.71582","3.63507","2.49805","0.02280","191.38000"
"216.50000","3.60635","702.02148","3.64348","2.50645","0.02286","191.46336"
"217.00000","3.61451","702.14697","3.65163","2.51461","0.02291","191.49759"
"217.50000","3.62302","702.24170","3.66014","2.52311","0.02296","191.52342"
"218.00000","3.63114","702.20953","3.66826","2.53123","0.02301","191.51465"
"218.50000","3.63991","702.51050","3.67701","2.53999","0.02307","191.59674"
"219.00000","3.64778","702.35846","3.68490","2.54787","0.02312","191.55527"
"219.50000","3.65645","702.06708","3.69358","2.55655","0.02317","191.47580"
"220.00000","3.66459","701.41272","3.70175","2.56472","0.02322","191.29733"
"220.50000","3.67328","701.37067","3.71044","2.57341","0.02328","191.28586"
"221.00000","3.68125","700.33844","3.71845","2.58142","0.02333","191.00435"
"221.50000","3.68963","699.51270","3.72687","2.58985","0.02338","190.77914"
"222.00000","3.69807","699.06879","3.73533","2.59830","0.02343","190.65807"
"222.50000","3.70616","698.71399","3.74344","2.60641","0.02348","190.56131"
"223.00000","3.71475","698.64325","3.75202","2.61500","0.02354","190.54201"
"223.50000","3.72284","698.34552","3.76013","2.62310","0.02359","190.46082"
"224.00000","3.73164","698.66034","3.76892","2.63189","0.02364","190.54668"
"224.50000","3.73942","697.76929","3.77674","2.63971","0.02369","190.30365"
"225.00000","3.74816","697.58887","3.78549","2.64846","0.02375","190.25446"
"225.50000","3.75624","697.08032","3.79359","2.65657","0.02380","190.11575"
"226.00000","3.76479","696.87177","3.80215","2.66512","0.02385","190.05887"
"226.50000","3.77291","696.25934","3.81030","2.67327","0.02390","189.89185"
"227.00000","3.78125","695.32153","3.81867","2.68165","0.02396","189.63608"
"227.50000","3.78979","692.72949","3.82734","2.69031","0.02401","188.92914"
"228.00000","3.79778","687.07635","3.83558","2.69855","0.02406","187.38736"
"228.50000","3.80647","685.66815","3.84433","2.70731","0.02412","187.00330"
"229.00000","3.81444","684.61432","3.85234","2.71532","0.02417","186.71588"
"229.50000","3.82334","684.27332","3.86126","2.72423","0.02422","186.62288"
"230.00000","3.83115","683.64392","3.86910","2.73208","0.02427","186.45122"
"230.50000","3.83979","683.64911","3.87774","2.74071","0.02433","186.45264"
"231.00000","3.84796","683.53357","3.88592","2.74889","0.02438","186.42113"
"231.50000","3.85641","683.64764","3.89436","2.75733","0.02443","186.45224"
"232.00000","3.86460","683.61322","3.90255","2.76553","0.02448","186.44286"
"232.50000","3.87283","683.75366","3.91078","2.77375","0.02453","186.48116"
"233.00000","3.88145","683.86145","3.91939","2.78237","0.02459","186.51054"
"233.50000","3.88942","683.83441","3.92736","2.79033","0.02464","186.50317"
"234.00000","3.89804","683.94971","3.93597","2.79895","0.02469","186.53462"
"234.50000","3.90616","683.20691","3.94413","2.80710","0.02474","186.33203"
"235.00000","3.91503","683.53351","3.95298","2.81595","0.02480","186.42111"
"235.50000","3.92286","683.29205","3.96082","2.82379","0.02485","186.35526"
"236.00000","3.93145","683.45203","3.96940","2.83238","0.02490","186.39890"
"236.50000","3.93969","683.53424","3.97764","2.84061","0.02495","186.42131"
"237.00000","3.94802","683.60376","3.98597","2.84894","0.02500","186.44028"
"237.50000","3.95630","683.78302","3.99424","2.85721","0.02506","186.48917"
"238.00000","3.96453","683.85968","4.00247","2.86544","0.02511","186.51007"
"238.50000","3.97319","684.21680","4.01112","2.87409","0.02516","186.60747"
"239.00000","3.98106","684.02014","4.01899","2.88196","0.02521","186.55383"
"239.50000","3.98981","684.44067","4.02772","2.89070","0.02527","186.66852"
"240.00000","3.99782","684.30597","4.03574","2.89871","0.02532","186.63179"
"240.50000","4.00660","684.61194","4.04451","2.90748","0.02537","186.71523"
"241.00000","4.01451","684.42792","4.05242","2.91540","0.02542","186.66504"
"241.50000","4.02310","684.24292","4.06102","2.92399","0.02548","186.61459"
"242.00000","4.03135","683.78461","4.06929","2.93226","0.02553","186.48959"
"242.50000","4.03958","683.07404","4.07755","2.94052","0.02558","186.29579"
"243.00000","4.04802","682.35248","4.08603","2.94900","0.02563","186.09900"
"243.50000","4.05611","681.40997","4.09416","2.95714","0.02568","185.84195"
"244.00000","4.06488","680.79218","4.10295","2.96592","0.02574","185.67346"
"244.50000","4.07278","680.10632","4.11089","2.97386","0.02579","185.48640"
"245.00000","4.08153","679.84076","4.11964","2.98262","0.02584","185.41399"
"245.50000","4.08956","679.34650","4.12770","2.99067","0.02589","185.27917"
"246.00000","4.09833","679.42419","4.13647","2.99944","0.02595","185.30037"
"246.50000","4.10624","679.02502","4.14439","3.00736","0.02600","185.19150"
"247.00000","4.11464","678.94409","4.15279","3.01577","0.02605","185.16943"
"247.50000","4.12304","678.84924","4.16120","3.02417","0.02610","185.14357"
"248.00000","4.13117","678.74915","4.16933","3.03231","0.02615","185.11626"
"248.50000","4.13963","678.70508","4.17780","3.04077","0.02621","185.10425"
"249.00000","4.14779","678.57233","4.18597","3.04894","0.02626","185.06804"
"249.50000","4.15660","678.81049","4.19477","3.05774","0.02631","185.13300"
"250.00000","4.16445","678.53345","4.20263","3.06560","0.02636","185.05743"
"250.50000","4.17314","678.64948","4.21131","3.07429","0.02642","185.08908"
"251.00000","4.18126","678.34460","4.21944","3.08242","0.02647","185.00594"
"251.50000","4.18995","678.26544","4.22813","3.09111","0.02652","184.98434"
"252.00000","4.19790","677.55408","4.23612","3.09909","0.02657","184.79033"
"252.50000","4.20632","677.45557","4.24454","3.10751","0.02663","184.76346"
"253.00000","4.21474","677.23730","4.25297","3.11595","0.02668","184.70393"
"253.50000","4.22278","676.95758","4.26103","3.12400","0.02673","184.62766"
"254.00000","4.23137","676.83081","4.26962","3.13259","0.02678","184.59308"
"254.50000","4.23945","676.43591","4.27772","3.14069","0.02683","184.48537"
"255.00000","4.24825","676.41510","4.28652","3.14950","0.02689","184.47969"
"255.50000","4.25611","675.77899","4.29441","3.15738","0.02694","184.30621"
"256.00000","4.26489","675.92511","4.30318","3.16615","0.02699","184.34605"
"256.50000","4.27292","675.35303","4.31124","3.17421","0.02705","184.19003"
"257.00000","4.28152","675.29889","4.31984","3.18282","0.02710","184.17528"
"257.50000","4.28962","674.78467","4.32796","3.19093","0.02715","184.03502"
"258.00000","4.29789","674.63824","4.33624","3.19921","0.02720","183.99509"
"258.50000","4.30639","674.53265","4.34475","3.20772","0.02726","183.96629"
"259.00000","4.31448","674.14117","4.35285","3.21582","0.02731","183.85953"
"259.50000","4.32311","674.09406","4.36149","3.22446","0.02736","183.84668"
"260.00000","4.33116","673.79114","4.36955","3.23252","0.02741","183.76405"
"260.50000","4.34000","673.79144","4.37839","3.24136","0.02747","183.76414"
"261.00000","4.34782","673.22180","4.38623","3.24921","0.02752","183.60878"
"261.50000","4.35641","672.94861","4.39483","3.25781","0.02757","183.53427"
"262.00000","4.36462","672.54620","4.40306","3.26603","0.02762","183.42453"
"262.50000","4.37309","672.46039","4.41154","3.27451","0.02767","183.40112"
"263.00000","4.38124","672.00226","4.41971","3.28268","0.02773","183.27617"
"263.50000","4.38951","671.61481","4.42800","3.29097","0.02778","183.17050"
"264.00000","4.39812","671.41956","4.43661","3.29959","0.02783","183.11725"
"264.50000","4.40612","670.87177","4.44464","3.30762","0.02788","182.96785"
"265.00000","4.41476","670.73773","4.45328","3.31625","0.02794","182.93130"
"265.50000","4.42285","670.19049","4.46140","3.32438","0.02799","182.78204"
"266.00000","4.43169","670.28314","4.47024","3.33321","0.02804","182.80731"
"266.50000","4.43949","669.38550","4.47808","3.34105","0.02809","182.56250"
"267.00000","4.44810","669.01233","4.48670","3.34967","0.02815","182.46072"
"267.50000","4.45629","668.35138","4.49492","3.35790","0.02820","182.28047"
"268.00000","4.46468","667.96008","4.50333","3.36630","0.02825","182.17375"
"268.50000","4.47294","667.08911","4.51162","3.37459","0.02830","181.93620"
"269.00000","4.48119","666.55389","4.51990","3.38287","0.02835","181.79024"
"269.50000","4.48980","665.96313","4.52854","3.39151","0.02841","181.62912"
"270.00000","4.49773","662.89801","4.53661","3.39958","0.02846","180.79317"
"270.50000","4.50648","661.00281","4.54544","3.40841","0.02851","180.27628"
"271.00000","4.51447","658.39777","4.55355","3.41652","0.02857","179.56580"
"271.50000","4.52331","656.19482","4.56248","3.42545","0.02862","178.96500"
"272.00000","4.53120","652.25110","4.57054","3.43352","0.02867","177.88942"
"272.50000","4.53972","647.60291","4.57927","3.44225","0.02873","176.62170"
"273.00000","4.54798","642.85522","4.58775","3.45072","0.02878","175.32686"
"273.50000","4.55632","638.70758","4.59627","3.45924","0.02883","174.19566"
"274.00000","4.56469","633.89117","4.60486","3.46784","0.02889","172.88208"
"274.50000","4.57283","629.84668","4.61318","3.47615","0.02894","171.77902"
"275.00000","4.58151","626.45312","4.62202","3.48499","0.02899","170.85349"
"275.50000","4.58942","623.24799","4.63006","3.49304","0.02905","169.97935"
"276.00000","4.59808","621.13715","4.63882","3.50179","0.02910","169.40366"
"276.50000","4.60620","618.80981","4.64705","3.51002","0.02915","168.76892"
"277.00000","4.61496","617.43280","4.65586","3.51884","0.02921","168.39337"
"277.50000","4.62285","615.79828","4.66383","3.52681","0.02926","167.94759"
"278.00000","4.63133","614.50281","4.67236","3.53534","0.02931","167.59427"
"278.50000","4.63971","613.26062","4.68080","3.54378","0.02936","167.25548"
"279.00000","4.64793","611.76776","4.68909","3.55206","0.02942","166.84833"
"279.50000","4.65632","608.81885","4.69761","3.56058","0.02947","166.04407"
"280.00000","4.66451","600.45978","4.70617","3.56915","0.02952","163.76428"
"280.50000","4.67324","592.51428","4.71527","3.57824","0.02958","161.59731"
"281.00000","4.68109","587.92145","4.72333","3.58631","0.02963","160.34470"
"281.50000","4.68982","585.59845","4.73217","3.59514","0.02969","159.71114"
"282.00000","4.69787","584.29663","4.74029","3.60326","0.02974","159.35609"
"282.50000","4.70658","584.01550","4.74901","3.61198","0.02979","159.27942"
"283.00000","4.71452","583.40735","4.75698","3.61995","0.02984","159.11356"
"283.50000","4.72300","583.27325","4.76547","3.62844","0.02989","159.07698"
"284.00000","4.73136","583.11804","4.77383","3.63681","0.02995","159.03465"
"284.50000","4.73951","583.08234","4.78198","3.64496","0.03000","159.02492"
"285.00000","4.74803","583.16895","4.79050","3.65348","0.03005","159.04854"
"285.50000","4.75612","583.08856","4.79860","3.66157","0.03010","159.02661"
"286.00000","4.76490","583.42639","4.80735","3.67033","0.03016","159.11874"
"286.50000","4.77280","583.35889","4.81526","3.67823","0.03021","159.10034"
"287.00000","4.78154","583.87115","4.82398","3.68695","0.03026","159.24005"
"287.50000","4.78956","583.76599","4.83200","3.69498","0.03031","159.21136"
"288.00000","4.79828","584.22351","4.84069","3.70367","0.03037","159.33615"
"288.50000","4.80629","584.18726","4.84871","3.71169","0.03042","159.32626"
"289.00000","4.81461","584.39001","4.85702","3.71999","0.03047","159.38156"
"289.50000","4.82307","584.43567","4.86548","3.72845","0.03052","159.39401"
"290.00000","4.83112","584.62445","4.87352","3.73650","0.03057","159.44550"
"290.50000","4.83966","584.74182","4.88205","3.74503","0.03063","159.47751"
"291.00000","4.84781","584.90259","4.89019","3.75317","0.03068","159.52135"
"291.50000","4.85657","585.24963","4.89894","3.76191","0.03073","159.61600"
"292.00000","4.86446","585.24139","4.90683","3.76981","0.03078","159.61375"
"292.50000","4.87315","585.65350","4.91550","3.77847","0.03084","159.72615"
"293.00000","4.88130","585.62646","4.92365","3.78663","0.03089","159.71878"
"293.50000","4.88983","585.86334","4.93217","3.79515","0.03094","159.78339"
"294.00000","4.89791","585.81573","4.94025","3.80322","0.03099","159.77040"
"294.50000","4.90623","585.77759","4.94857","3.81155","0.03104","159.75999"
"295.00000","4.91475","586.01483","4.95708","3.82006","0.03110","159.82469"
"295.50000","4.92276","585.98315","4.96509","3.82807","0.03115","159.81606"
"296.00000","4.93140","585.97650","4.97373","3.83671","0.03120","159.81424"
"296.50000","4.93949","584.02509","4.98191","3.84489","0.03125","159.28203"
"297.00000","4.94831","584.11157","4.99074","3.85371","0.03131","159.30562"
"297.50000","4.95614","583.90686","4.99857","3.86154","0.03136","159.24979"
"298.00000","4.96486","584.21844","5.00728","3.87025","0.03141","159.33476"
"298.50000","4.97294","584.09460","5.01537","3.87834","0.03146","159.30099"
"299.00000","4.98141","584.34656","5.02382","3.88679","0.03152","159.36971"
"299.50000","4.98959","584.23163","5.03201","3.89499","0.03157","159.33836"
"300.00000","4.99786","584.35004","5.04027","3.90324","0.03162","159.37065"
"300.50000","5.00645","584.44659","5.04885","3.91183","0.03167","159.39699"
"301.00000","5.01442","584.41742","5.05682","3.91980","0.03172","159.38904"
"301.50000","5.02316","584.68469","5.06556","3.92853","0.03178","159.46193"
"302.00000","5.03114","584.73254","5.07354","3.93651","0.03183","159.47498"
"302.11900","5.03338","584.87982","5.07577","3.93874","0.03184","159.51514"