File: compression/3_axis/Specimen_RawData_4.csv
Time,Extension,Load,Compressive stress,Compressive strain (Extension)
(s),(mm),(N),(MPa),(mm/mm)
"0.00000","0.00000","38.47190","0.79165","0.00000"
"0.10000","0.00038","41.51818","0.85433","0.00000"
"0.20000","0.00143","51.89437","1.06784","0.00001"
"0.30000","0.00386","77.33604","1.59136","0.00004"
"0.40000","0.00665","106.76717","2.19697","0.00007"
"0.50000","0.00848","126.24810","2.59784","0.00008"
"0.60000","0.01120","157.10069","3.23270","0.00011"
"0.70000","0.01319","178.57014","3.67448","0.00013"
"0.80000","0.01512","198.85605","4.09191","0.00015"
"0.90000","0.01753","218.96399","4.50567","0.00018"
"1.00000","0.01942","229.18552","4.71600","0.00019"
"1.10000","0.02187","244.66664","5.03456","0.00022"
"1.20000","0.02414","252.22803","5.19015","0.00024"
"1.30000","0.02592","260.75357","5.36559","0.00026"
"1.40000","0.02845","278.58557","5.73252","0.00028"
"1.50000","0.03035","285.90747","5.88318","0.00030"
"1.60000","0.03245","301.09036","6.19561","0.00032"
"1.70000","0.03517","321.50638","6.61571","0.00035"
"1.80000","0.03686","331.05347","6.81216","0.00037"
"1.90000","0.03914","353.21078","7.26810","0.00039"
"2.00000","0.04128","370.89102","7.63191","0.00041"
"2.10000","0.04324","388.31866","7.99052","0.00043"
"2.20000","0.04598","418.33542","8.60818","0.00046"
"2.30000","0.04776","432.51709","8.90000","0.00048"
"2.40000","0.04988","455.65390","9.37610","0.00050"
"2.50000","0.05220","480.79825","9.89350","0.00052"
"2.60000","0.05404","499.11844","10.27048","0.00054"
"2.70000","0.05662","531.14056","10.92940","0.00057"
"2.80000","0.05877","553.06519","11.38055","0.00059"
"2.90000","0.06063","573.15167","11.79387","0.00061"
"3.00000","0.06309","604.08002","12.43029","0.00063"
"3.10000","0.06499","624.67279","12.85404","0.00065"
"3.20000","0.06719","652.50482","13.42674","0.00067"
"3.30000","0.06974","684.48486","14.08480","0.00070"
"3.40000","0.07143","702.83240","14.46235","0.00071"
"3.50000","0.07394","738.39703","15.19417","0.00074"
"3.60000","0.07594","762.35889","15.68724","0.00076"
"3.70000","0.07789","787.32629","16.20100","0.00078"
"3.80000","0.08066","828.21045","17.04228","0.00081"
"3.90000","0.08241","848.37415","17.45719","0.00082"
"4.00000","0.08459","879.89502","18.10580","0.00085"
"4.10000","0.08685","911.11707","18.74827","0.00087"
"4.20000","0.08876","936.05426","19.26141","0.00089"
"4.30000","0.09139","976.48462","20.09335","0.00091"
"4.40000","0.09336","1001.13666","20.60062","0.00093"
"4.50000","0.09530","1028.12476","21.15596","0.00095"
"4.60000","0.09787","1067.64038","21.96908","0.00098"
"4.70000","0.09958","1089.55066","22.41994","0.00100"
"4.80000","0.10190","1126.56982","23.18169","0.00102"
"4.90000","0.10438","1164.46631","23.96149","0.00104"
"5.00000","0.10612","1187.60547","24.43763","0.00106"
"5.10000","0.10863","1228.65845","25.28239","0.00109"
"5.20000","0.11052","1254.75427","25.81937","0.00111"
"5.30000","0.11254","1285.44543","26.45091","0.00113"
"5.40000","0.11529","1331.09900","27.39033","0.00115"
"5.50000","0.11698","1352.86938","27.83831","0.00117"
"5.60000","0.11932","1391.11694","28.62534","0.00119"
"5.70000","0.12153","1424.80530","29.31855","0.00122"
"5.80000","0.12341","1452.23511","29.88298","0.00123"
"5.90000","0.12607","1497.52893","30.81500","0.00126"
"6.00000","0.12798","1524.12390","31.36225","0.00128"
"6.10000","0.12995","1554.07922","31.97865","0.00130"
"6.20000","0.13254","1597.26440","32.86728","0.00133"
"6.30000","0.13426","1620.80139","33.35161","0.00134"
"6.40000","0.13671","1663.37659","34.22769","0.00137"
"6.50000","0.13894","1698.59656","34.95242","0.00139"
"6.60000","0.14075","1725.52576","35.50655","0.00141"
"6.70000","0.14335","1772.13330","36.46560","0.00143"
"6.80000","0.14516","1798.87939","37.01596","0.00145"
"6.90000","0.14725","1833.80884","37.73471","0.00147"
"7.00000","0.15000","1883.53674","38.75797","0.00150"
"7.10000","0.15162","1906.30457","39.22647","0.00152"
"7.20000","0.15400","1950.19043","40.12952","0.00154"
"7.30000","0.15617","1988.24829","40.91265","0.00156"
"7.40000","0.15805","2021.54688","41.59784","0.00158"
"7.50000","0.16078","2077.35718","42.74626","0.00161"
"7.60000","0.16256","2108.08862","43.37863","0.00163"
"7.70000","0.16466","2149.27783","44.22619","0.00165"
"7.80000","0.16714","2199.29175","45.25534","0.00167"
"7.90000","0.16892","2231.58057","45.91975","0.00169"
"8.00000","0.17149","2285.38721","47.02694","0.00171"
"8.10000","0.17352","2323.00122","47.80093","0.00174"
"8.20000","0.17538","2358.08716","48.52291","0.00175"
"8.30000","0.17801","2413.08472","49.65461","0.00178"
"8.40000","0.17986","2447.36694","50.36004","0.00180"
"8.50000","0.18201","2490.59790","51.24961","0.00182"
"8.60000","0.18458","2543.70801","52.34247","0.00185"
"8.70000","0.18625","2573.64258","52.95844","0.00186"
"8.80000","0.18871","2626.04199","54.03667","0.00189"
"8.90000","0.19074","2665.44751","54.84753","0.00191"
"9.00000","0.19273","2705.04663","55.66237","0.00193"
"9.10000","0.19552","2766.38281","56.92450","0.00196"
"9.20000","0.19717","2796.17114","57.53746","0.00197"
"9.30000","0.19935","2842.91016","58.49922","0.00199"
"9.40000","0.20179","2895.49634","59.58130","0.00202"
"9.50000","0.20357","2930.55786","60.30277","0.00204"
"9.60000","0.20620","2990.64087","61.53911","0.00206"
"9.70000","0.20816","3030.11401","62.35136","0.00208"
"9.80000","0.21013","3071.29883","63.19883","0.00210"
"9.90000","0.21265","3128.13965","64.36845","0.00213"
"10.00000","0.21448","3165.07031","65.12839","0.00214"
"10.10000","0.21681","3217.59253","66.20915","0.00217"
"10.20000","0.21920","3270.46484","67.29711","0.00219"
"10.30000","0.22094","3305.38867","68.01575","0.00221"
"10.40000","0.22341","3363.02344","69.20171","0.00223"
"10.50000","0.22541","3404.98462","70.06516","0.00225"
"10.60000","0.22741","3448.53589","70.96133","0.00227"
"10.70000","0.23015","3513.63379","72.30086","0.00230"
"10.80000","0.23184","3546.81567","72.98365","0.00232"
"10.90000","0.23405","3597.28906","74.02225","0.00234"
"11.00000","0.23626","3646.22485","75.02921","0.00236"
"11.10000","0.23824","3688.43750","75.89783","0.00238"
"11.20000","0.24097","3754.20898","77.25123","0.00241"
"11.30000","0.24282","3791.33521","78.01518","0.00243"
"11.40000","0.24476","3832.79370","78.86829","0.00245"
"11.50000","0.24730","3892.23315","80.09138","0.00247"
"11.60000","0.24910","3928.12573","80.82996","0.00249"
"11.70000","0.25152","3985.05859","82.00147","0.00252"
"11.80000","0.25380","4034.51611","83.01917","0.00254"
"11.90000","0.25565","4072.09180","83.79238","0.00256"
"12.00000","0.25809","4128.10303","84.94493","0.00258"
"12.10000","0.25999","4166.76074","85.74040","0.00260"
"12.20000","0.26219","4215.66504","86.74672","0.00262"
"12.30000","0.26478","4275.05127","87.96872","0.00265"
"12.40000","0.26646","4306.29834","88.61170","0.00266"
"12.50000","0.26880","4359.61865","89.70889","0.00269"
"12.60000","0.27100","4406.50000","90.67358","0.00271"
"12.70000","0.27284","4443.29980","91.43081","0.00273"
"12.80000","0.27571","4512.72949","92.85948","0.00276"
"12.90000","0.27746","4544.93604","93.52220","0.00277"
"13.00000","0.27947","4587.40527","94.39610","0.00279"
"13.10000","0.28186","4640.86816","95.49622","0.00282"
"13.20000","0.28374","4678.05713","96.26147","0.00284"
"13.30000","0.28634","4739.26611","97.52098","0.00286"
"13.40000","0.28839","4780.24316","98.36417","0.00288"
"13.50000","0.29027","4817.82764","99.13756","0.00290"
"13.60000","0.29279","4875.20654","100.31826","0.00293"
"13.70000","0.29462","4910.16699","101.03764","0.00295"
"13.80000","0.29689","4960.38135","102.07092","0.00297"
"13.90000","0.29941","5015.79199","103.21111","0.00299"
"14.00000","0.30112","5046.85547","103.85032","0.00301"
"14.10000","0.30352","5100.97607","104.96397","0.00304"
"14.20000","0.30559","5142.59326","105.82034","0.00306"
"14.30000","0.30758","5182.79248","106.64752","0.00308"
"14.40000","0.31036","5247.44189","107.97783","0.00310"
"14.50000","0.31200","5274.85303","108.54188","0.00312"
"14.60000","0.31425","5323.84473","109.54999","0.00314"
"14.70000","0.31655","5372.77148","110.55677","0.00317"
"14.80000","0.31838","5407.45020","111.27036","0.00318"
"14.90000","0.32104","5469.64502","112.55016","0.00321"
"15.00000","0.32301","5507.21436","113.32323","0.00323"
"15.10000","0.32499","5547.23242","114.14669","0.00325"
"15.20000","0.32742","5600.56006","115.24403","0.00327"
"15.30000","0.32931","5636.41943","115.98191","0.00329"
"15.40000","0.33168","5689.28906","117.06982","0.00332"
"15.50000","0.33401","5738.34277","118.07921","0.00334"
"15.60000","0.33577","5770.54150","118.74178","0.00336"
"15.70000","0.33832","5829.53564","119.95571","0.00338"
"15.80000","0.34018","5864.02051","120.66531","0.00340"
"15.90000","0.34224","5906.65088","121.54253","0.00342"
"16.00000","0.34496","5969.51025","122.83600","0.00345"
"16.10000","0.34666","5998.53809","123.43331","0.00347"
"16.20000","0.34901","6050.93311","124.51146","0.00349"
"16.30000","0.35116","6094.54590","125.40889","0.00351"
"16.40000","0.35301","6129.69531","126.13216","0.00353"
"16.50000","0.35575","6194.10889","127.45762","0.00356"
"16.60000","0.35762","6228.35742","128.16235","0.00358"
"16.70000","0.35965","6269.98926","129.01903","0.00360"
"16.80000","0.36214","6325.93408","130.17021","0.00362"
"16.90000","0.36395","6359.23535","130.85547","0.00364"
"17.00000","0.36638","6414.64941","131.99573","0.00366"
"17.10000","0.36859","6460.35889","132.93631","0.00369"
"17.20000","0.37036","6493.03125","133.60861","0.00370"
"17.30000","0.37304","6556.54443","134.91554","0.00373"
"17.40000","0.37484","6588.92334","135.58180","0.00375"
"17.50000","0.37699","6635.37598","136.53767","0.00377"
"17.60000","0.37955","6693.51904","137.73410","0.00380"
"17.70000","0.38127","6723.49561","138.35094","0.00381"
"17.80000","0.38372","6779.99707","139.51358","0.00384"
"17.90000","0.38581","6821.66504","140.37099","0.00386"
"18.00000","0.38770","6858.35254","141.12592","0.00388"
"18.10000","0.39054","6926.79297","142.53423","0.00391"
"18.20000","0.39222","6953.96875","143.09343","0.00392"
"18.30000","0.39435","6999.24316","144.02505","0.00394"
"18.40000","0.39683","7054.50049","145.16209","0.00397"
"18.50000","0.39859","7085.04492","145.79062","0.00399"
"18.60000","0.40115","7144.30811","147.01009","0.00401"
"18.70000","0.40320","7183.92432","147.82527","0.00403"
"18.80000","0.40505","7218.78857","148.54269","0.00405"
"18.90000","0.40768","7280.17773","149.80591","0.00408"
"19.00000","0.40950","7312.46387","150.47026","0.00410"
"19.10000","0.41172","7360.68701","151.46257","0.00412"
"19.20000","0.41416","7413.02734","152.53958","0.00414"
"19.30000","0.41585","7441.26123","153.12056","0.00416"
"19.40000","0.41842","7500.79883","154.34567","0.00418"
"19.50000","0.42046","7539.92285","155.15074","0.00420"
"19.60000","0.42237","7576.36572","155.90063","0.00422"
"19.70000","0.42519","7643.24609","157.27686","0.00425"
"19.80000","0.42683","7668.04150","157.78706","0.00427"
"19.90000","0.42906","7716.19287","158.77789","0.00429"
"20.00000","0.43136","7764.37207","159.76929","0.00431"
"20.10000","0.43324","7799.51953","160.49252","0.00433"
"20.20000","0.43597","7863.89111","161.81711","0.00436"
"20.30000","0.43780","7895.05322","162.45834","0.00438"
"20.40000","0.43976","7933.11914","163.24164","0.00440"
"20.50000","0.44236","7992.85840","164.47090","0.00442"
"20.60000","0.44417","8023.98047","165.11131","0.00444"
"20.70000","0.44649","8074.54004","166.15169","0.00446"
"20.80000","0.44876","8120.74902","167.10254","0.00449"
"20.90000","0.45059","8153.33594","167.77309","0.00451"
"21.00000","0.45312","8210.79004","168.95534","0.00453"
"21.10000","0.45504","8245.60938","169.67181","0.00455"
"21.20000","0.45712","8287.13965","170.52640","0.00457"
"21.30000","0.45980","8348.63086","171.79172","0.00460"
"21.40000","0.46147","8374.23633","172.31860","0.00461"
"21.50000","0.46376","8424.08789","173.34441","0.00464"
"21.60000","0.46600","8469.57422","174.28040","0.00466"
"21.70000","0.46787","8503.71191","174.98285","0.00468"
"21.80000","0.47067","8570.30176","176.35309","0.00471"
"21.90000","0.47246","8599.30078","176.94981","0.00472"
"22.00000","0.47445","8638.27832","177.75186","0.00474"
"22.10000","0.47684","8690.04688","178.81711","0.00477"
"22.20000","0.47881","8726.82520","179.57391","0.00479"
"22.30000","0.48129","8783.02344","180.73032","0.00481"
"22.40000","0.48341","8823.52246","181.56367","0.00483"
"22.50000","0.48524","8856.03711","182.23273","0.00485"
"22.60000","0.48779","8913.98730","183.42519","0.00488"
"22.70000","0.48969","8947.69531","184.11880","0.00490"
"22.80000","0.49182","8991.41699","185.01848","0.00492"
"22.90000","0.49437","9047.97363","186.18225","0.00494"
"23.00000","0.49614","9077.44727","186.78874","0.00496"
"23.10000","0.49855","9131.18848","187.89459","0.00499"
"23.20000","0.50057","9169.26953","188.67819","0.00501"
"23.30000","0.50258","9208.62109","189.48793","0.00503"
"23.40000","0.50529","9272.77148","190.80797","0.00505"
"23.50000","0.50711","9303.35645","191.43733","0.00507"
"23.60000","0.50914","9344.86523","192.29146","0.00509"
"23.70000","0.51162","9401.12695","193.44917","0.00512"
"23.80000","0.51338","9432.43848","194.09348","0.00513"
"23.90000","0.51612","9500.04199","195.48457","0.00516"
"24.00000","0.51809","9535.96582","196.22379","0.00518"
"24.10000","0.51990","9569.94727","196.92303","0.00520"
"24.20000","0.52236","9628.27637","198.12328","0.00522"
"24.30000","0.52437","9668.04590","198.94162","0.00524"
"24.40000","0.52664","9719.61523","200.00278","0.00527"
"24.50000","0.52900","9771.31250","201.06657","0.00529"
"24.60000","0.53075","9802.36035","201.70544","0.00531"
"24.70000","0.53326","9862.74805","202.94806","0.00533"
"24.80000","0.53523","9900.68555","203.72870","0.00535"
"24.90000","0.53720","9940.46680","204.54729","0.00537"
"25.00000","0.53998","10009.33301","205.96437","0.00540"
"25.10000","0.54172","10038.18848","206.55814","0.00542"
"25.20000","0.54391","10086.51953","207.55266","0.00544"
"25.30000","0.54620","10136.70117","208.58525","0.00546"
"25.40000","0.54803","10170.33301","209.27730","0.00548"
"25.50000","0.55080","10239.98828","210.71062","0.00551"
"25.60000","0.55264","10270.91406","211.34698","0.00553"
"25.70000","0.55458","10309.61035","212.14325","0.00555"
"25.80000","0.55713","10369.86230","213.38307","0.00557"
"25.90000","0.55896","10402.55078","214.05571","0.00559"
"26.00000","0.56140","10459.88574","215.23550","0.00561"
"26.10000","0.56365","10506.56250","216.19598","0.00564"
"26.20000","0.56539","10536.69824","216.81609","0.00565"
"26.30000","0.56796","10598.35449","218.08481","0.00568"
"26.40000","0.56988","10633.35938","218.80510","0.00570"
"26.50000","0.57201","10678.30176","219.72989","0.00572"
"26.60000","0.57459","10738.00195","220.95836","0.00575"
"26.70000","0.57630","10764.98926","221.51369","0.00576"
"26.80000","0.57870","10820.05078","222.64670","0.00579"
"26.90000","0.58081","10861.58008","223.50125","0.00581"
"27.00000","0.58265","10894.74805","224.18376","0.00583"
"27.10000","0.58549","10966.38672","225.65788","0.00585"
"27.20000","0.58726","10993.39453","226.21364","0.00587"
"27.30000","0.58933","11036.37988","227.09814","0.00589"
"27.40000","0.59175","11089.63672","228.19403","0.00592"
"27.50000","0.59356","11120.43750","228.82782","0.00594"
"27.60000","0.59613","11181.19141","230.07797","0.00596"
"27.70000","0.59823","11220.76660","230.89232","0.00598"
"27.80000","0.60001","11251.21582","231.51888","0.00600"
"27.90000","0.60272","11316.62402","232.86481","0.00603"
"28.00000","0.60450","11344.62402","233.44096","0.00605"
"28.10000","0.60670","11391.33691","234.40219","0.00607"
"28.20000","0.60920","11446.58887","235.53912","0.00609"
"28.30000","0.61089","11471.88281","236.05960","0.00611"
"28.40000","0.61342","11530.92285","237.27448","0.00613"
"28.50000","0.61546","11567.64746","238.03017","0.00615"
"28.60000","0.61735","11601.58496","238.72852","0.00617"
"28.70000","0.62013","11667.97168","240.09456","0.00620"
"28.80000","0.62189","11693.68555","240.62369","0.00622"
"28.90000","0.62406","11738.20801","241.53983","0.00624"
"29.00000","0.62640","11786.44434","242.53241","0.00626"
"29.10000","0.62823","11816.53711","243.15163","0.00628"
"29.20000","0.63088","11878.42676","244.42514","0.00631"
"29.30000","0.63287","11905.77930","244.98799","0.00633"
"29.40000","0.63471","11930.48730","245.49641","0.00635"
"29.50000","0.63738","11990.29004","246.72699","0.00637"
"29.60000","0.63916","12009.18164","247.11572","0.00639"
"29.70000","0.64146","12036.40137","247.67583","0.00641"
"29.80000","0.64380","12057.56152","248.11124","0.00644"
"29.90000","0.64551","12030.92383","247.56311","0.00646"
"30.00000","0.64817","11957.58691","246.05405","0.00648"
"30.10000","0.65016","11909.94434","245.07368","0.00650"
"30.20000","0.65211","11829.93164","243.42725","0.00652"
"30.25500","0.65377","11654.25391","239.81229","0.00654"
"30.25700","0.65383","11499.76953","236.63342","0.00654"
"30.25900","0.65390","11289.19336","232.30035","0.00654"
"30.26100","0.65396","11034.22461","227.05380","0.00654"
"30.26200","0.65399","10893.38965","224.15581","0.00654"
"30.26300","0.65402","10745.21582","221.10680","0.00654"
"30.26400","0.65405","10590.77051","217.92874","0.00654"
"30.26500","0.65409","10431.05371","214.64221","0.00654"
"30.26600","0.65412","10267.01074","211.26666","0.00654"
"30.26700","0.65416","10099.54980","207.82079","0.00654"
"30.26800","0.65419","9929.53223","204.32230","0.00654"
"30.26900","0.65423","9757.76562","200.78781","0.00654"
"30.27000","0.65427","9584.99805","197.23273","0.00654"
"30.27100","0.65431","9411.91797","193.67122","0.00654"
"30.27200","0.65436","9239.15137","190.11617","0.00654"
"30.27300","0.65440","9067.26074","186.57913","0.00654"
"30.27400","0.65445","8896.76270","183.07076","0.00654"
"30.27500","0.65449","8728.12793","179.60071","0.00654"
"30.27600","0.65454","8561.79199","176.17798","0.00655"
"30.27700","0.65459","8398.15625","172.81081","0.00655"
"30.27800","0.65464","8237.58301","169.50665","0.00655"
"30.27900","0.65470","8080.39209","166.27211","0.00655"
"30.28000","0.65475","7926.86572","163.11296","0.00655"
"30.28100","0.65481","7777.24365","160.03415","0.00655"
"30.28200","0.65487","7631.72656","157.03981","0.00655"
"30.28300","0.65493","7490.48389","154.13342","0.00655"
"30.28400","0.65499","7353.65576","151.31789","0.00655"
"30.28500","0.65505","7221.35547","148.59550","0.00655"
"30.28600","0.65511","7093.67188","145.96814","0.00655"