File: flexion/5_axis/Specimen_RawData_1.csv
Specimen properties : Specimen label,"1"
Specimen properties : Support span,"72.00",mm
Specimen properties : Thickness,"4.49",mm
Specimen properties : Width,"14.03",mm
Maximum Load : Maximum Load,"567.0",N
Tangent Modulus of Elasticity : Tangent Modulus of Elasticity,"28851263247.22710",Pa
Test : Rate 1,"1.00000",mm/min
Specimen notes : Specimen note 1,""

Time,Displacement,Load,Flexure extension,Corrected extension,Flexure strain (Corrected extension),Flexure stress
(s),(mm),(N),(mm),(mm),(mm/mm),(MPa)
"0.00000","0.00000","8.87291","-0.04726","-1.04662","-0.00025","3.38797"
"0.50000","0.00638","10.69038","-0.04166","-1.04102","-0.00022","4.08194"
"1.00000","0.01491","13.03586","-0.03414","-1.03350","-0.00018","4.97752"
"1.50000","0.02304","15.21428","-0.02695","-1.02631","-0.00014","5.80931"
"2.00000","0.03177","17.45209","-0.01881","-1.01817","-0.00010","6.66378"
"2.50000","0.03969","19.46587","-0.01131","-1.01067","-0.00006","7.43271"
"3.00000","0.04843","21.74606","-0.00306","-1.00242","-0.00002","8.30336"
"3.50000","0.05644","23.66451","0.00455","-0.99481","0.00002","9.03589"
"4.00000","0.06525","26.02437","0.01285","-0.98650","0.00007","9.93696"
"4.50000","0.07312","27.80485","0.02035","-0.97901","0.00011","10.61681"
"5.00000","0.08156","29.94404","0.02834","-0.97102","0.00015","11.43362"
"5.50000","0.08992","32.19310","0.03623","-0.96313","0.00019","12.29239"
"6.00000","0.09813","34.13752","0.04403","-0.95533","0.00023","13.03483"
"6.50000","0.10652","36.31532","0.05202","-0.94734","0.00027","13.86639"
"7.00000","0.11472","38.43346","0.05994","-0.93942","0.00031","14.67516"
"7.50000","0.12350","40.73459","0.06841","-0.93095","0.00036","15.55381"
"8.00000","0.13136","42.80013","0.07598","-0.92338","0.00039","16.34250"
"8.50000","0.14009","45.00668","0.08442","-0.91494","0.00044","17.18503"
"9.00000","0.14812","47.06980","0.09218","-0.90718","0.00048","17.97280"
"9.50000","0.15690","49.46460","0.10064","-0.89872","0.00052","18.88721"
"10.00000","0.16479","51.89072","0.10819","-0.89117","0.00056","19.81359"
"10.50000","0.17327","54.26057","0.11636","-0.88300","0.00060","20.71847"
"11.00000","0.18162","56.63488","0.12439","-0.87497","0.00065","21.62506"
"11.50000","0.18974","58.95708","0.13222","-0.86714","0.00069","22.51176"
"12.00000","0.19825","61.45382","0.14044","-0.85892","0.00073","23.46509"
"12.50000","0.20637","63.76553","0.14829","-0.85107","0.00077","24.34778"
"13.00000","0.21516","66.44323","0.15676","-0.84259","0.00081","25.37021"
"13.50000","0.22298","68.71672","0.16432","-0.83504","0.00085","26.23831"
"14.00000","0.23180","71.40543","0.17283","-0.82653","0.00090","27.26495"
"14.50000","0.23976","73.73733","0.18051","-0.81884","0.00094","28.15534"
"15.00000","0.24848","76.46667","0.18892","-0.81044","0.00098","29.19749"
"15.50000","0.25650","78.96771","0.19664","-0.80272","0.00102","30.15248"
"16.00000","0.26483","81.79556","0.20464","-0.79472","0.00106","31.23224"
"16.50000","0.27329","84.66756","0.21277","-0.78659","0.00111","32.32886"
"17.00000","0.28139","87.55708","0.22053","-0.77883","0.00115","33.43218"
"17.50000","0.29002","90.73389","0.22885","-0.77051","0.00119","34.64519"
"18.00000","0.29807","93.50722","0.23663","-0.76273","0.00123","35.70414"
"18.50000","0.30689","96.64300","0.24515","-0.75421","0.00127","36.90148"
"19.00000","0.31471","99.50101","0.25269","-0.74667","0.00131","37.99277"
"19.50000","0.32336","102.73338","0.26102","-0.73834","0.00136","39.22699"
"20.00000","0.33151","105.72279","0.26888","-0.73048","0.00140","40.36844"
"20.50000","0.34007","108.91864","0.27713","-0.72223","0.00144","41.58873"
"21.00000","0.34813","111.89304","0.28489","-0.71447","0.00148","42.72445"
"21.50000","0.35646","115.11832","0.29290","-0.70646","0.00152","43.95597"
"22.00000","0.36503","118.22797","0.30118","-0.69818","0.00157","45.14333"
"22.50000","0.37305","121.21845","0.30890","-0.69046","0.00161","46.28520"
"23.00000","0.38164","124.50983","0.31716","-0.68220","0.00165","47.54196"
"23.50000","0.38974","127.58463","0.32497","-0.67439","0.00169","48.71601"
"24.00000","0.39859","130.97511","0.33349","-0.66587","0.00173","50.01061"
"24.50000","0.40638","133.86314","0.34100","-0.65836","0.00177","51.11336"
"25.00000","0.41507","137.17297","0.34937","-0.64999","0.00182","52.37716"
"25.50000","0.42319","140.40045","0.35718","-0.64218","0.00186","53.60952"
"26.00000","0.43164","143.71930","0.36530","-0.63406","0.00190","54.87676"
"26.50000","0.43982","146.70137","0.37319","-0.62617","0.00194","56.01542"
"27.00000","0.44811","149.83508","0.38118","-0.61818","0.00198","57.21197"
"27.50000","0.45669","153.06961","0.38944","-0.60992","0.00202","58.44702"
"28.00000","0.46464","156.03094","0.39710","-0.60226","0.00206","59.57775"
"28.50000","0.47338","159.39795","0.40554","-0.59382","0.00211","60.86339"
"29.00000","0.48138","162.42526","0.41327","-0.58609","0.00215","62.01932"
"29.50000","0.49025","165.93675","0.42185","-0.57751","0.00219","63.36012"
"30.00000","0.49809","168.80348","0.42944","-0.56992","0.00223","64.45473"
"30.50000","0.50670","172.12813","0.43777","-0.56159","0.00227","65.72419"
"31.00000","0.51485","175.12938","0.44567","-0.55369","0.00232","66.87017"
"31.50000","0.52328","178.43651","0.45382","-0.54554","0.00236","68.13294"
"32.00000","0.53157","181.39297","0.46185","-0.53751","0.00240","69.26182"
"32.50000","0.53977","184.51990","0.46979","-0.52957","0.00244","70.45578"
"33.00000","0.54842","187.86792","0.47816","-0.52120","0.00248","71.73416"
"33.50000","0.55633","190.74261","0.48582","-0.51354","0.00252","72.83182"
"34.00000","0.56498","194.00880","0.49419","-0.50517","0.00257","74.07896"
"34.50000","0.57308","196.92404","0.50204","-0.49732","0.00261","75.19209"
"35.00000","0.58187","200.33759","0.51054","-0.48882","0.00265","76.49549"
"35.50000","0.58975","203.35214","0.51818","-0.48118","0.00269","77.64655"
"36.00000","0.59830","206.51701","0.52648","-0.47288","0.00274","78.85500"
"36.50000","0.60660","209.58286","0.53453","-0.46483","0.00278","80.02564"
"37.00000","0.61488","212.65875","0.54257","-0.45679","0.00282","81.20012"
"37.50000","0.62319","215.85817","0.55062","-0.44874","0.00286","82.42176"
"38.00000","0.63142","218.88582","0.55861","-0.44075","0.00290","83.57782"
"38.50000","0.64013","222.18660","0.56705","-0.43231","0.00295","84.83817"
"39.00000","0.64799","224.97186","0.57469","-0.42467","0.00299","85.90167"
"39.50000","0.65675","228.27293","0.58318","-0.41618","0.00303","87.16212"
"40.00000","0.66475","231.20943","0.59096","-0.40840","0.00307","88.28338"
"40.50000","0.67353","234.55988","0.59946","-0.39990","0.00312","89.56269"
"41.00000","0.68143","237.43019","0.60713","-0.39223","0.00316","90.65867"
"41.50000","0.68999","240.56227","0.61544","-0.38392","0.00320","91.85460"
"42.00000","0.69825","243.63245","0.62346","-0.37590","0.00324","93.02689"
"42.50000","0.70646","246.66641","0.63143","-0.36793","0.00328","94.18536"
"43.00000","0.71492","249.74347","0.63966","-0.35970","0.00332","95.36028"
"43.50000","0.72304","252.73552","0.64755","-0.35181","0.00337","96.50275"
"44.00000","0.73181","255.85129","0.65608","-0.34328","0.00341","97.69245"
"44.50000","0.73966","258.67612","0.66371","-0.33565","0.00345","98.77106"
"45.00000","0.74845","262.01041","0.67225","-0.32711","0.00349","100.04420"
"45.50000","0.75643","264.76007","0.68001","-0.31935","0.00353","101.09412"
"46.00000","0.76523","268.03098","0.68857","-0.31079","0.00358","102.34306"
"46.50000","0.77319","270.66812","0.69632","-0.30304","0.00362","103.35001"
"47.00000","0.78159","273.73615","0.70449","-0.29487","0.00366","104.52148"
"47.50000","0.78997","276.73434","0.71264","-0.28672","0.00370","105.66629"
"48.00000","0.79805","279.67554","0.72049","-0.27887","0.00374","106.78934"
"48.50000","0.80656","282.61948","0.72878","-0.27058","0.00379","107.91343"
"49.00000","0.81471","285.66174","0.73670","-0.26266","0.00383","109.07507"
"49.50000","0.82350","288.91113","0.74523","-0.25413","0.00387","110.31579"
"50.00000","0.83138","291.42316","0.75293","-0.24643","0.00391","111.27496"
"50.50000","0.84009","294.77792","0.76142","-0.23794","0.00396","112.55592"
"51.00000","0.84817","297.44745","0.76931","-0.23005","0.00400","113.57523"
"51.50000","0.85681","300.54373","0.77775","-0.22161","0.00404","114.75750"
"52.00000","0.86479","303.35510","0.78554","-0.21382","0.00408","115.83097"
"52.50000","0.87319","306.34631","0.79375","-0.20561","0.00412","116.97311"
"53.00000","0.88164","309.12964","0.80201","-0.19735","0.00417","118.03588"
"53.50000","0.88969","311.95407","0.80987","-0.18949","0.00421","119.11434"
"54.00000","0.89830","315.04895","0.81827","-0.18109","0.00425","120.29607"
"54.50000","0.90638","317.78870","0.82617","-0.17319","0.00429","121.34219"
"55.00000","0.91523","320.93002","0.83481","-0.16455","0.00434","122.54166"
"55.50000","0.92301","323.49728","0.84242","-0.15694","0.00438","123.52192"
"56.00000","0.93182","326.60129","0.85102","-0.14834","0.00442","124.70713"
"56.50000","0.93981","329.27954","0.85883","-0.14053","0.00446","125.72978"
"57.00000","0.94838","332.27484","0.86720","-0.13216","0.00451","126.87348"
"57.50000","0.95650","335.00385","0.87513","-0.12423","0.00455","127.91550"
"58.00000","0.96479","337.68433","0.88324","-0.11612","0.00459","128.93900"
"58.50000","0.97333","340.67310","0.89158","-0.10778","0.00463","130.08022"
"59.00000","0.98131","343.27789","0.89940","-0.09996","0.00467","131.07481"
"59.50000","0.99005","346.16782","0.90795","-0.09141","0.00472","132.17828"
"60.00000","0.99805","348.96939","0.91577","-0.08359","0.00476","133.24802"
"60.50000","1.00695","351.91809","0.92448","-0.07488","0.00480","134.37392"
"61.00000","1.01478","354.37833","0.93215","-0.06721","0.00484","135.31332"
"61.50000","1.02341","357.25256","0.94060","-0.05876","0.00489","136.41080"
"62.00000","1.03153","359.92441","0.94855","-0.05081","0.00493","137.43100"
"62.50000","1.03997","362.65411","0.95681","-0.04255","0.00497","138.47330"
"63.00000","1.04818","365.18570","0.96486","-0.03450","0.00501","139.43993"
"63.50000","1.05640","367.83331","0.97291","-0.02645","0.00506","140.45088"
"64.00000","1.06504","370.79205","0.98136","-0.01800","0.00510","141.58063"
"64.50000","1.07303","373.23013","0.98919","-0.01017","0.00514","142.51157"
"65.00000","1.08174","376.11343","0.99772","-0.00164","0.00518","143.61250"
"65.50000","1.08976","378.66592","1.00557","0.00621","0.00523","144.58713"
"66.00000","1.09857","381.53787","1.01420","0.01485","0.00527","145.68373"
"66.50000","1.10638","383.86105","1.02187","0.02251","0.00531","146.57080"
"67.00000","1.11499","386.80182","1.03029","0.03093","0.00535","147.69368"
"67.50000","1.12319","389.23355","1.03833","0.03898","0.00540","148.62219"
"68.00000","1.13156","391.87042","1.04655","0.04719","0.00544","149.62904"
"68.50000","1.13987","394.47531","1.05472","0.05536","0.00548","150.62367"
"69.00000","1.14810","396.90454","1.06280","0.06344","0.00552","151.55124"
"69.50000","1.15679","399.73184","1.07133","0.07197","0.00557","152.63078"
"70.00000","1.16463","402.04715","1.07904","0.07968","0.00561","153.51485"
"70.50000","1.17347","404.86749","1.08772","0.08836","0.00565","154.59175"
"71.00000","1.18139","407.17920","1.09550","0.09615","0.00569","155.47444"
"71.50000","1.19022","409.97690","1.10417","0.10481","0.00574","156.54269"
"72.00000","1.19808","412.20551","1.11191","0.11255","0.00578","157.39365"
"72.50000","1.20661","414.85367","1.12029","0.12093","0.00582","158.40480"
"73.00000","1.21489","417.42181","1.12842","0.12906","0.00586","159.38541"
"73.50000","1.22313","419.82986","1.13653","0.13717","0.00591","160.30487"
"74.00000","1.23161","422.35614","1.14486","0.14550","0.00595","161.26949"
"74.50000","1.23970","424.71652","1.15281","0.15345","0.00599","162.17076"
"75.00000","1.24846","427.37186","1.16143","0.16207","0.00604","163.18466"
"75.50000","1.25635","429.46356","1.16920","0.16984","0.00608","163.98334"
"76.00000","1.26510","432.25034","1.17778","0.17842","0.00612","165.04742"
"76.50000","1.27312","434.44327","1.18569","0.18633","0.00616","165.88475"
"77.00000","1.28188","437.11249","1.19429","0.19493","0.00621","166.90395"
"77.50000","1.28978","439.23355","1.20207","0.20271","0.00625","167.71384"
"78.00000","1.29822","441.52933","1.21038","0.21102","0.00629","168.59044"
"78.50000","1.30664","444.04562","1.21866","0.21930","0.00633","169.55125"
"79.00000","1.31482","446.24042","1.22671","0.22735","0.00637","170.38930"
"79.50000","1.32330","448.62476","1.23505","0.23569","0.00642","171.29971"
"80.00000","1.33140","450.87375","1.24303","0.24367","0.00646","172.15845"
"80.50000","1.34015","453.30817","1.25164","0.25228","0.00650","173.08800"
"81.00000","1.34797","455.30606","1.25935","0.25999","0.00654","173.85086"
"81.50000","1.35674","458.10168","1.26796","0.26860","0.00659","174.91832"
"82.00000","1.36477","459.96387","1.27587","0.27652","0.00663","175.62936"
"82.50000","1.37345","462.39676","1.28442","0.28506","0.00667","176.55832"
"83.00000","1.38145","464.52014","1.29230","0.29294","0.00672","177.36909"
"83.50000","1.38990","466.74255","1.30062","0.30126","0.00676","178.21768"
"84.00000","1.39835","468.99146","1.30894","0.30958","0.00680","179.07639"
"84.50000","1.40638","471.16391","1.31686","0.31750","0.00684","179.90590"
"85.00000","1.41498","473.30548","1.32533","0.32597","0.00689","180.72363"
"85.50000","1.42302","475.37558","1.33325","0.33389","0.00693","181.51405"
"86.00000","1.43185","477.70142","1.34195","0.34259","0.00697","182.40215"
"86.50000","1.43969","479.50513","1.34969","0.35033","0.00701","183.09085"
"87.00000","1.44849","481.96069","1.35835","0.35899","0.00706","184.02847"
"87.50000","1.45645","483.89352","1.36620","0.36684","0.00710","184.76649"
"88.00000","1.46509","486.11649","1.37471","0.37535","0.00714","185.61530"
"88.50000","1.47320","488.06039","1.38271","0.38335","0.00719","186.35754"
"89.00000","1.48147","490.10040","1.39087","0.39151","0.00723","187.13649"
"89.50000","1.48999","492.22131","1.39927","0.39991","0.00727","187.94632"
"90.00000","1.49801","493.96753","1.40721","0.40785","0.00731","188.61308"
"90.50000","1.50666","496.14566","1.41575","0.41639","0.00736","189.44476"
"91.00000","1.51473","497.89487","1.42373","0.42437","0.00740","190.11267"
"91.50000","1.52359","499.81735","1.43249","0.43313","0.00744","190.84674"
"92.00000","1.53141","501.24396","1.44024","0.44088","0.00748","191.39146"
"92.50000","1.54008","503.09036","1.44882","0.44946","0.00753","192.09648"
"93.00000","1.54820","504.77963","1.45686","0.45750","0.00757","192.74150"
"93.50000","1.55671","506.65421","1.46528","0.46592","0.00761","193.45728"
"94.00000","1.56486","508.31012","1.47334","0.47398","0.00766","194.08955"
"94.50000","1.57311","510.11667","1.48150","0.48214","0.00770","194.77936"
"95.00000","1.58170","511.98505","1.49000","0.49064","0.00774","195.49277"
"95.50000","1.58964","513.56952","1.49786","0.49850","0.00778","196.09776"
"96.00000","1.59834","515.48010","1.50646","0.50710","0.00783","196.82729"
"96.50000","1.60637","517.04633","1.51441","0.51505","0.00787","197.42532"
"97.00000","1.61529","518.84332","1.52324","0.52388","0.00792","198.11148"
"97.50000","1.62308","519.81042","1.53099","0.53163","0.00796","198.48074"
"98.00000","1.63179","521.12469","1.53963","0.54027","0.00800","198.98257"
"98.50000","1.63988","522.47876","1.54765","0.54829","0.00804","199.49960"
"99.00000","1.64825","524.14850","1.55594","0.55658","0.00809","200.13716"
"99.50000","1.65656","525.62769","1.56417","0.56481","0.00813","200.70197"
"100.00000","1.66476","527.27551","1.57229","0.57293","0.00817","201.33116"
"100.50000","1.67341","529.04114","1.58085","0.58149","0.00822","202.00534"
"101.00000","1.68131","530.32648","1.58869","0.58933","0.00826","202.49612"
"101.50000","1.69010","532.29541","1.59738","0.59802","0.00830","203.24792"
"102.00000","1.69804","533.54108","1.60526","0.60590","0.00834","203.72356"
"102.50000","1.70695","535.55463","1.61407","0.61471","0.00839","204.49240"
"103.00000","1.71479","536.59576","1.62186","0.62250","0.00843","204.88994"
"103.50000","1.72332","538.04364","1.63031","0.63095","0.00847","205.44279"
"104.00000","1.73154","539.09821","1.63847","0.63911","0.00851","205.84546"
"104.50000","1.73981","540.16437","1.64670","0.64734","0.00856","206.25255"
"105.00000","1.74824","541.29431","1.65507","0.65571","0.00860","206.68401"
"105.50000","1.75641","542.15631","1.66320","0.66384","0.00864","207.01314"
"106.00000","1.76516","543.29236","1.67190","0.67254","0.00869","207.44693"
"106.50000","1.77304","543.99646","1.67974","0.68038","0.00873","207.71577"
"107.00000","1.78178","544.81567","1.68844","0.68908","0.00877","208.02858"
"107.50000","1.78979","545.26672","1.69643","0.69707","0.00882","208.20081"
"108.00000","1.79859","545.59009","1.70521","0.70585","0.00886","208.32428"
"108.50000","1.80646","543.14728","1.71320","0.71384","0.00890","207.39153"
"109.00000","1.81491","543.13245","1.72165","0.72229","0.00895","207.38586"
"109.50000","1.82326","543.13165","1.73001","0.73065","0.00899","207.38556"
"110.00000","1.83142","540.73010","1.73828","0.73892","0.00903","206.46857"
"110.50000","1.83992","540.07166","1.74681","0.74745","0.00908","206.21715"
"111.00000","1.84806","536.46649","1.75513","0.75577","0.00912","204.84058"
"111.50000","1.85685","535.22552","1.76398","0.76462","0.00917","204.36674"
"112.00000","1.86469","531.75970","1.77200","0.77264","0.00921","203.04338"
"112.50000","1.87350","522.05090","1.78129","0.78193","0.00926","199.33624"
"113.00000","1.88146","520.56641","1.78933","0.78997","0.00930","198.76941"
"113.50000","1.89015","520.46136","1.79802","0.79866","0.00934","198.72929"
"114.00000","1.89814","520.27478","1.80602","0.80666","0.00939","198.65805"
"114.50000","1.90658","520.67493","1.81444","0.81508","0.00943","198.81084"
"115.00000","1.91496","521.02899","1.82281","0.82345","0.00947","198.94604"
"115.50000","1.92302","521.47815","1.83084","0.83148","0.00951","199.11754"
"116.00000","1.93167","522.00781","1.83947","0.84011","0.00956","199.31978"
"116.50000","1.93970","522.36511","1.84748","0.84812","0.00960","199.45621"
"117.00000","1.94853","523.24170","1.85627","0.85691","0.00965","199.79092"
"117.50000","1.95637","523.59973","1.86408","0.86472","0.00969","199.92763"
"118.00000","1.96510","524.31848","1.87278","0.87342","0.00973","200.20207"
"118.50000","1.97311","524.83875","1.88076","0.88140","0.00977","200.40073"
"119.00000","1.98177","525.70752","1.88938","0.89002","0.00982","200.73245"
"119.50000","1.98984","526.25055","1.89742","0.89806","0.00986","200.93980"
"120.00000","1.99816","527.01990","1.90571","0.90635","0.00990","201.23357"
"120.50000","2.00669","527.86957","1.91419","0.91483","0.00995","201.55800"
"121.00000","2.01474","528.45117","1.92222","0.92286","0.00999","201.78008"
"121.50000","2.02334","529.40161","1.93077","0.93141","0.01003","202.14297"
"122.00000","2.03144","529.93561","1.93884","0.93948","0.01008","202.34688"
"122.50000","2.04021","530.83447","1.94756","0.94820","0.01012","202.69009"
"123.00000","2.04803","531.22437","1.95536","0.95601","0.01016","202.83897"
"123.50000","2.05670","532.09613","1.96399","0.96463","0.01021","203.17183"
"124.00000","2.06484","532.61584","1.97210","0.97274","0.01025","203.37029"
"124.50000","2.07338","533.28516","1.98061","0.98125","0.01029","203.62584"
"125.00000","2.08150","533.83588","1.98870","0.98934","0.01033","203.83612"
"125.50000","2.08982","534.63715","1.99698","0.99762","0.01038","204.14207"
"126.00000","2.09837","535.63525","2.00548","1.00612","0.01042","204.52319"
"126.50000","2.10638","536.21094","2.01346","1.01410","0.01046","204.74301"
"127.00000","2.11505","537.24500","2.02208","1.02272","0.01051","205.13785"
"127.50000","2.12308","537.91638","2.03007","1.03071","0.01055","205.39420"
"128.00000","2.13187","538.89203","2.03882","1.03946","0.01060","205.76674"
"128.50000","2.13974","539.51990","2.04665","1.04729","0.01064","206.00647"
"129.00000","2.14845","540.66925","2.05531","1.05595","0.01068","206.44534"
"129.50000","2.15652","541.42139","2.06334","1.06398","0.01072","206.73253"
"130.00000","2.16495","542.11298","2.07174","1.07238","0.01077","206.99660"
"130.50000","2.17321","542.97131","2.07996","1.08060","0.01081","207.32434"
"131.00000","2.18142","543.74866","2.08814","1.08878","0.01085","207.62115"
"131.50000","2.19001","544.81946","2.09667","1.09731","0.01090","208.03001"
"132.00000","2.19797","545.41162","2.10461","1.10525","0.01094","208.25613"
"132.50000","2.20672","546.29150","2.11331","1.11395","0.01098","208.59210"
"133.00000","2.21470","546.83795","2.12126","1.12190","0.01102","208.80075"
"133.50000","2.22358","547.86157","2.13010","1.13074","0.01107","209.19160"
"134.00000","2.23141","548.33179","2.13790","1.13854","0.01111","209.37114"
"134.50000","2.23999","549.22821","2.14644","1.14708","0.01115","209.71342"
"135.00000","2.24823","549.92786","2.15464","1.15529","0.01120","209.98058"
"135.50000","2.25659","550.60583","2.16297","1.16361","0.01124","210.23946"
"136.00000","2.26489","551.30444","2.17124","1.17188","0.01128","210.50620"
"136.50000","2.27315","551.83771","2.17947","1.18011","0.01133","210.70982"
"137.00000","2.28176","552.63013","2.18804","1.18868","0.01137","211.01239"
"137.50000","2.28965","553.03296","2.19591","1.19655","0.01141","211.16621"
"138.00000","2.29836","553.84924","2.20459","1.20523","0.01146","211.47789"
"138.50000","2.30643","554.22394","2.21263","1.21327","0.01150","211.62096"
"139.00000","2.31526","555.01050","2.22142","1.22206","0.01154","211.92130"
"139.50000","2.32309","555.36578","2.22923","1.22987","0.01158","212.05696"
"140.00000","2.33169","555.92987","2.23781","1.23845","0.01163","212.27234"
"140.50000","2.33993","556.43201","2.24603","1.24667","0.01167","212.46408"
"141.00000","2.34819","556.92938","2.25427","1.25491","0.01171","212.65399"
"141.50000","2.35655","557.32483","2.26260","1.26324","0.01176","212.80498"
"142.00000","2.36474","557.71118","2.27077","1.27141","0.01180","212.95250"
"142.50000","2.37345","558.49792","2.27945","1.28009","0.01185","213.25291"
"143.00000","2.38133","558.72272","2.28732","1.28796","0.01189","213.33875"
"143.50000","2.39018","559.39233","2.29613","1.29677","0.01193","213.59442"
"144.00000","2.39809","559.59711","2.30404","1.30468","0.01197","213.67261"
"144.50000","2.40689","560.27136","2.31280","1.31344","0.01202","213.93007"
"145.00000","2.41478","560.35541","2.32069","1.32133","0.01206","213.96216"
"145.50000","2.42329","560.75818","2.32918","1.32982","0.01210","214.11595"
"146.00000","2.43157","561.06311","2.33744","1.33808","0.01215","214.23238"
"146.50000","2.43973","561.17230","2.34559","1.34623","0.01219","214.27408"
"147.00000","2.44827","561.54578","2.35412","1.35476","0.01223","214.41669"
"147.50000","2.45635","561.47443","2.36221","1.36285","0.01228","214.38943"
"148.00000","2.46517","561.90460","2.37100","1.37164","0.01232","214.55370"
"148.50000","2.47304","561.84381","2.37887","1.37951","0.01236","214.53049"
"149.00000","2.48176","562.18250","2.38758","1.38822","0.01241","214.65981"
"149.50000","2.48979","562.14722","2.39561","1.39625","0.01245","214.64633"
"150.00000","2.49850","562.43518","2.40431","1.40495","0.01249","214.75629"
"150.50000","2.50647","562.26764","2.41229","1.41293","0.01254","214.69231"
"151.00000","2.51492","562.44965","2.42073","1.42137","0.01258","214.76181"
"151.50000","2.52333","562.31238","2.42914","1.42978","0.01262","214.70940"
"152.00000","2.53137","562.23016","2.43718","1.43782","0.01267","214.67801"
"152.50000","2.53994","562.32861","2.44575","1.44639","0.01271","214.71559"
"153.00000","2.54807","562.26385","2.45389","1.45453","0.01275","214.69087"
"153.50000","2.55687","562.36761","2.46268","1.46332","0.01280","214.73048"
"154.00000","2.56471","562.07294","2.47054","1.47118","0.01284","214.61797"
"154.50000","2.57347","562.19470","2.47929","1.47993","0.01288","214.66446"
"155.00000","2.58148","561.89514","2.48731","1.48795","0.01293","214.55008"
"155.50000","2.59009","561.79175","2.49593","1.49657","0.01297","214.51060"
"156.00000","2.59812","561.58191","2.50397","1.50461","0.01301","214.43048"
"156.50000","2.60651","561.55023","2.51236","1.51300","0.01306","214.41838"
"157.00000","2.61501","561.44366","2.52087","1.52151","0.01310","214.37769"
"157.50000","2.62302","561.34656","2.52888","1.52952","0.01314","214.34061"
"158.00000","2.63171","561.34601","2.53757","1.53821","0.01319","214.34041"
"158.50000","2.63971","561.13928","2.54558","1.54622","0.01323","214.26147"
"159.00000","2.64865","561.53870","2.55450","1.55514","0.01328","214.41397"
"159.50000","2.65640","561.27875","2.56226","1.56290","0.01332","214.31473"
"160.00000","2.66510","561.45557","2.57095","1.57159","0.01336","214.38223"
"160.50000","2.67313","561.51270","2.57898","1.57962","0.01340","214.40405"
"161.00000","2.68163","561.63013","2.58748","1.58812","0.01345","214.44888"
"161.50000","2.68986","561.65582","2.59571","1.59635","0.01349","214.45869"
"162.00000","2.69809","561.88501","2.60392","1.60456","0.01353","214.54622"
"162.50000","2.70667","562.06659","2.61250","1.61314","0.01358","214.61554"
"163.00000","2.71468","562.05951","2.62051","1.62115","0.01362","214.61284"
"163.50000","2.72335","562.22870","2.62917","1.62981","0.01366","214.67744"
"164.00000","2.73141","562.38922","2.63722","1.63786","0.01370","214.73874"
"164.50000","2.74025","562.59857","2.64605","1.64669","0.01375","214.81868"
"165.00000","2.74808","562.52594","2.65389","1.65453","0.01379","214.79094"
"165.50000","2.75670","562.71698","2.66249","1.66313","0.01384","214.86389"
"166.00000","2.76490","562.76514","2.67069","1.67133","0.01388","214.88228"
"166.50000","2.77327","562.93567","2.67905","1.67969","0.01392","214.94739"
"167.00000","2.78155","563.11877","2.68732","1.68796","0.01397","215.01730"
"167.50000","2.78979","563.02271","2.69557","1.69621","0.01401","214.98062"
"168.00000","2.79840","563.27649","2.70417","1.70481","0.01405","215.07753"
"168.50000","2.80632","563.20740","2.71209","1.71273","0.01409","215.05115"
"169.00000","2.81505","563.58899","2.72080","1.72144","0.01414","215.19685"
"169.50000","2.82307","563.67511","2.72882","1.72946","0.01418","215.22974"
"170.00000","2.83191","564.03625","2.73763","1.73827","0.01423","215.36763"
"170.50000","2.83972","563.90625","2.74545","1.74609","0.01427","215.31799"
"171.00000","2.84834","564.28687","2.75405","1.75469","0.01431","215.46332"
"171.50000","2.85657","564.16376","2.76229","1.76293","0.01435","215.41631"
"172.00000","2.86481","564.16028","2.77054","1.77118","0.01440","215.41498"
"172.50000","2.87323","564.34930","2.77895","1.77959","0.01444","215.48717"
"173.00000","2.88142","564.36639","2.78713","1.78777","0.01448","215.49368"
"173.50000","2.89015","564.56451","2.79585","1.79649","0.01453","215.56934"
"174.00000","2.89801","564.44458","2.80372","1.80436","0.01457","215.52354"
"174.50000","2.90680","564.57892","2.81250","1.81314","0.01462","215.57483"
"175.00000","2.91473","564.45978","2.82044","1.82108","0.01466","215.52934"
"175.50000","2.92361","564.81140","2.82930","1.82994","0.01470","215.66360"
"176.00000","2.93147","564.54224","2.83718","1.83782","0.01474","215.56082"
"176.50000","2.93991","564.65302","2.84561","1.84625","0.01479","215.60313"
"177.00000","2.94825","564.64166","2.85395","1.85459","0.01483","215.59879"
"177.50000","2.95646","564.62891","2.86216","1.86280","0.01487","215.59392"
"178.00000","2.96491","564.60480","2.87061","1.87125","0.01492","215.58472"
"178.50000","2.97305","564.51581","2.87875","1.87940","0.01496","215.55074"
"179.00000","2.98180","564.71497","2.88750","1.88814","0.01501","215.62679"
"179.50000","2.98967","564.48352","2.89538","1.89602","0.01505","215.53841"
"180.00000","2.99837","564.65277","2.90407","1.90471","0.01509","215.60303"
"180.50000","3.00646","564.68817","2.91216","1.91280","0.01513","215.61655"
"181.00000","3.01522","564.82458","2.92091","1.92155","0.01518","215.66864"
"181.50000","3.02314","564.61554","2.92884","1.92948","0.01522","215.58882"
"182.00000","3.03159","564.80389","2.93728","1.93792","0.01526","215.66074"
"182.50000","3.03996","564.69922","2.94566","1.94630","0.01531","215.62077"
"183.00000","3.04808","564.63971","2.95378","1.95443","0.01535","215.59805"
"183.50000","3.05665","564.79095","2.96234","1.96298","0.01539","215.65579"
"184.00000","3.06474","564.66248","2.97044","1.97108","0.01544","215.60674"
"184.50000","3.07352","564.92505","2.97921","1.97985","0.01548","215.70700"
"185.00000","3.08131","564.74066","2.98701","1.98765","0.01552","215.63660"
"185.50000","3.09012","565.17365","2.99580","1.99644","0.01557","215.80193"
"186.00000","3.09813","564.90253","3.00381","2.00445","0.01561","215.69839"
"186.50000","3.10673","565.11682","3.01241","2.01305","0.01565","215.78023"
"187.00000","3.11481","564.98712","3.02049","2.02113","0.01570","215.73070"
"187.50000","3.12320","565.06915","3.02888","2.02952","0.01574","215.76202"
"188.00000","3.13166","565.20581","3.03733","2.03797","0.01578","215.81421"
"188.50000","3.13970","565.16888","3.04538","2.04602","0.01583","215.80011"
"189.00000","3.14836","565.32135","3.05403","2.05467","0.01587","215.85832"
"189.50000","3.15635","565.34607","3.06201","2.06265","0.01591","215.86775"
"190.00000","3.16526","565.71655","3.07091","2.07155","0.01596","216.00922"
"190.50000","3.17306","565.52191","3.07872","2.07936","0.01600","215.93491"
"191.00000","3.18176","565.78662","3.08740","2.08804","0.01604","216.03598"
"191.50000","3.18982","565.73621","3.09547","2.09611","0.01609","216.01672"
"192.00000","3.19838","565.94287","3.10402","2.10466","0.01613","216.09564"
"192.50000","3.20651","565.94562","3.11214","2.11279","0.01617","216.09668"
"193.00000","3.21478","565.90479","3.12042","2.12106","0.01622","216.08110"
"193.50000","3.22336","566.03674","3.12899","2.12963","0.01626","216.13148"
"194.00000","3.23136","566.04321","3.13699","2.13763","0.01630","216.13396"
"194.50000","3.23996","566.24139","3.14558","2.14622","0.01635","216.20963"
"195.00000","3.24805","566.15387","3.15368","2.15432","0.01639","216.17621"
"195.50000","3.25694","566.56830","3.16255","2.16319","0.01644","216.33444"
"196.00000","3.26473","566.31122","3.17035","2.17099","0.01648","216.23628"
"196.50000","3.27342","566.47437","3.17904","2.17968","0.01652","216.29858"
"197.00000","3.28157","566.40619","3.18718","2.18782","0.01656","216.27255"
"197.50000","3.28998","566.52332","3.19559","2.19623","0.01661","216.31728"
"198.00000","3.29820","566.45099","3.20381","2.20445","0.01665","216.28966"
"198.50000","3.30644","566.39270","3.21206","2.21270","0.01669","216.26740"
"199.00000","3.31507","566.70441","3.22067","2.22131","0.01674","216.38641"
"199.50000","3.32297","566.43054","3.22858","2.22922","0.01678","216.28185"
"200.00000","3.33171","566.62567","3.23732","2.23796","0.01682","216.35635"
"200.50000","3.33970","566.42584","3.24531","2.24595","0.01687","216.28004"
"201.00000","3.34854","566.74133","3.25414","2.25478","0.01691","216.40051"
"201.50000","3.35639","566.57770","3.26200","2.26264","0.01695","216.33803"
"202.00000","3.36507","566.66028","3.27067","2.27131","0.01700","216.36957"
"202.50000","3.37321","566.66278","3.27881","2.27945","0.01704","216.37053"
"203.00000","3.38155","566.60645","3.28715","2.28779","0.01708","216.34901"
"203.50000","3.38992","566.70465","3.29552","2.29616","0.01713","216.38651"
"204.00000","3.39805","566.55188","3.30366","2.30430","0.01717","216.32817"
"204.50000","3.40679","566.67615","3.31239","2.31303","0.01721","216.37563"
"205.00000","3.41468","566.50153","3.32029","2.32093","0.01725","216.30894"
"205.50000","3.42344","566.55023","3.32904","2.32968","0.01730","216.32755"
"206.00000","3.43143","566.36334","3.33704","2.33768","0.01734","216.25618"
"206.50000","3.44025","566.53302","3.34585","2.34649","0.01739","216.32097"
"207.00000","3.44812","566.14166","3.35375","2.35439","0.01743","216.17154"
"207.50000","3.45659","566.07220","3.36222","2.36286","0.01747","216.14502"
"208.00000","3.46493","565.92670","3.37057","2.37121","0.01752","216.08946"
"208.50000","3.47313","565.30359","3.37880","2.37944","0.01756","215.85153"
"209.00000","3.48153","565.10095","3.38721","2.38785","0.01760","215.77417"
"209.50000","3.48971","564.80688","3.39540","2.39604","0.01765","215.66188"
"210.00000","3.49849","564.65106","3.40419","2.40483","0.01769","215.60239"
"210.50000","3.50635","564.11456","3.41208","2.41272","0.01773","215.39752"
"211.00000","3.51507","564.22021","3.42079","2.42143","0.01778","215.43787"
"211.50000","3.52312","563.62744","3.42887","2.42951","0.01782","215.21153"
"212.00000","3.53190","563.85583","3.43763","2.43827","0.01786","215.29874"
"212.50000","3.53980","563.28143","3.44556","2.44620","0.01791","215.07941"
"213.00000","3.54828","563.25769","3.45404","2.45468","0.01795","215.07034"
"213.50000","3.55664","562.94055","3.46242","2.46306","0.01799","214.94925"
"214.00000","3.56473","562.57056","3.47053","2.47117","0.01804","214.80798"
"214.50000","3.57325","562.30804","3.47906","2.47970","0.01808","214.70773"
"215.00000","3.58136","561.96686","3.48719","2.48783","0.01812","214.57747"
"215.50000","3.59017","561.91327","3.49600","2.49664","0.01817","214.55701"
"216.00000","3.59798","561.40082","3.50384","2.50448","0.01821","214.36133"
"216.50000","3.60680","561.31934","3.51267","2.51331","0.01825","214.33022"
"217.00000","3.61476","560.84796","3.52064","2.52128","0.01830","214.15024"
"217.50000","3.62348","560.75244","3.52937","2.53001","0.01834","214.11375"
"218.00000","3.63150","560.30823","3.53741","2.53805","0.01838","213.94414"
"218.50000","3.63985","559.98218","3.54577","2.54642","0.01843","213.81964"
"219.00000","3.64829","559.79346","3.55423","2.55487","0.01847","213.74759"
"219.50000","3.65638","559.42120","3.56233","2.56297","0.01851","213.60545"
"220.00000","3.66501","559.17639","3.57097","2.57161","0.01856","213.51198"
"220.50000","3.67307","558.82245","3.57905","2.57969","0.01860","213.37683"
"221.00000","3.68191","558.71948","3.58790","2.58854","0.01865","213.33751"
"221.50000","3.68971","558.12744","3.59573","2.59637","0.01869","213.11145"
"222.00000","3.69836","557.93982","3.60438","2.60502","0.01873","213.03981"
"222.50000","3.70650","557.41046","3.61255","2.61319","0.01877","212.83768"
"223.00000","3.71508","557.10779","3.62114","2.62178","0.01882","212.72211"
"223.50000","3.72314","556.57227","3.62923","2.62987","0.01886","212.51762"
"224.00000","3.73146","556.01935","3.63758","2.63822","0.01890","212.30650"
"224.50000","3.74003","555.74475","3.64616","2.64680","0.01895","212.20166"
"225.00000","3.74805","555.06903","3.65421","2.65485","0.01899","211.94365"
"225.50000","3.75665","554.44830","3.66284","2.66348","0.01903","211.70663"
"226.00000","3.76475","553.61224","3.67099","2.67163","0.01908","211.38739"
"226.50000","3.77361","552.91602","3.67988","2.68052","0.01912","211.12155"
"227.00000","3.78137","551.46259","3.68771","2.68835","0.01916","210.56659"
"227.50000","3.79006","550.58044","3.69644","2.69708","0.01921","210.22975"
"228.00000","3.79819","549.03601","3.70464","2.70528","0.01925","209.64005"
"228.50000","3.80663","547.71234","3.71315","2.71379","0.01930","209.13461"
"229.00000","3.81482","546.36060","3.72141","2.72205","0.01934","208.61848"
"229.50000","3.82312","545.07623","3.72977","2.73041","0.01938","208.12807"
"230.00000","3.83170","543.95117","3.73840","2.73904","0.01943","207.69849"
"230.50000","3.83965","542.67523","3.74641","2.74705","0.01947","207.21129"
"231.00000","3.84838","541.59045","3.75520","2.75584","0.01951","206.79709"
"231.50000","3.85637","540.49884","3.76324","2.76388","0.01956","206.38026"
"232.00000","3.86524","539.71716","3.77214","2.77278","0.01960","206.08180"
"232.50000","3.87308","538.30530","3.78005","2.78069","0.01964","205.54269"
"233.00000","3.88170","537.47656","3.78872","2.78936","0.01969","205.22626"
"233.50000","3.88985","536.26306","3.79694","2.79758","0.01973","204.76291"
"234.00000","3.89829","535.16248","3.80543","2.80607","0.01978","204.34267"
"234.50000","3.90659","534.10394","3.81378","2.81442","0.01982","203.93849"
"235.00000","3.91477","532.72119","3.82203","2.82267","0.01986","203.41051"
"235.50000","3.92342","531.73608","3.83073","2.83137","0.01991","203.03436"
"236.00000","3.93133","529.06323","3.83877","2.83941","0.01995","202.01378"
"236.50000","3.94000","527.25659","3.84753","2.84817","0.01999","201.32394"
"237.00000","3.94809","525.40570","3.85572","2.85636","0.02004","200.61720"
"237.50000","3.95689","523.94348","3.86459","2.86523","0.02008","200.05888"
"238.00000","3.96474","522.17188","3.87253","2.87317","0.02012","199.38243"
"238.50000","3.97329","520.90308","3.88114","2.88178","0.02017","198.89796"
"239.00000","3.98159","519.68835","3.88951","2.89015","0.02021","198.43414"
"239.50000","3.98989","518.57196","3.89786","2.89850","0.02026","198.00786"
"240.00000","3.99819","517.49072","3.90621","2.90685","0.02030","197.59502"
"240.50000","4.00643","516.51147","3.91450","2.91514","0.02034","197.22110"
"241.00000","4.01512","515.96777","3.92321","2.92385","0.02039","197.01350"
"241.50000","4.02298","515.04926","3.93112","2.93177","0.02043","196.66278"
"242.00000","4.03175","514.63281","3.93991","2.94055","0.02047","196.50377"
"242.50000","4.03977","513.80762","3.94797","2.94861","0.02052","196.18867"
"243.00000","4.04853","513.41693","3.95676","2.95740","0.02056","196.03951"
"243.50000","4.05641","512.41815","3.96468","2.96532","0.02060","195.65814"
"244.00000","4.06498","511.87430","3.97329","2.97393","0.02065","195.45047"
"244.50000","4.07326","511.07666","3.98160","2.98224","0.02069","195.14590"
"245.00000","4.08147","510.24860","3.98985","2.99049","0.02073","194.82973"
"245.50000","4.08993","509.68011","3.99834","2.99898","0.02078","194.61266"
"246.00000","4.09804","508.91275","4.00649","3.00713","0.02082","194.31966"
"246.50000","4.10681","508.53839","4.01528","3.01592","0.02087","194.17671"
"247.00000","4.11466","507.72675","4.02317","3.02381","0.02091","193.86681"
"247.50000","4.12346","507.25470","4.03200","3.03264","0.02095","193.68655"
"248.00000","4.13143","506.39655","4.04001","3.04065","0.02099","193.35889"
"248.50000","4.14023","505.85223","4.04883","3.04947","0.02104","193.15105"
"249.00000","4.14818","505.09180","4.05682","3.05746","0.02108","192.86069"
"249.50000","4.15657","504.38013","4.06525","3.06589","0.02113","192.58896"
"250.00000","4.16497","503.57812","4.07369","3.07433","0.02117","192.28271"
"250.50000","4.17307","502.72354","4.08183","3.08247","0.02121","191.95642"
"251.00000","4.18157","502.04269","4.09036","3.09100","0.02126","191.69644"
"251.50000","4.18970","501.15656","4.09854","3.09918","0.02130","191.35809"
"252.00000","4.19849","500.51459","4.10736","3.10800","0.02134","191.11296"
"252.50000","4.20637","499.21088","4.11531","3.11595","0.02139","190.61516"
"253.00000","4.21511","498.38562","4.12409","3.12473","0.02143","190.30005"
"253.50000","4.22317","496.91568","4.13222","3.13286","0.02147","189.73878"
"254.00000","4.23181","495.71283","4.14092","3.14156","0.02152","189.27950"
"254.50000","4.23978","494.07574","4.14897","3.14962","0.02156","188.65440"
"255.00000","4.24818","492.72208","4.15745","3.15809","0.02161","188.13753"
"255.50000","4.25664","491.29749","4.16597","3.16661","0.02165","187.59357"
"256.00000","4.26468","489.93384","4.17409","3.17473","0.02169","187.07288"
"256.50000","4.27330","488.64438","4.18277","3.18341","0.02174","186.58052"
"257.00000","4.28138","487.21600","4.19094","3.19158","0.02178","186.03513"
"257.50000","4.29023","486.24249","4.19985","3.20049","0.02183","185.66341"
"258.00000","4.29801","484.48267","4.20773","3.20837","0.02187","184.99144"
"258.50000","4.30683","483.33002","4.21661","3.21725","0.02191","184.55133"
"259.00000","4.31481","481.69003","4.22468","3.22532","0.02195","183.92513"
"259.50000","4.32339","480.24622","4.23335","3.23399","0.02200","183.37383"
"260.00000","4.33149","478.67392","4.24153","3.24217","0.02204","182.77347"
"260.50000","4.33981","477.30096","4.24993","3.25057","0.02209","182.24924"
"261.00000","4.34834","476.08636","4.25853","3.25917","0.02213","181.78546"
"261.50000","4.35633","474.89380","4.26659","3.26723","0.02217","181.33009"
"262.00000","4.36506","473.90051","4.27537","3.27601","0.02222","180.95084"
"262.50000","4.37305","472.58530","4.28344","3.28408","0.02226","180.44864"
"263.00000","4.38196","471.81339","4.29239","3.29303","0.02231","180.15390"
"263.50000","4.38978","470.47961","4.30029","3.30093","0.02235","179.64462"
"264.00000","4.39840","469.68018","4.30896","3.30960","0.02239","179.33937"
"264.50000","4.40653","468.19669","4.31717","3.31781","0.02244","178.77292"
"265.00000","4.41493","465.59097","4.32571","3.32635","0.02248","177.77797"
"265.50000","4.42315","462.95599","4.33409","3.33473","0.02252","176.77185"
"266.00000","4.43140","457.92252","4.34263","3.34327","0.02257","174.84990"
"266.50000","4.44004","454.25201","4.35148","3.35212","0.02261","173.44838"
"267.00000","4.44804","451.88461","4.35961","3.36025","0.02266","172.54443"
"267.50000","4.45673","450.33777","4.36839","3.36903","0.02270","171.95380"
"268.00000","4.46476","448.86884","4.37650","3.37714","0.02274","171.39291"
"268.50000","4.47356","447.95126","4.38536","3.38600","0.02279","171.04256"
"269.00000","4.48139","446.65680","4.39326","3.39390","0.02283","170.54828"
"269.50000","4.49000","445.87735","4.40191","3.40255","0.02288","170.25067"
"270.00000","4.49819","445.01279","4.41015","3.41079","0.02292","169.92055"
"270.50000","4.50652","444.31171","4.41852","3.41916","0.02296","169.65285"
"271.00000","4.51486","443.62497","4.42690","3.42754","0.02301","169.39062"
"271.50000","4.52311","442.65576","4.43521","3.43585","0.02305","169.02055"
"272.00000","4.53181","441.91125","4.44394","3.44458","0.02309","168.73628"
"272.50000","4.53965","441.04950","4.45184","3.45248","0.02314","168.40723"
"273.00000","4.54848","440.47128","4.46070","3.46134","0.02318","168.18645"
"273.50000","4.55639","439.51654","4.46867","3.46931","0.02322","167.82190"
"274.00000","4.56524","439.09891","4.47754","3.47818","0.02327","167.66243"
"274.50000","4.57309","438.27106","4.48543","3.48607","0.02331","167.34633"
"275.00000","4.58165","437.56799","4.49404","3.49468","0.02335","167.07788"
"275.29100","4.58623","436.96793","4.49865","3.49929","0.02338","166.84875"