File: flexion/5_axis/Specimen_RawData_6.csv
Specimen properties : Specimen label,"6"
Specimen properties : Support span,"72.00",mm
Specimen properties : Thickness,"4.48",mm
Specimen properties : Width,"13.15",mm
Maximum Load : Maximum Load,"602.3",N
Tangent Modulus of Elasticity : Tangent Modulus of Elasticity,"28956926455.23980",Pa
Test : Rate 1,"1.00000",mm/min
Specimen notes : Specimen note 1,""

Time,Displacement,Load,Flexure extension,Corrected extension,Flexure strain (Corrected extension),Flexure stress
(s),(mm),(N),(mm),(mm),(mm/mm),(MPa)
"0.00000","0.00000","9.11407","0.00079","-1.04672","0.00000","3.72953"
"0.40000","0.00442","10.61249","0.00456","-1.04295","0.00002","4.34269"
"0.80000","0.01150","13.15794","0.01055","-1.03697","0.00005","5.38431"
"1.20000","0.01828","15.44788","0.01634","-1.03118","0.00008","6.32136"
"1.60000","0.02504","17.73700","0.02255","-1.02496","0.00012","7.25809"
"2.00000","0.03138","19.84340","0.02845","-1.01906","0.00015","8.12004"
"2.40000","0.03798","21.82890","0.03462","-1.01289","0.00018","8.93252"
"2.80000","0.04452","23.89769","0.04073","-1.00678","0.00021","9.77908"
"3.20000","0.05141","25.87837","0.04720","-1.00031","0.00024","10.58958"
"3.60000","0.05845","28.27385","0.05373","-0.99378","0.00028","11.56983"
"4.00000","0.06492","30.16795","0.05980","-0.98771","0.00031","12.34491"
"4.40000","0.07152","32.17049","0.06599","-0.98153","0.00034","13.16436"
"4.80000","0.07796","34.27040","0.07198","-0.97554","0.00037","14.02365"
"5.20000","0.08459","36.32653","0.07824","-0.96928","0.00041","14.86503"
"5.60000","0.09131","38.37548","0.08469","-0.96282","0.00044","15.70347"
"6.00000","0.09828","40.65423","0.09134","-0.95617","0.00047","16.63595"
"6.40000","0.10504","42.66473","0.09784","-0.94968","0.00051","17.45866"
"6.80000","0.11144","44.69396","0.10396","-0.94355","0.00054","18.28904"
"7.20000","0.11804","46.69390","0.11029","-0.93722","0.00057","19.10743"
"7.60000","0.12453","48.70013","0.11652","-0.93099","0.00060","19.92838"
"8.00000","0.13131","50.85101","0.12301","-0.92451","0.00064","20.80853"
"8.40000","0.13831","52.99270","0.12972","-0.91779","0.00067","21.68493"
"8.80000","0.14505","55.09966","0.13618","-0.91133","0.00071","22.54711"
"9.20000","0.15157","57.21023","0.14241","-0.90510","0.00074","23.41077"
"9.60000","0.15800","59.19243","0.14861","-0.89890","0.00077","24.22190"
"10.00000","0.16457","61.33343","0.15493","-0.89259","0.00080","25.09801"
"10.40000","0.17123","63.36910","0.16135","-0.88616","0.00084","25.93102"
"10.80000","0.17814","65.58881","0.16800","-0.87951","0.00087","26.83933"
"11.20000","0.18515","67.80648","0.17475","-0.87276","0.00091","27.74682"
"11.60000","0.19152","69.95747","0.18087","-0.86664","0.00094","28.62702"
"12.00000","0.19810","72.13379","0.18719","-0.86032","0.00097","29.51758"
"12.40000","0.20461","74.04324","0.19349","-0.85403","0.00100","30.29894"
"12.80000","0.21125","76.33315","0.19985","-0.84767","0.00104","31.23598"
"13.20000","0.21814","78.63135","0.20647","-0.84104","0.00107","32.17642"
"13.60000","0.22493","80.85563","0.21301","-0.83451","0.00110","33.08661"
"14.00000","0.23165","83.04278","0.21947","-0.82805","0.00114","33.98160"
"14.40000","0.23802","85.10140","0.22560","-0.82192","0.00117","34.82400"
"14.80000","0.24470","87.23121","0.23202","-0.81549","0.00120","35.69553"
"15.20000","0.25125","89.39716","0.23836","-0.80915","0.00124","36.58185"
"15.60000","0.25803","91.61765","0.24493","-0.80259","0.00127","37.49049"
"16.00000","0.26512","93.99535","0.25178","-0.79573","0.00131","38.46346"
"16.40000","0.27151","96.11773","0.25797","-0.78954","0.00134","39.33195"
"16.80000","0.27819","98.23743","0.26444","-0.78308","0.00137","40.19934"
"17.20000","0.28459","100.40054","0.27063","-0.77688","0.00140","41.08450"
"17.60000","0.29127","102.67149","0.27709","-0.77042","0.00144","42.01379"
"18.00000","0.29801","105.00391","0.28360","-0.76392","0.00147","42.96823"
"18.40000","0.30497","107.27988","0.29034","-0.75718","0.00151","43.89957"
"18.80000","0.31177","109.71009","0.29690","-0.75062","0.00154","44.89402"
"19.20000","0.31807","111.69064","0.30301","-0.74451","0.00157","45.70448"
"19.60000","0.32471","114.08745","0.30941","-0.73810","0.00160","46.68526"
"20.00000","0.33118","116.21030","0.31567","-0.73185","0.00164","47.55395"
"20.40000","0.33799","118.57893","0.32225","-0.72526","0.00167","48.52321"
"20.80000","0.34497","121.10858","0.32898","-0.71853","0.00171","49.55836"
"21.20000","0.35169","123.32895","0.33549","-0.71202","0.00174","50.46694"
"21.60000","0.35823","125.62424","0.34180","-0.70571","0.00177","51.40619"
"22.00000","0.36466","127.74567","0.34802","-0.69949","0.00180","52.27429"
"22.40000","0.37127","130.05785","0.35441","-0.69311","0.00184","53.22045"
"22.80000","0.37787","132.35634","0.36079","-0.68673","0.00187","54.16101"
"23.20000","0.38482","134.81833","0.36749","-0.68002","0.00191","55.16846"
"23.60000","0.39178","137.32491","0.37422","-0.67330","0.00194","56.19417"
"24.00000","0.39820","139.50647","0.38042","-0.66709","0.00197","57.08688"
"24.40000","0.40471","141.66371","0.38672","-0.66079","0.00201","57.96964"
"24.80000","0.41129","144.07419","0.39307","-0.65445","0.00204","58.95602"
"25.20000","0.41792","146.26375","0.39948","-0.64803","0.00207","59.85200"
"25.60000","0.42484","148.64363","0.40618","-0.64133","0.00211","60.82586"
"26.00000","0.43164","151.13396","0.41273","-0.63478","0.00214","61.84492"
"26.40000","0.43829","153.46552","0.41915","-0.62836","0.00217","62.79901"
"26.80000","0.44472","155.69524","0.42537","-0.62214","0.00221","63.71142"
"27.20000","0.45134","157.99236","0.43176","-0.61575","0.00224","64.65141"
"27.60000","0.45789","160.23958","0.43812","-0.60939","0.00227","65.57099"
"28.00000","0.46468","162.67061","0.44471","-0.60280","0.00231","66.56579"
"28.40000","0.47178","165.32446","0.45159","-0.59592","0.00234","67.65176"
"28.80000","0.47826","167.51401","0.45788","-0.58963","0.00237","68.54774"
"29.20000","0.48484","170.04967","0.46424","-0.58327","0.00241","69.58534"
"29.60000","0.49130","172.16754","0.47052","-0.57699","0.00244","70.45199"
"30.00000","0.49793","174.69080","0.47694","-0.57057","0.00247","71.48452"
"30.40000","0.50468","177.05460","0.48349","-0.56403","0.00251","72.45180"
"30.80000","0.51154","179.69864","0.49012","-0.55739","0.00254","73.53376"
"31.20000","0.51836","182.26544","0.49673","-0.55079","0.00258","74.58411"
"31.60000","0.52472","184.41505","0.50290","-0.54461","0.00261","75.46375"
"32.00000","0.53141","186.98590","0.50937","-0.53815","0.00264","76.51575"
"32.40000","0.53791","189.20511","0.51568","-0.53183","0.00267","77.42386"
"32.80000","0.54468","191.75476","0.52224","-0.52527","0.00271","78.46719"
"33.20000","0.55165","194.30341","0.52899","-0.51852","0.00274","79.51012"
"33.60000","0.55828","196.75708","0.53541","-0.51210","0.00278","80.51418"
"34.00000","0.56490","199.18694","0.54183","-0.50568","0.00281","81.50848"
"34.40000","0.57128","201.57117","0.54801","-0.49950","0.00284","82.48412"
"34.80000","0.57796","203.88281","0.55450","-0.49301","0.00288","83.43007"
"35.20000","0.58458","206.35945","0.56092","-0.48659","0.00291","84.44352"
"35.60000","0.59155","208.94553","0.56769","-0.47983","0.00294","85.50176"
"36.00000","0.59841","211.42857","0.57435","-0.47316","0.00298","86.51784"
"36.40000","0.60485","213.78584","0.58060","-0.46692","0.00301","87.48244"
"36.80000","0.61142","216.15254","0.58698","-0.46053","0.00304","88.45091"
"37.20000","0.61790","218.48509","0.59327","-0.45424","0.00308","89.40540"
"37.60000","0.62460","220.90660","0.59977","-0.44774","0.00311","90.39630"
"38.00000","0.63152","223.34102","0.60650","-0.44101","0.00314","91.39248"
"38.40000","0.63833","225.83212","0.61312","-0.43440","0.00318","92.41186"
"38.80000","0.64494","228.24525","0.61954","-0.42798","0.00321","93.39932"
"39.20000","0.65141","230.57504","0.62581","-0.42170","0.00324","94.35268"
"39.60000","0.65795","232.97214","0.63217","-0.41535","0.00328","95.33360"
"40.00000","0.66455","235.18610","0.63859","-0.40892","0.00331","96.23956"
"40.40000","0.67137","237.33075","0.64523","-0.40228","0.00335","97.11716"
"40.80000","0.67845","239.77985","0.65212","-0.39539","0.00338","98.11935"
"41.20000","0.68487","242.12625","0.65835","-0.38916","0.00341","99.07951"
"41.60000","0.69149","244.34866","0.66479","-0.38272","0.00345","99.98894"
"42.00000","0.69797","246.68208","0.67110","-0.37641","0.00348","100.94379"
"42.40000","0.70461","248.96249","0.67756","-0.36995","0.00351","101.87694"
"42.80000","0.71139","251.29327","0.68417","-0.36335","0.00355","102.83071"
"43.20000","0.71826","253.64619","0.69086","-0.35666","0.00358","103.79354"
"43.60000","0.72501","256.05936","0.69742","-0.35010","0.00362","104.78102"
"44.00000","0.73137","258.21027","0.70362","-0.34390","0.00365","105.66119"
"44.40000","0.73806","260.48907","0.71013","-0.33739","0.00368","106.59369"
"44.80000","0.74453","262.73401","0.71643","-0.33109","0.00371","107.51233"
"45.20000","0.75134","265.09204","0.72306","-0.32445","0.00375","108.47725"
"45.60000","0.75838","267.52808","0.72991","-0.31760","0.00378","109.47409"
"46.00000","0.76492","269.87473","0.73627","-0.31124","0.00382","110.43435"
"46.40000","0.77156","272.14679","0.74274","-0.30478","0.00385","111.36409"
"46.80000","0.77799","274.23416","0.74900","-0.29851","0.00388","112.21826"
"47.20000","0.78458","276.45834","0.75543","-0.29209","0.00392","113.12841"
"47.60000","0.79125","278.81189","0.76191","-0.28560","0.00395","114.09149"
"48.00000","0.79818","281.20160","0.76866","-0.27885","0.00399","115.06937"
"48.40000","0.80510","283.61777","0.77539","-0.27212","0.00402","116.05808"
"48.80000","0.81147","285.70178","0.78161","-0.26591","0.00405","116.91088"
"49.20000","0.81811","287.89893","0.78807","-0.25944","0.00409","117.80996"
"49.60000","0.82454","289.95212","0.79435","-0.25316","0.00412","118.65014"
"50.00000","0.83125","292.22171","0.80091","-0.24661","0.00415","119.57887"
"50.40000","0.83816","294.52576","0.80765","-0.23986","0.00419","120.52170"
"50.80000","0.84505","296.86841","0.81439","-0.23312","0.00422","121.48033"
"51.20000","0.85163","298.99744","0.82083","-0.22669","0.00426","122.35154"
"51.60000","0.85802","301.08673","0.82708","-0.22043","0.00429","123.20649"
"52.00000","0.86462","303.28055","0.83353","-0.21398","0.00432","124.10422"
"52.40000","0.87122","305.49976","0.83998","-0.20753","0.00436","125.01233"
"52.80000","0.87807","307.78174","0.84668","-0.20083","0.00439","125.94613"
"53.20000","0.88515","310.18207","0.85360","-0.19391","0.00443","126.92836"
"53.60000","0.89158","312.20691","0.85989","-0.18762","0.00446","127.75694"
"54.00000","0.89814","314.27545","0.86632","-0.18119","0.00449","128.60339"
"54.40000","0.90464","316.31320","0.87268","-0.17483","0.00453","129.43726"
"54.80000","0.91124","318.54169","0.87913","-0.16839","0.00456","130.34917"
"55.20000","0.91801","320.76758","0.88575","-0.16176","0.00459","131.26001"
"55.60000","0.92496","322.90778","0.89256","-0.15495","0.00463","132.13579"
"56.00000","0.93172","325.16641","0.89917","-0.14835","0.00466","133.06004"
"56.40000","0.93807","327.05780","0.90539","-0.14213","0.00469","133.83401"
"56.80000","0.94472","329.13028","0.91190","-0.13561","0.00473","134.68208"
"57.20000","0.95126","331.23260","0.91830","-0.12921","0.00476","135.54236"
"57.60000","0.95793","333.34109","0.92483","-0.12268","0.00480","136.40517"
"58.00000","0.96500","335.47821","0.93176","-0.11575","0.00483","137.27969"
"58.40000","0.97154","337.62375","0.93815","-0.10936","0.00486","138.15765"
"58.80000","0.97823","339.73297","0.94470","-0.10281","0.00490","139.02077"
"59.20000","0.98468","341.35211","0.95104","-0.09647","0.00493","139.68332"
"59.60000","0.99130","343.43991","0.95753","-0.08998","0.00496","140.53766"
"60.00000","0.99796","345.41373","0.96406","-0.08345","0.00500","141.34537"
"60.40000","1.00489","347.66049","0.97085","-0.07667","0.00503","142.26476"
"60.80000","1.01176","349.79471","0.97759","-0.06993","0.00507","143.13809"
"61.20000","1.01814","351.66901","0.98384","-0.06367","0.00510","143.90506"
"61.60000","1.02473","353.63977","0.99031","-0.05721","0.00513","144.71150"
"62.00000","1.03124","355.63614","0.99669","-0.05082","0.00517","145.52843"
"62.40000","1.03797","357.58691","1.00329","-0.04423","0.00520","146.32671"
"62.80000","1.04490","359.62302","1.01009","-0.03743","0.00524","147.15988"
"63.20000","1.05171","361.63892","1.01677","-0.03074","0.00527","147.98480"
"63.60000","1.05834","363.57999","1.02328","-0.02424","0.00531","148.77910"
"64.00000","1.06468","365.47153","1.02949","-0.01802","0.00534","149.55313"
"64.40000","1.07129","367.37976","1.03598","-0.01153","0.00537","150.33400"
"64.80000","1.07789","369.34299","1.04245","-0.00506","0.00541","151.13736"
"65.20000","1.08477","371.51617","1.04919","0.00168","0.00544","152.02664"
"65.60000","1.09176","373.62802","1.05605","0.00854","0.00548","152.89082"
"66.00000","1.09821","375.43823","1.06239","0.01488","0.00551","153.63158"
"66.40000","1.10481","377.30667","1.06887","0.02135","0.00554","154.39615"
"66.80000","1.11130","379.28552","1.07523","0.02771","0.00558","155.20590"
"67.20000","1.11793","381.10904","1.08174","0.03423","0.00561","155.95210"
"67.60000","1.12471","383.06607","1.08840","0.04088","0.00564","156.75293"
"68.00000","1.13160","385.03644","1.09517","0.04765","0.00568","157.55922"
"68.40000","1.13840","387.03424","1.10184","0.05432","0.00571","158.37672"
"68.80000","1.14475","388.88605","1.10807","0.06056","0.00575","159.13449"
"69.20000","1.15134","390.70700","1.11455","0.06703","0.00578","159.87964"
"69.60000","1.15789","392.50970","1.12100","0.07349","0.00581","160.61732"
"70.00000","1.16470","394.44928","1.12770","0.08018","0.00585","161.41101"
"70.40000","1.17173","396.48236","1.13461","0.08709","0.00588","162.24295"
"70.80000","1.17827","398.40494","1.14104","0.09352","0.00592","163.02968"
"71.20000","1.18490","400.22278","1.14756","0.10005","0.00595","163.77356"
"71.60000","1.19131","401.89728","1.15388","0.10637","0.00598","164.45877"
"72.00000","1.19796","403.76328","1.16042","0.11291","0.00602","165.22235"
"72.40000","1.20461","405.58487","1.16697","0.11946","0.00605","165.96776"
"72.80000","1.21155","407.60818","1.17379","0.12628","0.00609","166.79570"
"73.20000","1.21840","409.42896","1.18055","0.13303","0.00612","167.54077"
"73.60000","1.22481","411.10562","1.18685","0.13934","0.00615","168.22688"
"74.00000","1.23145","412.80054","1.19340","0.14589","0.00619","168.92044"
"74.40000","1.23792","414.60950","1.19977","0.15225","0.00622","169.66069"
"74.80000","1.24466","416.49240","1.20640","0.15889","0.00626","170.43118"
"75.20000","1.25156","418.35495","1.21320","0.16569","0.00629","171.19334"
"75.60000","1.25827","420.33884","1.21979","0.17227","0.00632","172.00517"
"76.00000","1.26494","421.97452","1.22637","0.17886","0.00636","172.67450"
"76.40000","1.27137","423.59274","1.23270","0.18519","0.00639","173.33669"
"76.80000","1.27797","425.34018","1.23920","0.19169","0.00643","174.05174"
"77.20000","1.28457","427.08420","1.24571","0.19820","0.00646","174.76541"
"77.60000","1.29150","429.05862","1.25252","0.20501","0.00649","175.57335"
"78.00000","1.29844","430.83160","1.25936","0.21185","0.00653","176.29887"
"78.40000","1.30485","432.48740","1.26568","0.21816","0.00656","176.97643"
"78.80000","1.31147","434.23486","1.27220","0.22469","0.00660","177.69150"
"79.20000","1.31795","435.80649","1.27859","0.23108","0.00663","178.33463"
"79.60000","1.32456","437.39957","1.28511","0.23760","0.00666","178.98651"
"80.00000","1.33141","439.41293","1.29184","0.24433","0.00670","179.81039"
"80.40000","1.33834","441.27106","1.29867","0.25116","0.00673","180.57076"
"80.80000","1.34509","442.90680","1.30532","0.25781","0.00677","181.24011"
"81.20000","1.35143","444.41135","1.31158","0.26407","0.00680","181.85577"
"81.60000","1.35798","446.00977","1.31804","0.27053","0.00683","182.50986"
"82.00000","1.36452","447.68552","1.32448","0.27697","0.00687","183.19559"
"82.40000","1.37132","449.46176","1.33118","0.28367","0.00690","183.92244"
"82.80000","1.37838","451.43906","1.33813","0.29062","0.00694","184.73157"
"83.20000","1.38494","452.79126","1.34461","0.29710","0.00697","185.28490"
"83.60000","1.39152","454.47849","1.35110","0.30358","0.00701","185.97531"
"84.00000","1.39804","456.08920","1.35752","0.31001","0.00704","186.63443"
"84.40000","1.40462","457.63660","1.36402","0.31651","0.00707","187.26764"
"84.80000","1.41128","459.29459","1.37058","0.32307","0.00711","187.94609"
"85.20000","1.41818","461.07968","1.37738","0.32986","0.00714","188.67656"
"85.60000","1.42513","462.69788","1.38423","0.33672","0.00718","189.33875"
"86.00000","1.43142","464.05170","1.39045","0.34293","0.00721","189.89273"
"86.40000","1.43809","465.75937","1.39702","0.34951","0.00724","190.59152"
"86.80000","1.44457","467.15411","1.40342","0.35591","0.00728","191.16226"
"87.20000","1.45134","468.85287","1.41009","0.36258","0.00731","191.85741"
"87.60000","1.45828","470.60806","1.41693","0.36942","0.00735","192.57564"
"88.00000","1.46498","471.98026","1.42356","0.37605","0.00738","193.13715"
"88.40000","1.47164","473.72662","1.43012","0.38260","0.00742","193.85176"
"88.80000","1.47805","475.11859","1.43645","0.38893","0.00745","194.42137"
"89.20000","1.48464","476.37875","1.44297","0.39545","0.00748","194.93703"
"89.60000","1.49119","477.91614","1.44943","0.40192","0.00752","195.56615"
"90.00000","1.49811","479.14224","1.45628","0.40876","0.00755","196.06787"
"90.40000","1.50515","480.72455","1.46323","0.41572","0.00759","196.71536"
"90.80000","1.51153","482.02112","1.46954","0.42202","0.00762","197.24593"
"91.20000","1.51815","483.33499","1.47608","0.42856","0.00765","197.78357"
"91.60000","1.52463","484.81161","1.48248","0.43496","0.00769","198.38782"
"92.00000","1.53126","486.34457","1.48902","0.44151","0.00772","199.01511"
"92.40000","1.53804","487.74957","1.49572","0.44821","0.00776","199.59004"
"92.80000","1.54496","489.47241","1.50254","0.45503","0.00779","200.29504"
"93.20000","1.55168","490.90866","1.50918","0.46167","0.00783","200.88277"
"93.60000","1.55806","492.18945","1.51550","0.46799","0.00786","201.40686"
"94.00000","1.56467","493.54691","1.52204","0.47453","0.00789","201.96234"
"94.40000","1.57119","494.88480","1.52849","0.48098","0.00793","202.50981"
"94.80000","1.57806","496.55096","1.53528","0.48777","0.00796","203.19162"
"95.20000","1.58505","498.04492","1.54220","0.49469","0.00800","203.80296"
"95.60000","1.59163","499.45874","1.54871","0.50119","0.00803","204.38150"
"96.00000","1.59818","500.80804","1.55520","0.50768","0.00806","204.93364"
"96.40000","1.60467","502.11829","1.56161","0.51410","0.00810","205.46980"
"96.80000","1.61124","503.50995","1.56812","0.52061","0.00813","206.03928"
"97.20000","1.61792","504.85803","1.57472","0.52721","0.00817","206.59093"
"97.60000","1.62487","506.44461","1.58160","0.53409","0.00820","207.24016"
"98.00000","1.63177","507.86423","1.58843","0.54091","0.00824","207.82108"
"98.40000","1.63817","508.97925","1.59477","0.54726","0.00827","208.27736"
"98.80000","1.64473","510.24142","1.60127","0.55376","0.00830","208.79384"
"99.20000","1.65126","511.57404","1.60773","0.56022","0.00834","209.33916"
"99.60000","1.65796","512.95471","1.61436","0.56684","0.00837","209.90413"
"100.00000","1.66493","514.39081","1.62126","0.57374","0.00841","210.49179"
"100.40000","1.67157","515.52417","1.62784","0.58033","0.00844","210.95557"
"100.80000","1.67824","516.81195","1.63445","0.58694","0.00847","211.48254"
"101.20000","1.68467","517.88556","1.64082","0.59331","0.00851","211.92188"
"101.60000","1.69135","519.14661","1.64745","0.59993","0.00854","212.43790"
"102.00000","1.69795","520.32172","1.65398","0.60647","0.00858","212.91876"
"102.40000","1.70475","521.61829","1.66072","0.61321","0.00861","213.44933"
"102.80000","1.71181","523.11572","1.66770","0.62019","0.00865","214.06209"
"103.20000","1.71814","524.23157","1.67398","0.62647","0.00868","214.51869"
"103.60000","1.72480","525.34424","1.68058","0.63307","0.00871","214.97400"
"104.00000","1.73124","526.57031","1.68696","0.63944","0.00875","215.47572"
"104.40000","1.73794","527.78333","1.69360","0.64608","0.00878","215.97209"
"104.80000","1.74477","529.16638","1.70036","0.65285","0.00882","216.53804"
"105.20000","1.75168","530.30493","1.70721","0.65970","0.00885","217.00395"
"105.60000","1.75837","531.64081","1.71384","0.66632","0.00889","217.55060"
"106.00000","1.76471","532.59692","1.72013","0.67261","0.00892","217.94185"
"106.40000","1.77135","533.73730","1.72671","0.67919","0.00895","218.40849"
"106.80000","1.77785","535.06525","1.73314","0.68563","0.00899","218.95190"
"107.20000","1.78472","536.26849","1.73995","0.69244","0.00902","219.44427"
"107.60000","1.79167","537.48975","1.74685","0.69933","0.00906","219.94402"
"108.00000","1.79829","538.69897","1.75340","0.70589","0.00909","220.43884"
"108.40000","1.80486","539.80511","1.75992","0.71240","0.00913","220.89148"
"108.80000","1.81129","540.89496","1.76630","0.71878","0.00916","221.33745"
"109.20000","1.81790","541.94580","1.77285","0.72534","0.00919","221.76746"
"109.60000","1.82461","543.28564","1.77950","0.73198","0.00923","222.31573"
"110.00000","1.83160","544.44287","1.78643","0.73892","0.00926","222.78928"
"110.40000","1.83841","545.63556","1.79318","0.74567","0.00930","223.27733"
"110.80000","1.84480","546.69830","1.79953","0.75201","0.00933","223.71222"
"111.20000","1.85134","547.70929","1.80602","0.75850","0.00936","224.12592"
"111.60000","1.85792","548.83112","1.81254","0.76502","0.00940","224.58498"
"112.00000","1.86461","550.00726","1.81918","0.77166","0.00943","225.06625"
"112.40000","1.87164","551.35986","1.82613","0.77862","0.00947","225.61975"
"112.80000","1.87833","552.40533","1.83278","0.78526","0.00950","226.04756"
"113.20000","1.88489","553.34113","1.83929","0.79178","0.00954","226.43050"
"113.60000","1.89137","554.36969","1.84572","0.79821","0.00957","226.85139"
"114.00000","1.89798","555.31708","1.85228","0.80477","0.00960","227.23907"
"114.40000","1.90457","556.35620","1.85882","0.81131","0.00964","227.66429"
"114.80000","1.91143","557.49835","1.86563","0.81812","0.00967","228.13165"
"115.20000","1.91845","558.49878","1.87261","0.82509","0.00971","228.54105"
"115.60000","1.92487","559.17352","1.87898","0.83147","0.00974","228.81715"
"116.00000","1.93148","559.67950","1.88557","0.83806","0.00978","229.02420"
"116.40000","1.93794","559.64734","1.89203","0.84452","0.00981","229.01103"
"116.80000","1.94458","560.08289","1.89865","0.85114","0.00984","229.18927"
"117.20000","1.95145","560.96777","1.90548","0.85796","0.00988","229.55136"
"117.60000","1.95823","561.62030","1.91223","0.86471","0.00992","229.81839"
"118.00000","1.96500","558.96381","1.91913","0.87161","0.00995","228.73134"
"118.40000","1.97137","557.06927","1.92559","0.87808","0.00998","227.95609"
"118.80000","1.97803","557.01617","1.93225","0.88474","0.01002","227.93436"
"119.20000","1.98454","556.65717","1.93878","0.89126","0.01005","227.78745"
"119.60000","1.99140","557.12189","1.94562","0.89810","0.01009","227.97760"
"120.00000","1.99844","557.90637","1.95262","0.90511","0.01012","228.29863"
"120.40000","2.00489","558.35608","1.95905","0.91154","0.01016","228.48265"
"120.80000","2.01153","558.97253","1.96565","0.91814","0.01019","228.73491"
"121.20000","2.01794","559.58179","1.97204","0.92452","0.01023","228.98421"
"121.60000","2.02462","560.36481","1.97868","0.93116","0.01026","229.30463"
"122.00000","2.03131","561.05566","1.98534","0.93783","0.01029","229.58733"
"122.40000","2.03829","561.66956","1.99229","0.94477","0.01033","229.83855"
"122.80000","2.04507","560.61108","1.99911","0.95160","0.01037","229.40541"
"123.20000","2.05146","560.42358","2.00552","0.95800","0.01040","229.32867"
"123.60000","2.05807","560.69080","2.01211","0.96460","0.01043","229.43802"
"124.00000","2.06454","561.08966","2.01856","0.97105","0.01047","229.60124"
"124.40000","2.07127","561.37817","2.02528","0.97777","0.01050","229.71930"
"124.80000","2.07827","561.68628","2.03226","0.98475","0.01054","229.84538"
"125.20000","2.08501","561.83600","2.03900","0.99149","0.01057","229.90665"
"125.60000","2.09154","561.88538","2.04553","0.99801","0.01061","229.92685"
"126.00000","2.09805","562.22595","2.05203","1.00451","0.01064","230.06622"
"126.40000","2.10461","562.67554","2.05856","1.01105","0.01067","230.25020"
"126.80000","2.11124","563.29022","2.06516","1.01764","0.01071","230.50172"
"127.20000","2.11810","563.96765","2.07199","1.02447","0.01074","230.77893"
"127.60000","2.12511","564.77484","2.07896","1.03145","0.01078","231.10924"
"128.00000","2.13151","565.31812","2.08533","1.03782","0.01081","231.33156"
"128.40000","2.13811","566.12476","2.09189","1.04438","0.01085","231.66164"
"128.80000","2.14462","566.81293","2.09837","1.05086","0.01088","231.94324"
"129.20000","2.15127","567.57489","2.10498","1.05747","0.01091","232.25504"
"129.60000","2.15816","568.46735","2.11182","1.06431","0.01095","232.62024"
"130.00000","2.16497","569.26331","2.11860","1.07109","0.01099","232.94595"
"130.40000","2.17161","569.96326","2.12521","1.07769","0.01102","233.23238"
"130.80000","2.17802","570.66858","2.13158","1.08407","0.01105","233.52100"
"131.20000","2.18470","571.31549","2.13823","1.09072","0.01109","233.78572"
"131.60000","2.19119","571.83221","2.14469","1.09718","0.01112","233.99716"
"132.00000","2.19803","568.36914","2.15171","1.10419","0.01116","232.58005"
"132.40000","2.20509","567.23004","2.15882","1.11130","0.01119","232.11392"
"132.80000","2.21154","567.33142","2.16526","1.11775","0.01123","232.15541"
"133.20000","2.21819","568.03326","2.17188","1.12436","0.01126","232.44261"
"133.60000","2.22463","568.55621","2.17829","1.13078","0.01129","232.65660"
"134.00000","2.23124","569.22021","2.18487","1.13736","0.01133","232.92831"
"134.40000","2.23798","570.00470","2.19157","1.14406","0.01136","233.24933"
"134.80000","2.24491","570.82397","2.19847","1.15095","0.01140","233.58458"
"135.20000","2.25172","571.79272","2.20523","1.15772","0.01143","233.98100"
"135.60000","2.25808","572.35565","2.21156","1.16405","0.01147","234.21135"
"136.00000","2.26472","573.04480","2.21817","1.17066","0.01150","234.49336"
"136.40000","2.27120","573.75446","2.22461","1.17710","0.01154","234.78375"
"136.80000","2.27797","574.45563","2.23135","1.18383","0.01157","235.07068"
"137.20000","2.28492","575.35352","2.23826","1.19074","0.01161","235.43810"
"137.60000","2.29169","576.08167","2.24499","1.19748","0.01164","235.73607"
"138.00000","2.29824","576.77887","2.25151","1.20399","0.01167","236.02136"
"138.40000","2.30466","577.39276","2.25789","1.21038","0.01171","236.27257"
"138.80000","2.31126","578.02234","2.26447","1.21695","0.01174","236.53020"
"139.20000","2.31791","578.53503","2.27110","1.22358","0.01178","236.73999"
"139.60000","2.32484","579.22650","2.27799","1.23047","0.01181","237.02295"
"140.00000","2.33182","580.07751","2.28493","1.23741","0.01185","237.37119"
"140.40000","2.33820","580.13892","2.29130","1.24379","0.01188","237.39632"
"140.80000","2.34476","580.30664","2.29786","1.25034","0.01191","237.46495"
"141.20000","2.35127","580.63586","2.30435","1.25684","0.01195","237.59967"
"141.60000","2.35791","580.70557","2.31099","1.26347","0.01198","237.62819"
"142.00000","2.36478","580.96265","2.31784","1.27033","0.01202","237.73338"
"142.40000","2.37167","581.20990","2.32472","1.27721","0.01205","237.83456"
"142.80000","2.37833","581.39508","2.33137","1.28386","0.01209","237.91034"
"143.20000","2.38471","581.51605","2.33775","1.29023","0.01212","237.95984"
"143.60000","2.39134","581.85626","2.34436","1.29684","0.01216","238.09906"
"144.00000","2.39794","582.17517","2.35094","1.30343","0.01219","238.22957"
"144.40000","2.40466","582.48102","2.35765","1.31013","0.01222","238.35472"
"144.80000","2.41175","582.92657","2.36472","1.31720","0.01226","238.53703"
"145.20000","2.41818","583.08893","2.37114","1.32363","0.01229","238.60347"
"145.60000","2.42486","583.64154","2.37779","1.33028","0.01233","238.82961"
"146.00000","2.43131","583.99017","2.38422","1.33671","0.01236","238.97227"
"146.40000","2.43795","584.35675","2.39085","1.34334","0.01240","239.12228"
"146.80000","2.44471","585.09247","2.39757","1.35006","0.01243","239.42334"
"147.20000","2.45162","585.63629","2.40446","1.35694","0.01247","239.64587"
"147.60000","2.45842","586.17126","2.41123","1.36372","0.01250","239.86479"
"148.00000","2.46477","586.50043","2.41757","1.37005","0.01254","239.99948"
"148.40000","2.47135","586.97467","2.42412","1.37661","0.01257","240.19354"
"148.80000","2.47787","587.32819","2.43063","1.38312","0.01260","240.33821"
"149.20000","2.48466","587.91431","2.43738","1.38987","0.01264","240.57805"
"149.60000","2.49165","588.54974","2.44435","1.39684","0.01267","240.83807"
"150.00000","2.49836","588.78918","2.45104","1.40353","0.01271","240.93605"
"150.40000","2.50496","589.12549","2.45763","1.41011","0.01274","241.07367"
"150.80000","2.51132","589.28717","2.46398","1.41646","0.01278","241.13983"
"151.20000","2.51792","589.67584","2.47056","1.42304","0.01281","241.29887"
"151.60000","2.52458","590.01001","2.47720","1.42969","0.01284","241.43562"
"152.00000","2.53152","590.48181","2.48412","1.43661","0.01288","241.62869"
"152.40000","2.53843","591.04181","2.49101","1.44350","0.01292","241.85785"
"152.80000","2.54483","591.27753","2.49739","1.44988","0.01295","241.95430"
"153.20000","2.55144","591.44708","2.50400","1.45649","0.01298","242.02368"
"153.60000","2.55793","591.61432","2.51048","1.46297","0.01302","242.09212"
"154.00000","2.56457","591.77948","2.51712","1.46961","0.01305","242.15970"
"154.40000","2.57148","592.09668","2.52401","1.47650","0.01309","242.28951"
"154.80000","2.57833","592.23047","2.53086","1.48334","0.01312","242.34425"
"155.20000","2.58500","592.05737","2.53753","1.49001","0.01316","242.27342"
"155.60000","2.59139","592.10199","2.54392","1.49640","0.01319","242.29167"
"156.00000","2.59796","592.18811","2.55049","1.50298","0.01322","242.32692"
"156.40000","2.60453","592.39764","2.55705","1.50954","0.01326","242.41266"
"156.80000","2.61142","592.73785","2.56392","1.51640","0.01329","242.55188"
"157.20000","2.61844","593.17859","2.57092","1.52341","0.01333","242.73222"
"157.60000","2.62488","593.42792","2.57735","1.52984","0.01336","242.83426"
"158.00000","2.63153","593.67133","2.58399","1.53647","0.01340","242.93385"
"158.40000","2.63799","593.96210","2.59043","1.54292","0.01343","243.05284"
"158.80000","2.64458","594.24231","2.59701","1.54950","0.01347","243.16751"
"159.20000","2.65133","594.69781","2.60375","1.55623","0.01350","243.35390"
"159.60000","2.65825","594.92841","2.61065","1.56314","0.01354","243.44826"
"160.00000","2.66504","595.41522","2.61742","1.56990","0.01357","243.64748"
"160.40000","2.67144","595.73871","2.62381","1.57629","0.01360","243.77985"
"160.80000","2.67808","596.10931","2.63043","1.58292","0.01364","243.93149"
"161.20000","2.68457","596.36554","2.63691","1.58940","0.01367","244.03635"
"161.60000","2.69135","596.61871","2.64367","1.59616","0.01371","244.13994"
"162.00000","2.69834","597.15442","2.65064","1.60313","0.01374","244.35916"
"162.40000","2.70493","597.46735","2.65722","1.60971","0.01378","244.48721"
"162.80000","2.71155","597.62451","2.66383","1.61632","0.01381","244.55153"
"163.20000","2.71800","598.03455","2.67026","1.62275","0.01385","244.71931"
"163.60000","2.72463","598.22009","2.67688","1.62937","0.01388","244.79524"
"164.00000","2.73129","598.59521","2.68353","1.63601","0.01391","244.94875"
"164.40000","2.73825","598.97571","2.69047","1.64295","0.01395","245.10445"
"164.80000","2.74512","599.44543","2.69732","1.64980","0.01399","245.29666"
"165.20000","2.75146","599.49817","2.70366","1.65615","0.01402","245.31824"
"165.60000","2.75811","599.80066","2.71029","1.66278","0.01405","245.44202"
"166.00000","2.76458","599.94110","2.71676","1.66925","0.01409","245.49948"
"166.40000","2.77125","600.09766","2.72342","1.67591","0.01412","245.56355"
"166.80000","2.77820","600.42242","2.73035","1.68284","0.01416","245.69644"
"167.20000","2.78502","600.63281","2.73717","1.68966","0.01419","245.78253"
"167.60000","2.79167","600.90607","2.74380","1.69629","0.01423","245.89435"
"168.00000","2.79806","600.98529","2.75019","1.70268","0.01426","245.92677"
"168.40000","2.80464","601.07623","2.75677","1.70925","0.01429","245.96399"
"168.80000","2.81119","601.04346","2.76332","1.71580","0.01433","245.95058"
"169.20000","2.81807","601.32123","2.77018","1.72267","0.01436","246.06424"
"169.60000","2.82513","601.70367","2.77723","1.72972","0.01440","246.22075"
"170.00000","2.83155","601.62891","2.78365","1.73614","0.01443","246.19014"
"170.40000","2.83814","601.67010","2.79024","1.74272","0.01447","246.20700"
"170.80000","2.84468","601.72406","2.79678","1.74927","0.01450","246.22908"
"171.20000","2.85129","601.83185","2.80338","1.75587","0.01454","246.27319"
"171.60000","2.85803","601.93805","2.81012","1.76261","0.01457","246.31665"
"172.00000","2.86492","602.02905","2.81701","1.76949","0.01461","246.35388"
"172.40000","2.87175","602.20068","2.82382","1.77631","0.01464","246.42412"
"172.80000","2.87805","602.12585","2.83013","1.78262","0.01467","246.39349"
"173.20000","2.88473","602.09204","2.83681","1.78929","0.01471","246.37967"
"173.60000","2.89122","602.00531","2.84331","1.79579","0.01474","246.34418"
"174.00000","2.89804","601.96783","2.85013","1.80262","0.01478","246.32884"
"174.40000","2.90506","602.23944","2.85714","1.80962","0.01481","246.43999"
"174.80000","2.91163","602.17975","2.86371","1.81619","0.01485","246.41556"
"175.20000","2.91825","602.05084","2.87033","1.82282","0.01488","246.36281"
"175.60000","2.92468","601.61700","2.87679","1.82927","0.01492","246.18527"
"176.00000","2.93129","601.02142","2.88342","1.83591","0.01495","245.94156"
"176.40000","2.93789","600.33191","2.89005","1.84254","0.01499","245.65941"
"176.80000","2.94483","599.83728","2.89702","1.84950","0.01502","245.45700"
"177.20000","2.95183","599.23303","2.90404","1.85652","0.01506","245.20975"
"177.60000","2.95815","598.29712","2.91041","1.86289","0.01509","244.82675"
"178.00000","2.96475","597.18585","2.91706","1.86954","0.01513","244.37202"
"178.40000","2.97126","596.59613","2.92359","1.87607","0.01516","244.13071"
"178.80000","2.97795","595.97241","2.93030","1.88279","0.01519","243.87547"
"179.20000","2.98481","595.76813","2.93718","1.88967","0.01523","243.79189"
"179.60000","2.99166","595.63660","2.94403","1.89651","0.01527","243.73805"
"180.00000","2.99829","595.49225","2.95067","1.90316","0.01530","243.67899"
"180.40000","3.00469","595.10071","2.95709","1.90958","0.01533","243.51877"
"180.80000","3.01130","594.91632","2.96370","1.91619","0.01537","243.44331"
"181.20000","3.01786","594.82928","2.97027","1.92276","0.01540","243.40770"
"181.60000","3.02478","595.03961","2.97718","1.92966","0.01544","243.49377"
"182.00000","3.03183","595.03705","2.98423","1.93672","0.01547","243.49272"
"182.40000","3.03828","594.94208","2.99069","1.94317","0.01551","243.45386"
"182.80000","3.04481","594.96326","2.99721","1.94970","0.01554","243.46252"
"183.20000","3.05129","594.86249","3.00369","1.95618","0.01557","243.42128"
"183.60000","3.05790","594.96094","3.01030","1.96279","0.01561","243.46158"
"184.00000","3.06465","595.11450","3.01704","1.96953","0.01564","243.52441"
"184.40000","3.07161","595.31030","3.02399","1.97648","0.01568","243.60454"
"184.80000","3.07840","595.29736","3.03079","1.98327","0.01572","243.59924"
"185.20000","3.08479","595.11298","3.03718","1.98967","0.01575","243.52379"
"185.60000","3.09136","594.92328","3.04376","1.99625","0.01578","243.44617"
"186.00000","3.09791","594.91095","3.05031","2.00280","0.01582","243.44112"
"186.40000","3.10466","594.97510","3.05706","2.00954","0.01585","243.46736"
"186.80000","3.11168","595.23462","3.06406","2.01655","0.01589","243.57356"
"187.20000","3.11820","595.28381","3.07058","2.02307","0.01592","243.59369"
"187.60000","3.12487","595.27509","3.07726","2.02975","0.01596","243.59012"
"188.00000","3.13133","595.30719","3.08372","2.03621","0.01599","243.60326"
"188.40000","3.13800","595.26654","3.09038","2.04287","0.01602","243.58662"
"188.80000","3.14464","595.35022","3.09702","2.04951","0.01606","243.62086"
"189.20000","3.15149","595.51410","3.10387","2.05635","0.01609","243.68793"
"189.60000","3.15850","595.69458","3.11087","2.06336","0.01613","243.76178"
"190.00000","3.16479","595.63495","3.11716","2.06965","0.01616","243.73738"
"190.40000","3.17142","595.72766","3.12379","2.07628","0.01620","243.77531"
"190.80000","3.17787","595.65240","3.13024","2.08273","0.01623","243.74452"
"191.20000","3.18465","595.62872","3.13702","2.08951","0.01627","243.73483"
"191.60000","3.19151","595.93250","3.14387","2.09636","0.01630","243.85915"
"192.00000","3.19831","595.82715","3.15067","2.10316","0.01634","243.81602"
"192.40000","3.20499","595.77844","3.15736","2.10984","0.01637","243.79610"
"192.80000","3.21135","595.58569","3.16373","2.11621","0.01640","243.71722"
"193.20000","3.21799","595.30054","3.17038","2.12286","0.01644","243.60054"
"193.60000","3.22451","595.19061","3.17690","2.12939","0.01647","243.55556"
"194.00000","3.23143","595.33044","3.18381","2.13630","0.01651","243.61278"
"194.40000","3.23838","595.50940","3.19075","2.14324","0.01654","243.68600"
"194.80000","3.24492","595.32568","3.19731","2.14979","0.01658","243.61082"
"195.20000","3.25147","595.29211","3.20386","2.15634","0.01661","243.59709"
"195.60000","3.25793","595.11041","3.21032","2.16281","0.01665","243.52274"
"196.00000","3.26459","594.99530","3.21699","2.16948","0.01668","243.47563"
"196.40000","3.27135","594.74542","3.22376","2.17625","0.01672","243.37338"
"196.80000","3.27830","594.79016","3.23071","2.18320","0.01675","243.39169"
"197.20000","3.28501","594.75165","3.23742","2.18991","0.01679","243.37593"
"197.60000","3.29145","594.57013","3.24387","2.19635","0.01682","243.30165"
"198.00000","3.29799","594.22632","3.25042","2.20291","0.01685","243.16096"
"198.40000","3.30456","594.20782","3.25699","2.20948","0.01689","243.15340"
"198.80000","3.31131","594.04382","3.26375","2.21624","0.01692","243.08629"
"199.20000","3.31841","594.08948","3.27085","2.22334","0.01696","243.10497"
"199.60000","3.32499","593.86664","3.27744","2.22993","0.01699","243.01378"
"200.00000","3.33151","593.49841","3.28398","2.23647","0.01703","242.86310"
"200.40000","3.33800","593.11749","3.29048","2.24297","0.01706","242.70723"
"200.80000","3.34462","592.81702","3.29711","2.24960","0.01710","242.58427"
"201.20000","3.35128","592.58337","3.30378","2.25627","0.01713","242.48866"
"201.60000","3.35816","592.42682","3.31067","2.26316","0.01717","242.42459"
"202.00000","3.36508","592.15009","3.31761","2.27009","0.01720","242.31136"
"202.40000","3.37147","591.75372","3.32401","2.27650","0.01724","242.14915"
"202.80000","3.37810","591.36353","3.33067","2.28315","0.01727","241.98949"
"203.20000","3.38461","591.04254","3.33718","2.28967","0.01730","241.85814"
"203.60000","3.39126","590.79114","3.34385","2.29634","0.01734","241.75526"
"204.00000","3.39824","590.53925","3.35084","2.30333","0.01737","241.65219"
"204.40000","3.40490","590.24475","3.35752","2.31000","0.01741","241.53168"
"204.80000","3.41162","589.79950","3.36425","2.31674","0.01744","241.34949"
"205.20000","3.41800","589.16211","3.37066","2.32315","0.01748","241.08865"
"205.60000","3.42465","588.12860","3.37736","2.32985","0.01751","240.66574"
"206.00000","3.43124","587.20459","3.38400","2.33649","0.01755","240.28763"
"206.40000","3.43815","586.19196","3.39096","2.34344","0.01758","239.87326"
"206.80000","3.44513","585.30243","3.39799","2.35047","0.01762","239.50925"
"207.20000","3.45150","584.35596","3.40440","2.35689","0.01765","239.12195"
"207.60000","3.45815","583.57739","3.41109","2.36358","0.01769","238.80336"
"208.00000","3.46457","582.86920","3.41754","2.37003","0.01772","238.51357"
"208.40000","3.47128","582.17828","3.42428","2.37677","0.01776","238.23083"
"208.80000","3.47805","581.62122","3.43108","2.38357","0.01779","238.00288"
"209.20000","3.48505","581.27869","3.43809","2.39058","0.01783","237.86272"
"209.60000","3.49171","580.15015","3.44481","2.39730","0.01786","237.40091"
"210.00000","3.49807","578.96460","3.45123","2.40372","0.01790","236.91577"
"210.40000","3.50468","577.85858","3.45789","2.41038","0.01793","236.46318"
"210.80000","3.51121","576.75031","3.46447","2.41696","0.01796","236.00967"
"211.20000","3.51800","575.78326","3.47131","2.42380","0.01800","235.61395"
"211.60000","3.52501","575.00500","3.47836","2.43085","0.01804","235.29549"
"212.00000","3.53164","574.06854","3.48504","2.43752","0.01807","234.91228"
"212.40000","3.53815","572.87823","3.49161","2.44410","0.01810","234.42520"
"212.80000","3.54470","571.81360","3.49820","2.45069","0.01814","233.98955"
"213.20000","3.55126","570.86517","3.50481","2.45730","0.01817","233.60144"
"213.60000","3.55793","569.80243","3.51153","2.46402","0.01821","233.16656"
"214.00000","3.56484","569.12616","3.51848","2.47096","0.01824","232.88983"
"214.40000","3.57177","568.36188","3.52544","2.47793","0.01828","232.57707"
"214.80000","3.57814","567.56445","3.53185","2.48433","0.01831","232.25076"
"215.20000","3.58474","566.84882","3.53848","2.49097","0.01835","231.95793"
"215.60000","3.59124","566.00696","3.54503","2.49752","0.01838","231.61343"
"216.00000","3.59795","565.16772","3.55178","2.50426","0.01842","231.27002"
"216.40000","3.60495","564.60010","3.55881","2.51129","0.01845","231.03773"
"216.80000","3.61165","563.85925","3.56554","2.51803","0.01849","230.73457"
"217.20000","3.61825","562.96063","3.57219","2.52467","0.01852","230.36685"
"217.60000","3.62468","562.08020","3.57866","2.53114","0.01856","230.00658"
"218.00000","3.63132","561.27185","3.58534","2.53782","0.01859","229.67580"
"218.40000","3.63786","560.49774","3.59192","2.54440","0.01862","229.35902"
"218.80000","3.64474","559.66699","3.59883","2.55132","0.01866","229.01907"
"219.20000","3.65178","558.73212","3.60592","2.55841","0.01870","228.63652"
"219.60000","3.65816","557.21906","3.61237","2.56486","0.01873","228.01736"
"220.00000","3.66483","555.98938","3.61910","2.57159","0.01877","227.51418"
"220.40000","3.67128","554.83014","3.62560","2.57809","0.01880","227.03981"
"220.80000","3.67791","553.75189","3.63230","2.58478","0.01883","226.59859"
"221.20000","3.68473","552.91589","3.63916","2.59164","0.01887","226.25648"
"221.60000","3.69163","552.11749","3.64609","2.59858","0.01891","225.92978"
"222.00000","3.69835","551.20392","3.65285","2.60534","0.01894","225.55594"
"222.40000","3.70470","550.20233","3.65926","2.61174","0.01897","225.14609"
"222.80000","3.71135","549.39508","3.66594","2.61843","0.01901","224.81575"
"223.20000","3.71786","548.75244","3.67249","2.62497","0.01904","224.55278"
"223.60000","3.72469","548.22516","3.67933","2.63182","0.01908","224.33701"
"224.00000","3.73165","547.81604","3.68631","2.63880","0.01911","224.16960"
"224.40000","3.73832","547.21423","3.69302","2.64551","0.01915","223.92334"
"224.80000","3.74486","546.59503","3.69958","2.65207","0.01918","223.66995"
"225.20000","3.75131","546.05157","3.70607","2.65855","0.01922","223.44757"
"225.60000","3.75792","545.49023","3.71270","2.66519","0.01925","223.21786"
"226.00000","3.76461","544.92511","3.71942","2.67190","0.01929","222.98662"
"226.40000","3.77157","544.27814","3.72641","2.67890","0.01932","222.72186"
"226.80000","3.77844","543.51917","3.73331","2.68580","0.01936","222.41129"
"227.20000","3.78483","542.59521","3.73975","2.69224","0.01939","222.03320"
"227.60000","3.79138","541.83643","3.74634","2.69883","0.01943","221.72270"
"228.00000","3.79792","541.06372","3.75292","2.70540","0.01946","221.40651"
"228.40000","3.80460","540.20898","3.75963","2.71212","0.01949","221.05675"
"228.80000","3.81156","538.98792","3.76666","2.71914","0.01953","220.55708"
"229.20000","3.81831","537.90912","3.77346","2.72595","0.01957","220.11563"
"229.60000","3.82493","536.90417","3.78013","2.73262","0.01960","219.70439"
"230.00000","3.83136","536.07623","3.78661","2.73909","0.01963","219.36560"
"230.40000","3.83798","535.31030","3.79326","2.74575","0.01967","219.05217"
"230.80000","3.84461","534.53790","3.79994","2.75242","0.01970","218.73610"
"231.20000","3.85138","534.13416","3.80672","2.75921","0.01974","218.57089"
"231.60000","3.85842","533.62573","3.81378","2.76627","0.01978","218.36284"
"232.00000","3.86479","532.80408","3.82019","2.77268","0.01981","218.02661"
"232.40000","3.87150","532.16992","3.82694","2.77942","0.01984","217.76712"
"232.80000","3.87795","531.51874","3.83342","2.78591","0.01988","217.50064"
"233.20000","3.88463","531.14069","3.84012","2.79261","0.01991","217.34595"
"233.60000","3.89148","530.82788","3.84699","2.79947","0.01995","217.21794"
"234.00000","3.89829","530.34259","3.85382","2.80631","0.01998","217.01936"
"234.40000","3.90502","529.64160","3.86058","2.81307","0.02002","216.73251"
"234.80000","3.91140","528.81152","3.86701","2.81950","0.02005","216.39284"
"235.20000","3.91798","528.12268","3.87362","2.82611","0.02009","216.11096"
"235.60000","3.92453","527.08801","3.88022","2.83271","0.02012","215.68756"
"236.00000","3.93139","526.28168","3.88712","2.83961","0.02016","215.35760"
"236.40000","3.93840","525.11530","3.89419","2.84668","0.02019","214.88033"
"236.80000","3.94495","523.24927","3.90084","2.85332","0.02023","214.11673"
"237.20000","3.95156","521.35785","3.90754","2.86003","0.02026","213.34274"
"237.60000","3.95795","518.21155","3.91409","2.86658","0.02030","212.05527"
"238.00000","3.96458","512.39008","3.92101","2.87349","0.02033","209.67308"
"238.40000","3.97129","508.59885","3.92791","2.88040","0.02037","208.12169"
"238.80000","3.97827","506.44012","3.93500","2.88748","0.02040","207.23833"
"239.20000","3.98506","505.03519","3.94186","2.89434","0.02044","206.66342"
"239.60000","3.99143","501.39429","3.94841","2.90090","0.02047","205.17354"
"240.00000","3.99805","500.31287","3.95509","2.90757","0.02051","204.73102"
"240.40000","4.00457","499.35184","3.96165","2.91414","0.02054","204.33775"
"240.80000","4.01128","498.82623","3.96839","2.92088","0.02058","204.12268"
"241.20000","4.01829","498.69461","3.97541","2.92790","0.02061","204.06882"
"241.60000","4.02500","498.52170","3.98213","2.93462","0.02065","203.99806"
"242.00000","4.03160","498.37967","3.98873","2.94122","0.02068","203.93994"
"242.40000","4.03803","498.23508","3.99517","2.94766","0.02072","203.88077"
"242.80000","4.04460","498.30157","4.00174","2.95422","0.02075","203.90799"
"243.20000","4.05122","498.24802","4.00836","2.96085","0.02078","203.88606"
"243.60000","4.05815","498.37161","4.01528","2.96777","0.02082","203.93665"
"244.00000","4.06515","498.59079","4.02228","2.97476","0.02086","204.02634"
"244.40000","4.07150","498.52496","4.02863","2.98112","0.02089","203.99939"
"244.80000","4.07815","498.49814","4.03528","2.98776","0.02092","203.98842"
"245.20000","4.08462","498.57391","4.04174","2.99423","0.02096","204.01942"
"245.60000","4.09123","498.52649","4.04836","3.00084","0.02099","204.00002"
"246.00000","4.09811","498.71030","4.05522","3.00771","0.02103","204.07524"
"246.40000","4.10494","498.93115","4.06204","3.01453","0.02106","204.16560"
"246.80000","4.11166","498.83340","4.06877","3.02125","0.02110","204.12561"
"247.20000","4.11806","498.84726","4.07517","3.02766","0.02113","204.13129"
"247.60000","4.12471","498.91965","4.08181","3.03430","0.02116","204.16090"
"248.00000","4.13122","498.93781","4.08833","3.04081","0.02120","204.16833"
"248.40000","4.13806","499.12296","4.09516","3.04765","0.02123","204.24409"
"248.80000","4.14508","499.42062","4.10216","3.05465","0.02127","204.36591"
"249.20000","4.15156","499.33362","4.10864","3.06113","0.02130","204.33031"
"249.60000","4.15818","499.45764","4.11526","3.06775","0.02134","204.38106"
"250.00000","4.16464","499.51767","4.12171","3.07420","0.02137","204.40562"
"250.40000","4.17127","499.71481","4.12834","3.08082","0.02141","204.48628"
"250.80000","4.17800","499.98682","4.13505","3.08754","0.02144","204.59760"
"251.20000","4.18501","500.23566","4.14205","3.09453","0.02148","204.69942"
"251.60000","4.19177","500.31808","4.14881","3.10129","0.02151","204.73315"
"252.00000","4.19808","500.50537","4.15511","3.10759","0.02154","204.80978"
"252.40000","4.20472","500.46417","4.16175","3.11424","0.02158","204.79294"
"252.49900","4.20624","500.47723","4.16327","3.11576","0.02159","204.79828"