File: flexion/5_axis/Specimen_RawData_4.csv
Specimen properties : Specimen label,"4"
Specimen properties : Support span,"72.00",mm
Specimen properties : Thickness,"4.34",mm
Specimen properties : Width,"14.03",mm
Maximum Load : Maximum Load,"857.0",N
Tangent Modulus of Elasticity : Tangent Modulus of Elasticity,"40598295658.88360",Pa
Test : Rate 1,"1.00000",mm/min
Specimen notes : Specimen note 1,""

Time,Displacement,Load,Flexure extension,Corrected extension,Flexure strain (Corrected extension),Flexure stress
(s),(mm),(N),(mm),(mm),(mm/mm),(MPa)
"0.00000","0.00000","7.99464","-0.00768","-1.04607","-0.00004","3.26727"
"0.50000","0.00639","10.26264","-0.00244","-1.04083","-0.00001","4.19417"
"1.00000","0.01514","13.59281","0.00488","-1.03351","0.00002","5.55515"
"1.50000","0.02309","16.40323","0.01176","-1.02663","0.00006","6.70372"
"2.00000","0.03145","19.58942","0.01945","-1.01894","0.00010","8.00587"
"2.50000","0.03991","22.35710","0.02732","-1.01107","0.00014","9.13697"
"3.00000","0.04804","25.50705","0.03479","-1.00361","0.00017","10.42430"
"3.50000","0.05652","28.75225","0.04258","-0.99581","0.00021","11.75056"
"4.00000","0.06468","31.94058","0.05007","-0.98832","0.00025","13.05357"
"4.50000","0.07353","35.51831","0.05816","-0.98023","0.00029","14.51573"
"5.00000","0.08136","38.59306","0.06558","-0.97281","0.00033","15.77233"
"5.50000","0.09008","42.28226","0.07381","-0.96459","0.00037","17.28004"
"6.00000","0.09814","45.62490","0.08142","-0.95697","0.00041","18.64612"
"6.50000","0.10679","49.24348","0.08959","-0.94880","0.00045","20.12498"
"7.00000","0.11477","52.69298","0.09710","-0.94129","0.00049","21.53473"
"7.50000","0.12317","56.26659","0.10503","-0.93337","0.00053","22.99520"
"8.00000","0.13164","59.92553","0.11304","-0.92535","0.00057","24.49055"
"8.50000","0.13967","63.45798","0.12066","-0.91773","0.00061","25.93420"
"9.00000","0.14826","67.19432","0.12881","-0.90958","0.00065","27.46118"
"9.50000","0.15633","70.90074","0.13645","-0.90194","0.00069","28.97593"
"10.00000","0.16517","74.75074","0.14483","-0.89356","0.00073","30.54936"
"10.50000","0.17297","78.19623","0.15223","-0.88616","0.00076","31.95747"
"11.00000","0.18176","82.27248","0.16054","-0.87785","0.00081","33.62337"
"11.50000","0.18978","85.81123","0.16815","-0.87024","0.00084","35.06960"
"12.00000","0.19837","89.77165","0.17633","-0.86207","0.00089","36.68815"
"12.50000","0.20649","93.33386","0.18409","-0.85430","0.00092","38.14397"
"13.00000","0.21475","97.18375","0.19198","-0.84641","0.00096","39.71735"
"13.50000","0.22331","101.00797","0.20017","-0.83822","0.00101","41.28025"
"14.00000","0.23133","104.69788","0.20783","-0.83056","0.00104","42.78825"
"14.50000","0.24002","108.68150","0.21613","-0.82226","0.00109","44.41629"
"15.00000","0.24804","112.43019","0.22378","-0.81461","0.00112","45.94831"
"15.50000","0.25690","116.50591","0.23224","-0.80615","0.00117","47.61399"
"16.00000","0.26471","120.11050","0.23970","-0.79869","0.00120","49.08713"
"16.50000","0.27331","124.20320","0.24789","-0.79050","0.00125","50.75974"
"17.00000","0.28151","127.92388","0.25573","-0.78266","0.00128","52.28032"
"17.50000","0.28994","132.01042","0.26377","-0.77462","0.00132","53.95042"
"18.00000","0.29812","135.77635","0.27158","-0.76681","0.00136","55.48949"
"18.50000","0.30639","139.64984","0.27948","-0.75891","0.00140","57.07253"
"19.00000","0.31505","143.73930","0.28774","-0.75065","0.00145","58.74382"
"19.50000","0.32300","147.45695","0.29533","-0.74306","0.00148","60.26316"
"20.00000","0.33165","151.47543","0.30358","-0.73481","0.00152","61.90545"
"20.50000","0.33974","155.32787","0.31130","-0.72709","0.00156","63.47987"
"21.00000","0.34858","159.58792","0.31975","-0.71865","0.00161","65.22088"
"21.50000","0.35638","163.27563","0.32724","-0.71115","0.00164","66.72799"
"22.00000","0.36500","167.29430","0.33551","-0.70288","0.00169","68.37035"
"22.50000","0.37320","171.25922","0.34337","-0.69502","0.00172","69.99074"
"23.00000","0.38151","175.13416","0.35136","-0.68703","0.00176","71.57436"
"23.50000","0.38981","179.04562","0.35933","-0.67906","0.00180","73.17291"
"24.00000","0.39805","182.94867","0.36723","-0.67116","0.00184","74.76802"
"24.50000","0.40672","187.10611","0.37555","-0.66284","0.00189","76.46709"
"25.00000","0.41462","190.88687","0.38313","-0.65526","0.00192","78.01223"
"25.50000","0.42340","195.02774","0.39155","-0.64684","0.00197","79.70454"
"26.00000","0.43136","198.78500","0.39920","-0.63919","0.00201","81.24007"
"26.50000","0.44018","203.16150","0.40766","-0.63073","0.00205","83.02866"
"27.00000","0.44809","206.84656","0.41527","-0.62312","0.00209","84.53468"
"27.50000","0.45660","210.92575","0.42345","-0.61494","0.00213","86.20178"
"28.00000","0.46487","214.93172","0.43140","-0.60699","0.00217","87.83895"
"28.50000","0.47314","218.73529","0.43937","-0.59902","0.00221","89.39341"
"29.00000","0.48157","222.79045","0.44747","-0.59092","0.00225","91.05068"
"29.50000","0.48972","226.72319","0.45531","-0.58308","0.00229","92.65793"
"30.00000","0.49844","230.90544","0.46370","-0.57469","0.00233","94.36714"
"30.50000","0.50631","234.53172","0.47128","-0.56711","0.00237","95.84914"
"31.00000","0.51498","238.76172","0.47961","-0.55878","0.00241","97.57787"
"31.50000","0.52308","242.66238","0.48739","-0.55100","0.00245","99.17200"
"32.00000","0.53182","246.92572","0.49581","-0.54258","0.00249","100.91436"
"32.50000","0.53975","250.80475","0.50344","-0.53496","0.00253","102.49965"
"33.00000","0.54820","254.83398","0.51158","-0.52681","0.00257","104.14633"
"33.50000","0.55661","258.80930","0.51969","-0.51870","0.00261","105.77097"
"34.00000","0.56477","262.75232","0.52755","-0.51084","0.00265","107.38242"
"34.50000","0.57318","266.79715","0.53564","-0.50275","0.00269","109.03548"
"35.00000","0.58139","270.73352","0.54355","-0.49484","0.00273","110.64420"
"35.50000","0.59016","275.06732","0.55198","-0.48641","0.00277","112.41535"
"36.00000","0.59798","278.74411","0.55953","-0.47886","0.00281","113.91799"
"36.50000","0.60673","283.03152","0.56795","-0.47044","0.00285","115.67019"
"37.00000","0.61476","286.91824","0.57568","-0.46271","0.00289","117.25862"
"37.50000","0.62343","291.19809","0.58403","-0.45437","0.00293","119.00773"
"38.00000","0.63142","295.02902","0.59176","-0.44663","0.00297","120.57336"
"38.50000","0.63988","299.12204","0.59995","-0.43844","0.00301","122.24611"
"39.00000","0.64827","303.19302","0.60806","-0.43033","0.00305","123.90985"
"39.50000","0.65636","307.08356","0.61590","-0.42249","0.00309","125.49985"
"40.00000","0.66492","311.29233","0.62417","-0.41422","0.00314","127.21990"
"40.50000","0.67302","315.17877","0.63201","-0.40638","0.00317","128.80823"
"41.00000","0.68182","319.60803","0.64052","-0.39788","0.00322","130.61839"
"41.50000","0.68967","323.35150","0.64811","-0.39028","0.00326","132.14828"
"42.00000","0.69839","327.63425","0.65654","-0.38185","0.00330","133.89856"
"42.50000","0.70642","331.47748","0.66432","-0.37407","0.00334","135.46922"
"43.00000","0.71510","335.74365","0.67271","-0.36568","0.00338","137.21274"
"43.50000","0.72318","339.64993","0.68053","-0.35786","0.00342","138.80917"
"44.00000","0.73151","343.75302","0.68859","-0.34980","0.00346","140.48604"
"44.50000","0.73996","347.87506","0.69679","-0.34160","0.00350","142.17064"
"45.00000","0.74800","351.67722","0.70458","-0.33382","0.00354","143.72452"
"45.50000","0.75655","355.89258","0.71286","-0.32553","0.00358","145.44727"
"46.00000","0.76470","359.87531","0.72075","-0.31764","0.00362","147.07494"
"46.50000","0.77350","364.11240","0.72928","-0.30911","0.00366","148.80656"
"47.00000","0.78138","367.84473","0.73692","-0.30147","0.00370","150.33191"
"47.50000","0.79003","372.02325","0.74530","-0.29309","0.00374","152.03960"
"48.00000","0.79818","376.04947","0.75320","-0.28519","0.00378","153.68504"
"48.50000","0.80669","380.11606","0.76145","-0.27694","0.00382","155.34700"
"49.00000","0.81478","383.99527","0.76928","-0.26911","0.00386","156.93236"
"49.50000","0.82314","388.10590","0.77738","-0.26101","0.00390","158.61230"
"50.00000","0.83165","392.34030","0.78564","-0.25275","0.00395","160.34283"
"50.50000","0.83963","395.97116","0.79342","-0.24497","0.00399","161.82671"
"51.00000","0.84831","400.28296","0.80186","-0.23653","0.00403","163.58887"
"51.50000","0.85637","403.97797","0.80970","-0.22869","0.00407","165.09895"
"52.00000","0.86522","408.52750","0.81830","-0.22010","0.00411","166.95827"
"52.50000","0.87301","412.03970","0.82588","-0.21251","0.00415","168.39365"
"53.00000","0.88174","416.32593","0.83437","-0.20402","0.00419","170.14536"
"53.50000","0.88982","420.20819","0.84223","-0.19617","0.00423","171.73196"
"54.00000","0.89826","424.20551","0.85044","-0.18795","0.00427","173.36560"
"54.50000","0.90649","428.12430","0.85844","-0.17995","0.00431","174.96715"
"55.00000","0.91472","431.99429","0.86645","-0.17194","0.00435","176.54875"
"55.50000","0.92335","436.24435","0.87484","-0.16355","0.00439","178.28568"
"56.00000","0.93128","439.88559","0.88256","-0.15583","0.00443","179.77379"
"56.50000","0.94006","444.21722","0.89110","-0.14729","0.00448","181.54405"
"57.00000","0.94803","447.93988","0.89885","-0.13954","0.00452","183.06544"
"57.50000","0.95693","452.26175","0.90751","-0.13089","0.00456","184.83171"
"58.00000","0.96478","456.02377","0.91515","-0.12324","0.00460","186.36919"
"58.50000","0.97332","460.07730","0.92345","-0.11494","0.00464","188.02580"
"59.00000","0.98153","463.79837","0.93145","-0.10694","0.00468","189.54654"
"59.50000","0.98985","467.93857","0.93954","-0.09885","0.00472","191.23857"
"60.00000","0.99817","471.71545","0.94764","-0.09075","0.00476","192.78212"
"60.50000","1.00636","475.63635","0.95561","-0.08278","0.00480","194.38452"
"61.00000","1.01505","479.77325","0.96406","-0.07433","0.00484","196.07520"
"61.50000","1.02300","483.54486","0.97180","-0.06659","0.00488","197.61659"
"62.00000","1.03173","487.73700","0.98029","-0.05810","0.00492","199.32985"
"62.50000","1.03976","491.54022","0.98812","-0.05027","0.00496","200.88416"
"63.00000","1.04853","495.62985","0.99668","-0.04171","0.00501","202.55553"
"63.50000","1.05638","499.23053","1.00435","-0.03404","0.00504","204.02705"
"64.00000","1.06491","503.26129","1.01267","-0.02572","0.00509","205.67436"
"64.50000","1.07320","507.13684","1.02077","-0.01762","0.00513","207.25824"
"65.00000","1.08144","510.95718","1.02882","-0.00957","0.00517","208.81955"
"65.50000","1.08987","515.08594","1.03704","-0.00135","0.00521","210.50690"
"66.00000","1.09805","518.91400","1.04503","0.00664","0.00525","212.07137"
"66.50000","1.10681","522.91687","1.05359","0.01520","0.00529","213.70726"
"67.00000","1.11461","526.51532","1.06121","0.02282","0.00533","215.17789"
"67.50000","1.12347","530.78308","1.06986","0.03147","0.00537","216.92206"
"68.00000","1.13140","534.37415","1.07760","0.03921","0.00541","218.38966"
"68.50000","1.14014","538.62183","1.08614","0.04774","0.00546","220.12561"
"69.00000","1.14808","542.14362","1.09390","0.05551","0.00549","221.56491"
"69.50000","1.15652","546.09766","1.10215","0.06376","0.00554","223.18086"
"70.00000","1.16490","550.06110","1.11034","0.07195","0.00558","224.80064"
"70.50000","1.17304","553.77002","1.11830","0.07991","0.00562","226.31642"
"71.00000","1.18161","557.78088","1.12667","0.08828","0.00566","227.95560"
"71.50000","1.18966","561.40747","1.13455","0.09616","0.00570","229.43773"
"72.00000","1.19848","565.49182","1.14317","0.10477","0.00574","231.10693"
"72.50000","1.20634","569.06842","1.15086","0.11247","0.00578","232.56862"
"73.00000","1.21508","573.10419","1.15940","0.12101","0.00582","234.21797"
"73.50000","1.22312","576.80145","1.16726","0.12887","0.00586","235.72899"
"74.00000","1.23178","580.82074","1.17573","0.13734","0.00591","237.37160"
"74.50000","1.23976","584.41412","1.18353","0.14514","0.00595","238.84015"
"75.00000","1.24812","588.29840","1.19170","0.15331","0.00599","240.42758"
"75.50000","1.25663","592.32538","1.20002","0.16163","0.00603","242.07335"
"76.00000","1.26474","595.86591","1.20798","0.16959","0.00607","243.52029"
"76.50000","1.27331","599.80737","1.21637","0.17798","0.00611","245.13110"
"77.00000","1.28138","603.51624","1.22428","0.18589","0.00615","246.64687"
"77.50000","1.29016","607.35925","1.23288","0.19449","0.00619","248.21744"
"78.00000","1.29797","610.94067","1.24053","0.20214","0.00623","249.68111"
"78.50000","1.30670","615.00128","1.24908","0.21069","0.00627","251.34061"
"79.00000","1.31477","618.60449","1.25699","0.21860","0.00631","252.81317"
"79.50000","1.32333","622.54614","1.26537","0.22698","0.00636","254.42406"
"80.00000","1.33144","626.11902","1.27332","0.23493","0.00640","255.88423"
"80.50000","1.33981","629.87842","1.28152","0.24313","0.00644","257.42062"
"81.00000","1.34835","633.86652","1.28989","0.25149","0.00648","259.05051"
"81.50000","1.35633","637.25983","1.29771","0.25932","0.00652","260.43729"
"82.00000","1.36499","641.29138","1.30619","0.26780","0.00656","262.08493"
"82.50000","1.37299","644.74677","1.31404","0.27565","0.00660","263.49707"
"83.00000","1.38186","648.79645","1.32272","0.28433","0.00664","265.15213"
"83.50000","1.38969","652.10516","1.33041","0.29202","0.00668","266.50433"
"84.00000","1.39841","656.12830","1.33895","0.30056","0.00673","268.14853"
"84.50000","1.40646","659.56378","1.34685","0.30846","0.00677","269.55255"
"85.00000","1.41495","663.30829","1.35517","0.31678","0.00681","271.08286"
"85.50000","1.42319","666.98224","1.36324","0.32485","0.00685","272.58435"
"86.00000","1.43141","670.49463","1.37130","0.33291","0.00689","274.01981"
"86.50000","1.44000","674.29260","1.37973","0.34134","0.00693","275.57196"
"87.00000","1.44797","677.65924","1.38755","0.34916","0.00697","276.94785"
"87.50000","1.45666","681.52240","1.39607","0.35768","0.00701","278.52667"
"88.00000","1.46472","684.84698","1.40398","0.36559","0.00705","279.88535"
"88.50000","1.47356","688.75232","1.41265","0.37425","0.00710","281.48141"
"89.00000","1.48138","692.02728","1.42032","0.38193","0.00713","282.81982"
"89.50000","1.48998","695.84027","1.42875","0.39036","0.00718","284.37814"
"90.00000","1.49821","698.84509","1.43684","0.39845","0.00722","285.60614"
"90.50000","1.50659","702.13342","1.44508","0.40668","0.00726","286.95004"
"91.00000","1.51485","705.42126","1.45319","0.41480","0.00730","288.29373"
"91.50000","1.52306","706.93164","1.46133","0.42294","0.00734","288.91098"
"92.00000","1.53171","708.97021","1.46989","0.43150","0.00738","289.74411"
"92.50000","1.53960","710.63373","1.47770","0.43931","0.00742","290.42395"
"93.00000","1.54835","711.49890","1.48642","0.44802","0.00747","290.77756"
"93.50000","1.55635","713.76178","1.49432","0.45593","0.00751","291.70233"
"94.00000","1.56525","716.02826","1.50312","0.46473","0.00755","292.62863"
"94.50000","1.57307","714.43719","1.51100","0.47261","0.00759","291.97836"
"95.00000","1.58171","711.58521","1.51977","0.48138","0.00763","290.81281"
"95.50000","1.58989","709.70312","1.52804","0.48965","0.00768","290.04364"
"96.00000","1.59815","710.53564","1.53626","0.49787","0.00772","290.38388"
"96.50000","1.60655","712.18036","1.54459","0.50620","0.00776","291.05606"
"97.00000","1.61470","714.03198","1.55265","0.51426","0.00780","291.81277"
"97.50000","1.62341","716.65442","1.56125","0.52286","0.00784","292.88452"
"98.00000","1.63129","718.69769","1.56904","0.53064","0.00788","293.71957"
"98.50000","1.64009","721.55627","1.57771","0.53932","0.00793","294.88782"
"99.00000","1.64803","723.99072","1.58554","0.54715","0.00796","295.88275"
"99.50000","1.65688","726.97375","1.59425","0.55586","0.00801","297.10187"
"100.00000","1.66479","727.89160","1.60212","0.56373","0.00805","297.47696"
"100.50000","1.67322","730.31531","1.61045","0.57206","0.00809","298.46750"
"101.00000","1.68155","732.89923","1.61866","0.58027","0.00813","299.52350"
"101.50000","1.68971","735.23083","1.62672","0.58833","0.00817","300.47638"
"102.00000","1.69824","737.63190","1.63514","0.59675","0.00821","301.45767"
"102.50000","1.70638","737.55615","1.64328","0.60489","0.00825","301.42670"
"103.00000","1.71517","739.96368","1.65197","0.61358","0.00830","302.41061"
"103.50000","1.72303","742.02704","1.65974","0.62135","0.00834","303.25388"
"104.00000","1.73175","744.37231","1.66835","0.62996","0.00838","304.21234"
"104.50000","1.73978","746.05939","1.67631","0.63792","0.00842","304.90182"
"105.00000","1.74851","748.59778","1.68494","0.64655","0.00846","305.93924"
"105.50000","1.75646","750.74744","1.69280","0.65441","0.00850","306.81775"
"106.00000","1.76483","753.29047","1.70106","0.66267","0.00854","307.85706"
"106.50000","1.77327","756.01178","1.70939","0.67100","0.00859","308.96921"
"107.00000","1.78133","758.46851","1.71734","0.67895","0.00863","309.97324"
"107.50000","1.78992","761.18658","1.72583","0.68744","0.00867","311.08405"
"108.00000","1.79801","762.04266","1.73388","0.69549","0.00871","311.43393"
"108.50000","1.80687","761.36462","1.74277","0.70437","0.00875","311.15683"
"109.00000","1.81468","758.49127","1.75070","0.71231","0.00879","309.98254"
"109.50000","1.82348","754.43732","1.75967","0.72127","0.00884","308.32574"
"110.00000","1.83146","754.57916","1.76764","0.72925","0.00888","308.38373"
"110.50000","1.84004","755.84320","1.77617","0.73778","0.00892","308.90030"
"111.00000","1.84813","757.44812","1.78419","0.74580","0.00896","309.55621"
"111.50000","1.85649","759.48755","1.79246","0.75407","0.00900","310.38968"
"112.00000","1.86496","761.84247","1.80084","0.76245","0.00905","311.35211"
"112.50000","1.87296","763.80481","1.80876","0.77037","0.00909","312.15408"
"113.00000","1.88169","766.33929","1.81738","0.77899","0.00913","313.18988"
"113.50000","1.88967","768.74371","1.82526","0.78687","0.00917","314.17252"
"114.00000","1.89855","771.26593","1.83403","0.79564","0.00921","315.20331"
"114.50000","1.90637","773.38245","1.84176","0.80337","0.00925","316.06830"
"115.00000","1.91504","776.12415","1.85033","0.81194","0.00929","317.18878"
"115.50000","1.92312","778.35205","1.85831","0.81992","0.00933","318.09930"
"116.00000","1.93165","780.82324","1.86673","0.82834","0.00938","319.10922"
"116.50000","1.93983","783.15259","1.87482","0.83643","0.00942","320.06119"
"117.00000","1.94809","785.64484","1.88297","0.84458","0.00946","321.07974"
"117.50000","1.95669","788.30542","1.89146","0.85307","0.00950","322.16708"
"118.00000","1.96469","790.48584","1.89938","0.86098","0.00954","323.05817"
"118.50000","1.97336","793.03302","1.90794","0.86955","0.00958","324.09915"
"119.00000","1.98142","795.16431","1.91590","0.87751","0.00962","324.97018"
"119.50000","1.99020","797.73694","1.92457","0.88618","0.00967","326.02158"
"120.00000","1.99803","799.77643","1.93232","0.89393","0.00971","326.85507"
"120.50000","2.00663","801.99561","1.94081","0.90242","0.00975","327.76202"
"121.00000","2.01484","804.13062","1.94893","0.91054","0.00979","328.63455"
"121.50000","2.02324","806.17230","1.95725","0.91886","0.00983","329.46896"
"122.00000","2.03150","808.23627","1.96542","0.92703","0.00987","330.31247"
"122.50000","2.03975","810.09052","1.97359","0.93520","0.00991","331.07028"
"123.00000","2.04838","812.24164","1.98213","0.94374","0.00996","331.94940"
"123.50000","2.05634","813.82294","1.99002","0.95163","0.01000","332.59564"
"124.00000","2.06507","815.79254","1.99866","0.96027","0.01004","333.40060"
"124.50000","2.07307","817.19952","2.00660","0.96821","0.01008","333.97559"
"125.00000","2.08184","818.87415","2.01530","0.97690","0.01012","334.66000"
"125.50000","2.08971","819.96667","2.02312","0.98473","0.01016","335.10648"
"126.00000","2.09836","821.46173","2.03170","0.99331","0.01021","335.71750"
"126.50000","2.10653","822.34143","2.03984","1.00145","0.01025","336.07700"
"127.00000","2.11481","822.75348","2.04810","1.00971","0.01029","336.24542"
"127.50000","2.12322","822.90790","2.05650","1.01811","0.01033","336.30850"
"128.00000","2.13136","822.69720","2.06465","1.02626","0.01037","336.22241"
"128.50000","2.14003","823.00024","2.07331","1.03492","0.01041","336.34625"
"129.00000","2.14797","823.25012","2.08123","1.04284","0.01045","336.44836"
"129.50000","2.15673","824.03162","2.08996","1.05157","0.01050","336.76776"
"130.00000","2.16469","824.54553","2.09790","1.05951","0.01054","336.97778"
"130.50000","2.17354","825.52594","2.10671","1.06832","0.01058","337.37848"
"131.00000","2.18140","825.98108","2.11455","1.07616","0.01062","337.56448"
"131.50000","2.18989","826.90839","2.12300","1.08461","0.01066","337.94345"
"132.00000","2.19825","827.81458","2.13132","1.09293","0.01071","338.31378"
"132.50000","2.20649","828.43842","2.13953","1.10114","0.01075","338.56876"
"133.00000","2.21489","829.43951","2.14789","1.10950","0.01079","338.97787"
"133.50000","2.22310","830.33295","2.15606","1.11767","0.01083","339.34302"
"134.00000","2.23176","831.49988","2.16467","1.12628","0.01087","339.81992"
"134.50000","2.23964","832.32996","2.17251","1.13412","0.01091","340.15915"
"135.00000","2.24834","833.66364","2.18115","1.14276","0.01096","340.70419"
"135.50000","2.25641","834.57611","2.18919","1.15080","0.01100","341.07712"
"136.00000","2.26517","835.96027","2.19789","1.15950","0.01104","341.64279"
"136.50000","2.27307","836.69220","2.20576","1.16737","0.01108","341.94193"
"137.00000","2.28159","838.01898","2.21422","1.17583","0.01112","342.48416"
"137.50000","2.28994","838.96161","2.22252","1.18413","0.01116","342.86938"
"138.00000","2.29809","839.88879","2.23064","1.19225","0.01120","343.24832"
"138.50000","2.30657","840.83807","2.23907","1.20068","0.01125","343.63626"
"139.00000","2.31470","841.69830","2.24717","1.20878","0.01129","343.98782"
"139.50000","2.32344","842.98138","2.25585","1.21746","0.01133","344.51221"
"140.00000","2.33133","843.60541","2.26371","1.22532","0.01137","344.76724"
"140.50000","2.34015","845.03406","2.27247","1.23408","0.01141","345.35110"
"141.00000","2.34809","845.67133","2.28039","1.24200","0.01145","345.61154"
"141.50000","2.35676","846.82013","2.28901","1.25062","0.01150","346.08105"
"142.00000","2.36478","847.57153","2.29700","1.25861","0.01154","346.38812"
"142.50000","2.37319","848.49634","2.30537","1.26698","0.01158","346.76608"
"143.00000","2.38157","849.48212","2.31371","1.27532","0.01162","347.16895"
"143.50000","2.38966","850.14978","2.32177","1.28338","0.01166","347.44180"
"144.00000","2.39827","851.15015","2.33034","1.29194","0.01171","347.85065"
"144.50000","2.40633","851.77856","2.33837","1.29998","0.01175","348.10748"
"145.00000","2.41519","852.67566","2.34719","1.30880","0.01179","348.47409"
"145.50000","2.42304","852.98364","2.35503","1.31664","0.01183","348.59998"
"146.00000","2.43171","853.81000","2.36367","1.32528","0.01187","348.93768"
"146.50000","2.43979","854.19788","2.37173","1.33334","0.01191","349.09619"
"147.00000","2.44839","854.84070","2.38031","1.34191","0.01196","349.35892"
"147.50000","2.45647","855.32416","2.38836","1.34997","0.01200","349.55649"
"148.00000","2.46485","855.80072","2.39672","1.35833","0.01204","349.75125"
"148.50000","2.47332","856.29968","2.40518","1.36679","0.01208","349.95517"
"149.00000","2.48129","856.32568","2.41314","1.37475","0.01212","349.96579"
"149.50000","2.48992","856.79657","2.42175","1.38336","0.01216","350.15823"
"150.00000","2.49804","856.64020","2.42988","1.39149","0.01221","350.09433"
"150.50000","2.50689","856.96198","2.43871","1.40032","0.01225","350.22583"
"151.00000","2.51470","856.40131","2.44654","1.40815","0.01229","349.99670"
"151.50000","2.52342","856.58337","2.45526","1.41687","0.01233","350.07111"
"152.00000","2.53147","856.10480","2.46333","1.42494","0.01237","349.87552"
"152.50000","2.53997","856.06604","2.47183","1.43344","0.01242","349.85968"
"153.00000","2.54812","855.79065","2.48000","1.44161","0.01246","349.74713"
"153.50000","2.55644","855.72412","2.48832","1.44993","0.01250","349.71994"
"154.00000","2.56501","855.91199","2.49688","1.45849","0.01254","349.79672"
"154.50000","2.57298","855.74414","2.50486","1.46647","0.01258","349.72812"
"155.00000","2.58173","856.08038","2.51359","1.47520","0.01263","349.86554"
"155.50000","2.58969","856.05371","2.52155","1.48316","0.01267","349.85464"
"156.00000","2.59862","856.50348","2.53046","1.49207","0.01271","350.03845"
"156.50000","2.60639","856.32324","2.53824","1.49985","0.01275","349.96481"
"157.00000","2.61502","856.58142","2.54686","1.50847","0.01279","350.07031"
"157.50000","2.62313","856.54260","2.55497","1.51658","0.01283","350.05444"
"158.00000","2.63150","856.45679","2.56334","1.52495","0.01288","350.01938"
"158.50000","2.63985","856.43671","2.57169","1.53330","0.01292","350.01117"
"159.00000","2.64804","856.14697","2.57990","1.54151","0.01296","349.89276"
"159.50000","2.65669","855.95844","2.58855","1.55016","0.01300","349.81570"
"160.00000","2.66466","855.29535","2.59655","1.55816","0.01304","349.54471"
"160.50000","2.67335","855.07452","2.60526","1.56687","0.01309","349.45447"
"161.00000","2.68140","854.27618","2.61334","1.57495","0.01313","349.12820"
"161.50000","2.69024","853.67554","2.62220","1.58381","0.01317","348.88272"
"162.00000","2.69807","852.71356","2.63007","1.59168","0.01321","348.48959"
"162.50000","2.70664","852.30078","2.63866","1.60027","0.01325","348.32089"
"163.00000","2.71491","851.89825","2.64694","1.60855","0.01330","348.15637"
"163.50000","2.72313","851.79993","2.65517","1.61678","0.01334","348.11621"
"164.00000","2.73154","851.58099","2.66359","1.62520","0.01338","348.02673"
"164.50000","2.73973","851.26611","2.67180","1.63341","0.01342","347.89804"
"165.00000","2.74841","851.38123","2.68047","1.64208","0.01346","347.94507"
"165.50000","2.75631","851.15491","2.68837","1.64998","0.01350","347.85260"
"166.00000","2.76506","851.12115","2.69713","1.65874","0.01355","347.83881"
"166.50000","2.77305","850.88947","2.70513","1.66674","0.01359","347.74411"
"167.00000","2.78185","851.28070","2.71391","1.67552","0.01363","347.90399"
"167.50000","2.78970","850.91443","2.72178","1.68339","0.01367","347.75430"
"168.00000","2.79825","851.26672","2.73031","1.69192","0.01371","347.89828"
"168.50000","2.80657","851.41559","2.73863","1.70024","0.01376","347.95914"
"169.00000","2.81474","851.45227","2.74679","1.70840","0.01380","347.97412"
"169.50000","2.82325","851.95880","2.75528","1.71689","0.01384","348.18112"
"170.00000","2.83137","852.01404","2.76340","1.72501","0.01388","348.20370"
"170.50000","2.84017","852.46002","2.77218","1.73379","0.01393","348.38596"
"171.00000","2.84800","852.30170","2.78002","1.74163","0.01396","348.32126"
"171.50000","2.85680","852.89514","2.78880","1.75041","0.01401","348.56378"
"172.00000","2.86471","852.92676","2.79671","1.75832","0.01405","348.57672"
"172.50000","2.87350","853.46820","2.80547","1.76708","0.01409","348.79800"
"173.00000","2.88145","853.48859","2.81342","1.77503","0.01413","348.80634"
"173.50000","2.88982","853.76788","2.82178","1.78339","0.01417","348.92047"
"174.00000","2.89824","853.96448","2.83019","1.79180","0.01422","349.00082"
"174.50000","2.90638","853.81128","2.83834","1.79995","0.01426","348.93820"
"175.00000","2.91492","853.74939","2.84688","1.80849","0.01430","348.91290"
"175.50000","2.92302","853.03802","2.85501","1.81661","0.01434","348.62219"
"176.00000","2.93181","852.24994","2.86383","1.82544","0.01439","348.30011"
"176.50000","2.93966","851.19458","2.87173","1.83334","0.01443","347.86880"
"177.00000","2.94834","850.07874","2.88045","1.84206","0.01447","347.41278"
"177.50000","2.95646","848.55090","2.88864","1.85025","0.01451","346.78839"
"178.00000","2.96510","847.12610","2.89734","1.85895","0.01455","346.20609"
"178.50000","2.97312","845.44659","2.90543","1.86704","0.01459","345.51968"
"179.00000","2.98150","844.20453","2.91386","1.87547","0.01464","345.01208"
"179.50000","2.98997","842.85095","2.92238","1.88399","0.01468","344.45889"
"180.00000","2.99802","841.35468","2.93050","1.89211","0.01472","343.84741"
"180.50000","3.00665","840.25171","2.93918","1.90079","0.01476","343.39664"
"181.00000","3.01471","838.61053","2.94731","1.90892","0.01480","342.72592"
"181.50000","3.02352","837.31140","2.95618","1.91779","0.01485","342.19498"
"182.00000","3.03130","834.50696","2.96408","1.92569","0.01489","341.04886"
"182.50000","3.04008","832.58264","2.97294","1.93455","0.01493","340.26242"
"183.00000","3.04814","830.75769","2.98108","1.94269","0.01497","339.51660"
"183.50000","3.05662","829.51105","2.98961","1.95122","0.01502","339.00711"
"184.00000","3.06480","828.38739","2.99784","1.95945","0.01506","338.54788"
"184.50000","3.07311","827.56226","3.00619","1.96780","0.01510","338.21066"
"185.00000","3.08167","827.21014","3.01476","1.97637","0.01514","338.06677"
"185.50000","3.08966","826.59125","3.02278","1.98439","0.01518","337.81384"
"186.00000","3.09837","826.51117","3.03149","1.99310","0.01523","337.78110"
"186.50000","3.10633","826.10370","3.03947","2.00108","0.01527","337.61459"
"187.00000","3.11524","826.37518","3.04837","2.00998","0.01531","337.72552"
"187.50000","3.12305","826.13623","3.05619","2.01780","0.01535","337.62787"
"188.00000","3.13166","826.24304","3.06480","2.02641","0.01539","337.67154"
"188.50000","3.13982","826.05713","3.07296","2.03457","0.01544","337.59555"
"189.00000","3.14826","826.09253","3.08140","2.04301","0.01548","337.61002"
"189.50000","3.15650","826.08337","3.08965","2.05126","0.01552","337.60629"
"190.00000","3.16472","825.93103","3.09787","2.05948","0.01556","337.54401"
"190.50000","3.17336","826.06769","3.10651","2.06811","0.01560","337.59985"
"191.00000","3.18132","825.52728","3.11449","2.07610","0.01564","337.37903"
"191.50000","3.18995","825.58459","3.12312","2.08473","0.01569","337.40244"
"192.00000","3.19804","825.38770","3.13122","2.09283","0.01573","337.32196"
"192.50000","3.20693","825.60492","3.14009","2.10170","0.01577","337.41074"
"193.00000","3.21473","825.23755","3.14791","2.10952","0.01581","337.26059"
"193.50000","3.22336","825.48743","3.15653","2.11814","0.01586","337.36273"
"194.00000","3.23156","825.39410","3.16474","2.12635","0.01590","337.32458"
"194.50000","3.23985","825.29913","3.17302","2.13463","0.01594","337.28577"
"195.00000","3.24820","825.46936","3.18137","2.14298","0.01598","337.35535"
"195.50000","3.25639","825.38324","3.18956","2.15117","0.01602","337.32016"
"196.00000","3.26507","825.67938","3.19823","2.15984","0.01607","337.44116"
"196.50000","3.27292","825.39563","3.20610","2.16771","0.01610","337.32520"
"197.00000","3.28172","825.75696","3.21488","2.17649","0.01615","337.47287"
"197.50000","3.28970","825.34625","3.22287","2.18448","0.01619","337.30502"
"198.00000","3.29847","825.56250","3.23163","2.19324","0.01623","337.39340"
"198.50000","3.30640","825.26172","3.23958","2.20119","0.01627","337.27048"
"199.00000","3.31498","825.12341","3.24817","2.20978","0.01632","337.21396"
"199.50000","3.32322","824.85547","3.25642","2.21803","0.01636","337.10446"
"200.00000","3.33144","824.49152","3.26465","2.22626","0.01640","336.95572"
"200.50000","3.33992","824.31360","3.27314","2.23475","0.01644","336.88300"
"201.00000","3.34800","823.84113","3.28124","2.24285","0.01648","336.68991"
"201.50000","3.35682","823.73956","3.29006","2.25167","0.01653","336.64841"
"202.00000","3.36467","823.03296","3.29794","2.25955","0.01657","336.35962"
"202.50000","3.37342","822.82635","3.30670","2.26831","0.01661","336.27518"
"203.00000","3.38141","822.32190","3.31472","2.27633","0.01665","336.06903"
"203.50000","3.39015","822.20959","3.32346","2.28507","0.01669","336.02313"
"204.00000","3.39811","821.68549","3.33144","2.29305","0.01673","335.80893"
"204.50000","3.40651","821.40759","3.33986","2.30147","0.01678","335.69537"
"205.00000","3.41492","821.29755","3.34827","2.30988","0.01682","335.65039"
"205.50000","3.42305","820.85022","3.35642","2.31803","0.01686","335.46759"
"206.00000","3.43152","820.67291","3.36490","2.32651","0.01690","335.39511"
"206.50000","3.43967","820.41602","3.37306","2.33467","0.01694","335.29013"
"207.00000","3.44852","820.42859","3.38190","2.34351","0.01699","335.29526"
"207.50000","3.45634","820.06573","3.38975","2.35136","0.01703","335.14697"
"208.00000","3.46506","820.17743","3.39846","2.36007","0.01707","335.19263"
"208.50000","3.47313","819.79724","3.40655","2.36816","0.01711","335.03723"
"209.00000","3.48178","819.92719","3.41519","2.37680","0.01716","335.09036"
"209.50000","3.48979","819.78290","3.42321","2.38481","0.01720","335.03137"
"210.00000","3.49819","819.77380","3.43161","2.39321","0.01724","335.02768"
"210.50000","3.50664","819.94031","3.44005","2.40166","0.01728","335.09570"
"211.00000","3.51465","819.79651","3.44807","2.40968","0.01732","335.03696"
"211.50000","3.52326","820.02802","3.45666","2.41827","0.01736","335.13156"
"212.00000","3.53132","819.97662","3.46473","2.42634","0.01740","335.11057"
"212.50000","3.54017","820.24866","3.47357","2.43518","0.01745","335.22174"
"213.00000","3.54798","820.16669","3.48138","2.44299","0.01749","335.18823"
"213.50000","3.55677","820.46948","3.49015","2.45176","0.01753","335.31198"
"214.00000","3.56478","820.47253","3.49816","2.45977","0.01757","335.31323"
"214.50000","3.57337","820.68433","3.50675","2.46836","0.01761","335.39978"
"215.00000","3.58150","820.76898","3.51487","2.47648","0.01766","335.43439"
"215.50000","3.58977","820.94196","3.52314","2.48475","0.01770","335.50507"
"216.00000","3.59831","821.22058","3.53166","2.49327","0.01774","335.61893"
"216.50000","3.60632","821.17560","3.53968","2.50129","0.01778","335.60056"
"217.00000","3.61503","821.76422","3.54836","2.50997","0.01782","335.84113"
"217.50000","3.62303","821.79822","3.55636","2.51797","0.01786","335.85501"
"218.00000","3.63190","822.42725","3.56521","2.52681","0.01791","336.11209"
"218.50000","3.63971","822.32263","3.57301","2.53462","0.01795","336.06934"
"219.00000","3.64831","822.54401","3.58160","2.54321","0.01799","336.15979"
"219.50000","3.65650","822.23212","3.58981","2.55142","0.01803","336.03235"
"220.00000","3.66495","822.40497","3.59826","2.55986","0.01807","336.10297"
"220.50000","3.67312","822.40955","3.60642","2.56803","0.01812","336.10486"
"221.00000","3.68140","822.43250","3.61470","2.57631","0.01816","336.11423"
"221.50000","3.69005","822.70410","3.62334","2.58495","0.01820","336.22522"
"222.00000","3.69800","822.70111","3.63129","2.59290","0.01824","336.22400"
"222.50000","3.70666","822.83478","3.63994","2.60155","0.01828","336.27863"
"223.00000","3.71473","822.80945","3.64802","2.60963","0.01832","336.26828"
"223.50000","3.72359","823.20544","3.65685","2.61846","0.01837","336.43011"
"224.00000","3.73136","822.95898","3.66464","2.62625","0.01841","336.32941"
"224.50000","3.73999","823.35034","3.67326","2.63487","0.01845","336.48935"
"225.00000","3.74820","823.30164","3.68146","2.64307","0.01849","336.46942"
"225.50000","3.75650","823.39850","3.68976","2.65137","0.01853","336.50900"
"226.00000","3.76482","823.48706","3.69808","2.65969","0.01858","336.54520"
"226.50000","3.77306","823.57928","3.70631","2.66792","0.01862","336.58289"
"227.00000","3.78171","823.77551","3.71496","2.67657","0.01866","336.66309"
"227.50000","3.78961","823.67267","3.72286","2.68447","0.01870","336.62106"
"228.00000","3.79839","824.06799","3.73162","2.69323","0.01874","336.78262"
"228.50000","3.80637","823.89899","3.73960","2.70121","0.01878","336.71356"
"229.00000","3.81519","824.38654","3.74840","2.71001","0.01883","336.91281"
"229.50000","3.82308","824.26740","3.75630","2.71791","0.01887","336.86411"
"230.00000","3.83161","824.36633","3.76483","2.72644","0.01891","336.90454"
"230.50000","3.83987","824.47974","3.77308","2.73469","0.01895","336.95090"
"231.00000","3.84817","824.59479","3.78137","2.74298","0.01899","336.99792"
"231.50000","3.85658","824.73700","3.78979","2.75140","0.01904","337.05603"
"232.00000","3.86472","824.86224","3.79792","2.75953","0.01908","337.10724"
"232.50000","3.87343","825.10712","3.80662","2.76823","0.01912","337.20731"
"233.00000","3.88131","824.97064","3.81450","2.77611","0.01916","337.15152"
"233.50000","3.89000","825.47290","3.82316","2.78477","0.01920","337.35678"
"234.00000","3.89809","825.69318","3.83125","2.79286","0.01924","337.44681"
"234.50000","3.90683","826.06824","3.83998","2.80159","0.01929","337.60010"
"235.00000","3.91473","826.13312","3.84787","2.80948","0.01933","337.62662"
"235.50000","3.92320","826.39001","3.85633","2.81794","0.01937","337.73160"
"236.00000","3.93161","826.62476","3.86473","2.82633","0.01941","337.82755"
"236.50000","3.93978","826.85516","3.87289","2.83450","0.01945","337.92169"
"237.00000","3.94819","827.09381","3.88129","2.84290","0.01950","338.01923"
"237.50000","3.95638","827.30365","3.88947","2.85108","0.01954","338.10498"
"238.00000","3.96514","827.77686","3.89821","2.85982","0.01958","338.29837"
"238.50000","3.97297","827.76343","3.90604","2.86765","0.01962","338.29288"
"239.00000","3.98174","828.23688","3.91479","2.87640","0.01966","338.48639"
"239.50000","3.98976","828.21967","3.92281","2.88442","0.01970","338.47934"
"240.00000","3.99843","828.73291","3.93146","2.89307","0.01975","338.68909"
"240.50000","4.00641","828.59619","3.93944","2.90105","0.01979","338.63324"
"241.00000","4.01489","828.78546","3.94792","2.90953","0.01983","338.71057"
"241.50000","4.02327","828.75995","3.95629","2.91790","0.01987","338.70016"
"242.00000","4.03137","828.58752","3.96441","2.92601","0.01991","338.62967"
"242.50000","4.03993","828.69611","3.97296","2.93457","0.01996","338.67407"
"243.00000","4.04801","828.40149","3.98105","2.94266","0.02000","338.55365"
"243.50000","4.05681","828.69989","3.98984","2.95145","0.02004","338.67560"
"244.00000","4.06466","828.32129","3.99770","2.95931","0.02008","338.52087"
"244.50000","4.07342","828.43750","4.00646","2.96807","0.02013","338.56836"
"245.00000","4.08143","828.07410","4.01449","2.97610","0.02017","338.41986"
"245.50000","4.09011","828.15692","4.02316","2.98477","0.02021","338.45370"
"246.00000","4.09818","827.86371","4.03124","2.99285","0.02025","338.33386"
"246.50000","4.10649","827.49603","4.03957","3.00118","0.02029","338.18359"
"247.00000","4.11497","827.41425","4.04805","3.00966","0.02033","338.15018"
"247.50000","4.12300","826.79938","4.05611","3.01772","0.02037","337.89890"
"248.00000","4.13156","826.72595","4.06468","3.02629","0.02042","337.86890"
"248.50000","4.13968","826.20166","4.07282","3.03443","0.02046","337.65463"
"249.00000","4.14850","826.07642","4.08164","3.04325","0.02050","337.60342"
"249.50000","4.15636","825.43317","4.08953","3.05114","0.02054","337.34055"
"250.00000","4.16505","825.01367","4.09824","3.05985","0.02059","337.16910"
"250.50000","4.17318","824.31903","4.10640","3.06801","0.02063","336.88522"
"251.00000","4.18170","823.91229","4.11494","3.07655","0.02067","336.71899"
"251.50000","4.18978","822.95435","4.12305","3.08466","0.02071","336.32748"
"252.00000","4.19812","822.17633","4.13143","3.09304","0.02075","336.00952"
"252.50000","4.20666","821.41382","4.14000","3.10161","0.02080","335.69791"
"253.00000","4.21463","820.30341","4.14803","3.10964","0.02084","335.24411"
"253.50000","4.22331","819.55688","4.15674","3.11835","0.02088","334.93903"
"254.00000","4.23136","818.46637","4.16484","3.12645","0.02092","334.49335"
"254.50000","4.24021","817.80066","4.17371","3.13532","0.02097","334.22128"
"255.00000","4.24801","816.35229","4.18158","3.14319","0.02100","333.62936"
"255.50000","4.25676","815.58099","4.19036","3.15197","0.02105","333.31415"
"256.00000","4.26482","814.32379","4.19848","3.16009","0.02109","332.80032"
"256.50000","4.27326","813.29962","4.20696","3.16856","0.02113","332.38177"
"257.00000","4.28149","812.09912","4.21524","3.17685","0.02117","331.89114"
"257.50000","4.28973","811.06854","4.22352","3.18513","0.02122","331.46997"
"258.00000","4.29836","810.52368","4.23218","3.19379","0.02126","331.24728"
"258.50000","4.30629","809.36731","4.24016","3.20177","0.02130","330.77472"
"259.00000","4.31506","808.96130","4.24895","3.21056","0.02134","330.60876"
"259.50000","4.32303","808.15546","4.25695","3.21856","0.02138","330.27945"
"260.00000","4.33193","807.77435","4.26587","3.22748","0.02143","330.12369"
"260.50000","4.33978","806.89349","4.27376","3.23537","0.02147","329.76370"
"261.00000","4.34834","806.71729","4.28232","3.24393","0.02151","329.69168"
"261.50000","4.35653","806.16315","4.29054","3.25215","0.02155","329.46521"
"262.00000","4.36481","805.73645","4.29883","3.26044","0.02159","329.29083"
"262.50000","4.37313","805.45984","4.30717","3.26877","0.02164","329.17780"
"263.00000","4.38135","805.00256","4.31540","3.27701","0.02168","328.99091"
"263.50000","4.39006","804.93835","4.32412","3.28573","0.02172","328.96466"
"264.00000","4.39802","804.48102","4.33210","3.29371","0.02176","328.77777"
"264.50000","4.40673","804.38190","4.34081","3.30242","0.02180","328.73724"
"265.00000","4.41476","804.00305","4.34886","3.31047","0.02184","328.58243"
"265.50000","4.42353","804.02179","4.35763","3.31924","0.02189","328.59009"
"266.00000","4.43137","803.49622","4.36549","3.32710","0.02193","328.37531"
"266.50000","4.43993","803.30780","4.37406","3.33567","0.02197","328.29828"
"267.00000","4.44820","802.99377","4.38234","3.34395","0.02201","328.16995"
"267.50000","4.45641","802.68433","4.39057","3.35218","0.02205","328.04349"
"268.00000","4.46486","802.38989","4.39904","3.36064","0.02210","327.92316"
"268.50000","4.47305","801.98291","4.40724","3.36885","0.02214","327.75684"
"269.00000","4.48181","801.92273","4.41601","3.37762","0.02218","327.73224"
"269.50000","4.48962","801.08380","4.42385","3.38546","0.02222","327.38937"
"270.00000","4.49848","800.79150","4.43272","3.39433","0.02227","327.26993"
"270.50000","4.50639","798.68127","4.44072","3.40233","0.02231","326.40750"
"271.00000","4.51517","798.28564","4.44952","3.41113","0.02235","326.24582"
"271.50000","4.52308","797.17413","4.45748","3.41908","0.02239","325.79156"
"272.00000","4.53155","796.47473","4.46597","3.42758","0.02243","325.50574"
"272.50000","4.53990","795.48676","4.47437","3.43598","0.02248","325.10196"
"273.00000","4.54803","794.26794","4.48255","3.44416","0.02252","324.60385"
"273.50000","4.55661","793.35968","4.49117","3.45278","0.02256","324.23267"
"274.00000","4.56466","792.14117","4.49927","3.46088","0.02260","323.73468"
"274.50000","4.57348","791.40076","4.50812","3.46973","0.02264","323.43207"
"275.00000","4.58134","790.12634","4.51604","3.47765","0.02268","322.91125"
"275.50000","4.59007","789.54895","4.52479","3.48640","0.02273","322.67529"
"276.00000","4.59810","788.57446","4.53287","3.49447","0.02277","322.27701"
"276.50000","4.60678","788.04614","4.54156","3.50317","0.02281","322.06110"
"277.00000","4.61476","787.10571","4.54959","3.51120","0.02285","321.67676"
"277.50000","4.62312","786.41400","4.55797","3.51958","0.02290","321.39407"
"278.00000","4.63163","782.20087","4.56666","3.52827","0.02294","319.67224"
"278.50000","4.63973","781.03693","4.57480","3.53641","0.02298","319.19656"
"279.00000","4.64830","780.33008","4.58341","3.54502","0.02302","318.90768"
"279.50000","4.65638","779.53778","4.59152","3.55313","0.02306","318.58389"
"280.00000","4.66517","778.90454","4.60033","3.56194","0.02311","318.32510"
"280.50000","4.67296","777.61383","4.60818","3.56979","0.02315","317.79761"
"281.00000","4.68169","777.16339","4.61693","3.57854","0.02319","317.61353"
"281.50000","4.68976","776.41101","4.62503","3.58664","0.02323","317.30603"
"282.00000","4.69835","776.25964","4.63363","3.59524","0.02328","317.24417"
"282.50000","4.70645","775.61401","4.64176","3.60337","0.02332","316.98032"
"283.00000","4.71483","775.42603","4.65015","3.61176","0.02336","316.90347"
"283.50000","4.72335","775.08313","4.65868","3.62029","0.02340","316.76334"
"284.00000","4.73131","774.66589","4.66665","3.62826","0.02344","316.59283"
"284.50000","4.74001","774.33984","4.67536","3.63697","0.02349","316.45956"
"285.00000","4.74799","773.84894","4.68336","3.64497","0.02353","316.25894"
"285.50000","4.75685","773.92694","4.69222","3.65383","0.02357","316.29083"
"286.00000","4.76466","773.50342","4.70005","3.66166","0.02361","316.11774"
"286.50000","4.77338","771.60114","4.70885","3.67046","0.02365","315.34030"
"287.00000","4.78147","770.41852","4.71699","3.67860","0.02369","314.85699"
"287.50000","4.78997","770.25104","4.72550","3.68711","0.02374","314.78854"
"288.00000","4.79820","769.78918","4.73375","3.69536","0.02378","314.59979"
"288.50000","4.80640","769.49744","4.74195","3.70356","0.02382","314.48056"
"289.00000","4.81500","769.45306","4.75056","3.71217","0.02386","314.46243"
"289.50000","4.82297","769.18018","4.75854","3.72015","0.02390","314.35089"
"290.00000","4.83167","768.24261","4.76729","3.72889","0.02395","313.96774"
"290.50000","4.83974","767.85089","4.77536","3.73697","0.02399","313.80765"
"291.00000","4.84857","767.67883","4.78420","3.74581","0.02403","313.73734"
"291.50000","4.85639","766.49805","4.79207","3.75368","0.02407","313.25476"
"291.95600","4.86401","744.80103","4.80060","3.76221","0.02411","304.38757"
"292.45600","4.87257","742.97845","4.80924","3.77084","0.02416","303.64270"
"292.95600","4.88063","740.89252","4.81739","3.77900","0.02420","302.79022"
"293.45600","4.88926","739.16504","4.82609","3.78770","0.02424","302.08423"
"293.95600","4.89732","738.15967","4.83420","3.79581","0.02428","301.67334"
"294.45600","4.90610","736.56012","4.84305","3.80466","0.02433","301.01965"
"294.95600","4.91392","735.35590","4.85092","3.81253","0.02437","300.52750"
"295.45600","4.92260","733.89563","4.85967","3.82128","0.02441","299.93069"
"295.95600","4.93073","719.61237","4.86843","3.83004","0.02445","294.09338"
"296.37100","4.93747","679.90625","4.87695","3.83856","0.02450","277.86615"
"296.87100","4.94624","667.19019","4.88628","3.84789","0.02454","272.66931"
"297.37100","4.95425","665.10529","4.89439","3.85600","0.02459","271.81726"
"297.87100","4.96303","664.51447","4.90320","3.86481","0.02463","271.57581"
"298.37100","4.97090","663.71838","4.91110","3.87271","0.02467","271.25046"
"298.87100","4.97948","663.39581","4.91970","3.88131","0.02471","271.11862"
"299.37100","4.98773","663.21368","4.92795","3.88956","0.02475","271.04419"
"299.87100","4.99595","662.87256","4.93619","3.89780","0.02480","270.90479"
"300.37100","5.00440","662.17419","4.94466","3.90627","0.02484","270.61938"
"300.87100","5.01253","662.08850","4.95281","3.91442","0.02488","270.58435"
"301.37100","5.02130","662.34601","4.96156","3.92317","0.02492","270.68961"
"301.87100","5.02915","662.12689","4.96942","3.93103","0.02496","270.60004"
"302.37100","5.03795","662.21356","4.97822","3.93983","0.02501","270.63547"
"302.87100","5.04591","661.30792","4.98622","3.94783","0.02505","270.26535"
"303.37100","5.05472","659.26251","4.99512","3.95673","0.02509","269.42941"
"303.87100","5.06267","657.62018","5.00315","3.96476","0.02513","268.75824"
"304.37100","5.07106","654.05371","5.01170","3.97330","0.02517","267.30066"
"304.87100","5.07944","651.16736","5.02020","3.98181","0.02522","266.12106"
"305.37100","5.08756","643.09973","5.02868","3.99028","0.02526","262.82397"
"305.87100","5.09604","640.99835","5.03725","3.99886","0.02530","261.96518"
"306.37100","5.10419","637.67047","5.04555","4.00716","0.02534","260.60510"
"306.87100","5.11297","633.68634","5.05451","4.01612","0.02539","258.97687"
"307.37100","5.12087","626.90399","5.06271","4.02432","0.02543","256.20505"
"307.87100","5.12959","619.20679","5.07179","4.03339","0.02548","253.05933"
"308.37100","5.13766","613.71832","5.08010","4.04171","0.02552","250.81628"
"308.87100","5.14631","603.02637","5.08923","4.05084","0.02556","246.44666"
"309.37100","5.15428","596.72125","5.09748","4.05909","0.02561","243.86987"
"309.87100","5.16269","592.14722","5.10609","4.06770","0.02565","242.00053"
"310.37100","5.17112","588.62598","5.11469","4.07630","0.02569","240.56146"
"310.87100","5.17919","582.24628","5.12307","4.08467","0.02573","237.95419"
"311.37100","5.18778","571.02478","5.13220","4.09381","0.02578","233.36815"
"311.87100","5.19588","546.28558","5.14150","4.10311","0.02583","223.25766"
"312.37100","5.20472","535.36932","5.15087","4.11248","0.02587","218.79637"
"312.87100","5.21250","533.54010","5.15875","4.12036","0.02591","218.04880"
"313.37100","5.22132","533.80359","5.16756","4.12917","0.02596","218.15648"
"313.87100","5.22930","533.73895","5.17554","4.13715","0.02600","218.13007"
"314.37100","5.23789","534.40515","5.18409","4.14570","0.02604","218.40233"
"314.87100","5.24598","534.30652","5.19219","4.15379","0.02608","218.36201"
"315.37100","5.25428","534.74249","5.20046","4.16207","0.02612","218.54019"
"315.87100","5.26282","535.47430","5.20897","4.17058","0.02617","218.83928"
"316.37100","5.27083","535.57031","5.21697","4.17858","0.02621","218.87851"
"316.87100","5.27954","534.68707","5.22573","4.18734","0.02625","218.51755"
"317.37100","5.28754","533.49432","5.23379","4.19540","0.02629","218.03009"
"317.87100","5.29643","531.97314","5.24275","4.20436","0.02634","217.40842"
"318.30600","5.30330","528.66205","5.24979","4.21140","0.02637","216.05522"