File: flexion/5_axis/Specimen_RawData_10.csv
Specimen properties : Specimen label,"F3"
Specimen properties : Support span,"72.00",mm
Specimen properties : Thickness,"4.77",mm
Specimen properties : Width,"14.93",mm
Maximum Load : Maximum Load,"1444",N
Tangent Modulus of Elasticity : Tangent Modulus of Elasticity,"44007129860.46820",Pa
Test : Rate 1,"1.00000",mm/min
Specimen notes : Specimen note 1,""

Time,Displacement,Load,Flexure extension,Corrected extension,Flexure strain (Corrected extension),Flexure stress
(s),(mm),(N),(mm),(mm),(mm/mm),(MPa)
"0.00000","-0.00033","49.49940","0.05948","-1.05596","0.00033","15.73719"
"0.40000","0.00383","52.20161","0.06328","-1.05217","0.00035","16.59629"
"0.80000","0.01094","56.99047","0.06975","-1.04569","0.00039","18.11880"
"1.20000","0.01800","61.53838","0.07626","-1.03918","0.00042","19.56470"
"1.60000","0.02442","65.86411","0.08217","-1.03327","0.00045","20.93997"
"2.00000","0.03105","70.11981","0.08831","-1.02713","0.00049","22.29297"
"2.40000","0.03746","74.47366","0.09421","-1.02123","0.00052","23.67718"
"2.80000","0.04418","79.02405","0.10040","-1.01504","0.00055","25.12387"
"3.20000","0.05085","83.59956","0.10653","-1.00891","0.00059","26.57854"
"3.60000","0.05785","88.28075","0.11300","-1.00244","0.00062","28.06682"
"4.00000","0.06459","92.94785","0.11928","-0.99616","0.00066","29.55062"
"4.40000","0.07102","97.19923","0.12530","-0.99014","0.00069","30.90225"
"4.80000","0.07761","101.78716","0.13144","-0.98400","0.00073","32.36087"
"5.20000","0.08408","106.34640","0.13746","-0.97798","0.00076","33.81038"
"5.60000","0.09084","110.95594","0.14378","-0.97167","0.00079","35.27587"
"6.00000","0.09787","115.88107","0.15032","-0.96512","0.00083","36.84170"
"6.40000","0.10456","120.44827","0.15656","-0.95888","0.00086","38.29374"
"6.80000","0.11109","125.13243","0.16264","-0.95280","0.00090","39.78296"
"7.20000","0.11757","129.59277","0.16869","-0.94676","0.00093","41.20102"
"7.60000","0.12415","134.24162","0.17481","-0.94063","0.00097","42.67902"
"8.00000","0.13081","139.13168","0.18100","-0.93444","0.00100","44.23370"
"8.40000","0.13765","143.91116","0.18738","-0.92807","0.00103","45.75322"
"8.80000","0.14465","149.08379","0.19387","-0.92158","0.00107","47.39774"
"9.20000","0.15105","153.57918","0.19983","-0.91561","0.00110","48.82694"
"9.60000","0.15768","158.26955","0.20601","-0.90943","0.00114","50.31814"
"10.00000","0.16416","162.92447","0.21209","-0.90335","0.00117","51.79806"
"10.40000","0.17079","167.69289","0.21832","-0.89712","0.00121","53.31407"
"10.80000","0.17772","172.75177","0.22482","-0.89062","0.00124","54.92242"
"11.20000","0.18448","177.61308","0.23117","-0.88427","0.00128","56.46797"
"11.60000","0.19118","182.56253","0.23745","-0.87799","0.00131","58.04153"
"12.00000","0.19756","187.16170","0.24344","-0.87200","0.00134","59.50373"
"12.40000","0.20422","191.98428","0.24969","-0.86575","0.00138","61.03696"
"12.80000","0.21076","196.60324","0.25584","-0.85960","0.00141","62.50545"
"13.20000","0.21757","201.61250","0.26222","-0.85322","0.00145","64.09803"
"13.60000","0.22463","206.76974","0.26887","-0.84658","0.00148","65.73766"
"14.00000","0.23106","211.46169","0.27493","-0.84052","0.00152","67.22935"
"14.40000","0.23774","216.26753","0.28122","-0.83423","0.00155","68.75726"
"14.80000","0.24419","220.79335","0.28730","-0.82814","0.00159","70.19614"
"15.20000","0.25079","225.59409","0.29353","-0.82192","0.00162","71.72242"
"15.60000","0.25751","230.45332","0.29985","-0.81559","0.00166","73.26730"
"16.00000","0.26444","235.39665","0.30639","-0.80906","0.00169","74.83891"
"16.40000","0.27129","240.24605","0.31285","-0.80259","0.00173","76.38067"
"16.80000","0.27762","244.77809","0.31882","-0.79662","0.00176","77.82153"
"17.20000","0.28428","249.55292","0.32512","-0.79032","0.00179","79.33957"
"17.60000","0.29076","254.14554","0.33124","-0.78420","0.00183","80.79969"
"18.00000","0.29755","258.90280","0.33767","-0.77778","0.00186","82.31215"
"18.40000","0.30449","263.92645","0.34422","-0.77122","0.00190","83.90930"
"18.80000","0.31120","268.74136","0.35056","-0.76488","0.00194","85.44009"
"19.20000","0.31775","273.38232","0.35676","-0.75868","0.00197","86.91558"
"19.60000","0.32423","277.97742","0.36288","-0.75256","0.00200","88.37649"
"20.00000","0.33082","282.66443","0.36911","-0.74633","0.00204","89.86661"
"20.40000","0.33748","287.39853","0.37541","-0.74003","0.00207","91.37171"
"20.80000","0.34437","292.31812","0.38194","-0.73350","0.00211","92.93578"
"21.20000","0.35134","297.32605","0.38858","-0.72686","0.00215","94.52793"
"21.60000","0.35773","301.92352","0.39466","-0.72078","0.00218","95.98959"
"22.00000","0.36432","306.55496","0.40094","-0.71450","0.00221","97.46205"
"22.40000","0.37083","311.25876","0.40713","-0.70831","0.00225","98.95752"
"22.80000","0.37748","315.99310","0.41347","-0.70198","0.00228","100.46269"
"23.20000","0.38435","320.88754","0.42001","-0.69543","0.00232","102.01877"
"23.60000","0.39117","325.92902","0.42650","-0.68894","0.00235","103.62158"
"24.00000","0.39786","330.60486","0.43287","-0.68257","0.00239","105.10816"
"24.40000","0.40428","335.30576","0.43898","-0.67647","0.00242","106.60270"
"24.80000","0.41090","340.01367","0.44528","-0.67016","0.00246","108.09947"
"25.20000","0.41746","344.85370","0.45153","-0.66391","0.00249","109.63825"
"25.60000","0.42425","349.72144","0.45800","-0.65744","0.00253","111.18584"
"26.00000","0.43130","354.96185","0.46472","-0.65072","0.00257","112.85191"
"26.40000","0.43770","359.50488","0.47083","-0.64461","0.00260","114.29626"
"26.80000","0.44438","364.37445","0.47719","-0.63825","0.00263","115.84442"
"27.20000","0.45083","369.02493","0.48335","-0.63209","0.00267","117.32294"
"27.60000","0.45750","373.88110","0.48971","-0.62573","0.00270","118.86684"
"28.00000","0.46427","378.90686","0.49616","-0.61929","0.00274","120.46466"
"28.40000","0.47114","383.91473","0.50270","-0.61274","0.00278","122.05680"
"28.80000","0.47792","388.97650","0.50916","-0.60629","0.00281","123.66608"
"29.20000","0.48431","393.63144","0.51528","-0.60016","0.00284","125.14600"
"29.60000","0.49092","398.37366","0.52162","-0.59382","0.00288","126.65368"
"30.00000","0.49741","403.18417","0.52784","-0.58761","0.00291","128.18307"
"30.40000","0.50423","408.29471","0.53437","-0.58107","0.00295","129.80785"
"30.80000","0.51124","413.39340","0.54108","-0.57436","0.00299","131.42886"
"31.20000","0.51788","418.35410","0.54745","-0.56800","0.00302","133.00600"
"31.60000","0.52448","423.13287","0.55377","-0.56167","0.00306","134.52530"
"32.00000","0.53087","427.67249","0.55990","-0.55554","0.00309","135.96857"
"32.40000","0.53747","432.62811","0.56622","-0.54923","0.00313","137.54410"
"32.80000","0.54414","437.49612","0.57261","-0.54283","0.00316","139.09177"
"33.20000","0.55107","442.70367","0.57925","-0.53619","0.00320","140.74739"
"33.60000","0.55797","447.71326","0.58586","-0.52958","0.00323","142.34006"
"34.00000","0.56437","452.48071","0.59199","-0.52345","0.00327","143.85577"
"34.40000","0.57099","457.32190","0.59833","-0.51711","0.00330","145.39491"
"34.80000","0.57748","462.01367","0.60456","-0.51088","0.00334","146.88655"
"35.20000","0.58412","466.94168","0.61091","-0.50453","0.00337","148.45329"
"35.60000","0.59106","472.06924","0.61756","-0.49788","0.00341","150.08348"
"36.00000","0.59787","477.14557","0.62409","-0.49136","0.00345","151.69739"
"36.40000","0.60452","481.98541","0.63046","-0.48499","0.00348","153.23610"
"36.80000","0.61093","486.66312","0.63660","-0.47884","0.00351","154.72327"
"37.20000","0.61751","491.45670","0.64292","-0.47252","0.00355","156.24728"
"37.60000","0.62410","496.19318","0.64927","-0.46617","0.00358","157.75313"
"38.00000","0.63096","501.28159","0.65588","-0.45956","0.00362","159.37088"
"38.40000","0.63802","506.63980","0.66267","-0.45278","0.00366","161.07440"
"38.80000","0.64443","511.35309","0.66884","-0.44661","0.00369","162.57288"
"39.20000","0.65108","516.12152","0.67525","-0.44019","0.00373","164.08888"
"39.60000","0.65752","520.98419","0.68145","-0.43399","0.00376","165.63486"
"40.00000","0.66415","525.83228","0.68784","-0.42760","0.00380","167.17619"
"40.40000","0.67088","530.75824","0.69432","-0.42112","0.00383","168.74229"
"40.80000","0.67779","535.85193","0.70098","-0.41447","0.00387","170.36171"
"41.20000","0.68458","540.93811","0.70751","-0.40793","0.00391","171.97874"
"41.60000","0.69098","545.61182","0.71369","-0.40176","0.00394","173.46465"
"42.00000","0.69764","550.52844","0.72011","-0.39533","0.00398","175.02777"
"42.40000","0.70412","555.24316","0.72635","-0.38909","0.00401","176.52670"
"42.80000","0.71091","560.31506","0.73290","-0.38254","0.00405","178.13921"
"43.20000","0.71789","565.49323","0.73963","-0.37581","0.00408","179.78548"
"43.60000","0.72445","570.28259","0.74596","-0.36948","0.00412","181.30815"
"44.00000","0.73110","575.07910","0.75238","-0.36307","0.00415","182.83308"
"44.40000","0.73757","579.90826","0.75861","-0.35683","0.00419","184.36841"
"44.80000","0.74418","584.77753","0.76499","-0.35045","0.00422","185.91647"
"45.20000","0.75083","589.58179","0.77141","-0.34403","0.00426","187.44388"
"45.60000","0.75778","594.80530","0.77811","-0.33733","0.00430","189.10457"
"46.00000","0.76465","599.88464","0.78476","-0.33068","0.00433","190.71944"
"46.40000","0.77102","604.53961","0.79092","-0.32452","0.00437","192.19937"
"46.80000","0.77764","609.40173","0.79732","-0.31812","0.00440","193.74518"
"47.20000","0.78416","614.12238","0.80363","-0.31181","0.00444","195.24599"
"47.60000","0.79079","618.91809","0.81005","-0.30539","0.00447","196.77068"
"48.00000","0.79773","624.16675","0.81675","-0.29869","0.00451","198.43936"
"48.40000","0.80455","629.10498","0.82335","-0.29210","0.00455","200.00937"
"48.80000","0.81121","634.03247","0.82979","-0.28565","0.00458","201.57594"
"49.20000","0.81761","638.78882","0.83597","-0.27947","0.00462","203.08812"
"49.60000","0.82417","643.43738","0.84233","-0.27311","0.00465","204.56602"
"50.00000","0.83076","648.19092","0.84870","-0.26674","0.00469","206.07730"
"50.40000","0.83759","653.34412","0.85531","-0.26013","0.00472","207.71564"
"50.80000","0.84469","658.55988","0.86217","-0.25327","0.00476","209.37387"
"51.20000","0.85110","663.15460","0.86837","-0.24707","0.00479","210.83466"
"51.60000","0.85767","668.03333","0.87473","-0.24071","0.00483","212.38573"
"52.00000","0.86422","672.70349","0.88107","-0.23437","0.00486","213.87050"
"52.40000","0.87082","677.55640","0.88745","-0.22799","0.00490","215.41338"
"52.80000","0.87760","682.56067","0.89402","-0.22143","0.00494","217.00436"
"53.20000","0.88444","687.48773","0.90063","-0.21481","0.00497","218.57080"
"53.60000","0.89126","692.49005","0.90723","-0.20821","0.00501","220.16118"
"54.00000","0.89760","697.09277","0.91337","-0.20208","0.00504","221.62451"
"54.40000","0.90428","701.90363","0.91983","-0.19561","0.00508","223.15401"
"54.80000","0.91078","706.62524","0.92612","-0.18933","0.00511","224.65514"
"55.20000","0.91759","711.66724","0.93270","-0.18274","0.00515","226.25812"
"55.60000","0.92462","716.80310","0.93951","-0.17593","0.00519","227.89095"
"56.00000","0.93118","721.61047","0.94585","-0.16959","0.00522","229.41934"
"56.40000","0.93778","726.46387","0.95223","-0.16321","0.00526","230.96237"
"56.80000","0.94423","731.16748","0.95847","-0.15697","0.00529","232.45778"
"57.20000","0.95084","735.89996","0.96488","-0.15057","0.00533","233.96236"
"57.60000","0.95745","740.70374","0.97126","-0.14418","0.00536","235.48961"
"58.00000","0.96438","745.77472","0.97798","-0.13746","0.00540","237.10181"
"58.40000","0.97134","750.84485","0.98473","-0.13071","0.00544","238.71373"
"58.80000","0.97769","755.46509","0.99089","-0.12455","0.00547","240.18263"
"59.20000","0.98433","760.27527","0.99732","-0.11812","0.00551","241.71191"
"59.60000","0.99082","764.92725","1.00362","-0.11182","0.00554","243.19090"
"60.00000","0.99751","769.76709","1.01011","-0.10534","0.00558","244.72963"
"60.40000","1.00442","774.83167","1.01680","-0.09864","0.00561","246.33978"
"60.80000","1.01118","779.66132","1.02336","-0.09208","0.00565","247.87526"
"61.20000","1.01781","784.50122","1.02980","-0.08564","0.00569","249.41400"
"61.60000","1.02425","789.17834","1.03604","-0.07940","0.00572","250.90099"
"62.00000","1.03084","793.84436","1.04243","-0.07301","0.00576","252.38443"
"62.40000","1.03743","798.67157","1.04881","-0.06663","0.00579","253.91913"
"62.80000","1.04432","803.71881","1.05549","-0.05995","0.00583","255.52379"
"63.20000","1.05138","808.87451","1.06232","-0.05313","0.00586","257.16293"
"63.60000","1.05780","813.43073","1.06854","-0.04690","0.00590","258.61148"
"64.00000","1.06435","818.13306","1.07489","-0.04055","0.00593","260.10648"
"64.40000","1.07085","822.77710","1.08119","-0.03426","0.00597","261.58292"
"64.80000","1.07744","827.52545","1.08757","-0.02787","0.00600","263.09256"
"65.20000","1.08422","832.40869","1.09414","-0.02130","0.00604","264.64508"
"65.60000","1.09115","837.43127","1.10085","-0.01459","0.00608","266.24188"
"66.00000","1.09794","842.37970","1.10743","-0.00802","0.00611","267.81512"
"66.40000","1.10434","846.72748","1.11365","-0.00180","0.00615","269.19739"
"66.80000","1.11094","851.53088","1.12004","0.00460","0.00618","270.72452"
"67.20000","1.11745","856.11438","1.12636","0.01092","0.00622","272.18173"
"67.60000","1.12419","861.03210","1.13289","0.01745","0.00625","273.74521"
"68.00000","1.13128","866.23102","1.13977","0.02433","0.00629","275.39810"
"68.40000","1.13775","870.86011","1.14604","0.03060","0.00633","276.86981"
"68.80000","1.14442","875.55554","1.15251","0.03707","0.00636","278.36261"
"69.20000","1.15088","880.06396","1.15879","0.04335","0.00640","279.79596"
"69.60000","1.15755","884.92438","1.16525","0.04981","0.00643","281.34122"
"70.00000","1.16418","889.63190","1.17169","0.05625","0.00647","282.83786"
"70.40000","1.17103","894.53180","1.17834","0.06290","0.00651","284.39569"
"70.80000","1.17802","899.60095","1.18511","0.06967","0.00654","286.00729"
"71.20000","1.18434","903.98798","1.19125","0.07581","0.00658","287.40204"
"71.60000","1.19097","908.66962","1.19768","0.08224","0.00661","288.89047"
"72.00000","1.19742","913.12891","1.20395","0.08850","0.00665","290.30820"
"72.40000","1.20416","918.00513","1.21048","0.09504","0.00668","291.85849"
"72.80000","1.21112","922.99506","1.21723","0.10179","0.00672","293.44492"
"73.20000","1.21790","927.73309","1.22382","0.10838","0.00676","294.95126"
"73.60000","1.22452","932.45013","1.23023","0.11479","0.00679","296.45093"
"74.00000","1.23091","936.80536","1.23644","0.12100","0.00683","297.83557"
"74.40000","1.23753","941.46448","1.24287","0.12742","0.00686","299.31683"
"74.80000","1.24406","946.04669","1.24921","0.13376","0.00690","300.77365"
"75.20000","1.25100","951.00330","1.25592","0.14048","0.00693","302.34949"
"75.60000","1.25795","955.91431","1.26265","0.14721","0.00697","303.91083"
"76.00000","1.26446","960.40417","1.26896","0.15351","0.00701","305.33829"
"76.40000","1.27103","964.92499","1.27533","0.15988","0.00704","306.77557"
"76.80000","1.27749","969.35071","1.28159","0.16615","0.00708","308.18262"
"77.20000","1.28413","974.03125","1.28802","0.17258","0.00711","309.67068"
"77.60000","1.29090","978.62061","1.29458","0.17914","0.00715","311.12976"
"78.00000","1.29784","983.57361","1.30130","0.18585","0.00718","312.70447"
"78.40000","1.30456","988.25635","1.30781","0.19237","0.00722","314.19324"
"78.80000","1.31098","992.40057","1.31405","0.19861","0.00725","315.51077"
"79.20000","1.31756","996.84894","1.32043","0.20499","0.00729","316.92505"
"79.60000","1.32411","1001.26807","1.32680","0.21136","0.00733","318.32999"
"80.00000","1.33086","1005.84125","1.33336","0.21792","0.00736","319.78394"
"80.40000","1.33799","1010.72552","1.34028","0.22484","0.00740","321.33679"
"80.80000","1.34452","1015.07910","1.34663","0.23119","0.00743","322.72089"
"81.20000","1.35107","1019.42609","1.35300","0.23756","0.00747","324.10294"
"81.60000","1.35757","1023.61749","1.35932","0.24388","0.00750","325.43549"
"82.00000","1.36418","1027.98376","1.36575","0.25030","0.00754","326.82364"
"82.40000","1.37083","1032.34607","1.37222","0.25678","0.00758","328.21054"
"82.80000","1.37770","1036.83997","1.37889","0.26345","0.00761","329.63925"
"83.20000","1.38463","1041.58911","1.38563","0.27019","0.00765","331.14914"
"83.60000","1.39103","1045.39648","1.39187","0.27643","0.00768","332.35962"
"84.00000","1.39767","1049.77905","1.39832","0.28288","0.00772","333.75296"
"84.40000","1.40414","1053.69897","1.40463","0.28918","0.00775","334.99921"
"84.80000","1.41080","1057.87170","1.41111","0.29566","0.00779","336.32581"
"85.20000","1.41783","1062.28210","1.41794","0.30250","0.00783","337.72800"
"85.60000","1.42443","1066.30688","1.42437","0.30893","0.00786","339.00760"
"86.00000","1.43112","1070.41687","1.43088","0.31544","0.00790","340.31427"
"86.40000","1.43756","1074.21753","1.43716","0.32171","0.00793","341.52258"
"86.80000","1.44423","1077.90259","1.44367","0.32822","0.00797","342.69418"
"87.20000","1.45080","1081.37390","1.45008","0.33464","0.00801","343.79779"
"87.60000","1.45767","1085.23193","1.45679","0.34135","0.00804","345.02438"
"88.00000","1.46465","1089.23047","1.46360","0.34816","0.00808","346.29562"
"88.40000","1.47106","1092.54480","1.46986","0.35442","0.00811","347.34933"
"88.80000","1.47769","1096.15601","1.47635","0.36090","0.00815","348.49744"
"89.20000","1.48411","1099.20581","1.48263","0.36719","0.00819","349.46704"
"89.60000","1.49082","1102.35889","1.48921","0.37377","0.00822","350.46948"
"90.00000","1.49765","1105.51453","1.49590","0.38046","0.00826","351.47275"
"90.40000","1.50455","1108.55945","1.50267","0.38723","0.00830","352.44083"
"90.80000","1.51121","1111.69104","1.50920","0.39376","0.00833","353.43643"
"91.20000","1.51762","1114.59424","1.51548","0.40004","0.00837","354.35944"
"91.60000","1.52424","1117.00330","1.52200","0.40656","0.00840","355.12534"
"92.00000","1.53076","1117.84204","1.52848","0.41304","0.00844","355.39200"
"92.40000","1.53756","1120.54236","1.53516","0.41972","0.00848","356.25049"
"92.80000","1.54457","1123.06787","1.54207","0.42663","0.00851","357.05344"
"93.20000","1.55119","1126.34937","1.54855","0.43311","0.00855","358.09671"
"93.60000","1.55771","1129.77246","1.55492","0.43948","0.00858","359.18500"
"94.00000","1.56422","1133.21863","1.56129","0.44585","0.00862","360.28064"
"94.40000","1.57080","1137.04248","1.56770","0.45225","0.00865","361.49634"
"94.80000","1.57752","1140.75684","1.57425","0.45881","0.00869","362.67722"
"95.20000","1.58440","1144.56580","1.58098","0.46553","0.00873","363.88818"
"95.60000","1.59129","1148.63306","1.58770","0.47226","0.00877","365.18127"
"96.00000","1.59767","1152.08240","1.59393","0.47849","0.00880","366.27792"
"96.40000","1.60431","1155.84912","1.60041","0.48497","0.00884","367.47546"
"96.80000","1.61079","1159.65747","1.60673","0.49129","0.00887","368.68625"
"97.20000","1.61748","1163.16980","1.61328","0.49784","0.00891","369.80292"
"97.60000","1.62452","1166.55859","1.62019","0.50475","0.00894","370.88031"
"98.00000","1.63117","1170.23816","1.62669","0.51124","0.00898","372.05014"
"98.40000","1.63779","1174.12830","1.63315","0.51770","0.00902","373.28690"
"98.80000","1.64422","1177.94385","1.63941","0.52397","0.00905","374.49997"
"99.20000","1.65088","1181.88757","1.64591","0.53046","0.00909","375.75378"
"99.60000","1.65743","1185.81628","1.65230","0.53686","0.00912","377.00284"
"100.00000","1.66428","1189.69653","1.65899","0.54355","0.00916","378.23648"
"100.40000","1.67132","1193.15735","1.66589","0.55045","0.00920","379.33676"
"100.80000","1.67773","1184.92334","1.67263","0.55719","0.00923","376.71893"
"101.20000","1.68438","1184.85925","1.67929","0.56384","0.00927","376.69858"
"101.60000","1.69082","1185.75049","1.68569","0.57025","0.00931","376.98190"
"102.00000","1.69745","1185.36816","1.69233","0.57689","0.00934","376.86035"
"102.40000","1.70430","1185.60632","1.69918","0.58373","0.00938","376.93610"
"102.80000","1.71115","1184.03662","1.70609","0.59065","0.00942","376.43704"
"103.20000","1.71792","1185.87048","1.71278","0.59734","0.00946","377.02008"
"103.60000","1.72425","1187.61084","1.71904","0.60360","0.00949","377.57336"
"104.00000","1.73091","1189.95752","1.72560","0.61016","0.00953","378.31946"
"104.40000","1.73741","1192.21948","1.73201","0.61657","0.00956","379.03857"
"104.80000","1.74424","1195.01318","1.73873","0.62329","0.00960","379.92679"
"105.20000","1.75123","1197.96545","1.74559","0.63015","0.00964","380.86539"
"105.60000","1.75787","1200.70105","1.75211","0.63667","0.00967","381.73511"
"106.00000","1.76440","1203.29407","1.75852","0.64308","0.00971","382.55948"
"106.40000","1.77084","1204.53320","1.76492","0.64947","0.00974","382.95346"
"106.80000","1.77745","1205.28235","1.77148","0.65604","0.00978","383.19162"
"107.20000","1.78419","1207.30945","1.77814","0.66270","0.00982","383.83609"
"107.60000","1.79113","1210.10583","1.78496","0.66951","0.00985","384.72513"
"108.00000","1.79799","1212.30542","1.79171","0.67627","0.00989","385.42444"
"108.40000","1.80436","1214.54614","1.79799","0.68255","0.00993","386.13684"
"108.80000","1.81094","1217.02539","1.80446","0.68902","0.00996","386.92505"
"109.20000","1.81749","1219.49084","1.81090","0.69546","0.01000","387.70889"
"109.60000","1.82415","1221.59021","1.81747","0.70202","0.01003","388.37631"
"110.00000","1.83111","1223.70032","1.82434","0.70889","0.01007","389.04718"
"110.40000","1.83784","1225.69043","1.83098","0.71554","0.01011","389.67990"
"110.80000","1.84448","1227.33191","1.83755","0.72211","0.01014","390.20175"
"111.20000","1.85092","1228.93420","1.84392","0.72848","0.01018","390.71118"
"111.60000","1.85752","1225.08704","1.85069","0.73525","0.01022","389.48807"
"112.00000","1.86415","1226.18237","1.85727","0.74183","0.01025","389.83630"
"112.40000","1.87095","1227.84070","1.86400","0.74856","0.01029","390.36353"
"112.80000","1.87798","1229.88220","1.87094","0.75549","0.01033","391.01257"
"113.20000","1.88432","1230.27197","1.87725","0.76181","0.01036","391.13651"
"113.60000","1.89102","1228.93066","1.88402","0.76858","0.01040","390.71005"
"114.00000","1.89750","1229.03125","1.89049","0.77505","0.01044","390.74203"
"114.40000","1.90416","1230.03455","1.89710","0.78166","0.01047","391.06100"
"114.80000","1.91103","1231.70544","1.90390","0.78846","0.01051","391.59222"
"115.20000","1.91782","1233.45508","1.91062","0.79518","0.01055","392.14850"
"115.60000","1.92456","1235.46533","1.91726","0.80182","0.01058","392.78760"
"116.00000","1.93095","1237.27026","1.92358","0.80813","0.01062","393.36145"
"116.40000","1.93753","1239.14478","1.93008","0.81464","0.01066","393.95740"
"116.80000","1.94409","1241.06726","1.93655","0.82111","0.01069","394.56860"
"117.20000","1.95094","1243.38013","1.94329","0.82785","0.01073","395.30392"
"117.60000","1.95797","1245.93091","1.95021","0.83477","0.01077","396.11490"
"118.00000","1.96448","1247.65222","1.95665","0.84121","0.01080","396.66214"
"118.40000","1.97111","1249.54944","1.96321","0.84776","0.01084","397.26532"
"118.80000","1.97750","1251.17993","1.96952","0.85408","0.01087","397.78369"
"119.20000","1.98413","1252.88550","1.97608","0.86064","0.01091","398.32593"
"119.60000","1.99085","1254.77527","1.98273","0.86729","0.01095","398.92676"
"120.00000","1.99779","1256.81580","1.98958","0.87414","0.01098","399.57550"
"120.40000","2.00461","1258.76807","1.99631","0.88087","0.01102","400.19617"
"120.80000","2.01100","1260.42407","2.00264","0.88720","0.01106","400.72266"
"121.20000","2.01762","1262.18713","2.00918","0.89374","0.01109","401.28317"
"121.60000","2.02414","1263.71326","2.01564","0.90020","0.01113","401.76837"
"122.00000","2.03085","1265.16602","2.02229","0.90684","0.01116","402.23026"
"122.40000","2.03785","1266.89490","2.02922","0.91378","0.01120","402.77991"
"122.80000","2.04456","1268.32141","2.03586","0.92042","0.01124","403.23343"
"123.20000","2.05112","1269.73950","2.04237","0.92692","0.01128","403.68427"
"123.60000","2.05756","1271.04968","2.04875","0.93331","0.01131","404.10083"
"124.00000","2.06414","1272.62585","2.05526","0.93982","0.01135","404.60193"
"124.40000","2.07079","1274.13452","2.06185","0.94641","0.01138","405.08157"
"124.80000","2.07769","1275.81165","2.06868","0.95324","0.01142","405.61478"
"125.20000","2.08469","1277.76196","2.07560","0.96016","0.01146","406.23483"
"125.60000","2.09105","1279.07336","2.08191","0.96646","0.01149","406.65176"
"126.00000","2.09772","1280.70630","2.08851","0.97307","0.01153","407.17093"
"126.40000","2.10416","1282.11389","2.09489","0.97945","0.01157","407.61844"
"126.80000","2.11080","1283.79675","2.10146","0.98601","0.01160","408.15344"
"127.20000","2.11767","1285.65540","2.10825","0.99281","0.01164","408.74435"
"127.60000","2.12448","1287.42053","2.11499","0.99955","0.01168","409.30554"
"128.00000","2.13119","1289.02698","2.12163","1.00619","0.01171","409.81628"
"128.40000","2.13761","1290.18774","2.12800","1.01256","0.01175","410.18533"
"128.80000","2.14427","1291.16345","2.13462","1.01918","0.01178","410.49551"
"129.20000","2.15078","1291.90259","2.14110","1.02566","0.01182","410.73053"
"129.60000","2.15764","1293.01416","2.14791","1.03247","0.01186","411.08392"
"130.00000","2.16465","1294.02966","2.15488","1.03944","0.01190","411.40677"
"130.40000","2.17110","1294.54077","2.16131","1.04587","0.01193","411.56927"
"130.80000","2.17771","1295.16980","2.16789","1.05245","0.01197","411.76926"
"131.20000","2.18419","1296.12842","2.17434","1.05889","0.01200","412.07404"
"131.60000","2.19081","1297.08533","2.18091","1.06547","0.01204","412.37827"
"132.00000","2.19757","1298.65967","2.18760","1.07216","0.01208","412.87878"
"132.40000","2.20455","1300.37134","2.19451","1.07907","0.01212","413.42297"
"132.80000","2.21131","1302.20386","2.20120","1.08576","0.01215","414.00555"
"133.20000","2.21765","1303.59875","2.20748","1.09204","0.01219","414.44904"
"133.60000","2.22426","1305.37390","2.21402","1.09858","0.01222","415.01340"
"134.00000","2.23079","1307.01599","2.22048","1.10504","0.01226","415.53546"
"134.40000","2.23751","1308.80896","2.22712","1.11168","0.01230","416.10550"
"134.80000","2.24453","1310.55969","2.23407","1.11863","0.01233","416.66211"
"135.20000","2.25121","1311.68872","2.24070","1.12526","0.01237","417.02106"
"135.60000","2.25783","1309.90869","2.24740","1.13196","0.01241","416.45514"
"136.00000","2.26424","1306.48523","2.25395","1.13850","0.01244","415.36673"
"136.40000","2.27080","1306.03040","2.26053","1.14508","0.01248","415.22214"
"136.80000","2.27744","1306.61267","2.26714","1.15170","0.01252","415.40726"
"137.20000","2.28433","1307.79138","2.27399","1.15854","0.01255","415.78198"
"137.60000","2.29139","1309.48901","2.28098","1.16554","0.01259","416.32172"
"138.00000","2.29771","1310.67017","2.28725","1.17181","0.01263","416.69724"
"138.40000","2.30431","1312.09924","2.29379","1.17835","0.01266","417.15158"
"138.80000","2.31085","1313.90259","2.30025","1.18481","0.01270","417.72491"
"139.20000","2.31748","1315.71448","2.30681","1.19136","0.01274","418.30096"
"139.60000","2.32435","1317.69080","2.31359","1.19815","0.01277","418.92929"
"140.00000","2.33115","1319.75684","2.32031","1.20487","0.01281","419.58612"
"140.40000","2.33789","1321.78845","2.32696","1.21152","0.01285","420.23203"
"140.80000","2.34425","1323.55396","2.33325","1.21781","0.01288","420.79333"
"141.20000","2.35091","1325.60571","2.33983","1.22439","0.01292","421.44565"
"141.60000","2.35743","1327.61108","2.34626","1.23082","0.01295","422.08322"
"142.00000","2.36429","1329.83240","2.35303","1.23759","0.01299","422.78943"
"142.40000","2.37134","1332.11621","2.35999","1.24454","0.01303","423.51550"
"142.80000","2.37783","1334.02026","2.36639","1.25095","0.01306","424.12085"
"143.20000","2.38441","1336.01660","2.37289","1.25745","0.01310","424.75555"
"143.60000","2.39088","1337.88550","2.37928","1.26384","0.01314","425.34973"
"144.00000","2.39749","1339.78699","2.38581","1.27037","0.01317","425.95425"
"144.40000","2.40419","1341.90027","2.39243","1.27699","0.01321","426.62613"
"144.80000","2.41109","1344.01416","2.39924","1.28380","0.01325","427.29819"
"145.20000","2.41797","1346.11682","2.40603","1.29059","0.01328","427.96667"
"145.60000","2.42434","1347.60962","2.41234","1.29689","0.01332","428.44128"
"146.00000","2.43096","1349.37085","2.41888","1.30344","0.01335","429.00122"
"146.40000","2.43747","1351.03210","2.42532","1.30988","0.01339","429.52939"
"146.80000","2.44422","1352.70764","2.43200","1.31656","0.01343","430.06207"
"147.20000","2.45118","1354.58752","2.43888","1.32343","0.01346","430.65973"
"147.60000","2.45783","1356.40601","2.44545","1.33001","0.01350","431.23788"
"148.00000","2.46445","1357.89795","2.45201","1.33657","0.01354","431.71222"
"148.40000","2.47088","1359.37683","2.45838","1.34293","0.01357","432.18240"
"148.80000","2.47748","1361.00159","2.46490","1.34946","0.01361","432.69894"
"149.20000","2.48412","1362.76550","2.47147","1.35603","0.01364","433.25974"
"149.60000","2.49107","1364.62671","2.47834","1.36290","0.01368","433.85147"
"150.00000","2.49805","1366.69617","2.48523","1.36979","0.01372","434.50940"
"150.40000","2.50442","1368.08801","2.49154","1.37610","0.01376","434.95190"
"150.80000","2.51098","1369.74048","2.49803","1.38258","0.01379","435.47726"
"151.20000","2.51749","1371.31824","2.50447","1.38903","0.01383","435.97888"
"151.60000","2.52412","1373.05554","2.51103","1.39559","0.01386","436.53122"
"152.00000","2.53103","1374.88989","2.51785","1.40241","0.01390","437.11441"
"152.40000","2.53783","1376.88940","2.52458","1.40913","0.01394","437.75012"
"152.80000","2.54453","1378.64099","2.53119","1.41575","0.01397","438.30698"
"153.20000","2.55098","1380.21375","2.53758","1.42213","0.01401","438.80701"
"153.60000","2.55756","1381.90271","2.54409","1.42865","0.01405","439.34396"
"154.00000","2.56412","1383.60156","2.55057","1.43513","0.01408","439.88409"
"154.40000","2.57091","1385.52258","2.55729","1.44184","0.01412","440.49484"
"154.80000","2.57800","1387.61340","2.56428","1.44884","0.01416","441.15955"
"155.20000","2.58436","1389.13269","2.57058","1.45513","0.01419","441.64258"
"155.60000","2.59105","1390.80273","2.57719","1.46175","0.01423","442.17352"
"156.00000","2.59753","1392.31250","2.58361","1.46817","0.01426","442.65353"
"156.40000","2.60420","1394.00391","2.59021","1.47477","0.01430","443.19128"
"156.80000","2.61096","1395.69214","2.59689","1.48145","0.01434","443.72800"
"157.20000","2.61777","1397.46692","2.60363","1.48819","0.01437","444.29227"
"157.60000","2.62464","1399.15942","2.61043","1.49499","0.01441","444.83035"
"158.00000","2.63097","1400.42505","2.61671","1.50127","0.01445","445.23273"
"158.40000","2.63760","1401.80286","2.62329","1.50785","0.01448","445.67078"
"158.80000","2.64406","1403.09338","2.62970","1.51426","0.01452","446.08105"
"159.20000","2.65088","1404.67664","2.63646","1.52102","0.01456","446.58441"
"159.60000","2.65793","1406.25476","2.64344","1.52800","0.01459","447.08615"
"160.00000","2.66452","1407.38306","2.65000","1.53456","0.01463","447.44485"
"160.40000","2.67113","1408.54871","2.65656","1.54112","0.01467","447.81546"
"160.80000","2.67755","1409.57117","2.66294","1.54750","0.01470","448.14053"
"161.20000","2.68416","1410.79968","2.66950","1.55406","0.01474","448.53110"
"161.60000","2.69075","1412.05371","2.67605","1.56061","0.01477","448.92978"
"162.00000","2.69774","1413.46802","2.68298","1.56754","0.01481","449.37943"
"162.40000","2.70464","1414.72449","2.68983","1.57439","0.01485","449.77890"
"162.80000","2.71106","1415.63635","2.69622","1.58077","0.01489","450.06882"
"163.20000","2.71764","1416.66040","2.70276","1.58732","0.01492","450.39438"
"163.60000","2.72412","1417.48328","2.70921","1.59377","0.01496","450.65601"
"164.00000","2.73081","1418.52576","2.71586","1.60041","0.01499","450.98743"
"164.40000","2.73771","1419.68286","2.72271","1.60727","0.01503","451.35529"
"164.80000","2.74455","1420.74182","2.72951","1.61407","0.01507","451.69196"
"165.20000","2.75117","1421.58972","2.73610","1.62066","0.01511","451.96155"
"165.60000","2.75763","1422.27441","2.74253","1.62709","0.01514","452.17923"
"166.00000","2.76416","1423.11560","2.74903","1.63359","0.01518","452.44666"
"166.40000","2.77076","1424.00586","2.75559","1.64015","0.01521","452.72971"
"166.80000","2.77759","1425.03748","2.76238","1.64694","0.01525","453.05768"
"167.20000","2.78473","1426.11926","2.76948","1.65404","0.01529","453.40161"
"167.60000","2.79116","1426.69373","2.77589","1.66045","0.01533","453.58423"
"168.00000","2.79769","1427.39355","2.78239","1.66695","0.01536","453.80673"
"168.40000","2.80420","1428.16089","2.78887","1.67343","0.01540","454.05069"
"168.80000","2.81081","1428.89917","2.79546","1.68002","0.01543","454.28540"
"169.20000","2.81757","1429.85547","2.80218","1.68674","0.01547","454.58945"
"169.60000","2.82442","1430.98328","2.80899","1.69354","0.01551","454.94800"
"170.00000","2.83126","1431.78625","2.81579","1.70035","0.01555","455.20328"
"170.40000","2.83766","1431.91101","2.82219","1.70675","0.01558","455.24295"
"170.80000","2.84431","1432.72949","2.82881","1.71336","0.01562","455.50317"
"171.20000","2.85079","1433.46436","2.83526","1.71981","0.01565","455.73682"
"171.60000","2.85750","1434.37537","2.84194","1.72650","0.01569","456.02643"
"172.00000","2.86462","1435.62439","2.84900","1.73356","0.01573","456.42355"
"172.40000","2.87111","1436.45593","2.85546","1.74002","0.01576","456.68790"
"172.80000","2.87775","1437.33020","2.86207","1.74663","0.01580","456.96585"
"173.20000","2.88420","1438.03455","2.86850","1.75305","0.01584","457.18979"
"173.60000","2.89085","1438.90991","2.87511","1.75967","0.01587","457.46811"
"174.00000","2.89747","1439.62305","2.88170","1.76626","0.01591","457.69482"
"174.40000","2.90441","1440.99475","2.88859","1.77314","0.01595","458.13092"
"174.80000","2.91134","1442.17615","2.89548","1.78004","0.01599","458.50653"
"175.20000","2.91767","1442.10864","2.90181","1.78637","0.01602","458.48505"
"175.60000","2.92433","1443.05188","2.90843","1.79299","0.01606","458.78494"
"176.00000","2.93076","1442.96082","2.91486","1.79942","0.01609","458.75598"
"176.40000","2.93750","1442.99011","2.92160","1.80616","0.01613","458.76529"
"176.80000","2.94440","1440.58179","2.92860","1.81315","0.01617","457.99963"
"177.20000","2.95124","1440.97717","2.93542","1.81998","0.01621","458.12534"
"177.60000","2.95786","1441.34985","2.94202","1.82658","0.01624","458.24380"
"178.00000","2.96426","1441.51929","2.94842","1.83298","0.01628","458.29770"
"178.22900","2.96846","1416.50378","2.95359","1.83814","0.01631","450.34457"
"178.24100","2.96866","1370.69641","2.95567","1.84023","0.01632","435.78119"
"178.25500","2.96887","1323.99939","2.95786","1.84241","0.01633","420.93497"
"178.27400","2.96915","1281.68701","2.95990","1.84446","0.01634","407.48273"
"178.33100","2.96993","1239.06067","2.96248","1.84703","0.01636","393.93066"
"178.46100","2.97184","1198.04578","2.96619","1.85075","0.01638","380.89093"
"178.82900","2.97796","1167.89941","2.97357","1.85813","0.01642","371.30658"
"179.22900","2.98490","1160.17285","2.98083","1.86539","0.01646","368.85010"
"179.62900","2.99176","1156.01477","2.98786","1.87242","0.01650","367.52814"
"180.02900","2.99820","1153.16199","2.99442","1.87898","0.01653","366.62115"
"180.42900","3.00474","1151.24524","3.00104","1.88560","0.01657","366.01178"
"180.82900","3.01130","1148.75647","3.00770","1.89225","0.01660","365.22052"
"181.22900","3.01797","1147.14294","3.01443","1.89899","0.01664","364.70755"
"181.62900","3.02499","1146.26648","3.02149","1.90605","0.01668","364.42889"
"182.02900","3.03168","1145.01794","3.02824","1.91279","0.01672","364.03195"
"182.42900","3.03827","1135.73254","3.03522","1.91978","0.01676","361.07986"
"182.82900","3.04474","1128.59058","3.04200","1.92656","0.01679","358.80923"
"183.22900","3.05136","1126.14856","3.04873","1.93329","0.01683","358.03287"
"183.62900","3.05794","1124.47852","3.05538","1.93993","0.01687","357.50192"
"184.02900","3.06475","1123.32446","3.06224","1.94679","0.01691","357.13501"
"184.42900","3.07180","1122.44214","3.06933","1.95389","0.01695","356.85449"
"184.82900","3.07824","1120.56812","3.07585","1.96041","0.01698","356.25870"
"185.22900","3.08486","1117.58887","3.08260","1.96715","0.01702","355.31149"
"185.62900","3.09131","1115.21179","3.08915","1.97371","0.01705","354.55576"
"185.97700","3.09718","1100.18408","3.09566","1.98022","0.01709","349.77805"
"186.37700","3.10372","1097.18335","3.10233","1.98689","0.01713","348.82404"
"186.77700","3.11054","1095.84143","3.10920","1.99376","0.01717","348.39740"
"187.17700","3.11760","1094.97412","3.11630","2.00086","0.01720","348.12167"
"187.57700","3.12402","1093.94580","3.12277","2.00733","0.01724","347.79474"
"187.97700","3.13067","1093.21997","3.12945","2.01401","0.01728","347.56400"
"188.37700","3.13712","1092.31995","3.13594","2.02050","0.01731","347.27783"
"188.77700","3.14373","1090.95239","3.14261","2.02716","0.01735","346.84305"
"189.17700","3.15052","1089.82983","3.14945","2.03400","0.01739","346.48618"
"189.57700","3.15740","1089.16223","3.15636","2.04092","0.01743","346.27393"
"189.78400","3.16054","1054.54163","3.16098","2.04554","0.01745","335.26709"
"189.80100","3.16082","1008.05859","3.16323","2.04779","0.01746","320.48889"
"189.81700","3.16111","960.86945","3.16559","2.05015","0.01748","305.48621"
"189.88200","3.16247","918.47925","3.16877","2.05333","0.01749","292.00922"
"190.19500","3.16749","882.87433","3.17528","2.05984","0.01753","280.68945"
"190.59500","3.17443","874.09808","3.18258","2.06714","0.01757","277.89926"
"190.99500","3.18107","869.68829","3.18941","2.07397","0.01761","276.49725"
"191.39500","3.18769","865.68994","3.19620","2.08076","0.01765","275.22607"
"191.79500","3.19414","863.31519","3.20275","2.08731","0.01768","274.47107"
"192.19500","3.20073","858.50946","3.20954","2.09410","0.01772","272.94321"
"192.59500","3.20738","854.82391","3.21634","2.10090","0.01776","271.77148"
"192.99500","3.21434","852.74579","3.22339","2.10795","0.01780","271.11078"
"193.39500","3.22129","846.34869","3.23061","2.11517","0.01784","269.07697"
"193.79500","3.22766","838.11310","3.23733","2.12189","0.01787","266.45865"
"194.19500","3.23422","832.86047","3.24412","2.12868","0.01791","264.78870"
"194.59500","3.24074","819.96283","3.25120","2.13576","0.01795","260.68820"
"194.77400","3.24424","779.61993","3.25643","2.14099","0.01798","247.86211"
"194.99400","3.24736","740.61963","3.26118","2.14573","0.01800","235.46286"
"195.34700","3.25322","711.71802","3.26834","2.15289","0.01804","226.27426"
"195.37100","3.25372","665.79010","3.27087","2.15543","0.01806","211.67255"
"195.40500","3.25457","624.88104","3.27356","2.15811","0.01807","198.66646"
"195.59700","3.25755","584.33063","3.27838","2.16294","0.01810","185.77440"
"195.91200","3.26278","564.74463","3.28455","2.16911","0.01813","179.54749"
"196.31200","3.26938","554.18427","3.29167","2.17622","0.01817","176.19006"
"196.71200","3.27597","532.15900","3.29934","2.18390","0.01822","169.18764"
"197.11200","3.28285","526.70404","3.30649","2.19105","0.01825","167.45335"
"197.51200","3.28990","519.98242","3.31388","2.19844","0.01830","165.31638"
"197.91200","3.29626","516.03351","3.32044","2.20500","0.01833","164.06091"
"198.31200","3.30294","513.42542","3.32725","2.21180","0.01837","163.23172"
"198.71200","3.30938","512.23120","3.33375","2.21831","0.01841","162.85205"
"199.11200","3.31602","512.55896","3.34037","2.22493","0.01844","162.95625"
"199.51200","3.32280","512.98474","3.34712","2.23168","0.01848","163.09163"
"199.91200","3.32965","511.13943","3.35407","2.23863","0.01852","162.50494"
"200.31200","3.33643","509.38129","3.36094","2.24549","0.01856","161.94598"
"200.71200","3.34284","508.84061","3.36737","2.25193","0.01859","161.77409"
"201.11200","3.34949","506.81854","3.37413","2.25869","0.01863","161.13123"
"201.23100","3.35141","505.97849","3.37609","2.26065","0.01864","160.86415"