File: flexion/5_axis/Specimen_RawData_14.csv
Specimen properties : Specimen label,"G3"
Specimen properties : Support span,"72.00",mm
Specimen properties : Thickness,"4.32",mm
Specimen properties : Width,"14.28",mm
Maximum Load : Maximum Load,"1154",N
Tangent Modulus of Elasticity : Tangent Modulus of Elasticity,"46011118855.75730",Pa
Test : Rate 1,"1.00000",mm/min
Specimen notes : Specimen note 1,""

Time,Displacement,Load,Flexure extension,Corrected extension,Flexure strain (Corrected extension),Flexure stress
(s),(mm),(N),(mm),(mm),(mm/mm),(MPa)
"0.00000","0.00000","49.21110","0.00963","-1.05559","0.00005","19.94303"
"0.40000","0.00485","51.24405","0.01421","-1.05102","0.00007","20.76689"
"0.80000","0.01138","54.12025","0.02036","-1.04487","0.00010","21.93249"
"1.20000","0.01797","57.07760","0.02654","-1.03868","0.00013","23.13097"
"1.60000","0.02455","59.88762","0.03279","-1.03244","0.00016","24.26974"
"2.00000","0.03139","62.93346","0.03927","-1.02595","0.00020","25.50408"
"2.40000","0.03842","65.88050","0.04596","-1.01927","0.00023","26.69838"
"2.80000","0.04493","68.80786","0.05213","-1.01310","0.00026","27.88471"
"3.20000","0.05157","71.64458","0.05843","-1.00679","0.00029","29.03430"
"3.60000","0.05794","74.54002","0.06447","-1.00076","0.00032","30.20769"
"4.00000","0.06456","77.40859","0.07075","-0.99448","0.00035","31.37020"
"4.40000","0.07137","80.42619","0.07721","-0.98802","0.00039","32.59309"
"4.80000","0.07829","83.44882","0.08377","-0.98146","0.00042","33.81803"
"5.20000","0.08505","86.38531","0.09019","-0.97504","0.00045","35.00806"
"5.60000","0.09142","89.12854","0.09628","-0.96895","0.00048","36.11976"
"6.00000","0.09805","92.00815","0.10262","-0.96261","0.00051","37.28674"
"6.40000","0.10459","94.78999","0.10888","-0.95634","0.00054","38.41409"
"6.80000","0.11131","97.72923","0.11532","-0.94991","0.00058","39.60523"
"7.20000","0.11834","100.68985","0.12207","-0.94316","0.00061","40.80503"
"7.60000","0.12500","103.45823","0.12845","-0.93678","0.00064","41.92693"
"8.00000","0.13157","106.11440","0.13476","-0.93047","0.00067","43.00336"
"8.40000","0.13802","108.87923","0.14095","-0.92428","0.00070","44.12382"
"8.80000","0.14459","111.67816","0.14724","-0.91798","0.00074","45.25810"
"9.20000","0.15126","114.38808","0.15364","-0.91158","0.00077","46.35631"
"9.60000","0.15818","117.37267","0.16027","-0.90495","0.00080","47.56583"
"10.00000","0.16515","120.47764","0.16694","-0.89828","0.00083","48.82413"
"10.40000","0.17149","122.96415","0.17303","-0.89219","0.00087","49.83180"
"10.80000","0.17816","125.86580","0.17942","-0.88581","0.00090","51.00771"
"11.20000","0.18464","128.77916","0.18561","-0.87961","0.00093","52.18836"
"11.60000","0.19127","131.56836","0.19197","-0.87325","0.00096","53.31870"
"12.00000","0.19816","134.65552","0.19857","-0.86666","0.00099","54.56978"
"12.40000","0.20493","137.70459","0.20504","-0.86018","0.00103","55.80544"
"12.80000","0.21163","140.67372","0.21145","-0.85377","0.00106","57.00869"
"13.20000","0.21806","143.41113","0.21761","-0.84761","0.00109","58.11804"
"13.60000","0.22472","146.47929","0.22397","-0.84125","0.00112","59.36142"
"14.00000","0.23124","149.46103","0.23021","-0.83501","0.00115","60.56979"
"14.40000","0.23811","152.56435","0.23678","-0.82845","0.00118","61.82742"
"14.80000","0.24512","155.75392","0.24347","-0.82175","0.00122","63.12001"
"15.20000","0.25154","158.66739","0.24962","-0.81560","0.00125","64.30070"
"15.60000","0.25815","161.73010","0.25597","-0.80926","0.00128","65.54189"
"16.00000","0.26465","164.58202","0.26223","-0.80299","0.00131","66.69764"
"16.40000","0.27129","167.63333","0.26861","-0.79662","0.00134","67.93420"
"16.80000","0.27806","170.91379","0.27511","-0.79012","0.00138","69.26362"
"17.20000","0.28501","174.24617","0.28177","-0.78346","0.00141","70.61408"
"17.60000","0.29175","177.37373","0.28824","-0.77698","0.00144","71.88154"
"18.00000","0.29808","180.33459","0.29432","-0.77091","0.00147","73.08144"
"18.40000","0.30471","183.51962","0.30068","-0.76455","0.00150","74.37219"
"18.80000","0.31125","186.61960","0.30696","-0.75826","0.00153","75.62847"
"19.20000","0.31799","189.81711","0.31342","-0.75181","0.00157","76.92428"
"19.60000","0.32501","193.33121","0.32014","-0.74508","0.00160","78.34838"
"20.00000","0.33164","196.53975","0.32650","-0.73872","0.00163","79.64866"
"20.40000","0.33828","199.67314","0.33287","-0.73235","0.00166","80.91848"
"20.80000","0.34469","202.81987","0.33903","-0.72619","0.00170","82.19371"
"21.20000","0.35126","205.84590","0.34536","-0.71986","0.00173","83.42002"
"21.60000","0.35791","209.19107","0.35174","-0.71348","0.00176","84.77567"
"22.00000","0.36483","212.62283","0.35839","-0.70684","0.00179","86.16640"
"22.40000","0.37182","216.10530","0.36510","-0.70013","0.00183","87.57769"
"22.80000","0.37815","219.13594","0.37119","-0.69404","0.00186","88.80587"
"23.20000","0.38477","222.39357","0.37754","-0.68769","0.00189","90.12605"
"23.60000","0.39130","225.58206","0.38382","-0.68140","0.00192","91.41819"
"24.00000","0.39797","228.75681","0.39024","-0.67499","0.00195","92.70477"
"24.40000","0.40487","232.32480","0.39684","-0.66838","0.00198","94.15072"
"24.80000","0.41161","235.65540","0.40332","-0.66191","0.00202","95.50046"
"25.20000","0.41832","239.10921","0.40976","-0.65547","0.00205","96.90013"
"25.60000","0.42471","242.23306","0.41590","-0.64933","0.00208","98.16609"
"26.00000","0.43137","245.52504","0.42230","-0.64292","0.00211","99.50018"
"26.40000","0.43788","248.81665","0.42856","-0.63667","0.00214","100.83412"
"26.80000","0.44477","252.38844","0.43517","-0.63005","0.00218","102.28161"
"27.20000","0.45178","255.88165","0.44191","-0.62331","0.00221","103.69724"
"27.60000","0.45826","259.19131","0.44814","-0.61708","0.00224","105.03850"
"28.00000","0.46486","262.51035","0.45449","-0.61074","0.00227","106.38355"
"28.40000","0.47134","265.76138","0.46072","-0.60451","0.00230","107.70105"
"28.80000","0.47796","269.07214","0.46709","-0.59814","0.00234","109.04276"
"29.20000","0.48469","272.57095","0.47354","-0.59169","0.00237","110.46066"
"29.60000","0.49155","275.98868","0.48014","-0.58508","0.00240","111.84571"
"30.00000","0.49840","279.58829","0.48672","-0.57851","0.00243","113.30447"
"30.40000","0.50477","282.90295","0.49283","-0.57239","0.00246","114.64776"
"30.80000","0.51141","286.11630","0.49922","-0.56600","0.00250","115.94998"
"31.20000","0.51794","289.50571","0.50549","-0.55973","0.00253","117.32355"
"31.60000","0.52470","293.06091","0.51201","-0.55321","0.00256","118.76431"
"32.00000","0.53166","296.68515","0.51872","-0.54650","0.00259","120.23306"
"32.40000","0.53826","300.00507","0.52510","-0.54012","0.00263","121.57847"
"32.80000","0.54489","303.45670","0.53150","-0.53372","0.00266","122.97726"
"33.20000","0.55135","306.86337","0.53773","-0.52749","0.00269","124.35783"
"33.60000","0.55794","310.35156","0.54409","-0.52113","0.00272","125.77143"
"34.00000","0.56461","313.79465","0.55053","-0.51470","0.00275","127.16676"
"34.40000","0.57154","317.47156","0.55722","-0.50801","0.00279","128.65685"
"34.80000","0.57849","321.17673","0.56391","-0.50131","0.00282","130.15839"
"35.20000","0.58486","324.46747","0.57006","-0.49516","0.00285","131.49197"
"35.60000","0.59143","327.88556","0.57641","-0.48882","0.00288","132.87717"
"36.00000","0.59794","331.39099","0.58268","-0.48254","0.00291","134.29776"
"36.40000","0.60461","334.89450","0.58912","-0.47611","0.00295","135.71758"
"36.80000","0.61153","338.57162","0.59579","-0.46944","0.00298","137.20775"
"37.20000","0.61829","342.12613","0.60232","-0.46291","0.00301","138.64822"
"37.60000","0.62496","345.70081","0.60875","-0.45647","0.00304","140.09688"
"38.00000","0.63144","349.11719","0.61502","-0.45021","0.00308","141.48138"
"38.40000","0.63803","352.68994","0.62138","-0.44385","0.00311","142.92926"
"38.80000","0.64459","356.12378","0.62772","-0.43751","0.00314","144.32085"
"39.20000","0.65140","359.74091","0.63430","-0.43093","0.00317","145.78670"
"39.60000","0.65845","363.72751","0.64109","-0.42413","0.00321","147.40228"
"40.00000","0.66482","366.95212","0.64725","-0.41798","0.00324","148.70908"
"40.40000","0.67150","370.58762","0.65370","-0.41152","0.00327","150.18237"
"40.80000","0.67798","374.11359","0.65996","-0.40527","0.00330","151.61130"
"41.20000","0.68467","377.71054","0.66641","-0.39881","0.00333","153.06897"
"41.60000","0.69146","381.40515","0.67297","-0.39226","0.00336","154.56624"
"42.00000","0.69825","385.10904","0.67952","-0.38571","0.00340","156.06725"
"42.40000","0.70507","388.80154","0.68610","-0.37912","0.00343","157.56366"
"42.80000","0.71143","392.24155","0.69226","-0.37296","0.00346","158.95773"
"43.20000","0.71805","395.84082","0.69868","-0.36654","0.00349","160.41635"
"43.60000","0.72452","399.37350","0.70495","-0.36028","0.00352","161.84799"
"44.00000","0.73136","403.07812","0.71157","-0.35365","0.00356","163.34930"
"44.40000","0.73842","406.92975","0.71842","-0.34681","0.00359","164.91020"
"44.80000","0.74497","410.47531","0.72477","-0.34046","0.00362","166.34706"
"45.20000","0.75157","414.20508","0.73116","-0.33407","0.00366","167.85857"
"45.60000","0.75801","417.56845","0.73740","-0.32782","0.00369","169.22159"
"46.00000","0.76463","421.33237","0.74380","-0.32142","0.00372","170.74693"
"46.40000","0.77125","424.88724","0.75022","-0.31501","0.00375","172.18756"
"46.80000","0.77821","428.75363","0.75696","-0.30826","0.00378","173.75443"
"47.20000","0.78508","432.49252","0.76362","-0.30160","0.00382","175.26964"
"47.60000","0.79149","435.95285","0.76983","-0.29539","0.00385","176.67195"
"48.00000","0.79810","439.62085","0.77624","-0.28899","0.00388","178.15842"
"48.40000","0.80458","443.09540","0.78252","-0.28271","0.00391","179.56650"
"48.80000","0.81129","446.72672","0.78902","-0.27621","0.00395","181.03810"
"49.20000","0.81822","450.65616","0.79572","-0.26950","0.00398","182.63054"
"49.60000","0.82502","454.48309","0.80231","-0.26292","0.00401","184.18141"
"50.00000","0.83161","457.96246","0.80870","-0.25653","0.00404","185.59145"
"50.40000","0.83807","461.54913","0.81496","-0.25027","0.00407","187.04497"
"50.80000","0.84462","465.05536","0.82131","-0.24392","0.00411","188.46588"
"51.20000","0.85121","468.65103","0.82769","-0.23754","0.00414","189.92303"
"51.60000","0.85808","472.43652","0.83434","-0.23088","0.00417","191.45712"
"52.00000","0.86518","476.43744","0.84122","-0.22401","0.00421","193.07852"
"52.40000","0.87159","479.84808","0.84743","-0.21779","0.00424","194.46069"
"52.80000","0.87815","483.50687","0.85378","-0.21145","0.00427","195.94344"
"53.20000","0.88465","487.11285","0.86008","-0.20514","0.00430","197.40479"
"53.60000","0.89128","490.68326","0.86651","-0.19871","0.00433","198.85170"
"54.00000","0.89805","494.45859","0.87309","-0.19214","0.00437","200.38167"
"54.40000","0.90489","498.19858","0.87974","-0.18548","0.00440","201.89732"
"54.80000","0.91170","501.96466","0.88636","-0.17886","0.00443","203.42354"
"55.20000","0.91811","505.49759","0.89260","-0.17263","0.00446","204.85529"
"55.60000","0.92475","509.10464","0.89906","-0.16617","0.00450","206.31706"
"56.00000","0.93124","512.65375","0.90537","-0.15985","0.00453","207.75534"
"56.40000","0.93797","516.49683","0.91191","-0.15332","0.00456","209.31277"
"56.80000","0.94510","520.45270","0.91884","-0.14639","0.00459","210.91591"
"57.20000","0.95154","523.91345","0.92511","-0.14012","0.00463","212.31839"
"57.60000","0.95820","527.61157","0.93158","-0.13364","0.00466","213.81708"
"58.00000","0.96466","531.25110","0.93785","-0.12737","0.00469","215.29201"
"58.40000","0.97132","534.86090","0.94433","-0.12089","0.00472","216.75490"
"58.80000","0.97795","538.43317","0.95078","-0.11444","0.00475","218.20258"
"59.20000","0.98489","542.46716","0.95753","-0.10770","0.00479","219.83737"
"59.60000","0.99177","546.15741","0.96423","-0.10099","0.00482","221.33287"
"60.00000","0.99813","549.79340","0.97041","-0.09481","0.00485","222.80637"
"60.40000","1.00478","553.46613","0.97689","-0.08834","0.00488","224.29475"
"60.80000","1.01121","557.07367","0.98315","-0.08208","0.00492","225.75673"
"61.20000","1.01798","560.68262","0.98974","-0.07549","0.00495","227.21927"
"61.60000","1.02490","564.44489","0.99647","-0.06875","0.00498","228.74394"
"62.00000","1.03172","568.37683","1.00310","-0.06212","0.00502","230.33739"
"62.40000","1.03828","572.06323","1.00949","-0.05574","0.00505","231.83131"
"62.80000","1.04471","575.60760","1.01574","-0.04948","0.00508","233.26770"
"63.20000","1.05132","579.23694","1.02218","-0.04304","0.00511","234.73849"
"63.60000","1.05789","582.84955","1.02857","-0.03665","0.00514","236.20253"
"64.00000","1.06476","586.60095","1.03527","-0.02996","0.00518","237.72279"
"64.40000","1.07175","590.63910","1.04206","-0.02316","0.00521","239.35928"
"64.80000","1.07826","594.16455","1.04841","-0.01682","0.00524","240.78798"
"65.20000","1.08479","597.83527","1.05477","-0.01045","0.00527","242.27556"
"65.60000","1.09133","601.29803","1.06116","-0.00407","0.00531","243.67886"
"66.00000","1.09791","604.93726","1.06757","0.00235","0.00534","245.15367"
"66.40000","1.10477","608.80408","1.07426","0.00904","0.00537","246.72072"
"66.80000","1.11162","612.58698","1.08094","0.01572","0.00540","248.25375"
"67.20000","1.11835","616.33527","1.08751","0.02228","0.00544","249.77277"
"67.60000","1.12475","619.83435","1.09375","0.02852","0.00547","251.19080"
"68.00000","1.13140","623.40314","1.10024","0.03501","0.00550","252.63705"
"68.40000","1.13791","627.05402","1.10658","0.04136","0.00553","254.11659"
"68.80000","1.14466","630.74475","1.11316","0.04794","0.00557","255.61229"
"69.20000","1.15172","634.84595","1.12005","0.05482","0.00560","257.27432"
"69.60000","1.15828","638.48651","1.12644","0.06121","0.00563","258.74966"
"70.00000","1.16489","641.91248","1.13290","0.06767","0.00566","260.13806"
"70.40000","1.17133","645.52039","1.13918","0.07395","0.00570","261.60019"
"70.80000","1.17795","649.19141","1.14563","0.08040","0.00573","263.08789"
"71.20000","1.18464","652.83264","1.15216","0.08693","0.00576","264.56351"
"71.60000","1.19149","656.82147","1.15884","0.09361","0.00579","266.17999"
"72.00000","1.19842","660.60242","1.16560","0.10037","0.00583","267.71225"
"72.40000","1.20478","664.05237","1.17180","0.10657","0.00586","269.11035"
"72.80000","1.21146","667.75769","1.17831","0.11309","0.00589","270.61194"
"73.20000","1.21793","671.13910","1.18464","0.11941","0.00592","271.98227"
"73.60000","1.22461","674.78961","1.19116","0.12593","0.00596","273.46167"
"74.00000","1.23157","678.82788","1.19793","0.13270","0.00599","275.09821"
"74.40000","1.23826","682.48541","1.20446","0.13923","0.00602","276.58044"
"74.80000","1.24496","686.14001","1.21100","0.14577","0.00605","278.06146"
"75.20000","1.25133","689.70465","1.21721","0.15198","0.00609","279.50607"
"75.60000","1.25798","693.33215","1.22370","0.15847","0.00612","280.97614"
"76.00000","1.26455","696.84625","1.23011","0.16488","0.00615","282.40024"
"76.40000","1.27149","700.74628","1.23688","0.17165","0.00618","283.98074"
"76.80000","1.27843","704.53278","1.24364","0.17842","0.00622","285.51523"
"77.20000","1.28490","707.96594","1.24996","0.18473","0.00625","286.90652"
"77.60000","1.29147","711.49927","1.25638","0.19115","0.00628","288.33844"
"78.00000","1.29795","715.10028","1.26269","0.19746","0.00631","289.79776"
"78.40000","1.30458","718.56439","1.26917","0.20395","0.00635","291.20160"
"78.80000","1.31142","722.44647","1.27583","0.21061","0.00638","292.77484"
"79.20000","1.31834","726.30353","1.28258","0.21736","0.00641","294.33792"
"79.60000","1.32502","729.80542","1.28911","0.22388","0.00645","295.75708"
"80.00000","1.33144","733.29236","1.29537","0.23015","0.00648","297.17020"
"80.40000","1.33803","736.83093","1.30181","0.23658","0.00651","298.60422"
"80.80000","1.34458","740.41876","1.30819","0.24296","0.00654","300.05820"
"81.20000","1.35132","744.04785","1.31477","0.24954","0.00657","301.52890"
"81.60000","1.35839","747.91089","1.32168","0.25645","0.00661","303.09442"
"82.00000","1.36495","751.43268","1.32810","0.26287","0.00664","304.52164"
"82.40000","1.37154","754.92517","1.33454","0.26931","0.00667","305.93698"
"82.80000","1.37802","758.34155","1.34088","0.27566","0.00670","307.32147"
"83.20000","1.38463","761.97003","1.34734","0.28212","0.00674","308.79193"
"83.60000","1.39135","765.48242","1.35391","0.28869","0.00677","310.21536"
"84.00000","1.39817","769.22253","1.36057","0.29535","0.00680","311.73105"
"84.40000","1.40507","772.82202","1.36732","0.30210","0.00684","313.18976"
"84.80000","1.41143","776.23853","1.37354","0.30832","0.00687","314.57431"
"85.20000","1.41811","779.75732","1.38007","0.31485","0.00690","316.00034"
"85.60000","1.42458","783.29248","1.38639","0.32117","0.00693","317.43298"
"86.00000","1.43129","786.83997","1.39296","0.32774","0.00696","318.87061"
"86.40000","1.43831","790.61481","1.39983","0.33460","0.00700","320.40039"
"86.80000","1.44496","794.03119","1.40633","0.34111","0.00703","321.78488"
"87.20000","1.45162","797.52252","1.41283","0.34761","0.00706","323.19977"
"87.60000","1.45803","800.88330","1.41910","0.35388","0.00710","324.56174"
"88.00000","1.46461","804.36151","1.42553","0.36031","0.00713","325.97128"
"88.40000","1.47122","807.88129","1.43199","0.36676","0.00716","327.39771"
"88.80000","1.47813","811.54120","1.43873","0.37351","0.00719","328.88089"
"89.20000","1.48512","815.26849","1.44556","0.38034","0.00723","330.39139"
"89.60000","1.49153","818.56146","1.45184","0.38661","0.00726","331.72589"
"90.00000","1.49818","822.10907","1.45833","0.39311","0.00729","333.16357"
"90.40000","1.50460","825.28888","1.46461","0.39938","0.00732","334.45221"
"90.80000","1.51125","828.79254","1.47111","0.40588","0.00736","335.87207"
"91.20000","1.51808","832.47955","1.47778","0.41256","0.00739","337.36627"
"91.60000","1.52502","836.06915","1.48456","0.41934","0.00742","338.82095"
"92.00000","1.53166","839.52283","1.49105","0.42583","0.00746","340.22058"
"92.40000","1.53809","842.86554","1.49734","0.43211","0.00749","341.57523"
"92.80000","1.54469","846.21265","1.50380","0.43858","0.00752","342.93167"
"93.20000","1.55123","849.52527","1.51020","0.44498","0.00755","344.27411"
"93.60000","1.55801","853.13910","1.51683","0.45160","0.00758","345.73865"
"94.00000","1.56508","856.66852","1.52375","0.45853","0.00762","347.16895"
"94.40000","1.57164","860.05133","1.53017","0.46495","0.00765","348.53986"
"94.80000","1.57818","863.36517","1.53658","0.47135","0.00768","349.88281"
"95.20000","1.58467","866.50739","1.54293","0.47770","0.00771","351.15619"
"95.60000","1.59126","869.88110","1.54938","0.48415","0.00775","352.52341"
"96.00000","1.59797","873.28265","1.55594","0.49072","0.00778","353.90192"
"96.40000","1.60490","876.70953","1.56273","0.49751","0.00781","355.29068"
"96.80000","1.61177","880.00085","1.56947","0.50424","0.00785","356.62448"
"97.20000","1.61812","882.69775","1.57571","0.51048","0.00788","357.71744"
"97.60000","1.62480","885.76685","1.58225","0.51703","0.00791","358.96118"
"98.00000","1.63128","888.79828","1.58861","0.52338","0.00794","360.18970"
"98.40000","1.63793","891.96460","1.59512","0.52990","0.00798","361.47287"
"98.80000","1.64493","895.51642","1.60197","0.53675","0.00801","362.91226"
"99.20000","1.65158","898.59534","1.60850","0.54327","0.00804","364.16000"
"99.60000","1.65826","901.63928","1.61505","0.54983","0.00808","365.39355"
"100.00000","1.66470","904.55823","1.62137","0.55615","0.00811","366.57648"
"100.40000","1.67136","907.66205","1.62790","0.56267","0.00814","367.83432"
"100.80000","1.67795","910.52551","1.63436","0.56914","0.00817","368.99475"
"101.20000","1.68483","913.45935","1.64112","0.57590","0.00821","370.18372"
"101.60000","1.69180","916.38214","1.64797","0.58275","0.00824","371.36819"
"102.00000","1.69818","918.74432","1.65425","0.58902","0.00827","372.32547"
"102.40000","1.70478","921.14539","1.66075","0.59553","0.00830","373.29852"
"102.80000","1.71129","923.54315","1.66716","0.60193","0.00834","374.27020"
"103.20000","1.71797","926.03882","1.67373","0.60851","0.00837","375.28159"
"103.60000","1.72482","928.60022","1.68048","0.61525","0.00840","376.31961"
"104.00000","1.73170","931.09521","1.68725","0.62203","0.00844","377.33072"
"104.40000","1.73837","934.01093","1.69380","0.62858","0.00847","378.51233"
"104.80000","1.74473","936.51239","1.70006","0.63484","0.00850","379.52606"
"105.20000","1.75134","939.29980","1.70656","0.64133","0.00853","380.65567"
"105.60000","1.75790","942.00867","1.71300","0.64778","0.00857","381.75345"
"106.00000","1.76470","944.73956","1.71968","0.65446","0.00860","382.86017"
"106.40000","1.77174","947.87738","1.72658","0.66136","0.00863","384.13177"
"106.80000","1.77826","950.67444","1.73298","0.66776","0.00866","385.26529"
"107.20000","1.78488","953.32953","1.73948","0.67426","0.00870","386.34128"
"107.60000","1.79133","955.85522","1.74581","0.68059","0.00873","387.36484"
"108.00000","1.79791","956.91571","1.75235","0.68713","0.00876","387.79459"
"108.40000","1.80465","950.41992","1.75938","0.69415","0.00880","385.16214"
"108.80000","1.81156","950.30029","1.76629","0.70107","0.00883","385.11368"
"109.20000","1.81845","951.88690","1.77311","0.70789","0.00887","385.75665"
"109.60000","1.82478","953.68231","1.77936","0.71413","0.00890","386.48425"
"110.00000","1.83139","955.94006","1.78587","0.72064","0.00893","387.39920"
"110.40000","1.83791","958.39258","1.79229","0.72706","0.00896","388.39310"
"110.80000","1.84465","960.99115","1.79890","0.73368","0.00899","389.44620"
"111.20000","1.85165","963.77704","1.80578","0.74056","0.00903","390.57520"
"111.60000","1.85829","966.43933","1.81230","0.74708","0.00906","391.65408"
"112.00000","1.86495","969.22961","1.81884","0.75361","0.00909","392.78488"
"112.40000","1.87134","971.88586","1.82511","0.75989","0.00913","393.86133"
"112.80000","1.87798","974.58148","1.83163","0.76640","0.00916","394.95374"
"113.20000","1.88458","977.39270","1.83810","0.77288","0.00919","396.09299"
"113.60000","1.89150","980.42029","1.84488","0.77966","0.00922","397.31995"
"114.00000","1.89846","983.36346","1.85171","0.78649","0.00926","398.51266"
"114.40000","1.90487","985.93988","1.85801","0.79279","0.00929","399.55679"
"114.80000","1.91150","988.87952","1.86450","0.79928","0.00932","400.74808"
"115.20000","1.91796","991.46210","1.87085","0.80563","0.00935","401.79468"
"115.60000","1.92463","994.19495","1.87740","0.81217","0.00939","402.90219"
"116.00000","1.93147","996.93036","1.88413","0.81890","0.00942","404.01071"
"116.40000","1.93827","994.80731","1.89101","0.82579","0.00946","403.15036"
"116.80000","1.94503","995.52368","1.89774","0.83251","0.00949","403.44067"
"117.20000","1.95141","996.54022","1.90408","0.83885","0.00952","403.85263"
"117.60000","1.95802","997.35736","1.91066","0.84543","0.00955","404.18378"
"118.00000","1.96459","997.39917","1.91723","0.85200","0.00959","404.20071"
"118.40000","1.97143","999.10944","1.92399","0.85877","0.00962","404.89380"
"118.80000","1.97840","1000.89813","1.93089","0.86566","0.00965","405.61868"
"119.20000","1.98490","1002.05011","1.93734","0.87212","0.00969","406.08554"
"119.60000","1.99152","1003.50769","1.94390","0.87867","0.00972","406.67621"
"120.00000","1.99798","1004.70093","1.95031","0.88509","0.00975","407.15979"
"120.40000","2.00457","1006.20612","1.95683","0.89161","0.00978","407.76978"
"120.80000","2.01134","1007.70911","1.96354","0.89832","0.00982","408.37888"
"121.20000","2.01829","1009.46564","1.97042","0.90519","0.00985","409.09070"
"121.60000","2.02515","1011.19794","1.97720","0.91198","0.00989","409.79272"
"122.00000","2.03149","1012.71729","1.98349","0.91826","0.00992","410.40845"
"122.40000","2.03805","1014.19922","1.98998","0.92476","0.00995","411.00900"
"122.80000","2.04457","1008.10480","1.99675","0.93153","0.00998","408.53922"
"123.20000","2.05128","1008.82294","2.00344","0.93821","0.01002","408.83026"
"123.60000","2.05831","1010.07996","2.01041","0.94518","0.01005","409.33966"
"124.00000","2.06497","1011.32385","2.01702","0.95180","0.01009","409.84375"
"124.40000","2.07157","1012.52618","2.02357","0.95834","0.01012","410.33099"
"124.80000","2.07809","1013.91577","2.03003","0.96480","0.01015","410.89413"
"125.20000","2.08465","1015.49261","2.03653","0.97131","0.01018","411.53317"
"125.60000","2.09127","1016.99353","2.04308","0.97786","0.01022","412.14142"
"126.00000","2.09810","1018.87482","2.04984","0.98461","0.01025","412.90381"
"126.40000","2.10513","1020.52960","2.05680","0.99158","0.01028","413.57443"
"126.80000","2.11145","1020.33441","2.06313","0.99790","0.01032","413.49533"
"127.20000","2.11814","1021.39526","2.06977","1.00454","0.01035","413.92523"
"127.60000","2.12461","1022.73535","2.07619","1.01096","0.01038","414.46832"
"128.00000","2.13133","1024.33679","2.08283","1.01761","0.01041","415.11731"
"128.40000","2.13821","1026.15576","2.08964","1.02441","0.01045","415.85446"
"128.80000","2.14496","1028.08118","2.09631","1.03108","0.01048","416.63474"
"129.20000","2.15167","1029.74500","2.10295","1.03772","0.01051","417.30902"
"129.60000","2.15809","1031.34546","2.10930","1.04408","0.01055","417.95761"
"130.00000","2.16469","1033.15564","2.11583","1.05060","0.01058","418.69119"
"130.40000","2.17119","1034.88538","2.12225","1.05702","0.01061","419.39218"
"130.80000","2.17805","1036.87378","2.12903","1.06381","0.01065","420.19800"
"131.20000","2.18512","1038.99561","2.13601","1.07078","0.01068","421.05786"
"131.60000","2.19159","1040.59534","2.14241","1.07719","0.01071","421.70618"
"132.00000","2.19821","1042.32031","2.14897","1.08374","0.01074","422.40521"
"132.40000","2.20465","1043.20276","2.15536","1.09014","0.01078","422.76285"
"132.80000","2.21129","1043.98096","2.16197","1.09675","0.01081","423.07822"
"133.20000","2.21800","1045.14465","2.16863","1.10341","0.01084","423.54980"
"133.60000","2.22492","1046.28809","2.17550","1.11028","0.01088","424.01318"
"134.00000","2.23170","1047.50000","2.18223","1.11701","0.01091","424.50430"
"134.40000","2.23812","1048.31812","2.18862","1.12340","0.01094","424.83585"
"134.80000","2.24474","1049.24072","2.19519","1.12997","0.01098","425.20975"
"135.20000","2.25122","1049.89966","2.20165","1.13643","0.01101","425.47678"
"135.60000","2.25800","1050.65344","2.20840","1.14317","0.01104","425.78226"
"136.00000","2.26499","1051.39648","2.21535","1.15012","0.01108","426.08337"
"136.40000","2.27168","1052.00342","2.22201","1.15679","0.01111","426.32935"
"136.80000","2.27821","1052.59607","2.22853","1.16330","0.01114","426.56952"
"137.20000","2.28472","1053.30054","2.23500","1.16977","0.01117","426.85501"
"137.60000","2.29125","1054.44934","2.24148","1.17625","0.01121","427.32056"
"138.00000","2.29791","1055.50220","2.24810","1.18288","0.01124","427.74725"
"138.40000","2.30482","1056.79346","2.25495","1.18972","0.01127","428.27054"
"138.80000","2.31183","1058.37634","2.26189","1.19667","0.01131","428.91199"
"139.20000","2.31821","1059.41882","2.26823","1.20301","0.01134","429.33447"
"139.60000","2.32478","1060.65564","2.27474","1.20952","0.01137","429.83569"
"140.00000","2.33129","1061.65466","2.28121","1.21598","0.01141","430.24054"
"140.40000","2.33796","1062.80737","2.28783","1.22260","0.01144","430.70770"
"140.80000","2.34485","1064.19214","2.29466","1.22944","0.01147","431.26889"
"141.20000","2.35158","1065.26196","2.30135","1.23612","0.01151","431.70242"
"141.60000","2.35829","1066.44299","2.30801","1.24278","0.01154","432.18106"
"142.00000","2.36474","1067.24573","2.31442","1.24920","0.01157","432.50635"
"142.40000","2.37139","1068.11938","2.32103","1.25580","0.01161","432.86041"
"142.80000","2.37792","1068.58606","2.32755","1.26232","0.01164","433.04953"
"143.20000","2.38469","1067.63794","2.33436","1.26913","0.01167","432.66531"
"143.60000","2.39185","1059.54773","2.34186","1.27663","0.01171","429.38672"
"144.00000","2.39817","1051.84070","2.34851","1.28329","0.01174","426.26340"
"144.40000","2.40483","1047.84155","2.35535","1.29012","0.01178","424.64273"
"144.80000","2.41129","1045.61938","2.36190","1.29667","0.01181","423.74219"
"145.20000","2.41796","1044.48596","2.36862","1.30339","0.01184","423.28287"
"145.60000","2.42472","1043.72852","2.37541","1.31018","0.01188","422.97589"
"146.00000","2.43165","1043.22668","2.38236","1.31713","0.01191","422.77252"
"146.40000","2.43840","1042.84583","2.38913","1.32391","0.01195","422.61819"
"146.80000","2.44476","1042.31812","2.39551","1.33028","0.01198","422.40433"
"147.20000","2.45140","1042.22424","2.40216","1.33693","0.01201","422.36627"
"147.60000","2.45785","1042.06519","2.40861","1.34339","0.01204","422.30182"
"148.00000","2.46468","1042.20447","2.41544","1.35021","0.01208","422.35828"
"148.40000","2.47167","1042.87085","2.42240","1.35717","0.01211","422.62833"
"148.80000","2.47835","1043.41602","2.42906","1.36383","0.01215","422.84924"
"149.20000","2.48491","1044.12891","2.43558","1.37036","0.01218","423.13815"
"149.60000","2.49134","1044.88794","2.44198","1.37675","0.01221","423.44577"
"150.00000","2.49796","1045.86743","2.44856","1.38334","0.01224","423.84271"
"150.40000","2.50456","1047.00037","2.45511","1.38989","0.01228","424.30182"
"150.80000","2.51151","1048.41187","2.46200","1.39677","0.01231","424.87384"
"151.20000","2.51843","1050.03076","2.46885","1.40363","0.01234","425.52991"
"151.60000","2.52489","1051.17517","2.47526","1.41004","0.01238","425.99368"
"152.00000","2.53141","1052.61584","2.48172","1.41649","0.01241","426.57755"
"152.40000","2.53795","1054.00049","2.48820","1.42298","0.01244","427.13867"
"152.80000","2.54458","1055.53906","2.49477","1.42954","0.01247","427.76218"
"153.20000","2.55155","1057.25610","2.50166","1.43643","0.01251","428.45801"
"153.60000","2.55832","1058.83569","2.50836","1.44314","0.01254","429.09814"
"154.00000","2.56495","1060.49219","2.51493","1.44970","0.01257","429.76947"
"154.40000","2.57142","1061.81738","2.52133","1.45611","0.01261","430.30649"
"154.80000","2.57803","1063.30090","2.52788","1.46265","0.01264","430.90771"
"155.20000","2.58456","1064.56628","2.53435","1.46913","0.01267","431.42050"
"155.60000","2.59134","1066.16821","2.54107","1.47584","0.01271","432.06970"
"156.00000","2.59846","1067.96924","2.54811","1.48289","0.01274","432.79956"
"156.40000","2.60493","1069.21729","2.55452","1.48930","0.01277","433.30533"
"156.80000","2.61154","1070.75049","2.56107","1.49584","0.01281","433.92667"
"157.20000","2.61797","1071.98438","2.56745","1.50222","0.01284","434.42673"
"157.60000","2.62459","1073.49329","2.57400","1.50878","0.01287","435.03821"
"158.00000","2.63139","1075.09253","2.58073","1.51550","0.01290","435.68631"
"158.40000","2.63821","1076.63965","2.58748","1.52226","0.01294","436.31329"
"158.80000","2.64503","1078.28186","2.59423","1.52901","0.01297","436.97879"
"159.20000","2.65141","1079.35876","2.60057","1.53535","0.01300","437.41522"
"159.60000","2.65811","1080.79077","2.60721","1.54198","0.01304","437.99554"
"160.00000","2.66459","1081.96777","2.61363","1.54841","0.01307","438.47253"
"160.40000","2.67131","1083.45398","2.62029","1.55507","0.01310","439.07483"
"160.80000","2.67833","1084.99231","2.62725","1.56202","0.01314","439.69824"
"161.20000","2.68494","1086.43164","2.63380","1.56857","0.01317","440.28156"
"161.60000","2.69159","1087.62109","2.64039","1.57517","0.01320","440.76358"
"162.00000","2.69797","1088.88232","2.64672","1.58149","0.01323","441.27469"
"162.40000","2.70462","1090.21948","2.65331","1.58809","0.01327","441.81659"
"162.80000","2.71127","1091.43396","2.65990","1.59468","0.01330","442.30875"
"163.20000","2.71821","1093.03979","2.66678","1.60156","0.01333","442.95953"
"163.60000","2.72508","1094.50977","2.67359","1.60836","0.01337","443.55524"
"164.00000","2.73152","1095.82483","2.67997","1.61474","0.01340","444.08817"
"164.40000","2.73811","1097.04089","2.68651","1.62129","0.01343","444.58099"
"164.80000","2.74458","1098.37402","2.69292","1.62770","0.01346","445.12125"
"165.20000","2.75127","1099.97412","2.69954","1.63432","0.01350","445.76968"
"165.60000","2.75818","1101.37158","2.70639","1.64116","0.01353","446.33603"
"166.00000","2.76502","1103.15503","2.71316","1.64793","0.01357","447.05878"
"166.40000","2.77162","1104.46631","2.71970","1.65447","0.01360","447.59018"
"166.80000","2.77808","1105.76855","2.72610","1.66088","0.01363","448.11792"
"167.20000","2.78465","1107.25122","2.73261","1.66739","0.01366","448.71878"
"167.60000","2.79126","1108.61292","2.73916","1.67394","0.01370","449.27060"
"168.00000","2.79807","1110.27490","2.74590","1.68067","0.01373","449.94412"
"168.40000","2.80510","1112.04761","2.75286","1.68763","0.01376","450.66254"
"168.80000","2.81155","1113.17651","2.75925","1.69403","0.01380","451.12003"
"169.20000","2.81816","1114.72681","2.76580","1.70057","0.01383","451.74829"
"169.60000","2.82466","1116.19275","2.77223","1.70701","0.01386","452.34238"
"170.00000","2.83127","1117.54443","2.77879","1.71356","0.01389","452.89014"
"170.40000","2.83808","1119.02112","2.78554","1.72031","0.01393","453.48859"
"170.80000","2.84490","1120.62964","2.79228","1.72706","0.01396","454.14044"
"171.20000","2.85170","1122.20911","2.79902","1.73379","0.01400","454.78052"
"171.60000","2.85805","1123.36108","2.80532","1.74010","0.01403","455.24738"
"172.00000","2.86475","1124.92114","2.81195","1.74673","0.01406","455.87961"
"172.40000","2.87123","1126.19250","2.81837","1.75315","0.01409","456.39481"
"172.80000","2.87798","1127.66833","2.82507","1.75984","0.01413","456.99292"
"173.20000","2.88507","1129.24133","2.83209","1.76686","0.01416","457.63037"
"173.60000","2.89158","1130.41870","2.83855","1.77332","0.01419","458.10751"
"174.00000","2.89824","1131.76111","2.84514","1.77992","0.01423","458.65152"
"174.40000","2.90467","1132.80359","2.85153","1.78631","0.01426","459.07401"
"174.80000","2.91125","1134.10461","2.85806","1.79283","0.01429","459.60123"
"175.20000","2.91792","1135.31580","2.86467","1.79945","0.01432","460.09207"
"175.60000","2.92487","1136.67871","2.87156","1.80634","0.01436","460.64441"
"176.00000","2.93179","1137.96472","2.87843","1.81321","0.01439","461.16556"
"176.40000","2.93814","1138.90466","2.88474","1.81951","0.01442","461.54648"
"176.80000","2.94481","1140.06055","2.89136","1.82613","0.01446","462.01492"
"177.20000","2.95123","1141.07043","2.89774","1.83251","0.01449","462.42416"
"177.60000","2.95793","1142.06433","2.90440","1.83917","0.01452","462.82697"
"178.00000","2.96485","1143.40100","2.91126","1.84604","0.01456","463.36865"
"178.40000","2.97171","1144.62439","2.91807","1.85284","0.01459","463.86444"
"178.80000","2.97827","1145.53601","2.92459","1.85936","0.01462","464.23386"
"179.20000","2.98471","1146.20618","2.93100","1.86577","0.01465","464.50546"
"179.60000","2.99132","1147.06799","2.93757","1.87235","0.01469","464.85471"
"180.00000","2.99790","1147.84412","2.94413","1.87890","0.01472","465.16925"
"180.40000","3.00475","1148.59570","2.95094","1.88571","0.01475","465.47382"
"180.80000","3.01182","1149.80396","2.95796","1.89274","0.01479","465.96347"
"181.20000","3.01828","1150.29785","2.96440","1.89918","0.01482","466.16364"
"181.60000","3.02481","1150.71387","2.97091","1.90569","0.01485","466.33221"
"182.00000","3.03131","1151.28088","2.97739","1.91217","0.01489","466.56201"
"182.40000","3.03790","1151.61841","2.98397","1.91874","0.01492","466.69879"
"182.80000","3.04470","1152.08862","2.99074","1.92552","0.01495","466.88934"
"183.20000","3.05163","1152.66809","2.99765","1.93243","0.01499","467.12418"
"183.60000","3.05840","1153.03186","3.00441","1.93918","0.01502","467.27161"
"184.00000","3.06476","1153.12817","3.01077","1.94554","0.01505","467.31064"
"184.40000","3.07141","1153.22083","3.01741","1.95218","0.01509","467.34818"
"184.80000","3.07794","1153.31921","3.02393","1.95871","0.01512","467.38803"
"185.20000","3.08462","1153.51489","3.03061","1.96539","0.01515","467.46735"
"185.60000","3.09168","1153.96436","3.03765","1.97242","0.01519","467.64951"
"186.00000","3.09823","1154.18713","3.04419","1.97897","0.01522","467.73978"
"186.40000","3.10489","1154.04456","3.05086","1.98563","0.01525","467.68201"
"186.80000","3.11134","1153.96619","3.05730","1.99208","0.01529","467.65024"
"187.20000","3.11799","1153.81311","3.06397","1.99874","0.01532","467.58820"
"187.60000","3.12465","1153.90332","3.07062","2.00539","0.01535","467.62476"
"188.00000","3.13157","1153.88232","3.07754","2.01231","0.01539","467.61624"
"188.40000","3.13845","1153.61902","3.08443","2.01920","0.01542","467.50955"
"188.80000","3.14482","1153.04688","3.09082","2.02560","0.01545","467.27768"
"189.20000","3.15141","1152.56055","3.09744","2.03221","0.01549","467.08060"
"189.60000","3.15791","1151.88110","3.10397","2.03874","0.01552","466.80524"
"190.00000","3.16464","1151.48706","3.11071","2.04549","0.01555","466.64557"
"190.40000","3.17158","1151.06458","3.11767","2.05244","0.01559","466.47433"
"190.80000","3.17838","1150.64136","3.12449","2.05926","0.01562","466.30283"
"191.20000","3.18500","1150.05786","3.13113","2.06590","0.01566","466.06638"
"191.60000","3.19136","1149.07642","3.13753","2.07231","0.01569","465.66864"
"192.00000","3.19798","1148.27429","3.14419","2.07896","0.01572","465.34357"
"192.40000","3.20459","1147.50659","3.15082","2.08560","0.01575","465.03244"
"192.80000","3.21142","1146.77869","3.15769","2.09247","0.01579","464.73746"
"193.20000","3.21843","1145.99304","3.16473","2.09950","0.01582","464.41907"
"193.60000","3.22488","1144.88831","3.17122","2.10600","0.01586","463.97137"
"194.00000","3.23151","1143.44995","3.17792","2.11269","0.01589","463.38849"
"194.40000","3.23797","1141.84558","3.18444","2.11922","0.01592","462.73831"
"194.80000","3.24457","1140.42969","3.19111","2.12588","0.01596","462.16449"
"195.20000","3.25139","1139.05798","3.19799","2.13276","0.01599","461.60861"
"195.60000","3.25827","1137.74792","3.20493","2.13970","0.01602","461.07770"
"196.00000","3.26507","1136.46497","3.21177","2.14655","0.01606","460.55777"
"196.40000","3.27141","1134.71387","3.21820","2.15297","0.01609","459.84814"
"196.80000","3.27803","1133.23669","3.22487","2.15965","0.01612","459.24951"
"197.20000","3.28457","1131.90613","3.23148","2.16625","0.01616","458.71030"
"197.60000","3.29135","1130.67273","3.23830","2.17308","0.01619","458.21045"
"198.00000","3.29841","1129.94336","3.24540","2.18017","0.01623","457.91486"
"198.40000","3.30494","1128.80176","3.25197","2.18675","0.01626","457.45224"
"198.80000","3.31157","1127.82056","3.25865","2.19342","0.01629","457.05460"
"199.20000","3.31800","1126.53577","3.26513","2.19991","0.01633","456.53394"
"199.60000","3.32462","1125.38623","3.27181","2.20658","0.01636","456.06808"
"200.00000","3.33128","1124.49731","3.27850","2.21327","0.01639","455.70782"
"200.40000","3.33820","1123.76233","3.28546","2.22023","0.01643","455.40997"
"200.80000","3.34509","1123.19482","3.29237","2.22714","0.01646","455.17999"
"201.20000","3.35150","1122.20093","3.29881","2.23359","0.01649","454.77722"
"201.60000","3.35814","1121.66162","3.30548","2.24026","0.01653","454.55865"
"202.00000","3.36461","1121.01025","3.31198","2.24675","0.01656","454.29468"
"202.40000","3.37133","1120.59326","3.31872","2.25349","0.01659","454.12570"
"202.80000","3.37827","1120.28210","3.32567","2.26044","0.01663","453.99960"
"203.20000","3.38494","1120.08484","3.33235","2.26713","0.01666","453.91965"
"203.60000","3.39162","1119.82312","3.33904","2.27381","0.01670","453.81360"
"204.00000","3.39805","1119.53625","3.34548","2.28025","0.01673","453.69736"
"204.40000","3.40466","1119.23975","3.35210","2.28688","0.01676","453.57718"
"204.80000","3.41128","1119.12927","3.35873","2.29350","0.01679","453.53241"
"205.20000","3.41818","1119.27209","3.36562","2.30040","0.01683","453.59030"
"205.60000","3.42511","1119.39539","3.37255","2.30733","0.01686","453.64026"
"206.00000","3.43152","1119.24365","3.37896","2.31374","0.01689","453.57877"
"206.40000","3.43814","1119.25684","3.38559","2.32036","0.01693","453.58411"
"206.80000","3.44462","1119.40198","3.39206","2.32684","0.01696","453.64291"
"207.20000","3.45123","1119.50464","3.39867","2.33344","0.01699","453.68454"
"207.60000","3.45810","1119.92480","3.40551","2.34029","0.01703","453.85480"
"208.00000","3.46501","1120.09741","3.41242","2.34719","0.01706","453.92474"
"208.40000","3.47174","1120.34717","3.41914","2.35392","0.01710","454.02597"
"208.80000","3.47811","1120.33337","3.42550","2.36028","0.01713","454.02039"
"209.20000","3.48468","1120.45496","3.43207","2.36684","0.01716","454.06964"
"209.60000","3.49124","1120.52881","3.43863","2.37340","0.01719","454.09958"
"210.00000","3.49800","1120.90552","3.44538","2.38015","0.01723","454.25223"
"210.40000","3.50511","1121.33557","3.45247","2.38724","0.01726","454.42651"
"210.80000","3.51161","1121.49353","3.45896","2.39373","0.01729","454.49054"
"211.20000","3.51819","1121.56311","3.46553","2.40031","0.01733","454.51874"
"211.60000","3.52472","1121.71436","3.47206","2.40683","0.01736","454.58002"
"212.00000","3.53128","1121.73438","3.47862","2.41340","0.01739","454.58813"
"212.40000","3.53798","1121.90784","3.48531","2.42008","0.01743","454.65845"
"212.80000","3.54484","1122.22363","3.49216","2.42693","0.01746","454.78641"
"213.20000","3.55177","1122.51746","3.49908","2.43385","0.01750","454.90549"
"213.60000","3.55808","1122.42993","3.50539","2.44017","0.01753","454.87003"
"214.00000","3.56477","1122.41040","3.51208","2.44686","0.01756","454.86209"
"214.40000","3.57126","1122.41846","3.51857","2.45334","0.01759","454.86536"
"214.80000","3.57802","1122.41174","3.52533","2.46010","0.01763","454.86264"
"215.20000","3.58498","1122.64526","3.53228","2.46705","0.01766","454.95728"
"215.60000","3.59165","1122.58655","3.53895","2.47373","0.01769","454.93350"
"216.00000","3.59830","1122.41223","3.54561","2.48038","0.01773","454.86285"
"216.40000","3.60472","1122.10889","3.55204","2.48682","0.01776","454.73990"
"216.80000","3.61131","1121.86377","3.55865","2.49342","0.01779","454.64056"
"217.20000","3.61786","1121.52710","3.56521","2.49998","0.01783","454.50415"
"217.60000","3.62476","1121.40894","3.57212","2.50689","0.01786","454.45627"
"218.00000","3.63184","1121.22278","3.57921","2.51398","0.01790","454.38083"
"218.40000","3.63822","1120.49695","3.58561","2.52038","0.01793","454.08667"
"218.80000","3.64484","1119.58704","3.59227","2.52704","0.01796","453.71793"
"219.20000","3.65130","1118.43018","3.59878","2.53355","0.01799","453.24908"
"219.60000","3.65794","1117.40491","3.60547","2.54024","0.01803","452.83362"
"220.00000","3.66474","1116.12524","3.61232","2.54709","0.01806","452.31500"
"220.40000","3.67163","1114.79883","3.61926","2.55404","0.01810","451.77747"
"220.80000","3.67833","1113.13147","3.62604","2.56082","0.01813","451.10178"
"221.20000","3.68475","1111.36096","3.63254","2.56731","0.01816","450.38428"
"221.60000","3.69136","1109.60120","3.63922","2.57399","0.01820","449.67111"
"222.00000","3.69788","1107.69580","3.64582","2.58060","0.01823","448.89896"
"222.40000","3.70471","1105.78430","3.65273","2.58751","0.01826","448.12430"
"222.80000","3.71176","1104.14868","3.65985","2.59463","0.01830","447.46146"
"223.20000","3.71832","1102.42761","3.66649","2.60126","0.01833","446.76398"
"223.60000","3.72485","1100.74768","3.67309","2.60786","0.01837","446.08319"
"224.00000","3.73135","1099.39087","3.67965","2.61442","0.01840","445.53333"
"224.40000","3.73790","1097.82397","3.68627","2.62104","0.01843","444.89835"
"224.80000","3.74460","1096.53455","3.69302","2.62780","0.01847","444.37579"
"225.20000","3.75153","1094.00610","3.70006","2.63483","0.01850","443.35114"
"225.28000","3.75289","1043.73792","3.70358","2.63836","0.01852","422.97971"
"225.29200","3.75306","995.11102","3.70579","2.64056","0.01853","403.27344"
"225.30800","3.75330","951.17834","3.70799","2.64277","0.01854","385.46951"
"225.52900","3.75710","922.95648","3.71300","2.64778","0.01857","374.03247"
"225.90500","3.76336","897.30573","3.72033","2.65511","0.01860","363.63736"
"226.30500","3.77011","886.09204","3.72755","2.66232","0.01864","359.09299"
"226.70500","3.77651","874.57782","3.73443","2.66921","0.01867","354.42679"
"227.10500","3.78315","872.18347","3.74117","2.67595","0.01871","353.45645"
"227.48000","3.78927","859.13196","3.74784","2.68261","0.01874","348.16727"
"227.62700","3.79221","822.34943","3.75235","2.68712","0.01876","333.26099"
"228.02700","3.79862","817.57141","3.75897","2.69374","0.01879","331.32468"
"228.42700","3.80531","813.98608","3.76581","2.70058","0.01883","329.87170"
"228.60100","3.80803","777.80090","3.77007","2.70485","0.01885","315.20749"
"228.61700","3.80836","728.54865","3.77250","2.70728","0.01886","295.24777"
"228.63400","3.80874","681.35004","3.77499","2.70977","0.01887","276.12030"
"228.76500","3.81086","646.03302","3.77869","2.71346","0.01889","261.80792"
"229.03200","3.81563","605.60211","3.78526","2.72004","0.01893","245.42311"
"229.10400","3.81664","595.10016","3.78674","2.72152","0.01893","241.16714"