File: flexion/5_axis/Specimen_RawData_7.csv
Specimen properties : Specimen label,"7"
Specimen properties : Support span,"72.00",mm
Specimen properties : Thickness,"4.67",mm
Specimen properties : Width,"13.07",mm
Maximum Load : Maximum Load,"449.4",N
Tangent Modulus of Elasticity : Tangent Modulus of Elasticity,"19052353732.90140",Pa
Test : Rate 1,"1.00000",mm/min
Specimen notes : Specimen note 1,""

Time,Displacement,Load,Flexure extension,Corrected extension,Flexure strain (Corrected extension),Flexure stress
(s),(mm),(N),(mm),(mm),(mm/mm),(MPa)
"0.00000","0.00000","9.21764","-0.03862","-1.04677","-0.00021","3.49248"
"0.50000","0.00626","10.52268","-0.03293","-1.04107","-0.00018","3.98695"
"1.00000","0.01460","12.32191","-0.02536","-1.03350","-0.00014","4.66866"
"1.50000","0.02293","13.82429","-0.01768","-1.02582","-0.00010","5.23790"
"2.00000","0.03115","15.36177","-0.01012","-1.01827","-0.00005","5.82044"
"2.50000","0.03983","17.05127","-0.00188","-1.01003","-0.00001","6.46057"
"3.00000","0.04773","18.44888","0.00573","-1.00242","0.00003","6.99011"
"3.50000","0.05650","19.94569","0.01418","-0.99397","0.00008","7.55724"
"4.00000","0.06445","21.25941","0.02185","-0.98630","0.00012","8.05500"
"4.50000","0.07333","22.89782","0.03039","-0.97776","0.00016","8.67578"
"5.00000","0.08121","24.27519","0.03798","-0.97017","0.00021","9.19765"
"5.50000","0.08971","25.92110","0.04613","-0.96202","0.00025","9.82127"
"6.00000","0.09799","27.35750","0.05410","-0.95405","0.00029","10.36551"
"6.50000","0.10622","29.01133","0.06198","-0.94616","0.00034","10.99213"
"7.00000","0.11460","30.49724","0.07005","-0.93809","0.00038","11.55513"
"7.50000","0.12278","32.09585","0.07789","-0.93025","0.00042","12.16083"
"8.00000","0.13153","33.71704","0.08629","-0.92185","0.00047","12.77509"
"8.50000","0.13945","35.25674","0.09390","-0.91425","0.00051","13.35846"
"9.00000","0.14819","36.97617","0.10238","-0.90576","0.00055","14.00994"
"9.50000","0.15621","38.56811","0.11019","-0.89795","0.00060","14.61311"
"10.00000","0.16496","40.30522","0.11871","-0.88944","0.00064","15.27129"
"10.50000","0.17283","41.92607","0.12636","-0.88179","0.00068","15.88542"
"11.00000","0.18130","43.78678","0.13458","-0.87356","0.00073","16.59042"
"11.50000","0.18966","45.44277","0.14272","-0.86543","0.00077","17.21786"
"12.00000","0.19779","47.18244","0.15062","-0.85753","0.00081","17.87701"
"12.50000","0.20632","49.06898","0.15889","-0.84925","0.00086","18.59180"
"13.00000","0.21446","50.90714","0.16678","-0.84137","0.00090","19.28826"
"13.50000","0.22328","52.65037","0.17537","-0.83278","0.00095","19.94876"
"14.00000","0.23107","54.59349","0.18290","-0.82525","0.00099","20.68499"
"14.50000","0.23991","56.54274","0.19148","-0.81667","0.00103","21.42354"
"15.00000","0.24785","58.40408","0.19918","-0.80897","0.00108","22.12878"
"15.50000","0.25654","60.32571","0.20765","-0.80050","0.00112","22.85688"
"16.00000","0.26453","62.24971","0.21542","-0.79273","0.00116","23.58586"
"16.50000","0.27292","63.99242","0.22360","-0.78454","0.00121","24.24616"
"17.00000","0.28137","66.01853","0.23182","-0.77633","0.00125","25.01383"
"17.50000","0.28945","67.95538","0.23966","-0.76848","0.00130","25.74769"
"18.00000","0.29809","69.97324","0.24807","-0.76008","0.00134","26.51224"
"18.50000","0.30610","71.84739","0.25586","-0.75228","0.00138","27.22234"
"19.00000","0.31497","73.90566","0.26449","-0.74365","0.00143","28.00220"
"19.50000","0.32282","75.79750","0.27212","-0.73603","0.00147","28.71900"
"20.00000","0.33151","77.87704","0.28057","-0.72758","0.00152","29.50692"
"20.50000","0.33957","79.79938","0.28840","-0.71974","0.00156","30.23527"
"21.00000","0.34814","81.78311","0.29674","-0.71141","0.00160","30.98689"
"21.50000","0.35621","83.84417","0.30457","-0.70358","0.00165","31.76781"
"22.00000","0.36451","85.74663","0.31264","-0.69550","0.00169","32.48863"
"22.50000","0.37307","87.91686","0.32097","-0.68718","0.00173","33.31092"
"23.00000","0.38113","89.80479","0.32884","-0.67931","0.00178","34.02623"
"23.50000","0.38976","92.08773","0.33724","-0.67090","0.00182","34.89122"
"24.00000","0.39781","93.98122","0.34511","-0.66303","0.00187","35.60865"
"24.50000","0.40662","96.14489","0.35371","-0.65444","0.00191","36.42844"
"25.00000","0.41443","98.15093","0.36132","-0.64682","0.00195","37.18851"
"25.50000","0.42310","100.35863","0.36977","-0.63838","0.00200","38.02499"
"26.00000","0.43123","102.35208","0.37771","-0.63043","0.00204","38.78029"
"26.50000","0.43971","104.57271","0.38597","-0.62217","0.00209","39.62167"
"27.00000","0.44790","106.57346","0.39396","-0.61418","0.00213","40.37974"
"27.50000","0.45623","108.82356","0.40208","-0.60607","0.00217","41.23228"
"28.00000","0.46484","111.05157","0.41047","-0.59767","0.00222","42.07645"
"28.50000","0.47274","113.14304","0.41816","-0.58998","0.00226","42.86889"
"29.00000","0.48149","115.48243","0.42668","-0.58146","0.00231","43.75526"
"29.50000","0.48944","117.37203","0.43445","-0.57370","0.00235","44.47122"
"30.00000","0.49828","119.98113","0.44304","-0.56511","0.00239","45.45978"
"30.50000","0.50613","121.99405","0.45069","-0.55746","0.00244","46.22246"
"31.00000","0.51477","124.29710","0.45911","-0.54904","0.00248","47.09506"
"31.50000","0.52292","126.41796","0.46705","-0.54109","0.00252","47.89864"
"32.00000","0.53132","128.73602","0.47522","-0.53293","0.00257","48.77693"
"32.50000","0.53964","131.13245","0.48331","-0.52484","0.00261","49.68492"
"33.00000","0.54781","133.31647","0.49127","-0.51688","0.00266","50.51242"
"33.50000","0.55648","135.61491","0.49972","-0.50843","0.00270","51.38329"
"34.00000","0.56443","137.85173","0.50745","-0.50070","0.00274","52.23079"
"34.50000","0.57313","140.37416","0.51590","-0.49225","0.00279","53.18652"
"35.00000","0.58116","142.55283","0.52372","-0.48442","0.00283","54.01200"
"35.50000","0.58999","145.08231","0.53230","-0.47584","0.00288","54.97039"
"36.00000","0.59786","147.17314","0.53997","-0.46818","0.00292","55.76259"
"36.50000","0.60636","149.50769","0.54824","-0.45991","0.00296","56.64713"
"37.00000","0.61466","151.92169","0.55630","-0.45184","0.00301","57.56178"
"37.50000","0.62297","154.08815","0.56440","-0.44374","0.00305","58.38263"
"38.00000","0.63132","156.37337","0.57253","-0.43561","0.00309","59.24848"
"38.50000","0.63950","158.72083","0.58050","-0.42765","0.00314","60.13791"
"39.00000","0.64819","161.14644","0.58898","-0.41916","0.00318","61.05695"
"39.50000","0.65604","163.28702","0.59665","-0.41149","0.00322","61.86800"
"40.00000","0.66479","165.68835","0.60520","-0.40295","0.00327","62.77784"
"40.50000","0.67280","167.88821","0.61302","-0.39512","0.00331","63.61135"
"41.00000","0.68163","170.26408","0.62165","-0.38649","0.00336","64.51154"
"41.50000","0.68953","172.42372","0.62936","-0.37879","0.00340","65.32981"
"42.00000","0.69810","174.75653","0.63773","-0.37041","0.00345","66.21369"
"42.50000","0.70637","176.98395","0.64581","-0.36233","0.00349","67.05764"
"43.00000","0.71451","179.16411","0.65377","-0.35438","0.00353","67.88368"
"43.50000","0.72301","181.48695","0.66207","-0.34607","0.00358","68.76379"
"44.00000","0.73111","183.58553","0.67000","-0.33815","0.00362","69.55892"
"44.50000","0.73989","186.01012","0.67857","-0.32958","0.00367","70.47758"
"45.00000","0.74774","188.04610","0.68625","-0.32190","0.00371","71.24899"
"45.50000","0.75654","190.54100","0.69483","-0.31332","0.00376","72.19429"
"46.00000","0.76449","192.47557","0.70262","-0.30553","0.00380","72.92728"
"46.50000","0.77327","194.92976","0.71119","-0.29695","0.00384","73.85715"
"47.00000","0.78125","197.08929","0.71899","-0.28916","0.00389","74.67538"
"47.50000","0.78963","199.22482","0.72718","-0.28097","0.00393","75.48451"
"48.00000","0.79802","201.38870","0.73539","-0.27275","0.00397","76.30439"
"48.50000","0.80613","203.40332","0.74334","-0.26481","0.00402","77.06771"
"49.00000","0.81470","205.80513","0.75172","-0.25642","0.00406","77.97773"
"49.50000","0.82282","207.78531","0.75968","-0.24847","0.00411","78.72800"
"50.00000","0.83164","210.25168","0.76830","-0.23985","0.00415","79.66249"
"50.50000","0.83947","212.04637","0.77599","-0.23215","0.00419","80.34248"
"51.00000","0.84817","214.40556","0.78450","-0.22364","0.00424","81.23636"
"51.50000","0.85625","216.42509","0.79242","-0.21573","0.00428","82.00154"
"52.00000","0.86487","218.69965","0.80086","-0.20729","0.00433","82.86335"
"52.50000","0.87290","220.69229","0.80873","-0.19942","0.00437","83.61835"
"53.00000","0.88125","222.67413","0.81692","-0.19123","0.00442","84.36925"
"53.50000","0.88974","224.89140","0.82523","-0.18292","0.00446","85.20935"
"54.00000","0.89774","226.82108","0.83308","-0.17507","0.00450","85.94048"
"54.50000","0.90639","229.12906","0.84154","-0.16660","0.00455","86.81496"
"55.00000","0.91445","231.07661","0.84945","-0.15869","0.00459","87.55287"
"55.50000","0.92333","233.36447","0.85814","-0.15000","0.00464","88.41972"
"56.00000","0.93114","235.25832","0.86580","-0.14235","0.00468","89.13728"
"56.50000","0.93990","237.52316","0.87438","-0.13377","0.00473","89.99541"
"57.00000","0.94791","239.44466","0.88223","-0.12591","0.00477","90.72345"
"57.50000","0.95645","241.52315","0.89061","-0.11754","0.00481","91.51097"
"58.00000","0.96458","243.42793","0.89859","-0.10956","0.00486","92.23267"
"58.50000","0.97288","245.43779","0.90673","-0.10141","0.00490","92.99419"
"59.00000","0.98142","247.57057","0.91511","-0.09303","0.00495","93.80228"
"59.50000","0.98939","249.59361","0.92293","-0.08522","0.00499","94.56880"
"60.00000","0.99815","251.71696","0.93153","-0.07662","0.00503","95.37331"
"60.50000","1.00612","253.51578","0.93935","-0.06879","0.00508","96.05487"
"61.00000","1.01502","255.69247","0.94809","-0.06005","0.00512","96.87960"
"61.50000","1.02284","257.35187","0.95578","-0.05237","0.00517","97.50833"
"62.00000","1.03144","259.48718","0.96422","-0.04393","0.00521","98.31738"
"62.50000","1.03958","261.45697","0.97221","-0.03594","0.00525","99.06372"
"63.00000","1.04799","263.32260","0.98047","-0.02768","0.00530","99.77059"
"63.50000","1.05627","265.28723","0.98860","-0.01955","0.00534","100.51497"
"64.00000","1.06451","267.19617","0.99670","-0.01145","0.00539","101.23825"
"64.50000","1.07316","269.16180","1.00519","-0.00295","0.00543","101.98301"
"65.00000","1.08113","270.89844","1.01303","0.00489","0.00548","102.64101"
"65.50000","1.08982","273.06085","1.02156","0.01341","0.00552","103.46033"
"66.00000","1.09788","274.63095","1.02950","0.02135","0.00556","104.05522"
"66.50000","1.10664","276.68936","1.03810","0.02995","0.00561","104.83514"
"67.00000","1.11450","278.42050","1.04583","0.03768","0.00565","105.49105"
"67.50000","1.12304","280.36063","1.05422","0.04607","0.00570","106.22614"
"68.00000","1.13131","282.05606","1.06235","0.05421","0.00574","106.86853"
"68.50000","1.13961","283.88910","1.07052","0.06237","0.00579","107.56305"
"69.00000","1.14796","285.67822","1.07873","0.07059","0.00583","108.24094"
"69.50000","1.15617","287.40295","1.08681","0.07866","0.00587","108.89442"
"70.00000","1.16487","289.29758","1.09536","0.08721","0.00592","109.61227"
"70.50000","1.17277","290.84842","1.10315","0.09500","0.00596","110.19987"
"71.00000","1.18156","292.77142","1.11180","0.10366","0.00601","110.92849"
"71.50000","1.18950","294.29974","1.11965","0.11150","0.00605","111.50755"
"72.00000","1.19825","296.25742","1.12826","0.12012","0.00610","112.24930"
"72.50000","1.20617","297.82559","1.13608","0.12794","0.00614","112.84347"
"73.00000","1.21473","299.67331","1.14451","0.13637","0.00619","113.54355"
"73.50000","1.22299","301.38696","1.15266","0.14452","0.00623","114.19284"
"74.00000","1.23120","302.95413","1.16077","0.15262","0.00627","114.78662"
"74.50000","1.23969","304.55099","1.16915","0.16101","0.00632","115.39166"
"75.00000","1.24779","306.08862","1.17715","0.16900","0.00636","115.97426"
"75.50000","1.25653","307.77274","1.18578","0.17763","0.00641","116.61235"
"76.00000","1.26442","309.28650","1.19356","0.18542","0.00645","117.18590"
"76.50000","1.27317","310.86810","1.20221","0.19406","0.00650","117.78516"
"77.00000","1.28116","312.43579","1.21009","0.20194","0.00654","118.37914"
"77.50000","1.28992","314.32541","1.21873","0.21058","0.00659","119.09510"
"78.00000","1.29788","315.63333","1.22660","0.21845","0.00663","119.59066"
"78.50000","1.30629","317.35080","1.23489","0.22674","0.00667","120.24139"
"79.00000","1.31471","319.06265","1.24320","0.23505","0.00672","120.89000"
"79.50000","1.32287","320.49182","1.25126","0.24311","0.00676","121.43150"
"80.00000","1.33136","322.16626","1.25964","0.25149","0.00681","122.06593"
"80.50000","1.33953","323.50647","1.26772","0.25958","0.00685","122.57372"
"81.00000","1.34822","325.28949","1.27629","0.26814","0.00690","123.24929"
"81.50000","1.35608","326.75366","1.28406","0.27591","0.00694","123.80405"
"82.00000","1.36476","328.40277","1.29262","0.28448","0.00699","124.42889"
"82.50000","1.37287","329.91998","1.30063","0.29249","0.00703","125.00375"
"83.00000","1.38155","331.49677","1.30920","0.30106","0.00708","125.60117"
"83.50000","1.38955","332.90149","1.31711","0.30896","0.00712","126.13341"
"84.00000","1.39798","334.51236","1.32543","0.31728","0.00716","126.74376"
"84.50000","1.40641","336.02518","1.33376","0.32561","0.00721","127.31695"
"85.00000","1.41449","337.34973","1.34175","0.33360","0.00725","127.81881"
"85.50000","1.42305","338.79013","1.35021","0.34207","0.00730","128.36456"
"86.00000","1.43115","340.28027","1.35822","0.35008","0.00734","128.92917"
"86.50000","1.43994","341.89001","1.36690","0.35875","0.00739","129.53908"
"87.00000","1.44779","342.98691","1.37468","0.36654","0.00743","129.95468"
"87.50000","1.45658","344.54492","1.38337","0.37522","0.00748","130.54500"
"88.00000","1.46455","345.82974","1.39126","0.38311","0.00752","131.03181"
"88.50000","1.47311","347.35022","1.39972","0.39157","0.00757","131.60791"
"89.00000","1.48124","348.63965","1.40777","0.39963","0.00761","132.09647"
"89.50000","1.48957","350.02972","1.41601","0.40786","0.00765","132.62315"
"90.00000","1.49804","351.38165","1.42439","0.41625","0.00770","133.13538"
"90.50000","1.50607","352.54517","1.43235","0.42420","0.00774","133.57622"
"91.00000","1.51474","353.97162","1.44092","0.43278","0.00779","134.11670"
"91.50000","1.52277","355.28424","1.44887","0.44072","0.00783","134.61403"
"92.00000","1.53165","356.80643","1.45766","0.44951","0.00788","135.19078"
"92.50000","1.53949","358.03717","1.46541","0.45727","0.00792","135.65709"
"93.00000","1.54812","359.56387","1.47395","0.46580","0.00797","136.23555"
"93.50000","1.55626","360.67819","1.48201","0.47387","0.00801","136.65776"
"94.00000","1.56474","362.08508","1.49041","0.48226","0.00806","137.19081"
"94.50000","1.57291","363.50406","1.49849","0.49034","0.00810","137.72845"
"95.00000","1.58126","364.72244","1.50675","0.49861","0.00814","138.19009"
"95.50000","1.58979","366.19293","1.51519","0.50704","0.00819","138.74724"
"96.00000","1.59774","367.27237","1.52307","0.51492","0.00823","139.15623"
"96.50000","1.60637","368.70593","1.53162","0.52347","0.00828","139.69940"
"97.00000","1.61450","369.93146","1.53967","0.53152","0.00832","140.16374"
"97.50000","1.62335","371.46240","1.54842","0.54027","0.00837","140.74380"
"98.00000","1.63115","372.48898","1.55615","0.54800","0.00841","141.13277"
"98.50000","1.63982","373.78027","1.56474","0.55660","0.00846","141.62202"
"99.00000","1.64795","374.85464","1.57280","0.56466","0.00850","142.02908"
"99.50000","1.65635","376.10779","1.58112","0.57297","0.00855","142.50389"
"100.00000","1.66459","377.31009","1.58928","0.58113","0.00859","142.95943"
"100.50000","1.67286","378.31973","1.59749","0.58934","0.00863","143.34198"
"101.00000","1.68149","378.32663","1.60611","0.59796","0.00868","143.34459"
"101.50000","1.68941","378.98056","1.61399","0.60584","0.00872","143.59236"
"102.00000","1.69817","380.09122","1.62268","0.61454","0.00877","144.01318"
"102.50000","1.70613","379.70337","1.63067","0.62252","0.00881","143.86623"
"103.00000","1.71501","380.62250","1.63949","0.63135","0.00886","144.21448"
"103.50000","1.72284","381.48578","1.64727","0.63912","0.00890","144.54156"
"104.00000","1.73141","382.69147","1.65575","0.64761","0.00895","144.99840"
"104.50000","1.73958","383.64728","1.66386","0.65572","0.00899","145.36053"
"105.00000","1.74789","384.91010","1.67209","0.66395","0.00904","145.83900"
"105.50000","1.75631","386.00830","1.68044","0.67230","0.00908","146.25511"
"106.00000","1.76446","387.00067","1.68853","0.68039","0.00913","146.63110"
"106.50000","1.77318","388.19528","1.69717","0.68902","0.00917","147.08374"
"107.00000","1.78111","388.80496","1.70506","0.69691","0.00922","147.31474"
"107.50000","1.78982","388.83716","1.71377","0.70562","0.00926","147.32693"
"108.00000","1.79785","389.41876","1.72177","0.71362","0.00931","147.54730"
"108.50000","1.80663","390.45483","1.73049","0.72235","0.00935","147.93987"
"109.00000","1.81452","391.29984","1.73832","0.73018","0.00940","148.26003"
"109.50000","1.82303","392.22614","1.74679","0.73864","0.00944","148.61099"
"110.00000","1.83136","392.99942","1.75507","0.74692","0.00949","148.90398"
"110.50000","1.83950","393.63354","1.76318","0.75503","0.00953","149.14424"
"111.00000","1.84799","393.44550","1.77168","0.76353","0.00958","149.07300"
"111.50000","1.85617","392.50098","1.77991","0.77176","0.00962","148.71513"
"112.00000","1.86490","392.51099","1.78864","0.78049","0.00967","148.71892"
"112.50000","1.87275","392.47150","1.79649","0.78835","0.00971","148.70395"
"113.00000","1.88151","392.95599","1.80523","0.79708","0.00976","148.88753"
"113.50000","1.88952","393.62781","1.81320","0.80505","0.00980","149.14207"
"114.00000","1.89825","394.50851","1.82187","0.81373","0.00985","149.47577"
"114.50000","1.90617","395.04935","1.82976","0.82162","0.00989","149.68068"
"115.00000","1.91465","395.40302","1.83823","0.83008","0.00994","149.81468"
"115.50000","1.92304","394.22415","1.84668","0.83853","0.00998","149.36803"
"116.00000","1.93114","394.28979","1.85478","0.84663","0.01003","149.39290"
"116.50000","1.93973","394.95398","1.86333","0.85518","0.01007","149.64455"
"117.00000","1.94781","395.52612","1.87138","0.86324","0.01011","149.86133"
"117.50000","1.95666","396.14691","1.88019","0.87205","0.01016","150.09654"
"118.00000","1.96445","396.32587","1.88797","0.87982","0.01020","150.16434"
"118.50000","1.97322","396.76569","1.89672","0.88857","0.01025","150.33099"
"119.00000","1.98118","394.66202","1.90479","0.89665","0.01030","149.53392"
"119.50000","1.98985","394.31937","1.91349","0.90534","0.01034","149.40410"
"120.00000","1.99791","394.45920","1.92154","0.91340","0.01039","149.45708"
"120.50000","2.00621","394.94299","1.92981","0.92166","0.01043","149.64038"
"121.00000","2.01468","395.60074","1.93824","0.93010","0.01048","149.88960"
"121.50000","2.02279","396.16196","1.94632","0.93818","0.01052","150.10223"
"122.00000","2.03138","396.91040","1.95487","0.94672","0.01057","150.38582"
"122.50000","2.03947","397.66403","1.96292","0.95477","0.01061","150.67136"
"123.00000","2.04829","398.57608","1.97168","0.96353","0.01066","151.01692"
"123.50000","2.05611","399.03348","1.97948","0.97134","0.01070","151.19023"
"124.00000","2.06480","399.85971","1.98812","0.97998","0.01075","151.50328"
"124.50000","2.07295","400.30554","1.99624","0.98810","0.01079","151.67221"
"125.00000","2.08147","400.97064","2.00473","0.99658","0.01084","151.92421"
"125.50000","2.08958","401.47723","2.01281","1.00467","0.01088","152.11615"
"126.00000","2.09791","402.11148","2.02111","1.01296","0.01092","152.35646"
"126.50000","2.10643","402.83139","2.02958","1.02143","0.01097","152.62923"
"127.00000","2.11443","403.39627","2.03755","1.02940","0.01101","152.84326"
"127.50000","2.12310","404.08298","2.04618","1.03804","0.01106","153.10344"
"128.00000","2.13115","404.66684","2.05420","1.04605","0.01110","153.32466"
"128.50000","2.13995","405.37772","2.06296","1.05481","0.01115","153.59401"
"129.00000","2.14776","405.93402","2.07073","1.06259","0.01119","153.80479"
"129.50000","2.15647","406.68445","2.07940","1.07126","0.01124","154.08911"
"130.00000","2.16460","407.20673","2.08750","1.07936","0.01128","154.28700"
"130.50000","2.17300","407.81357","2.09587","1.08772","0.01133","154.51694"
"131.00000","2.18127","408.52805","2.10410","1.09595","0.01137","154.78764"
"131.50000","2.18953","409.11014","2.11232","1.10417","0.01142","155.00819"
"132.00000","2.19816","409.75137","2.12092","1.11277","0.01146","155.25114"
"132.50000","2.20609","406.79541","2.12902","1.12087","0.01151","154.13116"
"133.00000","2.21484","402.85745","2.13799","1.12984","0.01156","152.63910"
"133.50000","2.22278","402.70407","2.14594","1.13779","0.01160","152.58099"
"134.00000","2.23169","403.19617","2.15482","1.14668","0.01165","152.76744"
"134.50000","2.23951","403.41452","2.16263","1.15448","0.01169","152.85017"
"135.00000","2.24806","403.97867","2.17114","1.16300","0.01174","153.06392"
"135.50000","2.25627","404.35745","2.17934","1.17119","0.01178","153.20744"
"136.00000","2.26462","404.76196","2.18766","1.17951","0.01182","153.36070"
"136.50000","2.27293","405.16776","2.19595","1.18780","0.01187","153.51445"
"137.00000","2.28114","405.37949","2.20414","1.19600","0.01191","153.59468"
"137.50000","2.28982","405.56393","2.21282","1.20467","0.01196","153.66457"
"138.00000","2.29776","405.49765","2.22076","1.21261","0.01200","153.63945"
"138.50000","2.30642","405.68359","2.22941","1.22126","0.01205","153.70990"
"139.00000","2.31452","405.64319","2.23751","1.22936","0.01209","153.69460"
"139.50000","2.32332","405.91833","2.24630","1.23815","0.01214","153.79884"
"140.00000","2.33119","405.96161","2.25416","1.24602","0.01218","153.81525"
"140.50000","2.33974","406.25613","2.26269","1.25455","0.01223","153.92683"
"141.00000","2.34802","406.54330","2.27096","1.26281","0.01227","154.03564"
"141.50000","2.35622","406.74954","2.27915","1.27100","0.01232","154.11378"
"142.00000","2.36465","407.23868","2.28755","1.27940","0.01236","154.29910"
"142.50000","2.37282","407.57861","2.29570","1.28755","0.01241","154.42790"
"143.00000","2.38154","407.85934","2.30441","1.29626","0.01246","154.53427"
"143.50000","2.38937","408.29825","2.31221","1.30406","0.01250","154.70058"
"144.00000","2.39816","408.77634","2.32098","1.31283","0.01255","154.88171"
"144.50000","2.40615","409.06778","2.32895","1.32080","0.01259","154.99214"
"145.00000","2.41487","409.77173","2.33763","1.32948","0.01264","155.25887"
"145.50000","2.42286","410.13788","2.34560","1.33745","0.01268","155.39760"
"146.00000","2.43137","410.67038","2.35408","1.34593","0.01272","155.59935"
"146.50000","2.43971","411.19833","2.36238","1.35424","0.01277","155.79939"
"147.00000","2.44784","411.64575","2.37049","1.36234","0.01281","155.96892"
"147.50000","2.45638","412.13431","2.37901","1.37086","0.01286","156.15402"
"148.00000","2.46443","412.53873","2.38703","1.37888","0.01290","156.30725"
"148.50000","2.47328","413.37866","2.39583","1.38768","0.01295","156.62549"
"149.00000","2.48112","413.61401","2.40365","1.39551","0.01299","156.71466"
"149.50000","2.48985","414.20282","2.41236","1.40421","0.01304","156.93776"
"150.00000","2.49787","414.68466","2.42035","1.41220","0.01308","157.12033"
"150.50000","2.50655","415.23822","2.42899","1.42085","0.01313","157.33006"
"151.00000","2.51456","415.70532","2.43698","1.42883","0.01317","157.50705"
"151.50000","2.52290","416.12439","2.44529","1.43715","0.01322","157.66583"
"152.00000","2.53137","416.67294","2.45374","1.44559","0.01326","157.87367"
"152.50000","2.53945","416.98474","2.46179","1.45365","0.01331","157.99181"
"153.00000","2.54797","417.61584","2.47028","1.46213","0.01335","158.23093"
"153.50000","2.55610","418.01208","2.47839","1.47024","0.01340","158.38106"
"154.00000","2.56498","418.59747","2.48724","1.47909","0.01344","158.60286"
"154.50000","2.57280","418.84644","2.49504","1.48689","0.01349","158.69719"
"155.00000","2.58153","419.47662","2.50373","1.49558","0.01353","158.93596"
"155.50000","2.58960","419.87134","2.51178","1.50363","0.01358","159.08551"
"156.00000","2.59814","420.35376","2.52029","1.51214","0.01362","159.26830"
"156.50000","2.60624","420.71161","2.52837","1.52022","0.01367","159.40388"
"157.00000","2.61460","421.31332","2.53669","1.52855","0.01371","159.63187"
"157.50000","2.62309","421.79120","2.54516","1.53701","0.01376","159.81293"
"158.00000","2.63106","422.10367","2.55311","1.54497","0.01380","159.93132"
"158.50000","2.63972","422.69971","2.56174","1.55360","0.01385","160.15715"
"159.00000","2.64777","423.13068","2.56977","1.56162","0.01389","160.32045"
"159.50000","2.65662","423.79312","2.57858","1.57043","0.01394","160.57144"
"160.00000","2.66445","423.97702","2.58639","1.57825","0.01398","160.64111"
"160.50000","2.67318","424.72589","2.59508","1.58694","0.01403","160.92487"
"161.00000","2.68123","424.99454","2.60312","1.59497","0.01407","161.02664"
"161.50000","2.68972","425.56454","2.61158","1.60343","0.01412","161.24261"
"162.00000","2.69794","425.90396","2.61977","1.61163","0.01416","161.37122"
"162.50000","2.70618","426.31509","2.62800","1.61985","0.01420","161.52699"
"163.00000","2.71479","426.96759","2.63656","1.62842","0.01425","161.77422"
"163.50000","2.72275","427.28799","2.64451","1.63636","0.01429","161.89561"
"164.00000","2.73148","427.89294","2.65320","1.64506","0.01434","162.12483"
"164.50000","2.73949","428.19400","2.66120","1.65305","0.01438","162.23889"
"165.00000","2.74835","428.94598","2.67001","1.66186","0.01443","162.52382"
"165.50000","2.75617","429.12387","2.67782","1.66967","0.01447","162.59122"
"166.00000","2.76471","429.61026","2.68634","1.67819","0.01452","162.77550"
"166.50000","2.77296","430.12271","2.69456","1.68641","0.01456","162.96967"
"167.00000","2.78131","430.43097","2.70289","1.69474","0.01461","163.08646"
"167.50000","2.78959","430.85846","2.71114","1.70300","0.01465","163.24843"
"168.00000","2.79781","431.27631","2.71934","1.71120","0.01470","163.40675"
"168.50000","2.80650","431.79276","2.72800","1.71986","0.01475","163.60243"
"169.00000","2.81442","432.10977","2.73591","1.72776","0.01479","163.72255"
"169.50000","2.82311","432.63593","2.74456","1.73642","0.01483","163.92191"
"170.00000","2.83120","432.96838","2.75263","1.74448","0.01488","164.04787"
"170.50000","2.84002","433.58994","2.76142","1.75327","0.01493","164.28337"
"171.00000","2.84784","433.71054","2.76923","1.76109","0.01497","164.32906"
"171.50000","2.85640","434.21979","2.77776","1.76961","0.01501","164.52202"
"172.00000","2.86465","434.51804","2.78600","1.77785","0.01506","164.63501"
"172.50000","2.87288","434.83395","2.79421","1.78607","0.01510","164.75471"
"173.00000","2.88129","435.35571","2.80259","1.79444","0.01515","164.95241"
"173.50000","2.88947","435.62674","2.81075","1.80260","0.01519","165.05510"
"174.00000","2.89819","436.02814","2.81945","1.81130","0.01524","165.20718"
"174.50000","2.90605","436.18204","2.82730","1.81916","0.01528","165.26549"
"175.00000","2.91486","436.76645","2.83608","1.82793","0.01533","165.48692"
"175.50000","2.92282","436.95309","2.84402","1.83588","0.01537","165.55763"
"176.00000","2.93160","437.48651","2.85277","1.84463","0.01542","165.75975"
"176.50000","2.93952","437.51434","2.86069","1.85255","0.01546","165.77029"
"177.00000","2.94798","437.96600","2.86913","1.86098","0.01551","165.94142"
"177.50000","2.95633","438.30612","2.87746","1.86931","0.01555","166.07028"
"178.00000","2.96452","438.45804","2.88564","1.87749","0.01560","166.12785"
"178.50000","2.97303","438.71851","2.89414","1.88599","0.01564","166.22653"
"179.00000","2.98117","438.85526","2.90226","1.89412","0.01569","166.27835"
"179.50000","2.98992","439.23642","2.91099","1.90285","0.01573","166.42278"
"180.00000","2.99775","439.36237","2.91882","1.91068","0.01578","166.47049"
"180.50000","3.00643","439.75464","2.92748","1.91933","0.01582","166.61913"
"181.00000","3.01455","439.89310","2.93559","1.92744","0.01587","166.67159"
"181.50000","3.02323","440.35538","2.94424","1.93610","0.01591","166.84673"
"182.00000","3.03119","440.36560","2.95221","1.94406","0.01596","166.85060"
"182.50000","3.03959","440.71643","2.96058","1.95243","0.01600","166.98354"
"183.00000","3.04807","440.91534","2.96905","1.96090","0.01605","167.05890"
"183.50000","3.05620","441.27567","2.97716","1.96901","0.01609","167.19542"
"184.00000","3.06467","441.56317","2.98562","1.97747","0.01614","167.30435"
"184.50000","3.07283","441.77319","2.99376","1.98562","0.01618","167.38393"
"185.00000","3.08161","442.08151","3.00253","1.99438","0.01623","167.50075"
"185.50000","3.08941","442.24677","3.01032","2.00217","0.01627","167.56337"
"186.00000","3.09818","442.62210","3.01906","2.01092","0.01632","167.70557"
"186.50000","3.10623","442.76700","3.02711","2.01896","0.01636","167.76047"
"187.00000","3.11484","443.00015","3.03570","2.02755","0.01641","167.84882"
"187.50000","3.12287","443.24155","3.04372","2.03558","0.01645","167.94028"
"188.00000","3.13126","443.35541","3.05210","2.04396","0.01650","167.98341"
"188.50000","3.13973","443.66522","3.06055","2.05241","0.01654","168.10080"
"189.00000","3.14777","443.72980","3.06859","2.06044","0.01659","168.12527"
"189.50000","3.15639","444.00455","3.07720","2.06905","0.01663","168.22937"
"190.00000","3.16444","444.08838","3.08524","2.07709","0.01668","168.26114"
"190.50000","3.17326","444.42703","3.09404","2.08589","0.01672","168.38945"
"191.00000","3.18111","444.43533","3.10189","2.09374","0.01677","168.39259"
"191.50000","3.18982","444.66592","3.11059","2.10244","0.01681","168.47997"
"192.00000","3.19788","444.73721","3.11864","2.11050","0.01686","168.50697"
"192.50000","3.20648","445.00748","3.12723","2.11908","0.01690","168.60938"
"193.00000","3.21462","444.86969","3.13538","2.12723","0.01695","168.55716"
"193.50000","3.22290","445.13904","3.14364","2.13550","0.01699","168.65923"
"194.00000","3.23144","445.23877","3.15217","2.14403","0.01704","168.69701"
"194.50000","3.23943","445.20023","3.16017","2.15203","0.01708","168.68240"
"195.00000","3.24802","445.40689","3.16875","2.16060","0.01713","168.76071"
"195.50000","3.25614","445.53458","3.17686","2.16871","0.01717","168.80908"
"196.00000","3.26496","445.88782","3.18565","2.17751","0.01722","168.94293"
"196.50000","3.27282","445.82877","3.19352","2.18537","0.01726","168.92055"
"197.00000","3.28145","445.94565","3.20215","2.19400","0.01731","168.96484"
"197.50000","3.28964","446.26440","3.21032","2.20217","0.01735","169.08562"
"198.00000","3.29806","446.50891","3.21872","2.21058","0.01740","169.17825"
"198.50000","3.30623","446.46597","3.22689","2.21875","0.01744","169.16199"
"199.00000","3.31452","446.78641","3.23517","2.22703","0.01749","169.28339"
"199.50000","3.32312","447.08728","3.24375","2.23560","0.01753","169.39738"
"200.00000","3.33106","447.14777","3.25168","2.24354","0.01758","169.42030"
"200.50000","3.33976","447.42114","3.26037","2.25223","0.01762","169.52390"
"201.00000","3.34781","447.53021","3.26841","2.26026","0.01767","169.56522"
"201.50000","3.35663","447.93692","3.27722","2.26907","0.01771","169.71931"
"202.00000","3.36447","447.87979","3.28506","2.27691","0.01776","169.69766"
"202.50000","3.37317","448.20276","3.29373","2.28559","0.01780","169.82004"
"203.00000","3.38129","448.31955","3.30185","2.29370","0.01785","169.86429"
"203.50000","3.38964","448.53986","3.31018","2.30204","0.01789","169.94775"
"204.00000","3.39795","448.78806","3.31848","2.31034","0.01794","170.04179"
"204.50000","3.40614","448.83746","3.32667","2.31852","0.01798","170.06052"
"205.00000","3.41483","449.21176","3.33534","2.32719","0.01803","170.20233"
"205.50000","3.42272","449.18964","3.34323","2.33508","0.01807","170.19395"
"206.00000","3.43151","449.35645","3.35201","2.34387","0.01812","170.25716"
"206.50000","3.43948","445.87323","3.36017","2.35203","0.01816","168.93739"
"207.00000","3.44838","445.03888","3.36912","2.36098","0.01821","168.62128"
"207.50000","3.45624","444.70065","3.37700","2.36886","0.01825","168.49312"
"208.00000","3.46472","444.29907","3.38551","2.37736","0.01830","168.34096"
"208.50000","3.47298","443.92404","3.39379","2.38565","0.01834","168.19887"
"209.00000","3.48119","443.62558","3.40201","2.39387","0.01839","168.08578"
"209.50000","3.48959","443.36691","3.41043","2.40229","0.01843","167.98778"
"210.00000","3.49778","442.47708","3.41867","2.41052","0.01848","167.65063"
"210.50000","3.50650","442.12555","3.42741","2.41927","0.01853","167.51744"
"211.00000","3.51446","441.52966","3.43540","2.42726","0.01857","167.29166"
"211.50000","3.52317","441.32901","3.44413","2.43598","0.01862","167.21564"
"212.00000","3.53122","440.84488","3.45220","2.44405","0.01866","167.03220"
"212.50000","3.53995","440.66821","3.46094","2.45280","0.01871","166.96526"
"213.00000","3.54783","440.35986","3.46885","2.46070","0.01875","166.84843"
"213.50000","3.55633","440.32242","3.47734","2.46920","0.01880","166.83424"
"214.00000","3.56467","440.17230","3.48570","2.47755","0.01884","166.77737"
"214.50000","3.57282","440.02231","3.49385","2.48571","0.01888","166.72054"
"215.00000","3.58135","439.80499","3.50239","2.49424","0.01893","166.63820"
"215.50000","3.58948","439.27585","3.51056","2.50241","0.01897","166.43771"
"216.00000","3.59829","438.53555","3.51941","2.51126","0.01902","166.15721"
"216.50000","3.60608","436.02859","3.52734","2.51919","0.01907","165.20735"
"217.00000","3.61491","433.20139","3.53633","2.52819","0.01911","164.13615"
"217.50000","3.62283","432.16180","3.54431","2.53617","0.01916","163.74226"
"218.00000","3.63155","431.79416","3.55305","2.54490","0.01920","163.60297"
"218.50000","3.63954","431.33609","3.56107","2.55292","0.01925","163.42940"
"219.00000","3.64794","431.16495","3.56948","2.56133","0.01929","163.36456"
"219.50000","3.65636","431.08435","3.57790","2.56975","0.01934","163.33403"
"220.00000","3.66443","430.80612","3.58599","2.57784","0.01938","163.22861"
"220.50000","3.67307","430.91992","3.59463","2.58648","0.01943","163.27173"
"221.00000","3.68112","430.87244","3.60268","2.59453","0.01947","163.25374"
"221.50000","3.68998","431.12979","3.61152","2.60338","0.01952","163.35124"
"222.00000","3.69781","431.04779","3.61935","2.61121","0.01956","163.32018"
"222.50000","3.70652","431.41852","3.62804","2.61990","0.01961","163.46063"
"223.00000","3.71456","431.34311","3.63609","2.62794","0.01965","163.43207"
"223.50000","3.72313","431.60910","3.64464","2.63650","0.01970","163.53285"
"224.00000","3.73122","431.65720","3.65273","2.64458","0.01974","163.55107"
"224.50000","3.73951","431.75336","3.66101","2.65287","0.01979","163.58751"
"225.00000","3.74807","431.95532","3.66956","2.66141","0.01983","163.66403"
"225.50000","3.75614","432.05280","3.67762","2.66948","0.01988","163.70096"
"226.00000","3.76476","432.41577","3.68623","2.67808","0.01992","163.83849"
"226.50000","3.77283","432.29401","3.69430","2.68615","0.01997","163.79236"
"227.00000","3.78162","432.71570","3.70307","2.69493","0.02002","163.95213"
"227.50000","3.78943","432.63016","3.71088","2.70274","0.02006","163.91971"
"228.00000","3.79809","432.95645","3.71953","2.71138","0.02010","164.04335"
"228.50000","3.80623","433.06494","3.72766","2.71951","0.02015","164.08446"
"229.00000","3.81472","433.33606","3.73614","2.72799","0.02019","164.18718"
"229.50000","3.82290","433.42371","3.74431","2.73617","0.02024","164.22038"
"230.00000","3.83124","433.50317","3.75264","2.74449","0.02028","164.25049"
"230.50000","3.83983","433.76639","3.76122","2.75307","0.02033","164.35022"
"231.00000","3.84773","433.86087","3.76911","2.76097","0.02037","164.38602"
"231.50000","3.85648","434.18774","3.77785","2.76970","0.02042","164.50987"
"232.00000","3.86445","434.13239","3.78581","2.77767","0.02046","164.48889"
"232.50000","3.87329","434.50162","3.79464","2.78649","0.02051","164.62880"
"233.00000","3.88113","434.28769","3.80249","2.79434","0.02055","164.54774"
"233.50000","3.88976","434.65781","3.81110","2.80295","0.02060","164.68797"
"234.00000","3.89792","434.62109","3.81926","2.81111","0.02064","164.67406"
"234.50000","3.90633","434.72717","3.82767","2.81952","0.02069","164.71425"
"235.00000","3.91465","434.82828","3.83598","2.82784","0.02073","164.75256"
"235.50000","3.92282","434.82269","3.84414","2.83600","0.02078","164.75044"
"236.00000","3.93148","435.02548","3.85280","2.84465","0.02082","164.82729"
"236.50000","3.93941","434.88461","3.86073","2.85259","0.02087","164.77391"
"237.00000","3.94813","435.15201","3.86944","2.86129","0.02091","164.87523"
"237.50000","3.95617","434.97845","3.87749","2.86935","0.02096","164.80946"
"238.00000","3.96499","435.29602","3.88629","2.87815","0.02101","164.92979"
"238.50000","3.97284","435.18054","3.89415","2.88600","0.02105","164.88603"
"239.00000","3.98134","435.28821","3.90264","2.89450","0.02109","164.92683"
"239.50000","3.98966","435.32230","3.91096","2.90281","0.02114","164.93974"
"240.00000","3.99798","435.48672","3.91927","2.91113","0.02118","165.00204"
"240.50000","4.00631","435.40289","3.92760","2.91946","0.02123","164.97028"
"241.00000","4.01449","433.73108","3.93588","2.92774","0.02127","164.33684"
"241.50000","4.02318","433.35553","3.94459","2.93644","0.02132","164.19455"
"242.00000","4.03104","433.07751","3.95247","2.94432","0.02136","164.08922"
"242.50000","4.03978","433.01950","3.96121","2.95307","0.02141","164.06723"
"243.00000","4.04782","432.82468","3.96926","2.96111","0.02145","163.99342"
"243.50000","4.05663","432.93814","3.97807","2.96992","0.02150","164.03641"
"244.00000","4.06452","432.82343","3.98597","2.97782","0.02154","163.99295"
"244.50000","4.07310","433.00314","3.99453","2.98639","0.02159","164.06104"
"245.00000","4.08137","432.94373","4.00280","2.99466","0.02164","164.03853"
"245.50000","4.08953","432.96338","4.01096","3.00281","0.02168","164.04597"
"246.00000","4.09799","433.02209","4.01943","3.01128","0.02173","164.06822"
"246.50000","4.10611","433.13034","4.02754","3.01939","0.02177","164.10924"
"247.00000","4.11487","433.23767","4.03629","3.02814","0.02182","164.14990"
"247.50000","4.12274","433.25958","4.04416","3.03601","0.02186","164.15820"
"248.00000","4.13155","433.56671","4.05295","3.04481","0.02191","164.27457"
"248.50000","4.13949","433.51111","4.06090","3.05275","0.02195","164.25349"
"249.00000","4.14827","433.77872","4.06965","3.06151","0.02200","164.35489"
"249.50000","4.15624","433.69586","4.07763","3.06949","0.02204","164.32350"
"250.00000","4.16461","433.75833","4.08600","3.07785","0.02209","164.34717"
"250.50000","4.17301","433.93076","4.09439","3.08625","0.02213","164.41251"
"251.00000","4.18112","433.91473","4.10250","3.09435","0.02217","164.40643"
"251.50000","4.18969","434.05731","4.11106","3.10292","0.02222","164.46045"
"252.00000","4.19782","434.11505","4.11919","3.11104","0.02226","164.48233"
"252.50000","4.20663","434.44946","4.12798","3.11984","0.02231","164.60904"
"253.00000","4.21448","434.34384","4.13584","3.12769","0.02235","164.56902"
"253.50000","4.22319","434.66641","4.14453","3.13638","0.02240","164.69124"
"254.00000","4.23124","434.62650","4.15258","3.14444","0.02245","164.67612"
"254.50000","4.23988","434.81741","4.16121","3.15306","0.02249","164.74844"
"255.00000","4.24791","434.80402","4.16924","3.16109","0.02254","164.74338"
"255.50000","4.25626","434.91046","4.17759","3.16944","0.02258","164.78371"
"256.00000","4.26474","435.05029","4.18605","3.17791","0.02263","164.83669"
"256.50000","4.27275","435.11032","4.19407","3.18592","0.02267","164.85942"
"257.00000","4.28138","435.26865","4.20268","3.19454","0.02272","164.91942"
"257.50000","4.28944","435.15289","4.21075","3.20261","0.02276","164.87556"
"258.00000","4.29834","435.51108","4.21963","3.21149","0.02281","165.01128"
"258.50000","4.30614","435.42664","4.22743","3.21929","0.02285","164.97928"
"259.00000","4.31492","435.63605","4.23620","3.22805","0.02290","165.05862"
"259.50000","4.32290","435.48666","4.24419","3.23605","0.02294","165.00201"
"260.00000","4.33141","435.76453","4.25269","3.24454","0.02299","165.10730"
"260.50000","4.33957","435.71863","4.26084","3.25270","0.02303","165.08990"
"261.00000","4.34789","435.73691","4.26916","3.26102","0.02308","165.09683"
"261.50000","4.35642","435.88034","4.27769","3.26955","0.02312","165.15118"
"262.00000","4.36440","435.76239","4.28567","3.27752","0.02316","165.10649"
"262.50000","4.37314","435.88345","4.29441","3.28626","0.02321","165.15236"
"263.00000","4.38111","435.85175","4.30238","3.29424","0.02325","165.14035"
"263.50000","4.39002","436.21884","4.31127","3.30312","0.02330","165.27943"
"264.00000","4.39785","435.98596","4.31911","3.31097","0.02335","165.19119"
"264.50000","4.40645","436.25595","4.32770","3.31955","0.02339","165.29350"
"265.00000","4.41457","436.18912","4.33582","3.32768","0.02344","165.26817"
"265.50000","4.42298","436.34320","4.34422","3.33608","0.02348","165.32655"
"266.00000","4.43126","436.33905","4.35251","3.34436","0.02353","165.32498"
"266.50000","4.43952","436.39737","4.36076","3.35262","0.02357","165.34708"
"267.00000","4.44816","436.55051","4.36939","3.36125","0.02362","165.40511"
"267.50000","4.45613","436.40518","4.37737","3.36923","0.02366","165.35004"
"268.00000","4.46482","436.73026","4.38604","3.37790","0.02371","165.47321"
"268.50000","4.47287","436.56485","4.39410","3.38596","0.02375","165.41054"
"269.00000","4.48164","436.73450","4.40286","3.39471","0.02380","165.47481"
"269.50000","4.48951","436.56253","4.41074","3.40259","0.02384","165.40965"
"270.00000","4.49803","436.77927","4.41925","3.41111","0.02389","165.49178"
"270.50000","4.50630","436.59961","4.42752","3.41938","0.02393","165.42371"
"271.00000","4.51460","436.70856","4.43582","3.42768","0.02398","165.46498"
"271.50000","4.52296","436.81509","4.44418","3.43603","0.02402","165.50536"
"272.00000","4.53117","436.66385","4.45240","3.44425","0.02407","165.44804"
"272.50000","4.53988","436.87582","4.46109","3.45294","0.02411","165.52837"
"273.00000","4.54777","436.78717","4.46898","3.46084","0.02416","165.49477"
"273.50000","4.55654","436.82480","4.47775","3.46961","0.02420","165.50903"
"274.00000","4.56451","436.74866","4.48572","3.47758","0.02425","165.48018"
"274.50000","4.57326","436.95367","4.49447","3.48632","0.02429","165.55786"
"275.00000","4.58118","436.81757","4.50239","3.49424","0.02434","165.50629"
"275.50000","4.58973","437.03458","4.51094","3.50279","0.02438","165.58852"
"276.00000","4.59798","436.84113","4.51919","3.51104","0.02443","165.51521"
"276.50000","4.60617","436.85162","4.52738","3.51924","0.02447","165.51920"
"277.00000","4.61468","436.93130","4.53589","3.52775","0.02452","165.54938"
"277.50000","4.62280","436.70428","4.54402","3.53588","0.02456","165.46336"
"278.00000","4.63153","437.04532","4.55273","3.54458","0.02461","165.59258"
"278.50000","4.63943","436.91245","4.56064","3.55249","0.02465","165.54224"
"279.00000","4.64815","437.15335","4.56935","3.56120","0.02470","165.63351"
"279.50000","4.65616","436.98581","4.57736","3.56922","0.02474","165.57004"
"280.00000","4.66494","437.15671","4.58614","3.57799","0.02479","165.63478"
"280.50000","4.67289","436.94498","4.59410","3.58595","0.02483","165.55457"
"281.00000","4.68130","437.09082","4.60250","3.59435","0.02488","165.60982"
"281.50000","4.68972","437.06284","4.61092","3.60277","0.02492","165.59921"
"282.00000","4.69787","437.03864","4.61907","3.61092","0.02497","165.59004"
"282.50000","4.70636","437.18625","4.62756","3.61941","0.02501","165.64598"
"283.00000","4.71454","437.02689","4.63574","3.62760","0.02506","165.58560"
"283.50000","4.72323","437.09958","4.64442","3.63628","0.02510","165.61314"
"284.00000","4.73109","437.12650","4.65229","3.64414","0.02515","165.62334"
"284.50000","4.73976","437.15411","4.66096","3.65281","0.02519","165.63380"
"285.00000","4.74787","436.98462","4.66908","3.66093","0.02524","165.56958"
"285.50000","4.75656","437.19113","4.67775","3.66961","0.02528","165.64783"
"286.00000","4.76455","436.98596","4.68576","3.67761","0.02533","165.57008"
"286.50000","4.77297","436.95328","4.69418","3.68603","0.02537","165.55771"
"287.00000","4.78140","436.98334","4.70260","3.69446","0.02542","165.56909"
"287.50000","4.78949","436.97195","4.71070","3.70255","0.02546","165.56479"
"288.00000","4.79804","437.00864","4.71924","3.71109","0.02551","165.57869"
"288.50000","4.80615","436.88599","4.72736","3.71921","0.02555","165.53221"
"289.00000","4.81488","437.13812","4.73608","3.72793","0.02560","165.62775"
"289.50000","4.82277","436.91156","4.74398","3.73583","0.02564","165.54190"
"290.00000","4.83156","436.82080","4.75278","3.74463","0.02569","165.50751"
"290.50000","4.83956","436.66931","4.76078","3.75264","0.02573","165.45012"
"291.00000","4.84815","436.88367","4.76936","3.76122","0.02578","165.53133"
"291.50000","4.85625","436.72888","4.77747","3.76932","0.02582","165.47269"
"292.00000","4.86456","436.66772","4.78578","3.77763","0.02587","165.44951"
"292.50000","4.87304","436.75293","4.79426","3.78611","0.02591","165.48180"
"293.00000","4.88108","436.50729","4.80232","3.79417","0.02596","165.38873"
"293.50000","4.88975","436.58893","4.81097","3.80283","0.02600","165.41966"
"294.00000","4.89779","436.33176","4.81903","3.81088","0.02605","165.32222"
"294.50000","4.90667","436.52625","4.82790","3.81975","0.02610","165.39590"
"295.00000","4.91450","436.35486","4.83574","3.82759","0.02614","165.33098"
"295.50000","4.92311","436.41898","4.84435","3.83621","0.02618","165.35527"
"296.00000","4.93126","436.27563","4.85250","3.84436","0.02623","165.30095"
"296.50000","4.93976","436.39005","4.86100","3.85285","0.02627","165.34430"
"297.00000","4.94791","436.16602","4.86916","3.86102","0.02632","165.25941"
"297.50000","4.95625","436.26773","4.87750","3.86935","0.02636","165.29796"
"298.00000","4.96477","436.19604","4.88602","3.87788","0.02641","165.27080"
"298.50000","4.97272","435.36383","4.89402","3.88587","0.02645","164.95547"
"299.00000","4.98137","435.28812","4.90267","3.89452","0.02650","164.92679"
"299.50000","4.98950","434.97620","4.91082","3.90268","0.02654","164.80861"
"300.00000","4.99834","435.14191","4.91964","3.91150","0.02659","164.87140"
"300.50000","5.00616","434.67609","4.92749","3.91935","0.02663","164.69490"
"301.00000","5.01484","432.67816","4.93629","3.92814","0.02668","163.93790"
"301.50000","5.02295","431.95416","4.94444","3.93629","0.02673","163.66359"
"302.00000","5.03135","431.91211","4.95284","3.94470","0.02677","163.64766"
"302.50000","5.03958","431.62027","4.96109","3.95294","0.02682","163.53708"
"303.00000","5.04787","431.44659","4.96939","3.96124","0.02686","163.47127"
"303.50000","5.05648","431.35422","4.97801","3.96986","0.02691","163.43628"
"304.00000","5.06443","431.18411","4.98596","3.97782","0.02695","163.37183"
"304.50000","5.07321","431.33530","4.99474","3.98659","0.02700","163.42911"
"305.00000","5.08114","431.02283","5.00268","3.99454","0.02704","163.31071"
"305.50000","5.08999","431.36575","5.01152","4.00337","0.02709","163.44064"
"306.00000","5.09783","430.94388","5.01938","4.01123","0.02713","163.28079"
"306.50000","5.10641","430.96896","5.02796","4.01981","0.02718","163.29030"
"307.00000","5.11458","430.97046","5.03613","4.02798","0.02722","163.29086"
"307.50000","5.12290","430.99463","5.04444","4.03630","0.02727","163.30003"
"308.00000","5.13130","430.98898","5.05285","4.04470","0.02731","163.29788"
"308.50000","5.13945","430.85605","5.06100","4.05286","0.02736","163.24753"
"309.00000","5.14817","430.79694","5.06972","4.06158","0.02740","163.22513"
"309.50000","5.15611","430.62152","5.07768","4.06953","0.02745","163.15866"
"310.00000","5.16481","430.81973","5.08637","4.07822","0.02749","163.23376"
"310.50000","5.17284","430.43826","5.09442","4.08627","0.02754","163.08923"
"311.00000","5.18165","430.61859","5.10322","4.09507","0.02758","163.15755"
"311.50000","5.18953","430.38974","5.11111","4.10297","0.02763","163.07085"
"312.00000","5.19805","430.52560","5.11962","4.11148","0.02767","163.12231"
"312.50000","5.20638","430.36389","5.12796","4.11981","0.02772","163.06105"
"313.00000","5.21452","430.21747","5.13611","4.12796","0.02776","163.00557"
"313.50000","5.22297","430.27649","5.14456","4.13641","0.02781","163.02794"
"314.00000","5.23117","430.03470","5.15277","4.14463","0.02785","162.93633"
"314.50000","5.23989","430.08624","5.16149","4.15335","0.02790","162.95586"
"315.00000","5.24777","429.80188","5.16938","4.16123","0.02794","162.84811"
"315.50000","5.25653","429.73895","5.17814","4.17000","0.02799","162.82426"
"316.00000","5.26451","429.23135","5.18616","4.17801","0.02803","162.63194"
"316.50000","5.27324","428.82697","5.19490","4.18676","0.02808","162.47871"
"317.00000","5.28116","427.59204","5.20290","4.19475","0.02812","162.01082"
"317.50000","5.28966","425.81238","5.21150","4.20336","0.02817","161.33652"
"318.00000","5.29804","418.28897","5.22031","4.21216","0.02822","158.48596"
"318.50000","5.30614","407.62894","5.22902","4.22087","0.02826","154.44698"
"319.00000","5.31473","406.42606","5.23768","4.22953","0.02831","153.99121"
"319.50000","5.32281","405.87335","5.24579","4.23764","0.02835","153.78180"
"320.00000","5.33166","405.86279","5.25464","4.24649","0.02840","153.77780"
"320.50000","5.33945","405.70184","5.26243","4.25429","0.02844","153.71681"
"321.00000","5.34819","406.09302","5.27115","4.26301","0.02849","153.86504"
"321.50000","5.35616","405.95474","5.27913","4.27098","0.02853","153.81264"
"322.00000","5.36485","406.30774","5.28780","4.27966","0.02858","153.94638"
"322.50000","5.37291","406.42285","5.29586","4.28771","0.02862","153.99001"
"323.00000","5.38122","406.48068","5.30416","4.29602","0.02867","154.01192"
"323.22500","5.38497","406.55722","5.30791","4.29976","0.02869","154.04091"