File: flexion/5_axis/Specimen_RawData_5.csv
Specimen properties : Specimen label,"5"
Specimen properties : Support span,"72.00",mm
Specimen properties : Thickness,"4.40",mm
Specimen properties : Width,"14.00",mm
Maximum Load : Maximum Load,"732.8",N
Tangent Modulus of Elasticity : Tangent Modulus of Elasticity,"38778543545.32510",Pa
Test : Rate 1,"1.00000",mm/min
Specimen notes : Specimen note 1,""

Time,Displacement,Load,Flexure extension,Corrected extension,Flexure strain (Corrected extension),Flexure stress
(s),(mm),(N),(mm),(mm),(mm/mm),(MPa)
"0.00000","0.00000","7.81793","0.00454","-1.04595","0.00002","3.11517"
"0.60000","0.00818","11.02042","0.01112","-1.03937","0.00006","4.39125"
"1.20000","0.01833","15.20876","0.01946","-1.03103","0.00010","6.06016"
"1.80000","0.02849","19.05609","0.02870","-1.02179","0.00015","7.59319"
"2.40000","0.03813","22.77915","0.03755","-1.01293","0.00019","9.07670"
"3.00000","0.04823","26.62779","0.04684","-1.00365","0.00024","10.61025"
"3.60000","0.05845","30.70522","0.05620","-0.99429","0.00029","12.23496"
"4.20000","0.06865","34.92157","0.06551","-0.98498","0.00033","13.91503"
"4.80000","0.07811","38.72541","0.07441","-0.97608","0.00038","15.43073"
"5.40000","0.08819","43.07359","0.08391","-0.96658","0.00043","17.16333"
"6.00000","0.09835","47.52096","0.09347","-0.95701","0.00048","18.93545"
"6.60000","0.10842","51.97977","0.10294","-0.94755","0.00052","20.71213"
"7.20000","0.11816","56.20118","0.11211","-0.93838","0.00057","22.39421"
"7.80000","0.12826","60.74129","0.12167","-0.92882","0.00062","24.20329"
"8.40000","0.13856","65.42915","0.13141","-0.91908","0.00067","26.07124"
"9.00000","0.14849","69.92622","0.14082","-0.90967","0.00072","27.86316"
"9.60000","0.15808","74.38281","0.14989","-0.90060","0.00076","29.63896"
"10.20000","0.16822","79.06924","0.15947","-0.89102","0.00081","31.50634"
"10.80000","0.17852","83.97784","0.16920","-0.88128","0.00086","33.46224"
"11.40000","0.18841","88.66010","0.17857","-0.87192","0.00091","35.32796"
"12.00000","0.19813","93.28950","0.18784","-0.86265","0.00096","37.17262"
"12.60000","0.20831","97.98256","0.19756","-0.85293","0.00101","39.04264"
"13.20000","0.21864","102.96432","0.20740","-0.84309","0.00106","41.02769"
"13.80000","0.22832","107.64521","0.21662","-0.83387","0.00110","42.89286"
"14.40000","0.23814","112.23775","0.22600","-0.82449","0.00115","44.72283"
"15.00000","0.24832","117.13394","0.23570","-0.81479","0.00120","46.67379"
"15.60000","0.25851","121.97057","0.24541","-0.80507","0.00125","48.60102"
"16.20000","0.26825","126.65366","0.25470","-0.79579","0.00130","50.46707"
"16.80000","0.27818","131.40675","0.26416","-0.78632","0.00135","52.36101"
"17.40000","0.28840","136.20854","0.27392","-0.77657","0.00139","54.27436"
"18.00000","0.29863","141.15494","0.28367","-0.76682","0.00144","56.24532"
"18.60000","0.30825","145.71387","0.29284","-0.75764","0.00149","58.06190"
"19.20000","0.31814","150.50844","0.30227","-0.74822","0.00154","59.97237"
"19.80000","0.32832","155.26031","0.31198","-0.73850","0.00159","61.86583"
"20.40000","0.33852","160.17279","0.32174","-0.72875","0.00164","63.82328"
"21.00000","0.34823","164.71278","0.33106","-0.71943","0.00169","65.63230"
"21.60000","0.35818","169.59058","0.34060","-0.70989","0.00173","67.57594"
"22.20000","0.36848","174.48779","0.35048","-0.70000","0.00178","69.52731"
"22.80000","0.37863","179.38591","0.36021","-0.69027","0.00183","71.47903"
"23.40000","0.38810","183.83803","0.36930","-0.68119","0.00188","73.25305"
"24.00000","0.39815","188.63896","0.37895","-0.67154","0.00193","75.16605"
"24.60000","0.40840","193.53136","0.38878","-0.66171","0.00198","77.11550"
"25.20000","0.41853","198.42163","0.39849","-0.65200","0.00203","79.06411"
"25.80000","0.42817","203.01022","0.40775","-0.64273","0.00208","80.89250"
"26.40000","0.43825","207.73161","0.41746","-0.63303","0.00213","82.77381"
"27.00000","0.44851","212.70444","0.42733","-0.62316","0.00218","84.75531"
"27.60000","0.45856","217.46582","0.43699","-0.61350","0.00223","86.65255"
"28.20000","0.46809","221.82355","0.44617","-0.60432","0.00227","88.38895"
"28.80000","0.47823","226.69608","0.45592","-0.59456","0.00232","90.33049"
"29.40000","0.48848","231.62265","0.46577","-0.58471","0.00237","92.29356"
"30.00000","0.49838","236.26601","0.47531","-0.57518","0.00242","94.14377"
"30.60000","0.50817","240.84758","0.48473","-0.56576","0.00247","95.96937"
"31.20000","0.51836","245.63406","0.49454","-0.55595","0.00252","97.87662"
"31.80000","0.52859","250.48048","0.50440","-0.54609","0.00257","99.80775"
"32.40000","0.53837","255.02083","0.51383","-0.53666","0.00262","101.61691"
"33.00000","0.54813","259.53088","0.52325","-0.52724","0.00266","103.41402"
"33.60000","0.55828","264.25198","0.53303","-0.51745","0.00271","105.29520"
"34.20000","0.56842","269.10886","0.54280","-0.50768","0.00276","107.23050"
"34.80000","0.57831","273.76434","0.55233","-0.49816","0.00281","109.08555"
"35.40000","0.58820","278.22476","0.56188","-0.48861","0.00286","110.86288"
"36.00000","0.59836","283.01993","0.57168","-0.47881","0.00291","112.77358"
"36.60000","0.60870","287.83328","0.58164","-0.46884","0.00296","114.69154"
"37.20000","0.61825","292.33627","0.59087","-0.45962","0.00301","116.48582"
"37.80000","0.62810","296.78409","0.60042","-0.45007","0.00306","118.25812"
"38.40000","0.63829","301.57742","0.61029","-0.44020","0.00311","120.16810"
"39.00000","0.64860","306.35303","0.62028","-0.43020","0.00316","122.07101"
"39.60000","0.65819","310.81097","0.62957","-0.42092","0.00321","123.84734"
"40.20000","0.66819","315.35919","0.63927","-0.41122","0.00326","125.65965"
"40.80000","0.67848","320.37997","0.64922","-0.40126","0.00331","127.66026"
"41.40000","0.68863","324.87491","0.65907","-0.39141","0.00336","129.45132"
"42.00000","0.69811","329.17923","0.66826","-0.38223","0.00340","131.16646"
"42.60000","0.70821","333.89597","0.67805","-0.37244","0.00345","133.04591"
"43.20000","0.71837","338.48471","0.68790","-0.36259","0.00350","134.87436"
"43.80000","0.72849","343.18265","0.69771","-0.35277","0.00355","136.74632"
"44.40000","0.73819","347.47748","0.70714","-0.34335","0.00360","138.45767"
"45.00000","0.74827","352.06784","0.71692","-0.33357","0.00365","140.28677"
"45.60000","0.75855","356.80310","0.72689","-0.32359","0.00370","142.17360"
"46.20000","0.76858","361.42929","0.73663","-0.31386","0.00375","144.01698"
"46.80000","0.77810","365.71835","0.74588","-0.30461","0.00380","145.72601"
"47.40000","0.78821","370.21255","0.75570","-0.29479","0.00385","147.51680"
"48.00000","0.79845","374.85574","0.76564","-0.28484","0.00390","149.36696"
"48.60000","0.80836","379.28250","0.77527","-0.27522","0.00395","151.13086"
"49.20000","0.81818","383.53549","0.78481","-0.26568","0.00400","152.82553"
"49.80000","0.82834","388.11160","0.79468","-0.25581","0.00405","154.64896"
"50.40000","0.83863","392.80429","0.80469","-0.24580","0.00410","156.51883"
"51.00000","0.84837","397.19479","0.81418","-0.23630","0.00415","158.26828"
"51.60000","0.85814","401.50467","0.82371","-0.22678","0.00419","159.98563"
"52.20000","0.86822","405.84152","0.83354","-0.21694","0.00424","161.71370"
"52.80000","0.87850","410.57025","0.84355","-0.20694","0.00430","163.59795"
"53.40000","0.88830","414.70322","0.85312","-0.19737","0.00434","165.24478"
"54.00000","0.89813","419.16422","0.86270","-0.18779","0.00439","167.02234"
"54.60000","0.90838","423.50226","0.87269","-0.17780","0.00444","168.75090"
"55.20000","0.91873","428.13550","0.88278","-0.16770","0.00450","170.59708"
"55.80000","0.92824","432.39520","0.89205","-0.15844","0.00454","172.29442"
"56.40000","0.93813","436.53305","0.90170","-0.14879","0.00459","173.94321"
"57.00000","0.94833","441.10477","0.91165","-0.13884","0.00464","175.76488"
"57.60000","0.95854","445.46249","0.92160","-0.12889","0.00469","177.50128"
"58.20000","0.96818","449.52603","0.93101","-0.11948","0.00474","179.12045"
"58.80000","0.97820","453.76459","0.94079","-0.10970","0.00479","180.80937"
"59.40000","0.98844","458.27563","0.95078","-0.09971","0.00484","182.60687"
"60.00000","0.99868","462.66516","0.96076","-0.08973","0.00489","184.35594"
"60.60000","1.00819","466.53625","0.97006","-0.08043","0.00494","185.89844"
"61.20000","1.01817","470.79190","0.97979","-0.07070","0.00499","187.59416"
"61.80000","1.02830","475.12668","0.98967","-0.06082","0.00504","189.32143"
"62.40000","1.03847","479.47577","0.99960","-0.05089","0.00509","191.05438"
"63.00000","1.04819","483.47321","1.00908","-0.04140","0.00514","192.64723"
"63.60000","1.05825","487.73898","1.01890","-0.03159","0.00519","194.34698"
"64.20000","1.06852","491.98334","1.02894","-0.02154","0.00524","196.03822"
"64.80000","1.07857","496.12326","1.03879","-0.01170","0.00529","197.68784"
"65.40000","1.08808","499.94937","1.04811","-0.00238","0.00534","199.21240"
"66.00000","1.09822","504.19662","1.05803","0.00755","0.00539","200.90479"
"66.60000","1.10845","508.35736","1.06805","0.01757","0.00544","202.56270"
"67.20000","1.11842","512.42963","1.07782","0.02733","0.00549","204.18535"
"67.80000","1.12811","516.43567","1.08732","0.03683","0.00554","205.78162"
"68.40000","1.13830","520.42419","1.09730","0.04681","0.00559","207.37091"
"69.00000","1.14857","524.64484","1.10737","0.05688","0.00564","209.05269"
"69.60000","1.15837","528.39813","1.11698","0.06649","0.00569","210.54825"
"70.20000","1.16810","532.16278","1.12652","0.07603","0.00574","212.04832"
"70.80000","1.17829","536.30090","1.13649","0.08600","0.00579","213.69722"
"71.40000","1.18852","540.51099","1.14652","0.09603","0.00584","215.37480"
"72.00000","1.19828","544.29181","1.15609","0.10560","0.00589","216.88132"
"72.60000","1.20813","548.12708","1.16575","0.11527","0.00594","218.40955"
"73.20000","1.21835","552.11322","1.17578","0.12529","0.00599","219.99788"
"73.80000","1.22869","556.19574","1.18593","0.13544","0.00604","221.62462"
"74.40000","1.23827","559.82697","1.19533","0.14484","0.00609","223.07153"
"75.00000","1.24816","563.63165","1.20504","0.15455","0.00614","224.58757"
"75.60000","1.25829","567.51746","1.21498","0.16449","0.00619","226.13593"
"76.20000","1.26846","571.45294","1.22496","0.17447","0.00624","227.70409"
"76.80000","1.27818","575.17615","1.23450","0.18401","0.00629","229.18765"
"77.40000","1.28823","579.00165","1.24436","0.19387","0.00634","230.71198"
"78.00000","1.29843","582.89752","1.25437","0.20388","0.00639","232.26436"
"78.60000","1.30870","586.79907","1.26446","0.21397","0.00644","233.81898"
"79.20000","1.31817","590.30908","1.27376","0.22327","0.00649","235.21761"
"79.80000","1.32815","593.94318","1.28357","0.23309","0.00654","236.66566"
"80.40000","1.33832","597.74268","1.29358","0.24309","0.00659","238.17963"
"81.00000","1.34857","601.47089","1.30366","0.25317","0.00664","239.66519"
"81.60000","1.35819","604.91461","1.31312","0.26263","0.00669","241.03740"
"82.20000","1.36824","608.48041","1.32300","0.27252","0.00674","242.45824"
"82.80000","1.37851","612.20337","1.33311","0.28262","0.00679","243.94171"
"83.40000","1.38860","615.97681","1.34303","0.29255","0.00684","245.44530"
"84.00000","1.39809","619.15991","1.35238","0.30190","0.00689","246.71365"
"84.60000","1.40823","622.74402","1.36236","0.31187","0.00694","248.14180"
"85.20000","1.41845","626.29913","1.37242","0.32193","0.00699","249.55838"
"85.80000","1.42840","629.59906","1.38222","0.33173","0.00704","250.87329"
"86.40000","1.43813","632.20062","1.39184","0.34135","0.00709","251.90991"
"87.00000","1.44828","635.52399","1.40184","0.35135","0.00714","253.23416"
"87.60000","1.45856","638.64716","1.41198","0.36149","0.00719","254.47864"
"88.20000","1.46844","641.40350","1.42173","0.37124","0.00724","255.57695"
"88.80000","1.47810","644.39105","1.43126","0.38077","0.00729","256.76740"
"89.40000","1.48822","647.62982","1.44123","0.39075","0.00734","258.05792"
"90.00000","1.49853","650.69202","1.45140","0.40092","0.00739","259.27811"
"90.60000","1.50836","653.13995","1.46112","0.41064","0.00744","260.25351"
"91.20000","1.51816","655.24744","1.47083","0.42035","0.00749","261.09326"
"91.80000","1.52840","657.57947","1.48097","0.43048","0.00754","262.02249"
"92.40000","1.53862","660.12433","1.49108","0.44059","0.00759","263.03653"
"93.00000","1.54827","661.98773","1.50065","0.45016","0.00764","263.77905"
"93.60000","1.55812","663.30267","1.51043","0.45995","0.00769","264.30301"
"94.20000","1.56829","664.15045","1.52057","0.47008","0.00774","264.64081"
"94.80000","1.57851","663.64130","1.53082","0.48033","0.00780","264.43793"
"95.40000","1.58826","660.03558","1.54073","0.49024","0.00785","263.00119"
"96.00000","1.59819","657.32452","1.55077","0.50028","0.00790","261.92093"
"96.60000","1.60842","649.20557","1.56136","0.51087","0.00795","258.68579"
"97.20000","1.61864","645.43811","1.57175","0.52126","0.00800","257.18460"
"97.80000","1.62816","643.11523","1.58138","0.53089","0.00805","256.25900"
"98.40000","1.63814","641.53192","1.59143","0.54094","0.00810","255.62811"
"99.00000","1.64837","641.63269","1.60166","0.55117","0.00816","255.66827"
"99.60000","1.65855","642.73889","1.61178","0.56129","0.00821","256.10904"
"100.20000","1.66814","643.79706","1.62133","0.57084","0.00826","256.53070"
"100.80000","1.67822","645.44769","1.63133","0.58084","0.00831","257.18842"
"101.40000","1.68849","647.42944","1.64151","0.59102","0.00836","257.97809"
"102.00000","1.69858","649.45685","1.65152","0.60103","0.00841","258.78592"
"102.60000","1.70812","651.14465","1.66098","0.61049","0.00846","259.45847"
"103.20000","1.71823","653.10065","1.67100","0.62051","0.00851","260.23785"
"103.80000","1.72835","655.40820","1.68102","0.63053","0.00856","261.15732"
"104.40000","1.73839","657.40875","1.69097","0.64048","0.00861","261.95447"
"105.00000","1.74821","659.39056","1.70070","0.65021","0.00866","262.74417"
"105.60000","1.75833","660.90955","1.71076","0.66027","0.00871","263.34943"
"106.20000","1.76862","662.63452","1.72097","0.67048","0.00876","264.03677"
"106.80000","1.77851","664.21936","1.73079","0.68030","0.00881","264.66827"
"107.40000","1.78804","665.57434","1.74025","0.68977","0.00886","265.20819"
"108.00000","1.79823","667.16479","1.75038","0.69989","0.00891","265.84192"
"108.60000","1.80849","668.67834","1.76057","0.71008","0.00897","266.44501"
"109.20000","1.81835","669.81183","1.77038","0.71989","0.00902","266.89667"
"109.80000","1.82814","670.87347","1.78012","0.72963","0.00907","267.31970"
"110.40000","1.83838","672.48602","1.79028","0.73979","0.00912","267.96225"
"111.00000","1.84860","674.03021","1.80044","0.74995","0.00917","268.57755"
"111.60000","1.85829","675.20087","1.81008","0.75959","0.00922","269.04401"
"112.20000","1.86807","676.44470","1.81980","0.76932","0.00927","269.53964"
"112.80000","1.87828","677.94855","1.82994","0.77945","0.00932","270.13889"
"113.40000","1.88858","679.63245","1.84017","0.78968","0.00937","270.80984"
"114.00000","1.89824","680.82556","1.84978","0.79929","0.00942","271.28528"
"114.60000","1.90814","682.13275","1.85962","0.80913","0.00947","271.80612"
"115.20000","1.91840","683.42627","1.86982","0.81933","0.00952","272.32156"
"115.80000","1.92873","685.01917","1.88008","0.82959","0.00957","272.95627"
"116.40000","1.93816","686.10150","1.88946","0.83897","0.00962","273.38754"
"117.00000","1.94818","687.36658","1.89942","0.84894","0.00967","273.89163"
"117.60000","1.95832","688.46338","1.90952","0.85903","0.00972","274.32867"
"118.20000","1.96844","689.83856","1.91958","0.86909","0.00978","274.87662"
"118.80000","1.97813","690.85181","1.92922","0.87873","0.00982","275.28036"
"119.40000","1.98825","692.09564","1.93929","0.88880","0.00988","275.77600"
"120.00000","1.99848","693.53986","1.94945","0.89896","0.00993","276.35147"
"120.60000","2.00865","693.71655","1.95961","0.90912","0.00998","276.42188"
"121.20000","2.01814","694.17743","1.96908","0.91859","0.01003","276.60553"
"121.80000","2.02816","695.13287","1.97906","0.92857","0.01008","276.98624"
"122.40000","2.03839","696.17731","1.98924","0.93875","0.01013","277.40240"
"123.00000","2.04849","697.24384","1.99929","0.94880","0.01018","277.82736"
"123.60000","2.05815","697.95728","2.00892","0.95844","0.01023","278.11166"
"124.20000","2.06829","699.09369","2.01901","0.96853","0.01028","278.56448"
"124.80000","2.07860","700.27783","2.02927","0.97878","0.01033","279.03632"
"125.40000","2.08847","701.25128","2.03909","0.98860","0.01038","279.42419"
"126.00000","2.09810","701.94891","2.04870","0.99821","0.01043","279.70218"
"126.60000","2.10823","703.04413","2.05878","1.00829","0.01048","280.13858"
"127.20000","2.11848","704.08258","2.06898","1.01849","0.01054","280.55237"
"127.80000","2.12834","704.82617","2.07881","1.02832","0.01059","280.84866"
"128.40000","2.13812","705.46930","2.08856","1.03807","0.01064","281.10492"
"129.00000","2.14829","706.31091","2.09869","1.04820","0.01069","281.44028"
"129.60000","2.15868","707.29913","2.10903","1.05854","0.01074","281.83405"
"130.20000","2.16834","707.62408","2.11868","1.06819","0.01079","281.96353"
"130.80000","2.17813","707.62097","2.12847","1.07798","0.01084","281.96231"
"131.40000","2.18827","708.17944","2.13859","1.08810","0.01089","282.18484"
"132.00000","2.19852","708.76654","2.14880","1.09832","0.01094","282.41876"
"132.60000","2.20821","709.08966","2.15849","1.10800","0.01099","282.54752"
"133.20000","2.21819","709.46558","2.16845","1.11796","0.01104","282.69730"
"133.80000","2.22840","710.02875","2.17863","1.12814","0.01109","282.92172"
"134.40000","2.23865","710.46918","2.18886","1.13837","0.01115","283.09720"
"135.00000","2.24819","710.64111","2.19840","1.14791","0.01120","283.16571"
"135.60000","2.25816","710.87982","2.20836","1.15787","0.01125","283.26083"
"136.20000","2.26830","711.19604","2.21848","1.16799","0.01130","283.38684"
"136.80000","2.27848","711.87189","2.22863","1.17814","0.01135","283.65613"
"137.40000","2.28820","711.79840","2.23835","1.18786","0.01140","283.62686"
"138.00000","2.29822","712.25946","2.24835","1.19787","0.01145","283.81058"
"138.60000","2.30849","712.75330","2.25860","1.20811","0.01150","284.00735"
"139.20000","2.31860","713.09869","2.26870","1.21821","0.01155","284.14499"
"139.80000","2.32811","713.28070","2.27819","1.22771","0.01160","284.21750"
"140.40000","2.33820","713.61829","2.28827","1.23778","0.01165","284.35202"
"141.00000","2.34841","714.06128","2.29846","1.24797","0.01171","284.52853"
"141.60000","2.35851","714.37823","2.30855","1.25806","0.01176","284.65485"
"142.20000","2.36812","714.52850","2.31815","1.26767","0.01181","284.71472"
"142.80000","2.37826","714.87103","2.32827","1.27778","0.01186","284.85120"
"143.40000","2.38854","715.18927","2.33854","1.28806","0.01191","284.97800"
"144.00000","2.39850","715.30212","2.34850","1.29801","0.01196","285.02298"
"144.60000","2.40811","715.25745","2.35810","1.30762","0.01201","285.00516"
"145.20000","2.41829","715.49066","2.36828","1.31779","0.01206","285.09808"
"145.80000","2.42846","715.71759","2.37843","1.32795","0.01211","285.18851"
"146.40000","2.43835","715.67548","2.38833","1.33784","0.01216","285.17175"
"147.00000","2.44816","715.40839","2.39815","1.34766","0.01221","285.06531"
"147.60000","2.45834","715.45319","2.40833","1.35784","0.01226","285.08316"
"148.20000","2.46859","715.59723","2.41857","1.36809","0.01232","285.14056"
"148.80000","2.47842","715.49225","2.42841","1.37792","0.01237","285.09872"
"149.40000","2.48809","715.29614","2.43809","1.38760","0.01242","285.02060"
"150.00000","2.49829","715.63538","2.44827","1.39778","0.01247","285.15576"
"150.60000","2.50851","715.83429","2.45848","1.40799","0.01252","285.23502"
"151.20000","2.51828","715.85132","2.46825","1.41776","0.01257","285.24182"
"151.80000","2.52815","715.84064","2.47812","1.42763","0.01262","285.23755"
"152.40000","2.53841","715.86676","2.48838","1.43789","0.01267","285.24796"
"153.00000","2.54865","716.16229","2.49861","1.44812","0.01272","285.36572"
"153.60000","2.55818","715.98547","2.50815","1.45766","0.01277","285.29526"
"154.20000","2.56813","716.03442","2.51809","1.46760","0.01282","285.31476"
"154.80000","2.57832","716.21027","2.52827","1.47778","0.01288","285.38483"
"155.40000","2.58859","716.61798","2.53853","1.48804","0.01293","285.54730"
"156.00000","2.59821","716.34906","2.54816","1.49767","0.01298","285.44016"
"156.60000","2.60820","716.35840","2.55815","1.50766","0.01303","285.44385"
"157.20000","2.61846","716.52948","2.56840","1.51791","0.01308","285.51202"
"157.80000","2.62868","716.70288","2.57861","1.52812","0.01313","285.58112"
"158.40000","2.63809","716.41669","2.58804","1.53755","0.01318","285.46710"
"159.00000","2.64820","716.35638","2.59815","1.54766","0.01323","285.44305"
"159.60000","2.65842","716.50574","2.60837","1.55788","0.01328","285.50256"
"160.20000","2.66849","716.42615","2.61844","1.56795","0.01333","285.47086"
"160.80000","2.67817","716.02820","2.62813","1.57764","0.01338","285.31229"
"161.40000","2.68827","716.10327","2.63823","1.58774","0.01344","285.34219"
"162.00000","2.69852","716.01532","2.64849","1.59800","0.01349","285.30716"
"162.60000","2.70853","715.90967","2.65850","1.60801","0.01354","285.26505"
"163.20000","2.71812","715.41150","2.66811","1.61763","0.01359","285.06656"
"163.80000","2.72823","715.18927","2.67823","1.62774","0.01364","284.97800"
"164.40000","2.73840","715.02051","2.68841","1.63792","0.01369","284.91077"
"165.00000","2.74841","714.71094","2.69843","1.64794","0.01374","284.78741"
"165.60000","2.75818","714.58972","2.70821","1.65772","0.01379","284.73911"
"166.20000","2.76830","714.51794","2.71834","1.66785","0.01384","284.71051"
"166.80000","2.77865","714.64886","2.72868","1.67819","0.01390","284.76266"
"167.40000","2.78840","714.40527","2.73843","1.68794","0.01395","284.66562"
"168.00000","2.79806","714.08594","2.74811","1.69762","0.01399","284.53836"
"168.60000","2.80825","714.05682","2.75831","1.70782","0.01405","284.52676"
"169.20000","2.81860","713.93524","2.76866","1.71817","0.01410","284.47833"
"169.80000","2.82830","713.53845","2.77837","1.72789","0.01415","284.32022"
"170.40000","2.83815","713.33789","2.78823","1.73775","0.01420","284.24030"
"171.00000","2.84838","713.21924","2.79847","1.74798","0.01425","284.19302"
"171.60000","2.85864","713.64594","2.80871","1.75822","0.01430","284.36304"
"172.20000","2.86820","713.51721","2.81828","1.76779","0.01435","284.31174"
"172.80000","2.87816","713.46674","2.82824","1.77775","0.01440","284.29163"
"173.40000","2.88832","713.72052","2.83839","1.78790","0.01445","284.39276"
"174.00000","2.89855","714.17206","2.84860","1.79811","0.01451","284.57269"
"174.60000","2.90824","714.20074","2.85828","1.80779","0.01456","284.58411"
"175.20000","2.91822","714.54242","2.86825","1.81776","0.01461","284.72025"
"175.80000","2.92847","715.04987","2.87848","1.82799","0.01466","284.92245"
"176.40000","2.93865","715.55035","2.88864","1.83815","0.01471","285.12189"
"177.00000","2.94812","715.61536","2.89811","1.84762","0.01476","285.14780"
"177.60000","2.95819","715.96997","2.90815","1.85766","0.01481","285.28909"
"178.20000","2.96841","716.68427","2.91834","1.86785","0.01486","285.57370"
"178.80000","2.97845","716.88702","2.92837","1.87788","0.01491","285.65451"
"179.40000","2.98818","717.11365","2.93810","1.88761","0.01496","285.74481"
"180.00000","2.99828","717.64691","2.94817","1.89768","0.01501","285.95728"
"180.60000","3.00851","718.14966","2.95838","1.90790","0.01507","286.15762"
"181.20000","3.01855","718.69690","2.96839","1.91791","0.01512","286.37567"
"181.80000","3.02812","718.83850","2.97796","1.92747","0.01517","286.43210"
"182.40000","3.03818","719.14508","2.98801","1.93752","0.01522","286.55426"
"183.00000","3.04843","719.71228","2.99823","1.94774","0.01527","286.78027"
"183.60000","3.05846","720.06885","3.00824","1.95775","0.01532","286.92233"
"184.20000","3.06812","720.30255","3.01789","1.96740","0.01537","287.01547"
"184.80000","3.07831","720.68640","3.02807","1.97758","0.01542","287.16843"
"185.40000","3.08864","721.18292","3.03838","1.98789","0.01547","287.36627"
"186.00000","3.09838","721.32428","3.04811","1.99762","0.01552","287.42258"
"186.60000","3.10808","721.43109","3.05780","2.00731","0.01557","287.46515"
"187.20000","3.11830","721.62402","3.06801","2.01752","0.01562","287.54202"
"187.80000","3.12852","721.93433","3.07822","2.02773","0.01568","287.66568"
"188.40000","3.13825","722.12097","3.08794","2.03745","0.01573","287.74005"
"189.00000","3.14816","722.35272","3.09784","2.04735","0.01578","287.83240"
"189.60000","3.15837","722.56299","3.10804","2.05755","0.01583","287.91617"
"190.20000","3.16866","722.98199","3.11832","2.06783","0.01588","288.08313"
"190.80000","3.17827","723.01404","3.12792","2.07743","0.01593","288.09589"
"191.40000","3.18813","723.09790","3.13778","2.08730","0.01598","288.12930"
"192.00000","3.19827","723.12097","3.14792","2.09743","0.01603","288.13852"
"192.60000","3.20853","723.20227","3.15817","2.10768","0.01608","288.17090"
"193.20000","3.21820","723.14264","3.16784","2.11736","0.01613","288.14716"
"193.80000","3.22821","722.94629","3.17787","2.12738","0.01618","288.06891"
"194.40000","3.23845","722.83795","3.18811","2.13762","0.01624","288.02573"
"195.00000","3.24870","723.05450","3.19835","2.14786","0.01629","288.11203"
"195.60000","3.25813","722.25769","3.20782","2.15733","0.01634","287.79453"
"196.20000","3.26818","721.59924","3.21790","2.16741","0.01639","287.53217"
"196.80000","3.27835","721.56281","3.22807","2.17758","0.01644","287.51764"
"197.40000","3.28850","721.56268","3.23822","2.18773","0.01649","287.51758"
"198.00000","3.29814","721.10504","3.24788","2.19739","0.01654","287.33524"
"198.60000","3.30823","721.27875","3.25796","2.20748","0.01659","287.40445"
"199.20000","3.31850","721.48431","3.26822","2.21774","0.01664","287.48636"
"199.80000","3.32858","721.61621","3.27830","2.22781","0.01670","287.53891"
"200.40000","3.33810","721.44836","3.28783","2.23734","0.01674","287.47205"
"201.00000","3.34823","721.70862","3.29794","2.24745","0.01680","287.57574"
"201.60000","3.35847","722.13037","3.30816","2.25767","0.01685","287.74380"
"202.20000","3.36839","722.21295","3.31808","2.26759","0.01690","287.77670"
"202.80000","3.37812","722.25903","3.32781","2.27732","0.01695","287.79504"
"203.40000","3.38829","722.63135","3.33796","2.28747","0.01700","287.94342"
"204.00000","3.39860","723.04883","3.34825","2.29776","0.01705","288.10977"
"204.60000","3.40840","723.04865","3.35805","2.30757","0.01710","288.10968"
"205.20000","3.41815","723.11035","3.36780","2.31731","0.01715","288.13428"
"205.80000","3.42825","723.36487","3.37789","2.32740","0.01720","288.23569"
"206.40000","3.43843","723.69385","3.38805","2.33756","0.01725","288.36679"
"207.00000","3.44827","723.85449","3.39789","2.34740","0.01730","288.43079"
"207.60000","3.45820","723.92804","3.40781","2.35732","0.01735","288.46011"
"208.20000","3.46837","724.23920","3.41797","2.36748","0.01741","288.58408"
"208.80000","3.47867","724.54016","3.42825","2.37776","0.01746","288.70401"
"209.40000","3.48825","724.37933","3.43784","2.38736","0.01751","288.63992"
"210.00000","3.49812","724.49139","3.44770","2.39721","0.01756","288.68457"
"210.60000","3.50830","724.61157","3.45788","2.40739","0.01761","288.73245"
"211.20000","3.51860","725.04089","3.46816","2.41767","0.01766","288.90353"
"211.80000","3.52823","724.93970","3.47780","2.42731","0.01771","288.86322"
"212.40000","3.53817","725.21851","3.48773","2.43724","0.01776","288.97430"
"213.00000","3.54842","725.51239","3.49796","2.44748","0.01781","289.09140"
"213.60000","3.55864","725.92596","3.50817","2.45768","0.01787","289.25620"
"214.20000","3.56812","725.78986","3.51765","2.46716","0.01791","289.20197"
"214.80000","3.57817","726.02844","3.52768","2.47720","0.01797","289.29703"
"215.40000","3.58840","726.44739","3.53790","2.48741","0.01802","289.46396"
"216.00000","3.59851","726.75055","3.54800","2.49751","0.01807","289.58478"
"216.60000","3.60815","726.89386","3.55763","2.50714","0.01812","289.64188"
"217.20000","3.61822","727.23859","3.56768","2.51719","0.01817","289.77924"
"217.80000","3.62847","727.66168","3.57792","2.52743","0.01822","289.94781"
"218.40000","3.63861","727.92426","3.58804","2.53755","0.01827","290.05246"
"219.00000","3.64810","728.05164","3.59753","2.54704","0.01832","290.10321"
"219.60000","3.65819","728.25946","3.60761","2.55712","0.01837","290.18600"
"220.20000","3.66845","728.75476","3.61785","2.56736","0.01842","290.38339"
"220.80000","3.67844","729.15485","3.62782","2.57733","0.01848","290.54279"
"221.40000","3.68815","729.31067","3.63752","2.58703","0.01852","290.60489"
"222.00000","3.69833","729.60620","3.64769","2.59720","0.01858","290.72266"
"222.60000","3.70856","730.10266","3.65789","2.60740","0.01863","290.92047"
"223.20000","3.71844","730.39734","3.66776","2.61727","0.01868","291.03790"
"223.80000","3.72810","730.33685","3.67742","2.62693","0.01873","291.01379"
"224.40000","3.73825","730.59204","3.68756","2.63708","0.01878","291.11548"
"225.00000","3.74847","730.80725","3.69778","2.64729","0.01883","291.20123"
"225.60000","3.75839","731.06073","3.70768","2.65719","0.01888","291.30222"
"226.20000","3.76818","731.06006","3.71748","2.66699","0.01893","291.30197"
"226.80000","3.77836","731.42047","3.72764","2.67715","0.01898","291.44559"
"227.40000","3.78863","731.74493","3.73789","2.68740","0.01904","291.57486"
"228.00000","3.79829","731.70349","3.74755","2.69706","0.01908","291.55835"
"228.60000","3.80810","731.80481","3.75736","2.70687","0.01913","291.59872"
"229.20000","3.81833","732.05383","3.76758","2.71709","0.01919","291.69794"
"229.80000","3.82857","732.35162","3.77781","2.72732","0.01924","291.81659"
"230.40000","3.83820","732.36847","3.78744","2.73695","0.01929","291.82330"
"231.00000","3.84815","732.27911","3.79739","2.74690","0.01934","291.78772"
"231.60000","3.85840","732.42798","3.80763","2.75714","0.01939","291.84702"
"232.20000","3.86868","732.76459","3.81789","2.76741","0.01944","291.98117"
"232.80000","3.87817","732.33557","3.82741","2.77692","0.01949","291.81021"
"233.40000","3.88817","732.40533","3.83741","2.78692","0.01954","291.83801"
"234.00000","3.89831","732.30341","3.84754","2.79706","0.01959","291.79739"
"234.60000","3.90852","732.51648","3.85775","2.80726","0.01965","291.88229"
"235.20000","3.91823","732.16168","3.86747","2.81698","0.01970","291.74091"
"235.80000","3.92826","731.84015","3.87752","2.82703","0.01975","291.61279"
"236.40000","3.93851","731.80096","3.88777","2.83728","0.01980","291.59720"
"237.00000","3.94862","731.64880","3.89789","2.84740","0.01985","291.53656"
"237.60000","3.95808","731.10553","3.90737","2.85688","0.01990","291.32007"
"238.20000","3.96819","731.04364","3.91748","2.86699","0.01995","291.29541"
"238.80000","3.97841","730.87286","3.92772","2.87723","0.02000","291.22736"
"239.40000","3.98846","730.81494","3.93777","2.88728","0.02005","291.20428"
"240.00000","3.99816","730.34918","3.94749","2.89700","0.02010","291.01871"
"240.60000","4.00829","730.38617","3.95762","2.90713","0.02015","291.03345"
"241.20000","4.01854","730.60260","3.96785","2.91736","0.02021","291.11969"
"241.80000","4.02843","730.25580","3.97775","2.92727","0.02026","290.98148"
"242.40000","4.03807","730.13324","3.98741","2.93692","0.02031","290.93265"
"243.00000","4.04823","730.20459","3.99756","2.94708","0.02036","290.96109"
"243.60000","4.05853","730.33411","4.00786","2.95737","0.02041","291.01270"
"244.20000","4.06833","730.31207","4.01766","2.96717","0.02046","291.00391"
"244.80000","4.07812","730.26215","4.02745","2.97696","0.02051","290.98401"
"245.40000","4.08834","730.17285","4.03767","2.98718","0.02056","290.94843"
"246.00000","4.09866","730.43451","4.04798","2.99750","0.02061","291.05270"
"246.60000","4.10826","730.26135","4.05759","3.00710","0.02066","290.98370"
"247.20000","4.11814","730.21619","4.06747","3.01698","0.02071","290.96570"
"247.80000","4.12828","730.33136","4.07761","3.02712","0.02077","291.01160"
"248.40000","4.13845","730.42114","4.08777","3.03729","0.02082","291.04736"
"249.00000","4.14817","730.23401","4.09750","3.04702","0.02087","290.97281"
"249.60000","4.15822","730.15106","4.10756","3.05707","0.02092","290.93976"
"250.20000","4.16844","730.12585","4.11777","3.06729","0.02097","290.92972"
"250.80000","4.17872","730.36066","4.12804","3.07755","0.02102","291.02328"
"251.40000","4.18821","729.90802","4.13755","3.08707","0.02107","290.84293"
"252.00000","4.19811","729.89960","4.14746","3.09697","0.02112","290.83957"
"252.60000","4.20834","729.91949","4.15768","3.10720","0.02117","290.84747"
"253.20000","4.21856","729.80975","4.16791","3.11742","0.02123","290.80377"
"253.80000","4.22821","729.49432","4.17758","3.12709","0.02127","290.67807"
"254.40000","4.23822","729.38007","4.18759","3.13710","0.02133","290.63254"
"255.00000","4.24853","729.53723","4.19789","3.14740","0.02138","290.69516"
"255.60000","4.25859","729.64496","4.20795","3.15746","0.02143","290.73810"
"256.20000","4.26813","729.26263","4.21750","3.16701","0.02148","290.58575"
"256.80000","4.27817","729.18732","4.22755","3.17706","0.02153","290.55573"
"257.40000","4.28840","729.25787","4.23777","3.18729","0.02158","290.58386"
"258.00000","4.29846","729.34277","4.24783","3.19734","0.02163","290.61768"
"258.60000","4.30815","729.01843","4.25753","3.20704","0.02168","290.48843"
"259.20000","4.31822","728.93726","4.26760","3.21712","0.02173","290.45609"
"259.80000","4.32858","728.98303","4.27797","3.22748","0.02179","290.47433"
"260.40000","4.33852","728.86188","4.28791","3.23742","0.02184","290.42606"
"261.00000","4.34811","728.49249","4.29752","3.24703","0.02189","290.27887"
"261.60000","4.35827","728.42151","4.30768","3.25719","0.02194","290.25058"
"262.20000","4.36844","728.31110","4.31786","3.26737","0.02199","290.20660"
"262.80000","4.37828","728.17511","4.32770","3.27721","0.02204","290.15240"
"263.40000","4.38814","727.82812","4.33758","3.28709","0.02209","290.01416"
"264.00000","4.39836","727.82764","4.34780","3.29731","0.02214","290.01395"
"264.60000","4.40860","727.83313","4.35804","3.30755","0.02219","290.01614"
"265.20000","4.41834","727.58563","4.36778","3.31730","0.02224","289.91751"
"265.80000","4.42812","727.32263","4.37758","3.32709","0.02229","289.81271"
"266.40000","4.43825","727.30511","4.38771","3.33722","0.02234","289.80576"
"267.00000","4.44850","727.37488","4.39795","3.34747","0.02240","289.83356"
"267.60000","4.45826","727.04523","4.40774","3.35725","0.02245","289.70218"
"268.20000","4.46817","726.80695","4.41765","3.36717","0.02250","289.60724"
"268.80000","4.47843","726.45178","4.42793","3.37744","0.02255","289.46573"
"269.40000","4.48868","726.35956","4.43819","3.38770","0.02260","289.42899"
"270.00000","4.49820","725.77350","4.44773","3.39724","0.02265","289.19547"
"270.60000","4.50814","725.34375","4.45768","3.40720","0.02270","289.02420"
"271.20000","4.51833","724.84955","4.46790","3.41742","0.02275","288.82730"
"271.80000","4.52857","724.09772","4.47817","3.42768","0.02281","288.52771"
"272.40000","4.53817","722.64423","4.48784","3.43735","0.02285","287.94855"
"273.00000","4.54820","721.90308","4.49790","3.44741","0.02291","287.65323"
"273.60000","4.55844","721.54462","4.50815","3.45767","0.02296","287.51038"
"274.20000","4.56866","721.09839","4.51840","3.46791","0.02301","287.33258"
"274.80000","4.57811","719.97839","4.52790","3.47741","0.02306","286.88629"
"275.40000","4.58825","719.96802","4.53803","3.48755","0.02311","286.88217"
"276.00000","4.59837","719.72552","4.54817","3.49768","0.02316","286.78555"
"276.60000","4.60843","719.78241","4.55823","3.50774","0.02321","286.80820"
"277.20000","4.61815","719.59302","4.56795","3.51746","0.02326","286.73276"
"277.80000","4.62830","719.70856","4.57810","3.52761","0.02331","286.77878"
"278.40000","4.63853","720.03467","4.58831","3.53783","0.02337","286.90872"
"279.00000","4.64855","720.22394","4.59833","3.54784","0.02342","286.98413"
"279.60000","4.65807","719.94867","4.60786","3.55737","0.02347","286.87445"
"280.20000","4.66824","720.14093","4.61802","3.56754","0.02352","286.95108"
"280.80000","4.67841","720.40399","4.62818","3.57769","0.02357","287.05588"
"281.40000","4.68834","720.64862","4.63810","3.58761","0.02362","287.15335"
"282.00000","4.69812","720.46735","4.64789","3.59740","0.02367","287.08115"
"282.60000","4.70834","720.55170","4.65811","3.60762","0.02372","287.11475"
"283.20000","4.71863","720.92090","4.66838","3.61789","0.02377","287.26187"
"283.80000","4.72831","720.72559","4.67806","3.62757","0.02382","287.18402"
"284.40000","4.73808","720.56219","4.68784","3.63735","0.02387","287.11893"
"285.00000","4.74828","720.67535","4.69803","3.64755","0.02393","287.16403"
"285.60000","4.75859","720.94684","4.70834","3.65785","0.02398","287.27219"
"286.20000","4.76832","720.63293","4.71808","3.66759","0.02403","287.14713"
"286.80000","4.77816","720.47357","4.72792","3.67744","0.02408","287.08362"
"287.40000","4.78838","720.68677","4.73814","3.68765","0.02413","287.16858"
"288.00000","4.79872","720.79187","4.74847","3.69798","0.02418","287.21045"
"288.60000","4.80819","720.27991","4.75796","3.70747","0.02423","287.00644"
"289.20000","4.81816","720.09949","4.76795","3.71746","0.02428","286.93454"
"289.80000","4.82836","720.03967","4.77815","3.72766","0.02433","286.91071"
"290.40000","4.83855","720.05463","4.78834","3.73785","0.02439","286.91669"
"291.00000","4.84820","719.58038","4.79801","3.74752","0.02443","286.72772"
"291.60000","4.85821","719.50208","4.80802","3.75753","0.02449","286.69650"
"292.20000","4.86844","719.45355","4.81825","3.76776","0.02454","286.67719"
"292.80000","4.87862","719.46594","4.82843","3.77795","0.02459","286.68210"
"293.40000","4.88816","719.07275","4.83799","3.78750","0.02464","286.52545"
"294.00000","4.89820","719.10907","4.84803","3.79754","0.02469","286.53992"
"294.60000","4.90834","719.03400","4.85818","3.80769","0.02474","286.50998"
"295.20000","4.91850","719.11517","4.86833","3.81784","0.02479","286.54233"
"295.80000","4.92818","717.89130","4.87806","3.82757","0.02484","286.05466"
"296.40000","4.93824","717.89996","4.88812","3.83763","0.02489","286.05814"
"297.00000","4.94857","717.92920","4.89845","3.84796","0.02495","286.06976"
"297.60000","4.95853","717.89624","4.90841","3.85792","0.02500","286.05664"
"298.20000","4.96806","717.74194","4.91795","3.86746","0.02505","285.99515"
"298.80000","4.97820","717.70532","4.92809","3.87760","0.02510","285.98056"
"299.40000","4.98849","717.97644","4.93836","3.88788","0.02515","286.08859"
"300.00000","4.99838","718.05261","4.94826","3.89777","0.02520","286.11896"
"300.60000","5.00815","717.96802","4.95803","3.90754","0.02525","286.08524"
"301.20000","5.01832","718.20538","4.96819","3.91770","0.02530","286.17981"
"301.80000","5.02860","718.13300","4.97847","3.92798","0.02535","286.15097"
"302.40000","5.03836","718.16425","4.98823","3.93774","0.02540","286.16342"
"303.00000","5.04810","717.92310","4.99798","3.94749","0.02545","286.06735"
"303.60000","5.05828","717.93054","5.00816","3.95767","0.02550","286.07031"
"304.20000","5.06855","717.81470","5.01843","3.96794","0.02556","286.02414"
"304.80000","5.07829","714.09192","5.02834","3.97785","0.02561","284.54074"
"305.40000","5.08819","712.84644","5.03830","3.98781","0.02566","284.04446"
"306.00000","5.09841","712.42651","5.04854","3.99805","0.02571","283.87714"
"306.60000","5.10868","712.61774","5.05879","4.00831","0.02576","283.95334"
"307.20000","5.11822","712.42377","5.06835","4.01786","0.02581","283.87604"
"307.80000","5.12815","710.46326","5.07836","4.02787","0.02586","283.09485"
"308.40000","5.13833","709.27405","5.08860","4.03811","0.02591","282.62100"
"309.00000","5.14845","708.44202","5.09876","4.04827","0.02597","282.28946"
"309.60000","5.15824","704.81012","5.10870","4.05821","0.02602","280.84229"
"310.20000","5.16824","697.78998","5.11902","4.06853","0.02607","278.04498"
"310.80000","5.17844","696.74298","5.12927","4.07878","0.02612","277.62781"
"311.40000","5.18867","696.61719","5.13951","4.08902","0.02617","277.57767"
"312.00000","5.19816","695.83917","5.14903","4.09854","0.02622","277.26767"
"312.60000","5.20814","695.59436","5.15902","4.10853","0.02627","277.17010"
"313.20000","5.21835","695.69556","5.16922","4.11873","0.02632","277.21045"
"313.80000","5.22856","694.82397","5.17947","4.12898","0.02638","276.86313"
"314.40000","5.23813","693.69745","5.18909","4.13860","0.02643","276.41428"
"315.00000","5.24826","693.67200","5.19922","4.14874","0.02648","276.40411"
"315.60000","5.25857","694.07465","5.20951","4.15902","0.02653","276.56458"
"316.20000","5.26853","694.27576","5.21947","4.16898","0.02658","276.64468"
"316.80000","5.27808","694.10388","5.22902","4.17853","0.02663","276.57620"
"317.40000","5.28826","694.28656","5.23920","4.18871","0.02668","276.64902"
"318.00000","5.29844","694.55511","5.24937","4.19888","0.02673","276.75601"
"318.60000","5.30834","694.35144","5.25928","4.20879","0.02678","276.67487"
"319.20000","5.31815","694.20532","5.26909","4.21861","0.02683","276.61664"
"319.80000","5.32831","694.18964","5.27925","4.22877","0.02689","276.61038"
"320.40000","5.33864","692.86725","5.28963","4.23915","0.02694","276.08347"
"321.00000","5.34843","691.95966","5.29947","4.24898","0.02699","275.72180"
"321.60000","5.35811","690.93683","5.30920","4.25871","0.02704","275.31424"
"322.20000","5.36823","690.90924","5.31931","4.26883","0.02709","275.30325"
"322.80000","5.37852","691.11774","5.32959","4.27911","0.02714","275.38632"
"323.40000","5.38827","690.63831","5.33937","4.28888","0.02719","275.19531"
"324.00000","5.39817","690.64624","5.34927","4.29878","0.02724","275.19846"
"324.60000","5.40839","690.80322","5.35948","4.30900","0.02729","275.26102"
"325.20000","5.41871","690.74133","5.36980","4.31931","0.02735","275.23636"
"325.80000","5.42823","689.34863","5.37939","4.32890","0.02740","274.68140"
"326.40000","5.43814","688.87292","5.38932","4.33883","0.02745","274.49185"
"327.00000","5.44828","688.88940","5.39945","4.34896","0.02750","274.49841"
"327.60000","5.45853","688.59558","5.40972","4.35923","0.02755","274.38135"
"328.20000","5.46821","688.66858","5.41940","4.36891","0.02760","274.41043"
"328.80000","5.47818","688.75262","5.42937","4.37888","0.02765","274.44391"
"329.40000","5.48842","688.92639","5.43960","4.38911","0.02770","274.51315"
"330.00000","5.49871","689.33044","5.44986","4.39937","0.02775","274.67416"
"330.60000","5.50816","689.14136","5.45932","4.40883","0.02780","274.59882"
"331.20000","5.51818","689.18958","5.46934","4.41886","0.02785","274.61804"
"331.80000","5.52839","689.47003","5.47955","4.42906","0.02791","274.72980"
"332.40000","5.53849","689.74323","5.48963","4.43914","0.02796","274.83865"
"333.00000","5.54813","688.96924","5.49930","4.44882","0.02801","274.53024"
"333.60000","5.55825","689.03021","5.50942","4.45893","0.02806","274.55453"
"334.20000","5.56852","689.16638","5.51969","4.46920","0.02811","274.60880"
"334.80000","5.57856","689.39624","5.52971","4.47922","0.02816","274.70038"
"335.40000","5.58816","689.52502","5.53931","4.48882","0.02821","274.75171"
"336.00000","5.59820","689.78790","5.54933","4.49884","0.02826","274.85645"
"336.60000","5.60836","690.09277","5.55948","4.50899","0.02831","274.97794"
"337.20000","5.61837","690.17664","5.56949","4.51900","0.02836","275.01135"
"337.80000","5.62818","689.66833","5.57932","4.52884","0.02841","274.80881"
"338.40000","5.63830","689.92206","5.58943","4.53895","0.02846","274.90991"
"339.00000","5.64858","690.30719","5.59970","4.54921","0.02852","275.06335"
"339.60000","5.65842","690.52319","5.60952","4.55903","0.02857","275.14944"
"340.20000","5.66808","690.45099","5.61919","4.56870","0.02862","275.12067"
"340.80000","5.67825","690.85510","5.62934","4.57885","0.02867","275.28168"
"341.40000","5.68855","691.15393","5.63962","4.58914","0.02872","275.40076"
"342.00000","5.69833","691.19165","5.64940","4.59891","0.02877","275.41580"
"342.60000","5.70813","691.16333","5.65920","4.60872","0.02882","275.40451"
"343.20000","5.71836","691.14508","5.66943","4.61894","0.02887","275.39725"
"343.80000","5.72862","691.36255","5.67968","4.62920","0.02892","275.48389"
"344.40000","5.73825","691.34680","5.68932","4.63883","0.02897","275.47760"
"345.00000","5.74814","691.14166","5.69922","4.64873","0.02902","275.39587"
"345.60000","5.75834","691.42218","5.70940","4.65891","0.02908","275.50766"
"346.20000","5.76855","690.72241","5.71965","4.66916","0.02913","275.22882"
"346.80000","5.77821","687.99359","5.72942","4.67893","0.02918","274.14148"
"347.40000","5.78817","677.16150","5.73987","4.68938","0.02923","269.82526"
"347.94800","5.79774","655.64789","5.75040","4.69991","0.02928","261.25284"
"348.54800","5.80751","641.61273","5.76079","4.71030","0.02934","255.66032"
"349.14800","5.81724","638.37616","5.77067","4.72018","0.02939","254.37065"
"349.74800","5.82738","636.78442","5.78088","4.73039","0.02944","253.73640"
"350.34800","5.83767","636.14380","5.79120","4.74071","0.02949","253.48114"
"350.94800","5.84745","634.34814","5.80106","4.75057","0.02954","252.76562"
"351.54800","5.85732","633.52386","5.81096","4.76047","0.02959","252.43718"
"352.14800","5.86755","627.92102","5.82144","4.77095","0.02965","250.20465"
"352.74800","5.87779","624.06274","5.83186","4.78137","0.02970","248.66725"
"353.34800","5.88733","613.90552","5.84186","4.79137","0.02975","244.61996"
"353.64600","5.89229","612.90509","5.84686","4.79637","0.02978","244.22133"