File: flexion/5_axis/Specimen_RawData_8.csv
Specimen properties : Specimen label,"8"
Specimen properties : Support span,"72.00",mm
Specimen properties : Thickness,"4.89",mm
Specimen properties : Width,"14.06",mm
Maximum Load : Maximum Load,"401.2",N
Tangent Modulus of Elasticity : Tangent Modulus of Elasticity,"14863441130.98280",Pa
Test : Rate 1,"1.00000",mm/min
Specimen notes : Specimen note 1,""

Time,Displacement,Load,Flexure extension,Corrected extension,Flexure strain (Corrected extension),Flexure stress
(s),(mm),(N),(mm),(mm),(mm/mm),(MPa)
"0.00000","-0.00027","9.42127","0.03703","-1.04713","0.00021","3.02643"
"0.50000","0.00592","11.15764","0.04247","-1.04169","0.00024","3.58421"
"1.00000","0.01472","13.28175","0.05035","-1.03380","0.00028","4.26654"
"1.50000","0.02261","15.28095","0.05738","-1.02677","0.00032","4.90875"
"2.00000","0.03135","17.40677","0.06558","-1.01858","0.00037","5.59164"
"2.50000","0.03937","19.23756","0.07321","-1.01095","0.00041","6.17975"
"3.00000","0.04810","21.56109","0.08144","-1.00271","0.00046","6.92614"
"3.50000","0.05600","23.32618","0.08897","-0.99518","0.00050","7.49315"
"4.00000","0.06446","25.39395","0.09699","-0.98716","0.00055","8.15738"
"4.50000","0.07287","27.46745","0.10496","-0.97919","0.00059","8.82346"
"5.00000","0.08108","29.41407","0.11276","-0.97139","0.00064","9.44878"
"5.50000","0.08951","31.52079","0.12075","-0.96340","0.00068","10.12553"
"6.00000","0.09764","33.47886","0.12847","-0.95569","0.00073","10.75453"
"6.50000","0.10639","35.78358","0.13675","-0.94740","0.00077","11.49488"
"7.00000","0.11422","37.67530","0.14433","-0.93982","0.00082","12.10257"
"7.50000","0.12298","39.83219","0.15280","-0.93135","0.00086","12.79543"
"8.00000","0.13099","41.81273","0.16054","-0.92361","0.00091","13.43165"
"8.50000","0.13972","44.01580","0.16898","-0.91517","0.00096","14.13935"
"9.00000","0.14768","46.00826","0.17667","-0.90748","0.00100","14.77939"
"9.50000","0.15619","48.23701","0.18488","-0.89927","0.00105","15.49534"
"10.00000","0.16458","50.30104","0.19299","-0.89116","0.00109","16.15837"
"10.50000","0.17265","52.42571","0.20078","-0.88337","0.00114","16.84089"
"11.00000","0.18121","54.62836","0.20904","-0.87511","0.00118","17.54846"
"11.50000","0.18928","56.74269","0.21683","-0.86733","0.00123","18.22765"
"12.00000","0.19808","59.09391","0.22534","-0.85881","0.00128","18.98294"
"12.50000","0.20594","61.07108","0.23297","-0.85118","0.00132","19.61807"
"13.00000","0.21472","63.36374","0.24148","-0.84267","0.00137","20.35455"
"13.50000","0.22269","65.37772","0.24921","-0.83494","0.00141","21.00151"
"14.00000","0.23136","67.68193","0.25762","-0.82653","0.00146","21.74170"
"14.50000","0.23943","69.67812","0.26545","-0.81870","0.00150","22.38294"
"15.00000","0.24774","71.88599","0.27351","-0.81065","0.00155","23.09218"
"15.50000","0.25623","73.92159","0.28175","-0.80240","0.00159","23.74608"
"16.00000","0.26425","75.92498","0.28954","-0.79461","0.00164","24.38964"
"16.50000","0.27287","78.14056","0.29791","-0.78625","0.00169","25.10136"
"17.00000","0.28095","80.25258","0.30574","-0.77842","0.00173","25.77981"
"17.50000","0.28982","82.50317","0.31434","-0.76981","0.00178","26.50278"
"18.00000","0.29766","84.38504","0.32196","-0.76219","0.00182","27.10730"
"18.50000","0.30630","86.65337","0.33033","-0.75382","0.00187","27.83596"
"19.00000","0.31443","88.66310","0.33826","-0.74589","0.00191","28.48155"
"19.50000","0.32299","90.86366","0.34660","-0.73755","0.00196","29.18845"
"20.00000","0.33109","92.67164","0.35452","-0.72963","0.00201","29.76923"
"20.50000","0.33940","94.84104","0.36262","-0.72153","0.00205","30.46611"
"21.00000","0.34795","97.03800","0.37095","-0.71320","0.00210","31.17185"
"21.50000","0.35589","99.09837","0.37870","-0.70546","0.00214","31.83371"
"22.00000","0.36458","101.18390","0.38718","-0.69697","0.00219","32.50365"
"22.50000","0.37262","103.21040","0.39502","-0.68913","0.00224","33.15463"
"23.00000","0.38151","105.47423","0.40369","-0.68046","0.00228","33.88185"
"23.50000","0.38932","107.37424","0.41132","-0.67283","0.00233","34.49220"
"24.00000","0.39806","109.65884","0.41984","-0.66432","0.00238","35.22608"
"24.50000","0.40612","111.64259","0.42770","-0.65646","0.00242","35.86333"
"25.00000","0.41452","113.75849","0.43589","-0.64826","0.00247","36.54303"
"25.50000","0.42277","115.81951","0.44394","-0.64022","0.00251","37.20510"
"26.00000","0.43100","117.97835","0.45196","-0.63219","0.00256","37.89859"
"26.50000","0.43962","120.03738","0.46038","-0.62377","0.00261","38.56002"
"27.00000","0.44755","122.09048","0.46811","-0.61604","0.00265","39.21954"
"27.50000","0.45633","124.36387","0.47667","-0.60749","0.00270","39.94983"
"28.00000","0.46430","126.40923","0.48444","-0.59971","0.00274","40.60687"
"28.50000","0.47321","128.60551","0.49314","-0.59102","0.00279","41.31239"
"29.00000","0.48104","130.53580","0.50077","-0.58338","0.00283","41.93246"
"29.50000","0.48956","132.70901","0.50908","-0.57507","0.00288","42.63057"
"30.00000","0.49777","134.82866","0.51709","-0.56706","0.00293","43.31147"
"30.50000","0.50608","136.90567","0.52519","-0.55896","0.00297","43.97868"
"31.00000","0.51447","139.10229","0.53337","-0.55078","0.00302","44.68431"
"31.50000","0.52267","141.01718","0.54139","-0.54276","0.00306","45.29943"
"32.00000","0.53138","143.35999","0.54987","-0.53428","0.00311","46.05202"
"32.50000","0.53929","145.20097","0.55760","-0.52655","0.00316","46.64341"
"33.00000","0.54803","147.46199","0.56611","-0.51804","0.00320","47.36972"
"33.50000","0.55606","149.49884","0.57395","-0.51021","0.00325","48.02402"
"34.00000","0.56481","151.69501","0.58249","-0.50167","0.00330","48.72951"
"34.50000","0.57270","153.67221","0.59018","-0.49397","0.00334","49.36465"
"35.00000","0.58117","155.75049","0.59845","-0.48570","0.00339","50.03226"
"35.50000","0.58949","157.77583","0.60658","-0.47757","0.00343","50.68287"
"36.00000","0.59770","159.84065","0.61461","-0.46955","0.00348","51.34616"
"36.50000","0.60616","161.92610","0.62289","-0.46126","0.00353","52.01608"
"37.00000","0.61432","163.92514","0.63088","-0.45327","0.00357","52.65823"
"37.50000","0.62308","166.13979","0.63945","-0.44470","0.00362","53.36965"
"38.00000","0.63094","168.13753","0.64715","-0.43700","0.00366","54.01139"
"38.50000","0.63975","170.42821","0.65576","-0.42840","0.00371","54.74724"
"39.00000","0.64770","172.24867","0.66355","-0.42060","0.00376","55.33203"
"39.50000","0.65642","174.41772","0.67209","-0.41207","0.00380","56.02880"
"40.00000","0.66435","176.25446","0.67987","-0.40428","0.00385","56.61882"
"40.50000","0.67284","178.42949","0.68817","-0.39598","0.00389","57.31752"
"41.00000","0.68118","180.42961","0.69634","-0.38781","0.00394","57.96002"
"41.50000","0.68930","182.33160","0.70429","-0.37986","0.00399","58.57101"
"42.00000","0.69788","184.43095","0.71270","-0.37145","0.00403","59.24539"
"42.50000","0.70596","186.36740","0.72062","-0.36354","0.00408","59.86744"
"43.00000","0.71475","188.65880","0.72921","-0.35494","0.00413","60.60351"
"43.50000","0.72262","190.39775","0.73693","-0.34722","0.00417","61.16212"
"44.00000","0.73134","192.51332","0.74548","-0.33868","0.00422","61.84171"
"44.50000","0.73935","194.40849","0.75332","-0.33083","0.00426","62.45050"
"45.00000","0.74804","196.52762","0.76183","-0.32232","0.00431","63.13124"
"45.50000","0.75606","198.54312","0.76968","-0.31447","0.00436","63.77869"
"46.00000","0.76444","200.54280","0.77789","-0.30627","0.00440","64.42105"
"46.50000","0.77292","202.59084","0.78621","-0.29795","0.00445","65.07895"
"47.00000","0.78099","204.40710","0.79413","-0.29002","0.00449","65.66239"
"47.50000","0.78957","206.40784","0.80255","-0.28160","0.00454","66.30510"
"48.00000","0.79770","208.31223","0.81052","-0.27363","0.00459","66.91685"
"48.50000","0.80642","210.49522","0.81907","-0.26508","0.00464","67.61810"
"49.00000","0.81428","212.15512","0.82680","-0.25735","0.00468","68.15131"
"49.50000","0.82293","214.23953","0.83528","-0.24887","0.00473","68.82090"
"50.00000","0.83106","216.14629","0.84326","-0.24089","0.00477","69.43341"
"50.50000","0.83965","218.08003","0.85169","-0.23246","0.00482","70.05460"
"51.00000","0.84772","220.00757","0.85961","-0.22454","0.00487","70.67378"
"51.50000","0.85608","221.88162","0.86782","-0.21633","0.00491","71.27579"
"52.00000","0.86461","223.75569","0.87620","-0.20795","0.00496","71.87781"
"52.50000","0.87263","225.59679","0.88407","-0.20008","0.00500","72.46923"
"53.00000","0.88128","227.68369","0.89255","-0.19160","0.00505","73.13961"
"53.50000","0.88931","229.31516","0.90046","-0.18370","0.00510","73.66369"
"54.00000","0.89809","231.43045","0.90907","-0.17508","0.00515","74.34319"
"54.50000","0.90597","233.07761","0.91682","-0.16734","0.00519","74.87231"
"55.00000","0.91471","235.10698","0.92539","-0.15876","0.00524","75.52422"
"55.50000","0.92275","236.82404","0.93330","-0.15085","0.00528","76.07580"
"56.00000","0.93121","238.70053","0.94160","-0.14255","0.00533","76.67859"
"56.50000","0.93944","240.52705","0.94968","-0.13447","0.00537","77.26533"
"57.00000","0.94768","242.28358","0.95779","-0.12637","0.00542","77.82958"
"57.50000","0.95625","244.33269","0.96620","-0.11796","0.00547","78.48782"
"58.00000","0.96424","245.87819","0.97407","-0.11008","0.00551","78.98429"
"58.50000","0.97294","247.71385","0.98263","-0.10153","0.00556","79.57397"
"59.00000","0.98095","249.49617","0.99050","-0.09365","0.00561","80.14651"
"59.50000","0.98983","251.54861","0.99922","-0.08493","0.00566","80.80582"
"60.00000","0.99769","253.09331","1.00697","-0.07719","0.00570","81.30203"
"60.50000","1.00625","254.94890","1.01539","-0.06877","0.00575","81.89811"
"61.00000","1.01449","256.67007","1.02349","-0.06067","0.00579","82.45100"
"61.50000","1.02286","258.39655","1.03173","-0.05243","0.00584","83.00561"
"62.00000","1.03112","260.01450","1.03987","-0.04429","0.00589","83.52534"
"62.50000","1.03939","261.93420","1.04799","-0.03616","0.00593","84.14202"
"63.00000","1.04798","263.59454","1.05645","-0.02770","0.00598","84.67538"
"63.50000","1.05590","265.21930","1.06425","-0.01991","0.00602","85.19730"
"64.00000","1.06456","267.04242","1.07276","-0.01139","0.00607","85.78295"
"64.50000","1.07266","268.66006","1.08074","-0.00341","0.00612","86.30259"
"65.00000","1.08148","270.52228","1.08942","0.00526","0.00617","86.90079"
"65.50000","1.08934","272.05878","1.09716","0.01300","0.00621","87.39437"
"66.00000","1.09795","273.95502","1.10562","0.02147","0.00626","88.00351"
"66.50000","1.10616","275.42786","1.11372","0.02956","0.00630","88.47663"
"67.00000","1.11444","277.13242","1.12187","0.03771","0.00635","89.02419"
"67.50000","1.12278","278.71857","1.13008","0.04593","0.00640","89.53372"
"68.00000","1.13101","280.33414","1.13820","0.05404","0.00644","90.05270"
"68.50000","1.13968","282.13068","1.14673","0.06258","0.00649","90.62981"
"69.00000","1.14760","283.47321","1.15455","0.07039","0.00653","91.06107"
"69.50000","1.15640","285.40204","1.16320","0.07905","0.00658","91.68067"
"70.00000","1.16434","286.71927","1.17104","0.08688","0.00663","92.10381"
"70.50000","1.17313","288.63885","1.17968","0.09552","0.00668","92.72044"
"71.00000","1.18103","290.04510","1.18747","0.10332","0.00672","93.17218"
"71.50000","1.18954","291.59604","1.19587","0.11171","0.00677","93.67039"
"72.00000","1.19779","293.10468","1.20402","0.11986","0.00681","94.15502"
"72.50000","1.20598","294.72995","1.21210","0.12795","0.00686","94.67711"
"73.00000","1.21449","296.43881","1.22050","0.13635","0.00691","95.22605"
"73.50000","1.22262","297.89868","1.22853","0.14438","0.00695","95.69501"
"74.00000","1.23139","299.61789","1.23719","0.15304","0.00700","96.24728"
"74.50000","1.23930","301.04028","1.24500","0.16084","0.00705","96.70420"
"75.00000","1.24799","302.69550","1.25358","0.16943","0.00709","97.23591"
"75.50000","1.25603","304.10440","1.26152","0.17737","0.00714","97.68850"
"76.00000","1.26477","305.76010","1.27015","0.18600","0.00719","98.22037"
"76.50000","1.27270","307.19870","1.27798","0.19383","0.00723","98.68249"
"77.00000","1.28117","308.70590","1.28636","0.20221","0.00728","99.16666"
"77.50000","1.28956","310.19070","1.29465","0.21050","0.00733","99.64362"
"78.00000","1.29763","311.67877","1.30262","0.21846","0.00737","100.12164"
"78.50000","1.30616","313.26871","1.31105","0.22689","0.00742","100.63238"
"79.00000","1.31433","314.66043","1.31912","0.23497","0.00747","101.07944"
"79.50000","1.32311","316.36014","1.32778","0.24363","0.00751","101.62545"
"80.00000","1.33095","317.60522","1.33554","0.25139","0.00756","102.02541"
"80.50000","1.33969","319.26978","1.34417","0.26002","0.00761","102.56012"
"81.00000","1.34771","320.54181","1.35211","0.26796","0.00765","102.96874"
"81.50000","1.35636","322.07816","1.36066","0.27650","0.00770","103.46227"
"82.00000","1.36435","323.31476","1.36856","0.28440","0.00775","103.85950"
"82.50000","1.37278","324.90076","1.37688","0.29273","0.00779","104.36898"
"83.00000","1.38123","326.36832","1.38524","0.30109","0.00784","104.84041"
"83.50000","1.38928","327.57333","1.39320","0.30905","0.00789","105.22750"
"84.00000","1.39792","329.22073","1.40174","0.31759","0.00793","105.75671"
"84.50000","1.40597","330.41245","1.40971","0.32555","0.00798","106.13952"
"85.00000","1.41487","332.05377","1.41850","0.33434","0.00803","106.66677"
"85.50000","1.42264","333.29037","1.42618","0.34203","0.00807","107.06401"
"86.00000","1.43134","334.68518","1.43479","0.35064","0.00812","107.51207"
"86.50000","1.43935","336.06070","1.44271","0.35856","0.00817","107.95393"
"87.00000","1.44791","337.39972","1.45118","0.36702","0.00821","108.38406"
"87.50000","1.45609","338.68436","1.45927","0.37512","0.00826","108.79674"
"88.00000","1.46434","340.02222","1.46743","0.38328","0.00831","109.22650"
"88.50000","1.47289","341.29108","1.47590","0.39175","0.00835","109.63410"
"89.00000","1.48094","342.44424","1.48387","0.39972","0.00840","110.00454"
"89.50000","1.48958","343.85818","1.49242","0.40827","0.00845","110.45874"
"90.00000","1.49765","344.76953","1.50043","0.41628","0.00849","110.75150"
"90.50000","1.50649","346.33368","1.50917","0.42502","0.00854","111.25395"
"91.00000","1.51431","347.07565","1.51694","0.43279","0.00859","111.49230"
"91.50000","1.52293","348.14029","1.52550","0.44134","0.00863","111.83430"
"92.00000","1.53115","348.93759","1.53366","0.44951","0.00868","112.09042"
"92.50000","1.53956","349.99985","1.54201","0.45785","0.00873","112.43165"
"93.00000","1.54778","350.69617","1.55019","0.46603","0.00877","112.65533"
"93.50000","1.55606","351.66531","1.55840","0.47425","0.00882","112.96665"
"94.00000","1.56463","352.70349","1.56691","0.48276","0.00887","113.30015"
"94.50000","1.57257","353.37814","1.57480","0.49065","0.00891","113.51687"
"95.00000","1.58130","354.11758","1.58349","0.49934","0.00896","113.75440"
"95.50000","1.58932","354.27563","1.59150","0.50734","0.00901","113.80518"
"96.00000","1.59815","355.24179","1.60026","0.51610","0.00906","114.11554"
"96.50000","1.60594","355.86606","1.60802","0.52386","0.00910","114.31607"
"97.00000","1.61460","356.86563","1.61661","0.53245","0.00915","114.63717"
"97.50000","1.62280","357.74313","1.62475","0.54060","0.00920","114.91905"
"98.00000","1.63110","358.63718","1.63300","0.54884","0.00924","115.20625"
"98.50000","1.63949","359.57996","1.64132","0.55717","0.00929","115.50910"
"99.00000","1.64768","360.57172","1.64946","0.56530","0.00934","115.82769"
"99.50000","1.65638","361.43500","1.65810","0.57394","0.00938","116.10500"
"100.00000","1.66425","362.32581","1.66590","0.58175","0.00943","116.39116"
"100.50000","1.67302","363.25317","1.67462","0.59047","0.00948","116.68906"
"101.00000","1.68097","363.68121","1.68255","0.59839","0.00952","116.82656"
"101.50000","1.68984","364.60422","1.69135","0.60720","0.00957","117.12306"
"102.00000","1.69769","364.93143","1.69918","0.61503","0.00962","117.22817"
"102.50000","1.70618","365.42444","1.70764","0.62349","0.00966","117.38654"
"103.00000","1.71447","365.96570","1.71590","0.63174","0.00971","117.56042"
"103.50000","1.72273","366.55457","1.72411","0.63996","0.00976","117.74958"
"104.00000","1.73113","367.27933","1.73247","0.64832","0.00981","117.98240"
"104.50000","1.73930","367.79941","1.74061","0.65645","0.00985","118.14946"
"105.00000","1.74802","368.95013","1.74926","0.66510","0.00990","118.51911"
"105.50000","1.75592","369.51141","1.75712","0.67296","0.00994","118.69942"
"106.00000","1.76458","370.59326","1.76571","0.68156","0.00999","119.04694"
"106.50000","1.77270","371.30505","1.77378","0.68963","0.01004","119.27560"
"107.00000","1.78146","372.26440","1.78248","0.69833","0.01009","119.58377"
"107.50000","1.78937","372.99182","1.79034","0.70619","0.01013","119.81744"
"108.00000","1.79787","373.80807","1.79879","0.71464","0.01018","120.07965"
"108.50000","1.80620","374.41803","1.80708","0.72293","0.01023","120.27558"
"109.00000","1.81435","374.85291","1.81520","0.73105","0.01027","120.41528"
"109.50000","1.82285","374.89789","1.82371","0.73955","0.01032","120.42973"
"110.00000","1.83099","373.17215","1.83196","0.74780","0.01037","119.87537"
"110.50000","1.83976","371.67267","1.84082","0.75666","0.01042","119.39368"
"111.00000","1.84755","371.35052","1.84863","0.76448","0.01046","119.29020"
"111.50000","1.85636","371.50650","1.85743","0.77328","0.01051","119.34030"
"112.00000","1.86436","371.09570","1.86546","0.78131","0.01056","119.20834"
"112.50000","1.87299","371.18051","1.87408","0.78993","0.01061","119.23559"
"113.00000","1.88104","371.20114","1.88213","0.79798","0.01065","119.24221"
"113.50000","1.88947","371.58807","1.89053","0.80638","0.01070","119.36651"
"114.00000","1.89789","372.04861","1.89893","0.81477","0.01075","119.51445"
"114.50000","1.90596","372.51309","1.90696","0.82281","0.01079","119.66366"
"115.00000","1.91457","373.11380","1.91554","0.83139","0.01084","119.85662"
"115.50000","1.92260","373.58066","1.92353","0.83938","0.01089","120.00659"
"116.00000","1.93147","374.35382","1.93236","0.84821","0.01094","120.25496"
"116.50000","1.93930","374.75034","1.94016","0.85601","0.01098","120.38233"
"117.00000","1.94802","375.14676","1.94886","0.86470","0.01103","120.50967"
"117.50000","1.95606","375.57220","1.95686","0.87271","0.01108","120.64635"
"118.00000","1.96464","376.16245","1.96542","0.88126","0.01112","120.83595"
"118.50000","1.97275","376.71674","1.97348","0.88933","0.01117","121.01401"
"119.00000","1.98105","376.84131","1.98177","0.89762","0.01122","121.05402"
"119.50000","1.98957","377.24081","1.99027","0.90612","0.01126","121.18236"
"120.00000","1.99761","377.81271","1.99827","0.91412","0.01131","121.36607"
"120.50000","2.00617","378.51630","2.00679","0.92263","0.01136","121.59209"
"121.00000","2.01430","378.89563","2.01489","0.93074","0.01140","121.71394"
"121.50000","2.02321","379.66241","2.02375","0.93960","0.01145","121.96026"
"122.00000","2.03099","380.29984","2.03149","0.94734","0.01150","122.16502"
"122.50000","2.03966","380.83560","2.04013","0.95597","0.01155","122.33712"
"123.00000","2.04778","381.34384","2.04822","0.96407","0.01159","122.50039"
"123.50000","2.05621","381.88040","2.05662","0.97246","0.01164","122.67274"
"124.00000","2.06442","382.32779","2.06480","0.98065","0.01169","122.81647"
"124.50000","2.07272","382.81458","2.07307","0.98891","0.01173","122.97284"
"125.00000","2.08130","383.41296","2.08161","0.99745","0.01178","123.16506"
"125.50000","2.08923","383.75522","2.08951","1.00536","0.01183","123.27500"
"126.00000","2.09792","384.36752","2.09817","1.01401","0.01188","123.47169"
"126.50000","2.10594","384.85733","2.10615","1.02200","0.01192","123.62904"
"127.00000","2.11479","385.54523","2.11495","1.03080","0.01197","123.85001"
"127.50000","2.12263","385.86349","2.12278","1.03863","0.01201","123.95225"
"128.00000","2.13133","386.53162","2.13144","1.04728","0.01206","124.16688"
"128.50000","2.13944","386.93970","2.13952","1.05537","0.01211","124.29797"
"129.00000","2.14781","387.45273","2.14785","1.06370","0.01216","124.46277"
"129.50000","2.15615","388.00113","2.15616","1.07201","0.01220","124.63893"
"130.00000","2.16431","388.45465","2.16429","1.08014","0.01225","124.78461"
"130.50000","2.17301","389.22592","2.17294","1.08879","0.01230","125.03237"
"131.00000","2.18093","389.52744","2.18085","1.09669","0.01234","125.12923"
"131.50000","2.18967","390.16254","2.18955","1.10540","0.01239","125.33324"
"132.00000","2.19766","390.43344","2.19752","1.11337","0.01244","125.42027"
"132.50000","2.20650","390.99158","2.20633","1.12218","0.01249","125.59956"
"133.00000","2.21436","391.43060","2.21417","1.13002","0.01253","125.74059"
"133.50000","2.22285","387.69693","2.22288","1.13873","0.01258","124.54121"
"134.00000","2.23115","387.94730","2.23117","1.14701","0.01263","124.62164"
"134.50000","2.23940","388.32092","2.23939","1.15524","0.01267","124.74166"
"135.00000","2.24776","388.66031","2.24773","1.16358","0.01272","124.85068"
"135.50000","2.25596","389.11066","2.25590","1.17175","0.01277","124.99535"
"136.00000","2.26475","389.71158","2.26465","1.18050","0.01282","125.18839"
"136.50000","2.27260","389.96402","2.27250","1.18834","0.01286","125.26948"
"137.00000","2.28131","390.50098","2.28118","1.19702","0.01291","125.44196"
"137.50000","2.28938","390.21854","2.28926","1.20510","0.01296","125.35123"
"138.00000","2.29815","390.57645","2.29800","1.21385","0.01301","125.46621"
"138.50000","2.30603","390.79544","2.30587","1.22172","0.01305","125.53656"
"139.00000","2.31453","391.27838","2.31435","1.23019","0.01310","125.69170"
"139.50000","2.32285","391.60309","2.32265","1.23850","0.01315","125.79600"
"140.00000","2.33100","391.87012","2.33078","1.24663","0.01319","125.88178"
"140.50000","2.33948","392.35394","2.33923","1.25508","0.01324","126.03720"
"141.00000","2.34762","392.74326","2.34735","1.26320","0.01329","126.16226"
"141.50000","2.35640","393.26077","2.35610","1.27195","0.01333","126.32851"
"142.00000","2.36422","393.38376","2.36392","1.27977","0.01338","126.36801"
"142.50000","2.37303","393.86157","2.37270","1.28855","0.01343","126.52150"
"143.00000","2.38102","394.00101","2.38068","1.29653","0.01347","126.56629"
"143.50000","2.38972","394.32660","2.38937","1.30522","0.01352","126.67088"
"144.00000","2.39773","394.48059","2.39737","1.31321","0.01357","126.72035"
"144.50000","2.40610","394.74512","2.40572","1.32157","0.01362","126.80533"
"145.00000","2.41452","394.99966","2.41412","1.32997","0.01366","126.88709"
"145.50000","2.42263","395.13303","2.42223","1.33807","0.01371","126.92993"
"146.00000","2.43122","395.44357","2.43080","1.34665","0.01376","127.02969"
"146.50000","2.43931","395.46564","2.43889","1.35473","0.01380","127.03678"
"147.00000","2.44812","395.94183","2.44767","1.36352","0.01385","127.18975"
"147.50000","2.45594","395.83481","2.45549","1.37134","0.01390","127.15537"
"148.00000","2.46459","395.92697","2.46415","1.37999","0.01395","127.18497"
"148.50000","2.47274","395.40744","2.47233","1.38817","0.01399","127.01808"
"149.00000","2.48134","394.23987","2.48099","1.39683","0.01404","126.64302"
"149.50000","2.48939","392.51422","2.48913","1.40498","0.01409","126.08868"
"150.00000","2.49772","392.19968","2.49748","1.41333","0.01414","125.98765"
"150.50000","2.50627","392.15466","2.50603","1.42188","0.01418","125.97318"
"151.00000","2.51431","392.18744","2.51407","1.42992","0.01423","125.98371"
"151.50000","2.52285","392.26004","2.52261","1.43846","0.01428","126.00703"
"152.00000","2.53100","392.31320","2.53076","1.44661","0.01432","126.02411"
"152.50000","2.53983","392.68344","2.53956","1.45541","0.01437","126.14304"
"153.00000","2.54761","392.66724","2.54735","1.46320","0.01442","126.13784"
"153.50000","2.55632","393.03604","2.55604","1.47188","0.01447","126.25631"
"154.00000","2.56442","393.15182","2.56413","1.47998","0.01451","126.29350"
"154.50000","2.57292","393.35684","2.57262","1.48847","0.01456","126.35937"
"155.00000","2.58105","393.39877","2.58074","1.49659","0.01461","126.37283"
"155.50000","2.58937","393.52869","2.58906","1.50491","0.01465","126.41457"
"156.00000","2.59792","393.88971","2.59759","1.51344","0.01470","126.53054"
"156.50000","2.60592","393.92282","2.60558","1.52143","0.01475","126.54118"
"157.00000","2.61460","394.17874","2.61425","1.53010","0.01480","126.62338"
"157.50000","2.62263","394.20822","2.62228","1.53813","0.01484","126.63286"
"158.00000","2.63146","394.66522","2.63108","1.54693","0.01489","126.77966"
"158.50000","2.63932","394.61050","2.63895","1.55479","0.01494","126.76208"
"159.00000","2.64796","394.92493","2.64757","1.56342","0.01498","126.86308"
"159.50000","2.65609","394.98523","2.65570","1.57154","0.01503","126.88245"
"160.00000","2.66455","395.24451","2.66414","1.57999","0.01508","126.96574"
"160.50000","2.67281","395.36600","2.67240","1.58824","0.01513","127.00478"
"161.00000","2.68104","395.72324","2.68060","1.59645","0.01517","127.11953"
"161.50000","2.68963","395.91690","2.68918","1.60503","0.01522","127.18174"
"162.00000","2.69758","395.93103","2.69713","1.61298","0.01527","127.18628"
"162.50000","2.70621","396.27063","2.70574","1.62159","0.01531","127.29537"
"163.00000","2.71432","396.36636","2.71385","1.62970","0.01536","127.32613"
"163.50000","2.72311","396.80414","2.72262","1.63846","0.01541","127.46675"
"164.00000","2.73098","396.73965","2.73049","1.64633","0.01545","127.44604"
"164.50000","2.73957","397.14011","2.73905","1.65490","0.01550","127.57468"
"165.00000","2.74784","397.25015","2.74732","1.66316","0.01555","127.61002"
"165.50000","2.75616","397.33426","2.75564","1.67148","0.01560","127.63705"
"166.00000","2.76442","397.55408","2.76388","1.67972","0.01564","127.70766"
"166.50000","2.77268","397.74649","2.77213","1.68798","0.01569","127.76946"
"167.00000","2.78135","397.82663","2.78079","1.69664","0.01574","127.79521"
"167.50000","2.78923","397.95264","2.78867","1.70451","0.01578","127.83569"
"168.00000","2.79798","398.35187","2.79739","1.71324","0.01583","127.96394"
"168.50000","2.80599","398.39200","2.80540","1.72125","0.01588","127.97682"
"169.00000","2.81478","398.75516","2.81417","1.73002","0.01593","128.09349"
"169.50000","2.82265","398.67874","2.82205","1.73790","0.01597","128.06894"
"170.00000","2.83128","399.08252","2.83065","1.74649","0.01602","128.19864"
"170.50000","2.83948","399.25436","2.83885","1.75469","0.01607","128.25385"
"171.00000","2.84774","399.36569","2.84709","1.76294","0.01611","128.28961"
"171.50000","2.85614","399.39764","2.85549","1.77134","0.01616","128.29987"
"172.00000","2.86428","399.57635","2.86362","1.77947","0.01621","128.35728"
"172.50000","2.87304","399.99438","2.87236","1.78821","0.01626","128.49156"
"173.00000","2.88090","399.94659","2.88022","1.79607","0.01630","128.47621"
"173.50000","2.88969","400.08932","2.88901","1.80486","0.01635","128.52206"
"174.00000","2.89766","400.20786","2.89697","1.81281","0.01640","128.56013"
"174.50000","2.90648","400.56812","2.90577","1.82161","0.01645","128.67587"
"175.00000","2.91442","400.57986","2.91371","1.82956","0.01649","128.67964"
"175.50000","2.92284","400.60248","2.92213","1.83798","0.01654","128.68690"
"176.00000","2.93118","400.69809","2.93046","1.84631","0.01659","128.71762"
"176.50000","2.93931","400.75784","2.93859","1.85443","0.01663","128.73682"
"177.00000","2.94778","400.76300","2.94706","1.86291","0.01668","128.73846"
"177.50000","2.95595","400.81967","2.95522","1.87107","0.01673","128.75667"
"178.00000","2.96470","401.02649","2.96396","1.87981","0.01678","128.82310"
"178.50000","2.97263","400.94968","2.97190","1.88774","0.01682","128.79843"
"179.00000","2.98135","401.19226","2.98061","1.89645","0.01687","128.87636"
"179.50000","2.98940","400.94330","2.98867","1.90451","0.01692","128.79639"
"180.00000","2.99806","401.03778","2.99732","1.91316","0.01696","128.82674"
"180.50000","3.00602","400.86719","3.00529","1.92114","0.01701","128.77194"
"181.00000","3.01446","400.82666","3.01373","1.92958","0.01706","128.75893"
"181.50000","3.02287","400.77908","3.02215","1.93799","0.01710","128.74364"
"182.00000","3.03094","400.63940","3.03023","1.94607","0.01715","128.69876"
"182.50000","3.03953","400.73782","3.03881","1.95466","0.01720","128.73038"
"183.00000","3.04763","400.49655","3.04692","1.96276","0.01724","128.65288"
"183.50000","3.05647","400.54797","3.05576","1.97161","0.01729","128.66940"
"184.00000","3.06426","400.06195","3.06358","1.97943","0.01734","128.51328"
"184.50000","3.07307","399.73157","3.07241","1.98825","0.01739","128.40714"
"185.00000","3.08104","399.17050","3.08040","1.99625","0.01743","128.22691"
"185.50000","3.08965","398.97021","3.08903","2.00488","0.01748","128.16257"
"186.00000","3.09773","398.31592","3.09714","2.01299","0.01753","127.95238"
"186.50000","3.10606","397.91110","3.10550","2.02135","0.01758","127.82234"
"187.00000","3.11458","397.40842","3.11405","2.02989","0.01762","127.66087"
"187.50000","3.12257","396.88101","3.12207","2.03792","0.01767","127.49145"
"188.00000","3.13126","396.57162","3.13077","2.04662","0.01772","127.39206"
"188.50000","3.13929","396.10477","3.13883","2.05467","0.01776","127.24209"
"189.00000","3.14818","396.11011","3.14772","2.06357","0.01782","127.24380"
"189.50000","3.15602","395.68985","3.15558","2.07143","0.01786","127.10880"
"190.00000","3.16466","395.51160","3.16423","2.08008","0.01791","127.05154"
"190.50000","3.17276","395.24796","3.17235","2.08820","0.01795","126.96685"
"191.00000","3.18120","395.02829","3.18081","2.09665","0.01800","126.89629"
"191.50000","3.18940","394.76511","3.18902","2.10487","0.01805","126.81174"
"192.00000","3.19766","394.49121","3.19729","2.11314","0.01810","126.72376"
"192.50000","3.20626","394.42880","3.20589","2.12174","0.01814","126.70371"
"193.00000","3.21428","394.18164","3.21393","2.12977","0.01819","126.62432"
"193.50000","3.22295","393.75885","3.22262","2.13847","0.01824","126.48850"
"194.00000","3.23100","393.08249","3.23072","2.14656","0.01828","126.27123"
"194.50000","3.23981","392.76065","3.23954","2.15539","0.01833","126.16785"
"195.00000","3.24763","391.99274","3.24741","2.16325","0.01838","125.92117"
"195.50000","3.25624","391.59879","3.25604","2.17188","0.01843","125.79462"
"196.00000","3.26442","388.75854","3.26439","2.18023","0.01848","124.88224"
"196.50000","3.27280","387.71234","3.27283","2.18868","0.01852","124.54617"
"197.00000","3.28110","386.93277","3.28118","2.19703","0.01857","124.29574"
"197.50000","3.28936","386.36188","3.28948","2.20533","0.01862","124.11235"
"198.00000","3.29803","385.98932","3.29817","2.21401","0.01867","123.99267"
"198.50000","3.30589","385.68637","3.30605","2.22190","0.01871","123.89536"
"199.00000","3.31471","385.60376","3.31488","2.23072","0.01876","123.86881"
"199.50000","3.32262","385.37253","3.32280","2.23865","0.01881","123.79453"
"200.00000","3.33147","385.34329","3.33165","2.24750","0.01886","123.78514"
"200.50000","3.33932","385.27069","3.33951","2.25536","0.01890","123.76183"
"201.00000","3.34789","385.30798","3.34807","2.26392","0.01895","123.77380"
"201.50000","3.35612","385.26099","3.35631","2.27215","0.01900","123.75871"
"202.00000","3.36441","385.27347","3.36459","2.28044","0.01904","123.76272"
"202.50000","3.37284","385.38635","3.37302","2.28887","0.01909","123.79898"
"203.00000","3.38096","385.39462","3.38113","2.29698","0.01914","123.80164"
"203.50000","3.38968","385.62778","3.38984","2.30569","0.01919","123.87653"
"204.00000","3.39757","385.38852","3.39775","2.31359","0.01923","123.79967"
"204.50000","3.40632","385.54764","3.40648","2.32233","0.01928","123.85078"
"205.00000","3.41436","385.43045","3.41453","2.33038","0.01933","123.81314"
"205.50000","3.42315","385.73816","3.42331","2.33916","0.01937","123.91199"
"206.00000","3.43102","385.75443","3.43117","2.34702","0.01942","123.91721"
"206.50000","3.43947","385.62387","3.43964","2.35548","0.01947","123.87527"
"207.00000","3.44786","385.67422","3.44802","2.36387","0.01951","123.89145"
"207.50000","3.45609","385.69125","3.45625","2.37209","0.01956","123.89692"
"208.00000","3.46453","385.76059","3.46469","2.38054","0.01961","123.91920"
"208.50000","3.47267","385.85886","3.47282","2.38866","0.01966","123.95076"
"209.00000","3.48139","386.05212","3.48152","2.39737","0.01970","124.01285"
"209.50000","3.48921","385.95322","3.48935","2.40520","0.01975","123.98107"
"210.00000","3.49797","386.16370","3.49810","2.41395","0.01980","124.04868"
"210.50000","3.50600","386.09985","3.50613","2.42198","0.01984","124.02818"
"211.00000","3.51474","386.39301","3.51486","2.43070","0.01989","124.12234"
"211.50000","3.52270","386.30215","3.52282","2.43866","0.01994","124.09316"
"212.00000","3.53118","386.50043","3.53129","2.44714","0.01999","124.15685"
"212.50000","3.53958","386.65442","3.53967","2.45552","0.02003","124.20632"
"213.00000","3.54764","386.62796","3.54774","2.46358","0.02008","124.19782"
"213.50000","3.55621","386.81601","3.55630","2.47214","0.02013","124.25823"
"214.00000","3.56427","386.93976","3.56435","2.48020","0.02017","124.29798"
"214.50000","3.57307","386.97440","3.57315","2.48900","0.02022","124.30911"
"215.00000","3.58092","386.97821","3.58100","2.49685","0.02027","124.31033"
"215.50000","3.58973","387.44318","3.58978","2.50562","0.02032","124.45969"
"216.00000","3.59770","387.32028","3.59775","2.51360","0.02036","124.42022"
"216.50000","3.60638","387.61053","3.60642","2.52226","0.02041","124.51346"
"217.00000","3.61444","387.62064","3.61447","2.53032","0.02046","124.51670"
"217.50000","3.62274","387.70834","3.62277","2.53861","0.02050","124.54488"
"218.00000","3.63122","387.81989","3.63124","2.54709","0.02055","124.58071"
"218.50000","3.63927","387.89691","3.63929","2.55514","0.02060","124.60545"
"219.00000","3.64790","388.14575","3.64791","2.56375","0.02065","124.68539"
"219.50000","3.65598","388.20200","3.65598","2.57183","0.02069","124.70345"
"220.00000","3.66480","388.52023","3.66478","2.58063","0.02074","124.80569"
"220.50000","3.67263","388.28073","3.67263","2.58847","0.02079","124.72874"
"221.00000","3.68131","388.68018","3.68128","2.59713","0.02084","124.85706"
"221.50000","3.68944","388.59268","3.68941","2.60526","0.02088","124.82896"
"222.00000","3.69799","388.85422","3.69794","2.61379","0.02093","124.91297"
"222.50000","3.70610","388.85617","3.70605","2.62190","0.02098","124.91360"
"223.00000","3.71437","389.02234","3.71432","2.63016","0.02102","124.96698"
"223.50000","3.72293","389.05075","3.72287","2.63872","0.02107","124.97610"
"224.00000","3.73089","389.05438","3.73083","2.64668","0.02112","124.97727"
"224.50000","3.73958","389.29697","3.73951","2.65536","0.02116","125.05520"
"225.00000","3.74761","389.23627","3.74755","2.66339","0.02121","125.03570"
"225.50000","3.75650","389.56537","3.75641","2.67226","0.02126","125.14142"
"226.00000","3.76433","389.43704","3.76425","2.68010","0.02130","125.10020"
"226.50000","3.77306","389.65710","3.77297","2.68882","0.02135","125.17088"
"227.00000","3.78111","389.59525","3.78103","2.69687","0.02140","125.15102"
"227.50000","3.78952","389.70020","3.78943","2.70528","0.02145","125.18473"
"228.00000","3.79775","389.65576","3.79766","2.71351","0.02149","125.17046"
"228.50000","3.80600","389.64902","3.80591","2.72176","0.02154","125.16829"
"229.00000","3.81462","389.70132","3.81453","2.73037","0.02159","125.18509"
"229.50000","3.82257","389.62268","3.82248","2.73833","0.02163","125.15983"
"230.00000","3.83135","389.42044","3.83127","2.74712","0.02168","125.09486"
"230.50000","3.83928","388.76566","3.83925","2.75509","0.02173","124.88452"
"231.00000","3.84818","388.68753","3.84815","2.76399","0.02178","124.85943"
"231.50000","3.85604","388.16241","3.85604","2.77188","0.02182","124.69074"
"232.00000","3.86458","388.07233","3.86458","2.78043","0.02187","124.66180"
"232.50000","3.87278","387.55414","3.87282","2.78867","0.02192","124.49534"
"233.00000","3.88109","387.23999","3.88115","2.79700","0.02197","124.39442"
"233.50000","3.88948","387.12503","3.88954","2.80539","0.02201","124.35750"
"234.00000","3.89767","386.80792","3.89776","2.81361","0.02206","124.25563"
"234.50000","3.90638","386.65543","3.90648","2.82232","0.02211","124.20664"
"235.00000","3.91429","386.25687","3.91441","2.83026","0.02215","124.07861"
"235.50000","3.92300","386.09613","3.92314","2.83898","0.02220","124.02698"
"236.00000","3.93105","385.70905","3.93121","2.84705","0.02225","123.90263"
"236.50000","3.93980","385.56052","3.93997","2.85582","0.02230","123.85493"
"237.00000","3.94770","385.19559","3.94789","2.86374","0.02234","123.73769"
"237.50000","3.95617","385.02637","3.95638","2.87222","0.02239","123.68333"
"238.00000","3.96450","384.82144","3.96472","2.88056","0.02244","123.61751"
"238.50000","3.97269","384.66537","3.97292","2.88877","0.02249","123.56738"
"239.00000","3.98115","384.43958","3.98139","2.89724","0.02253","123.49484"
"239.50000","3.98930","383.92526","3.98958","2.90542","0.02258","123.32963"
"240.00000","3.99809","383.86197","3.99836","2.91421","0.02263","123.30930"
"240.50000","4.00595","383.42358","4.00626","2.92210","0.02267","123.16847"
"241.00000","4.01474","383.31516","4.01505","2.93090","0.02272","123.13364"
"241.50000","4.02268","382.92303","4.02301","2.93886","0.02277","123.00768"
"242.00000","4.03140","382.91611","4.03174","2.94758","0.02282","123.00546"
"242.50000","4.03936","382.43829","4.03973","2.95557","0.02286","122.85196"
"243.00000","4.04785","382.23596","4.04823","2.96408","0.02291","122.78696"
"243.50000","4.05619","382.06750","4.05658","2.97243","0.02296","122.73285"
"244.00000","4.06429","381.55179","4.06472","2.98056","0.02301","122.56718"
"244.50000","4.07288","381.44339","4.07331","2.98916","0.02305","122.53236"
"245.00000","4.08095","381.19366","4.08140","2.99725","0.02310","122.45215"
"245.50000","4.08976","381.05402","4.09022","3.00606","0.02315","122.40729"
"246.00000","4.09762","380.58270","4.09811","3.01395","0.02319","122.25588"
"246.50000","4.10633","380.43384","4.10682","3.02267","0.02324","122.20806"
"247.00000","4.11434","380.17728","4.11486","3.03070","0.02329","122.12565"
"247.50000","4.12305","380.16678","4.12356","3.03941","0.02334","122.12228"
"248.00000","4.13107","379.89371","4.13160","3.04745","0.02338","122.03455"
"248.50000","4.13943","379.82269","4.13997","3.05582","0.02343","122.01174"
"249.00000","4.14792","379.90085","4.14845","3.06429","0.02348","122.03685"
"249.50000","4.15601","379.91791","4.15654","3.07238","0.02352","122.04233"
"250.00000","4.16456","380.00018","4.16509","3.08093","0.02357","122.06876"
"250.50000","4.17271","379.83121","4.17325","3.08909","0.02362","122.01448"
"251.00000","4.18143","380.11441","4.18195","3.09779","0.02367","122.10545"
"251.50000","4.18928","379.96011","4.18981","3.10566","0.02371","122.05589"
"252.00000","4.19791","380.12167","4.19843","3.11428","0.02376","122.10779"
"252.50000","4.20605","380.15759","4.20657","3.12241","0.02381","122.11932"
"253.00000","4.21465","380.32056","4.21515","3.13100","0.02386","122.17168"
"253.50000","4.22274","380.29187","4.22325","3.13909","0.02390","122.16246"
"254.00000","4.23110","380.55713","4.23159","3.14743","0.02395","122.24767"
"254.50000","4.23960","380.53958","4.24009","3.15594","0.02400","122.24203"
"255.00000","4.24762","380.55545","4.24811","3.16396","0.02404","122.24713"
"255.50000","4.25628","380.20584","4.25679","3.17263","0.02409","122.13483"
"256.00000","4.26433","380.09418","4.26485","3.18070","0.02414","122.09895"
"256.50000","4.27311","380.21954","4.27362","3.18946","0.02419","122.13923"
"257.00000","4.28097","379.87628","4.28150","3.19735","0.02423","122.02896"
"257.50000","4.28970","380.06592","4.29022","3.20607","0.02428","122.08987"
"258.00000","4.29775","379.86642","4.29829","3.21413","0.02433","122.02579"
"258.50000","4.30623","380.02823","4.30675","3.22260","0.02438","122.07777"
"259.00000","4.31445","380.09760","4.31497","3.23082","0.02442","122.10005"
"259.50000","4.32268","380.04279","4.32321","3.23905","0.02447","122.08244"
"260.00000","4.33124","380.24457","4.33175","3.24759","0.02452","122.14726"
"260.50000","4.33923","380.19794","4.33974","3.25559","0.02456","122.13229"
"261.00000","4.34793","380.27209","4.34844","3.26429","0.02461","122.15611"
"261.50000","4.35596","380.21805","4.35647","3.27231","0.02466","122.13875"
"262.00000","4.36483","380.48486","4.36533","3.28117","0.02471","122.22446"
"262.50000","4.37268","380.29010","4.37319","3.28903","0.02475","122.16189"
"263.00000","4.38125","380.25293","4.38176","3.29760","0.02480","122.14995"
"263.50000","4.38946","380.26120","4.38997","3.30582","0.02485","122.15260"
"264.00000","4.39786","380.05765","4.39838","3.31423","0.02489","122.08722"
"264.50000","4.40611","379.96469","4.40664","3.32248","0.02494","122.05736"
"265.00000","4.41440","380.11084","4.41492","3.33076","0.02499","122.10431"
"265.50000","4.42299","380.21179","4.42350","3.33935","0.02504","122.13673"
"266.00000","4.43089","380.20184","4.43140","3.34725","0.02508","122.13354"
"266.50000","4.43957","380.41711","4.44007","3.35592","0.02513","122.20269"
"267.00000","4.44767","380.38705","4.44816","3.36401","0.02518","122.19304"
"267.50000","4.45649","380.65674","4.45697","3.37282","0.02523","122.27966"
"268.00000","4.46433","380.58267","4.46481","3.38066","0.02527","122.25587"
"268.43100","4.47149","380.65842","4.47197","3.38782","0.02531","122.28020"