File: flexion/5_axis/Specimen_RawData_15.csv
Specimen properties : Specimen label,"G4"
Specimen properties : Support span,"72.00",mm
Specimen properties : Thickness,"4.01",mm
Specimen properties : Width,"13.45",mm
Maximum Load : Maximum Load,"1013",N
Tangent Modulus of Elasticity : Tangent Modulus of Elasticity,"56344381149.37130",Pa
Test : Rate 1,"1.00000",mm/min
Specimen notes : Specimen note 1,""

Time,Displacement,Load,Flexure extension,Corrected extension,Flexure strain (Corrected extension),Flexure stress
(s),(mm),(N),(mm),(mm),(mm/mm),(MPa)
"0.00000","0.00000","48.30269","0.05385","-1.05547","0.00025","24.12037"
"0.40000","0.00478","50.23481","0.05837","-1.05096","0.00027","25.08519"
"0.80000","0.01134","53.14886","0.06455","-1.04478","0.00030","26.54035"
"1.20000","0.01799","56.06143","0.07081","-1.03852","0.00033","27.99477"
"1.60000","0.02473","58.92774","0.07718","-1.03214","0.00036","29.42609"
"2.00000","0.03156","61.89180","0.08366","-1.02566","0.00039","30.90622"
"2.40000","0.03847","64.79383","0.09024","-1.01909","0.00042","32.35537"
"2.80000","0.04480","67.37425","0.09626","-1.01306","0.00045","33.64393"
"3.20000","0.05141","69.96877","0.10257","-1.00675","0.00048","34.93952"
"3.60000","0.05789","72.66683","0.10874","-1.00059","0.00050","36.28682"
"4.00000","0.06468","75.23867","0.11522","-0.99411","0.00053","37.57109"
"4.40000","0.07167","78.14614","0.12188","-0.98745","0.00057","39.02296"
"4.80000","0.07834","80.81897","0.12823","-0.98109","0.00060","40.35767"
"5.20000","0.08496","83.44810","0.13454","-0.97478","0.00062","41.67055"
"5.60000","0.09138","85.93715","0.14067","-0.96865","0.00065","42.91348"
"6.00000","0.09800","88.69087","0.14699","-0.96233","0.00068","44.28857"
"6.40000","0.10458","91.34810","0.15332","-0.95601","0.00071","45.61548"
"6.80000","0.11153","94.20776","0.15998","-0.94934","0.00074","47.04348"
"7.20000","0.11847","97.17997","0.16663","-0.94269","0.00077","48.52768"
"7.60000","0.12489","99.37811","0.17285","-0.93648","0.00080","49.62533"
"8.00000","0.13149","102.38974","0.17915","-0.93017","0.00083","51.12922"
"8.40000","0.13796","105.17242","0.18535","-0.92398","0.00086","52.51878"
"8.80000","0.14464","108.12647","0.19174","-0.91759","0.00089","53.99391"
"9.20000","0.15146","111.13146","0.19826","-0.91106","0.00092","55.49448"
"9.60000","0.15834","114.18590","0.20485","-0.90448","0.00095","57.01974"
"10.00000","0.16500","117.19231","0.21121","-0.89812","0.00098","58.52102"
"10.40000","0.17145","120.11190","0.21737","-0.89195","0.00101","59.97894"
"10.80000","0.17800","122.94447","0.22365","-0.88568","0.00104","61.39340"
"11.20000","0.18459","125.94180","0.22994","-0.87938","0.00107","62.89015"
"11.60000","0.19140","129.10806","0.23645","-0.87288","0.00110","64.47125"
"12.00000","0.19850","132.39893","0.24322","-0.86610","0.00113","66.11457"
"12.40000","0.20497","135.34782","0.24940","-0.85992","0.00116","67.58713"
"12.80000","0.21152","138.33983","0.25567","-0.85366","0.00119","69.08121"
"13.20000","0.21803","141.42094","0.26188","-0.84745","0.00122","70.61980"
"13.60000","0.22465","144.44431","0.26820","-0.84112","0.00124","72.12954"
"14.00000","0.23136","147.66078","0.27460","-0.83473","0.00127","73.73572"
"14.40000","0.23821","150.80042","0.28114","-0.82818","0.00130","75.30352"
"14.80000","0.24508","154.11621","0.28770","-0.82163","0.00134","76.95929"
"15.20000","0.25149","157.15114","0.29381","-0.81552","0.00136","78.47481"
"15.60000","0.25814","160.32147","0.30018","-0.80915","0.00139","80.05794"
"16.00000","0.26462","163.35495","0.30641","-0.80292","0.00142","81.57274"
"16.40000","0.27132","166.57416","0.31283","-0.79650","0.00145","83.18027"
"16.80000","0.27837","169.99101","0.31959","-0.78974","0.00148","84.88651"
"17.20000","0.28490","173.04131","0.32586","-0.78347","0.00151","86.40971"
"17.60000","0.29158","176.24304","0.33227","-0.77706","0.00154","88.00851"
"18.00000","0.29803","179.33336","0.33845","-0.77087","0.00157","89.55170"
"18.40000","0.30470","182.62480","0.34485","-0.76447","0.00160","91.19530"
"18.80000","0.31129","185.72475","0.35118","-0.75815","0.00163","92.74329"
"19.20000","0.31820","189.06636","0.35780","-0.75153","0.00166","94.41196"
"19.60000","0.32513","192.51888","0.36444","-0.74489","0.00169","96.13600"
"20.00000","0.33151","195.56721","0.37055","-0.73877","0.00172","97.65821"
"20.40000","0.33815","198.85997","0.37691","-0.73241","0.00175","99.30248"
"20.80000","0.34459","201.72147","0.38312","-0.72621","0.00178","100.73139"
"21.20000","0.35134","205.22302","0.38958","-0.71974","0.00181","102.47993"
"21.60000","0.35820","208.76711","0.39616","-0.71316","0.00184","104.24969"
"22.00000","0.36505","211.91116","0.40276","-0.70657","0.00187","105.81971"
"22.40000","0.37166","215.19762","0.40911","-0.70022","0.00190","107.46083"
"22.80000","0.37808","218.27948","0.41528","-0.69404","0.00193","108.99979"
"23.20000","0.38471","221.59477","0.42165","-0.68768","0.00196","110.65530"
"23.60000","0.39124","224.79652","0.42792","-0.68140","0.00199","112.25413"
"24.00000","0.39809","228.22372","0.43450","-0.67483","0.00202","113.96553"
"24.40000","0.40509","231.69868","0.44122","-0.66811","0.00205","115.70078"
"24.80000","0.41164","234.91080","0.44752","-0.66181","0.00208","117.30478"
"25.20000","0.41816","238.05119","0.45378","-0.65554","0.00211","118.87296"
"25.60000","0.42470","241.29439","0.46006","-0.64927","0.00214","120.49248"
"26.00000","0.43128","244.49606","0.46639","-0.64293","0.00216","122.09126"
"26.40000","0.43805","248.01050","0.47289","-0.63644","0.00219","123.84623"
"26.80000","0.44493","251.34047","0.47951","-0.62982","0.00223","125.50908"
"27.20000","0.45174","254.81319","0.48605","-0.62327","0.00226","127.24321"
"27.60000","0.45812","258.04102","0.49219","-0.61713","0.00228","128.85506"
"28.00000","0.46477","261.21268","0.49859","-0.61073","0.00231","130.43886"
"28.40000","0.47126","264.34619","0.50485","-0.60448","0.00234","132.00360"
"28.80000","0.47799","267.85495","0.51131","-0.59802","0.00237","133.75574"
"29.20000","0.48506","271.46399","0.51810","-0.59123","0.00240","135.55794"
"29.60000","0.49165","274.64468","0.52444","-0.58488","0.00243","137.14624"
"30.00000","0.49826","277.93286","0.53080","-0.57853","0.00246","138.78822"
"30.40000","0.50470","281.14825","0.53699","-0.57233","0.00249","140.39386"
"30.80000","0.51136","284.46490","0.54340","-0.56593","0.00252","142.05006"
"31.20000","0.51793","287.75626","0.54972","-0.55960","0.00255","143.69362"
"31.60000","0.52481","291.28693","0.55633","-0.55299","0.00258","145.45670"
"32.00000","0.53179","294.96017","0.56307","-0.54625","0.00261","147.29097"
"32.40000","0.53818","297.95078","0.56926","-0.54007","0.00264","148.78435"
"32.80000","0.54484","301.38077","0.57569","-0.53363","0.00267","150.49715"
"33.20000","0.55129","304.55707","0.58193","-0.52739","0.00270","152.08325"
"33.60000","0.55795","308.00061","0.58836","-0.52097","0.00273","153.80283"
"34.00000","0.56486","311.60330","0.59503","-0.51430","0.00276","155.60185"
"34.40000","0.57164","314.94836","0.60158","-0.50775","0.00279","157.27225"
"34.80000","0.57836","318.28183","0.60808","-0.50124","0.00282","158.93684"
"35.20000","0.58471","321.52118","0.61421","-0.49511","0.00285","160.55444"
"35.60000","0.59136","324.78522","0.62065","-0.48868","0.00288","162.18436"
"36.00000","0.59789","328.05057","0.62696","-0.48237","0.00291","163.81494"
"36.40000","0.60477","331.62964","0.63360","-0.47573","0.00294","165.60219"
"36.80000","0.61176","335.26193","0.64034","-0.46898","0.00297","167.41600"
"37.20000","0.61831","338.46371","0.64668","-0.46265","0.00300","169.01485"
"37.60000","0.62487","341.77203","0.65302","-0.45631","0.00303","170.66689"
"38.00000","0.63132","345.08530","0.65926","-0.45007","0.00306","172.32138"
"38.40000","0.63794","348.41382","0.66566","-0.44366","0.00309","173.98352"
"38.80000","0.64472","351.88043","0.67222","-0.43710","0.00312","175.71460"
"39.20000","0.65165","355.29834","0.67893","-0.43039","0.00315","177.42136"
"39.60000","0.65842","358.83472","0.68548","-0.42385","0.00318","179.18729"
"40.00000","0.66482","361.96976","0.69167","-0.41765","0.00321","180.75279"
"40.40000","0.67141","365.36935","0.69805","-0.41128","0.00324","182.45041"
"40.80000","0.67795","368.72485","0.70437","-0.40495","0.00327","184.12601"
"41.20000","0.68465","372.04095","0.71086","-0.39846","0.00330","185.78194"
"41.60000","0.69167","375.72455","0.71764","-0.39169","0.00333","187.62137"
"42.00000","0.69830","379.12112","0.72406","-0.38527","0.00336","189.31747"
"42.40000","0.70493","382.46237","0.73047","-0.37886","0.00339","190.98596"
"42.80000","0.71140","385.75940","0.73673","-0.37260","0.00342","192.63235"
"43.20000","0.71800","389.13516","0.74311","-0.36621","0.00345","194.31807"
"43.60000","0.72466","392.33911","0.74959","-0.35973","0.00348","195.91800"
"44.00000","0.73148","395.94815","0.75621","-0.35312","0.00351","197.72020"
"44.40000","0.73845","399.49542","0.76297","-0.34636","0.00354","199.49156"
"44.80000","0.74479","402.66257","0.76913","-0.34020","0.00357","201.07310"
"45.20000","0.75149","406.19882","0.77563","-0.33370","0.00360","202.83896"
"45.60000","0.75797","409.44336","0.78192","-0.32740","0.00363","204.45915"
"46.00000","0.76466","412.87500","0.78842","-0.32091","0.00366","206.17278"
"46.40000","0.77158","416.34329","0.79514","-0.31419","0.00369","207.90469"
"46.80000","0.77830","419.87909","0.80166","-0.30766","0.00372","209.67033"
"47.20000","0.78500","423.29160","0.80816","-0.30116","0.00375","211.37439"
"47.60000","0.79143","426.48911","0.81441","-0.29492","0.00378","212.97110"
"48.00000","0.79801","429.86316","0.82080","-0.28853","0.00381","214.65596"
"48.40000","0.80457","433.21332","0.82717","-0.28216","0.00384","216.32889"
"48.80000","0.81146","436.66690","0.83386","-0.27546","0.00387","218.05347"
"49.20000","0.81846","440.41656","0.84065","-0.26868","0.00390","219.92590"
"49.60000","0.82493","443.58731","0.84694","-0.26239","0.00393","221.50923"
"50.00000","0.83157","447.02505","0.85338","-0.25595","0.00396","223.22591"
"50.40000","0.83797","450.17801","0.85961","-0.24972","0.00399","224.80035"
"50.80000","0.84461","453.64258","0.86605","-0.24328","0.00402","226.53043"
"51.20000","0.85139","457.10764","0.87263","-0.23670","0.00405","228.26073"
"51.60000","0.85832","460.64969","0.87935","-0.22997","0.00408","230.02948"
"52.00000","0.86505","464.12006","0.88589","-0.22344","0.00411","231.76245"
"52.40000","0.87146","467.34735","0.89211","-0.21721","0.00414","233.37402"
"52.80000","0.87808","470.59311","0.89855","-0.21078","0.00417","234.99483"
"53.20000","0.88460","473.90833","0.90489","-0.20444","0.00420","236.65030"
"53.60000","0.89135","477.42639","0.91143","-0.19789","0.00423","238.40707"
"54.00000","0.89841","481.07846","0.91828","-0.19104","0.00426","240.23077"
"54.40000","0.90503","484.42715","0.92471","-0.18462","0.00429","241.90297"
"54.80000","0.91156","487.66736","0.93106","-0.17827","0.00432","243.52100"
"55.20000","0.91804","490.88037","0.93736","-0.17196","0.00435","245.12544"
"55.60000","0.92463","494.25085","0.94378","-0.16555","0.00438","246.80852"
"56.00000","0.93129","497.50992","0.95028","-0.15905","0.00441","248.43597"
"56.40000","0.93820","501.22998","0.95701","-0.15232","0.00444","250.29361"
"56.80000","0.94515","504.67923","0.96378","-0.14554","0.00447","252.01602"
"57.20000","0.95151","507.82840","0.96998","-0.13934","0.00450","253.58859"
"57.60000","0.95819","511.28915","0.97649","-0.13283","0.00453","255.31674"
"58.00000","0.96463","514.46838","0.98277","-0.12656","0.00456","256.90433"
"58.40000","0.97129","517.90210","0.98926","-0.12007","0.00459","258.61899"
"58.80000","0.97823","521.39557","0.99602","-0.11331","0.00462","260.36346"
"59.20000","0.98494","524.82330","1.00256","-0.10676","0.00465","262.07513"
"59.60000","0.99164","528.24866","1.00909","-0.10024","0.00468","263.78561"
"60.00000","0.99808","531.48169","1.01537","-0.09396","0.00471","265.40005"
"60.40000","1.00474","534.85394","1.02185","-0.08747","0.00474","267.08405"
"60.80000","1.01127","538.09222","1.02823","-0.08110","0.00477","268.70111"
"61.20000","1.01817","541.63696","1.03495","-0.07438","0.00480","270.47119"
"61.60000","1.02515","545.14001","1.04176","-0.06756","0.00484","272.22049"
"62.00000","1.03156","548.48383","1.04801","-0.06131","0.00486","273.89023"
"62.40000","1.03816","551.71912","1.05446","-0.05487","0.00489","275.50580"
"62.80000","1.04467","554.96973","1.06081","-0.04852","0.00492","277.12903"
"63.20000","1.05131","558.26184","1.06729","-0.04204","0.00495","278.77298"
"63.60000","1.05810","561.74573","1.07391","-0.03542","0.00498","280.51270"
"64.00000","1.06505","565.22491","1.08069","-0.02864","0.00502","282.25006"
"64.40000","1.07177","568.62781","1.08724","-0.02208","0.00505","283.94931"
"64.80000","1.07811","571.78308","1.09343","-0.01589","0.00507","285.52493"
"65.20000","1.08473","575.30475","1.09988","-0.00945","0.00510","287.28351"
"65.60000","1.09128","578.47961","1.10627","-0.00305","0.00513","288.86890"
"66.00000","1.09802","581.83600","1.11285","0.00353","0.00516","290.54495"
"66.40000","1.10506","585.30157","1.11973","0.01040","0.00520","292.27551"
"66.80000","1.11166","588.68921","1.12616","0.01683","0.00523","293.96716"
"67.20000","1.11827","591.89252","1.13262","0.02330","0.00526","295.56674"
"67.60000","1.12470","595.20044","1.13890","0.02958","0.00529","297.21860"
"68.00000","1.13129","598.53821","1.14534","0.03601","0.00532","298.88535"
"68.40000","1.13795","601.80652","1.15185","0.04253","0.00535","300.51740"
"68.80000","1.14487","605.24664","1.15862","0.04930","0.00538","302.23526"
"69.20000","1.15185","608.81537","1.16544","0.05611","0.00541","304.01733"
"69.60000","1.15816","611.99457","1.17161","0.06228","0.00544","305.60489"
"70.00000","1.16478","615.18243","1.17809","0.06876","0.00547","307.19678"
"70.40000","1.17132","618.34003","1.18448","0.07516","0.00550","308.77356"
"70.80000","1.17798","621.86725","1.19099","0.08166","0.00553","310.53488"
"71.20000","1.18491","625.28613","1.19776","0.08844","0.00556","312.24216"
"71.60000","1.19164","628.52197","1.20435","0.09503","0.00559","313.85800"
"72.00000","1.19833","631.93988","1.21089","0.10156","0.00562","315.56476"
"72.40000","1.20473","635.04010","1.21714","0.10782","0.00565","317.11288"
"72.80000","1.21137","638.34332","1.22364","0.11431","0.00568","318.76236"
"73.20000","1.21791","641.55353","1.23003","0.12071","0.00571","320.36542"
"73.60000","1.22480","644.93799","1.23677","0.12745","0.00574","322.05548"
"74.00000","1.23183","648.56036","1.24364","0.13431","0.00577","323.86435"
"74.40000","1.23828","651.67316","1.24995","0.14062","0.00580","325.41873"
"74.80000","1.24489","654.95148","1.25641","0.14709","0.00583","327.05579"
"75.20000","1.25136","658.11145","1.26274","0.15342","0.00586","328.63376"
"75.60000","1.25799","661.49030","1.26922","0.15989","0.00589","330.32101"
"76.00000","1.26474","664.77545","1.27583","0.16651","0.00592","331.96149"
"76.40000","1.27159","668.17834","1.28253","0.17320","0.00595","333.66074"
"76.80000","1.27840","671.56604","1.28919","0.17986","0.00598","335.35242"
"77.20000","1.28480","674.77051","1.29544","0.18612","0.00601","336.95261"
"77.60000","1.29142","677.85608","1.30192","0.19259","0.00604","338.49341"
"78.00000","1.29795","681.10938","1.30831","0.19898","0.00607","340.11798"
"78.40000","1.30474","684.45404","1.31496","0.20563","0.00610","341.78818"
"78.80000","1.31172","687.88391","1.32177","0.21245","0.00613","343.50089"
"79.20000","1.31828","691.11401","1.32820","0.21887","0.00616","345.11389"
"79.60000","1.32491","694.30908","1.33469","0.22536","0.00619","346.70935"
"80.00000","1.33136","697.44025","1.34099","0.23166","0.00622","348.27295"
"80.40000","1.33794","700.68799","1.34743","0.23811","0.00625","349.89471"
"80.80000","1.34465","703.90356","1.35399","0.24467","0.00628","351.50046"
"81.20000","1.35160","707.25830","1.36079","0.25147","0.00632","353.17566"
"81.60000","1.35852","710.73517","1.36755","0.25823","0.00635","354.91187"
"82.00000","1.36487","713.78912","1.37377","0.26445","0.00638","356.43689"
"82.40000","1.37144","716.92993","1.38020","0.27087","0.00641","358.00528"
"82.80000","1.37796","720.17603","1.38658","0.27725","0.00644","359.62625"
"83.20000","1.38461","723.23993","1.39309","0.28376","0.00647","361.15625"
"83.60000","1.39159","726.63434","1.39991","0.29059","0.00650","362.85126"
"84.00000","1.39832","729.94537","1.40650","0.29718","0.00653","364.50467"
"84.40000","1.40497","733.12665","1.41301","0.30368","0.00656","366.09326"
"84.80000","1.41146","736.26862","1.41936","0.31003","0.00659","367.66223"
"85.20000","1.41803","739.38135","1.42579","0.31646","0.00662","369.21661"
"85.60000","1.42461","742.58960","1.43223","0.32290","0.00665","370.81866"
"86.00000","1.43143","745.89941","1.43891","0.32959","0.00668","372.47147"
"86.40000","1.43849","749.26331","1.44583","0.33650","0.00671","374.15125"
"86.80000","1.44482","752.29590","1.45203","0.34271","0.00674","375.66559"
"87.20000","1.45151","755.53516","1.45858","0.34926","0.00677","377.28314"
"87.60000","1.45800","758.69720","1.46494","0.35562","0.00680","378.86215"
"88.00000","1.46469","761.76306","1.47151","0.36218","0.00683","380.39310"
"88.40000","1.47152","765.10144","1.47820","0.36887","0.00686","382.06015"
"88.80000","1.47829","768.43433","1.48483","0.37550","0.00689","383.72446"
"89.20000","1.48508","771.59656","1.49149","0.38216","0.00692","385.30356"
"89.60000","1.49145","774.58453","1.49773","0.38840","0.00695","386.79562"
"90.00000","1.49807","777.82605","1.50421","0.39489","0.00698","388.41431"
"90.40000","1.50454","780.75616","1.51056","0.40124","0.00701","389.87747"
"90.80000","1.51138","784.10107","1.51727","0.40794","0.00704","391.54779"
"91.20000","1.51846","787.56635","1.52420","0.41487","0.00707","393.27820"
"91.60000","1.52498","790.62683","1.53059","0.42127","0.00710","394.80649"
"92.00000","1.53158","793.63080","1.53707","0.42774","0.00713","396.30655"
"92.40000","1.53803","796.63580","1.54339","0.43406","0.00716","397.80713"
"92.80000","1.54465","799.63562","1.54988","0.44055","0.00719","399.30511"
"93.20000","1.55129","802.85992","1.55637","0.44705","0.00722","400.91519"
"93.60000","1.55825","806.04425","1.56320","0.45387","0.00726","402.50531"
"94.00000","1.56509","809.18854","1.56990","0.46058","0.00729","404.07544"
"94.40000","1.57151","812.03607","1.57620","0.46687","0.00732","405.49738"
"94.80000","1.57811","814.93591","1.58267","0.47335","0.00735","406.94543"
"95.20000","1.58458","817.64233","1.58903","0.47970","0.00737","408.29691"
"95.60000","1.59132","820.72186","1.59563","0.48630","0.00741","409.83472"
"96.00000","1.59828","823.71442","1.60246","0.49313","0.00744","411.32907"
"96.40000","1.60505","826.49902","1.60911","0.49979","0.00747","412.71957"
"96.80000","1.61162","829.13495","1.61557","0.50624","0.00750","414.03586"
"97.20000","1.61809","831.70782","1.62193","0.51260","0.00753","415.32065"
"97.60000","1.62463","834.37030","1.62835","0.51902","0.00756","416.65018"
"98.00000","1.63124","837.03467","1.63485","0.52552","0.00759","417.98065"
"98.40000","1.63811","839.94299","1.64159","0.53226","0.00762","419.43295"
"98.80000","1.64519","842.88605","1.64854","0.53922","0.00765","420.90259"
"99.20000","1.65162","845.45148","1.65486","0.54553","0.00768","422.18365"
"99.60000","1.65816","848.12500","1.66129","0.55196","0.00771","423.51871"
"100.00000","1.66466","850.72601","1.66768","0.55836","0.00774","424.81754"
"100.40000","1.67130","853.31519","1.67422","0.56489","0.00777","426.11047"
"100.80000","1.67812","855.88434","1.68093","0.57160","0.00780","427.39340"
"101.20000","1.68493","858.28723","1.68763","0.57831","0.00783","428.59329"
"101.60000","1.69170","859.90167","1.69434","0.58501","0.00786","429.39948"
"102.00000","1.69812","860.18359","1.70075","0.59142","0.00789","429.54025"
"102.40000","1.70477","858.43494","1.70747","0.59814","0.00792","428.66705"
"102.80000","1.71127","859.45764","1.71393","0.60460","0.00795","429.17776"
"103.20000","1.71801","860.77832","1.72061","0.61128","0.00799","429.83725"
"103.60000","1.72514","862.78363","1.72765","0.61833","0.00802","430.83862"
"104.00000","1.73157","864.55701","1.73401","0.62468","0.00805","431.72418"
"104.40000","1.73822","866.70416","1.74057","0.63124","0.00808","432.79636"
"104.80000","1.74468","868.78632","1.74694","0.63762","0.00811","433.83612"
"105.20000","1.75134","869.96460","1.75356","0.64423","0.00814","434.42450"
"105.60000","1.75800","871.17596","1.76016","0.65083","0.00817","435.02939"
"106.00000","1.76493","867.87396","1.76723","0.65790","0.00820","433.38052"
"106.40000","1.77181","867.21930","1.77414","0.66481","0.00823","433.05362"
"106.80000","1.77813","868.43103","1.78041","0.67109","0.00826","433.65869"
"107.20000","1.78479","870.41364","1.78699","0.67766","0.00829","434.64871"
"107.60000","1.79124","872.43726","1.79335","0.68403","0.00832","435.65924"
"108.00000","1.79802","874.89410","1.80003","0.69070","0.00835","436.88608"
"108.40000","1.80495","877.22919","1.80687","0.69754","0.00839","438.05212"
"108.80000","1.81172","879.82825","1.81352","0.70419","0.00842","439.35001"
"109.20000","1.81830","882.23901","1.82001","0.71068","0.00845","440.55383"
"109.60000","1.82472","884.56335","1.82633","0.71700","0.00848","441.71451"
"110.00000","1.83134","887.07556","1.83284","0.72352","0.00851","442.96899"
"110.40000","1.83791","889.50507","1.83931","0.72999","0.00854","444.18219"
"110.80000","1.84481","892.17249","1.84609","0.73677","0.00857","445.51419"
"111.20000","1.85178","894.84302","1.85296","0.74363","0.00860","446.84775"
"111.60000","1.85827","897.35437","1.85934","0.75001","0.00863","448.10181"
"112.00000","1.86479","899.56616","1.86577","0.75644","0.00866","449.20630"
"112.40000","1.87134","901.87250","1.87222","0.76290","0.00869","450.35800"
"112.80000","1.87795","904.30963","1.87873","0.76940","0.00872","451.57498"
"113.20000","1.88482","906.65442","1.88550","0.77618","0.00875","452.74588"
"113.60000","1.89164","909.10046","1.89221","0.78289","0.00878","453.96735"
"114.00000","1.89834","911.26868","1.89883","0.78950","0.00881","455.05005"
"114.40000","1.90477","913.15143","1.90518","0.79585","0.00884","455.99023"
"114.80000","1.91141","915.18134","1.91173","0.80241","0.00887","457.00388"
"115.20000","1.91793","917.37665","1.91816","0.80883","0.00890","458.10013"
"115.60000","1.92469","919.51611","1.92483","0.81550","0.00893","459.16849"
"116.00000","1.93177","921.60425","1.93183","0.82250","0.00897","460.21121"
"116.40000","1.93830","923.76538","1.93826","0.82894","0.00900","461.29041"
"116.80000","1.94490","925.88354","1.94477","0.83544","0.00903","462.34811"
"117.20000","1.95134","928.07825","1.95113","0.84180","0.00906","463.44406"
"117.60000","1.95797","930.51978","1.95765","0.84833","0.00909","464.66327"
"118.00000","1.96468","932.82343","1.96427","0.85494","0.00912","465.81360"
"118.40000","1.97152","935.29523","1.97100","0.86167","0.00915","467.04791"
"118.80000","1.97842","937.63593","1.97781","0.86848","0.00918","468.21677"
"119.20000","1.98480","938.46552","1.98415","0.87482","0.00921","468.63104"
"119.60000","1.99148","940.57501","1.99074","0.88142","0.00924","469.68442"
"120.00000","1.99795","942.46881","1.99713","0.88780","0.00927","470.63013"
"120.40000","2.00465","944.61523","2.00374","0.89441","0.00930","471.70197"
"120.80000","2.01163","946.92932","2.01061","0.90129","0.00933","472.85751"
"121.20000","2.01829","949.08575","2.01718","0.90785","0.00936","473.93436"
"121.60000","2.02498","950.89331","2.02379","0.91447","0.00939","474.83698"
"122.00000","2.03134","950.26978","2.03018","0.92085","0.00942","474.52560"
"122.40000","2.03800","951.82416","2.03677","0.92745","0.00945","475.30179"
"122.80000","2.04459","953.35571","2.04328","0.93396","0.00948","476.06659"
"123.20000","2.05152","954.72949","2.05016","0.94083","0.00952","476.75259"
"123.60000","2.05844","955.30127","2.05705","0.94773","0.00955","477.03812"
"124.00000","2.06492","956.48468","2.06347","0.95415","0.00958","477.62906"
"124.40000","2.07149","958.31531","2.06997","0.96065","0.00961","478.54321"
"124.80000","2.07795","960.08740","2.07634","0.96702","0.00964","479.42810"
"125.20000","2.08461","961.98291","2.08292","0.97360","0.00967","480.37466"
"125.60000","2.09151","964.21558","2.08972","0.98039","0.00970","481.48956"
"126.00000","2.09836","966.19653","2.09648","0.98716","0.00973","482.47876"
"126.40000","2.10502","968.23352","2.10305","0.99372","0.00976","483.49594"
"126.80000","2.11146","970.04865","2.10941","1.00009","0.00979","484.40234"
"127.20000","2.11806","971.96252","2.11592","1.00660","0.00982","485.35806"
"127.60000","2.12460","973.73090","2.12238","1.01306","0.00985","486.24112"
"128.00000","2.13137","975.70709","2.12906","1.01974","0.00988","487.22794"
"128.40000","2.13843","977.69269","2.13604","1.02671","0.00991","488.21948"
"128.80000","2.14496","979.53809","2.14248","1.03316","0.00994","489.14099"
"129.20000","2.15156","980.62195","2.14903","1.03971","0.00997","489.68222"
"129.60000","2.15804","981.86353","2.15546","1.04613","0.01000","490.30222"
"130.00000","2.16463","982.67700","2.16202","1.05269","0.01003","490.70844"
"130.40000","2.17139","981.85120","2.16882","1.05949","0.01007","490.29605"
"130.80000","2.17822","977.92865","2.17582","1.06649","0.01010","488.33731"
"131.20000","2.18509","976.82214","2.18273","1.07341","0.01013","487.78476"
"131.60000","2.19143","976.42206","2.18910","1.07977","0.01016","487.58496"
"132.00000","2.19813","976.33795","2.19580","1.08647","0.01019","487.54297"
"132.40000","2.20460","976.40253","2.20227","1.09294","0.01022","487.57523"
"132.80000","2.21132","975.92053","2.20900","1.09968","0.01025","487.33453"
"133.20000","2.21835","976.26514","2.21602","1.10669","0.01028","487.50662"
"133.60000","2.22498","976.34717","2.22265","1.11332","0.01032","487.54758"
"134.00000","2.23162","976.64825","2.22927","1.11995","0.01035","487.69791"
"134.40000","2.23806","976.99603","2.23570","1.12637","0.01038","487.87158"
"134.80000","2.24463","977.69946","2.24224","1.13291","0.01041","488.22284"
"135.20000","2.25126","978.61682","2.24883","1.13950","0.01044","488.68094"
"135.60000","2.25817","979.76495","2.25569","1.14636","0.01047","489.25427"
"136.00000","2.26515","981.04700","2.26261","1.15328","0.01050","489.89447"
"136.40000","2.27154","982.00189","2.26896","1.15963","0.01053","490.37131"
"136.80000","2.27819","983.20245","2.27555","1.16623","0.01056","490.97083"
"137.20000","2.28462","984.19415","2.28193","1.17261","0.01059","491.46603"
"137.60000","2.29127","985.39105","2.28854","1.17921","0.01062","492.06372"
"138.00000","2.29813","986.78961","2.29534","1.18601","0.01065","492.76208"
"138.40000","2.30504","988.13129","2.30218","1.19286","0.01068","493.43207"
"138.80000","2.31167","989.32629","2.30876","1.19943","0.01072","494.02881"
"139.20000","2.31810","990.04547","2.31515","1.20583","0.01075","494.38794"
"139.60000","2.32471","987.66864","2.32187","1.21254","0.01078","493.20105"
"140.00000","2.33127","985.17853","2.32854","1.21922","0.01081","491.95758"
"140.40000","2.33806","984.23322","2.33538","1.22606","0.01084","491.48553"
"140.80000","2.34514","984.35327","2.34245","1.23312","0.01087","491.54550"
"141.20000","2.35164","984.26855","2.34896","1.23963","0.01090","491.50317"
"141.60000","2.35820","984.48584","2.35550","1.24617","0.01093","491.61169"
"142.00000","2.36469","984.69525","2.36199","1.25266","0.01096","491.71625"
"142.40000","2.37128","984.85919","2.36857","1.25924","0.01099","491.79813"
"142.80000","2.37799","985.31873","2.37526","1.26593","0.01102","492.02759"
"143.20000","2.38494","985.81091","2.38218","1.27286","0.01106","492.27338"
"143.60000","2.39179","986.49683","2.38901","1.27968","0.01109","492.61591"
"144.00000","2.39816","987.02509","2.39535","1.28602","0.01112","492.87967"
"144.40000","2.40479","987.68945","2.40195","1.29263","0.01115","493.21146"
"144.80000","2.41130","988.51801","2.40843","1.29910","0.01118","493.62518"
"145.20000","2.41797","989.30914","2.41506","1.30573","0.01121","494.02023"
"145.60000","2.42498","990.49884","2.42202","1.31269","0.01124","494.61432"
"146.00000","2.43159","991.49933","2.42858","1.31926","0.01127","495.11392"
"146.40000","2.43827","992.50415","2.43521","1.32589","0.01130","495.61569"
"146.80000","2.44471","993.45630","2.44161","1.33228","0.01133","496.09116"
"147.20000","2.45138","994.48199","2.44824","1.33891","0.01136","496.60336"
"147.60000","2.45796","995.49878","2.45478","1.34545","0.01139","497.11108"
"148.00000","2.46487","996.66638","2.46163","1.35231","0.01142","497.69415"
"148.40000","2.47183","997.98395","2.46854","1.35921","0.01146","498.35208"
"148.80000","2.47821","998.86505","2.47488","1.36556","0.01149","498.79208"
"149.20000","2.48478","999.97015","2.48141","1.37208","0.01152","499.34390"
"149.60000","2.49129","1000.79932","2.48788","1.37856","0.01155","499.75797"
"150.00000","2.49800","1001.98083","2.49454","1.38522","0.01158","500.34796"
"150.40000","2.50487","1003.15399","2.50137","1.39204","0.01161","500.93381"
"150.80000","2.51174","1004.13226","2.50820","1.39887","0.01164","501.42230"
"151.20000","2.51837","1005.14899","2.51478","1.40546","0.01167","501.93002"
"151.60000","2.52475","1005.79987","2.52113","1.41180","0.01170","502.25504"
"152.00000","2.53136","1006.76428","2.52770","1.41837","0.01173","502.73663"
"152.40000","2.53794","1007.63916","2.53424","1.42492","0.01176","503.17349"
"152.80000","2.54474","1008.66669","2.54100","1.43168","0.01179","503.68661"
"153.20000","2.55177","1009.75195","2.54799","1.43867","0.01183","504.22855"
"153.60000","2.55827","1010.41150","2.55446","1.44514","0.01186","504.55789"
"154.00000","2.56490","1011.04657","2.56106","1.45174","0.01189","504.87503"
"154.40000","2.57134","1011.49261","2.56748","1.45816","0.01192","505.09775"
"154.80000","2.57793","1012.05530","2.57405","1.46473","0.01195","505.37875"
"155.20000","2.58471","1012.55573","2.58081","1.47148","0.01198","505.62863"
"155.60000","2.59160","1012.60077","2.58770","1.47837","0.01201","505.65112"
"156.00000","2.59845","1011.80328","2.59458","1.48526","0.01204","505.25290"
"156.40000","2.60479","1009.83594","2.60100","1.49168","0.01207","504.27048"
"156.80000","2.61141","1007.06201","2.60774","1.49841","0.01210","502.88528"
"157.20000","2.61795","1004.86835","2.61437","1.50504","0.01213","501.78989"
"157.60000","2.62469","1003.22430","2.62118","1.51186","0.01217","500.96890"
"158.00000","2.63170","1002.20032","2.62823","1.51891","0.01220","500.45758"
"158.40000","2.63831","1001.38586","2.63488","1.52555","0.01223","500.05087"
"158.80000","2.64497","1000.98877","2.64156","1.53223","0.01226","499.85257"
"159.20000","2.65137","1000.55664","2.64797","1.53864","0.01229","499.63678"
"159.60000","2.65800","1000.33966","2.65461","1.54528","0.01232","499.52844"
"160.00000","2.66459","1000.33105","2.66121","1.55188","0.01235","499.52414"
"160.40000","2.67153","1000.60852","2.66813","1.55881","0.01238","499.66269"
"160.80000","2.67849","1000.73743","2.67508","1.56576","0.01242","499.72705"
"161.20000","2.68490","1000.71777","2.68150","1.57217","0.01245","499.71725"
"161.60000","2.69150","1000.72510","2.68810","1.57878","0.01248","499.72092"
"162.00000","2.69798","1000.70648","2.69457","1.58525","0.01251","499.71161"
"162.40000","2.70466","1000.89478","2.70125","1.59193","0.01254","499.80563"
"162.80000","2.71153","1001.17365","2.70810","1.59878","0.01257","499.94489"
"163.20000","2.71830","1001.42731","2.71486","1.60554","0.01260","500.07156"
"163.60000","2.72503","1001.60327","2.72159","1.61226","0.01263","500.15942"
"164.00000","2.73142","1001.68005","2.72798","1.61865","0.01266","500.19778"
"164.40000","2.73804","1001.62921","2.73460","1.62527","0.01269","500.17239"
"164.80000","2.74462","1001.52362","2.74118","1.63185","0.01272","500.11966"
"165.20000","2.75148","1001.44354","2.74804","1.63872","0.01275","500.07968"
"165.60000","2.75845","1001.30115","2.75502","1.64570","0.01279","500.00858"
"166.00000","2.76491","1000.54041","2.76152","1.65219","0.01282","499.62869"
"166.40000","2.77153","998.72723","2.76821","1.65888","0.01285","498.72327"
"166.80000","2.77800","993.65350","2.77490","1.66557","0.01288","496.18964"
"167.20000","2.78459","988.44897","2.78171","1.67239","0.01291","493.59073"
"167.60000","2.79138","983.05426","2.78874","1.67942","0.01294","490.89682"
"168.00000","2.79834","978.32745","2.79592","1.68659","0.01298","488.53644"
"168.40000","2.80515","974.94501","2.80288","1.69355","0.01301","486.84738"
"168.80000","2.81149","972.15204","2.80935","1.70002","0.01304","485.45270"
"169.20000","2.81808","970.11377","2.81602","1.70670","0.01307","484.43488"
"169.60000","2.82460","968.58392","2.82261","1.71329","0.01310","483.67093"
"170.00000","2.83132","967.63940","2.82938","1.72005","0.01313","483.19928"
"170.40000","2.83838","967.09381","2.83646","1.72714","0.01316","482.92682"
"170.80000","2.84498","966.77124","2.84308","1.73375","0.01320","482.76575"
"171.20000","2.85157","966.42145","2.84969","1.74036","0.01323","482.59106"
"171.60000","2.85811","966.47583","2.85622","1.74690","0.01326","482.61823"
"172.00000","2.86467","966.56549","2.86277","1.75345","0.01329","482.66299"
"172.40000","2.87131","966.89716","2.86940","1.76007","0.01332","482.82861"
"172.80000","2.87816","967.32245","2.87623","1.76690","0.01335","483.04099"
"173.20000","2.88514","968.01483","2.88318","1.77386","0.01338","483.38675"
"173.60000","2.89146","968.56763","2.88948","1.78015","0.01341","483.66278"
"174.00000","2.89816","969.25909","2.89615","1.78682","0.01344","484.00809"
"174.40000","2.90463","969.89526","2.90259","1.79326","0.01347","484.32574"
"174.80000","2.91136","970.85626","2.90927","1.79995","0.01350","484.80563"
"175.20000","2.91827","971.77039","2.91614","1.80682","0.01353","485.26212"
"175.60000","2.92500","972.72430","2.92283","1.81350","0.01357","485.73846"
"176.00000","2.93170","973.51587","2.92949","1.82017","0.01360","486.13373"
"176.40000","2.93810","974.25208","2.93586","1.82653","0.01363","486.50137"
"176.80000","2.94470","974.87476","2.94244","1.83311","0.01366","486.81232"
"177.20000","2.95122","975.57782","2.94892","1.83960","0.01369","487.16339"
"177.60000","2.95809","976.61035","2.95574","1.84642","0.01372","487.67899"
"178.00000","2.96517","977.60205","2.96278","1.85346","0.01375","488.17419"
"178.40000","2.97160","978.33685","2.96918","1.85985","0.01378","488.54114"
"178.80000","2.97822","979.08154","2.97576","1.86644","0.01381","488.91299"
"179.20000","2.98467","979.78210","2.98218","1.87286","0.01384","489.26285"
"179.60000","2.99131","980.53625","2.98879","1.87946","0.01387","489.63943"
"180.00000","2.99805","981.40387","2.99549","1.88616","0.01390","490.07269"
"180.40000","3.00496","982.18127","3.00237","1.89304","0.01393","490.46088"
"180.80000","3.01172","982.98126","3.00909","1.89976","0.01397","490.86035"
"181.20000","3.01814","983.48602","3.01549","1.90616","0.01400","491.11243"
"181.60000","3.02475","984.11627","3.02207","1.91274","0.01403","491.42715"
"182.00000","3.03123","984.64459","3.02853","1.91921","0.01406","491.69095"
"182.40000","3.03804","985.24884","3.03531","1.92598","0.01409","491.99271"
"182.80000","3.04504","985.85083","3.04229","1.93296","0.01412","492.29330"
"183.20000","3.05168","986.35748","3.04890","1.93958","0.01415","492.54630"
"183.60000","3.05823","986.74249","3.05544","1.94611","0.01418","492.73856"
"184.00000","3.06473","986.99921","3.06192","1.95260","0.01421","492.86676"
"184.40000","3.07126","987.30756","3.06844","1.95911","0.01424","493.02075"
"184.80000","3.07794","987.59576","3.07510","1.96578","0.01427","493.16464"
"185.20000","3.08486","988.02112","3.08201","1.97268","0.01430","493.37708"
"185.60000","3.09185","988.37811","3.08898","1.97965","0.01434","493.55533"
"186.00000","3.09822","988.10046","3.09537","1.98604","0.01437","493.41669"
"186.40000","3.10480","988.13092","3.10194","1.99261","0.01440","493.43188"
"186.80000","3.11131","988.01599","3.10846","1.99913","0.01443","493.37451"
"187.20000","3.11798","988.02020","3.11513","2.00580","0.01446","493.37662"
"187.60000","3.12490","988.09711","3.12204","2.01271","0.01449","493.41501"
"188.00000","3.13161","987.89075","3.12876","2.01943","0.01452","493.31195"
"188.40000","3.13831","987.80487","3.13547","2.02614","0.01455","493.26907"
"188.80000","3.14476","987.39227","3.14193","2.03261","0.01458","493.06305"
"189.20000","3.15140","987.12628","3.14859","2.03927","0.01461","492.93021"
"189.60000","3.15795","986.66901","3.15516","2.04583","0.01464","492.70187"
"190.00000","3.16473","986.40344","3.16195","2.05263","0.01468","492.56927"
"190.40000","3.17188","986.06555","3.16911","2.05978","0.01471","492.40054"
"190.80000","3.17819","985.37225","3.17546","2.06613","0.01474","492.05432"
"191.20000","3.18484","984.91992","3.18213","2.07280","0.01477","491.82846"
"191.60000","3.19130","984.34717","3.18861","2.07928","0.01480","491.54245"
"192.00000","3.19797","983.86572","3.19530","2.08597","0.01483","491.30203"
"192.40000","3.20475","983.48297","3.20210","2.09278","0.01486","491.11090"
"192.80000","3.21167","983.14423","3.20903","2.09971","0.01489","490.94174"
"193.20000","3.21842","982.70386","3.21580","2.10648","0.01493","490.72183"
"193.60000","3.22478","981.98914","3.22219","2.11287","0.01495","490.36493"
"194.00000","3.23142","981.47552","3.22886","2.11953","0.01499","490.10846"
"194.40000","3.23788","980.96521","3.23534","2.12601","0.01502","489.85364"
"194.80000","3.24472","980.38000","3.24220","2.13288","0.01505","489.56140"
"195.20000","3.25172","980.00842","3.24922","2.13990","0.01508","489.37585"
"195.60000","3.25837","979.43646","3.25590","2.14657","0.01511","489.09024"
"196.00000","3.26491","978.84833","3.26247","2.15314","0.01514","488.79654"
"196.40000","3.27135","978.31042","3.26893","2.15961","0.01517","488.52795"
"196.80000","3.27798","977.81104","3.27558","2.16625","0.01520","488.27856"
"197.20000","3.28461","977.21198","3.28224","2.17291","0.01523","487.97943"
"197.60000","3.29155","976.94855","3.28919","2.17986","0.01527","487.84787"
"198.00000","3.29843","976.63037","3.29608","2.18676","0.01530","487.68900"
"198.40000","3.30490","975.94391","3.30258","2.19326","0.01533","487.34619"
"198.80000","3.31143","975.57520","3.30913","2.19981","0.01536","487.16208"
"199.20000","3.31796","975.21906","3.31568","2.20636","0.01539","486.98425"
"199.60000","3.32461","974.78821","3.32235","2.21302","0.01542","486.76910"
"200.00000","3.33162","974.76440","3.32936","2.22003","0.01545","486.75720"
"200.40000","3.33836","974.47748","3.33611","2.22679","0.01548","486.61392"
"200.80000","3.34496","974.23291","3.34272","2.23340","0.01551","486.49179"
"201.20000","3.35143","973.84619","3.34921","2.23988","0.01554","486.29868"
"201.60000","3.35804","973.32800","3.35584","2.24651","0.01558","486.03992"
"202.00000","3.36458","973.06476","3.36240","2.25307","0.01561","485.90848"
"202.40000","3.37139","972.84790","3.36922","2.25989","0.01564","485.80017"
"202.80000","3.37850","972.88110","3.37632","2.26700","0.01567","485.81677"
"203.20000","3.38493","972.50214","3.38277","2.27345","0.01570","485.62753"
"203.60000","3.39155","972.24835","3.38940","2.28008","0.01573","485.50079"
"204.00000","3.39800","971.77948","3.39587","2.28654","0.01576","485.26666"
"204.40000","3.40461","971.50262","3.40250","2.29317","0.01579","485.12842"
"204.80000","3.41143","971.41156","3.40932","2.30000","0.01582","485.08295"
"205.20000","3.41824","971.34772","3.41613","2.30681","0.01585","485.05106"
"205.60000","3.42505","971.06024","3.42296","2.31363","0.01589","484.90750"
"206.00000","3.43143","970.41559","3.42937","2.32004","0.01592","484.58557"
"206.40000","3.43812","970.18500","3.43607","2.32674","0.01595","484.47043"
"206.80000","3.44460","969.85651","3.44256","2.33323","0.01598","484.30640"
"207.20000","3.45136","969.77808","3.44932","2.34000","0.01601","484.26724"
"207.60000","3.45840","969.02539","3.45639","2.34707","0.01604","483.89139"
"208.00000","3.46495","960.03448","3.46335","2.35403","0.01607","479.40170"
"208.23900","3.46874","929.84540","3.46845","2.35912","0.01610","464.32651"
"208.57400","3.47429","905.82324","3.47500","2.36568","0.01613","452.33084"
"208.97400","3.48127","892.81805","3.48253","2.37320","0.01616","445.83658"
"209.37400","3.48787","888.98468","3.48929","2.37996","0.01619","443.92233"
"209.63400","3.49207","860.82623","3.49467","2.38534","0.01622","429.86118"
"209.78300","3.49460","820.31201","3.49893","2.38961","0.01624","409.63004"
"210.11100","3.50004","791.71881","3.50560","2.39628","0.01627","395.35178"
"210.48000","3.50620","768.12335","3.51275","2.40342","0.01630","383.56918"
"210.88000","3.51266","760.36041","3.51953","2.41021","0.01633","379.69269"
"211.28000","3.51930","754.22888","3.52643","2.41710","0.01637","376.63086"
"211.65400","3.52550","733.67401","3.53352","2.42419","0.01640","366.36658"
"212.05400","3.53241","727.01154","3.54072","2.43139","0.01643","363.03961"
"212.45400","3.53934","718.31201","3.54804","2.43871","0.01647","358.69543"
"212.85400","3.54582","711.04608","3.55485","2.44552","0.01650","355.06714"
"213.21600","3.55182","695.69287","3.56153","2.45220","0.01653","347.40036"
"213.61600","3.55834","685.76819","3.56849","2.45917","0.01656","342.44440"
"214.01600","3.56492","682.34436","3.57522","2.46590","0.01659","340.73468"
"214.41600","3.57159","679.88977","3.58201","2.47268","0.01662","339.50894"
"214.81600","3.57842","679.56915","3.58885","2.47953","0.01666","339.34885"
"215.16000","3.58425","660.97931","3.59551","2.48618","0.01669","330.06586"
"215.56000","3.59100","659.94556","3.60230","2.49298","0.01672","329.54962"
"215.96000","3.59763","659.07941","3.60897","2.49965","0.01675","329.11713"
"216.36000","3.60408","658.78064","3.61543","2.50611","0.01678","328.96793"
"216.76000","3.61069","658.69940","3.62205","2.51272","0.01681","328.92737"
"217.16000","3.61732","658.63885","3.62868","2.51936","0.01684","328.89713"
"217.56000","3.62409","658.28888","3.63547","2.52615","0.01687","328.72235"
"217.96000","3.63112","658.48303","3.64249","2.53317","0.01691","328.81931"
"218.36000","3.63749","658.21564","3.64887","2.53954","0.01694","328.68579"
"218.76000","3.64419","655.19275","3.65571","2.54638","0.01697","327.17627"
"219.16000","3.65063","651.89642","3.66230","2.55297","0.01700","325.53024"
"219.56000","3.65732","650.24860","3.66905","2.55973","0.01703","324.70737"
"219.96000","3.66418","645.20465","3.67614","2.56682","0.01706","322.18863"
"220.36000","3.67099","643.52344","3.68302","2.57370","0.01709","321.34909"
"220.76000","3.67769","640.92383","3.68985","2.58052","0.01713","320.05096"
"221.16000","3.68410","638.28033","3.69637","2.58705","0.01716","318.73093"
"221.56000","3.69070","636.62891","3.70304","2.59371","0.01719","317.90625"
"221.96000","3.69723","633.34119","3.70972","2.60040","0.01722","316.26450"
"222.36000","3.70408","632.61005","3.71661","2.60728","0.01725","315.89941"
"222.76000","3.71112","632.38147","3.72365","2.61432","0.01728","315.78528"
"223.16000","3.71764","631.16888","3.73023","2.62091","0.01731","315.17975"
"223.56000","3.72427","627.94244","3.73700","2.62767","0.01734","313.56860"
"223.96000","3.73065","620.54547","3.74372","2.63439","0.01738","309.87485"
"224.36000","3.73728","617.21521","3.75049","2.64117","0.01741","308.21185"
"224.76000","3.74402","609.68890","3.75757","2.64824","0.01744","304.45352"
"225.16000","3.75095","608.01788","3.76458","2.65525","0.01747","303.61908"
"225.56000","3.75774","607.82251","3.77138","2.66205","0.01750","303.52155"
"225.70700","3.75981","607.57507","3.77346","2.66413","0.01751","303.39798"