File: flexion/5_axis/Specimen_RawData_12.csv
Specimen properties : Specimen label,"G1"
Specimen properties : Support span,"72.00",mm
Specimen properties : Thickness,"4.13",mm
Specimen properties : Width,"14.06",mm
Maximum Load : Maximum Load,"893.5",N
Tangent Modulus of Elasticity : Tangent Modulus of Elasticity,"49194255565.32100",Pa
Test : Rate 1,"1.00000",mm/min
Specimen notes : Specimen note 1,""

Time,Displacement,Load,Flexure extension,Corrected extension,Flexure strain (Corrected extension),Flexure stress
(s),(mm),(N),(mm),(mm),(mm/mm),(MPa)
"0.00000","0.00000","43.47411","0.08281","-1.05482","0.00040","19.57803"
"0.50000","0.00639","46.86226","0.08875","-1.04889","0.00042","21.10384"
"1.00000","0.01491","51.41939","0.09665","-1.04098","0.00046","23.15609"
"1.50000","0.02306","55.52743","0.10426","-1.03338","0.00050","25.00610"
"2.00000","0.03181","59.72474","0.11248","-1.02516","0.00054","26.89630"
"2.50000","0.03974","63.40408","0.11998","-1.01765","0.00057","28.55325"
"3.00000","0.04846","67.47425","0.12822","-1.00942","0.00061","30.38620"
"3.50000","0.05655","71.03535","0.13590","-1.00174","0.00065","31.98990"
"4.00000","0.06523","75.18024","0.14409","-0.99354","0.00069","33.85649"
"4.50000","0.07318","78.90734","0.15161","-0.98603","0.00072","35.53495"
"5.00000","0.08160","82.88390","0.15956","-0.97808","0.00076","37.32574"
"5.50000","0.08998","86.78815","0.16748","-0.97015","0.00080","39.08398"
"6.00000","0.09811","90.74104","0.17521","-0.96242","0.00084","40.86411"
"6.50000","0.10663","94.84164","0.18334","-0.95430","0.00088","42.71077"
"7.00000","0.11479","98.94428","0.19109","-0.94655","0.00091","44.55834"
"7.50000","0.12357","103.30929","0.19944","-0.93819","0.00095","46.52407"
"8.00000","0.13138","107.08573","0.20689","-0.93075","0.00099","48.22474"
"8.50000","0.14018","111.69215","0.21524","-0.92240","0.00103","50.29919"
"9.00000","0.14819","115.78553","0.22285","-0.91479","0.00107","52.14259"
"9.50000","0.15682","120.24159","0.23104","-0.90659","0.00110","54.14932"
"10.00000","0.16486","124.16403","0.23869","-0.89894","0.00114","55.91574"
"10.50000","0.17322","128.45384","0.24664","-0.89100","0.00118","57.84761"
"11.00000","0.18167","132.70619","0.25468","-0.88296","0.00122","59.76260"
"11.50000","0.18975","136.88091","0.26235","-0.87529","0.00125","61.64263"
"12.00000","0.19841","141.34407","0.27058","-0.86706","0.00129","63.65257"
"12.50000","0.20642","145.22772","0.27821","-0.85942","0.00133","65.40152"
"13.00000","0.21529","149.89561","0.28663","-0.85101","0.00137","67.50365"
"13.50000","0.22314","153.82356","0.29409","-0.84354","0.00141","69.27255"
"14.00000","0.23179","158.33090","0.30231","-0.83533","0.00145","71.30238"
"14.50000","0.23991","162.34111","0.31010","-0.82754","0.00148","73.10832"
"15.00000","0.24841","166.74562","0.31822","-0.81942","0.00152","75.09184"
"15.50000","0.25653","170.63646","0.32601","-0.81163","0.00156","76.84403"
"16.00000","0.26480","174.85271","0.33392","-0.80372","0.00160","78.74277"
"16.50000","0.27339","179.20166","0.34213","-0.79550","0.00164","80.70126"
"17.00000","0.28142","183.07971","0.34983","-0.78780","0.00167","82.44770"
"17.50000","0.29009","187.54672","0.35812","-0.77951","0.00171","84.45936"
"18.00000","0.29815","191.39392","0.36586","-0.77178","0.00175","86.19190"
"18.50000","0.30692","195.81213","0.37426","-0.76338","0.00179","88.18159"
"19.00000","0.31476","199.61133","0.38177","-0.75587","0.00182","89.89251"
"19.50000","0.32338","203.87817","0.39004","-0.74759","0.00186","91.81403"
"20.00000","0.33156","207.86554","0.39791","-0.73973","0.00190","93.60969"
"20.50000","0.33999","212.02603","0.40600","-0.73163","0.00194","95.48331"
"21.00000","0.34822","216.06621","0.41391","-0.72372","0.00198","97.30276"
"21.50000","0.35652","219.94116","0.42190","-0.71573","0.00202","99.04780"
"22.00000","0.36514","224.20114","0.43018","-0.70746","0.00206","100.96622"
"22.50000","0.37304","227.90495","0.43778","-0.69985","0.00209","102.63419"
"23.00000","0.38181","232.28775","0.44620","-0.69144","0.00213","104.60793"
"23.50000","0.38976","236.03825","0.45385","-0.68378","0.00217","106.29693"
"24.00000","0.39858","240.31990","0.46233","-0.67530","0.00221","108.22511"
"24.50000","0.40645","243.93706","0.46991","-0.66772","0.00225","109.85406"
"25.00000","0.41504","248.12233","0.47818","-0.65946","0.00229","111.73884"
"25.50000","0.42326","251.86765","0.48611","-0.65153","0.00232","113.42550"
"26.00000","0.43159","255.93280","0.49413","-0.64350","0.00236","115.25619"
"26.50000","0.43996","259.78152","0.50220","-0.63543","0.00240","116.98942"
"27.00000","0.44810","263.58591","0.51005","-0.62758","0.00244","118.70267"
"27.50000","0.45679","267.76144","0.51843","-0.61921","0.00248","120.58308"
"28.00000","0.46473","271.24655","0.52609","-0.61154","0.00251","122.15255"
"28.50000","0.47345","275.36472","0.53450","-0.60314","0.00255","124.00712"
"29.00000","0.48149","278.89838","0.54227","-0.59536","0.00259","125.59846"
"29.50000","0.49027","283.26459","0.55071","-0.58693","0.00263","127.56473"
"30.00000","0.49816","286.67514","0.55834","-0.57930","0.00267","129.10063"
"30.50000","0.50663","290.48334","0.56652","-0.57111","0.00271","130.81560"
"31.00000","0.51502","294.39145","0.57464","-0.56299","0.00275","132.57558"
"31.50000","0.52325","298.04431","0.58263","-0.55500","0.00279","134.22060"
"32.00000","0.53164","301.81290","0.59077","-0.54687","0.00282","135.91772"
"32.50000","0.53978","305.40207","0.59867","-0.53896","0.00286","137.53407"
"33.00000","0.54849","309.37683","0.60711","-0.53052","0.00290","139.32405"
"33.50000","0.55636","312.69885","0.61476","-0.52288","0.00294","140.82008"
"34.00000","0.56510","316.66608","0.62324","-0.51440","0.00298","142.60667"
"34.50000","0.57314","320.14203","0.63105","-0.50659","0.00302","144.17203"
"35.00000","0.58189","324.16327","0.63952","-0.49811","0.00306","145.98294"
"35.50000","0.58985","327.43365","0.64726","-0.49037","0.00309","147.45572"
"36.00000","0.59834","331.27203","0.65550","-0.48213","0.00313","149.18430"
"36.50000","0.60671","334.85559","0.66363","-0.47400","0.00317","150.79810"
"37.00000","0.61479","338.25201","0.67149","-0.46615","0.00321","152.32764"
"37.50000","0.62333","341.93631","0.67978","-0.45785","0.00325","153.98682"
"38.00000","0.63141","345.46518","0.68763","-0.45001","0.00329","155.57600"
"38.50000","0.64018","349.30139","0.69616","-0.44148","0.00333","157.30359"
"39.00000","0.64806","352.59705","0.70383","-0.43381","0.00336","158.78775"
"39.50000","0.65683","356.43066","0.71235","-0.42529","0.00341","160.51418"
"40.00000","0.66482","359.82108","0.72013","-0.41751","0.00344","162.04100"
"40.50000","0.67352","363.60345","0.72858","-0.40905","0.00348","163.74434"
"41.00000","0.68155","366.89291","0.73640","-0.40124","0.00352","165.22571"
"41.50000","0.68989","370.39343","0.74451","-0.39312","0.00356","166.80212"
"42.00000","0.69833","374.01562","0.75272","-0.38492","0.00360","168.43333"
"42.50000","0.70641","377.23236","0.76059","-0.37704","0.00364","169.88196"
"43.00000","0.71501","380.89505","0.76896","-0.36868","0.00368","171.53140"
"43.50000","0.72311","384.26221","0.77684","-0.36079","0.00371","173.04776"
"44.00000","0.73193","388.29880","0.78540","-0.35223","0.00375","174.86559"
"44.50000","0.73979","391.36322","0.79309","-0.34455","0.00379","176.24562"
"45.00000","0.74842","395.11713","0.80150","-0.33613","0.00383","177.93614"
"45.50000","0.75659","398.46106","0.80948","-0.32816","0.00387","179.44205"
"46.00000","0.76516","402.19016","0.81784","-0.31980","0.00391","181.12140"
"46.50000","0.77321","405.54065","0.82570","-0.31194","0.00395","182.63025"
"47.00000","0.78152","408.90012","0.83381","-0.30382","0.00399","184.14314"
"47.50000","0.79003","412.54642","0.84211","-0.29552","0.00403","185.78520"
"48.00000","0.79803","415.98654","0.84992","-0.28772","0.00406","187.33443"
"48.50000","0.80669","419.62244","0.85837","-0.27926","0.00410","188.97180"
"49.00000","0.81474","422.84406","0.86624","-0.27139","0.00414","190.42262"
"49.50000","0.82361","426.75394","0.87489","-0.26275","0.00418","192.18340"
"50.00000","0.83146","429.97458","0.88256","-0.25508","0.00422","193.63376"
"50.50000","0.84018","433.76443","0.89105","-0.24658","0.00426","195.34048"
"51.00000","0.84826","437.04080","0.89895","-0.23869","0.00430","196.81595"
"51.50000","0.85671","440.75436","0.90719","-0.23045","0.00434","198.48831"
"52.00000","0.86490","444.19653","0.91518","-0.22245","0.00437","200.03845"
"52.50000","0.87315","447.53333","0.92325","-0.21439","0.00441","201.54114"
"53.00000","0.88173","451.31491","0.93161","-0.20603","0.00445","203.24413"
"53.50000","0.88970","454.64398","0.93939","-0.19825","0.00449","204.74333"
"54.00000","0.89847","458.40045","0.94794","-0.18969","0.00453","206.43501"
"54.50000","0.90643","461.75113","0.95571","-0.18193","0.00457","207.94394"
"55.00000","0.91530","465.65897","0.96437","-0.17327","0.00461","209.70380"
"55.50000","0.92316","468.84161","0.97204","-0.16560","0.00465","211.13705"
"56.00000","0.93170","472.56757","0.98037","-0.15726","0.00469","212.81499"
"56.50000","0.93991","475.95071","0.98838","-0.14925","0.00472","214.33855"
"57.00000","0.94826","479.57596","0.99653","-0.14111","0.00476","215.97113"
"57.50000","0.95658","483.08685","1.00465","-0.13298","0.00480","217.55223"
"58.00000","0.96481","486.47928","1.01268","-0.12495","0.00484","219.07996"
"58.50000","0.97346","490.25748","1.02113","-0.11651","0.00488","220.78143"
"59.00000","0.98143","493.51910","1.02892","-0.10871","0.00492","222.25026"
"59.50000","0.99011","497.26880","1.03742","-0.10021","0.00496","223.93889"
"60.00000","0.99819","500.56433","1.04534","-0.09230","0.00500","225.42299"
"60.50000","1.00696","504.39694","1.05392","-0.08372","0.00504","227.14896"
"61.00000","1.01482","507.35529","1.06162","-0.07601","0.00507","228.48122"
"61.50000","1.02331","510.92044","1.06993","-0.06770","0.00511","230.08675"
"62.00000","1.03161","514.41107","1.07806","-0.05957","0.00515","231.65871"
"62.50000","1.03989","517.72992","1.08617","-0.05146","0.00519","233.15331"
"63.00000","1.04828","521.22229","1.09439","-0.04324","0.00523","234.72604"
"63.50000","1.05643","524.47797","1.10237","-0.03526","0.00527","236.19220"
"64.00000","1.06517","528.07709","1.11094","-0.02670","0.00531","237.81302"
"64.50000","1.07307","531.04785","1.11869","-0.01895","0.00535","239.15088"
"65.00000","1.08184","534.70483","1.12727","-0.01036","0.00539","240.79774"
"65.50000","1.08981","537.74506","1.13509","-0.00254","0.00543","242.16687"
"66.00000","1.09855","541.51062","1.14365","0.00601","0.00547","243.86266"
"66.50000","1.10649","544.35364","1.15145","0.01381","0.00550","245.14297"
"67.00000","1.11497","547.84424","1.15976","0.02213","0.00554","246.71492"
"67.50000","1.12330","551.04932","1.16794","0.03030","0.00558","248.15828"
"68.00000","1.13148","554.05786","1.17597","0.03833","0.00562","249.51315"
"68.50000","1.14002","557.54816","1.18433","0.04670","0.00566","251.08496"
"69.00000","1.14809","560.45477","1.19227","0.05463","0.00570","252.39392"
"69.50000","1.15686","564.10486","1.20086","0.06323","0.00574","254.03769"
"70.00000","1.16474","566.80969","1.20862","0.07098","0.00578","255.25578"
"70.50000","1.17347","570.46570","1.21717","0.07953","0.00582","256.90222"
"71.00000","1.18149","573.22772","1.22505","0.08742","0.00586","258.14606"
"71.50000","1.19019","576.79401","1.23358","0.09594","0.00590","259.75208"
"72.00000","1.19820","579.73505","1.24144","0.10381","0.00593","261.07654"
"72.50000","1.20655","582.83215","1.24965","0.11201","0.00597","262.47128"
"73.00000","1.21503","585.94897","1.25797","0.12034","0.00601","263.87491"
"73.50000","1.22316","588.99554","1.26596","0.12832","0.00605","265.24692"
"74.00000","1.23169","592.14966","1.27434","0.13671","0.00609","266.66733"
"74.50000","1.23982","595.27820","1.28233","0.14470","0.00613","268.07623"
"75.00000","1.24854","598.44873","1.29091","0.15327","0.00617","269.50403"
"75.50000","1.25640","601.14655","1.29865","0.16101","0.00621","270.71896"
"76.00000","1.26505","604.61633","1.30714","0.16950","0.00625","272.28152"
"76.50000","1.27321","607.44293","1.31518","0.17754","0.00629","273.55444"
"77.00000","1.28183","610.63104","1.32365","0.18601","0.00633","274.99017"
"77.50000","1.28987","613.36285","1.33157","0.19393","0.00637","276.22043"
"78.00000","1.29822","616.40045","1.33978","0.20214","0.00640","277.58838"
"78.50000","1.30674","619.48358","1.34816","0.21052","0.00644","278.97681"
"79.00000","1.31479","622.34674","1.35608","0.21845","0.00648","280.26620"
"79.50000","1.32338","625.48694","1.36453","0.22690","0.00652","281.68036"
"80.00000","1.33144","628.07269","1.37248","0.23485","0.00656","282.84482"
"80.50000","1.34021","631.31061","1.38111","0.24347","0.00660","284.30298"
"81.00000","1.34811","633.93341","1.38888","0.25125","0.00664","285.48413"
"81.50000","1.35684","637.11255","1.39747","0.25983","0.00668","286.91580"
"82.00000","1.36491","639.67139","1.40543","0.26779","0.00672","288.06815"
"82.50000","1.37340","642.74017","1.41378","0.27615","0.00676","289.45013"
"83.00000","1.38157","645.33368","1.42183","0.28420","0.00680","290.61810"
"83.50000","1.38982","648.10437","1.42996","0.29232","0.00684","291.86584"
"84.00000","1.39837","651.04132","1.43838","0.30074","0.00688","293.18845"
"84.50000","1.40638","653.53436","1.44628","0.30865","0.00691","294.31116"
"85.00000","1.41506","656.60004","1.45482","0.31718","0.00695","295.69174"
"85.50000","1.42309","659.04022","1.46274","0.32510","0.00699","296.79065"
"86.00000","1.43192","662.25964","1.47143","0.33380","0.00703","298.24048"
"86.50000","1.43981","664.58521","1.47922","0.34158","0.00707","299.28778"
"87.00000","1.44837","667.48901","1.48765","0.35001","0.00711","300.59546"
"87.50000","1.45662","669.96021","1.49579","0.35815","0.00715","301.70834"
"88.00000","1.46502","672.70685","1.50407","0.36643","0.00719","302.94525"
"88.50000","1.47325","675.28076","1.51218","0.37455","0.00723","304.10440"
"89.00000","1.48152","677.79852","1.52034","0.38270","0.00727","305.23822"
"89.50000","1.49009","680.66510","1.52878","0.39115","0.00731","306.52917"
"90.00000","1.49805","682.94250","1.53664","0.39900","0.00735","307.55475"
"90.50000","1.50668","685.72974","1.54515","0.40751","0.00739","308.80997"
"91.00000","1.51480","688.08850","1.55316","0.41553","0.00742","309.87219"
"91.50000","1.52361","691.02649","1.56184","0.42420","0.00747","311.19528"
"92.00000","1.53146","692.98749","1.56960","0.43196","0.00750","312.07840"
"92.50000","1.54008","695.83862","1.57809","0.44046","0.00754","313.36237"
"93.00000","1.54830","698.20020","1.58621","0.44858","0.00758","314.42587"
"93.50000","1.55661","700.59460","1.59441","0.45677","0.00762","315.50418"
"94.00000","1.56491","703.13641","1.60260","0.46496","0.00766","316.64883"
"94.50000","1.57315","705.44897","1.61073","0.47309","0.00770","317.69028"
"95.00000","1.58179","708.08685","1.61926","0.48162","0.00774","318.87820"
"95.50000","1.58974","710.11115","1.62711","0.48948","0.00778","319.78983"
"96.00000","1.59852","712.76282","1.63578","0.49814","0.00782","320.98398"
"96.50000","1.60648","714.87799","1.64364","0.50601","0.00786","321.93652"
"97.00000","1.61530","717.53021","1.65234","0.51471","0.00790","323.13092"
"97.50000","1.62317","719.59332","1.66012","0.52249","0.00794","324.06000"
"98.00000","1.63168","721.99219","1.66853","0.53089","0.00798","325.14032"
"98.50000","1.63994","724.16571","1.67669","0.53905","0.00801","326.11914"
"99.00000","1.64817","726.22400","1.68483","0.54719","0.00805","327.04605"
"99.50000","1.65662","728.54590","1.69317","0.55553","0.00809","328.09167"
"100.00000","1.66474","730.61700","1.70120","0.56356","0.00813","329.02438"
"100.50000","1.67349","733.03015","1.70985","0.57221","0.00817","330.11111"
"101.00000","1.68142","734.86755","1.71769","0.58005","0.00821","330.93857"
"101.50000","1.69011","737.26349","1.72627","0.58863","0.00825","332.01755"
"102.00000","1.69817","739.05109","1.73426","0.59662","0.00829","332.82257"
"102.50000","1.70694","741.57361","1.74292","0.60528","0.00833","333.95856"
"103.00000","1.71485","743.09607","1.75075","0.61311","0.00837","334.64417"
"103.50000","1.72331","745.29987","1.75912","0.62149","0.00841","335.63663"
"104.00000","1.73167","747.29486","1.76740","0.62976","0.00845","336.53506"
"104.50000","1.73979","748.98621","1.77545","0.63781","0.00849","337.29672"
"105.00000","1.74830","751.06903","1.78387","0.64623","0.00853","338.23471"
"105.50000","1.75646","752.91479","1.79196","0.65432","0.00857","339.06592"
"106.00000","1.76523","755.09857","1.80063","0.66299","0.00861","340.04935"
"106.50000","1.77308","756.63037","1.80842","0.67078","0.00864","340.73920"
"107.00000","1.78184","758.82806","1.81709","0.67945","0.00869","341.72888"
"107.50000","1.78986","760.33978","1.82504","0.68741","0.00872","342.40967"
"108.00000","1.79852","762.46448","1.83362","0.69598","0.00876","343.36652"
"108.50000","1.80649","763.89435","1.84152","0.70389","0.00880","344.01044"
"109.00000","1.81495","765.81653","1.84990","0.71227","0.00884","344.87607"
"109.50000","1.82334","767.46289","1.85823","0.72060","0.00888","345.61749"
"110.00000","1.83144","768.88928","1.86627","0.72863","0.00892","346.25983"
"110.50000","1.84008","770.80792","1.87483","0.73719","0.00896","347.12387"
"111.00000","1.84809","772.18811","1.88278","0.74515","0.00900","347.74542"
"111.50000","1.85699","773.92499","1.89161","0.75397","0.00904","348.52762"
"112.00000","1.86477","775.04095","1.89934","0.76170","0.00908","349.03015"
"112.50000","1.87350","776.96893","1.90799","0.77035","0.00912","349.89841"
"113.00000","1.88151","777.99426","1.91596","0.77832","0.00916","350.36014"
"113.50000","1.89010","779.96307","1.92447","0.78683","0.00920","351.24680"
"114.00000","1.89820","781.11926","1.93252","0.79489","0.00924","351.76746"
"114.50000","1.90650","782.54950","1.94076","0.80312","0.00928","352.41156"
"115.00000","1.91502","784.19409","1.94921","0.81158","0.00932","353.15216"
"115.50000","1.92308","785.49634","1.95722","0.81958","0.00936","353.73862"
"116.00000","1.93171","787.13428","1.96578","0.82814","0.00940","354.47626"
"116.50000","1.93977","788.19788","1.97379","0.83615","0.00943","354.95523"
"117.00000","1.94860","790.02216","1.98255","0.84491","0.00948","355.77676"
"117.50000","1.95644","790.90704","1.99035","0.85272","0.00951","356.17526"
"118.00000","1.96508","792.26422","1.99894","0.86130","0.00956","356.78644"
"118.50000","1.97327","793.01929","2.00709","0.86945","0.00959","357.12650"
"119.00000","1.98175","793.43201","2.01556","0.87792","0.00963","357.31235"
"119.50000","1.98992","793.79541","2.02371","0.88607","0.00967","357.47601"
"120.00000","1.99820","794.57788","2.03195","0.89432","0.00971","357.82837"
"120.50000","2.00676","795.45856","2.04047","0.90284","0.00975","358.22498"
"121.00000","2.01473","796.14612","2.04842","0.91078","0.00979","358.53461"
"121.50000","2.02344","797.28143","2.05708","0.91944","0.00983","359.04590"
"122.00000","2.03147","798.00525","2.06507","0.92744","0.00987","359.37186"
"122.50000","2.04029","799.30499","2.07384","0.93620","0.00991","359.95718"
"123.00000","2.04808","799.64337","2.08162","0.94398","0.00995","360.10956"
"123.50000","2.05674","800.85162","2.09022","0.95259","0.00999","360.65369"
"124.00000","2.06493","801.64569","2.09837","0.96074","0.01003","361.01129"
"124.50000","2.07328","802.60065","2.10668","0.96905","0.01007","361.44135"
"125.00000","2.08160","803.50439","2.11497","0.97733","0.01011","361.84833"
"125.50000","2.08980","804.33813","2.12314","0.98550","0.01015","362.22379"
"126.00000","2.09849","805.49579","2.13177","0.99414","0.01019","362.74512"
"126.50000","2.10640","806.19379","2.13965","1.00202","0.01023","363.05945"
"127.00000","2.11516","807.42596","2.14836","1.01073","0.01027","363.61435"
"127.50000","2.12310","808.01910","2.15627","1.01864","0.01031","363.88147"
"128.00000","2.13198","809.23810","2.16510","1.02746","0.01035","364.43042"
"128.50000","2.13981","809.82928","2.17291","1.03527","0.01039","364.69666"
"129.00000","2.14833","810.93683","2.18137","1.04374","0.01043","365.19543"
"129.50000","2.15662","811.82483","2.18963","1.05199","0.01047","365.59534"
"130.00000","2.16492","812.75983","2.19788","1.06025","0.01051","366.01639"
"130.50000","2.17327","813.74628","2.20620","1.06856","0.01055","366.46063"
"131.00000","2.18142","814.48694","2.21432","1.07668","0.01058","366.79419"
"131.50000","2.19014","815.78705","2.22298","1.08534","0.01063","367.37967"
"132.00000","2.19806","816.42914","2.23087","1.09323","0.01066","367.66882"
"132.50000","2.20673","817.45966","2.23949","1.10185","0.01070","368.13290"
"133.00000","2.21485","818.04425","2.24759","1.10995","0.01074","368.39618"
"133.50000","2.22364","819.09271","2.25634","1.11870","0.01079","368.86835"
"134.00000","2.23152","819.18640","2.26421","1.12657","0.01082","368.91052"
"134.50000","2.24000","819.13080","2.27269","1.13506","0.01086","368.88550"
"135.00000","2.24834","819.29126","2.28103","1.14339","0.01090","368.95773"
"135.50000","2.25652","819.32275","2.28921","1.15157","0.01094","368.97192"
"136.00000","2.26498","819.52911","2.29765","1.16002","0.01098","369.06485"
"136.50000","2.27312","819.79114","2.30578","1.16814","0.01102","369.18286"
"137.00000","2.28187","820.47607","2.31450","1.17687","0.01106","369.49130"
"137.50000","2.28969","820.28870","2.32233","1.18469","0.01110","369.40692"
"138.00000","2.29847","820.61401","2.33109","1.19346","0.01114","369.55344"
"138.50000","2.30650","819.97308","2.33915","1.20151","0.01118","369.26480"
"139.00000","2.31516","819.69171","2.34782","1.21019","0.01122","369.13809"
"139.50000","2.32318","818.78259","2.35588","1.21825","0.01126","368.72867"
"140.00000","2.33162","818.57855","2.36433","1.22670","0.01130","368.63678"
"140.50000","2.34003","818.65881","2.37274","1.23511","0.01134","368.67294"
"141.00000","2.34813","818.58325","2.38084","1.24320","0.01138","368.63892"
"141.50000","2.35671","819.00421","2.38941","1.25177","0.01142","368.82849"
"142.00000","2.36472","819.23529","2.39741","1.25977","0.01146","368.93256"
"142.50000","2.37359","820.10925","2.40624","1.26860","0.01150","369.32611"
"143.00000","2.38143","820.37433","2.41407","1.27643","0.01154","369.44550"
"143.50000","2.39015","821.37354","2.42274","1.28510","0.01158","369.89548"
"144.00000","2.39822","821.66785","2.43080","1.29316","0.01162","370.02802"
"144.50000","2.40682","822.45581","2.43937","1.30173","0.01166","370.38287"
"145.00000","2.41488","822.92316","2.44740","1.30977","0.01170","370.59332"
"145.50000","2.42318","822.27960","2.45573","1.31810","0.01174","370.30350"
"146.00000","2.43170","823.02905","2.46422","1.32659","0.01178","370.64102"
"146.50000","2.43974","823.53949","2.47224","1.33461","0.01182","370.87088"
"147.00000","2.44830","824.43591","2.48076","1.34312","0.01186","371.27457"
"147.50000","2.45644","825.12952","2.48887","1.35123","0.01190","371.58694"
"148.00000","2.46532","826.26392","2.49770","1.36007","0.01194","372.09781"
"148.50000","2.47311","826.88483","2.50547","1.36783","0.01198","372.37741"
"149.00000","2.48179","828.16461","2.51409","1.37646","0.01202","372.95377"
"149.50000","2.48994","828.87720","2.52220","1.38457","0.01206","373.27466"
"150.00000","2.49842","829.90814","2.53064","1.39301","0.01210","373.73892"
"150.50000","2.50656","830.65405","2.53875","1.40112","0.01214","374.07483"
"151.00000","2.51487","831.20691","2.54703","1.40940","0.01218","374.32382"
"151.50000","2.52343","831.84393","2.55557","1.41793","0.01222","374.61069"
"152.00000","2.53137","832.13568","2.56349","1.42586","0.01225","374.74207"
"152.50000","2.54004","832.75781","2.57214","1.43451","0.01230","375.02225"
"153.00000","2.54807","833.12177","2.58016","1.44252","0.01233","375.18616"
"153.50000","2.55691","834.09760","2.58895","1.45131","0.01238","375.62561"
"154.00000","2.56477","834.21545","2.59680","1.45917","0.01241","375.67868"
"154.50000","2.57347","835.05347","2.60547","1.46784","0.01245","376.05606"
"155.00000","2.58159","835.33337","2.61358","1.47594","0.01249","376.18213"
"155.50000","2.58999","835.98511","2.62195","1.48431","0.01253","376.47562"
"156.00000","2.59828","835.59973","2.63025","1.49262","0.01257","376.30206"
"156.50000","2.60646","836.00104","2.63841","1.50078","0.01261","376.48279"
"157.00000","2.61509","836.81561","2.64702","1.50938","0.01265","376.84961"
"157.50000","2.62308","837.04675","2.65499","1.51736","0.01269","376.95370"
"158.00000","2.63182","837.91119","2.66369","1.52606","0.01273","377.34302"
"158.50000","2.63981","837.98505","2.67168","1.53405","0.01277","377.37625"
"159.00000","2.64866","838.98828","2.68049","1.54286","0.01281","377.82806"
"159.50000","2.65649","838.88397","2.68832","1.55069","0.01285","377.78110"
"160.00000","2.66499","839.33417","2.69681","1.55917","0.01289","377.98383"
"160.50000","2.67329","839.57251","2.70509","1.56745","0.01293","378.09116"
"161.00000","2.68156","839.85834","2.71335","1.57572","0.01297","378.21988"
"161.50000","2.68988","840.13074","2.72166","1.58403","0.01301","378.34256"
"162.00000","2.69809","840.36511","2.72986","1.59222","0.01305","378.44809"
"162.50000","2.70682","841.13379","2.73856","1.60092","0.01309","378.79425"
"163.00000","2.71472","841.18304","2.74646","1.60882","0.01313","378.81644"
"163.50000","2.72341","841.57288","2.75512","1.61749","0.01317","378.99200"
"164.00000","2.73149","841.75385","2.76320","1.62556","0.01321","379.07349"
"164.50000","2.74030","842.44629","2.77198","1.63434","0.01325","379.38535"
"165.00000","2.74817","842.16547","2.77986","1.64222","0.01329","379.25885"
"165.50000","2.75666","842.29614","2.78835","1.65071","0.01333","379.31772"
"166.00000","2.76498","842.45587","2.79665","1.65902","0.01337","379.38965"
"166.50000","2.77317","842.33826","2.80486","1.66722","0.01341","379.33667"
"167.00000","2.78161","842.11005","2.81331","1.67567","0.01345","379.23392"
"167.50000","2.78977","841.59515","2.82148","1.68385","0.01349","379.00204"
"168.00000","2.79851","841.31006","2.83024","1.69260","0.01353","378.87366"
"168.50000","2.80637","840.68970","2.83812","1.70049","0.01357","378.59427"
"169.00000","2.81517","840.63623","2.84693","1.70929","0.01361","378.57019"
"169.50000","2.82316","840.08820","2.85494","1.71730","0.01365","378.32339"
"170.00000","2.83187","840.22546","2.86365","1.72601","0.01369","378.38522"
"170.50000","2.83987","839.73560","2.87166","1.73403","0.01373","378.16461"
"171.00000","2.84825","839.66693","2.88005","1.74242","0.01377","378.13367"
"171.50000","2.85664","839.61292","2.88844","1.75081","0.01381","378.10934"
"172.00000","2.86481","839.52191","2.89662","1.75898","0.01385","378.06836"
"172.50000","2.87336","839.76031","2.90516","1.76752","0.01389","378.17572"
"173.00000","2.88143","839.70251","2.91322","1.77559","0.01393","378.14972"
"173.50000","2.89021","840.03180","2.92200","1.78436","0.01397","378.29800"
"174.00000","2.89807","839.77997","2.92987","1.79223","0.01401","378.18457"
"174.50000","2.90673","840.17645","2.93851","1.80087","0.01405","378.36313"
"175.00000","2.91489","840.28345","2.94666","1.80902","0.01409","378.41132"
"175.50000","2.92351","840.82886","2.95526","1.81762","0.01413","378.65695"
"176.00000","2.93152","840.70105","2.96327","1.82564","0.01416","378.59940"
"176.50000","2.93985","840.97766","2.97160","1.83396","0.01420","378.72394"
"177.00000","2.94838","841.34723","2.98011","1.84247","0.01425","378.89038"
"177.50000","2.95645","841.46967","2.98817","1.85054","0.01428","378.94553"
"178.00000","2.96499","841.91394","2.99670","1.85906","0.01432","379.14560"
"178.50000","2.97314","842.07727","3.00483","1.86719","0.01436","379.21915"
"179.00000","2.98194","842.75305","3.01360","1.87597","0.01441","379.52347"
"179.50000","2.98975","841.37207","3.02147","1.88384","0.01444","378.90158"
"180.00000","2.99845","841.88550","3.03015","1.89252","0.01448","379.13278"
"180.50000","3.00655","841.83502","3.03825","1.90062","0.01452","379.11005"
"181.00000","3.01509","842.37567","3.04677","1.90913","0.01456","379.35352"
"181.50000","3.02320","842.57129","3.05487","1.91724","0.01460","379.44162"
"182.00000","3.03153","842.85626","3.06320","1.92556","0.01464","379.56995"
"182.50000","3.04004","843.46234","3.07167","1.93404","0.01468","379.84290"
"183.00000","3.04806","843.59802","3.07969","1.94206","0.01472","379.90399"
"183.50000","3.05673","844.10773","3.08834","1.95070","0.01476","380.13354"
"184.00000","3.06475","844.20135","3.09635","1.95871","0.01480","380.17569"
"184.50000","3.07357","844.87311","3.10514","1.96751","0.01484","380.47821"
"185.00000","3.08145","844.96851","3.11302","1.97538","0.01488","380.52118"
"185.50000","3.09010","845.63428","3.12164","1.98401","0.01492","380.82101"
"186.00000","3.09824","845.71277","3.12978","1.99214","0.01496","380.85635"
"186.50000","3.10677","846.15247","3.13829","2.00066","0.01500","381.05435"
"187.00000","3.11494","846.26404","3.14646","2.00882","0.01504","381.10461"
"187.50000","3.12315","846.45099","3.15466","2.01703","0.01508","381.18881"
"188.00000","3.13174","846.85681","3.16323","2.02560","0.01512","381.37155"
"188.50000","3.13972","846.82843","3.17121","2.03358","0.01516","381.35876"
"189.00000","3.14834","847.31824","3.17982","2.04218","0.01520","381.57935"
"189.50000","3.15647","847.45978","3.18793","2.05030","0.01524","381.64310"
"190.00000","3.16526","848.02911","3.19670","2.05906","0.01528","381.89948"
"190.50000","3.17313","848.03149","3.20457","2.06694","0.01532","381.90057"
"191.00000","3.18170","848.61096","3.21312","2.07548","0.01536","382.16153"
"191.50000","3.18997","848.99280","3.22137","2.08373","0.01540","382.33347"
"192.00000","3.19835","849.35437","3.22974","2.09210","0.01544","382.49631"
"192.50000","3.20656","849.55853","3.23794","2.10031","0.01548","382.58826"
"193.00000","3.21481","849.86835","3.24617","2.10854","0.01552","382.72775"
"193.50000","3.22345","850.60150","3.25479","2.11715","0.01556","383.05792"
"194.00000","3.23137","850.68988","3.26270","2.12507","0.01560","383.09772"
"194.50000","3.24009","851.57800","3.27139","2.13375","0.01564","383.49768"
"195.00000","3.24813","851.70569","3.27942","2.14178","0.01568","383.55518"
"195.50000","3.25692","852.53247","3.28818","2.15054","0.01572","383.92752"
"196.00000","3.26479","852.76105","3.29603","2.15840","0.01576","384.03046"
"196.50000","3.27340","853.41541","3.30462","2.16698","0.01580","384.32513"
"197.00000","3.28162","853.85803","3.31282","2.17518","0.01584","384.52448"
"197.50000","3.28990","854.37744","3.32107","2.18344","0.01588","384.75839"
"198.00000","3.29827","854.89160","3.32943","2.19179","0.01591","384.98993"
"198.50000","3.30642","855.34741","3.33756","2.19993","0.01595","385.19519"
"199.00000","3.31515","856.03314","3.34625","2.20862","0.01600","385.50400"
"199.50000","3.32306","856.37775","3.35415","2.21652","0.01603","385.65918"
"200.00000","3.33184","857.09308","3.36291","2.22527","0.01608","385.98132"
"200.50000","3.33981","857.45715","3.37086","2.23322","0.01611","386.14529"
"201.00000","3.34865","858.35150","3.37967","2.24203","0.01616","386.54803"
"201.50000","3.35655","858.41364","3.38756","2.24993","0.01619","386.57602"
"202.00000","3.36499","859.04968","3.39597","2.25834","0.01623","386.86246"
"202.50000","3.37333","859.52112","3.40429","2.26665","0.01627","387.07477"
"203.00000","3.38149","859.84229","3.41244","2.27481","0.01631","387.21939"
"203.50000","3.38991","860.47266","3.42083","2.28320","0.01635","387.50330"
"204.00000","3.39807","860.92566","3.42898","2.29134","0.01639","387.70728"
"204.50000","3.40683","861.53516","3.43770","2.30007","0.01643","387.98178"
"205.00000","3.41475","861.79535","3.44561","2.30798","0.01647","388.09894"
"205.50000","3.42347","862.53125","3.45431","2.31667","0.01651","388.43036"
"206.00000","3.43156","862.94263","3.46237","2.32474","0.01655","388.61560"
"206.50000","3.44022","863.74628","3.47101","2.33337","0.01659","388.97751"
"207.00000","3.44817","863.95026","3.47895","2.34132","0.01663","389.06937"
"207.50000","3.45659","864.51788","3.48734","2.34970","0.01667","389.32501"
"208.00000","3.46500","864.99127","3.49573","2.35810","0.01671","389.53818"
"208.50000","3.47310","865.45245","3.50382","2.36618","0.01675","389.74588"
"209.00000","3.48164","866.05444","3.51233","2.37470","0.01679","390.01697"
"209.50000","3.48978","866.35907","3.52046","2.38282","0.01683","390.15414"
"210.00000","3.49858","867.23419","3.52922","2.39158","0.01687","390.54825"
"210.50000","3.50638","867.25073","3.53702","2.39938","0.01691","390.55569"
"211.00000","3.51520","868.07513","3.54580","2.40817","0.01695","390.92697"
"211.50000","3.52319","868.27576","3.55379","2.41615","0.01699","391.01730"
"212.00000","3.53182","868.97083","3.56238","2.42475","0.01703","391.33032"
"212.50000","3.53986","869.18970","3.57042","2.43278","0.01707","391.42889"
"213.00000","3.54820","869.50671","3.57875","2.44111","0.01711","391.57166"
"213.50000","3.55669","870.14978","3.58720","2.44957","0.01715","391.86127"
"214.00000","3.56474","870.25409","3.59525","2.45761","0.01719","391.90823"
"214.50000","3.57340","870.92157","3.60389","2.46625","0.01723","392.20883"
"215.00000","3.58140","871.05872","3.61188","2.47424","0.01727","392.27060"
"215.50000","3.59030","871.86060","3.62075","2.48311","0.01731","392.63171"
"216.00000","3.59815","871.90149","3.62859","2.49096","0.01735","392.65012"
"216.50000","3.60679","872.50873","3.63721","2.49958","0.01739","392.92358"
"217.00000","3.61491","872.58929","3.64533","2.50769","0.01742","392.95987"
"217.50000","3.62341","873.01257","3.65381","2.51618","0.01747","393.15048"
"218.00000","3.63154","873.37921","3.66192","2.52429","0.01750","393.31558"
"218.50000","3.63980","873.62433","3.67018","2.53254","0.01754","393.42596"
"219.00000","3.64839","874.05090","3.67875","2.54111","0.01758","393.61807"
"219.50000","3.65642","874.24231","3.68676","2.54913","0.01762","393.70428"
"220.00000","3.66510","874.84790","3.69542","2.55778","0.01766","393.97699"
"220.50000","3.67315","874.92706","3.70346","2.56583","0.01770","394.01263"
"221.00000","3.68193","875.56091","3.71222","2.57458","0.01774","394.29810"
"221.50000","3.68976","875.55127","3.72005","2.58241","0.01778","394.29376"
"222.00000","3.69838","876.01019","3.72865","2.59101","0.01782","394.50043"
"222.50000","3.70655","876.19330","3.73682","2.59918","0.01786","394.58289"
"223.00000","3.71500","876.65411","3.74524","2.60760","0.01790","394.79041"
"223.50000","3.72322","876.84607","3.75346","2.61583","0.01794","394.87686"
"224.00000","3.73153","877.14380","3.76176","2.62412","0.01798","395.01093"
"224.50000","3.74014","877.61450","3.77034","2.63271","0.01802","395.22290"
"225.00000","3.74803","877.59271","3.77823","2.64060","0.01806","395.21310"
"225.50000","3.75681","878.25201","3.78699","2.64935","0.01810","395.51001"
"226.00000","3.76476","878.39960","3.79493","2.65730","0.01814","395.57645"
"226.50000","3.77359","879.12201","3.80373","2.66609","0.01818","395.90179"
"227.00000","3.78145","879.07947","3.81160","2.67396","0.01822","395.88263"
"227.50000","3.79005","879.74377","3.82016","2.68253","0.01826","396.18179"
"228.00000","3.79825","880.04175","3.82836","2.69072","0.01830","396.31598"
"228.50000","3.80658","880.37268","3.83667","2.69903","0.01834","396.46503"
"229.00000","3.81496","880.66962","3.84504","2.70740","0.01838","396.59872"
"229.50000","3.82310","880.89807","3.85316","2.71553","0.01842","396.70163"
"230.00000","3.83179","881.47894","3.86184","2.72420","0.01846","396.96320"
"230.50000","3.83972","881.49683","3.86976","2.73213","0.01850","396.97125"
"231.00000","3.84845","882.27747","3.87846","2.74083","0.01854","397.32281"
"231.50000","3.85650","882.27045","3.88651","2.74887","0.01858","397.31964"
"232.00000","3.86530","883.02869","3.89528","2.75764","0.01862","397.66110"
"232.50000","3.87317","882.90411","3.90315","2.76551","0.01866","397.60501"
"233.00000","3.88160","883.24994","3.91157","2.77394","0.01870","397.76074"
"233.50000","3.88999","883.59546","3.91995","2.78231","0.01874","397.91635"
"234.00000","3.89824","883.96576","3.92818","2.79054","0.01878","398.08310"
"234.50000","3.90666","884.25409","3.93659","2.79895","0.01882","398.21295"
"235.00000","3.91478","884.39758","3.94470","2.80707","0.01886","398.27759"
"235.50000","3.92348","884.97205","3.95338","2.81575","0.01890","398.53629"
"236.00000","3.93134","884.80731","3.96124","2.82361","0.01894","398.46210"
"236.50000","3.94010","885.57825","3.96997","2.83234","0.01898","398.80927"
"237.00000","3.94814","885.54144","3.97801","2.84038","0.01902","398.79269"
"237.50000","3.95689","886.11377","3.98674","2.84910","0.01906","399.05045"
"238.00000","3.96484","886.09711","3.99469","2.85705","0.01909","399.04294"
"238.50000","3.97335","886.58539","4.00318","2.86554","0.01914","399.26282"
"239.00000","3.98171","886.24451","4.01156","2.87392","0.01918","399.10931"
"239.50000","3.98980","886.30688","4.01964","2.88201","0.01921","399.13742"
"240.00000","3.99834","886.57660","4.02817","2.89054","0.01926","399.25888"
"240.50000","4.00640","886.61322","4.03623","2.89859","0.01929","399.27536"
"241.00000","4.01517","887.01965","4.04499","2.90735","0.01934","399.45840"
"241.50000","4.02305","886.95715","4.05286","2.91522","0.01937","399.43024"
"242.00000","4.03185","887.56244","4.06164","2.92400","0.01941","399.70282"
"242.50000","4.03983","887.52124","4.06962","2.93199","0.01945","399.68430"
"243.00000","4.04853","887.88190","4.07831","2.94067","0.01949","399.84671"
"243.50000","4.05656","887.85126","4.08633","2.94870","0.01953","399.83289"
"244.00000","4.06487","887.96979","4.09464","2.95701","0.01957","399.88629"
"244.50000","4.07333","888.26886","4.10309","2.96545","0.01961","400.02097"
"245.00000","4.08143","888.20428","4.11119","2.97355","0.01965","399.99188"
"245.50000","4.09002","888.49255","4.11977","2.98214","0.01969","400.12170"
"246.00000","4.09812","888.42792","4.12787","2.99023","0.01973","400.09259"
"246.50000","4.10691","889.08160","4.13663","2.99900","0.01977","400.38696"
"247.00000","4.11478","888.85754","4.14451","3.00687","0.01981","400.28607"
"247.50000","4.12344","889.10779","4.15316","3.01553","0.01985","400.39877"
"248.00000","4.13160","889.23688","4.16132","3.02368","0.01989","400.45691"
"248.50000","4.14018","889.43903","4.16990","3.03226","0.01993","400.54794"
"249.00000","4.14822","889.25848","4.17793","3.04030","0.01997","400.46661"
"249.50000","4.15650","889.32172","4.18621","3.04858","0.02001","400.49512"
"250.00000","4.16503","889.55945","4.19474","3.05710","0.02005","400.60217"
"250.50000","4.17303","889.42273","4.20274","3.06511","0.02009","400.54059"
"251.00000","4.18170","889.84778","4.21140","3.07376","0.02013","400.73199"
"251.50000","4.18973","889.82367","4.21943","3.08179","0.02017","400.72116"
"252.00000","4.19859","890.30957","4.22826","3.09063","0.02021","400.93997"
"252.50000","4.20644","889.94714","4.23613","3.09850","0.02025","400.77676"
"253.00000","4.21517","890.41608","4.24484","3.10720","0.02029","400.98795"
"253.50000","4.22325","890.28564","4.25293","3.11529","0.02033","400.92920"
"254.00000","4.23170","890.42706","4.26137","3.12373","0.02037","400.99289"
"254.50000","4.23989","890.47083","4.26956","3.13193","0.02041","401.01260"
"255.00000","4.24815","890.43750","4.27782","3.14019","0.02045","400.99759"
"255.50000","4.25674","890.68402","4.28640","3.14876","0.02049","401.10861"
"256.00000","4.26472","890.38049","4.29439","3.15675","0.02053","400.97192"
"256.50000","4.27348","890.93158","4.30312","3.16549","0.02057","401.22009"
"257.00000","4.28141","890.66699","4.31107","3.17344","0.02061","401.10092"
"257.50000","4.29030","891.21277","4.31993","3.18230","0.02065","401.34671"
"258.00000","4.29816","890.82373","4.32781","3.19017","0.02069","401.17151"
"258.50000","4.30673","891.13220","4.33636","3.19873","0.02073","401.31042"
"259.00000","4.31492","891.18024","4.34455","3.20692","0.02077","401.33206"
"259.50000","4.32326","891.21490","4.35290","3.21526","0.02081","401.34769"
"260.00000","4.33158","891.26562","4.36122","3.22358","0.02085","401.37051"
"260.50000","4.33978","891.30115","4.36941","3.23177","0.02089","401.38651"
"261.00000","4.34847","891.61920","4.37809","3.24045","0.02093","401.52975"
"261.50000","4.35643","891.40466","4.38605","3.24842","0.02097","401.43314"
"262.00000","4.36511","891.83087","4.39472","3.25708","0.02101","401.62506"
"262.50000","4.37318","891.63416","4.40280","3.26516","0.02105","401.53647"
"263.00000","4.38195","892.04645","4.41155","3.27391","0.02109","401.72214"
"263.50000","4.38980","891.86414","4.41941","3.28177","0.02113","401.64005"
"264.00000","4.39831","892.07983","4.42791","3.29028","0.02117","401.73718"
"264.50000","4.40663","892.14948","4.43622","3.29859","0.02121","401.76855"
"265.00000","4.41488","892.21429","4.44447","3.30684","0.02124","401.79773"
"265.50000","4.42328","892.40057","4.45286","3.31523","0.02129","401.88162"
"266.00000","4.43143","892.41870","4.46102","3.32338","0.02132","401.88980"
"266.50000","4.44018","892.86597","4.46975","3.33211","0.02137","402.09122"
"267.00000","4.44808","892.66290","4.47766","3.34002","0.02140","401.99976"
"267.50000","4.45684","892.91418","4.48641","3.34877","0.02145","402.11292"
"268.00000","4.46483","892.95593","4.49439","3.35675","0.02148","402.13171"
"268.50000","4.47357","893.42279","4.50311","3.36548","0.02153","402.34198"
"269.00000","4.48149","892.64771","4.51107","3.37344","0.02156","401.99292"
"269.50000","4.48998","892.60480","4.51956","3.38192","0.02160","401.97360"
"270.00000","4.49830","892.49939","4.52788","3.39025","0.02164","401.92612"
"270.50000","4.50644","892.46613","4.53603","3.39839","0.02168","401.91116"
"271.00000","4.51500","892.61151","4.54458","3.40694","0.02172","401.97662"
"271.50000","4.52307","892.49884","4.55265","3.41502","0.02176","401.92587"
"272.00000","4.53186","892.78583","4.56143","3.42379","0.02180","402.05511"
"272.50000","4.53975","892.64838","4.56933","3.43169","0.02184","401.99323"
"273.00000","4.54846","892.86108","4.57802","3.44039","0.02188","402.08902"
"273.50000","4.55649","892.89069","4.58606","3.44842","0.02192","402.10236"
"274.00000","4.56518","893.19629","4.59473","3.45710","0.02196","402.23996"
"274.50000","4.57321","893.04529","4.60277","3.46513","0.02200","402.17197"
"275.00000","4.58157","893.14758","4.61113","3.47349","0.02204","402.21805"
"275.50000","4.59004","893.28577","4.61959","3.48196","0.02208","402.28027"
"276.00000","4.59816","893.15417","4.62772","3.49008","0.02212","402.22101"
"276.50000","4.60669","893.33673","4.63624","3.49860","0.02216","402.30322"
"277.00000","4.61482","893.01050","4.64438","3.50675","0.02220","402.15631"
"277.50000","4.62356","893.30823","4.65311","3.51547","0.02224","402.29037"
"278.00000","4.63141","892.95825","4.66098","3.52334","0.02228","402.13278"
"278.50000","4.64005","893.03552","4.66961","3.53197","0.02232","402.16757"
"279.00000","4.64821","892.88586","4.67778","3.54014","0.02236","402.10016"
"279.50000","4.65683","892.93488","4.68639","3.54876","0.02240","402.12225"
"280.00000","4.66487","892.57385","4.69445","3.55681","0.02244","401.95966"
"280.50000","4.67323","892.33881","4.70282","3.56518","0.02248","401.85382"
"281.00000","4.68172","892.03174","4.71132","3.57369","0.02252","401.71552"
"281.50000","4.68979","889.82971","4.71949","3.58185","0.02256","400.72388"
"281.72900","4.69375","856.51196","4.72484","3.58721","0.02259","385.71964"
"282.06400","4.69924","827.65771","4.73156","3.59392","0.02262","372.72546"
"282.56400","4.70763","821.46338","4.74022","3.60258","0.02266","369.93594"
"283.06400","4.71611","818.41528","4.74883","3.61120","0.02270","368.56326"
"283.56400","4.72415","816.47339","4.75696","3.61932","0.02274","367.68875"
"284.06400","4.73284","815.69019","4.76568","3.62804","0.02278","367.33606"
"284.56400","4.74083","814.96143","4.77370","3.63607","0.02282","367.00787"
"285.06400","4.74973","815.09070","4.78259","3.64496","0.02286","367.06607"
"285.56400","4.75751","814.69568","4.79039","3.65275","0.02290","366.88818"
"286.06400","4.76620","814.96313","4.79907","3.66144","0.02294","367.00864"
"286.56400","4.77426","814.83618","4.80714","3.66950","0.02298","366.95145"
"287.06400","4.78279","813.82843","4.81571","3.67807","0.02302","366.49762"
"287.56400","4.79096","813.88281","4.82388","3.68624","0.02306","366.52213"
"288.06400","4.79920","813.91278","4.83212","3.69448","0.02310","366.53561"
"288.56400","4.80778","814.29102","4.84068","3.70305","0.02314","366.70596"
"289.06400","4.81581","813.93420","4.84872","3.71109","0.02318","366.54526"
"289.56400","4.82446","813.66150","4.85739","3.71975","0.02322","366.42245"
"290.06400","4.83252","813.07806","4.86547","3.72783","0.02326","366.15970"
"290.56400","4.84135","813.31757","4.87430","3.73666","0.02330","366.26758"
"291.06400","4.84920","812.88434","4.88216","3.74452","0.02334","366.07248"
"291.56400","4.85780","812.97253","4.89076","3.75312","0.02338","366.11218"
"292.06400","4.86601","812.85181","4.89897","3.76134","0.02342","366.05783"
"292.56400","4.87440","813.03070","4.90735","3.76971","0.02346","366.13837"
"293.06400","4.88265","812.96954","4.91560","3.77797","0.02350","366.11084"
"293.56400","4.89091","813.20416","4.92386","3.78623","0.02354","366.21649"
"294.06400","4.89952","813.65350","4.93244","3.79481","0.02358","366.41885"
"294.56400","4.90746","813.73810","4.94038","3.80275","0.02362","366.45694"
"294.84600","4.91227","813.95709","4.94518","3.80754","0.02364","366.55557"