File: flexion/5_axis/Specimen_RawData_9.csv
Specimen properties : Specimen label,"F2"
Specimen properties : Support span,"72.00",mm
Specimen properties : Thickness,"4.67",mm
Specimen properties : Width,"14.37",mm
Maximum Load : Maximum Load,"1339",N
Tangent Modulus of Elasticity : Tangent Modulus of Elasticity,"49183102090.80060",Pa
Test : Rate 1,"1.00000",mm/min
Specimen notes : Specimen note 1,""

Time,Displacement,Load,Flexure extension,Corrected extension,Flexure strain (Corrected extension),Flexure stress
(s),(mm),(N),(mm),(mm),(mm/mm),(MPa)
"0.00000","0.00000","49.28032","-0.02713","-1.05560","-0.00015","16.98270"
"0.30000","0.00239","50.30010","-0.02488","-1.05335","-0.00013","17.33413"
"0.60000","0.00810","53.03922","-0.01953","-1.04800","-0.00011","18.27807"
"0.90000","0.01304","55.46937","-0.01492","-1.04339","-0.00008","19.11553"
"1.20000","0.01830","58.08536","-0.01000","-1.03847","-0.00005","20.01704"
"1.50000","0.02335","60.30386","-0.00521","-1.03368","-0.00003","20.78157"
"1.80000","0.02843","62.79493","-0.00042","-1.02889","0.00000","21.64003"
"2.10000","0.03307","64.83237","0.00398","-1.02449","0.00002","22.34216"
"2.40000","0.03793","67.01754","0.00858","-1.01989","0.00005","23.09520"
"2.70000","0.04299","69.35819","0.01337","-1.01510","0.00007","23.90182"
"3.00000","0.04800","71.58579","0.01812","-1.01035","0.00010","24.66948"
"3.30000","0.05323","73.84321","0.02308","-1.00539","0.00012","25.44742"
"3.60000","0.05822","76.21330","0.02780","-1.00068","0.00015","26.26419"
"3.90000","0.06351","78.57330","0.03281","-0.99566","0.00018","27.07748"
"4.20000","0.06828","80.69114","0.03733","-0.99114","0.00020","27.80732"
"4.50000","0.07302","82.72168","0.04183","-0.98664","0.00023","28.50707"
"4.80000","0.07800","85.07590","0.04654","-0.98193","0.00025","29.31837"
"5.10000","0.08299","87.38788","0.05126","-0.97721","0.00028","30.11511"
"5.40000","0.08813","89.66455","0.05618","-0.97230","0.00030","30.89968"
"5.70000","0.09311","92.04473","0.06093","-0.96754","0.00033","31.71992"
"6.00000","0.09840","94.46152","0.06598","-0.96249","0.00036","32.55279"
"6.30000","0.10334","96.85403","0.07068","-0.95779","0.00038","33.37728"
"6.60000","0.10826","99.11054","0.07538","-0.95309","0.00041","34.15490"
"6.90000","0.11304","101.35040","0.07994","-0.94853","0.00043","34.92679"
"7.20000","0.11794","103.68255","0.08462","-0.94386","0.00046","35.73048"
"7.50000","0.12303","106.02763","0.08947","-0.93900","0.00048","36.53863"
"7.80000","0.12805","108.45486","0.09426","-0.93421","0.00051","37.37509"
"8.10000","0.13325","111.13952","0.09919","-0.92928","0.00054","38.30026"
"8.40000","0.13832","113.44077","0.10404","-0.92443","0.00056","39.09330"
"8.70000","0.14350","116.09444","0.10896","-0.91951","0.00059","40.00780"
"9.00000","0.14816","118.31720","0.11341","-0.91507","0.00061","40.77379"
"9.30000","0.15297","120.70363","0.11798","-0.91049","0.00064","41.59619"
"9.60000","0.15796","123.17835","0.12273","-0.90574","0.00066","42.44901"
"9.90000","0.16301","125.60779","0.12755","-0.90093","0.00069","43.28623"
"10.20000","0.16813","128.09439","0.13242","-0.89605","0.00072","44.14315"
"10.50000","0.17322","130.58344","0.13727","-0.89121","0.00074","45.00091"
"10.80000","0.17847","133.28284","0.14226","-0.88621","0.00077","45.93116"
"11.10000","0.18328","135.59999","0.14684","-0.88163","0.00079","46.72969"
"11.40000","0.18813","137.94757","0.15146","-0.87701","0.00082","47.53870"
"11.70000","0.19297","140.44057","0.15606","-0.87242","0.00084","48.39782"
"12.00000","0.19798","143.03171","0.16082","-0.86766","0.00087","49.29076"
"12.30000","0.20311","145.64874","0.16570","-0.86278","0.00090","50.19263"
"12.60000","0.20811","148.19075","0.17044","-0.85803","0.00092","51.06864"
"12.90000","0.21335","150.88821","0.17542","-0.85305","0.00095","51.99823"
"13.20000","0.21830","153.44920","0.18013","-0.84834","0.00097","52.88078"
"13.50000","0.22337","156.09157","0.18494","-0.84353","0.00100","53.79138"
"13.80000","0.22803","158.42123","0.18938","-0.83909","0.00102","54.59421"
"14.10000","0.23295","160.96530","0.19408","-0.83439","0.00105","55.47094"
"14.40000","0.23805","163.74727","0.19895","-0.82953","0.00108","56.42964"
"14.70000","0.24306","166.51028","0.20372","-0.82475","0.00110","57.38181"
"15.00000","0.24824","169.40666","0.20866","-0.81981","0.00113","58.37995"
"15.30000","0.25319","172.33817","0.21336","-0.81511","0.00115","59.39019"
"15.60000","0.25849","175.47061","0.21839","-0.81009","0.00118","60.46967"
"15.90000","0.26317","178.24553","0.22283","-0.80564","0.00120","61.42595"
"16.20000","0.26799","181.21033","0.22740","-0.80107","0.00123","62.44766"
"16.50000","0.27299","184.30013","0.23214","-0.79633","0.00125","63.51245"
"16.80000","0.27801","187.31322","0.23691","-0.79157","0.00128","64.55080"
"17.10000","0.28315","190.66411","0.24175","-0.78672","0.00131","65.70557"
"17.40000","0.28816","193.70003","0.24651","-0.78197","0.00133","66.75179"
"17.70000","0.29341","197.18402","0.25147","-0.77701","0.00136","67.95242"
"18.00000","0.29827","200.33545","0.25606","-0.77241","0.00138","69.03844"
"18.30000","0.30321","203.54863","0.26074","-0.76774","0.00141","70.14575"
"18.60000","0.30799","206.85474","0.26525","-0.76322","0.00143","71.28509"
"18.90000","0.31290","210.05289","0.26991","-0.75857","0.00146","72.38721"
"19.20000","0.31808","213.66426","0.27480","-0.75368","0.00149","73.63174"
"19.50000","0.32308","217.19301","0.27952","-0.74896","0.00151","74.84780"
"19.80000","0.32832","220.79111","0.28447","-0.74400","0.00154","76.08776"
"20.10000","0.33338","224.38513","0.28924","-0.73924","0.00156","77.32631"
"20.40000","0.33842","227.89168","0.29400","-0.73448","0.00159","78.53471"
"20.70000","0.34312","230.99434","0.29845","-0.73002","0.00161","79.60394"
"21.00000","0.34792","234.39034","0.30298","-0.72550","0.00164","80.77425"
"21.30000","0.35296","238.03090","0.30773","-0.72075","0.00166","82.02884"
"21.60000","0.35802","241.56172","0.31251","-0.71596","0.00169","83.24561"
"21.90000","0.36320","245.33586","0.31739","-0.71109","0.00172","84.54623"
"22.20000","0.36827","248.83847","0.32220","-0.70628","0.00174","85.75328"
"22.50000","0.37346","252.68076","0.32709","-0.70139","0.00177","87.07738"
"22.80000","0.37830","256.05365","0.33167","-0.69681","0.00179","88.23973"
"23.10000","0.38302","259.35556","0.33614","-0.69234","0.00182","89.37762"
"23.40000","0.38794","262.83075","0.34079","-0.68768","0.00184","90.57522"
"23.70000","0.39297","266.45538","0.34554","-0.68293","0.00187","91.82432"
"24.00000","0.39809","270.05740","0.35038","-0.67809","0.00189","93.06563"
"24.30000","0.40318","273.89777","0.35518","-0.67329","0.00192","94.38907"
"24.60000","0.40835","277.53400","0.36007","-0.66840","0.00195","95.64217"
"24.90000","0.41336","281.10965","0.36481","-0.66367","0.00197","96.87439"
"25.20000","0.41830","284.75485","0.36946","-0.65901","0.00200","98.13058"
"25.50000","0.42302","288.08142","0.37393","-0.65454","0.00202","99.27696"
"25.80000","0.42795","291.64383","0.37859","-0.64988","0.00205","100.50462"
"26.10000","0.43300","295.28101","0.38341","-0.64506","0.00207","101.75804"
"26.40000","0.43811","298.88669","0.38827","-0.64020","0.00210","103.00061"
"26.70000","0.44322","302.74725","0.39312","-0.63535","0.00212","104.33102"
"27.00000","0.44829","306.37604","0.39795","-0.63052","0.00215","105.58154"
"27.30000","0.45351","310.17004","0.40292","-0.62555","0.00218","106.88902"
"27.60000","0.45812","313.39758","0.40731","-0.62116","0.00220","108.00127"
"27.90000","0.46297","317.09991","0.41192","-0.61656","0.00223","109.27715"
"28.20000","0.46799","320.67172","0.41669","-0.61178","0.00225","110.50804"
"28.50000","0.47301","324.35562","0.42147","-0.60700","0.00228","111.77757"
"28.80000","0.47817","328.18594","0.42637","-0.60210","0.00230","113.09755"
"29.10000","0.48319","331.92432","0.43115","-0.59733","0.00233","114.38584"
"29.40000","0.48840","335.65326","0.43611","-0.59237","0.00236","115.67089"
"29.70000","0.49327","339.34399","0.44073","-0.58774","0.00238","116.94277"
"30.00000","0.49822","342.88715","0.44544","-0.58303","0.00241","118.16380"
"30.30000","0.50296","346.39294","0.44996","-0.57851","0.00243","119.37194"
"30.60000","0.50795","350.02118","0.45471","-0.57376","0.00246","120.62228"
"30.90000","0.51313","353.80988","0.45966","-0.56881","0.00248","121.92792"
"31.20000","0.51811","357.47327","0.46440","-0.56407","0.00251","123.19038"
"31.50000","0.52330","361.24368","0.46935","-0.55912","0.00254","124.48972"
"31.80000","0.52830","365.05038","0.47411","-0.55437","0.00256","125.80156"
"32.10000","0.53338","368.77060","0.47894","-0.54953","0.00259","127.08360"
"32.40000","0.53808","372.17563","0.48342","-0.54505","0.00261","128.25702"
"32.70000","0.54293","375.84070","0.48804","-0.54043","0.00264","129.52005"
"33.00000","0.54798","379.54428","0.49286","-0.53562","0.00266","130.79636"
"33.30000","0.55305","383.23865","0.49769","-0.53078","0.00269","132.06949"
"33.60000","0.55825","387.17661","0.50263","-0.52584","0.00272","133.42657"
"33.90000","0.56323","390.80786","0.50740","-0.52108","0.00274","134.67795"
"34.20000","0.56848","394.68912","0.51242","-0.51605","0.00277","136.01549"
"34.50000","0.57326","398.14990","0.51700","-0.51147","0.00279","137.20813"
"34.80000","0.57798","401.68427","0.52152","-0.50695","0.00282","138.42612"
"35.10000","0.58299","405.46884","0.52632","-0.50216","0.00284","139.73033"
"35.40000","0.58796","409.14212","0.53107","-0.49740","0.00287","140.99620"
"35.70000","0.59312","412.88977","0.53603","-0.49244","0.00290","142.28769"
"36.00000","0.59817","416.70200","0.54086","-0.48761","0.00292","143.60144"
"36.30000","0.60339","420.49734","0.54586","-0.48261","0.00295","144.90938"
"36.60000","0.60837","424.23489","0.55063","-0.47784","0.00298","146.19739"
"36.90000","0.61324","427.82571","0.55529","-0.47318","0.00300","147.43483"
"37.20000","0.61800","431.29730","0.55985","-0.46862","0.00303","148.63120"
"37.50000","0.62290","434.89990","0.56455","-0.46392","0.00305","149.87270"
"37.80000","0.62805","438.85986","0.56947","-0.45900","0.00308","151.23735"
"38.10000","0.63310","442.52036","0.57431","-0.45416","0.00310","152.49881"
"38.40000","0.63827","446.46106","0.57926","-0.44921","0.00313","153.85684"
"38.70000","0.64337","450.22424","0.58415","-0.44432","0.00316","155.15369"
"39.00000","0.64848","454.02301","0.58904","-0.43944","0.00318","156.46280"
"39.30000","0.65309","457.33551","0.59346","-0.43501","0.00321","157.60432"
"39.60000","0.65792","460.90637","0.59809","-0.43038","0.00323","158.83490"
"39.90000","0.66297","464.68851","0.60292","-0.42555","0.00326","160.13828"
"40.20000","0.66803","468.43542","0.60777","-0.42070","0.00329","161.42952"
"40.50000","0.67316","472.31042","0.61268","-0.41579","0.00331","162.76489"
"40.80000","0.67825","476.06332","0.61755","-0.41092","0.00334","164.05820"
"41.10000","0.68347","479.88898","0.62256","-0.40591","0.00336","165.37657"
"41.40000","0.68827","483.60995","0.62715","-0.40133","0.00339","166.65887"
"41.70000","0.69309","487.11398","0.63177","-0.39671","0.00341","167.86641"
"42.00000","0.69798","490.74759","0.63645","-0.39202","0.00344","169.11861"
"42.30000","0.70297","494.45416","0.64126","-0.38722","0.00347","170.39595"
"42.60000","0.70814","498.29175","0.64623","-0.38224","0.00349","171.71843"
"42.90000","0.71309","501.99442","0.65101","-0.37747","0.00352","172.99442"
"43.20000","0.71836","505.91946","0.65607","-0.37240","0.00355","174.34705"
"43.50000","0.72333","509.74557","0.66085","-0.36762","0.00357","175.66559"
"43.80000","0.72831","513.31927","0.66565","-0.36282","0.00360","176.89713"
"44.10000","0.73309","516.80621","0.67025","-0.35822","0.00362","178.09879"
"44.40000","0.73795","520.45288","0.67493","-0.35354","0.00365","179.35547"
"44.70000","0.74304","524.20245","0.67984","-0.34863","0.00367","180.64763"
"45.00000","0.74805","527.89343","0.68467","-0.34381","0.00370","181.91959"
"45.30000","0.75326","531.82330","0.68968","-0.33879","0.00373","183.27388"
"45.60000","0.75822","535.61530","0.69445","-0.33403","0.00375","184.58066"
"45.90000","0.76348","539.50726","0.69952","-0.32896","0.00378","185.92189"
"46.20000","0.76820","542.97229","0.70406","-0.32441","0.00381","187.11598"
"46.50000","0.77295","546.48639","0.70864","-0.31983","0.00383","188.32700"
"46.80000","0.77800","550.25946","0.71351","-0.31496","0.00386","189.62724"
"47.10000","0.78299","554.00397","0.71831","-0.31016","0.00388","190.91765"
"47.40000","0.78813","557.75751","0.72328","-0.30519","0.00391","192.21118"
"47.70000","0.79319","561.52112","0.72815","-0.30032","0.00394","193.50816"
"48.00000","0.79844","565.52899","0.73321","-0.29527","0.00396","194.88934"
"48.30000","0.80330","568.97302","0.73790","-0.29057","0.00399","196.07620"
"48.60000","0.80818","572.66846","0.74261","-0.28586","0.00401","197.34970"
"48.90000","0.81300","576.26294","0.74725","-0.28122","0.00404","198.58841"
"49.20000","0.81790","579.78052","0.75197","-0.27650","0.00406","199.80061"
"49.50000","0.82309","583.67987","0.75698","-0.27149","0.00409","201.14439"
"49.80000","0.82808","587.35999","0.76179","-0.26668","0.00412","202.41261"
"50.10000","0.83331","591.21075","0.76684","-0.26163","0.00414","203.73964"
"50.40000","0.83839","595.01691","0.77175","-0.25672","0.00417","205.05130"
"50.70000","0.84336","598.63458","0.77655","-0.25192","0.00420","206.29800"
"51.00000","0.84806","602.20898","0.78110","-0.24738","0.00422","207.52979"
"51.30000","0.85291","605.76959","0.78579","-0.24268","0.00425","208.75682"
"51.60000","0.85800","609.48578","0.79071","-0.23776","0.00427","210.03748"
"51.90000","0.86302","613.20203","0.79556","-0.23291","0.00430","211.31815"
"52.20000","0.86825","617.14362","0.80061","-0.22786","0.00433","212.67648"
"52.50000","0.87330","620.86188","0.80549","-0.22298","0.00435","213.95784"
"52.80000","0.87846","624.61584","0.81049","-0.21798","0.00438","215.25151"
"53.10000","0.88323","628.26953","0.81510","-0.21338","0.00441","216.51062"
"53.40000","0.88801","631.60748","0.81972","-0.20875","0.00443","217.66093"
"53.70000","0.89292","635.25922","0.82447","-0.20400","0.00446","218.91937"
"54.00000","0.89799","638.99066","0.82937","-0.19910","0.00448","220.20528"
"54.30000","0.90312","642.67975","0.83434","-0.19413","0.00451","221.47659"
"54.60000","0.90814","646.44751","0.83919","-0.18928","0.00454","222.77501"
"54.90000","0.91343","650.44708","0.84430","-0.18417","0.00456","224.15332"
"55.20000","0.91834","654.08789","0.84905","-0.17943","0.00459","225.40800"
"55.50000","0.92322","657.49274","0.85378","-0.17469","0.00461","226.58136"
"55.80000","0.92801","661.11920","0.85841","-0.17006","0.00464","227.83109"
"56.10000","0.93293","664.61975","0.86317","-0.16530","0.00467","229.03743"
"56.40000","0.93807","668.40460","0.86814","-0.16033","0.00469","230.34174"
"56.70000","0.94310","672.08240","0.87301","-0.15546","0.00472","231.60916"
"57.00000","0.94830","676.01227","0.87804","-0.15043","0.00475","232.96346"
"57.30000","0.95324","679.72003","0.88280","-0.14567","0.00477","234.24120"
"57.60000","0.95847","683.35498","0.88787","-0.14060","0.00480","235.49385"
"57.90000","0.96307","686.78143","0.89232","-0.13615","0.00482","236.67465"
"58.20000","0.96793","690.35278","0.89703","-0.13144","0.00485","237.90540"
"58.50000","0.97304","694.16577","0.90196","-0.12651","0.00488","239.21941"
"58.80000","0.97800","697.68567","0.90676","-0.12171","0.00490","240.43242"
"59.10000","0.98319","701.59088","0.91179","-0.11668","0.00493","241.77820"
"59.40000","0.98824","705.26740","0.91667","-0.11181","0.00495","243.04518"
"59.70000","0.99350","709.18243","0.92175","-0.10672","0.00498","244.39436"
"60.00000","0.99822","712.62939","0.92632","-0.10215","0.00501","245.58223"
"60.30000","1.00314","716.24805","0.93108","-0.09739","0.00503","246.82927"
"60.60000","1.00799","719.66101","0.93577","-0.09270","0.00506","248.00543"
"60.90000","1.01291","723.28485","0.94053","-0.08794","0.00508","249.25426"
"61.20000","1.01815","727.16431","0.94560","-0.08287","0.00511","250.59117"
"61.50000","1.02312","730.62256","0.95041","-0.07806","0.00514","251.78293"
"61.80000","1.02837","734.68060","0.95548","-0.07299","0.00516","253.18140"
"62.10000","1.03339","738.26160","0.96034","-0.06813","0.00519","254.41545"
"62.40000","1.03833","741.89349","0.96512","-0.06335","0.00522","255.66705"
"62.70000","1.04306","745.19934","0.96971","-0.05876","0.00524","256.80630"
"63.00000","1.04796","748.84320","0.97446","-0.05402","0.00527","258.06204"
"63.30000","1.05302","752.63647","0.97936","-0.04911","0.00529","259.36923"
"63.60000","1.05800","756.07617","0.98420","-0.04427","0.00532","260.55463"
"63.90000","1.06329","759.99457","0.98933","-0.03914","0.00535","261.90494"
"64.20000","1.06825","763.66016","0.99414","-0.03433","0.00537","263.16815"
"64.50000","1.07343","767.49268","0.99916","-0.02931","0.00540","264.48889"
"64.80000","1.07823","770.90955","1.00382","-0.02466","0.00543","265.66641"
"65.10000","1.08298","774.43079","1.00841","-0.02006","0.00545","266.87988"
"65.40000","1.08794","777.87640","1.01323","-0.01525","0.00548","268.06729"
"65.70000","1.09298","781.66791","1.01812","-0.01036","0.00550","269.37390"
"66.00000","1.09815","785.32202","1.02313","-0.00534","0.00553","270.63315"
"66.30000","1.10318","789.08221","1.02800","-0.00047","0.00556","271.92896"
"66.60000","1.10848","792.99078","1.03314","0.00467","0.00558","273.27591"
"66.90000","1.11333","796.30048","1.03785","0.00937","0.00561","274.41647"
"67.20000","1.11818","799.94366","1.04254","0.01407","0.00564","275.67197"
"67.50000","1.12298","803.32562","1.04719","0.01872","0.00566","276.83743"
"67.80000","1.12793","806.98523","1.05198","0.02351","0.00569","278.09860"
"68.10000","1.13304","810.67487","1.05694","0.02846","0.00571","279.37009"
"68.40000","1.13813","814.37836","1.06186","0.03339","0.00574","280.64636"
"68.70000","1.14330","818.10681","1.06687","0.03839","0.00577","281.93124"
"69.00000","1.14832","821.79688","1.07173","0.04326","0.00579","283.20291"
"69.30000","1.15347","825.45801","1.07672","0.04825","0.00582","284.46457"
"69.60000","1.15805","828.79169","1.08116","0.05269","0.00584","285.61340"
"69.90000","1.16292","832.28137","1.08588","0.05740","0.00587","286.81601"
"70.20000","1.16802","835.95544","1.09081","0.06234","0.00590","288.08215"
"70.50000","1.17306","839.72308","1.09569","0.06722","0.00592","289.38052"
"70.80000","1.17820","843.27106","1.10068","0.07221","0.00595","290.60321"
"71.10000","1.18322","846.86249","1.10555","0.07708","0.00598","291.84088"
"71.40000","1.18849","850.82800","1.11065","0.08218","0.00600","293.20743"
"71.70000","1.19317","854.15094","1.11520","0.08672","0.00603","294.35257"
"72.00000","1.19809","857.69305","1.11997","0.09150","0.00605","295.57324"
"72.30000","1.20297","861.28870","1.12469","0.09622","0.00608","296.81235"
"72.60000","1.20797","864.79419","1.12955","0.10108","0.00611","298.02039"
"72.90000","1.21316","868.58673","1.13458","0.10610","0.00613","299.32736"
"73.20000","1.21810","872.11554","1.13937","0.11090","0.00616","300.54343"
"73.50000","1.22338","875.87482","1.14449","0.11602","0.00619","301.83893"
"73.80000","1.22833","879.47064","1.14930","0.12083","0.00621","303.07809"
"74.10000","1.23331","883.09692","1.15412","0.12565","0.00624","304.32776"
"74.40000","1.23800","886.36774","1.15867","0.13020","0.00626","305.45493"
"74.70000","1.24293","889.84247","1.16346","0.13499","0.00629","306.65237"
"75.00000","1.24805","893.57959","1.16842","0.13995","0.00632","307.94025"
"75.30000","1.25305","897.10828","1.17328","0.14481","0.00634","309.15628"
"75.60000","1.25828","901.02069","1.17834","0.14987","0.00637","310.50455"
"75.90000","1.26327","904.54083","1.18319","0.15472","0.00640","311.71765"
"76.20000","1.26851","908.18042","1.18827","0.15980","0.00642","312.97189"
"76.50000","1.27315","911.46808","1.19278","0.16431","0.00645","314.10489"
"76.80000","1.27793","914.81714","1.19742","0.16895","0.00647","315.25900"
"77.10000","1.28299","918.39240","1.20232","0.17385","0.00650","316.49109"
"77.40000","1.28801","922.10352","1.20719","0.17871","0.00652","317.76999"
"77.70000","1.29318","925.76233","1.21221","0.18374","0.00655","319.03088"
"78.00000","1.29819","929.23474","1.21707","0.18859","0.00658","320.22751"
"78.30000","1.30346","933.07959","1.22218","0.19371","0.00661","321.55252"
"78.60000","1.30831","936.57074","1.22689","0.19841","0.00663","322.75562"
"78.90000","1.31314","939.84094","1.23157","0.20310","0.00666","323.88257"
"79.20000","1.31795","943.34705","1.23624","0.20777","0.00668","325.09082"
"79.50000","1.32295","946.83813","1.24109","0.21262","0.00671","326.29391"
"79.80000","1.32809","950.38953","1.24607","0.21759","0.00674","327.51776"
"80.10000","1.33311","953.88855","1.25093","0.22246","0.00676","328.72357"
"80.40000","1.33831","957.78217","1.25596","0.22749","0.00679","330.06537"
"80.70000","1.34338","961.21362","1.26087","0.23240","0.00682","331.24789"
"81.00000","1.34837","964.73486","1.26571","0.23724","0.00684","332.46136"
"81.30000","1.35304","967.93671","1.27024","0.24176","0.00687","333.56476"
"81.60000","1.35794","971.43793","1.27497","0.24650","0.00689","334.77133"
"81.90000","1.36298","974.88373","1.27986","0.25139","0.00692","335.95880"
"82.20000","1.36807","978.47357","1.28479","0.25631","0.00694","337.19592"
"82.50000","1.37320","982.07080","1.28976","0.26128","0.00697","338.43558"
"82.80000","1.37830","985.74872","1.29469","0.26622","0.00700","339.70303"
"83.10000","1.38352","989.38336","1.29975","0.27128","0.00703","340.95560"
"83.40000","1.38818","992.68158","1.30426","0.27579","0.00705","342.09219"
"83.70000","1.39300","995.86688","1.30895","0.28048","0.00707","343.18991"
"84.00000","1.39793","999.31897","1.31373","0.28526","0.00710","344.37955"
"84.30000","1.40303","1002.95569","1.31868","0.29021","0.00713","345.63281"
"84.60000","1.40815","1006.36707","1.32365","0.29518","0.00715","346.80841"
"84.90000","1.41316","1009.87823","1.32852","0.30004","0.00718","348.01840"
"85.20000","1.41844","1013.54663","1.33365","0.30517","0.00721","349.28259"
"85.50000","1.42328","1016.78064","1.33835","0.30987","0.00723","350.39709"
"85.80000","1.42820","1020.10303","1.34313","0.31465","0.00726","351.54202"
"86.10000","1.43297","1023.35858","1.34776","0.31929","0.00728","352.66394"
"86.40000","1.43796","1026.87537","1.35261","0.32414","0.00731","353.87585"
"86.70000","1.44309","1030.42310","1.35759","0.32912","0.00734","355.09848"
"87.00000","1.44810","1033.80688","1.36246","0.33399","0.00736","356.26456"
"87.30000","1.45329","1037.29102","1.36750","0.33902","0.00739","357.46524"
"87.60000","1.45826","1040.64771","1.37232","0.34385","0.00742","358.62201"
"87.90000","1.46346","1044.17004","1.37739","0.34891","0.00744","359.83588"
"88.20000","1.46806","1047.26062","1.38185","0.35337","0.00747","360.90091"
"88.50000","1.47292","1050.33923","1.38657","0.35810","0.00749","361.96185"
"88.80000","1.47802","1053.80627","1.39153","0.36306","0.00752","363.15665"
"89.10000","1.48304","1057.01941","1.39641","0.36793","0.00755","364.26395"
"89.40000","1.48819","1060.53552","1.40141","0.37293","0.00757","365.47565"
"89.70000","1.49322","1063.75671","1.40629","0.37782","0.00760","366.58569"
"90.00000","1.49849","1067.19812","1.41142","0.38294","0.00763","367.77167"
"90.30000","1.50322","1070.20386","1.41602","0.38755","0.00765","368.80750"
"90.60000","1.50805","1073.39307","1.42072","0.39225","0.00768","369.90652"
"90.90000","1.51293","1076.41650","1.42546","0.39699","0.00770","370.94846"
"91.20000","1.51796","1079.60779","1.43035","0.40188","0.00773","372.04822"
"91.50000","1.52314","1082.93201","1.43539","0.40692","0.00776","373.19379"
"91.80000","1.52811","1086.03748","1.44023","0.41176","0.00778","374.26398"
"92.10000","1.53341","1089.45386","1.44538","0.41691","0.00781","375.44131"
"92.40000","1.53840","1092.45789","1.45024","0.42177","0.00784","376.47653"
"92.70000","1.54330","1095.54517","1.45501","0.42653","0.00786","377.54047"
"93.00000","1.54803","1098.28320","1.45963","0.43115","0.00789","378.48404"
"93.30000","1.55290","1101.17639","1.46436","0.43589","0.00792","379.48105"
"93.60000","1.55800","1104.21838","1.46934","0.44086","0.00794","380.52939"
"93.90000","1.56306","1107.08826","1.47427","0.44580","0.00797","381.51837"
"94.20000","1.56826","1110.23462","1.47933","0.45086","0.00800","382.60266"
"94.50000","1.57336","1113.24683","1.48431","0.45584","0.00802","383.64072"
"94.80000","1.57847","1116.43518","1.48928","0.46081","0.00805","384.73947"
"95.10000","1.58319","1118.91614","1.49390","0.46543","0.00807","385.59442"
"95.40000","1.58794","1121.59192","1.49853","0.47005","0.00810","386.51654"
"95.70000","1.59294","1124.26074","1.50342","0.47494","0.00813","387.43625"
"96.00000","1.59800","1126.82971","1.50837","0.47990","0.00815","388.32156"
"96.30000","1.60315","1129.47742","1.51340","0.48493","0.00818","389.23401"
"96.60000","1.60824","1131.87512","1.51839","0.48991","0.00821","390.06027"
"96.90000","1.61347","1134.50366","1.52351","0.49503","0.00823","390.96613"
"97.20000","1.61828","1136.49548","1.52823","0.49976","0.00826","391.65253"
"97.50000","1.62312","1138.40564","1.53299","0.50452","0.00829","392.31079"
"97.80000","1.62794","1140.21045","1.53774","0.50926","0.00831","392.93274"
"98.10000","1.63297","1142.44666","1.54267","0.51420","0.00834","393.70337"
"98.40000","1.63805","1144.70691","1.54765","0.51918","0.00837","394.48230"
"98.70000","1.64314","1147.24939","1.55264","0.52417","0.00839","395.35846"
"99.00000","1.64831","1149.37341","1.55772","0.52925","0.00842","396.09045"
"99.30000","1.65333","1149.85608","1.56272","0.53425","0.00845","396.25677"
"99.60000","1.65843","1151.79004","1.56773","0.53926","0.00847","396.92325"
"99.90000","1.66303","1153.43262","1.57226","0.54379","0.00850","397.48929"
"100.20000","1.66794","1155.63123","1.57708","0.54861","0.00852","398.24698"
"100.50000","1.67301","1157.82129","1.58206","0.55359","0.00855","399.00171"
"100.80000","1.67803","1160.12463","1.58699","0.55852","0.00858","399.79547"
"101.10000","1.68322","1162.65112","1.59207","0.56360","0.00861","400.66614"
"101.40000","1.68827","1163.51599","1.59709","0.56861","0.00863","400.96417"
"101.70000","1.69347","1163.15833","1.60230","0.57383","0.00866","400.84091"
"102.00000","1.69821","1163.76953","1.60702","0.57854","0.00869","401.05154"
"102.30000","1.70308","1155.17419","1.61224","0.58377","0.00871","398.08948"
"102.60000","1.70794","1156.04944","1.61707","0.58860","0.00874","398.39108"
"102.90000","1.71299","1158.05542","1.62203","0.59356","0.00877","399.08240"
"103.20000","1.71818","1160.54224","1.62712","0.59865","0.00879","399.93936"
"103.50000","1.72313","1162.90454","1.63198","0.60350","0.00882","400.75345"
"103.80000","1.72840","1165.55383","1.63714","0.60867","0.00885","401.66644"
"104.10000","1.73332","1167.93542","1.64195","0.61348","0.00887","402.48718"
"104.40000","1.73825","1170.17908","1.64679","0.61832","0.00890","403.26038"
"104.70000","1.74300","1171.87231","1.65147","0.62300","0.00893","403.84387"
"105.00000","1.74795","1174.01111","1.65634","0.62787","0.00895","404.58093"
"105.30000","1.75302","1176.16992","1.66132","0.63285","0.00898","405.32489"
"105.60000","1.75809","1178.19397","1.66630","0.63783","0.00901","406.02240"
"105.90000","1.76332","1180.47852","1.67144","0.64297","0.00903","406.80969"
"106.20000","1.76828","1182.53528","1.67632","0.64784","0.00906","407.51849"
"106.50000","1.77346","1184.91101","1.68139","0.65292","0.00909","408.33719"
"106.80000","1.77816","1186.93579","1.68601","0.65754","0.00911","409.03497"
"107.10000","1.78291","1189.04443","1.69067","0.66220","0.00914","409.76163"
"107.40000","1.78798","1191.63110","1.69563","0.66716","0.00917","410.65305"
"107.70000","1.79299","1193.99817","1.70055","0.67208","0.00919","411.46878"
"108.00000","1.79819","1196.75366","1.70563","0.67716","0.00922","412.41833"
"108.30000","1.80325","1199.30579","1.71058","0.68211","0.00925","413.29785"
"108.60000","1.80846","1202.09839","1.71567","0.68720","0.00927","414.26022"
"108.90000","1.81329","1204.48755","1.72039","0.69192","0.00930","415.08356"
"109.20000","1.81809","1206.87634","1.72509","0.69662","0.00932","415.90677"
"109.50000","1.82294","1209.37891","1.72983","0.70136","0.00935","416.76920"
"109.80000","1.82794","1212.05334","1.73471","0.70624","0.00938","417.69083"
"110.10000","1.83311","1214.73022","1.73976","0.71129","0.00940","418.61334"
"110.40000","1.83815","1217.39453","1.74468","0.71621","0.00943","419.53149"
"110.70000","1.84336","1220.08655","1.74977","0.72130","0.00946","420.45920"
"111.00000","1.84839","1222.59534","1.75470","0.72623","0.00948","421.32376"
"111.30000","1.85335","1224.58435","1.75957","0.73109","0.00951","422.00919"
"111.60000","1.85801","1226.18054","1.76415","0.73568","0.00954","422.55927"
"111.90000","1.86293","1228.22351","1.76899","0.74051","0.00956","423.26331"
"112.20000","1.86801","1230.54614","1.77396","0.74549","0.00959","424.06372"
"112.50000","1.87304","1233.01086","1.77889","0.75042","0.00962","424.91309"
"112.80000","1.87823","1235.42871","1.78397","0.75550","0.00964","425.74631"
"113.10000","1.88332","1237.47314","1.78897","0.76050","0.00967","426.45087"
"113.40000","1.88849","1239.91052","1.79403","0.76556","0.00970","427.29080"
"113.70000","1.89317","1241.77368","1.79863","0.77015","0.00972","427.93289"
"114.00000","1.89800","1243.76526","1.80337","0.77490","0.00975","428.61920"
"114.30000","1.90297","1245.87585","1.80825","0.77978","0.00977","429.34656"
"114.60000","1.90801","1248.04578","1.81319","0.78472","0.00980","430.09433"
"114.90000","1.91321","1250.23181","1.81830","0.78983","0.00983","430.84769"
"115.20000","1.91810","1252.05371","1.82312","0.79465","0.00985","431.47552"
"115.50000","1.92347","1254.19946","1.82840","0.79993","0.00988","432.21500"
"115.80000","1.92825","1255.98450","1.83311","0.80464","0.00991","432.83014"
"116.10000","1.93315","1257.79089","1.83793","0.80946","0.00993","433.45264"
"116.40000","1.93803","1259.56567","1.84273","0.81426","0.00996","434.06427"
"116.70000","1.94297","1261.41394","1.84759","0.81912","0.00999","434.70120"
"117.00000","1.94809","1263.41382","1.85264","0.82417","0.01001","435.39038"
"117.30000","1.95309","1265.32471","1.85756","0.82909","0.01004","436.04892"
"117.60000","1.95834","1267.36682","1.86272","0.83424","0.01007","436.75266"
"117.90000","1.96325","1269.26746","1.86755","0.83908","0.01009","437.40762"
"118.20000","1.96844","1271.15796","1.87265","0.84418","0.01012","438.05914"
"118.50000","1.97312","1272.98206","1.87726","0.84879","0.01015","438.68774"
"118.80000","1.97789","1268.64880","1.88221","0.85374","0.01017","437.19443"
"119.10000","1.98304","1263.61536","1.88758","0.85910","0.01020","435.45984"
"119.40000","1.98802","1251.88818","1.89305","0.86458","0.01023","431.41849"
"119.70000","1.99320","1249.69104","1.89832","0.86985","0.01026","430.66132"
"120.00000","1.99825","1249.10535","1.90339","0.87492","0.01029","430.45947"
"120.30000","2.00349","1249.07617","1.90863","0.88016","0.01032","430.44943"
"120.60000","2.00822","1248.56360","1.91338","0.88491","0.01034","430.27280"
"120.90000","2.01305","1248.15540","1.91824","0.88976","0.01037","430.13211"
"121.20000","2.01797","1247.61377","1.92317","0.89470","0.01039","429.94547"
"121.50000","2.02292","1246.87024","1.92816","0.89969","0.01042","429.68924"
"121.80000","2.02817","1245.97290","1.93344","0.90497","0.01045","429.38000"
"122.10000","2.03314","1245.38220","1.93844","0.90997","0.01048","429.17642"
"122.40000","2.03837","1244.75427","1.94370","0.91523","0.01051","428.96005"
"122.70000","2.04339","1244.33215","1.94874","0.92026","0.01053","428.81458"
"123.00000","2.04822","1244.31079","1.95357","0.92509","0.01056","428.80722"
"123.30000","2.05300","1244.59241","1.95833","0.92986","0.01058","428.90427"
"123.60000","2.05791","1245.17822","1.96322","0.93474","0.01061","429.10614"
"123.90000","2.06304","1246.19751","1.96831","0.93984","0.01064","429.45740"
"124.20000","2.06807","1247.45020","1.97328","0.94481","0.01067","429.88910"
"124.50000","2.07331","1248.98413","1.97846","0.94999","0.01069","430.41772"
"124.80000","2.07836","1250.28357","1.98345","0.95498","0.01072","430.86551"
"125.10000","2.08343","1251.98376","1.98845","0.95998","0.01075","431.45142"
"125.40000","2.08813","1253.23511","1.99310","0.96462","0.01077","431.88266"
"125.70000","2.09292","1254.63403","1.99783","0.96936","0.01080","432.36475"
"126.00000","2.09793","1256.37463","2.00277","0.97429","0.01083","432.96460"
"126.30000","2.10304","1258.20227","2.00780","0.97933","0.01085","433.59442"
"126.60000","2.10818","1260.18457","2.01285","0.98438","0.01088","434.27756"
"126.90000","2.11320","1261.91052","2.01781","0.98934","0.01091","434.87234"
"127.20000","2.11854","1263.98291","2.02306","0.99458","0.01093","435.58652"
"127.50000","2.12324","1265.42944","2.02770","0.99922","0.01096","436.08499"
"127.80000","2.12808","1267.33972","2.03246","1.00399","0.01099","436.74332"
"128.10000","2.13296","1269.00513","2.03727","1.00880","0.01101","437.31723"
"128.40000","2.13797","1270.87061","2.04220","1.01373","0.01104","437.96011"
"128.70000","2.14311","1272.90918","2.04726","1.01879","0.01107","438.66263"
"129.00000","2.14812","1274.72742","2.05219","1.02372","0.01109","439.28922"
"129.30000","2.15338","1276.75696","2.05736","1.02889","0.01112","439.98862"
"129.60000","2.15828","1278.50879","2.06219","1.03372","0.01115","440.59232"
"129.90000","2.16339","1280.51050","2.06722","1.03875","0.01117","441.28214"
"130.20000","2.16798","1282.15491","2.07174","1.04327","0.01120","441.84885"
"130.50000","2.17291","1283.84680","2.07660","1.04813","0.01122","442.43188"
"130.80000","2.17805","1285.83398","2.08165","1.05318","0.01125","443.11670"
"131.10000","2.18304","1287.70105","2.08656","1.05809","0.01128","443.76010"
"131.40000","2.18825","1289.62439","2.09170","1.06323","0.01131","444.42291"
"131.70000","2.19331","1291.54224","2.09667","1.06820","0.01133","445.08383"
"132.00000","2.19855","1293.59863","2.10183","1.07335","0.01136","445.79251"
"132.30000","2.20314","1295.07385","2.10635","1.07788","0.01139","446.30087"
"132.60000","2.20802","1296.76685","2.11117","1.08270","0.01141","446.88431"
"132.90000","2.21298","1298.56604","2.11605","1.08757","0.01144","447.50433"
"133.20000","2.21796","1300.36475","2.12095","1.09248","0.01146","448.12421"
"133.50000","2.22319","1302.41675","2.12610","1.09763","0.01149","448.83136"
"133.80000","2.22816","1304.11511","2.13100","1.10253","0.01152","449.41663"
"134.10000","2.23346","1305.86829","2.13623","1.10776","0.01155","450.02081"
"134.40000","2.23837","1307.54028","2.14106","1.11259","0.01157","450.59698"
"134.70000","2.24318","1308.98633","2.14581","1.11734","0.01160","451.09534"
"135.00000","2.24802","1310.40234","2.15059","1.12212","0.01162","451.58331"
"135.30000","2.25296","1311.99573","2.15547","1.12700","0.01165","452.13242"
"135.60000","2.25807","1313.66919","2.16051","1.13204","0.01168","452.70911"
"135.90000","2.26305","1315.28552","2.16543","1.13696","0.01170","453.26611"
"136.20000","2.26835","1317.25134","2.17064","1.14217","0.01173","453.94357"
"136.50000","2.27332","1318.83020","2.17555","1.14708","0.01176","454.48767"
"136.80000","2.27841","1320.40076","2.18057","1.15210","0.01179","455.02890"
"137.10000","2.28311","1321.66638","2.18522","1.15675","0.01181","455.46506"
"137.40000","2.28795","1322.99231","2.19000","1.16153","0.01184","455.92200"
"137.70000","2.29297","1324.51721","2.19496","1.16648","0.01186","456.44748"
"138.00000","2.29801","1325.98193","2.19994","1.17147","0.01189","456.95224"
"138.30000","2.30321","1327.59937","2.20507","1.17660","0.01192","457.50964"
"138.60000","2.30823","1328.88660","2.21004","1.18157","0.01195","457.95325"
"138.90000","2.31355","1330.50061","2.21529","1.18682","0.01197","458.50946"
"139.20000","2.31822","1331.46948","2.21992","1.19145","0.01200","458.84335"
"139.50000","2.32304","1332.44788","2.22470","1.19623","0.01202","459.18051"
"139.80000","2.32794","1333.44116","2.22956","1.20109","0.01205","459.52280"
"140.10000","2.33297","1334.44031","2.23455","1.20608","0.01208","459.86713"
"140.40000","2.33809","1334.07092","2.23968","1.21121","0.01211","459.73984"
"140.70000","2.34318","1334.15967","2.24477","1.21630","0.01213","459.77042"
"141.00000","2.34841","1334.78357","2.24997","1.22150","0.01216","459.98541"
"141.30000","2.35331","1334.77795","2.25488","1.22640","0.01219","459.98349"
"141.60000","2.35832","1334.47827","2.25990","1.23143","0.01221","459.88022"
"141.90000","2.36297","1334.05212","2.26457","1.23609","0.01224","459.73337"
"142.20000","2.36793","1333.97107","2.26953","1.24105","0.01227","459.70541"
"142.50000","2.37304","1334.30688","2.27463","1.24616","0.01229","459.82114"
"142.80000","2.37808","1334.18066","2.27967","1.25120","0.01232","459.77765"
"143.10000","2.38328","1334.35510","2.28486","1.25639","0.01235","459.83777"
"143.40000","2.38829","1334.61121","2.28987","1.26139","0.01238","459.92603"
"143.70000","2.39348","1335.12573","2.29503","1.26656","0.01240","460.10333"
"144.00000","2.39808","1335.11743","2.29963","1.27116","0.01243","460.10046"
"144.30000","2.40299","1335.53406","2.30452","1.27605","0.01246","460.24405"
"144.60000","2.40797","1335.98938","2.30948","1.28101","0.01248","460.40097"
"144.90000","2.41303","1336.66431","2.31452","1.28605","0.01251","460.63354"
"145.20000","2.41820","1337.54126","2.31965","1.29118","0.01254","460.93576"
"145.50000","2.42314","1338.02905","2.32457","1.29610","0.01256","461.10385"
"145.80000","2.42847","1338.60217","2.32988","1.30140","0.01259","461.30136"
"146.10000","2.43327","1338.81360","2.33467","1.30620","0.01262","461.37424"
"146.40000","2.43813","1338.96521","2.33952","1.31105","0.01265","461.42648"
"146.70000","2.44296","1339.04382","2.34434","1.31587","0.01267","461.45355"
"147.00000","2.44796","1339.40991","2.34933","1.32086","0.01270","461.57971"
"147.30000","2.45309","1337.27832","2.35455","1.32608","0.01273","460.84515"
"147.60000","2.45810","1336.70386","2.35959","1.33111","0.01275","460.64719"
"147.90000","2.46335","1336.78918","2.36483","1.33636","0.01278","460.67657"
"148.20000","2.46830","1336.40137","2.36980","1.34133","0.01281","460.54294"
"148.50000","2.47341","1336.33459","2.37491","1.34644","0.01284","460.51993"
"148.80000","2.47806","1335.90857","2.37958","1.35111","0.01286","460.37311"
"149.10000","2.48290","1335.80847","2.38442","1.35595","0.01289","460.33862"
"149.40000","2.48801","1335.93933","2.38953","1.36105","0.01292","460.38370"
"149.70000","2.49304","1336.06641","2.39455","1.36608","0.01294","460.42749"
"150.00000","2.49824","1334.08911","2.39984","1.37136","0.01297","459.74609"
"150.30000","2.50329","1332.66394","2.40495","1.37647","0.01300","459.25497"
"150.60000","2.50848","1332.13562","2.41015","1.38168","0.01303","459.07291"
"150.90000","2.51323","1328.96057","2.41504","1.38657","0.01305","457.97873"
"151.20000","2.51799","1326.83240","2.41988","1.39141","0.01308","457.24533"
"151.50000","2.52293","1322.02161","2.42503","1.39656","0.01311","455.58746"
"151.80000","2.52798","1321.39246","2.43010","1.40163","0.01313","455.37067"
"152.10000","2.53313","1321.12207","2.43527","1.40679","0.01316","455.27747"
"152.40000","2.53818","1320.62207","2.44034","1.41186","0.01319","455.10516"
"152.70000","2.54341","1320.24475","2.44558","1.41711","0.01322","454.97513"
"153.00000","2.54838","1319.23608","2.45059","1.42212","0.01325","454.62753"
"153.30000","2.55320","1317.75366","2.45547","1.42700","0.01327","454.11667"
"153.60000","2.55798","1314.95154","2.46037","1.43190","0.01330","453.15103"
"153.90000","2.56295","1311.85669","2.46547","1.43700","0.01333","452.08450"
"154.20000","2.56802","1310.15210","2.47061","1.44214","0.01335","451.49707"
"154.50000","2.57312","1309.38110","2.47574","1.44727","0.01338","451.23135"
"154.80000","2.57827","1308.93518","2.48091","1.45244","0.01341","451.07770"
"155.10000","2.58335","1308.77466","2.48600","1.45753","0.01344","451.02237"
"155.40000","2.58846","1308.86768","2.49110","1.46263","0.01346","451.05444"
"155.70000","2.59308","1308.43237","2.49574","1.46726","0.01349","450.90442"
"156.00000","2.59796","1308.70508","2.50061","1.47214","0.01352","450.99841"
"156.30000","2.60295","1309.03101","2.50559","1.47712","0.01354","451.11072"
"156.60000","2.60808","1309.41138","2.51070","1.48223","0.01357","451.24179"
"156.90000","2.61318","1310.14014","2.51577","1.48730","0.01360","451.49295"
"157.20000","2.61822","1310.72620","2.52079","1.49232","0.01363","451.69492"
"157.50000","2.62352","1311.43604","2.52606","1.49758","0.01365","451.93951"
"157.80000","2.62820","1311.52649","2.53073","1.50226","0.01368","451.97070"
"158.10000","2.63305","1311.97253","2.53557","1.50710","0.01370","452.12442"
"158.40000","2.63795","1312.37976","2.54045","1.51197","0.01373","452.26474"
"158.70000","2.64299","1313.02454","2.54546","1.51699","0.01376","452.48694"
"159.00000","2.64814","1313.69751","2.55058","1.52211","0.01379","452.71887"
"159.30000","2.65315","1314.40771","2.55556","1.52709","0.01381","452.96362"
"159.60000","2.65836","1315.17383","2.56074","1.53227","0.01384","453.22763"
"159.90000","2.66330","1315.52234","2.56566","1.53719","0.01387","453.34772"
"160.20000","2.66836","1315.89819","2.57071","1.54224","0.01389","453.47726"
"160.50000","2.67299","1315.81519","2.57534","1.54687","0.01392","453.44864"
"160.80000","2.67792","1315.84790","2.58027","1.55179","0.01395","453.45993"
"161.10000","2.68308","1315.20215","2.58546","1.55699","0.01397","453.23740"
"161.40000","2.68808","1315.34424","2.59045","1.56198","0.01400","453.28635"
"161.70000","2.69324","1315.99255","2.59559","1.56712","0.01403","453.50977"
"162.00000","2.69826","1316.34521","2.60060","1.57212","0.01406","453.63129"
"162.30000","2.70350","1316.93347","2.60581","1.57733","0.01408","453.83401"
"162.60000","2.70814","1316.86731","2.61045","1.58198","0.01411","453.81122"
"162.90000","2.71296","1317.16748","2.61526","1.58678","0.01414","453.91467"
"163.20000","2.71793","1317.45740","2.62022","1.59174","0.01416","454.01459"
"163.50000","2.72300","1318.04211","2.62526","1.59679","0.01419","454.21606"
"163.80000","2.72820","1318.74609","2.63043","1.60196","0.01422","454.45868"
"164.10000","2.73316","1319.18018","2.63537","1.60690","0.01424","454.60828"
"164.40000","2.73846","1319.78687","2.64065","1.61218","0.01427","454.81735"
"164.70000","2.74338","1319.98499","2.64556","1.61709","0.01430","454.88562"
"165.00000","2.74812","1319.61145","2.65031","1.62184","0.01433","454.75690"
"165.30000","2.75299","1312.58606","2.65547","1.62700","0.01435","452.33585"
"165.60000","2.75790","1310.17273","2.66049","1.63202","0.01438","451.50418"
"165.90000","2.76307","1309.69751","2.66567","1.63720","0.01441","451.34039"
"166.20000","2.76810","1309.52490","2.67072","1.64224","0.01444","451.28091"
"166.50000","2.77334","1308.80457","2.67598","1.64751","0.01446","451.03268"
"166.80000","2.77841","1306.40723","2.68115","1.65268","0.01449","450.20654"
"167.10000","2.78340","1304.09888","2.68624","1.65776","0.01452","449.41104"
"167.40000","2.78810","1295.42322","2.69130","1.66283","0.01455","446.42130"
"167.56100","2.79084","1268.32251","2.69517","1.66670","0.01457","437.08200"
"167.77900","2.79463","1239.11829","2.70021","1.67173","0.01459","427.01779"
"168.07900","2.79933","1234.12195","2.70513","1.67666","0.01462","425.29599"
"168.37900","2.80425","1227.55139","2.71034","1.68187","0.01465","423.03168"
"168.67900","2.80931","1210.98572","2.71612","1.68765","0.01468","417.32291"
"168.93900","2.81384","1193.66309","2.72141","1.69294","0.01471","411.35330"
"169.23900","2.81903","1175.16541","2.72736","1.69889","0.01474","404.97873"
"169.53900","2.82400","1154.37122","2.73320","1.70473","0.01477","397.81274"
"169.80000","2.82801","1135.08997","2.73802","1.70955","0.01480","391.16815"
"170.10000","2.83295","1130.00952","2.74318","1.71471","0.01483","389.41736"
"170.40000","2.83799","1128.20801","2.74830","1.71983","0.01485","388.79654"
"170.70000","2.84311","1125.71216","2.75352","1.72505","0.01488","387.93643"
"171.00000","2.84819","1124.28821","2.75867","1.73020","0.01491","387.44571"
"171.30000","2.85339","1120.85876","2.76401","1.73554","0.01494","386.26389"
"171.60000","2.85834","1116.00085","2.76917","1.74069","0.01497","384.58978"
"171.90000","2.86323","1114.36414","2.77414","1.74566","0.01499","384.02576"
"172.20000","2.86800","1112.26282","2.77899","1.75052","0.01502","383.30161"
"172.50000","2.87293","1110.91150","2.78398","1.75551","0.01505","382.83591"
"172.80000","2.87807","1107.07581","2.78928","1.76081","0.01508","381.51407"
"173.10000","2.88307","1104.93823","2.79438","1.76590","0.01510","380.77744"
"173.40000","2.88827","1102.84131","2.79966","1.77119","0.01513","380.05481"
"173.70000","2.89332","1101.13281","2.80479","1.77632","0.01516","379.46603"
"174.00000","2.89843","1087.97034","2.81046","1.78199","0.01519","374.93005"
"174.30000","2.90315","1084.80188","2.81532","1.78685","0.01522","373.83817"
"174.60000","2.90797","1081.45923","2.82028","1.79181","0.01524","372.68625"
"174.90000","2.91299","1080.40637","2.82535","1.79688","0.01527","372.32343"
"175.20000","2.91802","1079.64172","2.83041","1.80194","0.01530","372.05991"
"175.50000","2.92322","1078.01428","2.83569","1.80721","0.01533","371.49905"
"175.80000","2.92817","1074.13818","2.84080","1.81233","0.01535","370.16330"
"176.10000","2.93345","1072.65137","2.84614","1.81767","0.01538","369.65094"
"176.40000","2.93828","1069.21484","2.85113","1.82265","0.01541","368.46664"
"176.70000","2.94306","1065.54456","2.85606","1.82759","0.01544","367.20181"
"177.00000","2.94798","1061.69104","2.86114","1.83267","0.01546","365.87384"
"177.30000","2.95296","1056.70081","2.86634","1.83787","0.01549","364.15414"
"177.60000","2.95809","1049.70776","2.87177","1.84330","0.01552","361.74423"
"177.90000","2.96314","1041.22388","2.87718","1.84871","0.01555","358.82056"
"177.93900","2.96372","1009.89386","2.87907","1.85060","0.01556","348.02380"
"178.21800","2.96863","993.47095","2.88468","1.85620","0.01559","342.36423"
"178.51800","2.97358","990.07666","2.88978","1.86131","0.01562","341.19452"
"178.81800","2.97873","988.48755","2.89500","1.86653","0.01565","340.64688"
"179.11800","2.98346","987.01819","2.89980","1.87132","0.01567","340.14053"
"179.41800","2.98819","982.33160","2.90473","1.87626","0.01570","338.52545"
"179.71800","2.99331","976.00305","2.91014","1.88167","0.01573","336.34454"
"180.01800","2.99830","971.99268","2.91531","1.88684","0.01576","334.96252"
"180.31800","3.00349","969.23157","2.92063","1.89215","0.01579","334.01099"
"180.61800","3.00856","966.82153","2.92580","1.89732","0.01581","333.18045"
"180.91800","3.01375","965.13733","2.93107","1.90260","0.01584","332.60007"
"181.21800","3.01858","963.36975","2.93597","1.90750","0.01587","331.99094"
"181.51800","3.02337","961.12152","2.94086","1.91239","0.01590","331.21616"
"181.81800","3.02826","958.65094","2.94586","1.91739","0.01592","330.36475"
"182.11800","3.03323","956.53058","2.95093","1.92246","0.01595","329.63406"
"182.41800","3.03842","954.45782","2.95622","1.92774","0.01598","328.91974"
"182.71800","3.04346","952.45551","2.96134","1.93287","0.01601","328.22974"
"183.01800","3.04867","949.64343","2.96668","1.93821","0.01604","327.26065"
"183.14600","3.05043","947.26904","2.96854","1.94007","0.01605","326.44238"