File: flexion/5_axis/Specimen_RawData_3.csv
Specimen properties : Specimen label,"3"
Specimen properties : Support span,"72.00",mm
Specimen properties : Thickness,"4.58",mm
Specimen properties : Width,"14.08",mm
Maximum Load : Maximum Load,"937.0",N
Tangent Modulus of Elasticity : Tangent Modulus of Elasticity,"34393652619.41980",Pa
Test : Rate 1,"1.00000",mm/min
Specimen notes : Specimen note 1,""

Time,Displacement,Load,Flexure extension,Corrected extension,Flexure strain (Corrected extension),Flexure stress
(s),(mm),(N),(mm),(mm),(mm/mm),(MPa)
"0.00000","0.00000","9.34418","-0.02628","-1.04682","-0.00014","3.41689"
"0.50000","0.00671","12.14680","-0.02078","-1.04132","-0.00011","4.44173"
"1.00000","0.01479","15.45629","-0.01412","-1.03466","-0.00007","5.65191"
"1.50000","0.02354","18.96184","-0.00618","-1.02672","-0.00003","6.93379"
"2.00000","0.03145","22.18934","0.00105","-1.01949","0.00001","8.11399"
"2.50000","0.03996","25.56948","0.00884","-1.01170","0.00005","9.35001"
"3.00000","0.04829","28.79220","0.01650","-1.00404","0.00009","10.52846"
"3.50000","0.05645","32.07186","0.02397","-0.99658","0.00013","11.72774"
"4.00000","0.06496","35.27544","0.03179","-0.98875","0.00017","12.89919"
"4.50000","0.07306","38.55481","0.03944","-0.98110","0.00021","14.09836"
"5.00000","0.08186","41.96484","0.04779","-0.97276","0.00025","15.34531"
"5.50000","0.08970","45.32753","0.05517","-0.96537","0.00029","16.57495"
"6.00000","0.09844","48.76347","0.06345","-0.95709","0.00034","17.83137"
"6.50000","0.10644","52.11153","0.07100","-0.94954","0.00038","19.05566"
"7.00000","0.11520","55.72644","0.07928","-0.94127","0.00042","20.37753"
"7.50000","0.12321","59.08562","0.08686","-0.93368","0.00046","21.60588"
"8.00000","0.13157","62.67933","0.09480","-0.92575","0.00050","22.91999"
"8.50000","0.14000","66.12060","0.10283","-0.91772","0.00055","24.17837"
"9.00000","0.14808","69.54769","0.11051","-0.91004","0.00059","25.43155"
"9.50000","0.15661","73.11510","0.11862","-0.90192","0.00063","26.73605"
"10.00000","0.16475","76.65376","0.12634","-0.89420","0.00067","28.03004"
"10.50000","0.17354","80.42598","0.13469","-0.88585","0.00071","29.40942"
"11.00000","0.18141","83.86202","0.14216","-0.87838","0.00075","30.66588"
"11.50000","0.19012","87.65469","0.15043","-0.87011","0.00080","32.05275"
"12.00000","0.19821","91.07423","0.15819","-0.86235","0.00084","33.30318"
"12.50000","0.20680","94.85867","0.16642","-0.85413","0.00088","34.68704"
"13.00000","0.21481","98.41859","0.17407","-0.84647","0.00092","35.98879"
"13.50000","0.22319","102.10059","0.18209","-0.83845","0.00097","37.33520"
"14.00000","0.23167","105.86778","0.19021","-0.83034","0.00101","38.71275"
"14.50000","0.23968","109.32606","0.19788","-0.82267","0.00105","39.97734"
"15.00000","0.24834","113.27251","0.20615","-0.81440","0.00109","41.42044"
"15.50000","0.25640","116.83429","0.21386","-0.80668","0.00113","42.72288"
"16.00000","0.26526","120.70517","0.22234","-0.79820","0.00118","44.13834"
"16.50000","0.27305","124.25854","0.22979","-0.79076","0.00122","45.43771"
"17.00000","0.28183","128.22662","0.23818","-0.78237","0.00126","46.88872"
"17.50000","0.28985","131.79987","0.24585","-0.77469","0.00130","48.19535"
"18.00000","0.29838","135.52458","0.25402","-0.76653","0.00135","49.55737"
"18.50000","0.30652","139.24602","0.26180","-0.75874","0.00139","50.91819"
"19.00000","0.31479","142.97546","0.26971","-0.75083","0.00143","52.28194"
"19.50000","0.32339","146.84520","0.27793","-0.74261","0.00147","53.69699"
"20.00000","0.33135","150.47530","0.28554","-0.73501","0.00151","55.02441"
"20.50000","0.34010","154.51373","0.29390","-0.72665","0.00156","56.50114"
"21.00000","0.34806","157.94760","0.30152","-0.71902","0.00160","57.75681"
"21.50000","0.35698","162.15785","0.31008","-0.71046","0.00164","59.29638"
"22.00000","0.36481","165.70975","0.31762","-0.70293","0.00168","60.59520"
"22.50000","0.37341","169.55173","0.32589","-0.69465","0.00173","62.00010"
"23.00000","0.38157","173.30760","0.33373","-0.68682","0.00177","63.37351"
"23.50000","0.38994","177.11525","0.34177","-0.67878","0.00181","64.76585"
"24.00000","0.39819","180.91638","0.34970","-0.67084","0.00185","66.15582"
"24.50000","0.40640","184.53476","0.35760","-0.66294","0.00190","67.47896"
"25.00000","0.41507","188.65338","0.36592","-0.65462","0.00194","68.98502"
"25.50000","0.42305","192.20734","0.37360","-0.64694","0.00198","70.28459"
"26.00000","0.43178","196.37340","0.38198","-0.63856","0.00202","71.80800"
"26.50000","0.43979","199.99843","0.38968","-0.63086","0.00207","73.13357"
"27.00000","0.44858","203.99564","0.39814","-0.62240","0.00211","74.59523"
"27.50000","0.45642","207.57430","0.40570","-0.61485","0.00215","75.90384"
"28.00000","0.46498","211.53040","0.41394","-0.60660","0.00219","77.35047"
"28.50000","0.47324","215.27281","0.42190","-0.59864","0.00224","78.71896"
"29.00000","0.48152","219.20328","0.42986","-0.59068","0.00228","80.15622"
"29.50000","0.48990","223.00603","0.43795","-0.58260","0.00232","81.54677"
"30.00000","0.49811","226.65677","0.44586","-0.57468","0.00236","82.88174"
"30.50000","0.50685","230.81149","0.45427","-0.56627","0.00241","84.40100"
"31.00000","0.51467","234.34250","0.46181","-0.55874","0.00245","85.69218"
"31.50000","0.52352","238.50433","0.47032","-0.55023","0.00249","87.21405"
"32.00000","0.53142","242.18576","0.47793","-0.54261","0.00253","88.56023"
"32.50000","0.54022","246.41170","0.48640","-0.53415","0.00258","90.10554"
"33.00000","0.54812","249.80148","0.49404","-0.52651","0.00262","91.34509"
"33.50000","0.55663","253.90836","0.50224","-0.51831","0.00266","92.84685"
"34.00000","0.56493","257.77380","0.51024","-0.51030","0.00270","94.26033"
"34.50000","0.57312","261.53760","0.51814","-0.50241","0.00275","95.63663"
"35.00000","0.58164","265.60336","0.52635","-0.49420","0.00279","97.12337"
"35.50000","0.58973","269.28842","0.53416","-0.48639","0.00283","98.47089"
"36.00000","0.59852","273.56979","0.54261","-0.47793","0.00288","100.03646"
"36.50000","0.60640","277.16626","0.55022","-0.47032","0.00292","101.35158"
"37.00000","0.61512","281.43875","0.55861","-0.46193","0.00296","102.91390"
"37.50000","0.62315","285.22141","0.56635","-0.45419","0.00300","104.29711"
"38.00000","0.63185","289.40997","0.57473","-0.44581","0.00305","105.82875"
"38.50000","0.63983","293.15118","0.58244","-0.43810","0.00309","107.19680"
"39.00000","0.64819","297.13281","0.59055","-0.43000","0.00313","108.65276"
"39.50000","0.65666","301.14938","0.59874","-0.42180","0.00317","110.12151"
"40.00000","0.66480","305.04221","0.60663","-0.41392","0.00322","111.54500"
"40.50000","0.67332","309.17145","0.61487","-0.40567","0.00326","113.05494"
"41.00000","0.68144","313.02631","0.62273","-0.39782","0.00330","114.46455"
"41.50000","0.69021","317.27762","0.63121","-0.38933","0.00335","116.01913"
"42.00000","0.69802","320.92575","0.63878","-0.38177","0.00339","117.35314"
"42.50000","0.70674","325.09613","0.64722","-0.37332","0.00343","118.87813"
"43.00000","0.71480","328.93417","0.65503","-0.36552","0.00347","120.28159"
"43.50000","0.72347","333.10974","0.66341","-0.35713","0.00352","121.80847"
"44.00000","0.73151","336.99939","0.67119","-0.34935","0.00356","123.23080"
"44.50000","0.73992","340.91855","0.67934","-0.34120","0.00360","124.66393"
"45.00000","0.74839","345.09930","0.68755","-0.33300","0.00364","126.19270"
"45.50000","0.75637","348.66061","0.69530","-0.32525","0.00369","127.49497"
"46.00000","0.76504","352.95752","0.70369","-0.31685","0.00373","129.06622"
"46.50000","0.77305","356.65372","0.71146","-0.30908","0.00377","130.41782"
"47.00000","0.78189","361.08276","0.72002","-0.30052","0.00382","132.03738"
"47.50000","0.78972","364.63046","0.72762","-0.29293","0.00386","133.33467"
"48.00000","0.79845","368.86447","0.73608","-0.28447","0.00390","134.88293"
"48.50000","0.80649","372.67947","0.74387","-0.27667","0.00394","136.27797"
"49.00000","0.81508","376.87741","0.75219","-0.26835","0.00399","137.81303"
"49.50000","0.82324","380.76126","0.76010","-0.26044","0.00403","139.23323"
"50.00000","0.83148","384.71454","0.76809","-0.25245","0.00407","140.67883"
"50.50000","0.84003","388.82867","0.77638","-0.24416","0.00412","142.18326"
"51.00000","0.84803","392.60629","0.78416","-0.23638","0.00416","143.56462"
"51.50000","0.85671","396.85052","0.79260","-0.22794","0.00420","145.11661"
"52.00000","0.86477","400.75372","0.80044","-0.22010","0.00424","146.54390"
"52.50000","0.87362","405.05072","0.80905","-0.21150","0.00429","148.11517"
"53.00000","0.88144","408.69055","0.81666","-0.20389","0.00433","149.44617"
"53.50000","0.89004","412.91257","0.82502","-0.19553","0.00437","150.99002"
"54.00000","0.89824","416.89877","0.83299","-0.18756","0.00442","152.44766"
"54.50000","0.90669","420.96448","0.84120","-0.17934","0.00446","153.93437"
"55.00000","0.91490","424.84109","0.84919","-0.17135","0.00450","155.35194"
"55.50000","0.92314","428.66476","0.85721","-0.16333","0.00454","156.75014"
"56.00000","0.93173","432.92291","0.86557","-0.15498","0.00459","158.30722"
"56.50000","0.93965","436.73389","0.87327","-0.14727","0.00463","159.70079"
"57.00000","0.94839","441.00885","0.88177","-0.13878","0.00467","161.26401"
"57.50000","0.95641","444.99966","0.88955","-0.13099","0.00472","162.72334"
"58.00000","0.96530","449.17255","0.89821","-0.12234","0.00476","164.24924"
"58.50000","0.97312","452.84860","0.90582","-0.11473","0.00480","165.59346"
"59.00000","0.98178","457.02826","0.91424","-0.10630","0.00485","167.12184"
"59.50000","0.98993","461.00952","0.92217","-0.09838","0.00489","168.57767"
"60.00000","0.99825","465.03384","0.93026","-0.09028","0.00493","170.04926"
"60.50000","1.00658","468.98880","0.93836","-0.08218","0.00497","171.49547"
"61.00000","1.01475","472.97714","0.94630","-0.07424","0.00502","172.95389"
"61.50000","1.02344","477.25574","0.95475","-0.06580","0.00506","174.51843"
"62.00000","1.03133","480.96347","0.96243","-0.05811","0.00510","175.87425"
"62.50000","1.04017","485.46176","0.97101","-0.04954","0.00515","177.51915"
"63.00000","1.04809","489.11298","0.97873","-0.04182","0.00519","178.85428"
"63.50000","1.05697","493.62384","0.98737","-0.03317","0.00523","180.50377"
"64.00000","1.06482","497.37567","0.99504","-0.02551","0.00527","181.87572"
"64.50000","1.07330","501.48639","1.00331","-0.01724","0.00532","183.37888"
"65.00000","1.08159","505.45135","1.01140","-0.00915","0.00536","184.82875"
"65.50000","1.08980","509.57349","1.01941","-0.00114","0.00540","186.33609"
"66.00000","1.09826","513.60095","1.02766","0.00712","0.00545","187.80882"
"66.50000","1.10644","517.71393","1.03563","0.01509","0.00549","189.31282"
"67.00000","1.11519","521.94043","1.04417","0.02363","0.00554","190.85832"
"67.50000","1.12307","525.86713","1.05186","0.03132","0.00558","192.29420"
"68.00000","1.13182","530.23340","1.06039","0.03984","0.00562","193.89082"
"68.50000","1.13985","534.09998","1.06823","0.04768","0.00566","195.30472"
"69.00000","1.14858","538.25684","1.07674","0.05620","0.00571","196.82475"
"69.50000","1.15649","542.12799","1.08446","0.06392","0.00575","198.24033"
"70.00000","1.16492","546.29388","1.09269","0.07215","0.00579","199.76367"
"70.50000","1.17331","550.36420","1.10088","0.08034","0.00584","201.25206"
"71.00000","1.18143","554.32147","1.10882","0.08827","0.00588","202.69913"
"71.50000","1.18996","558.45758","1.11715","0.09660","0.00592","204.21158"
"72.00000","1.19807","562.45123","1.12506","0.10451","0.00596","205.67194"
"72.50000","1.20690","566.86823","1.13367","0.11313","0.00601","207.28709"
"73.00000","1.21473","570.51038","1.14134","0.12079","0.00605","208.61893"
"73.50000","1.22354","574.99939","1.14992","0.12937","0.00610","210.26044"
"74.00000","1.23149","578.75891","1.15769","0.13715","0.00614","211.63518"
"74.50000","1.24013","582.91901","1.16613","0.14559","0.00618","213.15640"
"75.00000","1.24816","586.81012","1.17397","0.15343","0.00622","214.57927"
"75.50000","1.25656","590.98914","1.18217","0.16163","0.00627","216.10741"
"76.00000","1.26500","594.95184","1.19043","0.16989","0.00631","217.55646"
"76.50000","1.27306","598.89264","1.19831","0.17777","0.00635","218.99750"
"77.00000","1.28171","603.14630","1.20678","0.18623","0.00640","220.55293"
"77.50000","1.28973","606.89288","1.21462","0.19408","0.00644","221.92294"
"78.00000","1.29858","611.24689","1.22328","0.20273","0.00648","223.51508"
"78.50000","1.30640","614.90411","1.23094","0.21039","0.00653","224.85242"
"79.00000","1.31513","619.10187","1.23948","0.21893","0.00657","226.38742"
"79.50000","1.32315","622.86237","1.24733","0.22678","0.00661","227.76251"
"80.00000","1.33173","627.07623","1.25572","0.23518","0.00666","229.30341"
"80.50000","1.33986","630.89764","1.26368","0.24314","0.00670","230.70079"
"81.00000","1.34816","634.82361","1.27181","0.25126","0.00674","232.13640"
"81.50000","1.35674","638.93488","1.28020","0.25965","0.00679","233.63977"
"82.00000","1.36477","642.73975","1.28805","0.26751","0.00683","235.03110"
"82.50000","1.37339","646.78625","1.29650","0.27595","0.00687","236.51079"
"83.00000","1.38147","650.62683","1.30441","0.28386","0.00691","237.91518"
"83.50000","1.39023","654.94293","1.31298","0.29243","0.00696","239.49344"
"84.00000","1.39807","658.48834","1.32066","0.30012","0.00700","240.78989"
"84.50000","1.40671","662.64362","1.32912","0.30857","0.00705","242.30936"
"85.00000","1.41487","666.36749","1.33711","0.31656","0.00709","243.67107"
"85.50000","1.42334","670.37903","1.34540","0.32486","0.00713","245.13797"
"86.00000","1.43154","674.23822","1.35342","0.33288","0.00717","246.54916"
"86.50000","1.43983","677.79694","1.36156","0.34102","0.00722","247.85048"
"87.00000","1.44843","681.76501","1.36998","0.34943","0.00726","249.30148"
"87.50000","1.45639","685.48218","1.37778","0.35723","0.00730","250.66075"
"88.00000","1.46509","689.41876","1.38630","0.36576","0.00735","252.10023"
"88.50000","1.47311","693.00977","1.39416","0.37361","0.00739","253.41336"
"89.00000","1.48190","696.94977","1.40278","0.38223","0.00744","254.85411"
"89.50000","1.48977","700.48663","1.41048","0.38994","0.00748","256.14743"
"90.00000","1.49845","704.41577","1.41899","0.39844","0.00752","257.58420"
"90.50000","1.50656","707.89142","1.42694","0.40640","0.00756","258.85516"
"91.00000","1.51489","711.29559","1.43512","0.41458","0.00761","260.09995"
"91.50000","1.52324","715.01263","1.44331","0.42277","0.00765","261.45917"
"92.00000","1.53145","718.50934","1.45136","0.43082","0.00769","262.73782"
"92.50000","1.54007","722.24860","1.45982","0.43927","0.00774","264.10516"
"93.00000","1.54801","725.65680","1.46760","0.44706","0.00778","265.35144"
"93.50000","1.55676","729.42682","1.47618","0.45564","0.00783","266.73001"
"94.00000","1.56472","732.86945","1.48399","0.46345","0.00787","267.98889"
"94.50000","1.57361","736.72247","1.49270","0.47216","0.00791","269.39783"
"95.00000","1.58146","739.94489","1.50041","0.47987","0.00795","270.57617"
"95.50000","1.59000","743.64960","1.50879","0.48824","0.00800","271.93088"
"96.00000","1.59827","746.82678","1.51692","0.49638","0.00804","273.09268"
"96.50000","1.60656","749.84937","1.52509","0.50454","0.00808","274.19794"
"97.00000","1.61492","752.51605","1.53334","0.51280","0.00813","275.17307"
"97.50000","1.62317","755.06189","1.54148","0.52094","0.00817","276.10400"
"98.00000","1.63179","757.27448","1.55001","0.52947","0.00822","276.91309"
"98.50000","1.63968","758.63184","1.55784","0.53730","0.00826","277.40942"
"99.00000","1.64838","760.83423","1.56645","0.54591","0.00830","278.21478"
"99.50000","1.65646","763.13525","1.57444","0.55390","0.00835","279.05621"
"100.00000","1.66528","766.05426","1.58313","0.56259","0.00839","280.12360"
"100.50000","1.67313","766.71399","1.59096","0.57042","0.00843","280.36484"
"101.00000","1.68167","768.75165","1.59941","0.57887","0.00848","281.10995"
"101.50000","1.68997","770.74414","1.60763","0.58709","0.00852","281.83856"
"102.00000","1.69816","771.37152","1.61579","0.59525","0.00857","282.06796"
"102.50000","1.70661","769.42572","1.62432","0.60378","0.00861","281.35645"
"103.00000","1.71476","760.65588","1.63284","0.61230","0.00866","278.14957"
"103.50000","1.72349","758.02405","1.64168","0.62113","0.00870","277.18719"
"104.00000","1.73136","756.38855","1.64962","0.62907","0.00874","276.58914"
"104.50000","1.74018","752.82196","1.65859","0.63804","0.00879","275.28494"
"105.00000","1.74811","742.49341","1.66695","0.64641","0.00884","271.50809"
"105.50000","1.75689","742.94666","1.67571","0.65516","0.00888","271.67383"
"106.00000","1.76483","743.95172","1.68361","0.66307","0.00892","272.04135"
"106.50000","1.77326","744.96100","1.69199","0.67145","0.00897","272.41040"
"107.00000","1.78160","746.29535","1.70028","0.67974","0.00901","272.89835"
"107.50000","1.78973","748.21130","1.70833","0.68778","0.00906","273.59894"
"108.00000","1.79832","750.82422","1.71681","0.69627","0.00910","274.55441"
"108.50000","1.80639","753.06287","1.72478","0.70424","0.00914","275.37302"
"109.00000","1.81521","756.00983","1.73349","0.71294","0.00919","276.45065"
"109.50000","1.82307","758.40814","1.74124","0.72070","0.00923","277.32764"
"110.00000","1.83177","761.31921","1.74982","0.72928","0.00928","278.39212"
"110.50000","1.83984","763.80804","1.75779","0.73725","0.00932","279.30222"
"111.00000","1.84849","766.33075","1.76633","0.74579","0.00936","280.22470"
"111.50000","1.85650","768.47144","1.77425","0.75371","0.00941","281.00748"
"112.00000","1.86491","770.90710","1.78257","0.76202","0.00945","281.89813"
"112.50000","1.87336","773.48608","1.79090","0.77036","0.00949","282.84119"
"113.00000","1.88136","775.77527","1.79881","0.77826","0.00954","283.67828"
"113.50000","1.88998","778.49341","1.80732","0.78677","0.00958","284.67224"
"114.00000","1.89810","780.89703","1.81533","0.79479","0.00962","285.55118"
"114.50000","1.90692","783.76672","1.82404","0.80349","0.00967","286.60052"
"115.00000","1.91473","785.88806","1.83175","0.81121","0.00971","287.37625"
"115.50000","1.92348","788.72021","1.84039","0.81984","0.00976","288.41187"
"116.00000","1.93152","791.12488","1.84833","0.82779","0.00980","289.29120"
"116.50000","1.94010","793.78143","1.85679","0.83625","0.00984","290.26260"
"117.00000","1.94817","796.01508","1.86477","0.84423","0.00989","291.07938"
"117.50000","1.95650","798.22491","1.87301","0.85247","0.00993","291.88745"
"118.00000","1.96504","800.65570","1.88144","0.86089","0.00997","292.77634"
"118.50000","1.97304","802.50183","1.88936","0.86881","0.01002","293.45142"
"119.00000","1.98176","804.93622","1.89798","0.87743","0.01006","294.34158"
"119.50000","1.98975","806.75830","1.90588","0.88534","0.01010","295.00787"
"120.00000","1.99867","809.36188","1.91469","0.89415","0.01015","295.95993"
"120.50000","2.00642","811.02478","1.92237","0.90183","0.01019","296.56799"
"121.00000","2.01512","813.60052","1.93096","0.91041","0.01024","297.50989"
"121.50000","2.02317","815.60156","1.93893","0.91838","0.01028","298.24161"
"122.00000","2.03161","818.02148","1.94726","0.92672","0.01032","299.12650"
"122.50000","2.03990","820.36591","1.95545","0.93490","0.01037","299.98376"
"123.00000","2.04809","822.43683","1.96355","0.94301","0.01041","300.74106"
"123.50000","2.05671","824.93719","1.97205","0.95151","0.01045","301.65536"
"124.00000","2.06471","826.92682","1.97997","0.95943","0.01050","302.38290"
"124.50000","2.07340","829.41437","1.98855","0.96801","0.01054","303.29254"
"125.00000","2.08144","831.53375","1.99650","0.97596","0.01058","304.06754"
"125.50000","2.09027","834.06372","2.00522","0.98468","0.01063","304.99268"
"126.00000","2.09809","835.76337","2.01297","0.99242","0.01067","305.61417"
"126.50000","2.10671","838.23816","2.02148","1.00094","0.01072","306.51913"
"127.00000","2.11495","840.14160","2.02964","1.00909","0.01076","307.21518"
"127.50000","2.12324","842.09216","2.03784","1.01730","0.01080","307.92844"
"128.00000","2.13157","844.14062","2.04609","1.02554","0.01085","308.67749"
"128.50000","2.13979","846.04688","2.05423","1.03368","0.01089","309.37454"
"129.00000","2.14845","848.10583","2.06280","1.04226","0.01093","310.12744"
"129.50000","2.15636","849.73865","2.07064","1.05010","0.01098","310.72452"
"130.00000","2.16513","851.91431","2.07931","1.05877","0.01102","311.52011"
"130.50000","2.17311","853.42004","2.08723","1.06669","0.01106","312.07071"
"131.00000","2.18191","855.60809","2.09594","1.07540","0.01111","312.87082"
"131.50000","2.18974","856.86035","2.10373","1.08318","0.01115","313.32874"
"132.00000","2.19835","858.61523","2.11226","1.09171","0.01120","313.97043"
"132.50000","2.20662","859.86743","2.12047","1.09993","0.01124","314.42831"
"133.00000","2.21482","861.02228","2.12863","1.10809","0.01128","314.85062"
"133.50000","2.22328","861.90802","2.13705","1.11651","0.01133","315.17450"
"134.00000","2.23143","862.72778","2.14517","1.12462","0.01137","315.47427"
"134.50000","2.24021","864.03436","2.15390","1.13335","0.01142","315.95206"
"135.00000","2.24804","864.79999","2.16169","1.14115","0.01146","316.23203"
"135.50000","2.25684","866.27313","2.17043","1.14988","0.01151","316.77069"
"136.00000","2.26475","867.24005","2.17829","1.15775","0.01155","317.12427"
"136.50000","2.27357","868.83337","2.18705","1.16651","0.01159","317.70691"
"137.00000","2.28149","869.75677","2.19493","1.17439","0.01164","318.04456"
"137.50000","2.28991","871.13678","2.20329","1.18275","0.01168","318.54919"
"138.00000","2.29828","872.35254","2.21161","1.19107","0.01172","318.99377"
"138.50000","2.30645","873.65619","2.21973","1.19919","0.01177","319.47046"
"139.00000","2.31495","874.88593","2.22817","1.20763","0.01181","319.92014"
"139.50000","2.32306","875.98975","2.23624","1.21570","0.01185","320.32379"
"140.00000","2.33187","877.44269","2.24499","1.22444","0.01190","320.85507"
"140.50000","2.33972","878.24286","2.25281","1.23226","0.01194","321.14767"
"141.00000","2.34843","879.66937","2.26146","1.24091","0.01199","321.66931"
"141.50000","2.35652","880.69012","2.26951","1.24896","0.01203","322.04257"
"142.00000","2.36518","881.90277","2.27812","1.25757","0.01208","322.48599"
"142.50000","2.37317","882.74445","2.28607","1.26552","0.01212","322.79379"
"143.00000","2.38160","883.61017","2.29446","1.27392","0.01216","323.11035"
"143.50000","2.39002","884.61859","2.30284","1.28230","0.01221","323.47910"
"144.00000","2.39808","885.25128","2.31087","1.29033","0.01225","323.71045"
"144.50000","2.40667","886.19043","2.31943","1.29888","0.01230","324.05386"
"145.00000","2.41474","886.87555","2.32746","1.30692","0.01234","324.30441"
"145.50000","2.42355","887.97461","2.33623","1.31569","0.01238","324.70630"
"146.00000","2.43134","888.31903","2.34401","1.32346","0.01243","324.83224"
"146.50000","2.44014","889.33148","2.35276","1.33222","0.01247","325.20245"
"147.00000","2.44816","889.75458","2.36076","1.34022","0.01251","325.35718"
"147.50000","2.45671","890.64801","2.36928","1.34873","0.01256","325.68387"
"148.00000","2.46485","891.05170","2.37740","1.35686","0.01260","325.83151"
"148.50000","2.47322","891.51794","2.38575","1.36521","0.01265","326.00198"
"149.00000","2.48174","892.24304","2.39424","1.37369","0.01269","326.26715"
"149.50000","2.48973","892.34308","2.40222","1.38168","0.01273","326.30371"
"150.00000","2.49841","892.99567","2.41088","1.39034","0.01278","326.54236"
"150.50000","2.50637","893.18799","2.41883","1.39829","0.01282","326.61267"
"151.00000","2.51530","893.87384","2.42773","1.40719","0.01287","326.86346"
"151.50000","2.52311","893.84924","2.43554","1.41500","0.01291","326.85449"
"152.00000","2.53176","894.51642","2.44417","1.42362","0.01296","327.09845"
"152.50000","2.53987","894.75763","2.45226","1.43172","0.01300","327.18665"
"153.00000","2.54833","895.35089","2.46070","1.44016","0.01304","327.40359"
"153.50000","2.55652","895.85620","2.46887","1.44833","0.01309","327.58838"
"154.00000","2.56479","896.21649","2.47712","1.45658","0.01313","327.72012"
"154.50000","2.57339","896.82794","2.48570","1.46515","0.01318","327.94370"
"155.00000","2.58136","897.15765","2.49366","1.47311","0.01322","328.06427"
"155.50000","2.58997","897.73132","2.50225","1.48170","0.01326","328.27405"
"156.00000","2.59808","897.89600","2.51034","1.48980","0.01331","328.33426"
"156.50000","2.60699","898.82965","2.51921","1.49867","0.01335","328.67566"
"157.00000","2.61478","898.69183","2.52701","1.50647","0.01340","328.62527"
"157.50000","2.62343","899.30603","2.53564","1.51509","0.01344","328.84985"
"158.00000","2.63160","899.70526","2.54379","1.52325","0.01348","328.99585"
"158.50000","2.63993","900.21875","2.55210","1.53155","0.01353","329.18362"
"159.00000","2.64823","900.68494","2.56037","1.53983","0.01357","329.35410"
"159.50000","2.65648","901.07275","2.56862","1.54807","0.01362","329.49591"
"160.00000","2.66511","901.52844","2.57722","1.55668","0.01366","329.66254"
"160.50000","2.67298","901.67151","2.58509","1.56454","0.01370","329.71484"
"161.00000","2.68175","902.43549","2.59382","1.57328","0.01375","329.99420"
"161.50000","2.68973","902.66522","2.60180","1.58125","0.01379","330.07822"
"162.00000","2.69857","903.30627","2.61061","1.59006","0.01384","330.31265"
"162.50000","2.70643","903.53217","2.61845","1.59791","0.01388","330.39523"
"163.00000","2.71507","904.23859","2.62707","1.60653","0.01393","330.65356"
"163.50000","2.72325","904.59802","2.63523","1.61469","0.01397","330.78500"
"164.00000","2.73152","904.87933","2.64350","1.62295","0.01401","330.88785"
"164.50000","2.73996","905.23206","2.65191","1.63137","0.01406","331.01685"
"165.00000","2.74808","905.48889","2.66002","1.63948","0.01410","331.11075"
"165.50000","2.75683","906.02142","2.66875","1.64821","0.01415","331.30548"
"166.00000","2.76472","905.96863","2.67664","1.65610","0.01419","331.28619"
"166.50000","2.77348","906.26282","2.68539","1.66485","0.01424","331.39377"
"167.00000","2.78147","906.35632","2.69338","1.67283","0.01428","331.42795"
"167.50000","2.79027","906.41315","2.70218","1.68164","0.01432","331.44873"
"168.00000","2.79816","906.10797","2.71008","1.68954","0.01437","331.33713"
"168.50000","2.80658","906.08893","2.71850","1.69795","0.01441","331.33017"
"169.00000","2.81496","906.10132","2.72688","1.70634","0.01445","331.33472"
"169.50000","2.82313","905.88269","2.73506","1.71452","0.01450","331.25476"
"170.00000","2.83156","905.63556","2.74350","1.72296","0.01454","331.16440"
"170.50000","2.83973","905.25702","2.75169","1.73114","0.01459","331.02597"
"171.00000","2.84853","905.26007","2.76049","1.73994","0.01463","331.02707"
"171.50000","2.85637","904.83649","2.76835","1.74780","0.01467","330.87219"
"172.00000","2.86513","904.83380","2.77710","1.75656","0.01472","330.87122"
"172.50000","2.87318","904.44934","2.78517","1.76462","0.01476","330.73062"
"173.00000","2.88190","904.62646","2.79388","1.77334","0.01481","330.79538"
"173.50000","2.88983","904.38397","2.80182","1.78127","0.01485","330.70673"
"174.00000","2.89826","904.47589","2.81025","1.78971","0.01490","330.74033"
"174.50000","2.90666","904.63477","2.81864","1.79810","0.01494","330.79843"
"175.00000","2.91472","904.37897","2.82672","1.80617","0.01498","330.70490"
"175.50000","2.92330","904.44696","2.83529","1.81475","0.01503","330.72977"
"176.00000","2.93138","903.89301","2.84339","1.82285","0.01507","330.52719"
"176.50000","2.94020","903.74664","2.85222","1.83168","0.01512","330.47366"
"177.00000","2.94801","902.53241","2.86008","1.83954","0.01516","330.02966"
"177.50000","2.95684","900.98718","2.86898","1.84843","0.01521","329.46460"
"178.00000","2.96482","898.74707","2.87705","1.85650","0.01525","328.64548"
"178.50000","2.97345","896.95581","2.88575","1.86521","0.01530","327.99045"
"179.00000","2.98153","895.62598","2.89389","1.87334","0.01534","327.50418"
"179.50000","2.98984","894.90271","2.90223","1.88169","0.01538","327.23972"
"180.00000","2.99834","894.67725","2.91074","1.89020","0.01543","327.15726"
"180.50000","3.00638","894.43280","2.91879","1.89825","0.01547","327.06787"
"181.00000","3.01505","894.43402","2.92746","1.90692","0.01552","327.06833"
"181.50000","3.02309","894.33026","2.93551","1.91496","0.01556","327.03036"
"182.00000","3.03194","894.68530","2.94434","1.92380","0.01561","327.16019"
"182.50000","3.03974","894.64661","2.95214","1.93159","0.01565","327.14606"
"183.00000","3.04839","894.94281","2.96078","1.94024","0.01569","327.25436"
"183.50000","3.05656","895.20190","2.96893","1.94839","0.01574","327.34912"
"184.00000","3.06505","895.56158","2.97742","1.95687","0.01578","327.48062"
"184.50000","3.07315","895.82977","2.98551","1.96496","0.01583","327.57870"
"185.00000","3.08146","895.87140","2.99381","1.97327","0.01587","327.59393"
"185.50000","3.09008","896.21674","3.00242","1.98187","0.01592","327.72021"
"186.00000","3.09808","895.95691","3.01042","1.98988","0.01596","327.62518"
"186.50000","3.10669","895.69830","3.01905","1.99850","0.01600","327.53064"
"187.00000","3.11477","894.84613","3.02716","2.00662","0.01605","327.21902"
"187.50000","3.12362","894.24847","3.03604","2.01550","0.01609","327.00046"
"188.00000","3.13140","892.70837","3.04388","2.02334","0.01614","326.43729"
"188.50000","3.14009","892.04572","3.05260","2.03206","0.01618","326.19498"
"189.00000","3.14824","891.30255","3.06078","2.04024","0.01622","325.92322"
"189.50000","3.15663","891.02032","3.06918","2.04864","0.01627","325.82004"
"190.00000","3.16487","890.52905","3.07744","2.05690","0.01631","325.64038"
"190.50000","3.17311","890.49078","3.08569","2.06514","0.01636","325.62637"
"191.00000","3.18175","890.63971","3.09432","2.07378","0.01640","325.68085"
"191.50000","3.18966","890.53857","3.10224","2.08169","0.01644","325.64386"
"192.00000","3.19843","891.11469","3.11098","2.09043","0.01649","325.85452"
"192.50000","3.20639","891.28101","3.11893","2.09839","0.01653","325.91534"
"193.00000","3.21524","892.10895","3.12774","2.10720","0.01658","326.21811"
"193.50000","3.22310","892.36151","3.13560","2.11505","0.01662","326.31046"
"194.00000","3.23170","892.99689","3.14417","2.12362","0.01667","326.54279"
"194.50000","3.23989","893.51105","3.15234","2.13180","0.01671","326.73080"
"195.00000","3.24824","894.21014","3.16066","2.14012","0.01675","326.98645"
"195.50000","3.25661","894.84583","3.16901","2.14846","0.01680","327.21890"
"196.00000","3.26480","895.49097","3.17716","2.15662","0.01684","327.45480"
"196.50000","3.27347","896.22614","3.18581","2.16526","0.01689","327.72363"
"197.00000","3.28137","896.35675","3.19370","2.17316","0.01693","327.77139"
"197.50000","3.29004","896.81299","3.20235","2.18181","0.01698","327.93823"
"198.00000","3.29812","897.07996","3.21042","2.18988","0.01702","328.03586"
"198.50000","3.30691","897.46777","3.21919","2.19865","0.01706","328.17767"
"199.00000","3.31480","897.42346","3.22708","2.20654","0.01711","328.16147"
"199.50000","3.32330","897.59314","3.23558","2.21504","0.01715","328.22351"
"200.00000","3.33165","897.76831","3.24392","2.22338","0.01720","328.28757"
"200.50000","3.33987","897.87347","3.25213","2.23159","0.01724","328.32602"
"201.00000","3.34822","897.98340","3.26048","2.23994","0.01728","328.36621"
"201.50000","3.35643","898.15802","3.26868","2.24814","0.01733","328.43008"
"202.00000","3.36517","898.44550","3.27741","2.25687","0.01737","328.53519"
"202.50000","3.37300","898.01025","3.28526","2.26472","0.01741","328.37604"
"203.00000","3.38177","898.46515","3.29401","2.27347","0.01746","328.54239"
"203.50000","3.38979","898.34064","3.30204","2.28150","0.01750","328.49686"
"204.00000","3.39853","898.67322","3.31076","2.29022","0.01755","328.61847"
"204.50000","3.40645","898.56519","3.31869","2.29815","0.01759","328.57895"
"205.00000","3.41499","899.01501","3.32721","2.30666","0.01764","328.74344"
"205.50000","3.42331","899.00269","3.33552","2.31498","0.01768","328.73895"
"206.00000","3.43145","899.28394","3.34366","2.32311","0.01772","328.84180"
"206.50000","3.43996","899.58160","3.35216","2.33161","0.01777","328.95062"
"207.00000","3.44806","899.79132","3.36024","2.33970","0.01781","329.02731"
"207.50000","3.45685","900.31696","3.36901","2.34847","0.01786","329.21954"
"208.00000","3.46469","900.38544","3.37685","2.35631","0.01790","329.24457"
"208.50000","3.47349","901.16931","3.38562","2.36507","0.01795","329.53122"
"209.00000","3.48147","901.08002","3.39360","2.37305","0.01799","329.49857"
"209.50000","3.49023","901.79889","3.40233","2.38179","0.01804","329.76144"
"210.00000","3.49822","901.96887","3.41031","2.38977","0.01808","329.82358"
"210.50000","3.50656","902.31647","3.41864","2.39810","0.01812","329.95068"
"211.00000","3.51499","902.56018","3.42706","2.40652","0.01817","330.03983"
"211.50000","3.52305","902.75806","3.43511","2.41457","0.01821","330.11218"
"212.00000","3.53158","902.95605","3.44363","2.42309","0.01825","330.18457"
"212.50000","3.53972","903.11383","3.45177","2.43122","0.01830","330.24228"
"213.00000","3.54854","903.65839","3.46057","2.44002","0.01834","330.44141"
"213.50000","3.55642","903.57428","3.46845","2.44790","0.01839","330.41064"
"214.00000","3.56511","903.76166","3.47713","2.45659","0.01843","330.47916"
"214.50000","3.57321","903.85822","3.48523","2.46468","0.01847","330.51447"
"215.00000","3.58180","904.10132","3.49381","2.47326","0.01852","330.60336"
"215.50000","3.58982","903.87354","3.50184","2.48129","0.01856","330.52008"
"216.00000","3.59820","903.79443","3.51022","2.48968","0.01861","330.49115"
"216.50000","3.60669","903.94208","3.51870","2.49816","0.01865","330.54514"
"217.00000","3.61469","903.84119","3.52671","2.50617","0.01869","330.50824"
"217.50000","3.62336","904.30341","3.53536","2.51482","0.01874","330.67725"
"218.00000","3.63142","904.41846","3.54341","2.52286","0.01878","330.71933"
"218.50000","3.64029","905.04102","3.55226","2.53171","0.01883","330.94699"
"219.00000","3.64805","905.00610","3.56002","2.53948","0.01887","330.93420"
"219.50000","3.65683","905.55621","3.56877","2.54823","0.01892","331.13538"
"220.00000","3.66485","905.65466","3.57679","2.55625","0.01896","331.17139"
"220.50000","3.67337","906.13019","3.58529","2.56474","0.01901","331.34525"
"221.00000","3.68154","906.35754","3.59345","2.57291","0.01905","331.42841"
"221.50000","3.68979","906.78595","3.60168","2.58114","0.01909","331.58505"
"222.00000","3.69838","907.32837","3.61025","2.58971","0.01914","331.78339"
"222.50000","3.70633","907.48212","3.61819","2.59765","0.01918","331.83963"
"223.00000","3.71511","908.16522","3.62694","2.60640","0.01923","332.08942"
"223.50000","3.72307","908.28558","3.63490","2.61436","0.01927","332.13342"
"224.00000","3.73200","909.11707","3.64379","2.62325","0.01932","332.43747"
"224.50000","3.73980","909.16425","3.65160","2.63105","0.01936","332.45471"
"225.00000","3.74841","909.77789","3.66018","2.63963","0.01940","332.67911"
"225.50000","3.75657","910.15033","3.66832","2.64777","0.01945","332.81531"
"226.00000","3.76493","910.69714","3.67665","2.65611","0.01949","333.01526"
"226.50000","3.77320","911.12274","3.68491","2.66436","0.01953","333.17090"
"227.00000","3.78140","911.56586","3.69309","2.67255","0.01958","333.33292"
"227.50000","3.79007","912.19843","3.70174","2.68120","0.01962","333.56424"
"228.00000","3.79805","912.50940","3.70970","2.68915","0.01966","333.67795"
"228.50000","3.80678","913.10590","3.71841","2.69787","0.01971","333.89609"
"229.00000","3.81481","913.59589","3.72642","2.70587","0.01975","334.07526"
"229.50000","3.82360","914.23254","3.73518","2.71463","0.01980","334.30804"
"230.00000","3.83141","914.38324","3.74298","2.72244","0.01984","334.36316"
"230.50000","3.84000","915.07916","3.75154","2.73100","0.01989","334.61765"
"231.00000","3.84824","915.54449","3.75977","2.73922","0.01993","334.78781"
"231.50000","3.85653","916.03778","3.76803","2.74749","0.01997","334.96817"
"232.00000","3.86492","916.55499","3.77640","2.75586","0.02002","335.15732"
"232.50000","3.87309","917.01422","3.78456","2.76401","0.02006","335.32523"
"233.00000","3.88185","917.70746","3.79328","2.77274","0.02011","335.57874"
"233.50000","3.88966","917.87756","3.80109","2.78054","0.02015","335.64093"
"234.00000","3.89851","918.67029","3.80991","2.78936","0.02020","335.93082"
"234.50000","3.90643","918.85150","3.81782","2.79727","0.02024","335.99707"
"235.00000","3.91523","919.58020","3.82659","2.80605","0.02028","336.26355"
"235.50000","3.92310","919.71887","3.83446","2.81391","0.02033","336.31424"
"236.00000","3.93162","920.35419","3.84294","2.82240","0.02037","336.54657"
"236.50000","3.93994","920.88275","3.85124","2.83070","0.02042","336.73984"
"237.00000","3.94813","921.39941","3.85941","2.83887","0.02046","336.92877"
"237.50000","3.95666","921.97900","3.86792","2.84737","0.02050","337.14072"
"238.00000","3.96473","922.45673","3.87596","2.85542","0.02055","337.31540"
"238.50000","3.97353","923.27588","3.88473","2.86418","0.02059","337.61493"
"239.00000","3.98139","923.52740","3.89258","2.87204","0.02063","337.70691"
"239.50000","3.99014","924.41522","3.90129","2.88075","0.02068","338.03156"
"240.00000","3.99816","924.74725","3.90930","2.88876","0.02072","338.15298"
"240.50000","4.00687","925.68268","3.91797","2.89743","0.02077","338.49503"
"241.00000","4.01480","925.85620","3.92589","2.90535","0.02081","338.55847"
"241.50000","4.02318","926.46497","3.93425","2.91371","0.02086","338.78110"
"242.00000","4.03166","927.17578","3.94270","2.92215","0.02090","339.04102"
"242.50000","4.03981","927.57233","3.95083","2.93029","0.02094","339.18604"
"243.00000","4.04832","928.08167","3.95932","2.93878","0.02099","339.37228"
"243.50000","4.05642","928.63593","3.96740","2.94685","0.02103","339.57495"
"244.00000","4.06518","929.53339","3.97612","2.95557","0.02108","339.90314"
"244.50000","4.07300","928.18616","3.98399","2.96345","0.02112","339.41049"
"245.00000","4.08176","929.03522","3.99272","2.97217","0.02117","339.72095"
"245.50000","4.08981","928.97040","4.00078","2.98023","0.02121","339.69727"
"246.00000","4.09848","929.39355","4.00942","2.98888","0.02125","339.85199"
"246.50000","4.10650","929.68671","4.01743","2.99689","0.02130","339.95920"
"247.00000","4.11491","930.10498","4.02583","3.00529","0.02134","340.11215"
"247.50000","4.12339","930.76874","4.03428","3.01374","0.02139","340.35486"
"248.00000","4.13138","931.01672","4.04226","3.02172","0.02143","340.44553"
"248.50000","4.14003","931.64270","4.05089","3.03034","0.02147","340.67444"
"249.00000","4.14804","931.96326","4.05888","3.03833","0.02152","340.79166"
"249.50000","4.15690","932.65277","4.06771","3.04716","0.02156","341.04379"
"250.00000","4.16471","932.94678","4.07551","3.05497","0.02160","341.15131"
"250.50000","4.17348","933.50482","4.08425","3.06371","0.02165","341.35538"
"251.00000","4.18150","933.56586","4.09227","3.07172","0.02169","341.37769"
"251.50000","4.19006","934.22144","4.10080","3.08026","0.02174","341.61740"
"252.00000","4.19822","934.44183","4.10895","3.08841","0.02178","341.69800"
"252.50000","4.20648","934.69519","4.11720","3.09666","0.02182","341.79065"
"253.00000","4.21503","935.10291","4.12574","3.10519","0.02187","341.93973"
"253.50000","4.22303","935.08374","4.13374","3.11319","0.02191","341.93274"
"254.00000","4.23172","935.63049","4.14240","3.12186","0.02196","342.13266"
"254.50000","4.23977","935.55225","4.15046","3.12991","0.02200","342.10403"
"255.00000","4.24862","936.08124","4.15929","3.13875","0.02205","342.29749"
"255.50000","4.25644","935.91205","4.16711","3.14657","0.02209","342.23563"
"256.00000","4.26507","936.16760","4.17573","3.15519","0.02214","342.32907"
"256.50000","4.27324","936.05750","4.18390","3.16336","0.02218","342.28879"
"257.00000","4.28169","936.30896","4.19235","3.17180","0.02222","342.38077"
"257.50000","4.28990","936.07355","4.20057","3.18002","0.02227","342.29468"
"258.00000","4.29814","935.97223","4.20881","3.18826","0.02231","342.25763"
"258.50000","4.30675","936.11700","4.21741","3.19687","0.02236","342.31055"
"259.00000","4.31466","935.91083","4.22533","3.20479","0.02240","342.23517"
"259.50000","4.32338","935.56580","4.23407","3.21352","0.02244","342.10901"
"260.00000","4.33138","935.34381","4.24208","3.22154","0.02249","342.02783"
"260.50000","4.34031","935.74866","4.25099","3.23044","0.02253","342.17587"
"261.00000","4.34811","935.43018","4.25880","3.23826","0.02258","342.05942"
"261.50000","4.35679","935.61597","4.26748","3.24693","0.02262","342.12735"
"262.00000","4.36493","935.54724","4.27562","3.25507","0.02266","342.10220"
"262.50000","4.37323","935.55145","4.28392","3.26337","0.02271","342.10376"
"263.00000","4.38158","935.63971","4.29226","3.27172","0.02275","342.13602"
"263.50000","4.38975","935.48492","4.30044","3.27990","0.02280","342.07944"
"264.00000","4.39843","935.96967","4.30910","3.28856","0.02284","342.25668"
"264.50000","4.40634","935.80896","4.31701","3.29647","0.02288","342.19791"
"265.00000","4.41515","936.19934","4.32581","3.30527","0.02293","342.34067"
"265.50000","4.42309","936.08771","4.33375","3.31321","0.02297","342.29984"
"266.00000","4.43196","936.54395","4.34261","3.32207","0.02302","342.46667"
"266.50000","4.43984","936.47705","4.35049","3.32994","0.02306","342.44223"
"267.00000","4.44832","936.65942","4.35896","3.33842","0.02311","342.50891"
"267.50000","4.45658","936.69269","4.36722","3.34667","0.02315","342.52106"
"268.00000","4.46479","936.72675","4.37543","3.35489","0.02319","342.53354"
"268.50000","4.47327","936.80676","4.38390","3.36336","0.02324","342.56277"
"269.00000","4.48143","936.57849","4.39207","3.37153","0.02328","342.47931"
"269.50000","4.49020","936.66370","4.40084","3.38029","0.02333","342.51047"
"270.00000","4.49809","936.34186","4.40874","3.38820","0.02337","342.39279"
"270.50000","4.50681","936.48230","4.41746","3.39692","0.02342","342.44415"
"271.00000","4.51482","936.04846","4.42549","3.40494","0.02346","342.28549"
"271.50000","4.52358","935.59454","4.43427","3.41372","0.02351","342.11951"
"272.00000","4.53149","935.00513","4.44220","3.42166","0.02355","341.90399"
"272.50000","4.53992","934.65167","4.45064","3.43010","0.02359","341.77472"
"273.00000","4.54831","933.89954","4.45906","3.43852","0.02364","341.49969"
"273.50000","4.55642","933.28729","4.46720","3.44665","0.02368","341.27582"
"274.00000","4.56496","932.67041","4.47577","3.45523","0.02373","341.05023"
"274.50000","4.57308","931.91235","4.48392","3.46337","0.02377","340.77304"
"275.00000","4.58191","931.79218","4.49276","3.47221","0.02382","340.72910"
"275.50000","4.58972","931.05957","4.50060","3.48005","0.02386","340.46121"
"276.00000","4.59854","931.03564","4.50941","3.48887","0.02390","340.45245"
"276.50000","4.60650","930.37628","4.51740","3.49686","0.02395","340.21133"
"277.00000","4.61515","930.30017","4.52606","3.50552","0.02399","340.18350"
"277.50000","4.62317","929.49103","4.53411","3.51357","0.02403","339.88763"
"278.00000","4.63156","929.20392","4.54251","3.52197","0.02408","339.78265"
"278.50000","4.63999","928.54321","4.55097","3.53043","0.02412","339.54105"
"279.00000","4.64803","928.05621","4.55903","3.53849","0.02417","339.36298"
"279.50000","4.65670","927.92426","4.56771","3.54716","0.02421","339.31470"
"280.00000","4.66474","927.43652","4.57576","3.55522","0.02426","339.13635"
"280.50000","4.67358","927.55676","4.58460","3.56406","0.02430","339.18033"
"281.00000","4.68141","927.20648","4.59245","3.57190","0.02434","339.05225"
"281.50000","4.69010","927.34528","4.60113","3.58059","0.02439","339.10300"
"282.00000","4.69816","927.04694","4.60920","3.58866","0.02443","338.99390"
"282.50000","4.70676","927.26312","4.61779","3.59725","0.02448","339.07297"
"283.00000","4.71488","926.89215","4.62593","3.60539","0.02452","338.93732"
"283.50000","4.72318","926.99005","4.63423","3.61368","0.02457","338.97311"
"284.00000","4.73173","926.84515","4.64278","3.62224","0.02461","338.92010"
"284.50000","4.73975","926.56726","4.65081","3.63027","0.02465","338.81851"
"285.00000","4.74840","926.52075","4.65946","3.63892","0.02470","338.80148"
"285.50000","4.75648","926.25061","4.66755","3.64701","0.02474","338.70270"
"286.00000","4.76525","926.17542","4.67633","3.65578","0.02479","338.67520"
"286.50000","4.77308","925.67401","4.68418","3.66364","0.02483","338.49185"
"287.00000","4.78171","925.64124","4.69282","3.67227","0.02488","338.47989"
"287.50000","4.78988","925.08289","4.70101","3.68046","0.02492","338.27570"
"288.00000","4.79835","923.03723","4.70956","3.68902","0.02497","337.52768"
"288.50000","4.80654","921.84705","4.71780","3.69726","0.02501","337.09247"
"289.00000","4.81482","920.53638","4.72613","3.70559","0.02505","336.61319"
"289.50000","4.82343","920.05536","4.73476","3.71422","0.02510","336.43729"
"290.00000","4.83139","918.90302","4.74278","3.72224","0.02514","336.01590"
"290.50000","4.84009","917.89246","4.75152","3.73097","0.02519","335.64636"
"291.00000","4.84810","913.05200","4.75973","3.73918","0.02523","333.87637"
"291.50000","4.85686","911.26599","4.76856","3.74802","0.02528","333.22327"
"292.00000","4.86476","905.76813","4.77669","3.75615","0.02532","331.21286"
"292.43600","4.87205","874.58435","4.78529","3.76475","0.02537","319.80988"
"292.59100","4.87484","822.99542","4.79027","3.76973","0.02539","300.94531"
"292.92300","4.88052","783.27850","4.79765","3.77711","0.02543","286.42200"
"293.42300","4.88841","764.84320","4.80632","3.78577","0.02548","279.68076"
"293.92300","4.89723","757.38416","4.81544","3.79490","0.02553","276.95319"
"294.42300","4.90515","747.25903","4.82379","3.80324","0.02557","273.25073"
"294.92300","4.91401","736.71558","4.83310","3.81256","0.02562","269.39529"
"295.41800","4.92182","719.50793","4.84168","3.82114","0.02567","263.10297"
"295.91800","4.93022","716.40143","4.85022","3.82968","0.02571","261.96701"
"296.36100","4.93785","715.73651","4.85788","3.83734","0.02575","261.72388"