File: flexion/5_axis/Specimen_RawData_2.csv
Specimen properties : Specimen label,"2"
Specimen properties : Support span,"72.00",mm
Specimen properties : Thickness,"4.64",mm
Specimen properties : Width,"14.01",mm
Maximum Load : Maximum Load,"812.8",N
Tangent Modulus of Elasticity : Tangent Modulus of Elasticity,"32923634488.61430",Pa
Test : Rate 1,"1.00000",mm/min
Specimen notes : Specimen note 1,""

Time,Displacement,Load,Flexure extension,Corrected extension,Flexure strain (Corrected extension),Flexure stress
(s),(mm),(N),(mm),(mm),(mm/mm),(MPa)
"0.00000","-0.00006","9.49211","0.01104","-1.04695","0.00006","3.39870"
"0.50000","0.00588","11.96242","0.01592","-1.04207","0.00009","4.28320"
"1.00000","0.01473","15.58869","0.02321","-1.03478","0.00012","5.58161"
"1.50000","0.02273","19.02818","0.03045","-1.02754","0.00016","6.81313"
"2.00000","0.03153","22.53863","0.03851","-1.01948","0.00021","8.07007"
"2.50000","0.03944","25.71561","0.04574","-1.01225","0.00025","9.20760"
"3.00000","0.04803","29.23571","0.05359","-1.00440","0.00029","10.46799"
"3.50000","0.05631","32.68875","0.06114","-0.99685","0.00033","11.70437"
"4.00000","0.06446","36.01566","0.06863","-0.98936","0.00037","12.89558"
"4.50000","0.07294","39.55103","0.07663","-0.98136","0.00041","14.16144"
"5.00000","0.08106","42.95574","0.08430","-0.97369","0.00045","15.38051"
"5.50000","0.08982","46.70659","0.09255","-0.96544","0.00050","16.72352"
"6.00000","0.09767","50.05622","0.09996","-0.95803","0.00054","17.92288"
"6.50000","0.10648","54.00753","0.10824","-0.94975","0.00058","19.33766"
"7.00000","0.11443","57.46000","0.11572","-0.94227","0.00062","20.57384"
"7.50000","0.12325","61.62065","0.12405","-0.93394","0.00067","22.06358"
"8.00000","0.13118","65.16067","0.13157","-0.92642","0.00071","23.33110"
"8.50000","0.13956","68.88245","0.13951","-0.91848","0.00075","24.66370"
"9.00000","0.14794","72.78719","0.14743","-0.91056","0.00079","26.06181"
"9.50000","0.15606","76.67953","0.15510","-0.90289","0.00083","27.45548"
"10.00000","0.16463","80.74352","0.16319","-0.89480","0.00088","28.91061"
"10.50000","0.17275","84.60254","0.17086","-0.88713","0.00092","30.29235"
"11.00000","0.18158","88.80975","0.17923","-0.87876","0.00096","31.79877"
"11.50000","0.18941","92.49113","0.18670","-0.87129","0.00100","33.11690"
"12.00000","0.19813","96.57539","0.19502","-0.86297","0.00105","34.57930"
"12.50000","0.20618","100.35056","0.20270","-0.85529","0.00109","35.93101"
"13.00000","0.21485","104.51511","0.21096","-0.84703","0.00113","37.42215"
"13.50000","0.22284","108.16031","0.21860","-0.83939","0.00117","38.72733"
"14.00000","0.23119","112.06222","0.22656","-0.83143","0.00122","40.12443"
"14.50000","0.23965","115.91112","0.23465","-0.82334","0.00126","41.50254"
"15.00000","0.24768","119.84364","0.24230","-0.81569","0.00130","42.91060"
"15.50000","0.25632","123.96307","0.25053","-0.80746","0.00135","44.38559"
"16.00000","0.26439","127.73763","0.25823","-0.79976","0.00139","45.73709"
"16.50000","0.27326","131.87695","0.26670","-0.79129","0.00143","47.21919"
"17.00000","0.28107","135.56590","0.27415","-0.78384","0.00147","48.54004"
"17.50000","0.28986","139.75772","0.28253","-0.77546","0.00152","50.04094"
"18.00000","0.29785","143.45209","0.29017","-0.76782","0.00156","51.36372"
"18.50000","0.30638","147.36261","0.29832","-0.75967","0.00160","52.76391"
"19.00000","0.31451","151.21461","0.30607","-0.75192","0.00164","54.14314"
"19.50000","0.32282","155.21373","0.31400","-0.74399","0.00169","55.57504"
"20.00000","0.33135","159.13869","0.32216","-0.73583","0.00173","56.98039"
"20.50000","0.33933","163.01018","0.32980","-0.72819","0.00177","58.36660"
"21.00000","0.34808","167.16634","0.33820","-0.71979","0.00182","59.85473"
"21.50000","0.35606","170.74356","0.34588","-0.71211","0.00186","61.13557"
"22.00000","0.36496","175.03938","0.35441","-0.70358","0.00190","62.67371"
"22.50000","0.37277","178.79913","0.36190","-0.69609","0.00194","64.01991"
"23.00000","0.38140","182.94167","0.37018","-0.68781","0.00199","65.50317"
"23.50000","0.38951","186.65936","0.37798","-0.68001","0.00203","66.83430"
"24.00000","0.39797","190.69186","0.38609","-0.67190","0.00207","68.27816"
"24.50000","0.40621","194.40395","0.39402","-0.66397","0.00212","69.60729"
"25.00000","0.41445","198.40128","0.40192","-0.65607","0.00216","71.03855"
"25.50000","0.42310","202.54401","0.41022","-0.64777","0.00220","72.52188"
"26.00000","0.43106","206.25258","0.41789","-0.64010","0.00224","73.84975"
"26.50000","0.43976","210.42433","0.42626","-0.63173","0.00229","75.34347"
"27.00000","0.44780","214.17378","0.43400","-0.62399","0.00233","76.68597"
"27.50000","0.45658","218.41777","0.44243","-0.61556","0.00238","78.20556"
"28.00000","0.46442","222.12984","0.44998","-0.60801","0.00242","79.53468"
"28.50000","0.47299","226.12981","0.45823","-0.59976","0.00246","80.96689"
"29.00000","0.48124","230.10196","0.46616","-0.59183","0.00250","82.38914"
"29.50000","0.48956","234.12488","0.47416","-0.58383","0.00255","83.82957"
"30.00000","0.49788","238.00418","0.48217","-0.57582","0.00259","85.21857"
"30.50000","0.50610","241.96852","0.49007","-0.56792","0.00263","86.63802"
"31.00000","0.51480","246.17622","0.49844","-0.55955","0.00268","88.14461"
"31.50000","0.52271","249.89140","0.50607","-0.55192","0.00272","89.47485"
"32.00000","0.53150","254.09863","0.51453","-0.54346","0.00276","90.98126"
"32.50000","0.53943","257.79474","0.52218","-0.53581","0.00280","92.30467"
"33.00000","0.54820","262.10300","0.53062","-0.52737","0.00285","93.84727"
"33.50000","0.55611","265.90170","0.53824","-0.51975","0.00289","95.20741"
"34.00000","0.56469","270.06784","0.54650","-0.51149","0.00293","96.69912"
"34.50000","0.57293","273.84698","0.55445","-0.50354","0.00298","98.05226"
"35.00000","0.58113","277.71912","0.56236","-0.49563","0.00302","99.43870"
"35.50000","0.58960","281.74554","0.57052","-0.48747","0.00306","100.88038"
"36.00000","0.59772","285.64374","0.57833","-0.47966","0.00311","102.27615"
"36.50000","0.60646","289.85999","0.58675","-0.47124","0.00315","103.78579"
"37.00000","0.61436","293.46997","0.59440","-0.46359","0.00319","105.07837"
"37.50000","0.62310","297.80087","0.60286","-0.45513","0.00324","106.62907"
"38.00000","0.63109","301.55945","0.61059","-0.44740","0.00328","107.97485"
"38.50000","0.63988","305.82904","0.61909","-0.43890","0.00332","109.50359"
"39.00000","0.64782","309.56119","0.62679","-0.43120","0.00337","110.83990"
"39.50000","0.65626","313.55942","0.63496","-0.42303","0.00341","112.27149"
"40.00000","0.66466","317.54404","0.64310","-0.41489","0.00345","113.69820"
"40.50000","0.67282","321.30255","0.65100","-0.40699","0.00350","115.04396"
"41.00000","0.68129","325.48477","0.65919","-0.39880","0.00354","116.54142"
"41.50000","0.68947","329.23071","0.66712","-0.39087","0.00358","117.88268"
"42.00000","0.69815","333.51657","0.67552","-0.38247","0.00363","119.41725"
"42.50000","0.70601","337.11032","0.68314","-0.37485","0.00367","120.70401"
"43.00000","0.71470","341.19556","0.69155","-0.36644","0.00371","122.16675"
"43.50000","0.72280","344.99826","0.69940","-0.35859","0.00376","123.52832"
"44.00000","0.73149","349.17426","0.70783","-0.35016","0.00380","125.02356"
"44.50000","0.73949","352.82974","0.71559","-0.34240","0.00384","126.33243"
"45.00000","0.74792","356.74713","0.72378","-0.33421","0.00389","127.73506"
"45.50000","0.75634","360.83630","0.73193","-0.32606","0.00393","129.19922"
"46.00000","0.76443","364.41602","0.73979","-0.31820","0.00397","130.48094"
"46.50000","0.77297","368.49606","0.74807","-0.30992","0.00402","131.94183"
"47.00000","0.78108","372.24506","0.75594","-0.30205","0.00406","133.28418"
"47.50000","0.78985","376.40558","0.76444","-0.29355","0.00411","134.77386"
"48.00000","0.79772","379.98062","0.77209","-0.28591","0.00415","136.05392"
"48.50000","0.80652","384.06924","0.78063","-0.27737","0.00419","137.51788"
"49.00000","0.81448","387.73038","0.78835","-0.26964","0.00423","138.82877"
"49.50000","0.82309","391.78528","0.79672","-0.26127","0.00428","140.28064"
"50.00000","0.83118","395.44077","0.80460","-0.25339","0.00432","141.58951"
"50.50000","0.83952","399.19028","0.81273","-0.24526","0.00436","142.93204"
"51.00000","0.84797","403.03259","0.82096","-0.23703","0.00441","144.30780"
"51.50000","0.85601","406.74420","0.82878","-0.22921","0.00445","145.63676"
"52.00000","0.86467","410.73477","0.83721","-0.22078","0.00450","147.06560"
"52.50000","0.87271","414.34393","0.84505","-0.21294","0.00454","148.35788"
"53.00000","0.88158","418.41104","0.85369","-0.20430","0.00458","149.81413"
"53.50000","0.88942","421.96378","0.86133","-0.19666","0.00463","151.08621"
"54.00000","0.89806","425.93396","0.86974","-0.18825","0.00467","152.50775"
"54.50000","0.90619","429.60522","0.87766","-0.18033","0.00471","153.82227"
"55.00000","0.91472","433.59180","0.88596","-0.17203","0.00476","155.24968"
"55.50000","0.92284","437.15076","0.89388","-0.16411","0.00480","156.52397"
"56.00000","0.93121","440.99936","0.90203","-0.15596","0.00484","157.90199"
"56.50000","0.93972","444.85913","0.91032","-0.14767","0.00489","159.28400"
"57.00000","0.94766","448.54526","0.91805","-0.13994","0.00493","160.60384"
"57.50000","0.95632","452.46411","0.92649","-0.13150","0.00498","162.00700"
"58.00000","0.96443","456.07635","0.93439","-0.12360","0.00502","163.30038"
"58.50000","0.97326","460.26456","0.94298","-0.11501","0.00506","164.79999"
"59.00000","0.98109","463.63934","0.95062","-0.10737","0.00511","166.00835"
"59.50000","0.98975","467.72012","0.95905","-0.09894","0.00515","167.46950"
"60.00000","0.99787","471.28824","0.96697","-0.09102","0.00519","168.74707"
"60.50000","1.00630","475.13373","0.97518","-0.08281","0.00524","170.12396"
"61.00000","1.01452","478.83295","0.98319","-0.07480","0.00528","171.44849"
"61.50000","1.02280","482.49484","0.99125","-0.06674","0.00532","172.75964"
"62.00000","1.03141","486.50891","0.99963","-0.05836","0.00537","174.19691"
"62.50000","1.03935","489.98434","1.00738","-0.05061","0.00541","175.44130"
"63.00000","1.04814","494.07156","1.01597","-0.04202","0.00546","176.90475"
"63.50000","1.05609","497.50128","1.02374","-0.03425","0.00550","178.13278"
"64.00000","1.06499","501.54248","1.03244","-0.02555","0.00554","179.57976"
"64.50000","1.07278","505.01102","1.04006","-0.01793","0.00559","180.82167"
"65.00000","1.08136","508.85458","1.04844","-0.00955","0.00563","182.19789"
"65.50000","1.08953","512.45203","1.05643","-0.00156","0.00567","183.48596"
"66.00000","1.09782","516.02893","1.06455","0.00656","0.00572","184.76669"
"66.50000","1.10625","519.97083","1.07278","0.01479","0.00576","186.17812"
"67.00000","1.11439","523.38165","1.08074","0.02275","0.00580","187.39937"
"67.50000","1.12310","527.24469","1.08926","0.03127","0.00585","188.78255"
"68.00000","1.13103","530.72211","1.09702","0.03903","0.00589","190.02766"
"68.50000","1.13975","534.62878","1.10554","0.04755","0.00594","191.42647"
"69.00000","1.14778","537.89716","1.11341","0.05542","0.00598","192.59673"
"69.50000","1.15658","541.96527","1.12200","0.06401","0.00603","194.05333"
"70.00000","1.16445","545.08459","1.12972","0.07173","0.00607","195.17023"
"70.50000","1.17298","548.89417","1.13807","0.08008","0.00611","196.53426"
"71.00000","1.18131","552.56091","1.14622","0.08823","0.00616","197.84715"
"71.50000","1.18947","556.03320","1.15422","0.09623","0.00620","199.09042"
"72.00000","1.19793","559.55933","1.16250","0.10451","0.00624","200.35297"
"72.50000","1.20611","563.17883","1.17051","0.11252","0.00629","201.64896"
"73.00000","1.21483","566.80768","1.17905","0.12106","0.00633","202.94827"
"73.50000","1.22268","569.98071","1.18675","0.12876","0.00637","204.08440"
"74.00000","1.23147","573.91327","1.19535","0.13736","0.00642","205.49246"
"74.50000","1.23946","577.10437","1.20319","0.14520","0.00646","206.63506"
"75.00000","1.24820","580.79578","1.21175","0.15376","0.00651","207.95679"
"75.50000","1.25609","583.91760","1.21949","0.16150","0.00655","209.07457"
"76.00000","1.26459","587.66577","1.22780","0.16981","0.00659","210.41663"
"76.50000","1.27297","591.07318","1.23603","0.17804","0.00664","211.63666"
"77.00000","1.28109","594.33130","1.24400","0.18601","0.00668","212.80324"
"77.50000","1.28967","597.78644","1.25242","0.19443","0.00673","214.04037"
"78.00000","1.29774","600.85120","1.26035","0.20236","0.00677","215.13773"
"78.50000","1.30658","604.10529","1.26905","0.21106","0.00682","216.30287"
"79.00000","1.31437","606.88159","1.27671","0.21872","0.00686","217.29694"
"79.50000","1.32317","610.22607","1.28536","0.22737","0.00690","218.49445"
"80.00000","1.33112","611.59430","1.29325","0.23526","0.00695","218.98434"
"80.50000","1.33981","614.02747","1.30183","0.24384","0.00699","219.85556"
"81.00000","1.34784","616.67511","1.30974","0.25175","0.00703","220.80356"
"81.50000","1.35617","619.63538","1.31794","0.25995","0.00708","221.86349"
"82.00000","1.36464","622.59351","1.32628","0.26829","0.00712","222.92267"
"82.50000","1.37273","625.51343","1.33424","0.27625","0.00717","223.96815"
"83.00000","1.38131","628.79932","1.34267","0.28468","0.00721","225.14468"
"83.50000","1.38939","631.69470","1.35062","0.29263","0.00725","226.18140"
"84.00000","1.39820","634.93549","1.35928","0.30129","0.00730","227.34177"
"84.50000","1.40604","637.82159","1.36700","0.30901","0.00734","228.37515"
"85.00000","1.41473","640.98260","1.37555","0.31756","0.00739","229.50697"
"85.50000","1.42286","643.68750","1.38356","0.32557","0.00743","230.47548"
"86.00000","1.43143","645.82404","1.39202","0.33403","0.00748","231.24048"
"86.50000","1.43953","647.58405","1.40005","0.34206","0.00752","231.87065"
"87.00000","1.44786","649.56073","1.40829","0.35030","0.00756","232.57841"
"87.50000","1.45638","651.62799","1.41672","0.35873","0.00761","233.31860"
"88.00000","1.46438","653.26044","1.42465","0.36666","0.00765","233.90311"
"88.50000","1.47305","655.33447","1.43323","0.37524","0.00770","234.64574"
"89.00000","1.48108","655.28687","1.44125","0.38326","0.00774","234.62868"
"89.50000","1.48992","657.13794","1.45001","0.39202","0.00779","235.29147"
"90.00000","1.49770","658.17596","1.45775","0.39976","0.00783","235.66315"
"90.50000","1.50644","660.11029","1.46640","0.40841","0.00788","236.35573"
"91.00000","1.51454","661.83539","1.47443","0.41644","0.00792","236.97342"
"91.50000","1.52294","664.28406","1.48271","0.42472","0.00796","237.85017"
"92.00000","1.53119","666.92157","1.49085","0.43286","0.00801","238.79454"
"92.50000","1.53947","669.51862","1.49901","0.44102","0.00805","239.72443"
"93.00000","1.54809","672.20044","1.50751","0.44952","0.00810","240.68468"
"93.50000","1.55602","674.47845","1.51534","0.45735","0.00814","241.50032"
"94.00000","1.56476","677.31592","1.52395","0.46596","0.00818","242.51630"
"94.50000","1.57271","679.25513","1.53182","0.47383","0.00823","243.21063"
"95.00000","1.58162","681.40845","1.54063","0.48264","0.00827","243.98164"
"95.50000","1.58945","683.14905","1.54838","0.49039","0.00832","244.60487"
"96.00000","1.59803","685.54883","1.55685","0.49886","0.00836","245.46413"
"96.50000","1.60622","687.50482","1.56496","0.50697","0.00840","246.16449"
"97.00000","1.61456","689.77423","1.57320","0.51521","0.00845","246.97705"
"97.50000","1.62290","691.22601","1.58147","0.52348","0.00849","247.49687"
"98.00000","1.63108","690.75830","1.58968","0.53169","0.00854","247.32941"
"98.50000","1.63975","691.72925","1.59831","0.54032","0.00858","247.67706"
"99.00000","1.64768","692.89099","1.60618","0.54819","0.00863","248.09303"
"99.50000","1.65636","694.66168","1.61478","0.55679","0.00867","248.72704"
"100.00000","1.66444","696.27600","1.62279","0.56480","0.00871","249.30505"
"100.50000","1.67332","697.09222","1.63163","0.57364","0.00876","249.59731"
"101.00000","1.68113","694.57306","1.63955","0.58156","0.00880","248.69530"
"101.50000","1.68968","696.05914","1.64804","0.59005","0.00885","249.22740"
"102.00000","1.69794","697.64227","1.65623","0.59824","0.00889","249.79425"
"102.50000","1.70615","698.16986","1.66442","0.60643","0.00894","249.98315"
"103.00000","1.71459","698.91888","1.67282","0.61483","0.00898","250.25134"
"103.50000","1.72277","699.79175","1.68096","0.62297","0.00903","250.56387"
"104.00000","1.73148","700.82166","1.68963","0.63164","0.00907","250.93263"
"104.50000","1.73931","701.61786","1.69742","0.63943","0.00912","251.21773"
"105.00000","1.74810","701.93878","1.70619","0.64820","0.00916","251.33263"
"105.50000","1.75608","702.72894","1.71414","0.65615","0.00921","251.61555"
"106.00000","1.76484","704.22113","1.72284","0.66485","0.00925","252.14984"
"106.50000","1.77278","704.53870","1.73076","0.67277","0.00929","252.26355"
"107.00000","1.78134","706.30115","1.73924","0.68125","0.00934","252.89459"
"107.50000","1.78962","708.00360","1.74745","0.68946","0.00938","253.50417"
"108.00000","1.79777","709.76624","1.75552","0.69753","0.00943","254.13528"
"108.50000","1.80632","711.73987","1.76398","0.70599","0.00947","254.84196"
"109.00000","1.81437","713.53088","1.77195","0.71396","0.00952","255.48325"
"109.50000","1.82323","715.57422","1.78072","0.72273","0.00956","256.21487"
"110.00000","1.83106","716.91846","1.78848","0.73049","0.00960","256.69617"
"110.50000","1.83980","717.65222","1.79720","0.73921","0.00965","256.95889"
"111.00000","1.84780","718.41443","1.80516","0.74717","0.00969","257.23181"
"111.50000","1.85651","719.97083","1.81380","0.75581","0.00974","257.78909"
"112.00000","1.86450","721.04504","1.82174","0.76375","0.00978","258.17374"
"112.50000","1.87286","722.13489","1.83005","0.77206","0.00983","258.56393"
"113.00000","1.88131","723.40771","1.83845","0.78046","0.00987","259.01968"
"113.50000","1.88939","724.31451","1.84648","0.78849","0.00992","259.34436"
"114.00000","1.89792","725.25635","1.85497","0.79698","0.00996","259.68161"
"114.50000","1.90606","725.84192","1.86309","0.80510","0.01001","259.89127"
"115.00000","1.91494","726.96411","1.87192","0.81393","0.01005","260.29306"
"115.50000","1.92272","727.64423","1.87966","0.82167","0.01009","260.53659"
"116.00000","1.93145","729.01819","1.88833","0.83034","0.01014","261.02853"
"116.50000","1.93953","730.00842","1.89637","0.83838","0.01018","261.38312"
"117.00000","1.94811","731.41064","1.90489","0.84690","0.01023","261.88519"
"117.50000","1.95618","732.38007","1.91291","0.85492","0.01027","262.23227"
"118.00000","1.96454","733.67328","1.92121","0.86322","0.01032","262.69531"
"118.50000","1.97303","735.05969","1.92964","0.87165","0.01036","263.19174"
"119.00000","1.98100","736.08197","1.93758","0.87958","0.01041","263.55777"
"119.50000","1.98966","737.50348","1.94617","0.88818","0.01045","264.06674"
"120.00000","1.99770","738.71802","1.95416","0.89617","0.01049","264.50162"
"120.50000","2.00656","740.24994","1.96294","0.90495","0.01054","265.05014"
"121.00000","2.01435","740.99561","1.97071","0.91272","0.01058","265.31711"
"121.50000","2.02314","742.45746","1.97942","0.92143","0.01063","265.84055"
"122.00000","2.03117","743.50092","1.98742","0.92943","0.01067","266.21417"
"122.50000","2.03969","744.78839","1.99587","0.93788","0.01072","266.67514"
"123.00000","2.04790","745.75433","2.00405","0.94606","0.01076","267.02100"
"123.50000","2.05612","746.93451","2.01221","0.95422","0.01081","267.44357"
"124.00000","2.06471","748.15210","2.02076","0.96277","0.01085","267.87955"
"124.50000","2.07268","749.08539","2.02869","0.97070","0.01089","268.21371"
"125.00000","2.08143","750.45319","2.03738","0.97939","0.01094","268.70346"
"125.50000","2.08942","751.13251","2.04534","0.98735","0.01098","268.94669"
"126.00000","2.09828","752.56879","2.05414","0.99615","0.01103","269.46097"
"126.50000","2.10609","753.17017","2.06192","1.00393","0.01107","269.67627"
"127.00000","2.11466","754.34875","2.07045","1.01246","0.01112","270.09827"
"127.50000","2.12291","755.19507","2.07866","1.02067","0.01116","270.40131"
"128.00000","2.13128","755.99939","2.08700","1.02901","0.01121","270.68930"
"128.50000","2.13951","756.73645","2.09520","1.03721","0.01125","270.95322"
"129.00000","2.14775","757.57892","2.10340","1.04541","0.01130","271.25485"
"129.50000","2.15644","758.36804","2.11206","1.05407","0.01134","271.53741"
"130.00000","2.16437","758.66125","2.11998","1.06199","0.01139","271.64240"
"130.50000","2.17305","759.43579","2.12862","1.07063","0.01143","271.91971"
"131.00000","2.18111","759.44220","2.13669","1.07870","0.01147","271.92203"
"131.50000","2.18997","760.02710","2.14552","1.08753","0.01152","272.13144"
"132.00000","2.19776","759.79834","2.15332","1.09533","0.01156","272.04953"
"132.50000","2.20635","759.97870","2.16191","1.10392","0.01161","272.11411"
"133.00000","2.21459","759.92572","2.17015","1.11216","0.01165","272.09515"
"133.50000","2.22285","759.89166","2.17841","1.12042","0.01170","272.08295"
"134.00000","2.23122","759.86652","2.18678","1.12879","0.01174","272.07394"
"134.50000","2.23940","759.87048","2.19495","1.13696","0.01179","272.07538"
"135.00000","2.24812","760.13324","2.20366","1.14567","0.01183","272.16943"
"135.50000","2.25598","760.19775","2.21153","1.15354","0.01188","272.19254"
"136.00000","2.26479","760.82202","2.22031","1.16232","0.01192","272.41608"
"136.50000","2.27275","760.95129","2.22827","1.17028","0.01197","272.46234"
"137.00000","2.28156","761.75159","2.23704","1.17905","0.01201","272.74890"
"137.50000","2.28947","761.94025","2.24494","1.18695","0.01206","272.81647"
"138.00000","2.29794","762.62506","2.25338","1.19539","0.01210","273.06165"
"138.50000","2.30627","763.19586","2.26169","1.20370","0.01215","273.26602"
"139.00000","2.31448","763.83752","2.26987","1.21188","0.01219","273.49579"
"139.50000","2.32298","764.58551","2.27834","1.22035","0.01224","273.76361"
"140.00000","2.33110","765.19537","2.28643","1.22844","0.01228","273.98196"
"140.50000","2.33984","766.06049","2.29514","1.23715","0.01233","274.29172"
"141.00000","2.34769","766.36108","2.30298","1.24499","0.01237","274.39935"
"141.50000","2.35639","767.24176","2.31164","1.25365","0.01241","274.71469"
"142.00000","2.36448","767.78137","2.31971","1.26172","0.01246","274.90790"
"142.50000","2.37318","768.67474","2.32837","1.27038","0.01250","275.22778"
"143.00000","2.38111","769.12891","2.33628","1.27829","0.01255","275.39038"
"143.50000","2.38954","769.90302","2.34468","1.28669","0.01259","275.66757"
"144.00000","2.39800","770.65656","2.35311","1.29512","0.01264","275.93738"
"144.50000","2.40612","771.07166","2.36121","1.30322","0.01268","276.08600"
"145.00000","2.41460","771.85004","2.36966","1.31167","0.01273","276.36472"
"145.50000","2.42275","772.29950","2.37779","1.31980","0.01277","276.52563"
"146.00000","2.43157","773.23340","2.38657","1.32858","0.01282","276.86002"
"146.50000","2.43936","773.42035","2.39435","1.33636","0.01286","276.92697"
"147.00000","2.44813","774.37738","2.40308","1.34509","0.01291","277.26962"
"147.50000","2.45616","774.87268","2.41109","1.35310","0.01295","277.44696"
"148.00000","2.46477","775.58026","2.41967","1.36168","0.01299","277.70032"
"148.50000","2.47281","775.98395","2.42769","1.36970","0.01304","277.84488"
"149.00000","2.48123","776.74005","2.43609","1.37810","0.01308","278.11560"
"149.50000","2.48967","777.36432","2.44450","1.38651","0.01313","278.33911"
"150.00000","2.49772","777.63867","2.45253","1.39454","0.01317","278.43735"
"150.50000","2.50633","778.22504","2.46112","1.40313","0.01322","278.64731"
"151.00000","2.51436","778.39709","2.46915","1.41116","0.01326","278.70889"
"151.50000","2.52322","778.95209","2.47798","1.41999","0.01331","278.90762"
"152.00000","2.53104","778.81262","2.48581","1.42782","0.01335","278.85770"
"152.50000","2.53979","779.45831","2.49454","1.43655","0.01340","279.08887"
"153.00000","2.54783","779.55353","2.50256","1.44457","0.01344","279.12299"
"153.50000","2.55643","779.84344","2.51116","1.45317","0.01349","279.22678"
"154.00000","2.56456","779.92957","2.51929","1.46130","0.01353","279.25763"
"154.50000","2.57283","780.12927","2.52755","1.46956","0.01357","279.32913"
"155.00000","2.58136","780.52740","2.53606","1.47807","0.01362","279.47168"
"155.50000","2.58935","780.39447","2.54406","1.48607","0.01366","279.42407"
"156.00000","2.59796","780.72070","2.55265","1.49466","0.01371","279.54089"
"156.50000","2.60606","780.72418","2.56075","1.50276","0.01375","279.54214"
"157.00000","2.61488","781.25482","2.56955","1.51156","0.01380","279.73212"
"157.50000","2.62275","781.09186","2.57742","1.51943","0.01384","279.67377"
"158.00000","2.63140","781.34479","2.58606","1.52807","0.01389","279.76434"
"158.50000","2.63956","781.36304","2.59423","1.53624","0.01393","279.77087"
"159.00000","2.64802","781.50677","2.60267","1.54468","0.01398","279.82236"
"159.50000","2.65617","781.64478","2.61082","1.55283","0.01402","279.87177"
"160.00000","2.66448","781.69751","2.61913","1.56114","0.01407","279.89062"
"160.50000","2.67306","781.97961","2.62770","1.56971","0.01411","279.99164"
"161.00000","2.68100","781.91974","2.63564","1.57765","0.01415","279.97021"
"161.50000","2.68971","782.45282","2.64433","1.58634","0.01420","280.16107"
"162.00000","2.69774","782.43359","2.65236","1.59437","0.01424","280.15421"
"162.50000","2.70660","783.01642","2.66120","1.60321","0.01429","280.36288"
"163.00000","2.71441","782.55127","2.66902","1.61103","0.01433","280.19632"
"163.50000","2.72309","782.23126","2.67772","1.61973","0.01438","280.08176"
"164.00000","2.73122","782.25482","2.68585","1.62786","0.01442","280.09018"
"164.50000","2.73958","782.50134","2.69420","1.63621","0.01447","280.17847"
"165.00000","2.74789","782.99402","2.70249","1.64450","0.01451","280.35486"
"165.50000","2.75608","783.12170","2.71067","1.65268","0.01456","280.40057"
"166.00000","2.76476","783.64630","2.71933","1.66134","0.01460","280.58841"
"166.50000","2.77265","783.70013","2.72721","1.66922","0.01465","280.60770"
"167.00000","2.78145","784.24457","2.73599","1.67800","0.01469","280.80261"
"167.50000","2.78941","784.32306","2.74395","1.68596","0.01474","280.83072"
"168.00000","2.79831","784.77509","2.75283","1.69484","0.01478","280.99258"
"168.50000","2.80618","784.54150","2.76071","1.70272","0.01483","280.90894"
"169.00000","2.81467","784.96570","2.76918","1.71119","0.01487","281.06082"
"169.50000","2.82292","784.90332","2.77744","1.71945","0.01492","281.03848"
"170.00000","2.83114","784.92395","2.78565","1.72766","0.01496","281.04587"
"170.50000","2.83955","784.93414","2.79406","1.73607","0.01501","281.04953"
"171.00000","2.84772","784.69336","2.80225","1.74426","0.01505","280.96332"
"171.50000","2.85643","784.81995","2.81095","1.75296","0.01510","281.00864"
"172.00000","2.86437","784.39880","2.81891","1.76092","0.01514","280.85785"
"172.50000","2.87312","784.48376","2.82765","1.76966","0.01519","280.88828"
"173.00000","2.88115","784.00403","2.83570","1.77771","0.01523","280.71649"
"173.50000","2.88990","783.99823","2.84445","1.78646","0.01528","280.71442"
"174.00000","2.89777","783.42584","2.85235","1.79436","0.01532","280.50946"
"174.50000","2.90627","783.44464","2.86085","1.80286","0.01536","280.51620"
"175.00000","2.91460","783.10419","2.86919","1.81120","0.01541","280.39432"
"175.50000","2.92275","783.04352","2.87734","1.81935","0.01545","280.37259"
"176.00000","2.93127","783.10480","2.88586","1.82787","0.01550","280.39453"
"176.50000","2.93941","783.03534","2.89400","1.83601","0.01554","280.36966"
"177.00000","2.94821","783.51562","2.90279","1.84480","0.01559","280.54163"
"177.50000","2.95600","783.30060","2.91058","1.85259","0.01563","280.46463"
"178.00000","2.96489","783.69836","2.91945","1.86146","0.01568","280.60706"
"178.50000","2.97278","783.62689","2.92735","1.86936","0.01572","280.58145"
"179.00000","2.98151","784.10089","2.93606","1.87807","0.01577","280.75119"
"179.50000","2.98947","783.91144","2.94403","1.88604","0.01581","280.68335"
"180.00000","2.99787","784.12585","2.95242","1.89443","0.01586","280.76013"
"180.50000","3.00630","784.28528","2.96084","1.90285","0.01590","280.81720"
"181.00000","3.01437","784.21906","2.96892","1.91093","0.01594","280.79349"
"181.50000","3.02302","784.57483","2.97755","1.91956","0.01599","280.92087"
"182.00000","3.03103","784.59930","2.98556","1.92757","0.01603","280.92963"
"182.50000","3.03988","785.22333","2.99438","1.93639","0.01608","281.15308"
"183.00000","3.04772","785.19415","3.00223","1.94424","0.01612","281.14264"
"183.50000","3.05646","785.76886","3.01094","1.95295","0.01617","281.34842"
"184.00000","3.06451","785.76801","3.01899","1.96100","0.01621","281.34808"
"184.50000","3.07312","786.11401","3.02759","1.96960","0.01626","281.47198"
"185.00000","3.08115","786.24554","3.03560","1.97761","0.01630","281.51907"
"185.50000","3.08946","786.26794","3.04391","1.98592","0.01635","281.52710"
"186.00000","3.09802","786.38495","3.05247","1.99448","0.01639","281.56900"
"186.50000","3.10609","786.20312","3.06055","2.00256","0.01644","281.50391"
"187.00000","3.11471","786.27838","3.06917","2.01118","0.01648","281.53085"
"187.50000","3.12276","786.29645","3.07721","2.01922","0.01653","281.53732"
"188.00000","3.13156","786.65961","3.08600","2.02801","0.01657","281.66733"
"188.50000","3.13936","786.52234","3.09381","2.03582","0.01661","281.61819"
"189.00000","3.14806","786.94989","3.10249","2.04450","0.01666","281.77127"
"189.50000","3.15616","786.91785","3.11060","2.05261","0.01671","281.75980"
"190.00000","3.16467","787.20917","3.11908","2.06109","0.01675","281.86411"
"190.50000","3.17284","787.26562","3.12726","2.06927","0.01679","281.88434"
"191.00000","3.18116","787.37000","3.13557","2.07758","0.01684","281.92169"
"191.50000","3.18975","787.66064","3.14415","2.08616","0.01689","282.02576"
"192.00000","3.19766","787.63177","3.15206","2.09407","0.01693","282.01544"
"192.50000","3.20642","788.06616","3.16081","2.10282","0.01697","282.17096"
"193.00000","3.21438","788.03076","3.16876","2.11077","0.01702","282.15829"
"193.50000","3.22324","788.57263","3.17760","2.11961","0.01706","282.35229"
"194.00000","3.23106","788.59796","3.18542","2.12743","0.01711","282.36139"
"194.50000","3.23975","788.72351","3.19411","2.13612","0.01715","282.40634"
"195.00000","3.24786","789.00299","3.20220","2.14421","0.01720","282.50641"
"195.50000","3.25629","789.31433","3.21062","2.15263","0.01724","282.61789"
"196.00000","3.26458","789.45758","3.21891","2.16092","0.01729","282.66916"
"196.50000","3.27277","789.76306","3.22708","2.16909","0.01733","282.77853"
"197.00000","3.28140","790.34650","3.23569","2.17770","0.01738","282.98746"
"197.50000","3.28936","790.37714","3.24365","2.18566","0.01742","282.99841"
"198.00000","3.29809","790.93396","3.25235","2.19436","0.01747","283.19778"
"198.50000","3.30610","790.92810","3.26036","2.20237","0.01751","283.19571"
"199.00000","3.31492","791.54083","3.26916","2.21117","0.01756","283.41510"
"199.50000","3.32276","791.54095","3.27700","2.21901","0.01760","283.41513"
"200.00000","3.33130","791.87427","3.28553","2.22754","0.01764","283.53448"
"200.50000","3.33959","792.09760","3.29380","2.23581","0.01769","283.61444"
"201.00000","3.34793","792.38525","3.30213","2.24414","0.01773","283.71744"
"201.50000","3.35625","792.56567","3.31045","2.25245","0.01778","283.78204"
"202.00000","3.36441","792.72986","3.31860","2.26061","0.01782","283.84082"
"202.50000","3.37310","793.19080","3.32727","2.26928","0.01787","284.00586"
"203.00000","3.38097","793.20081","3.33514","2.27715","0.01791","284.00946"
"203.50000","3.38973","793.71863","3.34388","2.28589","0.01796","284.19485"
"204.00000","3.39774","793.83160","3.35188","2.29389","0.01800","284.23532"
"204.50000","3.40658","794.42487","3.36069","2.30270","0.01805","284.44772"
"205.00000","3.41446","794.47522","3.36858","2.31059","0.01809","284.46576"
"205.50000","3.42306","795.00128","3.37715","2.31916","0.01814","284.65411"
"206.00000","3.43131","795.09058","3.38540","2.32741","0.01818","284.68610"
"206.50000","3.43947","795.35358","3.39355","2.33556","0.01822","284.78027"
"207.00000","3.44794","795.64227","3.40201","2.34402","0.01827","284.88364"
"207.50000","3.45604","795.93744","3.41009","2.35210","0.01831","284.98932"
"208.00000","3.46481","796.43231","3.41884","2.36085","0.01836","285.16650"
"208.50000","3.47268","796.42328","3.42671","2.36872","0.01840","285.16327"
"209.00000","3.48150","796.93652","3.43551","2.37752","0.01845","285.34705"
"209.50000","3.48943","796.93292","3.44343","2.38544","0.01849","285.34576"
"210.00000","3.49822","797.51947","3.45220","2.39421","0.01854","285.55576"
"210.50000","3.50618","797.67462","3.46016","2.40217","0.01858","285.61133"
"211.00000","3.51456","797.89636","3.46852","2.41053","0.01863","285.69070"
"211.50000","3.52294","798.31287","3.47689","2.41890","0.01867","285.83984"
"212.00000","3.53108","798.52429","3.48502","2.42703","0.01872","285.91556"
"212.50000","3.53963","799.12439","3.49354","2.43555","0.01876","286.13043"
"213.00000","3.54775","799.30695","3.50165","2.44366","0.01881","286.19577"
"213.50000","3.55656","799.88904","3.51044","2.45245","0.01885","286.40421"
"214.00000","3.56440","799.76477","3.51828","2.46029","0.01889","286.35971"
"214.50000","3.57312","800.36285","3.52698","2.46899","0.01894","286.57385"
"215.00000","3.58117","800.43182","3.53503","2.47704","0.01898","286.59854"
"215.50000","3.58985","800.95294","3.54369","2.48570","0.01903","286.78513"
"216.00000","3.59785","800.80585","3.55169","2.49370","0.01907","286.73248"
"216.50000","3.60620","801.13037","3.56002","2.50203","0.01912","286.84866"
"217.00000","3.61466","801.37000","3.56848","2.51049","0.01916","286.93448"
"217.50000","3.62268","801.43463","3.57649","2.51850","0.01921","286.95761"
"218.00000","3.63131","801.61652","3.58511","2.52712","0.01925","287.02274"
"218.50000","3.63938","801.67188","3.59318","2.53519","0.01930","287.04257"
"219.00000","3.64828","802.16071","3.60206","2.54407","0.01934","287.21759"
"219.50000","3.65607","801.97797","3.60986","2.55187","0.01939","287.15216"
"220.00000","3.66486","802.23798","3.61864","2.56065","0.01943","287.24524"
"220.50000","3.67284","801.95557","3.62663","2.56864","0.01948","287.14413"
"221.00000","3.68137","802.30200","3.63515","2.57716","0.01952","287.26819"
"221.50000","3.68952","802.17950","3.64330","2.58531","0.01957","287.22430"
"222.00000","3.69783","802.20642","3.65160","2.59361","0.01961","287.23395"
"222.50000","3.70636","802.42798","3.66013","2.60214","0.01966","287.31329"
"223.00000","3.71433","802.25214","3.66811","2.61012","0.01970","287.25034"
"223.50000","3.72307","802.55737","3.67684","2.61885","0.01975","287.35962"
"224.00000","3.73105","802.29480","3.68483","2.62684","0.01979","287.26559"
"224.50000","3.73996","802.73199","3.69372","2.63573","0.01984","287.42215"
"225.00000","3.74777","802.39380","3.70154","2.64355","0.01988","287.30106"
"225.50000","3.75639","802.63690","3.71015","2.65216","0.01992","287.38809"
"226.00000","3.76451","802.52185","3.71827","2.66028","0.01997","287.34689"
"226.50000","3.77296","802.58447","3.72672","2.66873","0.02001","287.36932"
"227.00000","3.78122","802.47845","3.73499","2.67700","0.02006","287.33136"
"227.50000","3.78945","802.56964","3.74321","2.68522","0.02010","287.36401"
"228.00000","3.79811","802.86255","3.75186","2.69387","0.02015","287.46887"
"228.50000","3.80607","802.78973","3.75982","2.70183","0.02019","287.44281"
"229.00000","3.81477","803.24310","3.76850","2.71051","0.02024","287.60513"
"229.50000","3.82280","803.30811","3.77653","2.71854","0.02028","287.62842"
"230.00000","3.83159","803.62018","3.78531","2.72732","0.02033","287.74014"
"230.50000","3.83943","803.61804","3.79315","2.73516","0.02037","287.73938"
"231.00000","3.84798","804.00568","3.80168","2.74369","0.02042","287.87817"
"231.50000","3.85623","804.18463","3.80992","2.75193","0.02046","287.94226"
"232.00000","3.86457","804.54510","3.81824","2.76025","0.02051","288.07132"
"232.50000","3.87290","804.70789","3.82657","2.76858","0.02055","288.12961"
"233.00000","3.88111","804.87952","3.83477","2.77678","0.02059","288.19107"
"233.50000","3.88980","805.32318","3.84344","2.78545","0.02064","288.34991"
"234.00000","3.89770","805.36902","3.85134","2.79335","0.02068","288.36633"
"234.50000","3.90649","805.80505","3.86011","2.80212","0.02073","288.52246"
"235.00000","3.91445","805.80304","3.86808","2.81009","0.02077","288.52173"
"235.50000","3.92321","806.30371","3.87682","2.81883","0.02082","288.70102"
"236.00000","3.93111","806.20441","3.88471","2.82672","0.02086","288.66547"
"236.50000","3.93970","806.66064","3.89328","2.83529","0.02091","288.82880"
"237.00000","3.94792","805.36444","3.90156","2.84357","0.02095","288.36469"
"237.50000","3.95615","805.43134","3.90978","2.85179","0.02100","288.38864"
"238.00000","3.96462","805.51843","3.91826","2.86026","0.02104","288.41983"
"238.50000","3.97273","805.55927","3.92636","2.86837","0.02109","288.43445"
"239.00000","3.98145","805.93658","3.93507","2.87708","0.02113","288.56955"
"239.50000","3.98935","805.69659","3.94297","2.88498","0.02118","288.48364"
"240.00000","3.99812","805.96051","3.95173","2.89374","0.02122","288.57812"
"240.50000","4.00609","805.98163","3.95970","2.90171","0.02127","288.58569"
"241.00000","4.01489","806.41864","3.96848","2.91049","0.02131","288.74216"
"241.50000","4.02281","806.15460","3.97642","2.91843","0.02135","288.64761"
"242.00000","4.03125","806.61230","3.98483","2.92684","0.02140","288.81149"
"242.50000","4.03964","806.74841","3.99322","2.93523","0.02145","288.86023"
"243.00000","4.04783","806.83221","4.00141","2.94342","0.02149","288.89023"
"243.50000","4.05630","807.16022","4.00986","2.95187","0.02153","289.00769"
"244.00000","4.06446","807.30200","4.01802","2.96003","0.02158","289.05844"
"244.50000","4.07315","807.65576","4.02670","2.96870","0.02162","289.18512"
"245.00000","4.08101","807.69110","4.03455","2.97656","0.02167","289.19778"
"245.50000","4.08973","808.12213","4.04325","2.98526","0.02171","289.35211"
"246.00000","4.09782","808.33978","4.05133","2.99334","0.02176","289.43002"
"246.50000","4.10651","808.66644","4.06001","3.00202","0.02180","289.54700"
"247.00000","4.11448","808.74695","4.06798","3.00999","0.02185","289.57584"
"247.50000","4.12292","809.09857","4.07640","3.01841","0.02189","289.70172"
"248.00000","4.13135","809.43237","4.08481","3.02682","0.02194","289.82123"
"248.50000","4.13945","809.61920","4.09290","3.03491","0.02198","289.88812"
"249.00000","4.14798","809.89410","4.10143","3.04344","0.02203","289.98657"
"249.50000","4.15608","810.08887","4.10952","3.05153","0.02207","290.05630"
"250.00000","4.16483","810.43842","4.11825","3.06026","0.02212","290.18146"
"250.50000","4.17271","810.39288","4.12613","3.06814","0.02216","290.16516"
"251.00000","4.18153","811.01752","4.13493","3.07694","0.02221","290.38882"
"251.50000","4.18948","810.87817","4.14288","3.08489","0.02225","290.33893"
"252.00000","4.19809","811.23962","4.15148","3.09349","0.02229","290.46832"
"252.50000","4.20618","811.34503","4.15956","3.10157","0.02234","290.50607"
"253.00000","4.21450","811.67102","4.16787","3.10988","0.02238","290.62280"
"253.50000","4.22296","811.83099","4.17632","3.11833","0.02243","290.68008"
"254.00000","4.23102","811.86127","4.18438","3.12639","0.02247","290.69092"
"254.50000","4.23968","812.11066","4.19303","3.13504","0.02252","290.78021"
"255.00000","4.24770","812.14673","4.20104","3.14305","0.02256","290.79312"
"255.50000","4.25657","812.59229","4.20990","3.15191","0.02261","290.95267"
"256.00000","4.26441","812.39221","4.21775","3.15976","0.02265","290.88101"
"256.50000","4.27308","812.62274","4.22640","3.16841","0.02270","290.96356"
"257.00000","4.28119","812.50500","4.23452","3.17653","0.02274","290.92142"
"257.50000","4.28972","812.70941","4.24304","3.18505","0.02279","290.99460"
"258.00000","4.29786","812.57483","4.25119","3.19320","0.02283","290.94641"
"258.50000","4.30620","812.54614","4.25953","3.20154","0.02288","290.93616"
"259.00000","4.31473","812.48749","4.26806","3.21007","0.02292","290.91513"
"259.50000","4.32267","812.36438","4.27601","3.21802","0.02296","290.87106"
"260.00000","4.33131","812.30963","4.28465","3.22666","0.02301","290.85147"
"260.50000","4.33942","812.00104","4.29277","3.23478","0.02305","290.74097"
"261.00000","4.34826","812.29926","4.30160","3.24361","0.02310","290.84775"
"261.50000","4.35608","811.88141","4.30944","3.25145","0.02314","290.69812"
"262.00000","4.36478","811.78741","4.31815","3.26016","0.02319","290.66449"
"262.50000","4.37288","811.61298","4.32625","3.26826","0.02323","290.60202"
"263.00000","4.38130","811.47150","4.33468","3.27669","0.02328","290.55136"
"263.50000","4.38951","811.19946","4.34290","3.28491","0.02332","290.45395"
"264.00000","4.39778","810.98511","4.35118","3.29319","0.02337","290.37720"
"264.50000","4.40642","810.95715","4.35982","3.30183","0.02341","290.36719"
"265.00000","4.41436","810.63873","4.36778","3.30979","0.02346","290.25317"
"265.50000","4.42314","810.73859","4.37654","3.31855","0.02350","290.28894"
"266.00000","4.43108","810.28967","4.38450","3.32651","0.02355","290.12820"
"266.50000","4.43997","810.52649","4.39339","3.33540","0.02359","290.21298"
"267.00000","4.44778","810.09406","4.40122","3.34323","0.02364","290.05817"
"267.50000","4.45636","810.11755","4.40979","3.35180","0.02368","290.06656"
"268.00000","4.46452","809.73395","4.41797","3.35998","0.02373","289.92923"
"268.50000","4.47282","809.57245","4.42628","3.36829","0.02377","289.87140"
"269.00000","4.48123","809.56055","4.43469","3.37670","0.02382","289.86713"
"269.50000","4.48939","809.38757","4.44286","3.38487","0.02386","289.80521"
"270.00000","4.49810","809.43878","4.45156","3.39357","0.02391","289.82355"
"270.50000","4.50604","809.13025","4.45952","3.40153","0.02395","289.71307"
"271.00000","4.51474","809.11945","4.46822","3.41023","0.02400","289.70920"
"271.50000","4.52278","808.67755","4.47627","3.41828","0.02404","289.55096"
"272.00000","4.53159","809.01001","4.48507","3.42708","0.02409","289.67001"
"272.50000","4.53944","808.57184","4.49295","3.43495","0.02413","289.51312"
"273.00000","4.54798","808.61914","4.50148","3.44349","0.02417","289.53006"
"273.50000","4.55630","808.42108","4.50980","3.45181","0.02422","289.45914"
"274.00000","4.56448","808.25128","4.51799","3.46000","0.02426","289.39835"
"274.50000","4.57294","808.15100","4.52646","3.46847","0.02431","289.36243"
"275.00000","4.58111","807.78992","4.53465","3.47666","0.02435","289.23315"
"275.50000","4.58983","807.87183","4.54337","3.48538","0.02440","289.26248"
"276.00000","4.59771","807.43896","4.55126","3.49327","0.02444","289.10748"
"276.50000","4.60647","807.40369","4.56002","3.50203","0.02449","289.09485"
"277.00000","4.61445","807.02368","4.56801","3.51002","0.02453","288.95880"
"277.50000","4.62320","807.09930","4.57676","3.51877","0.02458","288.98587"
"278.00000","4.63111","806.58038","4.58469","3.52671","0.02462","288.80008"
"278.50000","4.63960","806.68872","4.59319","3.53520","0.02467","288.83887"
"279.00000","4.64796","806.66357","4.60155","3.54356","0.02471","288.82986"
"279.50000","4.65607","806.34839","4.60967","3.55168","0.02476","288.71701"
"280.00000","4.66464","806.49097","4.61823","3.56024","0.02480","288.76807"
"280.50000","4.67272","806.27148","4.62633","3.56834","0.02485","288.68948"
"281.00000","4.68160","806.29150","4.63520","3.57721","0.02489","288.69662"
"281.50000","4.68938","805.54504","4.64301","3.58502","0.02493","288.42935"
"282.00000","4.69815","805.80579","4.65177","3.59378","0.02498","288.52274"
"282.50000","4.70611","804.41571","4.65979","3.60180","0.02502","288.02499"
"283.00000","4.71481","800.47717","4.66866","3.61067","0.02507","286.61478"
"283.50000","4.72286","794.05261","4.67699","3.61900","0.02512","284.31445"
"284.00000","4.73118","792.78375","4.68537","3.62738","0.02516","283.86011"
"284.50000","4.73964","792.22339","4.69385","3.63586","0.02521","283.65948"
"285.00000","4.74774","785.97229","4.70221","3.64422","0.02525","281.42123"
"285.50000","4.75632","785.60962","4.71080","3.65281","0.02530","281.29138"
"286.00000","4.76441","785.28088","4.71890","3.66091","0.02534","281.17368"
"286.50000","4.77321","785.50165","4.72770","3.66971","0.02539","281.25272"
"287.00000","4.78104","785.37988","4.73554","3.67754","0.02543","281.20914"
"287.50000","4.78974","785.58276","4.74423","3.68624","0.02548","281.28177"
"288.00000","4.79788","785.42920","4.75238","3.69439","0.02552","281.22678"
"288.50000","4.80642","785.40759","4.76091","3.70292","0.02557","281.21906"
"289.00000","4.81453","785.28992","4.76903","3.71104","0.02561","281.17691"
"289.50000","4.82286","785.04858","4.77737","3.71938","0.02566","281.09052"
"290.00000","4.83137","785.02026","4.78588","3.72789","0.02570","281.08035"
"290.50000","4.83938","784.64075","4.79391","3.73592","0.02575","280.94449"
"291.00000","4.84806","784.67773","4.80258","3.74459","0.02579","280.95773"
"291.50000","4.85608","784.17377","4.81063","3.75264","0.02583","280.77728"
"292.00000","4.86491","784.36414","4.81945","3.76146","0.02588","280.84543"
"292.50000","4.87269","783.92468","4.82725","3.76926","0.02592","280.68808"
"293.00000","4.88143","783.82410","4.83600","3.77800","0.02597","280.65207"
"293.50000","4.88953","783.37903","4.84411","3.78612","0.02601","280.49271"
"294.00000","4.89794","783.28809","4.85253","3.79454","0.02606","280.46014"
"294.50000","4.90621","783.00293","4.86081","3.80282","0.02610","280.35806"
"295.00000","4.91450","782.60413","4.86911","3.81112","0.02615","280.21527"
"295.50000","4.92309","782.31561","4.87772","3.81973","0.02620","280.11194"
"296.00000","4.93101","781.95081","4.88565","3.82766","0.02624","279.98132"
"296.50000","4.93976","781.87744","4.89440","3.83641","0.02628","279.95505"
"297.00000","4.94770","781.31976","4.90237","3.84438","0.02633","279.75537"
"297.50000","4.95664","781.38214","4.91131","3.85332","0.02638","279.77771"
"298.00000","4.96444","780.41595","4.91915","3.86116","0.02642","279.43176"
"298.50000","4.97300","779.73419","4.92773","3.86974","0.02646","279.18765"
"299.00000","4.98123","779.09839","4.93598","3.87799","0.02651","278.96002"
"299.50000","4.98958","778.50177","4.94436","3.88637","0.02655","278.74640"
"300.00000","4.99788","777.70190","4.95269","3.89470","0.02660","278.45999"
"300.50000","5.00607","774.87170","4.96101","3.90302","0.02664","277.44662"
"300.98700","5.01458","753.47668","4.97040","3.91241","0.02669","269.78604"
"301.48700","5.02248","751.25812","4.97840","3.92041","0.02674","268.99167"
"301.98700","5.03118","751.35260","4.98710","3.92911","0.02678","269.02548"
"302.48700","5.03927","750.59381","4.99522","3.93723","0.02683","268.75381"
"302.98700","5.04804","750.50256","5.00399","3.94600","0.02687","268.72113"
"303.48700","5.05593","749.96545","5.01190","3.95391","0.02692","268.52881"
"303.98700","5.06441","749.89929","5.02039","3.96240","0.02696","268.50513"
"304.48700","5.07276","749.14514","5.02877","3.97078","0.02701","268.23511"
"304.98700","5.08090","748.49054","5.03693","3.97894","0.02705","268.00073"
"305.48700","5.08942","741.62122","5.04574","3.98775","0.02710","265.54114"
"305.98700","5.09753","739.17523","5.05396","3.99597","0.02714","264.66531"
"306.48700","5.10628","738.86578","5.06273","4.00474","0.02719","264.55453"
"306.98700","5.11411","738.37347","5.07058","4.01259","0.02723","264.37827"
"307.48700","5.12290","738.13495","5.07938","4.02139","0.02728","264.29285"
"307.98700","5.13091","737.10358","5.08744","4.02945","0.02732","263.92355"
"308.48700","5.13954","736.58173","5.09609","4.03810","0.02737","263.73669"
"308.98700","5.14760","732.90039","5.10431","4.04632","0.02741","262.41858"
"309.48700","5.15605","732.00397","5.11281","4.05482","0.02746","262.09763"
"309.98700","5.16447","731.35999","5.12125","4.06326","0.02750","261.86703"
"310.48700","5.17252","729.29657","5.12940","4.07140","0.02755","261.12823"
"310.98700","5.18114","728.27478","5.13805","4.08006","0.02759","260.76236"
"311.48700","5.18913","726.11914","5.14614","4.08815","0.02764","259.99054"
"311.76300","5.19386","687.62860","5.15260","4.09461","0.02767","246.20880"
"311.99700","5.19819","639.46497","5.15907","4.10108","0.02771","228.96358"
"312.49700","5.20601","637.66827","5.16697","4.10898","0.02775","228.32027"
"312.99700","5.21475","638.40717","5.17568","4.11769","0.02780","228.58482"
"313.49700","5.22276","638.22168","5.18369","4.12570","0.02784","228.51842"
"313.99700","5.23144","639.69098","5.19232","4.13433","0.02788","229.04449"
"314.49700","5.23945","640.96234","5.20026","4.14227","0.02793","229.49973"
"314.99700","5.24778","636.98724","5.20878","4.15079","0.02797","228.07642"
"315.49700","5.25626","637.85504","5.21722","4.15923","0.02802","228.38713"
"315.99700","5.26435","638.96448","5.22525","4.16726","0.02806","228.78438"
"316.49700","5.27287","640.55249","5.23370","4.17571","0.02811","229.35297"
"316.67400","5.27563","641.12500","5.23644","4.17845","0.02812","229.55795"